Workbook

Sheet 933 builds
B1: MAX GFLOPS: | D1: =MAX(I:I) -> 8.5334 | L1: Odroid10 throttling time [1/100s] | O1: Odroid11 throttling time [1/100s] | R1: Odroid12 throttling time [1/100s] | U1: Odroid13 throttling time [1/100s]
B2: RUN | D2: N | E2: NB | F2: P | G2: Q | H2: Time | I2: GFLOPS | J2: Date | K2: Time | L2: 1700MHz | M2: 1800MHz | N2: 1900MHz | O2: 1700MHz | P2: 1800MHz | Q2: 1900MHz | R2: 1700MHz | S2: 1800MHz | T2: 1900MHz | U2: 1700MHz | V2: 1800MHz | W2: 1900MHz
A3: small-atlasarch-tune-flags | B3: 0 | C3: WR00L2L2 | D3: 25984 | E3: 128 | F3: 2 | G3: 8 | H3: 1372.97 | I3: 8.5193 | J3: 45318 | K3: 0.26398148 | L3: 0 | M3: 0 | N3: 0 | O3: 0 | P3: 0 | Q3: 0 | R3: 0 | S3: 0 | T3: 0 | U3: 0 | V3: 0 | W3: 0 | X3: =AVERAGE(I3:I7) -> 8.51756
A4: small-atlasarch-tune-flags | B4: 1 | C4: WR00L2L2 | D4: 25984 | E4: 128 | F4: 2 | G4: 8 | H4: 1373.17 | I4: 8.5181 | J4: 45318 | K4: 0.28020833 | L4: 0 | M4: 0 | N4: 0 | O4: 0 | P4: 0 | Q4: 0 | R4: 0 | S4: 0 | T4: 0 | U4: 0 | V4: 0 | W4: 0 | X4: =X3 -> 8.51756
A5: small-atlasarch-tune-flags | B5: 2 | C5: WR00L2L2 | D5: 25984 | E5: 128 | F5: 2 | G5: 8 | H5: 1373.85 | I5: 8.5139 | J5: 45318 | K5: 0.29645833 | L5: 0 | M5: 0 | N5: 0 | O5: 0 | P5: 0 | Q5: 0 | R5: 0 | S5: 0 | T5: 0 | U5: 0 | V5: 0 | W5: 0 | X5: =X4 -> 8.51756
A6: small-atlasarch-tune-flags | B6: 3 | C6: WR00L2L2 | D6: 25984 | E6: 128 | F6: 2 | G6: 8 | H6: 1373.24 | I6: 8.5176 | J6: 45318 | K6: 0.31269676 | L6: 0 | M6: 0 | N6: 0 | O6: 0 | P6: 0 | Q6: 0 | R6: 0 | S6: 0 | T6: 0 | U6: 0 | V6: 0 | W6: 0 | X6: =X5 -> 8.51756
A7: small-atlasarch-tune-flags | B7: 4 | C7: WR00L2L2 | D7: 25984 | E7: 128 | F7: 2 | G7: 8 | H7: 1373.03 | I7: 8.5189 | J7: 45318 | K7: 0.32892361 | L7: 0 | M7: 0 | N7: 0 | O7: 0 | P7: 0 | Q7: 0 | R7: 0 | S7: 0 | T7: 0 | U7: 0 | V7: 0 | W7: 0 | X7: =X6 -> 8.51756
A8: small-arch-tune-flags | B8: 0 | C8: WR00L2L2 | D8: 25984 | E8: 128 | F8: 2 | G8: 8 | H8: 1394.44 | I8: 8.3881 | J8: 45318 | K8: 0.3453125 | L8: 0 | M8: 0 | N8: 0 | O8: 0 | P8: 0 | Q8: 0 | R8: 0 | S8: 0 | T8: 0 | U8: 0 | V8: 0 | W8: 0 | X8: =AVERAGE(I8:I12) -> 8.38768
A9: small-arch-tune-flags | B9: 1 | C9: WR00L2L2 | D9: 25984 | E9: 128 | F9: 2 | G9: 8 | H9: 1394.48 | I9: 8.3879 | J9: 45318 | K9: 0.36170139 | L9: 0 | M9: 0 | N9: 0 | O9: 0 | P9: 0 | Q9: 0 | R9: 0 | S9: 0 | T9: 0 | U9: 0 | V9: 0 | W9: 0 | X9: =X8 -> 8.38768
A10: small-arch-tune-flags | B10: 2 | C10: WR00L2L2 | D10: 25984 | E10: 128 | F10: 2 | G10: 8 | H10: 1394.53 | I10: 8.3876 | J10: 45318 | K10: 0.37809028 | L10: 0 | M10: 0 | N10: 0 | O10: 0 | P10: 0 | Q10: 0 | R10: 0 | S10: 0 | T10: 0 | U10: 0 | V10: 0 | W10: 0 | X10: =X9 -> 8.38768
A11: small-arch-tune-flags | B11: 3 | C11: WR00L2L2 | D11: 25984 | E11: 128 | F11: 2 | G11: 8 | H11: 1395 | I11: 8.3848 | J11: 45318 | K11: 0.39447917 | L11: 0 | M11: 0 | N11: 0 | O11: 0 | P11: 0 | Q11: 0 | R11: 0 | S11: 0 | T11: 0 | U11: 0 | V11: 0 | W11: 0 | X11: =X10 -> 8.38768
A12: small-arch-tune-flags | B12: 4 | C12: WR00L2L2 | D12: 25984 | E12: 128 | F12: 2 | G12: 8 | H12: 1394.13 | I12: 8.39 | J12: 45318 | K12: 0.41085648 | L12: 0 | M12: 0 | N12: 0 | O12: 0 | P12: 0 | Q12: 0 | R12: 0 | S12: 0 | T12: 0 | U12: 0 | V12: 0 | W12: 0 | X12: =X11 -> 8.38768
A13: small-cpu-flags | B13: 0 | C13: WR00L2L2 | D13: 25984 | E13: 128 | F13: 2 | G13: 8 | H13: 1395.27 | I13: 8.3831 | J13: 45318 | K13: 0.42751157 | L13: 0 | M13: 0 | N13: 0 | O13: 0 | P13: 0 | Q13: 0 | R13: 0 | S13: 0 | T13: 0 | U13: 0 | V13: 0 | W13: 0 | X13: =AVERAGE(I13:I17) -> 8.38574
A14: small-cpu-flags | B14: 1 | C14: WR00L2L2 | D14: 25984 | E14: 128 | F14: 2 | G14: 8 | H14: 1395.18 | I14: 8.3836 | J14: 45318 | K14: 0.44391204 | L14: 0 | M14: 0 | N14: 0 | O14: 0 | P14: 0 | Q14: 0 | R14: 0 | S14: 0 | T14: 0 | U14: 0 | V14: 0 | W14: 0 | X14: =X13 -> 8.38574
A15: small-cpu-flags | B15: 2 | C15: WR00L2L2 | D15: 25984 | E15: 128 | F15: 2 | G15: 8 | H15: 1394.42 | I15: 8.3882 | J15: 45318 | K15: 0.46030093 | L15: 0 | M15: 0 | N15: 0 | O15: 0 | P15: 0 | Q15: 0 | R15: 0 | S15: 0 | T15: 0 | U15: 0 | V15: 0 | W15: 0 | X15: =X14 -> 8.38574
A16: small-cpu-flags | B16: 3 | C16: WR00L2L2 | D16: 25984 | E16: 128 | F16: 2 | G16: 8 | H16: 1394.84 | I16: 8.3857 | J16: 45318 | K16: 0.47670139 | L16: 0 | M16: 0 | N16: 0 | O16: 0 | P16: 0 | Q16: 0 | R16: 0 | S16: 0 | T16: 0 | U16: 0 | V16: 0 | W16: 0 | X16: =X15 -> 8.38574
A17: small-cpu-flags | B17: 4 | C17: WR00L2L2 | D17: 25984 | E17: 128 | F17: 2 | G17: 8 | H17: 1394.44 | I17: 8.3881 | J17: 45318 | K17: 0.49309028 | L17: 0 | M17: 0 | N17: 0 | O17: 0 | P17: 0 | Q17: 0 | R17: 0 | S17: 0 | T17: 0 | U17: 0 | V17: 0 | W17: 0 | X17: =X16 -> 8.38574
A18: small | B18: 0 | C18: WR00L2L2 | D18: 25984 | E18: 128 | F18: 2 | G18: 8 | H18: 1372.21 | I18: 8.524 | J18: 45319 | K18: 0.11185185 | L18: 0 | M18: 0 | N18: 0 | O18: 0 | P18: 0 | Q18: 0 | R18: 0 | S18: 0 | T18: 0 | U18: 0 | V18: 0 | W18: 0 | X18: =AVERAGE(I18:I22) -> 8.52848
A19: small | B19: 1 | C19: WR00L2L2 | D19: 25984 | E19: 128 | F19: 2 | G19: 8 | H19: 1371.46 | I19: 8.5287 | J19: 45319 | K19: 0.12804398 | L19: 0 | M19: 0 | N19: 0 | O19: 0 | P19: 0 | Q19: 0 | R19: 0 | S19: 0 | T19: 0 | U19: 0 | V19: 0 | W19: 0 | X19: =X18 -> 8.52848
A20: small | B20: 2 | C20: WR00L2L2 | D20: 25984 | E20: 128 | F20: 2 | G20: 8 | H20: 1371.85 | I20: 8.5263 | J20: 45319 | K20: 0.14423611 | L20: 0 | M20: 0 | N20: 0 | O20: 0 | P20: 0 | Q20: 0 | R20: 0 | S20: 0 | T20: 0 | U20: 0 | V20: 0 | W20: 0 | X20: =X19 -> 8.52848
A21: small | B21: 3 | C21: WR00L2L2 | D21: 25984 | E21: 128 | F21: 2 | G21: 8 | H21: 1370.71 | I21: 8.5334 | J21: 45319 | K21: 0.16042824 | L21: 0 | M21: 0 | N21: 0 | O21: 0 | P21: 0 | Q21: 0 | R21: 0 | S21: 0 | T21: 0 | U21: 0 | V21: 0 | W21: 0 | X21: =X20 -> 8.52848
A22: small | B22: 4 | C22: WR00L2L2 | D22: 25984 | E22: 128 | F22: 2 | G22: 8 | H22: 1371.24 | I22: 8.53 | J22: 45319 | K22: 0.1766088 | L22: 0 | M22: 0 | N22: 0 | O22: 0 | P22: 0 | Q22: 0 | R22: 0 | S22: 0 | T22: 0 | U22: 0 | V22: 0 | W22: 0 | X22: =X21 -> 8.52848
A23: small-atlasarch-tune | B23: 0 | C23: WR00L2L2 | D23: 25984 | E23: 128 | F23: 2 | G23: 8 | H23: 1606.63 | I23: 7.2803 | J23: 45319 | K23: 0.19552083 | L23: 0 | M23: 0 | N23: 0 | O23: 0 | P23: 0 | Q23: 0 | R23: 0 | S23: 0 | T23: 0 | U23: 0 | V23: 0 | W23: 0 | X23: =AVERAGE(I23:I27) -> 7.2748
A24: small-atlasarch-tune | B24: 1 | C24: WR00L2L2 | D24: 25984 | E24: 128 | F24: 2 | G24: 8 | H24: 1607.74 | I24: 7.2752 | J24: 45319 | K24: 0.21443287 | L24: 0 | M24: 0 | N24: 0 | O24: 0 | P24: 0 | Q24: 0 | R24: 0 | S24: 0 | T24: 0 | U24: 0 | V24: 0 | W24: 0 | X24: =X23 -> 7.2748
A25: small-atlasarch-tune | B25: 2 | C25: WR00L2L2 | D25: 25984 | E25: 128 | F25: 2 | G25: 8 | H25: 1607.85 | I25: 7.2748 | J25: 45319 | K25: 0.23335648 | L25: 0 | M25: 0 | N25: 0 | O25: 0 | P25: 0 | Q25: 0 | R25: 0 | S25: 0 | T25: 0 | U25: 0 | V25: 0 | W25: 0 | X25: =X24 -> 7.2748
A26: small-atlasarch-tune | B26: 3 | C26: WR00L2L2 | D26: 25984 | E26: 128 | F26: 2 | G26: 8 | H26: 1608.49 | I26: 7.2719 | J26: 45319 | K26: 0.25229167 | L26: 0 | M26: 0 | N26: 0 | O26: 0 | P26: 0 | Q26: 0 | R26: 0 | S26: 0 | T26: 0 | U26: 0 | V26: 0 | W26: 0 | X26: =X25 -> 7.2748
A27: small-atlasarch-tune | B27: 4 | C27: WR00L2L2 | D27: 25984 | E27: 128 | F27: 2 | G27: 8 | H27: 1608.51 | I27: 7.2718 | J27: 45319 | K27: 0.27121528 | L27: 0 | M27: 0 | N27: 0 | O27: 0 | P27: 0 | Q27: 0 | R27: 0 | S27: 0 | T27: 0 | U27: 0 | V27: 0 | W27: 0 | X27: =X26 -> 7.2748
A28: small-arch-tune | B28: 0 | C28: WR00L2L2 | D28: 25984 | E28: 128 | F28: 2 | G28: 8 | H28: 2050.62 | I28: 5.704 | J28: 45319 | K28: 0.29630787 | L28: 0 | M28: 0 | N28: 0 | O28: 0 | P28: 0 | Q28: 0 | R28: 0 | S28: 0 | T28: 0 | U28: 0 | V28: 0 | W28: 0 | X28: =AVERAGE(I28:I32) -> 5.70352
A29: small-arch-tune | B29: 1 | C29: WR00L2L2 | D29: 25984 | E29: 128 | F29: 2 | G29: 8 | H29: 2050.74 | I29: 5.7037 | J29: 45319 | K29: 0.32138889 | L29: 0 | M29: 0 | N29: 0 | O29: 0 | P29: 0 | Q29: 0 | R29: 0 | S29: 0 | T29: 0 | U29: 0 | V29: 0 | W29: 0 | X29: =X28 -> 5.70352
A30: small-arch-tune | B30: 2 | C30: WR00L2L2 | D30: 25984 | E30: 128 | F30: 2 | G30: 8 | H30: 2050.72 | I30: 5.7037 | J30: 45319 | K30: 0.34648148 | L30: 0 | M30: 0 | N30: 0 | O30: 0 | P30: 0 | Q30: 0 | R30: 0 | S30: 0 | T30: 0 | U30: 0 | V30: 0 | W30: 0 | X30: =X29 -> 5.70352
A31: small-arch-tune | B31: 3 | C31: WR00L2L2 | D31: 25984 | E31: 128 | F31: 2 | G31: 8 | H31: 2050.72 | I31: 5.7037 | J31: 45319 | K31: 0.3715625 | L31: 0 | M31: 0 | N31: 0 | O31: 0 | P31: 0 | Q31: 0 | R31: 0 | S31: 0 | T31: 0 | U31: 0 | V31: 0 | W31: 0 | X31: =X30 -> 5.70352
A32: small-arch-tune | B32: 4 | C32: WR00L2L2 | D32: 25984 | E32: 128 | F32: 2 | G32: 8 | H32: 2051.16 | I32: 5.7025 | J32: 45319 | K32: 0.39665509 | L32: 0 | M32: 0 | N32: 0 | O32: 0 | P32: 0 | Q32: 0 | R32: 0 | S32: 0 | T32: 0 | U32: 0 | V32: 0 | W32: 0 | X32: =X31 -> 5.70352
A33: small-atlasarch-tune2 | B33: 0 | C33: WR00L2L2 | D33: 25984 | E33: 128 | F33: 2 | G33: 8 | H33: 1607.2 | I33: 7.2777 | J33: 45319 | K33: 0.41556713 | L33: 0 | M33: 0 | N33: 0 | O33: 0 | P33: 0 | Q33: 0 | R33: 0 | S33: 0 | T33: 0 | U33: 0 | V33: 0 | W33: 0 | X33: =AVERAGE(I33:I37) -> 7.2753
A34: small-atlasarch-tune2 | B34: 1 | C34: WR00L2L2 | D34: 25984 | E34: 128 | F34: 2 | G34: 8 | H34: 1607.85 | I34: 7.2748 | J34: 45319 | K34: 0.43449074 | L34: 0 | M34: 0 | N34: 0 | O34: 0 | P34: 0 | Q34: 0 | R34: 0 | S34: 0 | T34: 0 | U34: 0 | V34: 0 | W34: 0 | X34: =X33 -> 7.2753
A35: small-atlasarch-tune2 | B35: 2 | C35: WR00L2L2 | D35: 25984 | E35: 128 | F35: 2 | G35: 8 | H35: 1608.07 | I35: 7.2737 | J35: 45319 | K35: 0.45341435 | L35: 0 | M35: 0 | N35: 0 | O35: 0 | P35: 0 | Q35: 0 | R35: 0 | S35: 0 | T35: 0 | U35: 0 | V35: 0 | W35: 0 | X35: =X34 -> 7.2753
A36: small-atlasarch-tune2 | B36: 3 | C36: WR00L2L2 | D36: 25984 | E36: 128 | F36: 2 | G36: 8 | H36: 1607.65 | I36: 7.2757 | J36: 45319 | K36: 0.47232639 | L36: 0 | M36: 0 | N36: 0 | O36: 0 | P36: 0 | Q36: 0 | R36: 0 | S36: 0 | T36: 0 | U36: 0 | V36: 0 | W36: 0 | X36: =X35 -> 7.2753
A37: small-atlasarch-tune2 | B37: 4 | C37: WR00L2L2 | D37: 25984 | E37: 128 | F37: 2 | G37: 8 | H37: 1607.88 | I37: 7.2746 | J37: 45319 | K37: 0.49125 | L37: 0 | M37: 0 | N37: 0 | O37: 0 | P37: 0 | Q37: 0 | R37: 0 | S37: 0 | T37: 0 | U37: 0 | V37: 0 | W37: 0 | X37: =X36 -> 7.2753
A38: small-cpu | B38: 0 | C38: WR00L2L2 | D38: 25984 | E38: 128 | F38: 2 | G38: 8 | H38: 1609.33 | I38: 7.2681 | J38: 45319 | K38: 0.51122685 | L38: 0 | M38: 0 | N38: 0 | O38: 0 | P38: 0 | Q38: 0 | R38: 0 | S38: 0 | T38: 0 | U38: 0 | V38: 0 | W38: 0 | X38: =AVERAGE(I38:I42) -> 7.26552
A39: small-cpu | B39: 1 | C39: WR00L2L2 | D39: 25984 | E39: 128 | F39: 2 | G39: 8 | H39: 1610.6 | I39: 7.2623 | J39: 45319 | K39: 0.53122685 | L39: 0 | M39: 0 | N39: 0 | O39: 0 | P39: 0 | Q39: 0 | R39: 0 | S39: 0 | T39: 0 | U39: 0 | V39: 0 | W39: 0 | X39: =X38 -> 7.26552
A40: small-cpu | B40: 2 | C40: WR00L2L2 | D40: 25984 | E40: 128 | F40: 2 | G40: 8 | H40: 1609.79 | I40: 7.266 | J40: 45319 | K40: 0.5512037 | L40: 0 | M40: 0 | N40: 0 | O40: 0 | P40: 0 | Q40: 0 | R40: 0 | S40: 0 | T40: 0 | U40: 0 | V40: 0 | W40: 0 | X40: =X39 -> 7.26552
...

Sheet 933 params, RAW
A1: Max avg. GFLOPS (and params): | E1: =MAX(W$1:W$500) -> 9.02122 | F1: =INDEX(C$1:C$500,MATCH(MAX($W$1:$W$500),$W$1:$W$500,0)) -> 28992 | G1: =INDEX(D$1:D$500,MATCH(MAX($W$1:$W$500),$W$1:$W$500,0)) -> 96 | H1: =INDEX(E$1:E$500,MATCH(MAX($W$1:$W$500),$W$1:$W$500,0)) -> 2 | I1: =INDEX(F$1:F$500,MATCH(MAX($W$1:$W$500),$W$1:$W$500,0)) -> 8 | L1: ATLAS - small | Y1: Max avg. GFLOPS (and params): | AC1: =MAX(AU:AU) -> 10.039 | AD1: =INDEX(AA:AA,MATCH(MAX($AU:$AU),$AU:$AU,0)) -> 29056 | AE1: =INDEX(AB:AB,MATCH(MAX($AU:$AU),$AU:$AU,0)) -> 64 | AF1: =INDEX(AC:AC,MATCH(MAX($AU:$AU),$AU:$AU,0)) -> 2 | AG1: =INDEX(AD:AD,MATCH(MAX($AU:$AU),$AU:$AU,0)) -> 8 | AJ1: OpenBLAS
A2: MAX GFLOPS: | C2: =MAX(H$1:H$500) -> 9.0246 | K2: Odroid10 throttling time [1/100s] | N2: Odroid11 throttling time [1/100s] | Q2: Odroid12 throttling time [1/100s] | T2: Odroid13 throttling time [1/100s] | Y2: MAX GFLOPS: | AA2: =MAX(AF:AF) -> 10.045 | AI2: Odroid10 throttling time [1/100s] | AL2: Odroid11 throttling time [1/100s] | AO2: Odroid12 throttling time [1/100s] | AR2: Odroid13 throttling time [1/100s]
A3: RUN | C3: N | D3: NB | E3: P | F3: Q | G3: Time | H3: GFLOPS | I3: Date | J3: Time | K3: 1700MHz | L3: 1800MHz | M3: 1900MHz | N3: 1700MHz | O3: 1800MHz | P3: 1900MHz | Q3: 1700MHz | R3: 1800MHz | S3: 1900MHz | T3: 1700MHz | U3: 1800MHz | V3: 1900MHz | Y3: RUN | AA3: N | AB3: NB | AC3: P | AD3: Q | AE3: Time | AF3: GFLOPS | AG3: Date | AH3: Time | AI3: 1700MHz | AJ3: 1800MHz | AK3: 1900MHz | AL3: 1700MHz | AM3: 1800MHz | AN3: 1900MHz | AO3: 1700MHz | AP3: 1800MHz | AQ3: 1900MHz | AR3: 1700MHz | AS3: 1800MHz | AT3: 1900MHz
A4: 0 | B4: WR00L2L2 | C4: 25984 | D4: 32 | E4: 1 | F4: 16 | G4: 1363.97 | H4: 8.5755 | I4: 45482 | J4: 0.049525463 | K4: 0 | L4: 0 | M4: 0 | N4: 0 | O4: 0 | P4: 0 | Q4: 0 | R4: 0 | S4: 0 | T4: 0 | U4: 0 | V4: 0 | W4: =AVERAGE(H4:H8) -> 8.57764 | Y4: 0 | Z4: WR00L2L2 | AA4: 25984 | AB4: 32 | AC4: 1 | AD4: 16 | AE4: 1229.39 | AF4: 9.5142 | AG4: 45477 | AH4: 0.62855324 | AI4: 0 | AJ4: 0 | AK4: 0 | AL4: 0 | AM4: 0 | AN4: 0 | AO4: 0 | AP4: 0 | AQ4: 0 | AR4: 0 | AS4: 0 | AT4: 0 | AU4: =AVERAGE(AF4:AF8) -> 9.51508
A5: 1 | B5: WR00L2L2 | C5: 25984 | D5: 32 | E5: 1 | F5: 16 | G5: 1363.56 | H5: 8.5781 | I5: 45482 | J5: 0.5587037 | K5: 0 | L5: 0 | M5: 0 | N5: 0 | O5: 0 | P5: 0 | Q5: 0 | R5: 0 | S5: 0 | T5: 0 | U5: 0 | V5: 0 | W5: =W4 -> 8.57764 | Y5: 1 | Z5: WR00L2L2 | AA5: 25984 | AB5: 32 | AC5: 1 | AD5: 16 | AE5: 1228.94 | AF5: 9.5178 | AG5: 45478 | AH5: 0.13922454 | AI5: 0 | AJ5: 0 | AK5: 0 | AL5: 0 | AM5: 0 | AN5: 0 | AO5: 0 | AP5: 0 | AQ5: 0 | AR5: 0 | AS5: 0 | AT5: 0 | AU5: =AU4 -> 9.51508
A6: 2 | B6: WR00L2L2 | C6: 25984 | D6: 32 | E6: 1 | F6: 16 | G6: 1364.14 | H6: 8.5744 | I6: 45483 | J6: 0.11537037 | K6: 0 | L6: 0 | M6: 0 | N6: 0 | O6: 0 | P6: 0 | Q6: 0 | R6: 0 | S6: 0 | T6: 0 | U6: 0 | V6: 0 | W6: =W5 -> 8.57764 | Y6: 2 | Z6: WR00L2L2 | AA6: 25984 | AB6: 32 | AC6: 1 | AD6: 16 | AE6: 1229.43 | AF6: 9.5139 | AG6: 45478 | AH6: 0.6499537 | AI6: 0 | AJ6: 0 | AK6: 0 | AL6: 0 | AM6: 0 | AN6: 0 | AO6: 0 | AP6: 0 | AQ6: 0 | AR6: 0 | AS6: 0 | AT6: 0 | AU6: =AU5 -> 9.51508
A7: 3 | B7: WR00L2L2 | C7: 25984 | D7: 32 | E7: 1 | F7: 16 | G7: 1362.85 | H7: 8.5826 | I7: 45477 | J7: 0.53040509 | K7: 0 | L7: 0 | M7: 0 | N7: 0 | O7: 0 | P7: 0 | Q7: 0 | R7: 0 | S7: 0 | T7: 0 | U7: 0 | V7: 0 | W7: =W6 -> 8.57764 | Y7: 3 | Z7: WR00L2L2 | AA7: 25984 | AB7: 32 | AC7: 1 | AD7: 16 | AE7: 1229.6 | AF7: 9.5127 | AG7: 45479 | AH7: 0.16050926 | AI7: 0 | AJ7: 0 | AK7: 0 | AL7: 0 | AM7: 0 | AN7: 0 | AO7: 0 | AP7: 0 | AQ7: 0 | AR7: 0 | AS7: 0 | AT7: 0 | AU7: =AU6 -> 9.51508
A8: 4 | B8: WR00L2L2 | C8: 25984 | D8: 32 | E8: 1 | F8: 16 | G8: 1363.64 | H8: 8.5776 | I8: 45478 | J8: 0.055231481 | K8: 0 | L8: 0 | M8: 0 | N8: 0 | O8: 0 | P8: 0 | Q8: 0 | R8: 0 | S8: 0 | T8: 0 | U8: 0 | V8: 0 | W8: =W7 -> 8.57764 | Y8: 4 | Z8: WR00L2L2 | AA8: 25984 | AB8: 32 | AC8: 1 | AD8: 16 | AE8: 1229.06 | AF8: 9.5168 | AG8: 45479 | AH8: 0.67127315 | AI8: 0 | AJ8: 0 | AK8: 0 | AL8: 0 | AM8: 0 | AN8: 0 | AO8: 0 | AP8: 0 | AQ8: 0 | AR8: 0 | AS8: 0 | AT8: 0 | AU8: =AU7 -> 9.51508
A9: 0 | B9: WR00L2L2 | C9: 27520 | D9: 32 | E9: 1 | F9: 16 | G9: 1618.88 | H9: 8.5837 | I9: 45481 | J9: 0.87810185 | K9: 0 | L9: 0 | M9: 0 | N9: 0 | O9: 0 | P9: 0 | Q9: 0 | R9: 0 | S9: 0 | T9: 0 | U9: 0 | V9: 0 | W9: =AVERAGE(H9:H13) -> 8.58208 | Y9: 0 | Z9: WR00L2L2 | AA9: 27520 | AB9: 32 | AC9: 1 | AD9: 16 | AE9: 1455.12 | AF9: 9.5497 | AG9: 45477 | AH9: 0.46255787 | AI9: 0 | AJ9: 0 | AK9: 0 | AL9: 0 | AM9: 0 | AN9: 0 | AO9: 0 | AP9: 0 | AQ9: 0 | AR9: 0 | AS9: 0 | AT9: 0 | AU9: =AVERAGE(AF9:AF13) -> 9.54286
A10: 1 | B10: WR00L2L2 | C10: 27520 | D10: 32 | E10: 1 | F10: 16 | G10: 1619.72 | H10: 8.5793 | I10: 45482 | J10: 0.40324074 | K10: 0 | L10: 0 | M10: 0 | N10: 0 | O10: 0 | P10: 0 | Q10: 0 | R10: 0 | S10: 0 | T10: 0 | U10: 0 | V10: 0 | W10: =W9 -> 8.58208 | Y10: 1 | Z10: WR00L2L2 | AA10: 27520 | AB10: 32 | AC10: 1 | AD10: 16 | AE10: 1457.1 | AF10: 9.5368 | AG10: 45477 | AH10: 0.97311343 | AI10: 0 | AJ10: 0 | AK10: 0 | AL10: 0 | AM10: 0 | AN10: 0 | AO10: 0 | AP10: 0 | AQ10: 0 | AR10: 0 | AS10: 0 | AT10: 0 | AU10: =AU9 -> 9.54286
A11: 2 | B11: WR00L2L2 | C11: 27520 | D11: 32 | E11: 1 | F11: 16 | G11: 1619.71 | H11: 8.5793 | I11: 45482 | J11: 0.94396991 | K11: 0 | L11: 0 | M11: 0 | N11: 0 | O11: 0 | P11: 0 | Q11: 0 | R11: 0 | S11: 0 | T11: 0 | U11: 0 | V11: 0 | W11: =W10 -> 8.58208 | Y11: 2 | Z11: WR00L2L2 | AA11: 27520 | AB11: 32 | AC11: 1 | AD11: 16 | AE11: 1455.66 | AF11: 9.5462 | AG11: 45478 | AH11: 0.48377315 | AI11: 0 | AJ11: 0 | AK11: 0 | AL11: 0 | AM11: 0 | AN11: 0 | AO11: 0 | AP11: 0 | AQ11: 0 | AR11: 0 | AS11: 0 | AT11: 0 | AU11: =AU10 -> 9.54286
A12: 3 | B12: WR00L2L2 | C12: 27520 | D12: 32 | E12: 1 | F12: 16 | G12: 1619.43 | H12: 8.5808 | I12: 45483 | J12: 0.46905093 | K12: 0 | L12: 0 | M12: 0 | N12: 0 | O12: 0 | P12: 0 | Q12: 0 | R12: 0 | S12: 0 | T12: 0 | U12: 0 | V12: 0 | W12: =W11 -> 8.58208 | Y12: 3 | Z12: WR00L2L2 | AA12: 27520 | AB12: 32 | AC12: 1 | AD12: 16 | AE12: 1456.75 | AF12: 9.539 | AG12: 45478 | AH12: 0.99439815 | AI12: 0 | AJ12: 0 | AK12: 0 | AL12: 0 | AM12: 0 | AN12: 0 | AO12: 0 | AP12: 0 | AQ12: 0 | AR12: 0 | AS12: 0 | AT12: 0 | AU12: =AU11 -> 9.54286
A13: 4 | B13: WR00L2L2 | C13: 27520 | D13: 32 | E13: 1 | F13: 16 | G13: 1618.21 | H13: 8.5873 | I13: 45477 | J13: 0.88393519 | K13: 0 | L13: 0 | M13: 0 | N13: 0 | O13: 0 | P13: 0 | Q13: 0 | R13: 0 | S13: 0 | T13: 0 | U13: 0 | V13: 0 | W13: =W12 -> 8.58208 | Y13: 4 | Z13: WR00L2L2 | AA13: 27520 | AB13: 32 | AC13: 1 | AD13: 16 | AE13: 1456.21 | AF13: 9.5426 | AG13: 45479 | AH13: 0.50518519 | AI13: 0 | AJ13: 0 | AK13: 0 | AL13: 0 | AM13: 0 | AN13: 0 | AO13: 0 | AP13: 0 | AQ13: 0 | AR13: 0 | AS13: 0 | AT13: 0 | AU13: =AU12 -> 9.54286
A14: 0 | B14: WR00L2L2 | C14: 29056 | D14: 32 | E14: 1 | F14: 16 | G14: 1893.24 | H14: 8.6386 | I14: 45482 | J14: 0.20321759 | K14: 0 | L14: 0 | M14: 0 | N14: 0 | O14: 0 | P14: 0 | Q14: 0 | R14: 0 | S14: 0 | T14: 0 | U14: 0 | V14: 0 | W14: =AVERAGE(H14:H18) -> 8.64986 | Y14: 0 | Z14: WR00L2L2 | AA14: 29056 | AB14: 32 | AC14: 1 | AD14: 16 | AE14: 1706.21 | AF14: 9.5856 | AG14: 45477 | AH14: 0.77922454 | AI14: 0 | AJ14: 0 | AK14: 0 | AL14: 0 | AM14: 0 | AN14: 0 | AO14: 0 | AP14: 0 | AQ14: 0 | AR14: 0 | AS14: 0 | AT14: 0 | AU14: =AVERAGE(AF14:AF18) -> 9.58884
A15: 1 | B15: WR00L2L2 | C15: 29056 | D15: 32 | E15: 1 | F15: 16 | G15: 1890.13 | H15: 8.6528 | I15: 45482 | J15: 0.74396991 | K15: 0 | L15: 0 | M15: 0 | N15: 0 | O15: 0 | P15: 0 | Q15: 0 | R15: 0 | S15: 0 | T15: 0 | U15: 0 | V15: 0 | W15: =W14 -> 8.64986 | Y15: 1 | Z15: WR00L2L2 | AA15: 29056 | AB15: 32 | AC15: 1 | AD15: 16 | AE15: 1705.62 | AF15: 9.5889 | AG15: 45478 | AH15: 0.28994213 | AI15: 0 | AJ15: 0 | AK15: 0 | AL15: 0 | AM15: 0 | AN15: 0 | AO15: 0 | AP15: 0 | AQ15: 0 | AR15: 0 | AS15: 0 | AT15: 0 | AU15: =AU14 -> 9.58884
A16: 2 | B16: WR00L2L2 | C16: 29056 | D16: 32 | E16: 1 | F16: 16 | G16: 1892.69 | H16: 8.6411 | I16: 45483 | J16: 0.2691088 | K16: 0 | L16: 0 | M16: 0 | N16: 0 | O16: 0 | P16: 0 | Q16: 0 | R16: 0 | S16: 0 | T16: 0 | U16: 0 | V16: 0 | W16: =W15 -> 8.64986 | Y16: 2 | Z16: WR00L2L2 | AA16: 29056 | AB16: 32 | AC16: 1 | AD16: 16 | AE16: 1705.29 | AF16: 9.5907 | AG16: 45478 | AH16: 0.8006713 | AI16: 0 | AJ16: 0 | AK16: 0 | AL16: 0 | AM16: 0 | AN16: 0 | AO16: 0 | AP16: 0 | AQ16: 0 | AR16: 0 | AS16: 0 | AT16: 0 | AU16: =AU15 -> 9.58884
A17: 3 | B17: WR00L2L2 | C17: 29056 | D17: 32 | E17: 1 | F17: 16 | G17: 1889.85 | H17: 8.6541 | I17: 45477 | J17: 0.68400463 | K17: 0 | L17: 0 | M17: 0 | N17: 0 | O17: 0 | P17: 0 | Q17: 0 | R17: 0 | S17: 0 | T17: 0 | U17: 0 | V17: 0 | W17: =W16 -> 8.64986 | Y17: 3 | Z17: WR00L2L2 | AA17: 29056 | AB17: 32 | AC17: 1 | AD17: 16 | AE17: 1704.89 | AF17: 9.593 | AG17: 45479 | AH17: 0.31133102 | AI17: 0 | AJ17: 0 | AK17: 0 | AL17: 0 | AM17: 0 | AN17: 0 | AO17: 0 | AP17: 0 | AQ17: 0 | AR17: 0 | AS17: 0 | AT17: 0 | AU17: =AU16 -> 9.58884
A18: 4 | B18: WR00L2L2 | C18: 29056 | D18: 32 | E18: 1 | F18: 16 | G18: 1887.97 | H18: 8.6627 | I18: 45477 | J18: 0.57290509 | K18: 0 | L18: 0 | M18: 0 | N18: 0 | O18: 0 | P18: 0 | Q18: 0 | R18: 0 | S18: 0 | T18: 0 | U18: 0 | V18: 0 | W18: =W17 -> 8.64986 | Y18: 4 | Z18: WR00L2L2 | AA18: 29056 | AB18: 32 | AC18: 1 | AD18: 16 | AE18: 1706.14 | AF18: 9.586 | AG18: 45479 | AH18: 0.82206019 | AI18: 0 | AJ18: 0 | AK18: 0 | AL18: 0 | AM18: 0 | AN18: 0 | AO18: 0 | AP18: 0 | AQ18: 0 | AR18: 0 | AS18: 0 | AT18: 0 | AU18: =AU17 -> 9.58884
A19: 0 | B19: WR00L2L2 | C19: 25984 | D19: 32 | E19: 2 | F19: 8 | G19: 1341.13 | H19: 8.7215 | I19: 45482 | J19: 0.065358796 | K19: 0 | L19: 0 | M19: 0 | N19: 0 | O19: 0 | P19: 0 | Q19: 0 | R19: 0 | S19: 0 | T19: 0 | U19: 0 | V19: 0 | W19: =AVERAGE(H19:H23) -> 8.72676 | Y19: 0 | Z19: WR00L2L2 | AA19: 25984 | AB19: 32 | AC19: 2 | AD19: 8 | AE19: 1221.44 | AF19: 9.5762 | AG19: 45477 | AH19: 0.64405093 | AI19: 0 | AJ19: 0 | AK19: 0 | AL19: 0 | AM19: 0 | AN19: 0 | AO19: 0 | AP19: 0 | AQ19: 0 | AR19: 0 | AS19: 0 | AT19: 0 | AU19: =AVERAGE(AF19:AF23) -> 9.57026
A20: 1 | B20: WR00L2L2 | C20: 25984 | D20: 32 | E20: 2 | F20: 8 | G20: 1340.29 | H20: 8.727 | I20: 45482 | J20: 0.57453704 | K20: 0 | L20: 0 | M20: 0 | N20: 0 | O20: 0 | P20: 0 | Q20: 0 | R20: 0 | S20: 0 | T20: 0 | U20: 0 | V20: 0 | W20: =W19 -> 8.72676 | Y20: 1 | Z20: WR00L2L2 | AA20: 25984 | AB20: 32 | AC20: 2 | AD20: 8 | AE20: 1222.38 | AF20: 9.5688 | AG20: 45478 | AH20: 0.1547338 | AI20: 0 | AJ20: 0 | AK20: 0 | AL20: 0 | AM20: 0 | AN20: 0 | AO20: 0 | AP20: 0 | AQ20: 0 | AR20: 0 | AS20: 0 | AT20: 0 | AU20: =AU19 -> 9.57026
A21: 2 | B21: WR00L2L2 | C21: 25984 | D21: 32 | E21: 2 | F21: 8 | G21: 1341.31 | H21: 8.7203 | I21: 45483 | J21: 0.13121528 | K21: 0 | L21: 0 | M21: 0 | N21: 0 | O21: 0 | P21: 0 | Q21: 0 | R21: 0 | S21: 0 | T21: 0 | U21: 0 | V21: 0 | W21: =W20 -> 8.72676 | Y21: 2 | Z21: WR00L2L2 | AA21: 25984 | AB21: 32 | AC21: 2 | AD21: 8 | AE21: 1221.92 | AF21: 9.5724 | AG21: 45478 | AH21: 0.66546296 | AI21: 0 | AJ21: 0 | AK21: 0 | AL21: 0 | AM21: 0 | AN21: 0 | AO21: 0 | AP21: 0 | AQ21: 0 | AR21: 0 | AS21: 0 | AT21: 0 | AU21: =AU20 -> 9.57026
A22: 3 | B22: WR00L2L2 | C22: 25984 | D22: 32 | E22: 2 | F22: 8 | G22: 1339.78 | H22: 8.7303 | I22: 45477 | J22: 0.54622685 | K22: 0 | L22: 0 | M22: 0 | N22: 0 | O22: 0 | P22: 0 | Q22: 0 | R22: 0 | S22: 0 | T22: 0 | U22: 0 | V22: 0 | W22: =W21 -> 8.72676 | Y22: 3 | Z22: WR00L2L2 | AA22: 25984 | AB22: 32 | AC22: 2 | AD22: 8 | AE22: 1222.69 | AF22: 9.5664 | AG22: 45479 | AH22: 0.17601852 | AI22: 0 | AJ22: 0 | AK22: 0 | AL22: 0 | AM22: 0 | AN22: 0 | AO22: 0 | AP22: 0 | AQ22: 0 | AR22: 0 | AS22: 0 | AT22: 0 | AU22: =AU21 -> 9.57026
A23: 4 | B23: WR00L2L2 | C23: 25984 | D23: 32 | E23: 2 | F23: 8 | G23: 1339.11 | H23: 8.7347 | I23: 45477 | J23: 0.43521991 | K23: 0 | L23: 0 | M23: 0 | N23: 0 | O23: 0 | P23: 0 | Q23: 0 | R23: 0 | S23: 0 | T23: 0 | U23: 0 | V23: 0 | W23: =W22 -> 8.72676 | Y23: 4 | Z23: WR00L2L2 | AA23: 25984 | AB23: 32 | AC23: 2 | AD23: 8 | AE23: 1222.55 | AF23: 9.5675 | AG23: 45479 | AH23: 0.68678241 | AI23: 0 | AJ23: 0 | AK23: 0 | AL23: 0 | AM23: 0 | AN23: 0 | AO23: 0 | AP23: 0 | AQ23: 0 | AR23: 0 | AS23: 0 | AT23: 0 | AU23: =AU22 -> 9.57026
A24: 0 | B24: WR00L2L2 | C24: 27520 | D24: 32 | E24: 2 | F24: 8 | G24: 1588.02 | H24: 8.7505 | I24: 45481 | J24: 0.8968287 | K24: 0 | L24: 0 | M24: 0 | N24: 0 | O24: 0 | P24: 0 | Q24: 0 | R24: 0 | S24: 0 | T24: 0 | U24: 0 | V24: 0 | W24: =AVERAGE(H24:H28) -> 8.7489 | Y24: 0 | Z24: WR00L2L2 | AA24: 27520 | AB24: 32 | AC24: 2 | AD24: 8 | AE24: 1443.25 | AF24: 9.6282 | AG24: 45477 | AH24: 0.48078704 | AI24: 0 | AJ24: 0 | AK24: 0 | AL24: 0 | AM24: 0 | AN24: 0 | AO24: 0 | AP24: 0 | AQ24: 0 | AR24: 0 | AS24: 0 | AT24: 0 | AU24: =AVERAGE(AF24:AF28) -> 9.61962
A25: 1 | B25: WR00L2L2 | C25: 27520 | D25: 32 | E25: 2 | F25: 8 | G25: 1589.06 | H25: 8.7448 | I25: 45482 | J25: 0.68856481 | K25: 0 | L25: 0 | M25: 0 | N25: 0 | O25: 0 | P25: 0 | Q25: 0 | R25: 0 | S25: 0 | T25: 0 | U25: 0 | V25: 0 | W25: =W24 -> 8.7489 | Y25: 1 | Z25: WR00L2L2 | AA25: 27520 | AB25: 32 | AC25: 2 | AD25: 8 | AE25: 1444.98 | AF25: 9.6167 | AG25: 45477 | AH25: 0.99135417 | AI25: 0 | AJ25: 0 | AK25: 0 | AL25: 0 | AM25: 0 | AN25: 0 | AO25: 0 | AP25: 0 | AQ25: 0 | AR25: 0 | AS25: 0 | AT25: 0 | AU25: =AU24 -> 9.61962
A26: 2 | B26: WR00L2L2 | C26: 27520 | D26: 32 | E26: 2 | F26: 8 | G26: 1588.56 | H26: 8.7476 | I26: 45482 | J26: 0.96270833 | K26: 0 | L26: 0 | M26: 0 | N26: 0 | O26: 0 | P26: 0 | Q26: 0 | R26: 0 | S26: 0 | T26: 0 | U26: 0 | V26: 0 | W26: =W25 -> 8.7489 | Y26: 2 | Z26: WR00L2L2 | AA26: 27520 | AB26: 32 | AC26: 2 | AD26: 8 | AE26: 1445.18 | AF26: 9.6154 | AG26: 45478 | AH26: 0.50202546 | AI26: 0 | AJ26: 0 | AK26: 0 | AL26: 0 | AM26: 0 | AN26: 0 | AO26: 0 | AP26: 0 | AQ26: 0 | AR26: 0 | AS26: 0 | AT26: 0 | AU26: =AU25 -> 9.61962
A27: 3 | B27: WR00L2L2 | C27: 27520 | D27: 32 | E27: 2 | F27: 8 | G27: 1588.82 | H27: 8.7461 | I27: 45483 | J27: 0.48778935 | K27: 0 | L27: 0 | M27: 0 | N27: 0 | O27: 0 | P27: 0 | Q27: 0 | R27: 0 | S27: 0 | T27: 0 | U27: 0 | V27: 0 | W27: =W26 -> 8.7489 | Y27: 3 | Z27: WR00L2L2 | AA27: 27520 | AB27: 32 | AC27: 2 | AD27: 8 | AE27: 1444.42 | AF27: 9.6205 | AG27: 45479 | AH27: 0.012638889 | AI27: 0 | AJ27: 0 | AK27: 0 | AL27: 0 | AM27: 0 | AN27: 0 | AO27: 0 | AP27: 0 | AQ27: 0 | AR27: 0 | AS27: 0 | AT27: 0 | AU27: =AU26 -> 9.61962
A28: 4 | B28: WR00L2L2 | C28: 27520 | D28: 32 | E28: 2 | F28: 8 | G28: 1587.11 | H28: 8.7555 | I28: 45477 | J28: 0.90266204 | K28: 0 | L28: 0 | M28: 0 | N28: 0 | O28: 0 | P28: 0 | Q28: 0 | R28: 0 | S28: 0 | T28: 0 | U28: 0 | V28: 0 | W28: =W27 -> 8.7489 | Y28: 4 | Z28: WR00L2L2 | AA28: 27520 | AB28: 32 | AC28: 2 | AD28: 8 | AE28: 1444.9 | AF28: 9.6173 | AG28: 45479 | AH28: 0.52342593 | AI28: 0 | AJ28: 0 | AK28: 0 | AL28: 0 | AM28: 0 | AN28: 0 | AO28: 0 | AP28: 0 | AQ28: 0 | AR28: 0 | AS28: 0 | AT28: 0 | AU28: =AU27 -> 9.61962
A29: 0 | B29: WR00L2L2 | C29: 29056 | D29: 32 | E29: 2 | F29: 8 | G29: 1861.95 | H29: 8.7838 | I29: 45482 | J29: 0.22516204 | K29: 0 | L29: 0 | M29: 0 | N29: 0 | O29: 0 | P29: 0 | Q29: 0 | R29: 0 | S29: 0 | T29: 0 | U29: 0 | V29: 0 | W29: =AVERAGE(H29:H33) -> 8.78732 | Y29: 0 | Z29: WR00L2L2 | AA29: 29056 | AB29: 32 | AC29: 2 | AD29: 8 | AE29: 1692.5 | AF29: 9.6632 | AG29: 45477 | AH29: 0.80050926 | AI29: 0 | AJ29: 0 | AK29: 0 | AL29: 0 | AM29: 0 | AN29: 0 | AO29: 0 | AP29: 0 | AQ29: 0 | AR29: 0 | AS29: 0 | AT29: 0 | AU29: =AVERAGE(AF29:AF33) -> 9.65866
A30: 1 | B30: WR00L2L2 | C30: 29056 | D30: 32 | E30: 2 | F30: 8 | G30: 1861.49 | H30: 8.7859 | I30: 45482 | J30: 0.76590278 | K30: 0 | L30: 0 | M30: 0 | N30: 0 | O30: 0 | P30: 0 | Q30: 0 | R30: 0 | S30: 0 | T30: 0 | U30: 0 | V30: 0 | W30: =W29 -> 8.78732 | Y30: 1 | Z30: WR00L2L2 | AA30: 29056 | AB30: 32 | AC30: 2 | AD30: 8 | AE30: 1693.46 | AF30: 9.6577 | AG30: 45478 | AH30: 0.31123843 | AI30: 0 | AJ30: 0 | AK30: 0 | AL30: 0 | AM30: 0 | AN30: 0 | AO30: 0 | AP30: 0 | AQ30: 0 | AR30: 0 | AS30: 0 | AT30: 0 | AU30: =AU29 -> 9.65866
A31: 2 | B31: WR00L2L2 | C31: 29056 | D31: 32 | E31: 2 | F31: 8 | G31: 1863.24 | H31: 8.7777 | I31: 45483 | J31: 0.29106481 | K31: 0 | L31: 0 | M31: 0 | N31: 0 | O31: 0 | P31: 0 | Q31: 0 | R31: 0 | S31: 0 | T31: 0 | U31: 0 | V31: 0 | W31: =W30 -> 8.78732 | Y31: 2 | Z31: WR00L2L2 | AA31: 29056 | AB31: 32 | AC31: 2 | AD31: 8 | AE31: 1692.53 | AF31: 9.663 | AG31: 45478 | AH31: 0.82195602 | AI31: 0 | AJ31: 0 | AK31: 0 | AL31: 0 | AM31: 0 | AN31: 0 | AO31: 0 | AP31: 0 | AQ31: 0 | AR31: 0 | AS31: 0 | AT31: 0 | AU31: =AU30 -> 9.65866
A32: 3 | B32: WR00L2L2 | C32: 29056 | D32: 32 | E32: 2 | F32: 8 | G32: 1860.64 | H32: 8.79 | I32: 45477 | J32: 0.70592593 | K32: 0 | L32: 0 | M32: 0 | N32: 0 | O32: 0 | P32: 0 | Q32: 0 | R32: 0 | S32: 0 | T32: 0 | U32: 0 | V32: 0 | W32: =W31 -> 8.78732 | Y32: 3 | Z32: WR00L2L2 | AA32: 29056 | AB32: 32 | AC32: 2 | AD32: 8 | AE32: 1694.07 | AF32: 9.6542 | AG32: 45479 | AH32: 0.33262731 | AI32: 0 | AJ32: 0 | AK32: 0 | AL32: 0 | AM32: 0 | AN32: 0 | AO32: 0 | AP32: 0 | AQ32: 0 | AR32: 0 | AS32: 0 | AT32: 0 | AU32: =AU31 -> 9.65866
A33: 4 | B33: WR00L2L2 | C33: 29056 | D33: 32 | E33: 2 | F33: 8 | G33: 1858.68 | H33: 8.7992 | I33: 45477 | J33: 0.59480324 | K33: 0 | L33: 0 | M33: 0 | N33: 0 | O33: 0 | P33: 0 | Q33: 0 | R33: 0 | S33: 0 | T33: 0 | U33: 0 | V33: 0 | W33: =W32 -> 8.78732 | Y33: 4 | Z33: WR00L2L2 | AA33: 29056 | AB33: 32 | AC33: 2 | AD33: 8 | AE33: 1693.89 | AF33: 9.6552 | AG33: 45479 | AH33: 0.84335648 | AI33: 0 | AJ33: 0 | AK33: 0 | AL33: 0 | AM33: 0 | AN33: 0 | AO33: 0 | AP33: 0 | AQ33: 0 | AR33: 0 | AS33: 0 | AT33: 0 | AU33: =AU32 -> 9.65866
A34: 0 | B34: WR00L2L2 | C34: 25984 | D34: 32 | E34: 4 | F34: 4 | G34: 1355.23 | H34: 8.6308 | I34: 45482 | J34: 0.081365741 | K34: 0 | L34: 0 | M34: 0 | N34: 0 | O34: 0 | P34: 0 | Q34: 0 | R34: 0 | S34: 0 | T34: 0 | U34: 0 | V34: 0 | W34: =AVERAGE(H34:H38) -> 8.6367 | Y34: 0 | Z34: WR00L2L2 | AA34: 25984 | AB34: 32 | AC34: 4 | AD34: 4 | AE34: 1240.42 | AF34: 9.4297 | AG34: 45477 | AH34: 0.65975694 | AI34: 0 | AJ34: 0 | AK34: 0 | AL34: 0 | AM34: 0 | AN34: 0 | AO34: 0 | AP34: 0 | AQ34: 0 | AR34: 0 | AS34: 0 | AT34: 0 | AU34: =AVERAGE(AF34:AF38) -> 9.43108
A35: 1 | B35: WR00L2L2 | C35: 25984 | D35: 32 | E35: 4 | F35: 4 | G35: 1353.64 | H35: 8.641 | I35: 45482 | J35: 0.59052083 | K35: 0 | L35: 0 | M35: 0 | N35: 0 | O35: 0 | P35: 0 | Q35: 0 | R35: 0 | S35: 0 | T35: 0 | U35: 0 | V35: 0 | W35: =W34 -> 8.6367 | Y35: 1 | Z35: WR00L2L2 | AA35: 25984 | AB35: 32 | AC35: 4 | AD35: 4 | AE35: 1239.3 | AF35: 9.4382 | AG35: 45478 | AH35: 0.17043981 | AI35: 0 | AJ35: 0 | AK35: 0 | AL35: 0 | AM35: 0 | AN35: 0 | AO35: 0 | AP35: 0 | AQ35: 0 | AR35: 0 | AS35: 0 | AT35: 0 | AU35: =AU34 -> 9.43108
A36: 2 | B36: WR00L2L2 | C36: 25984 | D36: 32 | E36: 4 | F36: 4 | G36: 1355.9 | H36: 8.6265 | I36: 45483 | J36: 0.14722222 | K36: 0 | L36: 0 | M36: 0 | N36: 0 | O36: 0 | P36: 0 | Q36: 0 | R36: 0 | S36: 0 | T36: 0 | U36: 0 | V36: 0 | W36: =W35 -> 8.6367 | Y36: 2 | Z36: WR00L2L2 | AA36: 25984 | AB36: 32 | AC36: 4 | AD36: 4 | AE36: 1239.19 | AF36: 9.439 | AG36: 45478 | AH36: 0.68115741 | AI36: 0 | AJ36: 0 | AK36: 0 | AL36: 0 | AM36: 0 | AN36: 0 | AO36: 0 | AP36: 0 | AQ36: 0 | AR36: 0 | AS36: 0 | AT36: 0 | AU36: =AU35 -> 9.43108
A37: 3 | B37: WR00L2L2 | C37: 25984 | D37: 32 | E37: 4 | F37: 4 | G37: 1354.4 | H37: 8.6361 | I37: 45477 | J37: 0.56222222 | K37: 0 | L37: 0 | M37: 0 | N37: 0 | O37: 0 | P37: 0 | Q37: 0 | R37: 0 | S37: 0 | T37: 0 | U37: 0 | V37: 0 | W37: =W36 -> 8.6367 | Y37: 3 | Z37: WR00L2L2 | AA37: 25984 | AB37: 32 | AC37: 4 | AD37: 4 | AE37: 1241.24 | AF37: 9.4234 | AG37: 45479 | AH37: 0.19174769 | AI37: 0 | AJ37: 0 | AK37: 0 | AL37: 0 | AM37: 0 | AN37: 0 | AO37: 0 | AP37: 0 | AQ37: 0 | AR37: 0 | AS37: 0 | AT37: 0 | AU37: =AU36 -> 9.43108
A38: 4 | B38: WR00L2L2 | C38: 25984 | D38: 32 | E38: 4 | F38: 4 | G38: 1352.37 | H38: 8.6491 | I38: 45477 | J38: 0.45119213 | K38: 0 | L38: 0 | M38: 0 | N38: 0 | O38: 0 | P38: 0 | Q38: 0 | R38: 0 | S38: 0 | T38: 0 | U38: 0 | V38: 0 | W38: =W37 -> 8.6367 | Y38: 4 | Z38: WR00L2L2 | AA38: 25984 | AB38: 32 | AC38: 4 | AD38: 4 | AE38: 1241.02 | AF38: 9.4251 | AG38: 45479 | AH38: 0.7025 | AI38: 0 | AJ38: 0 | AK38: 0 | AL38: 0 | AM38: 0 | AN38: 0 | AO38: 0 | AP38: 0 | AQ38: 0 | AR38: 0 | AS38: 0 | AT38: 0 | AU38: =AU37 -> 9.43108
A39: 0 | B39: WR00L2L2 | C39: 27520 | D39: 32 | E39: 4 | F39: 4 | G39: 1600.51 | H39: 8.6822 | I39: 45481 | J39: 0.91570602 | K39: 0 | L39: 0 | M39: 0 | N39: 0 | O39: 0 | P39: 0 | Q39: 0 | R39: 0 | S39: 0 | T39: 0 | U39: 0 | V39: 0 | W39: =AVERAGE(H39:H43) -> 8.68562 | Y39: 0 | Z39: WR00L2L2 | AA39: 27520 | AB39: 32 | AC39: 4 | AD39: 4 | AE39: 1464.26 | AF39: 9.4901 | AG39: 45477 | AH39: 0.49923611 | AI39: 0 | AJ39: 0 | AK39: 0 | AL39: 0 | AM39: 0 | AN39: 0 | AO39: 0 | AP39: 0 | AQ39: 0 | AR39: 0 | AS39: 0 | AT39: 0 | AU39: =AVERAGE(AF39:AF43) -> 9.48626
A40: 1 | B40: WR00L2L2 | C40: 27520 | D40: 32 | E40: 4 | F40: 4 | G40: 1600.02 | H40: 8.6849 | I40: 45482 | J40: 0.42488426 | K40: 0 | L40: 0 | M40: 0 | N40: 0 | O40: 0 | P40: 0 | Q40: 0 | R40: 0 | S40: 0 | T40: 0 | U40: 0 | V40: 0 | W40: =W39 -> 8.68562 | Y40: 1 | Z40: WR00L2L2 | AA40: 27520 | AB40: 32 | AC40: 4 | AD40: 4 | AE40: 1464.5 | AF40: 9.4886 | AG40: 45478 | AH40: 0.0098263889 | AI40: 0 | AJ40: 0 | AK40: 0 | AL40: 0 | AM40: 0 | AN40: 0 | AO40: 0 | AP40: 0 | AQ40: 0 | AR40: 0 | AS40: 0 | AT40: 0 | AU40: =AU39 -> 9.48626
...

Sheet 933 params
B1: ATLAS - small | I1: OpenBLAS
B2: =INDEX(B4:B500,MATCH(MAX(F4:F500),F4:F500,0)) -> 28992 | C2: =INDEX(C4:C500,MATCH(MAX(F4:F500),F4:F500,0)) -> 96 | D2: =INDEX(D4:D500,MATCH(MAX(F4:F500),F4:F500,0)) -> 2 | E2: =INDEX(E4:E500,MATCH(MAX(F4:F500),F4:F500,0)) -> 8 | F2: =MAX(F4:F500) -> 9.02122 | I2: =INDEX(I4:I500,MATCH(MAX(M4:M500),M4:M500,0)) -> 29056 | J2: =INDEX(J4:J500,MATCH(MAX(M4:M500),M4:M500,0)) -> 64 | K2: =INDEX(K4:K500,MATCH(MAX(M4:M500),M4:M500,0)) -> 2 | L2: =INDEX(L4:L500,MATCH(MAX(M4:M500),M4:M500,0)) -> 8 | M2: =MAX(M4:M500) -> 10.039
A3: N (round) | B3: N | C3: NB | D3: P | E3: Q | F3: Average GFLOP/s | H3: N (round) | I3: N | J3: NB | K3: P | L3: Q | M3: Average GFLOP/s
A4: =CHOOSE(IF(ABS(B4-25984) <= ABS(B4-27520),IF(ABS(B4-25984) <= ABS(B4-29056),1,3),IF(ABS(B4-27520) <= ABS(B4-29056),2,3)),25984,27520,29056) -> 25984 | B4: {=_xlfn.CHOOSECOLS(_xlfn._xlws.FILTER('933 params, RAW'!A4:W410,'933 params, RAW'!A4:A410=0),3,4,5,6,23)} -> 25984 | C4: 32 | D4: 1 | E4: 16 | F4: 8.57764 | H4: =CHOOSE(IF(ABS(I4-25984) <= ABS(I4-27520),IF(ABS(I4-25984) <= ABS(I4-29056),1,3),IF(ABS(I4-27520) <= ABS(I4-29056),2,3)),25984,27520,29056) -> 25984 | I4: {=_xlfn.CHOOSECOLS(_xlfn._xlws.FILTER('933 params, RAW'!Y4:AU500,'933 params, RAW'!Y4:Y500=0),3,4,5,6,23)} -> 25984 | J4: 32 | K4: 1 | L4: 16 | M4: 9.51508
A5: =CHOOSE(IF(ABS(B5-25984) <= ABS(B5-27520),IF(ABS(B5-25984) <= ABS(B5-29056),1,3),IF(ABS(B5-27520) <= ABS(B5-29056),2,3)),25984,27520,29056) -> 27520 | B5: 27520 | C5: 32 | D5: 1 | E5: 16 | F5: 8.58208 | H5: =CHOOSE(IF(ABS(I5-25984) <= ABS(I5-27520),IF(ABS(I5-25984) <= ABS(I5-29056),1,3),IF(ABS(I5-27520) <= ABS(I5-29056),2,3)),25984,27520,29056) -> 27520 | I5: 27520 | J5: 32 | K5: 1 | L5: 16 | M5: 9.54286
A6: =CHOOSE(IF(ABS(B6-25984) <= ABS(B6-27520),IF(ABS(B6-25984) <= ABS(B6-29056),1,3),IF(ABS(B6-27520) <= ABS(B6-29056),2,3)),25984,27520,29056) -> 29056 | B6: 29056 | C6: 32 | D6: 1 | E6: 16 | F6: 8.64986 | H6: =CHOOSE(IF(ABS(I6-25984) <= ABS(I6-27520),IF(ABS(I6-25984) <= ABS(I6-29056),1,3),IF(ABS(I6-27520) <= ABS(I6-29056),2,3)),25984,27520,29056) -> 29056 | I6: 29056 | J6: 32 | K6: 1 | L6: 16 | M6: 9.58884
A7: =CHOOSE(IF(ABS(B7-25984) <= ABS(B7-27520),IF(ABS(B7-25984) <= ABS(B7-29056),1,3),IF(ABS(B7-27520) <= ABS(B7-29056),2,3)),25984,27520,29056) -> 25984 | B7: 25984 | C7: 32 | D7: 2 | E7: 8 | F7: 8.72676 | H7: =CHOOSE(IF(ABS(I7-25984) <= ABS(I7-27520),IF(ABS(I7-25984) <= ABS(I7-29056),1,3),IF(ABS(I7-27520) <= ABS(I7-29056),2,3)),25984,27520,29056) -> 25984 | I7: 25984 | J7: 32 | K7: 2 | L7: 8 | M7: 9.57026
A8: =CHOOSE(IF(ABS(B8-25984) <= ABS(B8-27520),IF(ABS(B8-25984) <= ABS(B8-29056),1,3),IF(ABS(B8-27520) <= ABS(B8-29056),2,3)),25984,27520,29056) -> 27520 | B8: 27520 | C8: 32 | D8: 2 | E8: 8 | F8: 8.7489 | H8: =CHOOSE(IF(ABS(I8-25984) <= ABS(I8-27520),IF(ABS(I8-25984) <= ABS(I8-29056),1,3),IF(ABS(I8-27520) <= ABS(I8-29056),2,3)),25984,27520,29056) -> 27520 | I8: 27520 | J8: 32 | K8: 2 | L8: 8 | M8: 9.61962
A9: =CHOOSE(IF(ABS(B9-25984) <= ABS(B9-27520),IF(ABS(B9-25984) <= ABS(B9-29056),1,3),IF(ABS(B9-27520) <= ABS(B9-29056),2,3)),25984,27520,29056) -> 29056 | B9: 29056 | C9: 32 | D9: 2 | E9: 8 | F9: 8.78732 | H9: =CHOOSE(IF(ABS(I9-25984) <= ABS(I9-27520),IF(ABS(I9-25984) <= ABS(I9-29056),1,3),IF(ABS(I9-27520) <= ABS(I9-29056),2,3)),25984,27520,29056) -> 29056 | I9: 29056 | J9: 32 | K9: 2 | L9: 8 | M9: 9.65866
A10: =CHOOSE(IF(ABS(B10-25984) <= ABS(B10-27520),IF(ABS(B10-25984) <= ABS(B10-29056),1,3),IF(ABS(B10-27520) <= ABS(B10-29056),2,3)),25984,27520,29056) -> 25984 | B10: 25984 | C10: 32 | D10: 4 | E10: 4 | F10: 8.6367 | H10: =CHOOSE(IF(ABS(I10-25984) <= ABS(I10-27520),IF(ABS(I10-25984) <= ABS(I10-29056),1,3),IF(ABS(I10-27520) <= ABS(I10-29056),2,3)),25984,27520,29056) -> 25984 | I10: 25984 | J10: 32 | K10: 4 | L10: 4 | M10: 9.43108
A11: =CHOOSE(IF(ABS(B11-25984) <= ABS(B11-27520),IF(ABS(B11-25984) <= ABS(B11-29056),1,3),IF(ABS(B11-27520) <= ABS(B11-29056),2,3)),25984,27520,29056) -> 27520 | B11: 27520 | C11: 32 | D11: 4 | E11: 4 | F11: 8.68562 | H11: =CHOOSE(IF(ABS(I11-25984) <= ABS(I11-27520),IF(ABS(I11-25984) <= ABS(I11-29056),1,3),IF(ABS(I11-27520) <= ABS(I11-29056),2,3)),25984,27520,29056) -> 27520 | I11: 27520 | J11: 32 | K11: 4 | L11: 4 | M11: 9.48626
A12: =CHOOSE(IF(ABS(B12-25984) <= ABS(B12-27520),IF(ABS(B12-25984) <= ABS(B12-29056),1,3),IF(ABS(B12-27520) <= ABS(B12-29056),2,3)),25984,27520,29056) -> 29056 | B12: 29056 | C12: 32 | D12: 4 | E12: 4 | F12: 8.72512 | H12: =CHOOSE(IF(ABS(I12-25984) <= ABS(I12-27520),IF(ABS(I12-25984) <= ABS(I12-29056),1,3),IF(ABS(I12-27520) <= ABS(I12-29056),2,3)),25984,27520,29056) -> 29056 | I12: 29056 | J12: 32 | K12: 4 | L12: 4 | M12: 9.53514
A13: =CHOOSE(IF(ABS(B13-25984) <= ABS(B13-27520),IF(ABS(B13-25984) <= ABS(B13-29056),1,3),IF(ABS(B13-27520) <= ABS(B13-29056),2,3)),25984,27520,29056) -> 25984 | B13: 25984 | C13: 64 | D13: 1 | E13: 16 | F13: 8.35836 | H13: =CHOOSE(IF(ABS(I13-25984) <= ABS(I13-27520),IF(ABS(I13-25984) <= ABS(I13-29056),1,3),IF(ABS(I13-27520) <= ABS(I13-29056),2,3)),25984,27520,29056) -> 25984 | I13: 25984 | J13: 64 | K13: 1 | L13: 16 | M13: 9.7087
A14: =CHOOSE(IF(ABS(B14-25984) <= ABS(B14-27520),IF(ABS(B14-25984) <= ABS(B14-29056),1,3),IF(ABS(B14-27520) <= ABS(B14-29056),2,3)),25984,27520,29056) -> 27520 | B14: 27520 | C14: 64 | D14: 1 | E14: 16 | F14: 8.3761 | H14: =CHOOSE(IF(ABS(I14-25984) <= ABS(I14-27520),IF(ABS(I14-25984) <= ABS(I14-29056),1,3),IF(ABS(I14-27520) <= ABS(I14-29056),2,3)),25984,27520,29056) -> 27520 | I14: 27520 | J14: 64 | K14: 1 | L14: 16 | M14: 9.74818
A15: =CHOOSE(IF(ABS(B15-25984) <= ABS(B15-27520),IF(ABS(B15-25984) <= ABS(B15-29056),1,3),IF(ABS(B15-27520) <= ABS(B15-29056),2,3)),25984,27520,29056) -> 29056 | B15: 29056 | C15: 64 | D15: 1 | E15: 16 | F15: 8.45058 | H15: =CHOOSE(IF(ABS(I15-25984) <= ABS(I15-27520),IF(ABS(I15-25984) <= ABS(I15-29056),1,3),IF(ABS(I15-27520) <= ABS(I15-29056),2,3)),25984,27520,29056) -> 29056 | I15: 29056 | J15: 64 | K15: 1 | L15: 16 | M15: 9.81322
A16: =CHOOSE(IF(ABS(B16-25984) <= ABS(B16-27520),IF(ABS(B16-25984) <= ABS(B16-29056),1,3),IF(ABS(B16-27520) <= ABS(B16-29056),2,3)),25984,27520,29056) -> 25984 | B16: 25984 | C16: 64 | D16: 2 | E16: 8 | F16: 8.61652 | H16: =CHOOSE(IF(ABS(I16-25984) <= ABS(I16-27520),IF(ABS(I16-25984) <= ABS(I16-29056),1,3),IF(ABS(I16-27520) <= ABS(I16-29056),2,3)),25984,27520,29056) -> 25984 | I16: 25984 | J16: 64 | K16: 2 | L16: 8 | M16: 9.93448
... A86: =CHOOSE(IF(ABS(B86-25984) <= ABS(B86-27520),IF(ABS(B86-25984) <= ABS(B86-29056),1,3),IF(ABS(B86-27520) <= ABS(B86-29056),2,3)),25984,27520,29056) -> 25984 | B86: 0 | C86: 0 | D86: 0 | E86: 0 | F86: 0 | H86: =CHOOSE(IF(ABS(I86-25984) <= ABS(I86-27520),IF(ABS(I86-25984) <= ABS(I86-29056),1,3),IF(ABS(I86-27520) <= ABS(I86-29056),2,3)),25984,27520,29056) -> 25984 | I86: 0 | J86: 0 | K86: 0 | L86: 0 | M86: 0
H87: =CHOOSE(IF(ABS(I87-25984) <= ABS(I87-27520),IF(ABS(I87-25984) <= ABS(I87-29056),1,3),IF(ABS(I87-27520) <= ABS(I87-29056),2,3)),25984,27520,29056) -> 25984 | I87: 0 | J87: 0 | K87: 0 | L87: 0 | M87: 0
H88: =CHOOSE(IF(ABS(I88-25984) <= ABS(I88-27520),IF(ABS(I88-25984) <= ABS(I88-29056),1,3),IF(ABS(I88-27520) <= ABS(I88-29056),2,3)),25984,27520,29056) -> 25984 | I88: 0 | J88: 0 | K88: 0 | L88: 0 | M88: 0
H89: =CHOOSE(IF(ABS(I89-25984) <= ABS(I89-27520),IF(ABS(I89-25984) <= ABS(I89-29056),1,3),IF(ABS(I89-27520) <= ABS(I89-29056),2,3)),25984,27520,29056) -> 25984 | I89: 0 | J89: 0 | K89: 0 | L89: 0 | M89: 0
H90: =CHOOSE(IF(ABS(I90-25984) <= ABS(I90-27520),IF(ABS(I90-25984) <= ABS(I90-29056),1,3),IF(ABS(I90-27520) <= ABS(I90-29056),2,3)),25984,27520,29056) -> 25984 | I90: 0 | J90: 0 | K90: 0 | L90: 0 | M90: 0
H91: =CHOOSE(IF(ABS(I91-25984) <= ABS(I91-27520),IF(ABS(I91-25984) <= ABS(I91-29056),1,3),IF(ABS(I91-27520) <= ABS(I91-29056),2,3)),25984,27520,29056) -> 25984 | I91: 0 | J91: 0 | K91: 0 | L91: 0 | M91: 0
H92: =CHOOSE(IF(ABS(I92-25984) <= ABS(I92-27520),IF(ABS(I92-25984) <= ABS(I92-29056),1,3),IF(ABS(I92-27520) <= ABS(I92-29056),2,3)),25984,27520,29056) -> 25984 | I92: 0 | J92: 0 | K92: 0 | L92: 0 | M92: 0
H93: =CHOOSE(IF(ABS(I93-25984) <= ABS(I93-27520),IF(ABS(I93-25984) <= ABS(I93-29056),1,3),IF(ABS(I93-27520) <= ABS(I93-29056),2,3)),25984,27520,29056) -> 25984 | I93: 0 | J93: 0 | K93: 0 | L93: 0 | M93: 0
H94: =CHOOSE(IF(ABS(I94-25984) <= ABS(I94-27520),IF(ABS(I94-25984) <= ABS(I94-29056),1,3),IF(ABS(I94-27520) <= ABS(I94-29056),2,3)),25984,27520,29056) -> 25984 | I94: 0 | J94: 0 | K94: 0 | L94: 0 | M94: 0
H95: =CHOOSE(IF(ABS(I95-25984) <= ABS(I95-27520),IF(ABS(I95-25984) <= ABS(I95-29056),1,3),IF(ABS(I95-27520) <= ABS(I95-29056),2,3)),25984,27520,29056) -> 25984 | I95: 0 | J95: 0 | K95: 0 | L95: 0 | M95: 0
H96: =CHOOSE(IF(ABS(I96-25984) <= ABS(I96-27520),IF(ABS(I96-25984) <= ABS(I96-29056),1,3),IF(ABS(I96-27520) <= ABS(I96-29056),2,3)),25984,27520,29056) -> 25984 | I96: 0 | J96: 0 | K96: 0 | L96: 0 | M96: 0
H97: =CHOOSE(IF(ABS(I97-25984) <= ABS(I97-27520),IF(ABS(I97-25984) <= ABS(I97-29056),1,3),IF(ABS(I97-27520) <= ABS(I97-29056),2,3)),25984,27520,29056) -> 25984 | I97: 0 | J97: 0 | K97: 0 | L97: 0 | M97: 0
H98: =CHOOSE(IF(ABS(I98-25984) <= ABS(I98-27520),IF(ABS(I98-25984) <= ABS(I98-29056),1,3),IF(ABS(I98-27520) <= ABS(I98-29056),2,3)),25984,27520,29056) -> 25984 | I98: 0 | J98: 0 | K98: 0 | L98: 0 | M98: 0
... H176: =CHOOSE(IF(ABS(I176-25984) <= ABS(I176-27520),IF(ABS(I176-25984) <= ABS(I176-29056),1,3),IF(ABS(I176-27520) <= ABS(I176-29056),2,3)),25984,27520,29056) -> 25984 | I176: 0 | J176: 0 | K176: 0 | L176: 0 | M176: 0

Sheet 825 params, RAW
A1: Max avg. GFLOPS (and params): | E1: =MAX(W:W) -> 9.94182 | F1: =INDEX(C:C,MATCH(MAX($W:$W),$W:$W,0)) -> 29056 | G1: =INDEX(D:D,MATCH(MAX($W:$W),$W:$W,0)) -> 64 | H1: =INDEX(E:E,MATCH(MAX($W:$W),$W:$W,0)) -> 2 | I1: =INDEX(F:F,MATCH(MAX($W:$W),$W:$W,0)) -> 8 | L1: OpenBLAS | Y1: Max avg. GFLOPS (and params): | AC1: =MAX(AU$1:AU$430) -> 8.82502 | AD1: =INDEX(AA$1:AA$430,MATCH(MAX($AU$1:$AU$430),$AU$1:$AU$430,0)) -> 28992 | AE1: =INDEX(AB$1:AB$430,MATCH(MAX($AU$1:$AU$430),$AU$1:$AU$430,0)) -> 96 | AF1: =INDEX(AC$1:AC$430,MATCH(MAX($AU$1:$AU$430),$AU$1:$AU$430,0)) -> 4 | AG1: =INDEX(AD$1:AD$430,MATCH(MAX($AU$1:$AU$430),$AU$1:$AU$430,0)) -> 4 | AJ1: ATLAS
A2: MAX GFLOPS: | C2: =MAX(H:H) -> 9.9545 | K2: Odroid10 throttling time [1/100s] | N2: Odroid11 throttling time [1/100s] | Q2: Odroid12 throttling time [1/100s] | T2: Odroid13 throttling time [1/100s] | Y2: MAX GFLOPS: | AA2: =MAX(AF$1:AF$430) -> 8.8947 | AI2: Odroid10 throttling time [1/100s] | AL2: Odroid11 throttling time [1/100s] | AO2: Odroid12 throttling time [1/100s] | AR2: Odroid13 throttling time [1/100s]
A3: RUN | C3: N | D3: NB | E3: P | F3: Q | G3: Time | H3: GFLOPS | I3: Date | J3: Time | K3: 1700MHz | L3: 1800MHz | M3: 1900MHz | N3: 1700MHz | O3: 1800MHz | P3: 1900MHz | Q3: 1700MHz | R3: 1800MHz | S3: 1900MHz | T3: 1700MHz | U3: 1800MHz | V3: 1900MHz | Y3: RUN | AA3: N | AB3: NB | AC3: P | AD3: Q | AE3: Time | AF3: GFLOPS | AG3: Date | AH3: Time | AI3: 1700MHz | AJ3: 1800MHz | AK3: 1900MHz | AL3: 1700MHz | AM3: 1800MHz | AN3: 1900MHz | AO3: 1700MHz | AP3: 1800MHz | AQ3: 1900MHz | AR3: 1700MHz | AS3: 1800MHz | AT3: 1900MHz
A4: 0 | B4: WR00L2L2 | C4: 25984 | D4: 32 | E4: 1 | F4: 16 | G4: 1243.19 | H4: 9.4086 | I4: 45477 | J4: 0.60111111 | K4: 0 | L4: 0 | M4: 0 | N4: 0 | O4: 0 | P4: 0 | Q4: 0 | R4: 0 | S4: 0 | T4: 0 | U4: 0 | V4: 0 | W4: =AVERAGE(H4:H8) -> 9.40384 | Y4: 0 | Z4: WR00L2L2 | AA4: 25984 | AB4: 32 | AC4: 1 | AD4: 16 | AE4: 1383.64 | AF4: 8.4536 | AG4: 45477 | AH4: 0.61025463 | AI4: 0 | AJ4: 0 | AK4: 0 | AL4: 0 | AM4: 0 | AN4: 0 | AO4: 0 | AP4: 0 | AQ4: 0 | AR4: 0 | AS4: 0 | AT4: 0 | AU4: =AVERAGE(AF4:AF8) -> 8.44925
A5: 1 | B5: WR00L2L2 | C5: 25984 | D5: 32 | E5: 1 | F5: 16 | G5: 1244.56 | H5: 9.3983 | I5: 45478 | J5: 0.10706019 | K5: 0 | L5: 0 | M5: 0 | N5: 0 | O5: 0 | P5: 0 | Q5: 0 | R5: 0 | S5: 0 | T5: 0 | U5: 0 | V5: 0 | W5: =W4 -> 9.40384 | Y5: 1 | Z5: WR00L2L2 | AA5: 25984 | AB5: 32 | AC5: 1 | AD5: 16 | AE5: 1384.5 | AF5: 8.4483 | AG5: 45478 | AH5: 0.14212963 | AI5: 0 | AJ5: 0 | AK5: 0 | AL5: 0 | AM5: 0 | AN5: 0 | AO5: 0 | AP5: 0 | AQ5: 0 | AR5: 0 | AS5: 0 | AT5: 0 | AU5: =AU4 -> 8.44925
A6: 2 | B6: WR00L2L2 | C6: 25984 | D6: 32 | E6: 1 | F6: 16 | G6: 1244.12 | H6: 9.4016 | I6: 45478 | J6: 0.61311343 | K6: 0 | L6: 0 | M6: 0 | N6: 0 | O6: 0 | P6: 0 | Q6: 0 | R6: 0 | S6: 0 | T6: 0 | U6: 0 | V6: 0 | W6: =W5 -> 9.40384 | Y6: 2 | Z6: WR00L2L2 | AA6: 25984 | AB6: 32 | AC6: 1 | AD6: 16 | AE6: 1385.1 | AF6: 8.4447 | AG6: 45478 | AH6: 0.6741088 | AI6: 0 | AJ6: 0 | AK6: 0 | AL6: 0 | AM6: 0 | AN6: 0 | AO6: 0 | AP6: 0 | AQ6: 0 | AR6: 0 | AS6: 0 | AT6: 0 | AU6: =AU5 -> 8.44925
A7: 3 | B7: WR00L2L2 | C7: 25984 | D7: 32 | E7: 1 | F7: 16 | G7: 1243.53 | H7: 9.4061 | I7: 45479 | J7: 0.11931713 | K7: 0 | L7: 0 | M7: 0 | N7: 0 | O7: 0 | P7: 0 | Q7: 0 | R7: 0 | S7: 0 | T7: 0 | U7: 0 | V7: 0 | W7: =W6 -> 9.40384 | Y7: 3 | Z7: WR00L2L2 | AA7: 25984 | AB7: 32 | AC7: 1 | AD7: 16 | AE7: 1384.17 | AF7: 8.4504 | AG7: 45479 | AH7: 0.20608796 | AI7: 0 | AJ7: 0 | AK7: 0 | AL7: 0 | AM7: 0 | AN7: 0 | AO7: 0 | AP7: 0 | AQ7: 0 | AR7: 0 | AS7: 0 | AT7: 0 | AU7: =AU6 -> 8.44925
A8: 4 | B8: WR00L2L2 | C8: 25984 | D8: 32 | E8: 1 | F8: 16 | G8: 1243.72 | H8: 9.4046 | I8: 45479 | J8: 0.62555556 | K8: 0 | L8: 0 | M8: 0 | N8: 0 | O8: 0 | P8: 0 | Q8: 0 | R8: 0 | S8: 0 | T8: 0 | U8: 0 | V8: 0 | W8: =W7 -> 9.40384 | Y8: 4 | Z8: WR00L2L2 | AA8: 25984 | AB8: 32 | AC8: 1 | AD8: 16 | AU8: =AU7 -> 8.44925
A9: 0 | B9: WR00L2L2 | C9: 27520 | D9: 32 | E9: 1 | F9: 16 | G9: 1471.78 | H9: 9.4416 | I9: 45477 | J9: 0.43626157 | K9: 0 | L9: 0 | M9: 0 | N9: 0 | O9: 0 | P9: 0 | Q9: 0 | R9: 0 | S9: 0 | T9: 0 | U9: 0 | V9: 0 | W9: =AVERAGE(H9:H13) -> 9.43808 | Y9: 0 | Z9: WR00L2L2 | AA9: 27520 | AB9: 32 | AC9: 1 | AD9: 16 | AE9: 1643.84 | AF9: 8.4534 | AG9: 45477 | AH9: 0.43667824 | AI9: 0 | AJ9: 0 | AK9: 0 | AL9: 0 | AM9: 0 | AN9: 0 | AO9: 0 | AP9: 0 | AQ9: 0 | AR9: 0 | AS9: 0 | AT9: 0 | AU9: =AVERAGE(AF9:AF13) -> 8.45375
A10: 1 | B10: WR00L2L2 | C10: 27520 | D10: 32 | E10: 1 | F10: 16 | G10: 1472.39 | H10: 9.4377 | I10: 45477 | J10: 0.94208333 | K10: 0 | L10: 0 | M10: 0 | N10: 0 | O10: 0 | P10: 0 | Q10: 0 | R10: 0 | S10: 0 | T10: 0 | U10: 0 | V10: 0 | W10: =W9 -> 9.43808 | Y10: 1 | Z10: WR00L2L2 | AA10: 27520 | AB10: 32 | AC10: 1 | AD10: 16 | AE10: 1643.57 | AF10: 8.4548 | AG10: 45477 | AH10: 0.96849537 | AI10: 0 | AJ10: 0 | AK10: 0 | AL10: 0 | AM10: 0 | AN10: 0 | AO10: 0 | AP10: 0 | AQ10: 0 | AR10: 0 | AS10: 0 | AT10: 0 | AU10: =AU9 -> 8.45375
A11: 2 | B11: WR00L2L2 | C11: 27520 | D11: 32 | E11: 1 | F11: 16 | G11: 1472.85 | H11: 9.4348 | I11: 45478 | J11: 0.4481713 | K11: 0 | L11: 0 | M11: 0 | N11: 0 | O11: 0 | P11: 0 | Q11: 0 | R11: 0 | S11: 0 | T11: 0 | U11: 0 | V11: 0 | W11: =W10 -> 9.43808 | Y11: 2 | Z11: WR00L2L2 | AA11: 27520 | AB11: 32 | AC11: 1 | AD11: 16 | AE11: 1644.29 | AF11: 8.4511 | AG11: 45478 | AH11: 0.50048611 | AI11: 0 | AJ11: 0 | AK11: 0 | AL11: 0 | AM11: 0 | AN11: 0 | AO11: 0 | AP11: 0 | AQ11: 0 | AR11: 0 | AS11: 0 | AT11: 0 | AU11: =AU10 -> 8.45375
A12: 3 | B12: WR00L2L2 | C12: 27520 | D12: 32 | E12: 1 | F12: 16 | G12: 1472.28 | H12: 9.4384 | I12: 45478 | J12: 0.95429398 | K12: 0 | L12: 0 | M12: 0 | N12: 0 | O12: 0 | P12: 0 | Q12: 0 | R12: 0 | S12: 0 | T12: 0 | U12: 0 | V12: 0 | W12: =W11 -> 9.43808 | Y12: 3 | Z12: WR00L2L2 | AA12: 27520 | AB12: 32 | AC12: 1 | AD12: 16 | AE12: 1643.39 | AF12: 8.4557 | AG12: 45479 | AH12: 0.032418981 | AI12: 0 | AJ12: 0 | AK12: 0 | AL12: 0 | AM12: 0 | AN12: 0 | AO12: 0 | AP12: 0 | AQ12: 0 | AR12: 0 | AS12: 0 | AT12: 0 | AU12: =AU11 -> 8.45375
A13: 4 | B13: WR00L2L2 | C13: 27520 | D13: 32 | E13: 1 | F13: 16 | G13: 1472.35 | H13: 9.4379 | I13: 45479 | J13: 0.46049769 | K13: 0 | L13: 0 | M13: 0 | N13: 0 | O13: 0 | P13: 0 | Q13: 0 | R13: 0 | S13: 0 | T13: 0 | U13: 0 | V13: 0 | W13: =W12 -> 9.43808 | Y13: 4 | Z13: WR00L2L2 | AA13: 27520 | AB13: 32 | AC13: 1 | AD13: 16 | AU13: =AU12 -> 8.45375
A14: 0 | B14: WR00L2L2 | C14: 29056 | D14: 32 | E14: 1 | F14: 16 | G14: 1723.38 | H14: 9.4901 | I14: 45477 | J14: 0.74974537 | K14: 0 | L14: 0 | M14: 0 | N14: 0 | O14: 0 | P14: 0 | Q14: 0 | R14: 0 | S14: 0 | T14: 0 | U14: 0 | V14: 0 | W14: =AVERAGE(H14:H18) -> 9.48428 | Y14: 0 | Z14: WR00L2L2 | AA14: 29056 | AB14: 32 | AC14: 1 | AD14: 16 | AE14: 1917.48 | AF14: 8.5294 | AG14: 45477 | AH14: 0.76590278 | AI14: 0 | AJ14: 0 | AK14: 0 | AL14: 0 | AM14: 0 | AN14: 0 | AO14: 0 | AP14: 0 | AQ14: 0 | AR14: 0 | AS14: 0 | AT14: 0 | AU14: =AVERAGE(AF14:AF18) -> 8.524275
A15: 1 | B15: WR00L2L2 | C15: 29056 | D15: 32 | E15: 1 | F15: 16 | G15: 1722.79 | H15: 9.4933 | I15: 45478 | J15: 0.25581019 | K15: 0 | L15: 0 | M15: 0 | N15: 0 | O15: 0 | P15: 0 | Q15: 0 | R15: 0 | S15: 0 | T15: 0 | U15: 0 | V15: 0 | W15: =W14 -> 9.48428 | Y15: 1 | Z15: WR00L2L2 | AA15: 29056 | AB15: 32 | AC15: 1 | AD15: 16 | AE15: 1919.37 | AF15: 8.521 | AG15: 45478 | AH15: 0.29783565 | AI15: 0 | AJ15: 0 | AK15: 0 | AL15: 0 | AM15: 0 | AN15: 0 | AO15: 0 | AP15: 0 | AQ15: 0 | AR15: 0 | AS15: 0 | AT15: 0 | AU15: =AU14 -> 8.524275
A16: 2 | B16: WR00L2L2 | C16: 29056 | D16: 32 | E16: 1 | F16: 16 | G16: 1724.86 | H16: 9.4819 | I16: 45478 | J16: 0.76190972 | K16: 0 | L16: 0 | M16: 0 | N16: 0 | O16: 0 | P16: 0 | Q16: 0 | R16: 0 | S16: 0 | T16: 0 | U16: 0 | V16: 0 | W16: =W15 -> 9.48428 | Y16: 2 | Z16: WR00L2L2 | AA16: 29056 | AB16: 32 | AC16: 1 | AD16: 16 | AE16: 1918.54 | AF16: 8.5247 | AG16: 45478 | AH16: 0.82981481 | AI16: 0 | AJ16: 0 | AK16: 0 | AL16: 0 | AM16: 0 | AN16: 0 | AO16: 0 | AP16: 0 | AQ16: 0 | AR16: 0 | AS16: 0 | AT16: 0 | AU16: =AU15 -> 8.524275
A17: 3 | B17: WR00L2L2 | C17: 29056 | D17: 32 | E17: 1 | F17: 16 | G17: 1726.08 | H17: 9.4752 | I17: 45479 | J17: 0.2681713 | K17: 0 | L17: 0 | M17: 0 | N17: 0 | O17: 0 | P17: 0 | Q17: 0 | R17: 0 | S17: 0 | T17: 0 | U17: 0 | V17: 0 | W17: =W16 -> 9.48428 | Y17: 3 | Z17: WR00L2L2 | AA17: 29056 | AB17: 32 | AC17: 1 | AD17: 16 | AE17: 1919.16 | AF17: 8.522 | AG17: 45479 | AH17: 0.36184028 | AI17: 0 | AJ17: 0 | AK17: 0 | AL17: 0 | AM17: 0 | AN17: 0 | AO17: 0 | AP17: 0 | AQ17: 0 | AR17: 0 | AS17: 0 | AT17: 0 | AU17: =AU16 -> 8.524275
A18: 4 | B18: WR00L2L2 | C18: 29056 | D18: 32 | E18: 1 | F18: 16 | G18: 1725.04 | H18: 9.4809 | I18: 45479 | J18: 0.77430556 | K18: 0 | L18: 0 | M18: 0 | N18: 0 | O18: 0 | P18: 0 | Q18: 0 | R18: 0 | S18: 0 | T18: 0 | U18: 0 | V18: 0 | W18: =W17 -> 9.48428 | Y18: 4 | Z18: WR00L2L2 | AA18: 29056 | AB18: 32 | AC18: 1 | AD18: 16 | AU18: =AU17 -> 8.524275
A19: 0 | B19: WR00L2L2 | C19: 25984 | D19: 32 | E19: 2 | F19: 8 | G19: 1235.69 | H19: 9.4657 | I19: 45477 | J19: 0.61678241 | K19: 0 | L19: 0 | M19: 0 | N19: 0 | O19: 0 | P19: 0 | Q19: 0 | R19: 0 | S19: 0 | T19: 0 | U19: 0 | V19: 0 | W19: =AVERAGE(H19:H23) -> 9.46458 | Y19: 0 | Z19: WR00L2L2 | AA19: 25984 | AB19: 32 | AC19: 2 | AD19: 8 | AE19: 1360.44 | AF19: 8.5977 | AG19: 45477 | AH19: 0.62633102 | AI19: 0 | AJ19: 0 | AK19: 0 | AL19: 0 | AM19: 0 | AN19: 0 | AO19: 0 | AP19: 0 | AQ19: 0 | AR19: 0 | AS19: 0 | AT19: 0 | AU19: =AVERAGE(AF19:AF23) -> 8.600175
A20: 1 | B20: WR00L2L2 | C20: 25984 | D20: 32 | E20: 2 | F20: 8 | G20: 1235.57 | H20: 9.4667 | I20: 45478 | J20: 0.12273148 | K20: 0 | L20: 0 | M20: 0 | N20: 0 | O20: 0 | P20: 0 | Q20: 0 | R20: 0 | S20: 0 | T20: 0 | U20: 0 | V20: 0 | W20: =W19 -> 9.46458 | Y20: 1 | Z20: WR00L2L2 | AA20: 25984 | AB20: 32 | AC20: 2 | AD20: 8 | AE20: 1360.02 | AF20: 8.6004 | AG20: 45478 | AH20: 0.15820602 | AI20: 0 | AJ20: 0 | AK20: 0 | AL20: 0 | AM20: 0 | AN20: 0 | AO20: 0 | AP20: 0 | AQ20: 0 | AR20: 0 | AS20: 0 | AT20: 0 | AU20: =AU19 -> 8.600175
A21: 2 | B21: WR00L2L2 | C21: 25984 | D21: 32 | E21: 2 | F21: 8 | G21: 1236.36 | H21: 9.4606 | I21: 45478 | J21: 0.6287963 | K21: 0 | L21: 0 | M21: 0 | N21: 0 | O21: 0 | P21: 0 | Q21: 0 | R21: 0 | S21: 0 | T21: 0 | U21: 0 | V21: 0 | W21: =W20 -> 9.46458 | Y21: 2 | Z21: WR00L2L2 | AA21: 25984 | AB21: 32 | AC21: 2 | AD21: 8 | AE21: 1359.84 | AF21: 8.6016 | AG21: 45478 | AH21: 0.69017361 | AI21: 0 | AJ21: 0 | AK21: 0 | AL21: 0 | AM21: 0 | AN21: 0 | AO21: 0 | AP21: 0 | AQ21: 0 | AR21: 0 | AS21: 0 | AT21: 0 | AU21: =AU20 -> 8.600175
A22: 3 | B22: WR00L2L2 | C22: 25984 | D22: 32 | E22: 2 | F22: 8 | G22: 1235.41 | H22: 9.4679 | I22: 45479 | J22: 0.13498843 | K22: 0 | L22: 0 | M22: 0 | N22: 0 | O22: 0 | P22: 0 | Q22: 0 | R22: 0 | S22: 0 | T22: 0 | U22: 0 | V22: 0 | W22: =W21 -> 9.46458 | Y22: 3 | Z22: WR00L2L2 | AA22: 25984 | AB22: 32 | AC22: 2 | AD22: 8 | AE22: 1359.93 | AF22: 8.601 | AG22: 45479 | AH22: 0.22215278 | AI22: 0 | AJ22: 0 | AK22: 0 | AL22: 0 | AM22: 0 | AN22: 0 | AO22: 0 | AP22: 0 | AQ22: 0 | AR22: 0 | AS22: 0 | AT22: 0 | AU22: =AU21 -> 8.600175
A23: 4 | B23: WR00L2L2 | C23: 25984 | D23: 32 | E23: 2 | F23: 8 | G23: 1236.18 | H23: 9.462 | I23: 45479 | J23: 0.64122685 | K23: 0 | L23: 0 | M23: 0 | N23: 0 | O23: 0 | P23: 0 | Q23: 0 | R23: 0 | S23: 0 | T23: 0 | U23: 0 | V23: 0 | W23: =W22 -> 9.46458 | Y23: 4 | Z23: WR00L2L2 | AA23: 25984 | AB23: 32 | AC23: 2 | AD23: 8 | AU23: =AU22 -> 8.600175
A24: 0 | B24: WR00L2L2 | C24: 27520 | D24: 32 | E24: 2 | F24: 8 | G24: 1460.5 | H24: 9.5145 | I24: 45477 | J24: 0.45469907 | K24: 0 | L24: 0 | M24: 0 | N24: 0 | O24: 0 | P24: 0 | Q24: 0 | R24: 0 | S24: 0 | T24: 0 | U24: 0 | V24: 0 | W24: =AVERAGE(H24:H28) -> 9.51158 | Y24: 0 | Z24: WR00L2L2 | AA24: 27520 | AB24: 32 | AC24: 2 | AD24: 8 | AE24: 1610.33 | AF24: 8.6293 | AG24: 45477 | AH24: 0.4556713 | AI24: 0 | AJ24: 0 | AK24: 0 | AL24: 0 | AM24: 0 | AN24: 0 | AO24: 0 | AP24: 0 | AQ24: 0 | AR24: 0 | AS24: 0 | AT24: 0 | AU24: =AVERAGE(AF24:AF28) -> 8.627
A25: 1 | B25: WR00L2L2 | C25: 27520 | D25: 32 | E25: 2 | F25: 8 | G25: 1460.79 | H25: 9.5127 | I25: 45477 | J25: 0.96050926 | K25: 0 | L25: 0 | M25: 0 | N25: 0 | O25: 0 | P25: 0 | Q25: 0 | R25: 0 | S25: 0 | T25: 0 | U25: 0 | V25: 0 | W25: =W24 -> 9.51158 | Y25: 1 | Z25: WR00L2L2 | AA25: 27520 | AB25: 32 | AC25: 2 | AD25: 8 | AE25: 1610.47 | AF25: 8.6285 | AG25: 45477 | AH25: 0.9875 | AI25: 0 | AJ25: 0 | AK25: 0 | AL25: 0 | AM25: 0 | AN25: 0 | AO25: 0 | AP25: 0 | AQ25: 0 | AR25: 0 | AS25: 0 | AT25: 0 | AU25: =AU24 -> 8.627
A26: 2 | B26: WR00L2L2 | C26: 27520 | D26: 32 | E26: 2 | F26: 8 | G26: 1461.11 | H26: 9.5106 | I26: 45478 | J26: 0.46662037 | K26: 0 | L26: 0 | M26: 0 | N26: 0 | O26: 0 | P26: 0 | Q26: 0 | R26: 0 | S26: 0 | T26: 0 | U26: 0 | V26: 0 | W26: =W25 -> 9.51158 | Y26: 2 | Z26: WR00L2L2 | AA26: 27520 | AB26: 32 | AC26: 2 | AD26: 8 | AE26: 1610.94 | AF26: 8.626 | AG26: 45478 | AH26: 0.51949074 | AI26: 0 | AJ26: 0 | AK26: 0 | AL26: 0 | AM26: 0 | AN26: 0 | AO26: 0 | AP26: 0 | AQ26: 0 | AR26: 0 | AS26: 0 | AT26: 0 | AU26: =AU25 -> 8.627
A27: 3 | B27: WR00L2L2 | C27: 27520 | D27: 32 | E27: 2 | F27: 8 | G27: 1460.79 | H27: 9.5126 | I27: 45478 | J27: 0.97273148 | K27: 0 | L27: 0 | M27: 0 | N27: 0 | O27: 0 | P27: 0 | Q27: 0 | R27: 0 | S27: 0 | T27: 0 | U27: 0 | V27: 0 | W27: =W26 -> 9.51158 | Y27: 3 | Z27: WR00L2L2 | AA27: 27520 | AB27: 32 | AC27: 2 | AD27: 8 | AE27: 1611.27 | AF27: 8.6242 | AG27: 45479 | AH27: 0.051423611 | AI27: 0 | AJ27: 0 | AK27: 0 | AL27: 0 | AM27: 0 | AN27: 0 | AO27: 0 | AP27: 0 | AQ27: 0 | AR27: 0 | AS27: 0 | AT27: 0 | AU27: =AU26 -> 8.627
A28: 4 | B28: WR00L2L2 | C28: 27520 | D28: 32 | E28: 2 | F28: 8 | G28: 1461.58 | H28: 9.5075 | I28: 45479 | J28: 0.47894676 | K28: 0 | L28: 0 | M28: 0 | N28: 0 | O28: 0 | P28: 0 | Q28: 0 | R28: 0 | S28: 0 | T28: 0 | U28: 0 | V28: 0 | W28: =W27 -> 9.51158 | Y28: 4 | Z28: WR00L2L2 | AA28: 27520 | AB28: 32 | AC28: 2 | AD28: 8 | AU28: =AU27 -> 8.627
A29: 0 | B29: WR00L2L2 | C29: 29056 | D29: 32 | E29: 2 | F29: 8 | G29: 1711.06 | H29: 9.5584 | I29: 45477 | J29: 0.77123843 | K29: 0 | L29: 0 | M29: 0 | N29: 0 | O29: 0 | P29: 0 | Q29: 0 | R29: 0 | S29: 0 | T29: 0 | U29: 0 | V29: 0 | W29: =AVERAGE(H29:H33) -> 9.5522 | Y29: 0 | Z29: WR00L2L2 | AA29: 29056 | AB29: 32 | AC29: 2 | AD29: 8 | AE29: 1887.61 | AF29: 8.6644 | AG29: 45477 | AH29: 0.78813657 | AI29: 0 | AJ29: 0 | AK29: 0 | AL29: 0 | AM29: 0 | AN29: 0 | AO29: 0 | AP29: 0 | AQ29: 0 | AR29: 0 | AS29: 0 | AT29: 0 | AU29: =AVERAGE(AF29:AF33) -> 8.664675
A30: 1 | B30: WR00L2L2 | C30: 29056 | D30: 32 | E30: 2 | F30: 8 | G30: 1712.29 | H30: 9.5515 | I30: 45478 | J30: 0.27732639 | K30: 0 | L30: 0 | M30: 0 | N30: 0 | O30: 0 | P30: 0 | Q30: 0 | R30: 0 | S30: 0 | T30: 0 | U30: 0 | V30: 0 | W30: =W29 -> 9.5522 | Y30: 1 | Z30: WR00L2L2 | AA30: 29056 | AB30: 32 | AC30: 2 | AD30: 8 | AE30: 1887.85 | AF30: 8.6633 | AG30: 45478 | AH30: 0.32008102 | AI30: 0 | AJ30: 0 | AK30: 0 | AL30: 0 | AM30: 0 | AN30: 0 | AO30: 0 | AP30: 0 | AQ30: 0 | AR30: 0 | AS30: 0 | AT30: 0 | AU30: =AU29 -> 8.664675
A31: 2 | B31: WR00L2L2 | C31: 29056 | D31: 32 | E31: 2 | F31: 8 | G31: 1712.69 | H31: 9.5493 | I31: 45478 | J31: 0.78342593 | K31: 0 | L31: 0 | M31: 0 | N31: 0 | O31: 0 | P31: 0 | Q31: 0 | R31: 0 | S31: 0 | T31: 0 | U31: 0 | V31: 0 | W31: =W30 -> 9.5522 | Y31: 2 | Z31: WR00L2L2 | AA31: 29056 | AB31: 32 | AC31: 2 | AD31: 8 | AE31: 1887.2 | AF31: 8.6663 | AG31: 45478 | AH31: 0.85204861 | AI31: 0 | AJ31: 0 | AK31: 0 | AL31: 0 | AM31: 0 | AN31: 0 | AO31: 0 | AP31: 0 | AQ31: 0 | AR31: 0 | AS31: 0 | AT31: 0 | AU31: =AU30 -> 8.664675
A32: 3 | B32: WR00L2L2 | C32: 29056 | D32: 32 | E32: 2 | F32: 8 | G32: 1713.42 | H32: 9.5452 | I32: 45479 | J32: 0.28969907 | K32: 0 | L32: 0 | M32: 0 | N32: 0 | O32: 0 | P32: 0 | Q32: 0 | R32: 0 | S32: 0 | T32: 0 | U32: 0 | V32: 0 | W32: =W31 -> 9.5522 | Y32: 3 | Z32: WR00L2L2 | AA32: 29056 | AB32: 32 | AC32: 2 | AD32: 8 | AE32: 1887.54 | AF32: 8.6647 | AG32: 45479 | AH32: 0.38407407 | AI32: 0 | AJ32: 0 | AK32: 0 | AL32: 0 | AM32: 0 | AN32: 0 | AO32: 0 | AP32: 0 | AQ32: 0 | AR32: 0 | AS32: 0 | AT32: 0 | AU32: =AU31 -> 8.664675
A33: 4 | B33: WR00L2L2 | C33: 29056 | D33: 32 | E33: 2 | F33: 8 | G33: 1711.39 | H33: 9.5566 | I33: 45479 | J33: 0.79581019 | K33: 0 | L33: 0 | M33: 0 | N33: 0 | O33: 0 | P33: 0 | Q33: 0 | R33: 0 | S33: 0 | T33: 0 | U33: 0 | V33: 0 | W33: =W32 -> 9.5522 | Y33: 4 | Z33: WR00L2L2 | AA33: 29056 | AB33: 32 | AC33: 2 | AD33: 8 | AU33: =AU32 -> 8.664675
A34: 0 | B34: WR00L2L2 | C34: 25984 | D34: 32 | E34: 4 | F34: 4 | G34: 1251.59 | H34: 9.3455 | I34: 45477 | J34: 0.63262731 | K34: 0 | L34: 0 | M34: 0 | N34: 0 | O34: 0 | P34: 0 | Q34: 0 | R34: 0 | S34: 0 | T34: 0 | U34: 0 | V34: 0 | W34: =AVERAGE(H34:H38) -> 9.33394 | Y34: 0 | Z34: WR00L2L2 | AA34: 25984 | AB34: 32 | AC34: 4 | AD34: 4 | AE34: 1371.96 | AF34: 8.5256 | AG34: 45477 | AH34: 0.64252315 | AI34: 0 | AJ34: 0 | AK34: 0 | AL34: 0 | AM34: 0 | AN34: 0 | AO34: 0 | AP34: 0 | AQ34: 0 | AR34: 0 | AS34: 0 | AT34: 0 | AU34: =AVERAGE(AF34:AF38) -> 8.5202
A35: 1 | B35: WR00L2L2 | C35: 25984 | D35: 32 | E35: 4 | F35: 4 | G35: 1252.52 | H35: 9.3385 | I35: 45478 | J35: 0.13858796 | K35: 0 | L35: 0 | M35: 0 | N35: 0 | O35: 0 | P35: 0 | Q35: 0 | R35: 0 | S35: 0 | T35: 0 | U35: 0 | V35: 0 | W35: =W34 -> 9.33394 | Y35: 1 | Z35: WR00L2L2 | AA35: 25984 | AB35: 32 | AC35: 4 | AD35: 4 | AE35: 1372.46 | AF35: 8.5225 | AG35: 45478 | AH35: 0.17440972 | AI35: 0 | AJ35: 0 | AK35: 0 | AL35: 0 | AM35: 0 | AN35: 0 | AO35: 0 | AP35: 0 | AQ35: 0 | AR35: 0 | AS35: 0 | AT35: 0 | AU35: =AU34 -> 8.5202
