Workbook

Sheet HPL 4 nodes, builds, old
A1: ? MHz | M1: ? MHz
A2: Old builds, no throttling information | M2: NEW builds, no throttling information
AA3: OdroidMC1, big runs on small cores and vice-versa | AL3: OdroidMC1, big runs on small cores and vice-versa
A4: Build | B4: #run | C4: Flags | D4: N | E4: NB | F4: P | G4: Q | H4: Time | I4: GFLOPS | M4: Build | N4: #run | O4: Flags | P4: N | Q4: NB | R4: P | S4: Q | T4: Time | U4: GFLOPS | V4: Average GFLOPS | W4: Date | X4: Time | AA4: Build | AB4: #run | AC4: Flags | AD4: N | AE4: NB | AF4: P | AG4: Q | AH4: Time | AI4: GFLOPS | AL4: Build | AM4: #run | AN4: Flags | AO4: N | AP4: NB | AQ4: P | AR4: Q | AS4: Time | AT4: GFLOPS
A5: optimized-big-atlasarch-tune, | B5: 1 | C5: WR00L2L2 | D5: 25984 | E5: 128 | F5: 2 | G5: 8 | H5: 386.27 | I5: 30.281 | J5: =AVERAGE(I5:I8) -> 30.02925 | K5: =A5 -> optimized-big-atlasarch-tune, | M5: big | N5: 0 | O5: WR00L2L2 | P5: 25984 | Q5: 128 | R5: 2 | S5: 8 | T5: 324.54 | U5: 36.041 | V5: =AVERAGE(U5:U8) -> 36.01975 | W5: 45090 | X5: 0.66299769 | AA5: optimized-big-atlasarch-tune | AB5: 1 | AC5: WR00L2L2 | AD5: 25984 | AE5: 128 | AF5: 2 | AG5: 8 | AH5: 1768.96 | AI5: 6.6122 | AL5: atlarch | AM5: 1 | AN5: WR00L2L2 | AO5: 18368 | AP5: 64 | AQ5: 2 | AR5: 4 | AS5: 2171.03 | AT5: 1.9032
A6: optimized-big-atlasarch-tune, | B6: 2 | C6: WR00L2L2 | D6: 25984 | E6: 128 | F6: 2 | G6: 8 | H6: 390.42 | I6: 29.959 | M6: big | N6: 1 | O6: WR00L2L2 | P6: 25984 | Q6: 128 | R6: 2 | S6: 8 | T6: 324.95 | U6: 35.996 | W6: 45090 | X6: 0.66690972 | AA6: optimized-big-atlasarch-tune | AB6: 2 | AC6: WR00L2L2 | AD6: 25984 | AE6: 128 | AF6: 2 | AG6: 8 | AH6: 1768.31 | AI6: 6.6146 | AL6: atlarch | AM6: 2 | AN6: WR00L2L2 | AO6: 18368 | AP6: 64 | AQ6: 2 | AR6: 4 | AS6: 2099.93 | AT6: 1.9676
A7: optimized-big-atlasarch-tune, | B7: 3 | C7: WR00L2L2 | D7: 25984 | E7: 128 | F7: 2 | G7: 8 | H7: 390.94 | I7: 29.92 | M7: big | N7: 2 | O7: WR00L2L2 | P7: 25984 | Q7: 128 | R7: 2 | S7: 8 | T7: 324.74 | U7: 36.018 | W7: 45090 | X7: 0.67081019 | AA7: optimized-big-atlasarch-tune | AB7: 3 | AC7: WR00L2L2 | AD7: 25984 | AE7: 128 | AF7: 2 | AG7: 8 | AH7: 1767.88 | AI7: 6.6162 | AL7: atlarch | AM7: 3 | AN7: WR00L2L2 | AO7: 18368 | AP7: 64 | AQ7: 2 | AR7: 4 | AS7: 2161.9 | AT7: 1.9112
A8: optimized-big-atlasarch-tune, | B8: 4 | C8: WR00L2L2 | D8: 25984 | E8: 128 | F8: 2 | G8: 8 | H8: 390.45 | I8: 29.957 | M8: big | N8: 3 | O8: WR00L2L2 | P8: 25984 | Q8: 128 | R8: 2 | S8: 8 | T8: 324.69 | U8: 36.024 | W8: 45090 | X8: 0.67471065 | AA8: optimized-big-atlasarch-tune | AB8: 4 | AC8: WR00L2L2 | AD8: 25984 | AE8: 128 | AF8: 2 | AG8: 8 | AH8: 1768.8 | AI8: 6.6128 | AL8: atlarch | AM8: 4 | AN8: WR00L2L2 | AO8: 18368 | AP8: 64 | AQ8: 2 | AR8: 4 | AS8: 2169.22 | AT8: 1.9048
A9: optimized-big-arch-tune, | B9: 1 | C9: WR00L2L2 | D9: 25984 | E9: 128 | F9: 2 | G9: 8 | H9: 721.89 | I9: 16.203 | J9: =AVERAGE(I9:I12) -> 16.1985 | K9: =A9 -> optimized-big-arch-tune, | M9: big | N9: 4 | O9: WR00L2L2 | P9: 25984 | Q9: 128 | R9: 2 | S9: 8 | T9: 324.93 | U9: 35.998 | V9: =AVERAGE(U9:U12) -> 32.7175 | W9: 45090 | X9: 0.67862269 | AA9: optimized-big-arch-tune | AB9: 1 | AC9: WR00L2L2 | AD9: 25984 | AE9: 128 | AF9: 2 | AG9: 8 | AH9: 2074.65 | AI9: 5.6379 | AL9: cpu-tune | AM9: 1 | AN9: WR00L2L2 | AO9: 18368 | AP9: 64 | AQ9: 2 | AR9: 4 | AS9: 2404.98 | AT9: 1.7181
A10: optimized-big-arch-tune, | B10: 2 | C10: WR00L2L2 | D10: 25984 | E10: 128 | F10: 2 | G10: 8 | H10: 721.8 | I10: 16.205 | M10: big-arch-tune | N10: 0 | O10: WR00L2L2 | P10: 25984 | Q10: 128 | R10: 2 | S10: 8 | T10: 369.34 | U10: 31.669 | W10: 45090 | X10: 0.68334491 | AA10: optimized-big-arch-tune | AB10: 2 | AC10: WR00L2L2 | AD10: 25984 | AE10: 128 | AF10: 2 | AG10: 8 | AH10: 2074.75 | AI10: 5.6376 | AL10: cpu-tune | AM10: 2 | AN10: WR00L2L2 | AO10: 18368 | AP10: 64 | AQ10: 2 | AR10: 4 | AS10: 2420.85 | AT10: 1.7068
A11: optimized-big-arch-tune, | B11: 3 | C11: WR00L2L2 | D11: 25984 | E11: 128 | F11: 2 | G11: 8 | H11: 721.96 | I11: 16.201 | M11: big-arch-tune | N11: 1 | O11: WR00L2L2 | P11: 25984 | Q11: 128 | R11: 2 | S11: 8 | T11: 370.63 | U11: 31.559 | W11: 45090 | X11: 0.6880787 | AA11: optimized-big-arch-tune | AB11: 3 | AC11: WR00L2L2 | AD11: 25984 | AE11: 128 | AF11: 2 | AG11: 8 | AH11: 2074.34 | AI11: 5.6388 | AL11: cpu-tune | AM11: 3 | AN11: WR00L2L2 | AO11: 18368 | AP11: 64 | AQ11: 2 | AR11: 4 | AS11: 2466 | AT11: 1.6755
A12: optimized-big-arch-tune, | B12: 4 | C12: WR00L2L2 | D12: 25984 | E12: 128 | F12: 2 | G12: 8 | H12: 722.7 | I12: 16.185 | M12: big-arch-tune | N12: 2 | O12: WR00L2L2 | P12: 25984 | Q12: 128 | R12: 2 | S12: 8 | T12: 369.63 | U12: 31.644 | W12: 45090 | X12: 0.69280093 | AA12: optimized-big-arch-tune | AB12: 4 | AC12: WR00L2L2 | AD12: 25984 | AE12: 128 | AF12: 2 | AG12: 8 | AH12: 2074.7 | AI12: 5.6378 | AL12: cpu-tune | AM12: 4 | AN12: WR00L2L2 | AO12: 18368 | AP12: 64 | AQ12: 2 | AR12: 4 | AS12: 2448.97 | AT12: 1.6872
A13: optimized-big-atlasarch-tune2, | B13: 1 | C13: WR00L2L2 | D13: 25984 | E13: 128 | F13: 2 | G13: 8 | H13: 391.07 | I13: 29.91 | J13: =AVERAGE(I13:I16) -> 29.887 | K13: =A13 -> optimized-big-atlasarch-tune2, | M13: big-arch-tune | N13: 3 | O13: WR00L2L2 | P13: 25984 | Q13: 128 | R13: 2 | S13: 8 | T13: 369.59 | U13: 31.648 | V13: =AVERAGE(U13:U16) -> 32.3715 | W13: 45090 | X13: 0.69752315 | AA13: optimized-big-atlasarch-tune2 | AB13: 1 | AC13: WR00L2L2 | AD13: 25984 | AE13: 128 | AF13: 2 | AG13: 8 | AH13: 1768.33 | AI13: 6.6146 | AL13: arch-native-tune | AM13: 1 | AN13: WR00L2L2 | AO13: 18368 | AP13: 64 | AQ13: 2 | AR13: 4 | AS13: 2543.42 | AT13: 1.6245
A14: optimized-big-atlasarch-tune2, | B14: 2 | C14: WR00L2L2 | D14: 25984 | E14: 128 | F14: 2 | G14: 8 | H14: 391.61 | I14: 29.868 | M14: big-arch-tune | N14: 4 | O14: WR00L2L2 | P14: 25984 | Q14: 128 | R14: 2 | S14: 8 | T14: 370.19 | U14: 31.597 | W14: 45090 | X14: 0.70224537 | AA14: optimized-big-atlasarch-tune2 | AB14: 2 | AC14: WR00L2L2 | AD14: 25984 | AE14: 128 | AF14: 2 | AG14: 8 | AH14: 1767.99 | AI14: 6.6158 | AL14: arch-native-tune | AM14: 2 | AN14: WR00L2L2 | AO14: 18368 | AP14: 64 | AQ14: 2 | AR14: 4 | AS14: 2477.2 | AT14: 1.668
A15: optimized-big-atlasarch-tune2, | B15: 3 | C15: WR00L2L2 | D15: 25984 | E15: 128 | F15: 2 | G15: 8 | H15: 391.19 | I15: 29.9 | M15: big-atlasarch-tune2 | N15: 0 | O15: WR00L2L2 | P15: 25984 | Q15: 128 | R15: 2 | S15: 8 | T15: 353.24 | U15: 33.113 | W15: 45090 | X15: 0.70648148 | AA15: optimized-big-atlasarch-tune2 | AB15: 3 | AC15: WR00L2L2 | AD15: 25984 | AE15: 128 | AF15: 2 | AG15: 8 | AH15: 1768.41 | AI15: 6.6143 | AL15: arch-native-tune | AM15: 3 | AN15: WR00L2L2 | AO15: 18368 | AP15: 64 | AQ15: 2 | AR15: 4 | AS15: 2511.35 | AT15: 1.6453
A16: optimized-big-atlasarch-tune2, | B16: 4 | C16: WR00L2L2 | D16: 25984 | E16: 128 | F16: 2 | G16: 8 | H16: 391.59 | I16: 29.87 | M16: big-atlasarch-tune2 | N16: 1 | O16: WR00L2L2 | P16: 25984 | Q16: 128 | R16: 2 | S16: 8 | T16: 353.08 | U16: 33.128 | W16: 45090 | X16: 0.71071759 | AA16: optimized-big-atlasarch-tune2 | AB16: 4 | AC16: WR00L2L2 | AD16: 25984 | AE16: 128 | AF16: 2 | AG16: 8 | AH16: 1768.55 | AI16: 6.6138 | AL16: arch-native-tune | AM16: 4 | AN16: WR00L2L2 | AO16: 18368 | AP16: 64 | AQ16: 2 | AR16: 4 | AS16: 2537.24 | AT16: 1.6285
A17: optimized-big | B17: 1 | C17: WR00L2L2 | D17: 25984 | E17: 128 | F17: 2 | G17: 8 | H17: 354.71 | I17: 32.975 | J17: =AVERAGE(I17:I20) -> 32.67675 | K17: =A17 -> optimized-big | M17: big-atlasarch-tune2 | N17: 2 | O17: WR00L2L2 | P17: 25984 | Q17: 128 | R17: 2 | S17: 8 | T17: 353.71 | U17: 33.069 | V17: =AVERAGE(U17:U20) -> 32.7165 | W17: 45090 | X17: 0.7149537 | AA17: optimized-small | AB17: 1 | AC17: WR00L2L2 | AD17: 25984 | AE17: 128 | AF17: 2 | AG17: 8 | AH17: 404.36 | AI17: 28.927 | AL17: cpu-tune-overr | AM17: 1 | AN17: WR00L2L2 | AO17: 18368 | AP17: 64 | AQ17: 2 | AR17: 4 | AS17: 3283.31 | AT17: 1.2584
A18: optimized-big | B18: 2 | C18: WR00L2L2 | D18: 25984 | E18: 128 | F18: 2 | G18: 8 | H18: 358.74 | I18: 32.605 | M18: big-atlasarch-tune2 | N18: 3 | O18: WR00L2L2 | P18: 25984 | Q18: 128 | R18: 2 | S18: 8 | T18: 353.13 | U18: 33.123 | W18: 45090 | X18: 0.71918981 | AA18: optimized-small | AB18: 2 | AC18: WR00L2L2 | AD18: 25984 | AE18: 128 | AF18: 2 | AG18: 8 | AH18: 407.5 | AI18: 28.703 | AL18: cpu-tune-overr | AM18: 2 | AN18: WR00L2L2 | AO18: 18368 | AP18: 64 | AQ18: 2 | AR18: 4 | AS18: 3225.76 | AT18: 1.2809
A19: optimized-big | B19: 3 | C19: WR00L2L2 | D19: 25984 | E19: 128 | F19: 2 | G19: 8 | H19: 359.21 | I19: 32.562 | M19: big-atlasarch-tune2 | N19: 4 | O19: WR00L2L2 | P19: 25984 | Q19: 128 | R19: 2 | S19: 8 | T19: 353.42 | U19: 33.096 | W19: 45090 | X19: 0.72342593 | AA19: optimized-small | AB19: 3 | AC19: WR00L2L2 | AD19: 25984 | AE19: 128 | AF19: 2 | AG19: 8 | AH19: 407.68 | AI19: 28.691 | AL19: cpu-tune-overr | AM19: 3 | AN19: WR00L2L2 | AO19: 18368 | AP19: 64 | AQ19: 2 | AR19: 4 | AS19: 3186.46 | AT19: 1.2967
A20: optimized-big | B20: 4 | C20: WR00L2L2 | D20: 25984 | E20: 128 | F20: 2 | G20: 8 | H20: 359.19 | I20: 32.565 | M20: big-arch7a-tune | N20: 0 | O20: WR00L2L2 | P20: 25984 | Q20: 128 | R20: 2 | S20: 8 | T20: 370.41 | U20: 31.578 | W20: 45090 | X20: 0.72815972 | AA20: optimized-small | AB20: 4 | AC20: WR00L2L2 | AD20: 25984 | AE20: 128 | AF20: 2 | AG20: 8 | AH20: 407.44 | AI20: 28.708 | AL20: cpu-tune-overr | AM20: 4 | AN20: WR00L2L2 | AO20: 18368 | AP20: 64 | AQ20: 2 | AR20: 4 | AS20: 3179.9 | AT20: 1.2994
A21: optimized-big-flags | B21: 1 | C21: WR00L2L2 | D21: 25984 | E21: 128 | F21: 2 | G21: 8 | H21: 396.32 | I21: 29.513 | J21: =AVERAGE(I21:I24) -> 29.27875 | K21: =A21 -> optimized-big-flags | M21: big-arch7a-tune | N21: 1 | O21: WR00L2L2 | P21: 25984 | Q21: 128 | R21: 2 | S21: 8 | T21: 369.65 | U21: 31.643 | V21: =AVERAGE(U21:U24) -> 31.62 | W21: 45090 | X21: 0.73288194 | AA21: optimized-small-atlasarch-tune | AB21: 1 | AC21: WR00L2L2 | AD21: 25984 | AE21: 128 | AF21: 2 | AG21: 8 | AH21: 405.29 | AI21: 28.86 | AL21: atlarch-flags | AM21: 1 | AN21: WR00L2L2 | AO21: 18368 | AP21: 64 | AQ21: 2 | AR21: 4 | AS21: 2154.49 | AT21: 1.9178
A22: optimized-big-flags | B22: 2 | C22: WR00L2L2 | D22: 25984 | E22: 128 | F22: 2 | G22: 8 | H22: 400.54 | I22: 29.202 | M22: big-arch7a-tune | N22: 2 | O22: WR00L2L2 | P22: 25984 | Q22: 128 | R22: 2 | S22: 8 | T22: 369.91 | U22: 31.621 | W22: 45090 | X22: 0.73760417 | AA22: optimized-small-atlasarch-tune | AB22: 2 | AC22: WR00L2L2 | AD22: 25984 | AE22: 128 | AF22: 2 | AG22: 8 | AH22: 405.44 | AI22: 28.849 | AL22: atlarch-flags | AM22: 2 | AN22: WR00L2L2 | AO22: 18368 | AP22: 64 | AQ22: 2 | AR22: 4 | AS22: 2052.7 | AT22: 2.0129
A23: optimized-big-flags | B23: 3 | C23: WR00L2L2 | D23: 25984 | E23: 128 | F23: 2 | G23: 8 | H23: 400.37 | I23: 29.215 | M23: big-arch7a-tune | N23: 3 | O23: WR00L2L2 | P23: 25984 | Q23: 128 | R23: 2 | S23: 8 | T23: 370.59 | U23: 31.562 | W23: 45090 | X23: 0.74233796 | AA23: optimized-small-atlasarch-tune | AB23: 3 | AC23: WR00L2L2 | AD23: 25984 | AE23: 128 | AF23: 2 | AG23: 8 | AH23: 406.14 | AI23: 28.8 | AL23: atlarch-flags | AM23: 3 | AN23: WR00L2L2 | AO23: 18368 | AP23: 64 | AQ23: 2 | AR23: 4 | AS23: 2146.85 | AT23: 1.9246
A24: optimized-big-flags | B24: 4 | C24: WR00L2L2 | D24: 25984 | E24: 128 | F24: 2 | G24: 8 | H24: 400.78 | I24: 29.185 | M24: big-arch7a-tune | N24: 4 | O24: WR00L2L2 | P24: 25984 | Q24: 128 | R24: 2 | S24: 8 | T24: 369.52 | U24: 31.654 | W24: 45090 | X24: 0.74706019 | AA24: optimized-small-atlasarch-tune | AB24: 4 | AC24: WR00L2L2 | AD24: 25984 | AE24: 128 | AF24: 2 | AG24: 8 | AH24: 405.84 | AI24: 28.821 | AL24: atlarch-flags | AM24: 4 | AN24: WR00L2L2 | AO24: 18368 | AP24: 64 | AQ24: 2 | AR24: 4 | AS24: 2132.7 | AT24: 1.9374
A25: optimized-big-arch-tune-flags | B25: 1 | C25: WR00L2L2 | D25: 25984 | E25: 128 | F25: 2 | G25: 8 | H25: 404.58 | I25: 28.911 | J25: =AVERAGE(I25:I28) -> 28.915 | K25: =A25 -> optimized-big-arch-tune-flags | M25: big-cpu | N25: 0 | O25: WR00L2L2 | P25: 25984 | Q25: 128 | R25: 2 | S25: 8 | T25: 370.83 | U25: 31.542 | V25: =AVERAGE(U25:U28) -> 31.54225 | W25: 45090 | X25: 0.75180556 | AA25: optimized-small-arch-tune | AB25: 1 | AC25: WR00L2L2 | AD25: 25984 | AE25: 128 | AF25: 2 | AG25: 8 | AH25: 723.48 | AI25: 16.167 | AL25: cpu-tune-flags | AM25: 1 | AN25: WR00L2L2 | AO25: 18368 | AP25: 64 | AQ25: 2 | AR25: 4 | AS25: 2273.58 | AT25: 1.8173
A26: optimized-big-arch-tune-flags | B26: 2 | C26: WR00L2L2 | D26: 25984 | E26: 128 | F26: 2 | G26: 8 | H26: 404.38 | I26: 28.925 | M26: big-cpu | N26: 1 | O26: WR00L2L2 | P26: 25984 | Q26: 128 | R26: 2 | S26: 8 | T26: 371.23 | U26: 31.508 | W26: 45090 | X26: 0.75653935 | AA26: optimized-small-arch-tune | AB26: 2 | AC26: WR00L2L2 | AD26: 25984 | AE26: 128 | AF26: 2 | AG26: 8 | AH26: 722.22 | AI26: 16.196 | AL26: cpu-tune-flags | AM26: 2 | AN26: WR00L2L2 | AO26: 18368 | AP26: 64 | AQ26: 2 | AR26: 4 | AS26: 2239.74 | AT26: 1.8448
A27: optimized-big-arch-tune-flags | B27: 3 | C27: WR00L2L2 | D27: 25984 | E27: 128 | F27: 2 | G27: 8 | H27: 404.62 | I27: 28.908 | M27: big-cpu | N27: 2 | O27: WR00L2L2 | P27: 25984 | Q27: 128 | R27: 2 | S27: 8 | T27: 370.4 | U27: 31.579 | W27: 45090 | X27: 0.76127315 | AA27: optimized-small-arch-tune | AB27: 3 | AC27: WR00L2L2 | AD27: 25984 | AE27: 128 | AF27: 2 | AG27: 8 | AH27: 721.86 | AI27: 16.204 | AL27: cpu-tune-flags | AM27: 3 | AN27: WR00L2L2 | AO27: 18368 | AP27: 64 | AQ27: 2 | AR27: 4 | AS27: 2271.34 | AT27: 1.8191
A28: optimized-big-arch-tune-flags | B28: 4 | C28: WR00L2L2 | D28: 25984 | E28: 128 | F28: 2 | G28: 8 | H28: 404.51 | I28: 28.916 | M28: big-cpu | N28: 3 | O28: WR00L2L2 | P28: 25984 | Q28: 128 | R28: 2 | S28: 8 | T28: 370.85 | U28: 31.54 | W28: 45090 | X28: 0.76600694 | AA28: optimized-small-arch-tune | AB28: 4 | AC28: WR00L2L2 | AD28: 25984 | AE28: 128 | AF28: 2 | AG28: 8 | AH28: 720.97 | AI28: 16.224 | AL28: cpu-tune-flags | AM28: 4 | AN28: WR00L2L2 | AO28: 18368 | AP28: 64 | AQ28: 2 | AR28: 4 | AS28: 2342.5 | AT28: 1.7639
A29: optimized-big-arch7a-tune | B29: 1 | C29: WR00L2L2 | D29: 25984 | E29: 128 | F29: 2 | G29: 8 | H29: 714.65 | I29: 16.367 | J29: =AVERAGE(I29:I32) -> 16.38475 | K29: =A29 -> optimized-big-arch7a-tune | M29: big-cpu | N29: 4 | O29: WR00L2L2 | P29: 25984 | Q29: 128 | R29: 2 | S29: 8 | T29: 371.38 | U29: 31.495 | V29: =AVERAGE(U29:U32) -> 34.755 | W29: 45090 | X29: 0.77075231 | AA29: optimized-small-atlasarch-tune2 | AB29: 1 | AC29: WR00L2L2 | AD29: 25984 | AE29: 128 | AF29: 2 | AG29: 8 | AH29: 405.36 | AI29: 28.855 | AL29: arch-native-tune-flags | AM29: 1 | AN29: WR00L2L2 | AO29: 18368 | AP29: 64 | AQ29: 2 | AR29: 4 | AS29: 2237.62 | AT29: 1.8466
A30: optimized-big-arch7a-tune | B30: 2 | C30: WR00L2L2 | D30: 25984 | E30: 128 | F30: 2 | G30: 8 | H30: 712.5 | I30: 16.417 | M30: big-noMHz | N30: 0 | O30: WR00L2L2 | P30: 25984 | Q30: 128 | R30: 2 | S30: 8 | T30: 325.42 | U30: 35.944 | W30: 45090 | X30: 0.77466435 | AA30: optimized-small-atlasarch-tune2 | AB30: 2 | AC30: WR00L2L2 | AD30: 25984 | AE30: 128 | AF30: 2 | AG30: 8 | AH30: 405.77 | AI30: 28.826 | AL30: arch-native-tune-flags | AM30: 2 | AN30: WR00L2L2 | AO30: 18368 | AP30: 64 | AQ30: 2 | AR30: 4 | AS30: 2233.42 | AT30: 1.85
A31: optimized-big-arch7a-tune | B31: 3 | C31: WR00L2L2 | D31: 25984 | E31: 128 | F31: 2 | G31: 8 | H31: 712.99 | I31: 16.405 | M31: big-noMHz | N31: 1 | O31: WR00L2L2 | P31: 25984 | Q31: 128 | R31: 2 | S31: 8 | T31: 326.02 | U31: 35.877 | W31: 45090 | X31: 0.77857639 | AA31: optimized-small-atlasarch-tune2 | AB31: 3 | AC31: WR00L2L2 | AD31: 25984 | AE31: 128 | AF31: 2 | AG31: 8 | AH31: 406.6 | AI31: 28.767 | AL31: arch-native-tune-flags | AM31: 3 | AN31: WR00L2L2 | AO31: 18368 | AP31: 64 | AQ31: 2 | AR31: 4 | AS31: 2162.59 | AT31: 1.9106
A32: optimized-big-arch7a-tune | B32: 4 | C32: WR00L2L2 | D32: 25984 | E32: 128 | F32: 2 | G32: 8 | H32: 715.38 | I32: 16.35 | M32: big-noMHz | N32: 2 | O32: WR00L2L2 | P32: 25984 | Q32: 128 | R32: 2 | S32: 8 | T32: 327.61 | U32: 35.704 | W32: 45090 | X32: 0.78251157 | AA32: optimized-small-atlasarch-tune2 | AB32: 4 | AC32: WR00L2L2 | AD32: 25984 | AE32: 128 | AF32: 2 | AG32: 8 | AH32: 405.95 | AI32: 28.813 | AL32: arch-native-tune-flags | AM32: 4 | AN32: WR00L2L2 | AO32: 18368 | AP32: 64 | AQ32: 2 | AR32: 4 | AS32: 2239.5 | AT32: 1.845
A33: optimized-big-arch7a-tune-flags | B33: 1 | C33: WR00L2L2 | D33: 25984 | E33: 128 | F33: 2 | G33: 8 | H33: 401.1 | I33: 29.161 | J33: =AVERAGE(I33:I36) -> 28.958 | K33: =A33 -> optimized-big-arch7a-tune-flags | M33: big-noMHz | N33: 3 | O33: WR00L2L2 | P33: 25984 | Q33: 128 | R33: 2 | S33: 8 | T33: 324.89 | U33: 36.002 | V33: =AVERAGE(U33:U36) -> 33.2705 | W33: 45090 | X33: 0.78641204 | AL33: cpu-tune-overr-flags | AM33: 1 | AN33: WR00L2L2 | AO33: 18368 | AP33: 64 | AQ33: 2 | AR33: 4 | AS33: 2273.1 | AT33: 1.8177
A34: optimized-big-arch7a-tune-flags | B34: 2 | C34: WR00L2L2 | D34: 25984 | E34: 128 | F34: 2 | G34: 8 | H34: 404.88 | I34: 28.89 | M34: big-noMHz | N34: 4 | O34: WR00L2L2 | P34: 25984 | Q34: 128 | R34: 2 | S34: 8 | T34: 326.54 | U34: 35.821 | W34: 45090 | X34: 0.79033565 | AL34: cpu-tune-overr-flags | AM34: 2 | AN34: WR00L2L2 | AO34: 18368 | AP34: 64 | AQ34: 2 | AR34: 4 | AS34: 2107.93 | AT34: 1.9602
A35: optimized-big-arch7a-tune-flags | B35: 3 | C35: WR00L2L2 | D35: 25984 | E35: 128 | F35: 2 | G35: 8 | H35: 405.22 | I35: 28.865 | M35: big-flags | N35: 0 | O35: WR00L2L2 | P35: 25984 | Q35: 128 | R35: 2 | S35: 8 | T35: 383.49 | U35: 30.5 | W35: 45093 | X35: 0.94741898 | AL35: cpu-tune-overr-flags | AM35: 3 | AN35: WR00L2L2 | AO35: 18368 | AP35: 64 | AQ35: 2 | AR35: 4 | AS35: 2215 | AT35: 1.8654
A36: optimized-big-arch7a-tune-flags | B36: 4 | C36: WR00L2L2 | D36: 25984 | E36: 128 | F36: 2 | G36: 8 | H36: 404.5 | I36: 28.916 | M36: big-flags | N36: 1 | O36: WR00L2L2 | P36: 25984 | Q36: 128 | R36: 2 | S36: 8 | T36: 380.27 | U36: 30.759 | W36: 45093 | X36: 0.95194444 | AL36: cpu-tune-overr-flags | AM36: 4 | AN36: WR00L2L2 | AO36: 18368 | AP36: 64 | AQ36: 2 | AR36: 4 | AS36: 2250.13 | AT36: 1.8363
A37: optimized-small | B37: 1 | C37: WR00L2L2 | D37: 25984 | E37: 128 | F37: 2 | G37: 8 | H37: 1390.29 | I37: 8.4132 | J37: =AVERAGE(I37:I40) -> 8.410325 | K37: =A37 -> optimized-small | M37: big-flags | N37: 2 | O37: WR00L2L2 | P37: 25984 | Q37: 128 | R37: 2 | S37: 8 | T37: 380.43 | U37: 30.746 | V37: =AVERAGE(U37:U40) -> 30.30725 | W37: 45093 | X37: 0.95645833
A38: optimized-small | B38: 2 | C38: WR00L2L2 | D38: 25984 | E38: 128 | F38: 2 | G38: 8 | H38: 1391.29 | I38: 8.4071 | M38: big-flags | N38: 3 | O38: WR00L2L2 | P38: 25984 | Q38: 128 | R38: 2 | S38: 8 | T38: 380.19 | U38: 30.765 | W38: 45093 | X38: 0.96097222
A39: optimized-small | B39: 3 | C39: WR00L2L2 | D39: 25984 | E39: 128 | F39: 2 | G39: 8 | H39: 1390.25 | I39: 8.4134 | M39: big-flags | N39: 4 | O39: WR00L2L2 | P39: 25984 | Q39: 128 | R39: 2 | S39: 8 | T39: 379.9 | U39: 30.789 | W39: 45093 | X39: 0.96548611
A40: optimized-small | B40: 4 | C40: WR00L2L2 | D40: 25984 | E40: 128 | F40: 2 | G40: 8 | H40: 1391.22 | I40: 8.4076 | M40: big-arch-tune-flags | N40: 0 | O40: WR00L2L2 | P40: 25984 | Q40: 128 | R40: 2 | S40: 8 | T40: 404.33 | U40: 28.929 | W40: 45093 | X40: 0.9703125
...

Sheet Arch details
A1: SBC | B1: Cores | C1: march | D1: mcpu | E1: mtune | F1: fpu | G1: mfloat-abi | J1: ostalo | K1: ostalo (Thumb)
A2: Rpi 1B | C2: armv6 | D2: arm1176jzf-s | E2: arm1176jzf-s | F2: vfpv2 (alias is vfp) | G2: hard | K2: Thumb | L2: 16KB L1 and no L2
A3: Cubieboard2 | C3: armv7-a | D3: cortex-a7 | E3: cortex-a7 | F3: neon-vfpv4 | G3: hard | J3: -funsafe-math-optimizations | K3: Thumb-2
A4: OdroidU3 | C4: armv7-a | D4: cortex-a9 | E4: cortex-a9 | F4: neon-vfpv3 (alias is neon) | G4: hard | J4: -funsafe-math-optimizations | K4: Thumb or Thumb-2 | L4: 1MB L2 cache total? From paper…
A5: OdroidMC1 | B5: LITTLE | C5: armv7-a | D5: cortex-a7 | E5: cortex-a7 | F5: neon-vfpv4 | G5: hard | J5: -funsafe-math-optimizations | K5: Thumb-2 | L5: 2 sockets, 2,5MB L2 cache per socket
B6: Big | C6: armv7-a | D6: cortex-a15 | E6: cortex-a15 | F6: neon-vfpv4 | G6: hard | J6: -funsafe-math-optimizations | K6: Thumb-2
A11: HPL Runs (fixed parameters) | C11: Number of nodes | D11: Node | E11: Total memory of a node (kB) | F11: N, alpha | G11: N, alpha (NB round) | H11: N, beta | I11: N, beta (NB round) | J11: NB | K11: P | L11: Q | M11: Ns difference | N11: Half of the Ns difference | O11: N1 | P11: N2 | Q11: N3
C12: 1 | D12: OdroidMC1 | E12: 2042436 | F12: =$B$13*SQRT(($C12*$E12*1024)/8) -> 12935.082 | G12: =_xlfn.CEILING.MATH(F12/J12)*J12 -> 13056 | H12: =SQRT($B$13*($C12*$E12*1024)/8) -> 14461.862 | I12: =_xlfn.CEILING.MATH(H12/J12)*J12 -> 14464 | J12: 128 | K12: 2 | L12: 8 | M12: =I12-G12 -> 1408 | N12: =M12/2 -> 704 | O12: =G12 -> 13056 | P12: =_xlfn.CEILING.MATH((O12+N12)/J12)*J12 -> 13824 | Q12: =_xlfn.CEILING.MATH((P12+N12)/J12)*J12 -> 14592
A13: Percentage of mem | B13: 0.8 | C13: 4 | D13: OdroidMC1 | E13: 2042436 | F13: =$B$13*SQRT(($C13*$E13*1024)/8) -> 25870.165 | G13: =_xlfn.CEILING.MATH(F13/J13)*J13 -> 25984 | H13: =SQRT($B$13*($C13*$E13*1024)/8) -> 28923.724 | I13: =_xlfn.CEILING.MATH(H13/J13)*J13 -> 28928 | J13: 128 | K13: 2 | L13: 2 | M13: =I13-G13 -> 2944 | N13: =M13/2 -> 1472 | O13: =G13 -> 25984 | P13: =_xlfn.CEILING.MATH((O13+N13)/J13)*J13 -> 27520 | Q13: =_xlfn.CEILING.MATH((P13+N13)/J13)*J13 -> 29056
A21: Board | B21: Odroid MC1 Solo (Revised Odroid-XU4) | E21: Board | F21: Odroid MC1 (Odroid XU4)
A22: SoC | B22: Exynos5422 | E22: OS | F22: Ubuntu 18.04.6 LTS
A23: CPU | B23: ARM Cortex-A7 | C23: ARM Cortex-A15 | E23: Kernel | F23: 4.14.180-178 armv7l
A24: ARM ISA | B24: ARMv7-A | E24: MPI implementation | F24: MPICH 3.4.3
A25: Cores/Clock | B25: 4 × 1.4GHz | C25: 4 × 2.0GHz | E25: BLAS 1 | F25: ATLAS 3.10.3
A26: Cache | B26: 512 KB of L2 cache | C26: 2 MB of L2 cache | E26: BLAS 2 | F26: OpenBLAS 0.3.23
A27: DP FLOPs/cycle | B27: 0.5 | C27: 2 | E27: HPL | F27: Netlib, 2.3
A28: Rpeak | B28: 0.75 GFLOPs | C28: 4 GFLOPs
A29: Memory | B29: 2 GB LP-DDR3, 750 MHz
A30: Ethernet [Mbps] | B30: 10/100/1000
A31: Storage employed | B31: MicroSD: Kingston Canvas Select Plus, 16GB, U1, V10, A1 (initially) Kingston EP MicroSDXC, EP Series 64GB MICRO SDXC V30 A1 (later measurements)
A32: Release year** | B32: 2015

Sheet HPL_Builds
A1: Odroid MC1 | C1: Flags used for building ATLAS | D1: Flags used for flagsearching - mandatory | E1: Flags used for building HPL | F1: Machine setup for building HPL | G1: Gflops | H1: NOTE
A2: 1 | B2: optimized-small | C2: -D c -DWALL -b 32 -A ARMa7 --force-tids="4 0 1 2 3" | D2: -O2 -mcpu=cortex-a7 -fno-schedule-insns -fselective-scheduling2 | E2: -O2 -mcpu=cortex-a7 -fno-schedule-insns -fselective-scheduling2 | F2: odroid12 | K2: optimized-small | P2: 2024
A3: 2 | B3: optimized-small-atlasarch-tune | C3: -D c -DWALL -b 32 -A ARMa7 --force-tids="4 0 1 2 3" -Fa al "-mcpu=cortex-a7 -mfloat-abi=hard -mfpu=neon-vfpv4" | D3: -O2 -mcpu=cortex-a7 -fno-schedule-insns -fselective-scheduling2 -mfloat-abi=hard -mfpu=neon-vfpv4 | E3: -O2 -fselective-scheduling2 -mcpu=cortex-a7 -mfloat-abi=hard -mfpu=neon-vfpv4 (implied by -A ARMa15 and custom ones) | F3: odroid10 | K3: optimized-small-atlasarch-tune
A4: 3 | B4: optimized-small-arch-tune | C4: -D c -DWALL -b 32 --force-tids="4 0 1 2 3" -F al "-march=armv7 -mtune=cortex-a7 -mfloat-abi=hard -mfpu=neon-vfpv4" | D4: -march=armv7 -mtune=cortex-a7 -mfloat-abi=hard -mfpu=neon-vfpv4 | E4: -march=armv7 -mtune=cortex-a7 -mfloat-abi=hard -mfpu=neon-vfpv4 | F4: Odroid13 | H4: overridea li -F i task-set? | K4: optimized-small-arch-tune
A5: 4 | B5: optimized-big | C5: -D c -DWALL -b 32 -A ARMa15 --force-tids="4 4 5 6 7" | D5: -O2 -fno-schedule-insns -fno-schedule-insns2 -fprefetch-loop-arrays | E5: -O2 -fselective-scheduling2 (implied by -A ARMa15) | F5: Odroid10 | H5: made without taskset | K5: optimized-small-atlasarch-tune2
A6: 5 | B6: optimized-big-atlasarch-tune | C6: -D c -DWALL -b 32 -A ARMa15 --force-tids="4 4 5 6 7" -Fa al "-mcpu=cortex-a15 -mfloat-abi=hard -mfpu=neon-vfpv4" | D6: -O2 -fno-schedule-insns -fno-schedule-insns2 -fprefetch-loop-arrays -mcpu=cortex-a15 -mfloat-abi=hard -mfpu=neon-vfpv4 | E6: -O2 -fselective-scheduling2 -mcpu=cortex-a15 -mfloat-abi=hard -mfpu=neon-vfpv4 (implied by -A ARMa15 and the custom ones) | F6: Odroid10 | H6: made without taskset | K6: optimized-small-arch-tune-flags
A7: 6 | B7: optimized-big-arch-tune | C7: -D c -DWALL -b 32 --force-tids="4 4 5 6 7" -F al "-march=armv7 -mtune=cortex-a15 -mfloat-abi=hard -mfpu=neon-vfpv4" | D7: -march=armv7 -mtune=cortex-a15 -mfloat-abi=hard -mfpu=neon-vfpv4 | E7: -march=armv7 -mtune=cortex-a15 -mfloat-abi=hard -mfpu=neon-vfpv4 | F7: Odroid12 | K7: optimized-small-arch-tune-flags-taskset
A8: 7 | B8: optimized-small-atlasarch-tune2 | C8: -D c -DWALL -b 32 -A ARMa7 --force-tids="4 0 1 2 3" -Fa al "-mtune=cortex-a7 -mfloat-abi=hard -mfpu=neon-vfpv4" | D8: -O2 -mcpu=cortex-a7 -fno-schedule-insns -fselective-scheduling2 | E8: -O2 -fselective-scheduling2 -mtune=cortex-a7 -mfloat-abi=hard -mfpu=neon-vfpv4 | F8: Odroid11 | K8: optimized-small-flags
A9: 8 | B9: optimized-big-atlasarch-tune2 | C9: -D c -DWALL -b 32 -A ARMa15 --force-tids="4 4 5 6 7" -Fa al "-mtune=cortex-a15 -mfloat-abi=hard -mfpu=neon-vfpv4" | D9: -O2 -fno-schedule-insns -fno-schedule-insns2 -fprefetch-loop-arrays -mtune=cortex-a15 -mfloat-abi=hard -mfpu=neon-vfpv4 | E9: -O2 -fselective-scheduling2 -mtune=cortex-a15 -mfloat-abi=hard -mfpu=neon-vfpv4 (implied by -A ARMa15 and the custom ones) | F9: Odroid10 | H9: made without taskset | K9: small-cpu
A10: 9 | B10: optimized-small-arch-tune-flags | C10: -D c -DWALL -b 32 --force-tids="4 0 1 2 3" -F al "-O1 -march=armv7 -mtune=cortex-a7 -mfloat-abi=hard -mfpu=neon-vfpv4 -fno-expensive-optimizations -fschedule-insns2 -frename-registers" | E10: -O1 -march=armv7 -mtune=cortex-a7 -mfloat-abi=hard -mfpu=neon-vfpv4 -fno-expensive-optimizations -fschedule-insns2 -frename-registers | F10: Odroid12
A11: 10 | B11: optimized-big-arch7a-tune | C11: -D c -DWALL -b 32 --force-tids="4 4 5 6 7" -m 2000 -F al "-march=armv7-a -mtune=cortex-a15 -mfloat-abi=hard -mfpu=neon-vfpv4" | D11: -march=armv7-a -mtune=cortex-a15 -mfloat-abi=hard -mfpu=neon-vfpv4 | E11: -march=armv7-a -mtune=cortex-a15 -mfloat-abi=hard -mfpu=neon-vfpv4 | F11: Odroid13
A12: 11 | B12: optimized-big-flags | C12: -D c -DWALL -b 32 --force-tids="4 4 5 6 7" -m 2000 -Fa al "-O2 -fno-schedule-insns -fno-schedule-insns2 -fprefetch-loop-arrays -mfpu=neon-vfpv4 -fno-peephole2" | E12: -O2 -fno-schedule-insns -fno-schedule-insns2 -fprefetch-loop-arrays -mfpu=neon-vfpv4 -fno-peephole2 | F12: Odroid10
A13: 12 | B13: optimized-big-arch-tune-flags | C13: -D c -DWALL -b 32 --force-tids="4 4 5 6 7" -m 2000 -F al "-O1 -march=armv7 -mtune=cortex-a15 -mfloat-abi=hard -mfpu=neon-vfpv4 -fschedule-insns2 -fselective-scheduling2 -fno-move-loop-invariants" | E13: -O1 -march=armv7 -mtune=cortex-a15 -mfloat-abi=hard -mfpu=neon-vfpv4 -fschedule-insns2 -fselective-scheduling2 -fno-move-loop-invariants | F13: Odroid11
A14: 13 | B14: optimized-big-arch7a-tune-flags | C14: -D c -DWALL -b 32 --force-tids="4 4 5 6 7" -m 2000 -F al "-O1 -march=armv7-a -mtune=cortex-a15 -mfloat-abi=hard -mfpu=neon-vfpv4 -fschedule-insns2 -fselective-scheduling2 -fivopts" | E14: -O1 -march=armv7-a -mtune=cortex-a15 -mfloat-abi=hard -mfpu=neon-vfpv4 -fschedule-insns2 -fselective-scheduling2 -fivopts | F14: Odroid13
A15: 14 | B15: optimized-small-flags | C15: -D c -DWALL -b 32 -A ARMa7 --force-tids="4 0 1 2 3" -Fa al "-O2 -mcpu=cortex-a7 -fno-schedule-insns -fselective-scheduling2 -frename-registers -fno-tree-pre" | E15: -O2 -mcpu=cortex-a7 -fno-schedule-insns -fselective-scheduling2 -frename-registers -fno-tree-pre | F15: Odroid11
A16: 15 | B16: big-cpu | C16: -D c -DWALL -b 32 -m 2000 --force-tids="4 4 5 6 7" -Fa al "-mcpu=cortex-a15 -mfloat-abi=hard -mfpu=neon-vfpv4" | D16: -mcpu=cortex-a15 -mfloat-abi=hard -mfpu=neon-vfpv4 | E16: -mcpu=cortex-a15 -mfloat-abi=hard -mfpu=neon-vfpv4 | F16: Odorid12
A17: 16 | B17: small-cpu | C17: -D c -DWALL -b 32 --force-tids="4 0 1 2 3" -Fa al "-mcpu=cortex-a7 -mfloat-abi=hard -mfpu=neon-vfpv4" | D17: -mcpu=cortex-a7 -mfloat-abi=hard -mfpu=neon-vfpv4 | E17: -mcpu=cortex-a7 -mfloat-abi=hard -mfpu=neon-vfpv4 | F17: Odroid13
A18: 17 | B18: optimized-big-noMHZ | C18: -D c -DWALL -b 32 -A ARMa15 --force-tids="4 4 5 6 7" | D18: -O2 -fno-schedule-insns -fno-schedule-insns2 -fprefetch-loop-arrays | E18: -O2 -fno-schedule-insns -fno-schedule-insns2 -fprefetch-loop-arrays | F18: Odroid11
B20: New (from the actual config files)
B21: small | C21: -D c -DWALL -b 32 -A ARMa7 --force-tids="4 0 1 2 3" | D21: 8.52848
B22: small-arch-tune | C22: -D c -DWALL -b 32 --force-tids="4 0 1 2 3" -F alg "-march=armv7 -mtune=cortex-a7 -mfloat-abi=hard -mfpu=neon-vfpv4" | D22: 5.70352
B23: small-arch-tune-flags | C23: -D c -DWALL -b 32 --force-tids="4 0 1 2 3" -Fa alg "-O1 -march=armv7 -mtune=cortex-a7 -mfloat-abi=hard -mfpu=neon-vfpv4 -fno-expensive-optimizations -fschedule-insns -fschedule-insns2 -funroll-all-loops" | D23: 8.38768
B24: small-atlasarch-tune | C24: -D c -DWALL -b 32 --force-tids="4 0 1 2 3" -Fa alg "-mcpu=cortex-a7 -mfloat-abi=hard -mfpu=neon-vfpv4" | D24: 7.2748
B25: small-atlasarch-tune2 | C25: -D c -DWALL -b 32 -A ARMa7 --force-tids="4 0 1 2 3" -Fa alg "-mtune=cortex-a7 -mfloat-abi=hard -mfpu=neon-vfpv4" | D25: 7.2753
B26: small-atlasarch-tune2-flags | C26: -D c -DWALL -b 32 --force-tids="4 0 1 2 3" -Fa alg "-O1 -fselective-scheduling2 -mtune=cortex-a7 -mfloat-abi=hard -mfpu=neon-vfpv4 -fno-expensive-optimizations -fschedule-insns -fschedule-insns2 -fselective-scheduling" | D26: 8.08884
B27: small-atlasarch-tune-flags | C27: -D c -DWALL -b 32 --force-tids="4 0 1 2 3" -Fa alg "-O1 -fselective-scheduling2 -mcpu=cortex-a7 -mfloat-abi=hard -mfpu=neon-vfpv4 -fno-expensive-optimizations -fschedule-insns2" | D27: 8.51756
B28: small-cpu | C28: -D c -DWALL -b 32 --force-tids="4 0 1 2 3" -Fa alg "-mcpu=cortex-a7 -mfloat-abi=hard -mfpu=neon-vfpv4" | D28: 7.26552
B29: small-cpu-flags | C29: -D c -DWALL -b 32 --force-tids="4 0 1 2 3" -Fa alg "-O1 -mcpu=cortex-a7 -mfloat-abi=hard -mfpu=neon-vfpv4 -fno-expensive-optimizations -fschedule-insns -fschedule-insns2 -funroll-all-loops" | D29: 8.38574
B30: small-flags | C30: -D c -DWALL -b 32 --force-tids="4 0 1 2 3" -Fa alg "-O1 -mcpu=cortex-a7 -fno-schedule-insns -fselective-scheduling2 -fschedule-insns -fschedule-insns2 -mfpu=neon-vfpv4 -fselective-scheduling" | D30: 8.09026
B32: BIG:
B33: big | C33: -D c -DWALL -b 32 -A ARMa15 -m 2000 --force-tids="4 4 5 6 7"
B34: big-arch-tune | C34: -D c -DWALL -b 32 --force-tids="4 4 5 6 7" -m 2000 -Fa alg "-march=armv7 -mtune=cortex-a15 -mfloat-abi=hard -mfpu=neon-vfpv4"
B35: big-atlasarch-tune2 | C35: -D c -DWALL -b 32 -A ARMa15 --force-tids="4 4 5 6 7" -Fa alg "-mtune=cortex-a15 -mfloat-abi=hard -mfpu=neon-vfpv4"
B36: big-arch7a-tune | C36: -D c -DWALL -b 32 --force-tids="4 4 5 6 7" -m 2000 -Fa alg "-march=armv7-a -mtune=cortex-a15 -mfloat-abi=hard -mfpu=neon-vfpv4"
B37: big-cpu | C37: -D c -DWALL -b 32 -m 2000 --force-tids="4 4 5 6 7" -Fa alg "-mcpu=cortex-a15 -mfloat-abi=hard -mfpu=neon-vfpv4"
B38: big-noMHz | C38: -D c -DWALL -b 32 -A ARMa15 --force-tids="4 4 5 6 7"
B39: big-flags | C39: -D c -DWALL -b 32 --force-tids="4 4 5 6 7" -m 2000 -Fa alg "-O3 -fno-schedule-insns -fno-schedule-insns2 -fprefetch-loop-arrays -mfpu=neon-vfpv4 -mfloat-abi=hard"
B40: big-arch-tune-flags | C40: -D c -DWALL -b 32 --force-tids="4 4 5 6 7" -m 2000 -Fa alg "-Os -march=armv7 -mtune=cortex-a15 -mfloat-abi=hard -mfpu=neon-vfpv4 -fschedule-insns2 -mfloat-abi=hard -fselective-scheduling2 -fno-tree-ter"
B41: big-atlasarch-tune2-flags | C41: -D c -DWALL -b 32 --force-tids="4 4 5 6 7" -m 2000 -Fa alg "-O1 -fno-schedule-insns -fno-schedule-insns2 -fprefetch-loop-arrays -mtune=cortex-a7 -mfloat-abi=hard -mfpu=neon-vfpv4 -fschedule-insns2 -fsched2-use-superblocks"
B42: big-arch7a-tune-flags | C42: -D c -DWALL -b 32 --force-tids="4 4 5 6 7" -m 2000 -Fa alg "-Os -march=armv7-a -mtune=cortex-a15 -mfloat-abi=hard -mfpu=neon-vfpv4 -fselective-scheduling2 -fmodulo-sched -fno-tree-ter"
...

Sheet ATLAS builds
A1: OdroidMC1 | C1: Flags used for building | D1: Flags used for flagsearching - mandatory | E1: Flags used for flagsearching - optional | F1: Machine originally built on | G1: Needs flagsearching | H1: Flagsearched (d) | I1: Flagsearched (s) No need! HPL uses only double precision! See ATLAS install manual | J1: Flagsearched (Td) | K1: Kernel | M1: NOTE | O1: TODO
A2: 1 | B2: optimized-small | C2: -D c -DWALL -b 32 -A ARMa7 --force-tids="4 0 1 2 3" | D2: -O2 -mcpu=cortex-a7 -fno-schedule-insns -fselective-scheduling2 | E2: -mfloat-abi=hard -mfpu=neon-vfpv4 | F2: Odroid11 | G2: X | H2: X | J2: X | K2: 1 | M2: OK build prema najnoviji saznanjima. | O2: In progress
A3: 2 | B3: optimized-small-atlasarch-tune | C3: -D c -DWALL -b 32 -A ARMa7 --force-tids="4 0 1 2 3" -Fa al "-mcpu=cortex-a7 -mfloat-abi=hard -mfpu=neon-vfpv4" | D3: -O2 -mcpu=cortex-a7 -fno-schedule-insns -fselective-scheduling2 -mfloat-abi=hard -mfpu=neon-vfpv4 | E3: -march=armv7-a -march=armv7 | F3: Odroid11 | G3: X | J3: X | K3: 1 | M3: NIJE POTREBAN BUILD, isto možemo postići s buildom 1 uz dodatak u flagsearchu mfloat mfpu. | O3: Freshly finished
A4: 3 | B4: optimized-small-arch-tune | C4: -D c -DWALL -b 32 --force-tids="4 0 1 2 3" -F al "-march=armv7 -mtune=cortex-a7 -mfloat-abi=hard -mfpu=neon-vfpv4" | D4: -march=armv7 -mtune=cortex-a7 -mfloat-abi=hard -mfpu=neon-vfpv4 | E4: -march=armv7-a | F4: Odroid13 | G4: X | H4: X | J4: X | K4: 1 | M4: OK build prema najnoviji saznanjima. | O4: Done
A5: 4 | B5: optimized-big | C5: -D c -DWALL -b 32 -A ARMa15 -m 2000 --force-tids="4 4 5 6 7" | D5: -O2 -fno-schedule-insns -fno-schedule-insns2 -fprefetch-loop-arrays | E5: -march=armv7 -march=armv7-a -mcpu=cortex-a15 -mtune=cortex-a15 -mfloat-abi=hard -mfpu=neon-vfpv4 | F5: Odroid10 | G5: X | J5: X | K5: 2 | M5: OK build prema najnoviji saznanjima. ARMa15 implicira "-O2 -fno-schedule-insns -fno-schedule-insns2 -fprefetch-loop-arrays" za dmc kompajler (koji je gcc kompajler za MM kernel u duploj precinosti) | O5: TODO with the same settings!
A6: 5 | B6: optimized-big-atlasarch-tune | C6: -D c -DWALL -b 32 -A ARMa15 --force-tids="4 4 5 6 7" -Fa al "-mcpu=cortex-a15 -mfloat-abi=hard -mfpu=neon-vfpv4" | D6: -O2 -fno-schedule-insns -fno-schedule-insns2 -fprefetch-loop-arrays -mcpu=cortex-a15 -mfloat-abi=hard -mfpu=neon-vfpv4 | F6: Odroid10 | G6: X | H6: X | J6: X | K6: 2 | M6: Nije ok build jer kombinira optimizacijske flagove (u ARMa15). DO THE FLAGSEARCH
A7: 6 | B7: optimized-big-arch-tune | C7: -D c -DWALL -b 32 --force-tids="4 4 5 6 7" -m 2000 -F al "-march=armv7 -mtune=cortex-a15 -mfloat-abi=hard -mfpu=neon-vfpv4" | D7: -march=armv7 -mtune=cortex-a15 -mfloat-abi=hard -mfpu=neon-vfpv4 | E7: -march=armv7-a | F7: Odroid10 | G7: X | H7: X | J7: X | K7: 1
A8: 7 | B8: optimized-small-atlasarch-tune2 | C8: -D c -DWALL -b 32 -A ARMa7 --force-tids="4 0 1 2 3" -Fa al "-mtune=cortex-a7 -mfloat-abi=hard -mfpu=neon-vfpv4" | D8: -O2 -mcpu=cortex-a7 -fno-schedule-insns -fselective-scheduling2 | E8: -march=armv7-a -march=armv7 | F8: Odroid11 | J8: X | K8: 1 | M8: NIJE POTREBAN BUILD, predefinirani flag -mcpu ne ide u kombinaciji s mtune koji smo dodali. Ostalo rješava build 3
A9: 8 | B9: optimized-big-atlasarch-tune2 | C9: -D c -DWALL -b 32 -A ARMa15 --force-tids="4 4 5 6 7" -Fa al "-mtune=cortex-a15 -mfloat-abi=hard -mfpu=neon-vfpv4" | D9: -O2 -fno-schedule-insns -fno-schedule-insns2 -fprefetch-loop-arrays -mtune=cortex-a15 -mfloat-abi=hard -mfpu=neon-vfpv4 | E9: -march=armv7-a -march=armv7 | F9: Odroid10 | J9: X | K9: 2 | M9: Nije ok build jer kombinira optimizacijske flagove (u ARMa15).
A10: 9 | B10: optimized-small-arch-tune-flags | C10: -D c -DWALL -b 32 --force-tids="4 0 1 2 3" -F al "-O1 -march=armv7 -mtune=cortex-a7 -mfloat-abi=hard -mfpu=neon-vfpv4 -fno-expensive-optimizations -fschedule-insns2 -frename-registers" | F10: Odroid12 | K10: 1
A11: 10 | B11: optimized-big-arch7a-tune | C11: -D c -DWALL -b 32 --force-tids="4 4 5 6 7" -m 2000 -F al "-march=armv7-a -mtune=cortex-a15 -mfloat-abi=hard -mfpu=neon-vfpv4" | D11: -march=armv7-a -mtune=cortex-a15 -mfloat-abi=hard -mfpu=neon-vfpv4 | E11: -march=armv7 | F11: Odroid13 | K11: 1
A12: 11 | B12: optimized-big-flags | C12: -D c -DWALL -b 32 --force-tids="4 4 5 6 7" -m 2000 -Fa al "-O2 -fno-schedule-insns -fno-schedule-insns2 -fprefetch-loop-arrays -mfpu=neon-vfpv4 -fno-peephole2" | F12: Odroid10 | K12: 1
A13: 12 | B13: optimized-big-arch-tune-flags | C13: -D c -DWALL -b 32 --force-tids="4 4 5 6 7" -m 2000 -F al "-O1 -march=armv7 -mtune=cortex-a15 -mfloat-abi=hard -mfpu=neon-vfpv4 -fschedule-insns2 -fselective-scheduling2 -fno-move-loop-invariants" | F13: Odroid11 | K13: 1
A14: 13 | B14: optimized-big-arch7a-tune-flags | C14: -D c -DWALL -b 32 --force-tids="4 4 5 6 7" -m 2000 -F al "-O1 -march=armv7-a -mtune=cortex-a15 -mfloat-abi=hard -mfpu=neon-vfpv4 -fschedule-insns2 -fselective-scheduling2 -fivopts" | F14: Odroid13 | K14: 1 | M14: Nema ga ni na jednom stroju osim na odroid13, no ipak je HPL radio. Znači li to da build ne moram kopirati na strojeve već samo HPL koji je buildan povrh tog builda ATLAS-a? Provjeriti tako da se ovaj build kopira na sve strojeve i pokrene HPL opet. Ako su rez jako slični onda vrijedi to.
A15: 14 | B15: optimized-small-flags | C15: -D c -DWALL -b 32 -A ARMa7 --force-tids="4 0 1 2 3" -Fa al "-O2 -mcpu=cortex-a7 -fno-schedule-insns -fselective-scheduling2 -frename-registers -fno-tree-pre" | F15: Odroid11 | K15: 1 | M15: Poslati ga na odroid10 još!
A16: 15 | B16: big-cpu | C16: -D c -DWALL -b 32 -m 2000 --force-tids="4 4 5 6 7" -Fa al "-mcpu=cortex-a15 -mfloat-abi=hard -mfpu=neon-vfpv4" | D16: -mcpu=cortex-a15 -mfloat-abi=hard -mfpu=neon-vfpv4 | F16: Odorid12
A17: 16 | B17: small-cpu | C17: -D c -DWALL -b 32 --force-tids="4 0 1 2 3" -Fa al "-mcpu=cortex-a7 -mfloat-abi=hard -mfpu=neon-vfpv4" | D17: -mcpu=cortex-a7 -mfloat-abi=hard -mfpu=neon-vfpv4 | F17: Odroid13
A18: 17 | B18: optimized-big-noMHZ | C18: -D c -DWALL -b 32 -A ARMa15 --force-tids="4 4 5 6 7" | D18: -O2 -fno-schedule-insns -fno-schedule-insns2 -fprefetch-loop-arrays | E18: -march=armv7-a -march=armv7 -mcpu=cortex-a15 -mtune=cortex-a15 -mfloat-abi=hard -mfpu=neon-vfpv4 | F18: Odroid11
B20: VARIANTS FOR THE PAPER
D21: ATLAS flags | G21: GCC Flags
B22: Name of the build | C22: All flags used | D22: -A ARMa15 | E22: --force-tids="4 4 5 6 7" | F22: -m 2000 | G22: -march=armv7 | H22: -march=armv7-a | I22: -mtune=cortex-a15 | J22: -mcpu=cortex-a15 | K22: -mfloat-abi=hard | L22: -mfpu=neon-vfpv4 | M22: Optimization level
B23: big | C23: -D c -DWALL -b 32 -A ARMa15 -m 2000 --force-tids="4 4 5 6 7" | D23: Y | E23: Y | F23: Y | G23: N | H23: N | I23: N | J23: N | K23: N | L23: N | N23: 36.308
B24: big-arch-tune | C24: -D c -DWALL -b 32 --force-tids="4 4 5 6 7" -m 2000 -Fa alg "-march=armv7 -mtune=cortex-a15 -mfloat-abi=hard -mfpu=neon-vfpv4" | D24: N | E24: Y | F24: Y | G24: Y | H24: N | I24: Y | J24: N | K24: Y | L24: Y | N24: 32.0022
B25: big-atlasarch-tune2 | C25: -D c -DWALL -b 32 -A ARMa15 --force-tids="4 4 5 6 7" -Fa alg "-mtune=cortex-a15 -mfloat-abi=hard -mfpu=neon-vfpv4" | D25: Y | E25: Y | F25: N | G25: N | H25: N | I25: Y | J25: N | K25: Y | L25: Y | N25: 33.3488
B26: big-arch7a-tune | C26: -D c -DWALL -b 32 --force-tids="4 4 5 6 7" -m 2000 -Fa alg "-march=armv7-a -mtune=cortex-a15 -mfloat-abi=hard -mfpu=neon-vfpv4" | D26: N | E26: Y | F26: Y | G26: Y | H26: N | I26: Y | J26: N | K26: Y | L26: Y | N26: 32.0082
B27: big-cpu | C27: -D c -DWALL -b 32 -m 2000 --force-tids="4 4 5 6 7" -Fa alg "-mcpu=cortex-a15 -mfloat-abi=hard -mfpu=neon-vfpv4" | D27: N | E27: Y | F27: Y | G27: N | H27: N | I27: N | J27: Y | K27: Y | L27: Y | N27: 31.9314
B28: big-noMHz | C28: -D c -DWALL -b 32 -A ARMa15 --force-tids="4 4 5 6 7" | D28: Y | E28: Y | F28: N | G28: N | H28: N | I28: N | J28: N | K28: N | L28: N | N28: 36.295
B29: big-flags | C29: -D c -DWALL -b 32 --force-tids="4 4 5 6 7" -m 2000 -Fa alg "-O3 -fno-schedule-insns -fno-schedule-insns2 -fprefetch-loop-arrays -mfpu=neon-vfpv4 -mfloat-abi=hard" | D29: N | E29: Y | F29: Y | G29: N | H29: N | I29: N | J29: N | K29: Y | L29: Y | M29: -O3 | N29: 31.2112
B30: big-arch-tune-flags | C30: -D c -DWALL -b 32 --force-tids="4 4 5 6 7" -m 2000 -Fa alg "-Os -march=armv7 -mtune=cortex-a15 -mfloat-abi=hard -mfpu=neon-vfpv4 -fschedule-insns2 -mfloat-abi=hard -fselective-scheduling2 -fno-tree-ter" | D30: N | E30: Y | F30: Y | G30: Y | H30: N | I30: Y | J30: N | K30: Y | L30: Y | M30: -Os | N30: 29.316
B31: big-atlasarch-tune2-flags | C31: -D c -DWALL -b 32 --force-tids="4 4 5 6 7" -m 2000 -Fa alg "-O1 -fno-schedule-insns -fno-schedule-insns2 -fprefetch-loop-arrays -mtune=cortex-a7 -mfloat-abi=hard -mfpu=neon-vfpv4 -fschedule-insns2 -fsched2-use-superblocks" | D31: N | E31: Y | F31: Y | G31: N | H31: N | I31: Y | J31: N | K31: Y | L31: Y | M31: -O1 | N31: 32.706
B32: big-arch7a-tune-flags | C32: -D c -DWALL -b 32 --force-tids="4 4 5 6 7" -m 2000 -Fa alg "-Os -march=armv7-a -mtune=cortex-a15 -mfloat-abi=hard -mfpu=neon-vfpv4 -fselective-scheduling2 -fmodulo-sched -fno-tree-ter" | D32: N | E32: Y | F32: Y | G32: N | H32: Y | I32: Y | J32: N | K32: Y | L32: Y | M32: -Os | N32: 29.2004
B33: big-cpu-flags | C33: -D c -DWALL -b 32 --force-tids="4 4 5 6 7" -m 2000 -Fa alg "-O1 -mcpu=cortex-a15 -mfloat-abi=hard -mfpu=neon-vfpv4 -fno-schedule-insns -fschedule-insns2 -fselective-scheduling2 -fno-move-loop-invariants" | D33: N | E33: Y | F33: Y | G33: N | H33: N | I33: N | J33: Y | K33: Y | L33: Y | M33: -O1 | N33: 32.0792
B34: big-noMHz-flags | C34: -D c -DWALL -b 32 --force-tids="4 4 5 6 7" -m 2000 -Fa alg "-O2 -fno-schedule-insns -fno-schedule-insns2 -fprefetch-loop-arrays -mfpu=neon-vfpv4" | D34: N | E34: Y | F34: Y | G34: N | H34: N | I34: N | J34: N | K34: N | L34: Y | M34: -O2 | N34: 31.2734
B38: big | C38: -A ARMa15 -m 2000 | D38: =VLOOKUP(B38,'4 node, builds'!$A$67:$B$78,2,FALSE) -> 36.308
B39: big-arch-tune | C39: -m 2000 -Fa alg "-march=armv7 -mtune=cortex-a15 -mfloat-abi=hard -mfpu=neon-vfpv4" | D39: =VLOOKUP(B39,'4 node, builds'!$A$67:$B$78,2,FALSE) -> 32.0022
B40: big-atlasarch-tune2 | C40: -A ARMa15 -Fa alg "-mtune=cortex-a15 -mfloat-abi=hard -mfpu=neon-vfpv4" | D40: =VLOOKUP(B40,'4 node, builds'!$A$67:$B$78,2,FALSE) -> 33.3488
B41: big-arch7a-tune | C41: -m 2000 -Fa alg "-march=armv7-a -mtune=cortex-a15 -mfloat-abi=hard -mfpu=neon-vfpv4" | D41: =VLOOKUP(B41,'4 node, builds'!$A$67:$B$78,2,FALSE) -> 32.0082
B42: big-cpu | C42: -m 2000 -Fa alg "-mcpu=cortex-a15 -mfloat-abi=hard -mfpu=neon-vfpv4" | D42: =VLOOKUP(B42,'4 node, builds'!$A$67:$B$78,2,FALSE) -> 31.9314
B43: big-noMHz | C43: -A ARMa15 | D43: =VLOOKUP(B43,'4 node, builds'!$A$67:$B$78,2,FALSE) -> 36.295
B44: big-flags | C44: -m 2000 -Fa alg "-O3 -fno-schedule-insns -fno-schedule-insns2 -fprefetch-loop-arrays -mfpu=neon-vfpv4 -mfloat-abi=hard" | D44: =VLOOKUP(B44,'4 node, builds'!$A$67:$B$78,2,FALSE) -> 31.2112
...

Sheet ATLAS make time results
C1: Single precision | S1: Double precision
C2: Real | K2: Complex | S2: Real | AA2: Complex
C3: kSelMM | D3: kGenMM | E3: kMM_NT | F3: kMM_TN | G3: BIG_MM | H3: kMV_N | I3: kMV_T | J3: kGER | K3: kSelMM | L3: kGenMM | M3: kMM_NT | N3: kMM_TN | O3: BIG_MM | P3: kMV_N | Q3: kMV_T | R3: kGER | S3: kSelMM | T3: kGenMM | U3: kMM_NT | V3: kMM_TN | W3: BIG_MM | X3: kMV_N | Y3: kMV_T | Z3: kGER | AA3: kSelMM | AB3: kGenMM | AC3: kMM_NT | AD3: kMM_TN | AE3: BIG_MM | AF3: kMV_N | AG3: kMV_T | AH3: kGER
A14: OdroidMC1
A15: 1 | B15: optimized-small | C15: {=TRANSPOSE((OFFSET($D$27,(ROW(K1)-1)*8,0)):(OFFSET($D$34,(ROW(K1)-1)*8,0)))} -> 264.5 | D15: 186.9 | E15: 181.1 | F15: 179 | G15: 83 | H15: 77.5 | I15: 64.9 | J15: 49.3 | K15: {=TRANSPOSE((OFFSET($E$27,(ROW(L1)-1)*8,0)):(OFFSET($E$34,(ROW(L1)-1)*8,0)))} -> 246.5 | L15: 200.1 | M15: 166.1 | N15: 188.8 | O15: 77.4 | P15: 70.9 | Q15: 56.6 | R15: 45.9 | S15: {=TRANSPOSE((OFFSET($F$27,(ROW(M1)-1)*8,0)):(OFFSET($F$34,(ROW(M1)-1)*8,0)))} -> 257.3 | T15: 190.2 | U15: 189.9 | V15: 192.3 | W15: 75 | X15: 119.3 | Y15: 106.9 | Z15: 98.3 | AA15: {=TRANSPOSE((OFFSET($G$27,(ROW(N1)-1)*8,0)):(OFFSET($G$34,(ROW(N1)-1)*8,0)))} -> 243.8 | AB15: 202.7 | AC15: 175.9 | AD15: 208.1 | AE15: 70 | AF15: 108 | AG15: 97.2 | AH15: 66.6 | AI15: {=TRANSPOSE((OFFSET($H$27,(ROW(O1)-1)*8,0)):(OFFSET($H$34,(ROW(O1)-1)*8,0)))} -> 246.1 | AJ15: 196.3 | AK15: 154 | AL15: 169.2 | AM15: 44.1 | AN15: 34.5 | AO15: 48.9 | AP15: 30.8 | AQ15: {=TRANSPOSE((OFFSET($I$27,(ROW(P1)-1)*8,0)):(OFFSET($I$34,(ROW(P1)-1)*8,0)))} -> 240.6 | AR15: 160 | AS15: 141.8 | AT15: 149.4 | AU15: 41.1 | AV15: 33.2 | AW15: 47.6 | AX15: 27.6 | AY15: {=TRANSPOSE((OFFSET($J$27,(ROW(Q1)-1)*8,0)):(OFFSET($J$34,(ROW(Q1)-1)*8,0)))} -> 244 | AZ15: 208.7 | BA15: 172 | BB15: 171.5 | BC15: 45.8 | BD15: 71.4 | BE15: 71.8 | BF15: 47.4 | BG15: {=TRANSPOSE((OFFSET($K$27,(ROW(R1)-1)*8,0)):(OFFSET($K$34,(ROW(R1)-1)*8,0)))} -> 234.9 | BH15: 166.6 | BI15: 162.5 | BJ15: 165.9 | BK15: 42.7 | BL15: 68.1 | BM15: 71.1 | BN15: 48.9
A16: 2 | B16: optimized-small-atlasarch-tune | C16: {=TRANSPOSE((OFFSET($D$27,(ROW(K2)-1)*8,0)):(OFFSET($D$34,(ROW(K2)-1)*8,0)))} -> 264.5 | D16: 186.9 | E16: 181.1 | F16: 179 | G16: 83 | H16: 77.5 | I16: 64.9 | J16: 49.3 | K16: {=TRANSPOSE((OFFSET($E$27,(ROW(L2)-1)*8,0)):(OFFSET($E$34,(ROW(L2)-1)*8,0)))} -> 246.5 | L16: 200.1 | M16: 166.1 | N16: 188.8 | O16: 77.4 | P16: 70.9 | Q16: 56.6 | R16: 45.9 | S16: {=TRANSPOSE((OFFSET($F$27,(ROW(M2)-1)*8,0)):(OFFSET($F$34,(ROW(M2)-1)*8,0)))} -> 257.3 | T16: 190.2 | U16: 189.9 | V16: 192.3 | W16: 75 | X16: 119.3 | Y16: 106.9 | Z16: 98.3 | AA16: {=TRANSPOSE((OFFSET($G$27,(ROW(N2)-1)*8,0)):(OFFSET($G$34,(ROW(N2)-1)*8,0)))} -> 243.8 | AB16: 202.7 | AC16: 175.9 | AD16: 208.1 | AE16: 70 | AF16: 108 | AG16: 97.2 | AH16: 66.6 | AI16: {=TRANSPOSE((OFFSET($H$27,(ROW(O2)-1)*8,0)):(OFFSET($H$34,(ROW(O2)-1)*8,0)))} -> 246.1 | AJ16: 196.3 | AK16: 154 | AL16: 169.2 | AM16: 44.1 | AN16: 34.5 | AO16: 48.9 | AP16: 30.8 | AQ16: {=TRANSPOSE((OFFSET($I$27,(ROW(P2)-1)*8,0)):(OFFSET($I$34,(ROW(P2)-1)*8,0)))} -> 240.6 | AR16: 160 | AS16: 141.8 | AT16: 149.4 | AU16: 41.1 | AV16: 33.2 | AW16: 47.6 | AX16: 27.6 | AY16: {=TRANSPOSE((OFFSET($J$27,(ROW(Q2)-1)*8,0)):(OFFSET($J$34,(ROW(Q2)-1)*8,0)))} -> 244 | AZ16: 208.7 | BA16: 172 | BB16: 171.5 | BC16: 45.8 | BD16: 71.4 | BE16: 71.8 | BF16: 47.4 | BG16: {=TRANSPOSE((OFFSET($K$27,(ROW(R2)-1)*8,0)):(OFFSET($K$34,(ROW(R2)-1)*8,0)))} -> 234.9 | BH16: 166.6 | BI16: 162.5 | BJ16: 165.9 | BK16: 42.7 | BL16: 68.1 | BM16: 71.1 | BN16: 48.9
A17: 3 | B17: optimized-small-arch-tune | C17: {=TRANSPOSE((OFFSET($D$27,(ROW(K3)-1)*8,0)):(OFFSET($D$34,(ROW(K3)-1)*8,0)))} -> 264.5 | D17: 186.9 | E17: 181.1 | F17: 179 | G17: 83.8 | H17: 77.5 | I17: 64.9 | J17: 49.3 | K17: {=TRANSPOSE((OFFSET($E$27,(ROW(L3)-1)*8,0)):(OFFSET($E$34,(ROW(L3)-1)*8,0)))} -> 246.3 | L17: 191.1 | M17: 144.5 | N17: 184.6 | O17: 78.2 | P17: 73.6 | Q17: 57.3 | R17: 44.7 | S17: {=TRANSPOSE((OFFSET($F$27,(ROW(M3)-1)*8,0)):(OFFSET($F$34,(ROW(M3)-1)*8,0)))} -> 257.3 | T17: 190.2 | U17: 189.9 | V17: 192.3 | W17: 75.1 | X17: 119.3 | Y17: 106.9 | Z17: 98.3 | AA17: {=TRANSPOSE((OFFSET($G$27,(ROW(N3)-1)*8,0)):(OFFSET($G$34,(ROW(N3)-1)*8,0)))} -> 242.3 | AB17: 193.4 | AC17: 171.4 | AD17: 192.2 | AE17: 70.2 | AF17: 108.9 | AG17: 98.9 | AH17: 66.9 | AI17: {=TRANSPOSE((OFFSET($H$27,(ROW(O3)-1)*8,0)):(OFFSET($H$34,(ROW(O3)-1)*8,0)))} -> 246.1 | AJ17: 196.3 | AK17: 154 | AL17: 169.2 | AM17: 37 | AN17: 34.5 | AO17: 48.9 | AP17: 30.8 | AQ17: {=TRANSPOSE((OFFSET($I$27,(ROW(P3)-1)*8,0)):(OFFSET($I$34,(ROW(P3)-1)*8,0)))} -> 235.7 | AR17: 161 | AS17: 143.4 | AT17: 150.4 | AU17: 34.5 | AV17: 34.8 | AW17: 48.4 | AX17: 29.4 | AY17: {=TRANSPOSE((OFFSET($J$27,(ROW(Q3)-1)*8,0)):(OFFSET($J$34,(ROW(Q3)-1)*8,0)))} -> 244 | AZ17: 208.7 | BA17: 172 | BB17: 171.5 | BC17: 38.3 | BD17: 71.4 | BE17: 71.8 | BF17: 47.4 | BG17: {=TRANSPOSE((OFFSET($K$27,(ROW(R3)-1)*8,0)):(OFFSET($K$34,(ROW(R3)-1)*8,0)))} -> 228.3 | BH17: 168.1 | BI17: 162.1 | BJ17: 166.2 | BK17: 35.7 | BL17: 69.4 | BM17: 68.3 | BN17: 47.9
A18: 4 | B18: optimized-big | C18: {=TRANSPOSE((OFFSET($D$27,(ROW(K4)-1)*8,0)):(OFFSET($D$34,(ROW(K4)-1)*8,0)))} -> 177.6 | D18: 151.2 | E18: 119.6 | F18: 124.8 | G18: 175.1 | H18: 61.2 | I18: 76.9 | J18: 49 | K18: {=TRANSPOSE((OFFSET($E$27,(ROW(L4)-1)*8,0)):(OFFSET($E$34,(ROW(L4)-1)*8,0)))} -> 248.3 | L18: 178 | M18: 153.4 | N18: 157.4 | O18: 238.1 | P18: 83.3 | Q18: 95.9 | R18: 28.6 | S18: {=TRANSPOSE((OFFSET($F$27,(ROW(M4)-1)*8,0)):(OFFSET($F$34,(ROW(M4)-1)*8,0)))} -> 179 | T18: 128.1 | U18: 131.8 | V18: 134.3 | W18: 179.1 | X18: 102.1 | Y18: 107.1 | Z18: 87.7 | AA18: {=TRANSPOSE((OFFSET($G$27,(ROW(N4)-1)*8,0)):(OFFSET($G$34,(ROW(N4)-1)*8,0)))} -> 245.1 | AB18: 183.2 | AC18: 185.5 | AD18: 163.7 | AE18: 239.7 | AF18: 121.7 | AG18: 114.8 | AH18: 48.8 | AI18: {=TRANSPOSE((OFFSET($H$27,(ROW(O4)-1)*8,0)):(OFFSET($H$34,(ROW(O4)-1)*8,0)))} -> 172.5 | AJ18: 139.7 | AK18: 127.6 | AL18: 141.5 | AM18: 165.9 | AN18: 39.4 | AO18: 47.6 | AP18: 28.3 | AQ18: {=TRANSPOSE((OFFSET($I$27,(ROW(P4)-1)*8,0)):(OFFSET($I$34,(ROW(P4)-1)*8,0)))} -> 239.3 | AR18: 175.7 | AS18: 138.7 | AT18: 175.5 | AU18: 215 | AV18: 39.4 | AW18: 48.2 | AX18: 17.6 | AY18: {=TRANSPOSE((OFFSET($J$27,(ROW(Q4)-1)*8,0)):(OFFSET($J$34,(ROW(Q4)-1)*8,0)))} -> 169.7 | AZ18: 141.6 | BA18: 122.4 | BB18: 131.4 | BC18: 167.7 | BD18: 70.2 | BE18: 72.3 | BF18: 53.4 | BG18: {=TRANSPOSE((OFFSET($K$27,(ROW(R4)-1)*8,0)):(OFFSET($K$34,(ROW(R4)-1)*8,0)))} -> 235.6 | BH18: 166.9 | BI18: 162.7 | BJ18: 153.9 | BK18: 221.8 | BL18: 88.9 | BM18: 81.1 | BN18: 27.2
A19: 5 | B19: optimized-big-atlasarch-tune | C19: {=TRANSPOSE((OFFSET($D$27,(ROW(K5)-1)*8,0)):(OFFSET($D$34,(ROW(K5)-1)*8,0)))} -> 177.6 | D19: 151.2 | E19: 119.6 | F19: 124.8 | G19: 175.1 | H19: 61.2 | I19: 76.9 | J19: 49 | K19: {=TRANSPOSE((OFFSET($E$27,(ROW(L5)-1)*8,0)):(OFFSET($E$34,(ROW(L5)-1)*8,0)))} -> 248.8 | L19: 169.7 | M19: 162.7 | N19: 161.9 | O19: 238.8 | P19: 67.1 | Q19: 95.3 | R19: 50.1 | S19: {=TRANSPOSE((OFFSET($F$27,(ROW(M5)-1)*8,0)):(OFFSET($F$34,(ROW(M5)-1)*8,0)))} -> 179 | T19: 128.1 | U19: 131.8 | V19: 134.3 | W19: 179.1 | X19: 102.1 | Y19: 107.1 | Z19: 87.7 | AA19: {=TRANSPOSE((OFFSET($G$27,(ROW(N5)-1)*8,0)):(OFFSET($G$34,(ROW(N5)-1)*8,0)))} -> 244.8 | AB19: 195.4 | AC19: 193 | AD19: 168.1 | AE19: 239.8 | AF19: 121 | AG19: 122 | AH19: 49.6 | AI19: {=TRANSPOSE((OFFSET($H$27,(ROW(O5)-1)*8,0)):(OFFSET($H$34,(ROW(O5)-1)*8,0)))} -> 172.5 | AJ19: 139.7 | AK19: 127.6 | AL19: 141.5 | AM19: 165.9 | AN19: 39.4 | AO19: 47.6 | AP19: 28.3 | AQ19: {=TRANSPOSE((OFFSET($I$27,(ROW(P5)-1)*8,0)):(OFFSET($I$34,(ROW(P5)-1)*8,0)))} -> 209 | AR19: 164.2 | AS19: 135.4 | AT19: 161.8 | AU19: 190.6 | AV19: 39.5 | AW19: 47.5 | AX19: 17.9 | AY19: {=TRANSPOSE((OFFSET($J$27,(ROW(Q5)-1)*8,0)):(OFFSET($J$34,(ROW(Q5)-1)*8,0)))} -> 169.7 | AZ19: 141.6 | BA19: 122.4 | BB19: 131.4 | BC19: 167.7 | BD19: 70.2 | BE19: 72.3 | BF19: 53.4 | BG19: {=TRANSPOSE((OFFSET($K$27,(ROW(R5)-1)*8,0)):(OFFSET($K$34,(ROW(R5)-1)*8,0)))} -> 203.6 | BH19: 173.4 | BI19: 122 | BJ19: 144.6 | BK19: 193.8 | BL19: 96.6 | BM19: 83.2 | BN19: 30.1
A20: 6 | B20: optimized-big-arch-tune | C20: {=TRANSPOSE((OFFSET($D$27,(ROW(K6)-1)*8,0)):(OFFSET($D$34,(ROW(K6)-1)*8,0)))} -> 264.5 | D20: 186.9 | E20: 181.1 | F20: 179 | G20: 243.7 | H20: 77.5 | I20: 64.9 | J20: 49.3 | K20: {=TRANSPOSE((OFFSET($E$27,(ROW(L6)-1)*8,0)):(OFFSET($E$34,(ROW(L6)-1)*8,0)))} -> 246 | L20: 90 | M20: 70.3 | N20: 84.5 | O20: 227.4 | P20: 71.3 | Q20: 57.2 | R20: 29.9 | S20: {=TRANSPOSE((OFFSET($F$27,(ROW(M6)-1)*8,0)):(OFFSET($F$34,(ROW(M6)-1)*8,0)))} -> 257.3 | T20: 190.2 | U20: 189.9 | V20: 192.3 | W20: 248.9 | X20: 119.3 | Y20: 106.9 | Z20: 98.3 | AA20: {=TRANSPOSE((OFFSET($G$27,(ROW(N6)-1)*8,0)):(OFFSET($G$34,(ROW(N6)-1)*8,0)))} -> 242.6 | AB20: 91.1 | AC20: 74.1 | AD20: 87.3 | AE20: 231.8 | AF20: 108.7 | AG20: 98.2 | AH20: 67.5 | AI20: {=TRANSPOSE((OFFSET($H$27,(ROW(O6)-1)*8,0)):(OFFSET($H$34,(ROW(O6)-1)*8,0)))} -> 246.1 | AJ20: 196.3 | AK20: 154 | AL20: 169.2 | AM20: 105.4 | AN20: 34.5 | AO20: 48.9 | AP20: 30.8 | AQ20: {=TRANSPOSE((OFFSET($I$27,(ROW(P6)-1)*8,0)):(OFFSET($I$34,(ROW(P6)-1)*8,0)))} -> 105.4 | AR20: 78.4 | AS20: 59.2 | AT20: 70 | AU20: 98.4 | AV20: 34.9 | AW20: 33.1 | AX20: 29.4 | AY20: {=TRANSPOSE((OFFSET($J$27,(ROW(Q6)-1)*8,0)):(OFFSET($J$34,(ROW(Q6)-1)*8,0)))} -> 244 | AZ20: 208.7 | BA20: 172 | BB20: 171.5 | BC20: 110.8 | BD20: 71.4 | BE20: 71.8 | BF20: 47.4 | BG20: {=TRANSPOSE((OFFSET($K$27,(ROW(R6)-1)*8,0)):(OFFSET($K$34,(ROW(R6)-1)*8,0)))} -> 106.9 | BH20: 80.9 | BI20: 61.9 | BJ20: 67.8 | BK20: 103.3 | BL20: 72.9 | BM20: 70.5 | BN20: 31.7
A21: 7 | B21: optimized-small-atlasarch-tune2 | C21: {=TRANSPOSE((OFFSET($D$27,(ROW(K7)-1)*8,0)):(OFFSET($D$34,(ROW(K7)-1)*8,0)))} -> 264.5 | D21: 186.9 | E21: 181.1 | F21: 179 | G21: 83.6 | H21: 77.5 | I21: 64.9 | J21: 49.3 | K21: {=TRANSPOSE((OFFSET($E$27,(ROW(L7)-1)*8,0)):(OFFSET($E$34,(ROW(L7)-1)*8,0)))} -> 247.1 | L21: 190.4 | M21: 144.4 | N21: 184 | O21: 78 | P21: 72.5 | Q21: 57.4 | R21: 45.1 | S21: {=TRANSPOSE((OFFSET($F$27,(ROW(M7)-1)*8,0)):(OFFSET($F$34,(ROW(M7)-1)*8,0)))} -> 257.3 | T21: 190.2 | U21: 189.9 | V21: 192.3 | W21: 75.1 | X21: 119.3 | Y21: 106.9 | Z21: 98.3 | AA21: {=TRANSPOSE((OFFSET($G$27,(ROW(N7)-1)*8,0)):(OFFSET($G$34,(ROW(N7)-1)*8,0)))} -> 242 | AB21: 194.1 | AC21: 171.9 | AD21: 191.6 | AE21: 70.1 | AF21: 108.2 | AG21: 97.8 | AH21: 67.2 | AI21: {=TRANSPOSE((OFFSET($H$27,(ROW(O7)-1)*8,0)):(OFFSET($H$34,(ROW(O7)-1)*8,0)))} -> 246.1 | AJ21: 196.3 | AK21: 154 | AL21: 169.2 | AM21: 37 | AN21: 34.5 | AO21: 48.9 | AP21: 30.8 | AQ21: {=TRANSPOSE((OFFSET($I$27,(ROW(P7)-1)*8,0)):(OFFSET($I$34,(ROW(P7)-1)*8,0)))} -> 239.3 | AR21: 158.9 | AS21: 142.7 | AT21: 150.9 | AU21: 34.5 | AV21: 33.5 | AW21: 49.4 | AX21: 29.1 | AY21: {=TRANSPOSE((OFFSET($J$27,(ROW(Q7)-1)*8,0)):(OFFSET($J$34,(ROW(Q7)-1)*8,0)))} -> 244 | AZ21: 208.7 | BA21: 172 | BB21: 171.5 | BC21: 38.3 | BD21: 71.4 | BE21: 71.8 | BF21: 47.4 | BG21: {=TRANSPOSE((OFFSET($K$27,(ROW(R7)-1)*8,0)):(OFFSET($K$34,(ROW(R7)-1)*8,0)))} -> 232.2 | BH21: 168.2 | BI21: 161.3 | BJ21: 164.9 | BK21: 35.7 | BL21: 72.5 | BM21: 70.8 | BN21: 47.9
A22: 8 | B22: optimized-big-atlasarch-tune2 | C22: {=TRANSPOSE((OFFSET($D$27,(ROW(K8)-1)*8,0)):(OFFSET($D$34,(ROW(K8)-1)*8,0)))} -> 177.6 | D22: 151.2 | E22: 119.6 | F22: 124.8 | G22: 175.1 | H22: 61.2 | I22: 76.9 | J22: 49 | K22: {=TRANSPOSE((OFFSET($E$27,(ROW(L8)-1)*8,0)):(OFFSET($E$34,(ROW(L8)-1)*8,0)))} -> 186.5 | L22: 125.8 | M22: 120.3 | N22: 121.7 | O22: 178.6 | P22: 62.8 | Q22: 70.1 | R22: 36.4 | S22: {=TRANSPOSE((OFFSET($F$27,(ROW(M8)-1)*8,0)):(OFFSET($F$34,(ROW(M8)-1)*8,0)))} -> 179 | T22: 128.1 | U22: 131.8 | V22: 134.3 | W22: 179.1 | X22: 102.1 | Y22: 107.1 | Z22: 87.7 | AA22: {=TRANSPOSE((OFFSET($G$27,(ROW(N8)-1)*8,0)):(OFFSET($G$34,(ROW(N8)-1)*8,0)))} -> 183.6 | AB22: 146.9 | AC22: 144 | AD22: 126.1 | AE22: 179.8 | AF22: 90.2 | AG22: 91.8 | AH22: 37 | AI22: {=TRANSPOSE((OFFSET($H$27,(ROW(O8)-1)*8,0)):(OFFSET($H$34,(ROW(O8)-1)*8,0)))} -> 172.5 | AJ22: 139.7 | AK22: 127.6 | AL22: 141.5 | AM22: 165.9 | AN22: 39.4 | AO22: 47.6 | AP22: 28.3 | AQ22: {=TRANSPOSE((OFFSET($I$27,(ROW(P8)-1)*8,0)):(OFFSET($I$34,(ROW(P8)-1)*8,0)))} -> 155.5 | AR22: 124.2 | AS22: 99.3 | AT22: 121.5 | AU22: 142.2 | AV22: 29.6 | AW22: 37.4 | AX22: 11.9 | AY22: {=TRANSPOSE((OFFSET($J$27,(ROW(Q8)-1)*8,0)):(OFFSET($J$34,(ROW(Q8)-1)*8,0)))} -> 169.7 | AZ22: 141.6 | BA22: 122.4 | BB22: 131.4 | BC22: 167.7 | BD22: 70.2 | BE22: 72.3 | BF22: 53.4 | BG22: {=TRANSPOSE((OFFSET($K$27,(ROW(R8)-1)*8,0)):(OFFSET($K$34,(ROW(R8)-1)*8,0)))} -> 154.1 | BH22: 130.1 | BI22: 91.2 | BJ22: 108.6 | BK22: 145.4 | BL22: 66.4 | BM22: 62.1 | BN22: 21.9
N25: OdroidMC1: atlas-optimized-small (and big) vs the rest (build 2 etc)
C26: OdroidMC1
B27: 1 | C27: kSelMM | D27: 264.5 | E27: 246.5 | F27: 257.3 | G27: 243.8 | H27: 246.1 | I27: 240.6 | J27: 244 | K27: 234.9
C28: kGenMM | D28: 186.9 | E28: 200.1 | F28: 190.2 | G28: 202.7 | H28: 196.3 | I28: 160 | J28: 208.7 | K28: 166.6
C29: kMM_NT | D29: 181.1 | E29: 166.1 | F29: 189.9 | G29: 175.9 | H29: 154 | I29: 141.8 | J29: 172 | K29: 162.5
C30: kMM_TN | D30: 179 | E30: 188.8 | F30: 192.3 | G30: 208.1 | H30: 169.2 | I30: 149.4 | J30: 171.5 | K30: 165.9
C31: BIG_MM | D31: 83 | E31: 77.4 | F31: 75 | G31: 70 | H31: 44.1 | I31: 41.1 | J31: 45.8 | K31: 42.7
C32: kMV_N | D32: 77.5 | E32: 70.9 | F32: 119.3 | G32: 108 | H32: 34.5 | I32: 33.2 | J32: 71.4 | K32: 68.1
C33: kMV_T | D33: 64.9 | E33: 56.6 | F33: 106.9 | G33: 97.2 | H33: 48.9 | I33: 47.6 | J33: 71.8 | K33: 71.1
C34: kGER | D34: 49.3 | E34: 45.9 | F34: 98.3 | G34: 66.6 | H34: 30.8 | I34: 27.6 | J34: 47.4 | K34: 48.9
B35: 2 | C35: kSelMM | D35: 264.5 | E35: 246.5 | F35: 257.3 | G35: 243.8 | H35: 246.1 | I35: 240.6 | J35: 244 | K35: 234.9 | M35: 2 | N35: kSelMM | O35: 246.5 | P35: 246.3 | Q35: =(O35-P35)*100/O35 -> 0.081135903 | R35: 243.8 | S35: 242.3 | U35: 240.6 | V35: 235.7 | X35: 234.9 | Y35: 228.3
C36: kGenMM | D36: 186.9 | E36: 200.1 | F36: 190.2 | G36: 202.7 | H36: 196.3 | I36: 160 | J36: 208.7 | K36: 166.6 | N36: kGenMM | O36: 200.1 | P36: 191.1 | Q36: =(O36-P36)*100/O36 -> 4.4977511 | R36: 202.7 | S36: 193.4 | U36: 160 | V36: 161 | X36: 166.6 | Y36: 168.1
C37: kMM_NT | D37: 181.1 | E37: 166.1 | F37: 189.9 | G37: 175.9 | H37: 154 | I37: 141.8 | J37: 172 | K37: 162.5 | N37: kMM_NT | O37: 166.1 | P37: 144.5 | Q37: =(O37-P37)*100/O37 -> 13.004214 | R37: 175.9 | S37: 171.4 | U37: 141.8 | V37: 143.4 | X37: 162.5 | Y37: 162.1
C38: kMM_TN | D38: 179 | E38: 188.8 | F38: 192.3 | G38: 208.1 | H38: 169.2 | I38: 149.4 | J38: 171.5 | K38: 165.9 | N38: kMM_TN | O38: 188.8 | P38: 184.6 | Q38: =(O38-P38)*100/O38 -> 2.2245763 | R38: 208.1 | S38: 192.2 | U38: 149.4 | V38: 150.4 | X38: 165.9 | Y38: 166.2
C39: BIG_MM | D39: 83 | E39: 77.4 | F39: 75 | G39: 70 | H39: 44.1 | I39: 41.1 | J39: 45.8 | K39: 42.7 | N39: BIG_MM | O39: 77.5 | P39: 78.2 | Q39: =(O39-P39)*100/O39 -> -0.90322581 | R39: 70 | S39: 70.2 | U39: 41.2 | V39: 34.5 | X39: 42.7 | Y39: 35.7
C40: kMV_N | D40: 77.5 | E40: 70.9 | F40: 119.3 | G40: 108 | H40: 34.5 | I40: 33.2 | J40: 71.4 | K40: 68.1 | N40: kMV_N | O40: 70.9 | P40: 73.6 | Q40: =(O40-P40)*100/O40 -> -3.8081805 | R40: 108 | S40: 108.9 | U40: 33.2 | V40: 34.8 | X40: 68.1 | Y40: 69.4
C41: kMV_T | D41: 64.9 | E41: 56.6 | F41: 106.9 | G41: 97.2 | H41: 48.9 | I41: 47.6 | J41: 71.8 | K41: 71.1 | N41: kMV_T | O41: 56.6 | P41: 57.3 | Q41: =(O41-P41)*100/O41 -> -1.2367491 | R41: 97.2 | S41: 98.9 | U41: 47.6 | V41: 48.4 | X41: 71.1 | Y41: 68.3
C42: kGER | D42: 49.3 | E42: 45.9 | F42: 98.3 | G42: 66.6 | H42: 30.8 | I42: 27.6 | J42: 47.4 | K42: 48.9 | N42: kGER | O42: 45.9 | P42: 44.7 | Q42: =(O42-P42)*100/O42 -> 2.6143791 | R42: 66.6 | S42: 66.9 | U42: 27.6 | V42: 29.4 | X42: 48.9 | Y42: 47.9
B43: 3 | C43: kSelMM | D43: 264.5 | E43: 246.3 | F43: 257.3 | G43: 242.3 | H43: 246.1 | I43: 235.7 | J43: 244 | K43: 228.3 | M43: 3 | N43: kSelMM | O43: 246.5 | P43: 246.4 | Q43: =(O43-P43)*100/O43 -> 0.040567951 | R43: 243.8 | S43: 243.3 | U43: 240.6 | V43: 106.6 | X43: 234.9 | Y43: 108.8
C44: kGenMM | D44: 186.9 | E44: 191.1 | F44: 190.2 | G44: 193.4 | H44: 196.3 | I44: 161 | J44: 208.7 | K44: 168.1 | N44: kGenMM | O44: 200.1 | P44: 89.9 | Q44: =(O44-P44)*100/O44 -> 55.072464 | R44: 202.7 | S44: 91.1 | U44: 160 | V44: 76.4 | X44: 166.6 | Y44: 80.3
C45: kMM_NT | D45: 181.1 | E45: 144.5 | F45: 189.9 | G45: 171.4 | H45: 154 | I45: 143.4 | J45: 172 | K45: 162.1 | N45: kMM_NT | O45: 166.1 | P45: 67.8 | Q45: =(O45-P45)*100/O45 -> 59.181216 | R45: 175.9 | S45: 71.3 | U45: 141.8 | V45: 59.2 | X45: 162.5 | Y45: 61.8
C46: kMM_TN | D46: 179 | E46: 184.6 | F46: 192.3 | G46: 192.2 | H46: 169.2 | I46: 150.4 | J46: 171.5 | K46: 166.2 | N46: kMM_TN | O46: 188.8 | P46: 84.9 | Q46: =(O46-P46)*100/O46 -> 55.03178 | R46: 208.1 | S46: 87.2 | U46: 149.4 | V46: 69.8 | X46: 165.9 | Y46: 68.5
