Workbook

Sheet Arch details
A1: SBC | B1: Cores | C1: march | D1: mcpu | E1: mtune | F1: fpu | G1: mfloat-abi | J1: ostalo | K1: ostalo (Thumb)
A2: Rpi 1B | C2: armv6 | D2: arm1176jzf-s | E2: arm1176jzf-s | F2: vfpv2 (alias is vfp) | G2: hard | K2: Thumb | L2: 16KB L1 and no L2
A3: Cubieboard2 | C3: armv7-a | D3: cortex-a7 | E3: cortex-a7 | F3: neon-vfpv4 | G3: hard | J3: -funsafe-math-optimizations | K3: Thumb-2
A4: OdroidU3 | C4: armv7-a | D4: cortex-a9 | E4: cortex-a9 | F4: neon-vfpv3 (alias is neon) | G4: hard | J4: -funsafe-math-optimizations | K4: Thumb or Thumb-2 | L4: 1MB L2 cache total? From paper…
A5: OdroidMC1 | B5: LITTLE | C5: armv7-a | D5: cortex-a7 | E5: cortex-a7 | F5: neon-vfpv4 | G5: hard | J5: -funsafe-math-optimizations | K5: Thumb-2 | L5: 2 sockets, 2,5MB L2 cache per socket
B6: Big | C6: armv7-a | D6: cortex-a15 | E6: cortex-a15 | F6: neon-vfpv4 | G6: hard | J6: -funsafe-math-optimizations | K6: Thumb-2
A12: HPL Runs (fixed parameters) | C12: Number of nodes | D12: Node | E12: Total memory of a node (kB) | F12: N, alpha | G12: N, alpha (NB round) | H12: N, beta | I12: N, beta (NB round) | J12: NB | K12: P | L12: Q | M12: Ns difference | N12: Half of the Ns difference | O12: N1 | P12: N2 | Q12: N3
A13: Number of nodes | B13: 4 | C13: 1 | D13: Raspberry Pi 4 B | E13: 3937528 | F13: =$B$14*SQRT(($C13*$E13*1024)/8) -> 17960.019 | G13: =_xlfn.CEILING.MATH(F13/J13)*J13 -> 17984 | H13: =SQRT($B$14*($C13*$E13*1024)/8) -> 20079.912 | I13: =_xlfn.CEILING.MATH(H13/J13)*J13 -> 20096 | J13: 64 | K13: 2 | L13: 2 | M13: =I13-G13 -> 2112 | N13: =M13/2 -> 1056 | O13: =G13 -> 17984 | P13: =_xlfn.CEILING.MATH((O13+N13)/J13)*J13 -> 19072 | Q13: =_xlfn.CEILING.MATH((P13+N13)/J13)*J13 -> 20160
A14: Percentage of mem | B14: 0.8 | C14: 4 | D14: Raspberry Pi 4 B | E14: 3937528 | F14: =$B$14*SQRT(($B$13*$E14*1024)/8) -> 35920.039 | G14: =_xlfn.CEILING.MATH(F14/J14)*J14 -> 36000 | H14: =SQRT($B$14*($B$13*$E14*1024)/8) -> 40159.824 | I14: =_xlfn.CEILING.MATH(H14/J14)*J14 -> 40160 | J14: 160 | K14: 2 | L14: 8 | M14: =I14-G14 -> 4160 | N14: =M14/2 -> 2080 | O14: =G14 -> 36000 | P14: =_xlfn.CEILING.MATH((O14+N14)/J14)*J14 -> 38080 | Q14: =_xlfn.CEILING.MATH((P14+N14)/J14)*J14 -> 40160

Sheet ATLAS builds
A1: Raspberry Pi 4B | C1: Repetitive flags | D1: 32/64 build (or none) | E1: Other ATLAS config flags | F1: Compiler flag addendum type | G1: Compiler flags used for building | H1: All flags | J1: Flags used for flagsearching - mandatory | K1: Flags used for flagsearching - optional | L1: Machine originally built on | M1: Needs flagsearching | N1: Flagsearched (d) | O1: Flagsearched (s) No need! HPL uses only double precision! See ATLAS install manual | P1: Flagsearched (Td) | Q1: Kernel | S1: NOTE | U1: TODO
A2: 1 | B2: atlarch | C2: -D c -DWALL | D2: -b 64 | E2: -A ARM64xgene1 | H2: =_xlfn.TEXTJOIN(" ", TRUE, C2, D2, E2, F2, G2) -> -D c -DWALL -b 64 -A ARM64xgene1 | I2: =VLOOKUP(B2,'HPL 4 nodes, builds'!$A$4:$Y$183,25,FALSE) -> 37.7186 | J2: -march=native -mtune=native -mcpu=native -march=armv8-a+crc -mtune=cortex-a72 -mcpu=cortex-a72 -mabi=lp64 | S2: https://gist.github.com/fm4dd/c663217935dc17f0fc73c9c81b0aa845 | U2: In progress
A3: 2 | B3: atlarch-tune | C3: -D c -DWALL | D3: -b 64 | E3: -A ARM64xgene1 | F3: -Fa alg | G3: -march=native -mtune=native -mcpu=native -mabi=lp64 | H3: =_xlfn.TEXTJOIN(" ", TRUE, C3, D3, E3, F3, G3) -> -D c -DWALL -b 64 -A ARM64xgene1 -Fa alg -march=native -mtune=native -mcpu=native -mabi=lp64 | I3: =VLOOKUP(B3,'HPL 4 nodes, builds'!$A$4:$Y$183,25,FALSE) -> 37.8688 | U3: Freshly finished
A4: 3 | B4: arch-tune | C4: -D c -DWALL | D4: -b 64 | F4: -Fa alg | G4: -march=native -mtune=native -mcpu=native -mabi=lp64 | H4: =_xlfn.TEXTJOIN(" ", TRUE, C4, D4, E4, F4, G4) -> -D c -DWALL -b 64 -Fa alg -march=native -mtune=native -mcpu=native -mabi=lp64 | I4: =VLOOKUP(B4,'HPL 4 nodes, builds'!$A$4:$Y$183,25,FALSE) -> 37.5448 | U4: Done
A5: 4 | B5: atlarch-tune-spec-crc | C5: -D c -DWALL | D5: -b 64 | E5: -A ARM64xgene1 | F5: -Fa alg | G5: -march=armv8-a+crc -mtune=cortex-a72 -mcpu=cortex-a72 -mabi=lp64 | H5: =_xlfn.TEXTJOIN(" ", TRUE, C5, D5, E5, F5, G5) -> -D c -DWALL -b 64 -A ARM64xgene1 -Fa alg -march=armv8-a+crc -mtune=cortex-a72 -mcpu=cortex-a72 -mabi=lp64 | I5: =VLOOKUP(B5,'HPL 4 nodes, builds'!$A$4:$Y$183,25,FALSE) -> 37.7226 | U5: TODO with the same settings!
A6: 5 | B6: atlarch-tune-spec | C6: -D c -DWALL | D6: -b 64 | E6: -A ARM64xgene1 | F6: -Fa alg | G6: -march=armv8-a -mtune=cortex-a72 -mcpu=cortex-a72 -mabi=lp64 | H6: =_xlfn.TEXTJOIN(" ", TRUE, C6, D6, E6, F6, G6) -> -D c -DWALL -b 64 -A ARM64xgene1 -Fa alg -march=armv8-a -mtune=cortex-a72 -mcpu=cortex-a72 -mabi=lp64 | I6: =VLOOKUP(B6,'HPL 4 nodes, builds'!$A$4:$Y$183,25,FALSE) -> 37.8396
A7: 6 | B7: cpu | C7: -D c -DWALL | D7: -b 64 | F7: -Fa alg | G7: -mcpu=cortex-a72 -mabi=lp64 | H7: =_xlfn.TEXTJOIN(" ", TRUE, C7, D7, E7, F7, G7) -> -D c -DWALL -b 64 -Fa alg -mcpu=cortex-a72 -mabi=lp64 | I7: =VLOOKUP(B7,'HPL 4 nodes, builds'!$A$4:$Y$183,25,FALSE) -> 37.4826
A8: 7 | B8: cpu-tune | C8: -D c -DWALL | D8: -b 64 | F8: -Fa alg | G8: -mcpu=cortex-a72 -mtune=cortex-a72 -mabi=lp64 | H8: =_xlfn.TEXTJOIN(" ", TRUE, C8, D8, E8, F8, G8) -> -D c -DWALL -b 64 -Fa alg -mcpu=cortex-a72 -mtune=cortex-a72 -mabi=lp64 | I8: =VLOOKUP(B8,'HPL 4 nodes, builds'!$A$4:$Y$183,25,FALSE) -> 37.751
A9: 8 | B9: atlarch-cpu | C9: -D c -DWALL | D9: -b 64 | E9: -A ARM64xgene1 | F9: -Fa alg | G9: -mcpu=cortex-a72 -mabi=lp64 | H9: =_xlfn.TEXTJOIN(" ", TRUE, C9, D9, E9, F9, G9) -> -D c -DWALL -b 64 -A ARM64xgene1 -Fa alg -mcpu=cortex-a72 -mabi=lp64 | I9: =VLOOKUP(B9,'HPL 4 nodes, builds'!$A$4:$Y$183,25,FALSE) -> 36.8264
A10: 9 | B10: atlarch-cpu-tune | C10: -D c -DWALL | D10: -b 64 | E10: -A ARM64xgene1 | F10: -Fa alg | G10: -mcpu=cortex-a72 -mtune=cortex-a72 -mabi=lp64 | H10: =_xlfn.TEXTJOIN(" ", TRUE, C10, D10, E10, F10, G10) -> -D c -DWALL -b 64 -A ARM64xgene1 -Fa alg -mcpu=cortex-a72 -mtune=cortex-a72 -mabi=lp64 | I10: =VLOOKUP(B10,'HPL 4 nodes, builds'!$A$4:$Y$183,25,FALSE) -> 38.0274
A11: 10 | B11: atlarch-tune-overr | C11: -D c -DWALL | D11: -b 64 | E11: -A ARM64xgene1 | F11: -F alg | G11: -march=native -mtune=native -mcpu=native -mabi=lp64 | H11: =_xlfn.TEXTJOIN(" ", TRUE, C11, D11, E11, F11, G11) -> -D c -DWALL -b 64 -A ARM64xgene1 -F alg -march=native -mtune=native -mcpu=native -mabi=lp64 | I11: =VLOOKUP(B11,'HPL 4 nodes, builds'!$A$4:$Y$183,25,FALSE) -> 26.0796
A12: 11 | B12: arch-tune-overr | C12: -D c -DWALL | D12: -b 64 | F12: -Fa alg | G12: -march=native -mtune=native -mcpu=native -mabi=lp64 | H12: =_xlfn.TEXTJOIN(" ", TRUE, C12, D12, E12, F12, G12) -> -D c -DWALL -b 64 -Fa alg -march=native -mtune=native -mcpu=native -mabi=lp64 | I12: =VLOOKUP(B12,'HPL 4 nodes, builds'!$A$4:$Y$183,25,FALSE) -> 27.4566
A13: 12 | B13: atlarch-tune-spec-crc-overr | C13: -D c -DWALL | D13: -b 64 | E13: -A ARM64xgene1 | F13: -F alg | G13: -march=armv8-a+crc -mtune=cortex-a72 -mcpu=cortex-a72 -mabi=lp64 | H13: =_xlfn.TEXTJOIN(" ", TRUE, C13, D13, E13, F13, G13) -> -D c -DWALL -b 64 -A ARM64xgene1 -F alg -march=armv8-a+crc -mtune=cortex-a72 -mcpu=cortex-a72 -mabi=lp64 | I13: =VLOOKUP(B13,'HPL 4 nodes, builds'!$A$4:$Y$183,25,FALSE) -> 27.7634
A14: 13 | B14: atlarch-tune-spec-overr | C14: -D c -DWALL | D14: -b 64 | E14: -A ARM64xgene1 | F14: -F alg | G14: -march=armv8-a -mtune=cortex-a72 -mcpu=cortex-a72 -mabi=lp64 | H14: =_xlfn.TEXTJOIN(" ", TRUE, C14, D14, E14, F14, G14) -> -D c -DWALL -b 64 -A ARM64xgene1 -F alg -march=armv8-a -mtune=cortex-a72 -mcpu=cortex-a72 -mabi=lp64 | I14: =VLOOKUP(B14,'HPL 4 nodes, builds'!$A$4:$Y$183,25,FALSE) -> 27.267
A15: 14 | B15: cpu-overr | C15: -D c -DWALL | D15: -b 64 | F15: -F alg | G15: -mcpu=cortex-a72 -mabi=lp64 | H15: =_xlfn.TEXTJOIN(" ", TRUE, C15, D15, E15, F15, G15) -> -D c -DWALL -b 64 -F alg -mcpu=cortex-a72 -mabi=lp64 | I15: =VLOOKUP(B15,'HPL 4 nodes, builds'!$A$4:$Y$183,25,FALSE) -> 27.8834
A16: 15 | B16: cpu-tune-overr | C16: -D c -DWALL | D16: -b 64 | F16: -F alg | G16: -mcpu=cortex-a72 -mtune=cortex-a72 -mabi=lp64 | H16: =_xlfn.TEXTJOIN(" ", TRUE, C16, D16, E16, F16, G16) -> -D c -DWALL -b 64 -F alg -mcpu=cortex-a72 -mtune=cortex-a72 -mabi=lp64 | I16: =VLOOKUP(B16,'HPL 4 nodes, builds'!$A$4:$Y$183,25,FALSE) -> 27.9334
A17: 16 | B17: atlarch-cpu-overr | C17: -D c -DWALL | D17: -b 64 | E17: -A ARM64xgene1 | F17: -F alg | G17: -mcpu=cortex-a72 -mabi=lp64 | H17: =_xlfn.TEXTJOIN(" ", TRUE, C17, D17, E17, F17, G17) -> -D c -DWALL -b 64 -A ARM64xgene1 -F alg -mcpu=cortex-a72 -mabi=lp64 | I17: =VLOOKUP(B17,'HPL 4 nodes, builds'!$A$4:$Y$183,25,FALSE) -> 27.9388
A18: 17 | B18: atlarch-cpu-tune-overr | C18: -D c -DWALL | D18: -b 64 | E18: -A ARM64xgene1 | F18: -F alg | G18: -mcpu=cortex-a72 -mtune=cortex-a72 -mabi=lp64 | H18: =_xlfn.TEXTJOIN(" ", TRUE, C18, D18, E18, F18, G18) -> -D c -DWALL -b 64 -A ARM64xgene1 -F alg -mcpu=cortex-a72 -mtune=cortex-a72 -mabi=lp64 | I18: =VLOOKUP(B18,'HPL 4 nodes, builds'!$A$4:$Y$183,25,FALSE) -> 27.6152
A19: 18 | B19: generic | C19: -D c -DWALL | E19: -Si archdef 1 | H19: =_xlfn.TEXTJOIN(" ", TRUE, C19, D19, E19, F19, G19) -> -D c -DWALL -Si archdef 1 | I19: =VLOOKUP(B19,'HPL 4 nodes, builds'!$A$4:$Y$183,25,FALSE) -> 36.6642
A20: 19 | B20: noarch | C20: -D c -DWALL | E20: -Si archdef 0 | H20: =_xlfn.TEXTJOIN(" ", TRUE, C20, D20, E20, F20, G20) -> -D c -DWALL -Si archdef 0 | I20: =VLOOKUP(B20,'HPL 4 nodes, builds'!$A$4:$Y$183,25,FALSE) -> #N/A
A21: 20 | B21: atlarch-flags | C21: -D c -DWALL | D21: -b 64 | F21: -Fa alg | G21: -O1 -pipe -fschedule-insns2 | H21: =_xlfn.TEXTJOIN(" ", TRUE, C21, D21, E21, F21, G21) -> -D c -DWALL -b 64 -Fa alg -O1 -pipe -fschedule-insns2 | I21: =VLOOKUP(B21,'HPL 4 nodes, builds'!$A$4:$Y$183,25,FALSE) -> 38.1116 | K21: 243761
A22: 21 | B22: atlarch-tune-flags | C22: -D c -DWALL | D22: -b 64 | F22: -Fa alg | G22: -O1 -pipe -fno-schedule-insns -fno-expensive-optimizations -fschedule-insns2 | H22: =_xlfn.TEXTJOIN(" ", TRUE, C22, D22, E22, F22, G22) -> -D c -DWALL -b 64 -Fa alg -O1 -pipe -fno-schedule-insns -fno-expensive-optimizations -fschedule-insns2 | I22: =VLOOKUP(B22,'HPL 4 nodes, builds'!$A$4:$Y$183,25,FALSE) -> 38.2788 | K22: 231860
A23: 22 | B23: arch-tune-flags | C23: -D c -DWALL | D23: -b 64 | F23: -Fa alg | G23: -Os -pipe -funroll-all-loops | H23: =_xlfn.TEXTJOIN(" ", TRUE, C23, D23, E23, F23, G23) -> -D c -DWALL -b 64 -Fa alg -Os -pipe -funroll-all-loops | I23: =VLOOKUP(B23,'HPL 4 nodes, builds'!$A$4:$Y$183,25,FALSE) -> 38.0034 | K23: 217447
A24: 23 | B24: atlarch-tune-spec-crc-flags | C24: -D c -DWALL | D24: -b 64 | F24: -Fa alg | G24: -Os -pipe -fschedule-insns2 -mtune=native -fexpensive-optimizations | H24: =_xlfn.TEXTJOIN(" ", TRUE, C24, D24, E24, F24, G24) -> -D c -DWALL -b 64 -Fa alg -Os -pipe -fschedule-insns2 -mtune=native -fexpensive-optimizations | I24: =VLOOKUP(B24,'HPL 4 nodes, builds'!$A$4:$Y$183,25,FALSE) -> 39.1944 | K24: 249047
A25: 24 | B25: atlarch-tune-spec-flags | C25: -D c -DWALL | D25: -b 64 | F25: -Fa alg | G25: -O1 -pipe -fno-schedule-insns -fno-expensive-optimizations -fschedule-insns2 | H25: =_xlfn.TEXTJOIN(" ", TRUE, C25, D25, E25, F25, G25) -> -D c -DWALL -b 64 -Fa alg -O1 -pipe -fno-schedule-insns -fno-expensive-optimizations -fschedule-insns2 | I25: =VLOOKUP(B25,'HPL 4 nodes, builds'!$A$4:$Y$183,25,FALSE) -> 37.389 | K25: 232195
A26: 25 | B26: cpu-flags | C26: -D c -DWALL | D26: -b 64 | F26: -Fa alg | G26: -Os -pipe -fschedule-insns2 -mtune=native -frename-registers | H26: =_xlfn.TEXTJOIN(" ", TRUE, C26, D26, E26, F26, G26) -> -D c -DWALL -b 64 -Fa alg -Os -pipe -fschedule-insns2 -mtune=native -frename-registers | I26: =VLOOKUP(B26,'HPL 4 nodes, builds'!$A$4:$Y$183,25,FALSE) -> 39.1934 | K26: 250512
A27: 26 | B27: cpu-tune-flags | C27: -D c -DWALL | D27: -b 64 | F27: -Fa alg | G27: -Os -pipe -fno-expensive-optimizations | H27: =_xlfn.TEXTJOIN(" ", TRUE, C27, D27, E27, F27, G27) -> -D c -DWALL -b 64 -Fa alg -Os -pipe -fno-expensive-optimizations | I27: =VLOOKUP(B27,'HPL 4 nodes, builds'!$A$4:$Y$183,25,FALSE) -> 38.2004 | K27: 251713
A28: 27 | B28: atlarch-cpu-flags | C28: -D c -DWALL | D28: -b 64 | F28: -Fa alg | G28: -O1 -pipe -fschedule-insns2 | H28: =_xlfn.TEXTJOIN(" ", TRUE, C28, D28, E28, F28, G28) -> -D c -DWALL -b 64 -Fa alg -O1 -pipe -fschedule-insns2 | I28: =VLOOKUP(B28,'HPL 4 nodes, builds'!$A$4:$Y$183,25,FALSE) -> 38.2768 | K28: 245070
A29: 28 | B29: atlarch-cpu-tune-flags | C29: -D c -DWALL | D29: -b 64 | F29: -Fa alg | G29: -O1 -pipe -fno-schedule-insns -fschedule-insns2 -fno-tree-ter | H29: =_xlfn.TEXTJOIN(" ", TRUE, C29, D29, E29, F29, G29) -> -D c -DWALL -b 64 -Fa alg -O1 -pipe -fno-schedule-insns -fschedule-insns2 -fno-tree-ter | I29: =VLOOKUP(B29,'HPL 4 nodes, builds'!$A$4:$Y$183,25,FALSE) -> 38.341 | K29: 245968
A30: 29 | B30: atlarch-tune-overr-flags | C30: -D c -DWALL | D30: -b 64 | F30: -Fa alg | G30: -O1 -pipe -fschedule-insns2 | H30: =_xlfn.TEXTJOIN(" ", TRUE, C30, D30, E30, F30, G30) -> -D c -DWALL -b 64 -Fa alg -O1 -pipe -fschedule-insns2 | I30: =VLOOKUP(B30,'HPL 4 nodes, builds'!$A$4:$Y$183,25,FALSE) -> 38.3944 | K30: 229366
A31: 30 | B31: arch-tune-overr-flags | C31: -D c -DWALL | D31: -b 64 | F31: -Fa alg | G31: -Os -pipe -fschedule-insns2 -mtune=native -fno-tree-ter | H31: =_xlfn.TEXTJOIN(" ", TRUE, C31, D31, E31, F31, G31) -> -D c -DWALL -b 64 -Fa alg -Os -pipe -fschedule-insns2 -mtune=native -fno-tree-ter | I31: =VLOOKUP(B31,'HPL 4 nodes, builds'!$A$4:$Y$183,25,FALSE) -> 39.0966 | K31: 246153
A32: 31 | B32: atlarch-tune-spec-crc-overr-flags | C32: -D c -DWALL | D32: -b 64 | F32: -Fa alg | G32: -O1 -pipe -fschedule-insns2 | H32: =_xlfn.TEXTJOIN(" ", TRUE, C32, D32, E32, F32, G32) -> -D c -DWALL -b 64 -Fa alg -O1 -pipe -fschedule-insns2 | I32: =VLOOKUP(B32,'HPL 4 nodes, builds'!$A$4:$Y$183,25,FALSE) -> 37.8516 | K32: 231666
... A38: 37 | B38: generic-flags | C38: -D c -DWALL | D38: -b 64 | F38: -Fa alg | G38: -Os -pipe -fschedule-insns2 -mtune=native | H38: =_xlfn.TEXTJOIN(" ", TRUE, C38, D38, E38, F38, G38) -> -D c -DWALL -b 64 -Fa alg -Os -pipe -fschedule-insns2 -mtune=native | I38: =VLOOKUP(B38,'HPL 4 nodes, builds'!$A$4:$Y$183,25,FALSE) -> 39.423 | K38: 253163
A43: Raspberry Pi 4B | C43: Other ATLAS config flags | E43: Compiler flags used for building
A44: 1 | B44: atlarch | C44: -A ARM64xgene1 | E44: N/A | F44: 37.7186
A45: 19 | B45: noarch | C45: -Si archdef 0 | E45: N/A | F45: #N/A
A46: 18 | B46: generic | C46: -Si archdef 1 | E46: N/A | F46: #N/A
A47: 17 | B47: atlarch-cpu-tune-overr | C47: -A ARM64xgene1 | D47: (override) | E47: -mcpu=cortex-a72 -mtune=cortex-a72 -mabi=lp64 | F47: #N/A
A48: 9 | B48: atlarch-cpu-tune | C48: -A ARM64xgene1 | E48: -mcpu=cortex-a72 -mtune=cortex-a72 -mabi=lp64 | F48: 38.0274
A49: 15 | B49: cpu-tune-overr | C49: N/A | D49: (override) | E49: -mcpu=cortex-a72 -mtune=cortex-a72 -mabi=lp64 | F49: #N/A
...

Sheet HPL 4 nodes, builds
A1: Max avg. GFLOPS (and params): | B1: =INDEX(A:A,MATCH(MAX($Y:$Y),$Y:$Y,0)) -> cpu-tune-overr-flags | F1: =MAX(Y:Y) -> 39.445 | G1: =INDEX(D:D,MATCH(MAX($Y:$Y),$Y:$Y,0)) -> 36000 | H1: =INDEX(E:E,MATCH(MAX($Y:$Y),$Y:$Y,0)) -> 160 | I1: =INDEX(F:F,MATCH(MAX($Y:$Y),$Y:$Y,0)) -> 2 | J1: =INDEX(G:G,MATCH(MAX($Y:$Y),$Y:$Y,0)) -> 8 | L1: ATLAS | Y1: Average GFLOPs
A2: MAX GFLOPS: | D2: =MAX(I4:I841) -> 40.12 | L2: raspi21 throttling time [1/100s] | O2: raspi22 throttling time [1/100s] | R2: raspi23 throttling time [1/100s] | U2: raspi24 throttling time [1/100s]
A3: Build | B3: RUN | D3: N | E3: NB | F3: P | G3: Q | H3: Time | I3: GFLOPS | J3: Date | K3: Time | L3: 1200MHz | M3: 1300MHz | N3: 1400MHz | O3: 1200MHz | P3: 1300MHz | Q3: 1400MHz | R3: 1200MHz | S3: 1300MHz | T3: 1400MHz | U3: 1200MHz | V3: 1300MHz | W3: 1400MHz
A4: cpu-tune-overr-flags | B4: 0 | C4: WR00L2L2 | D4: 36000 | E4: 160 | F4: 2 | G4: 8 | H4: 791.03 | I4: 39.323 | J4: 45481 | K4: 0.73668981 | L4: 0 | M4: 0 | N4: 0 | O4: 0 | P4: 0 | Q4: 0 | R4: 0 | S4: 0 | T4: 0 | U4: 0 | V4: 0 | W4: 0 | Y4: =AVERAGE(I4:I8) -> 39.445
A5: cpu-tune-overr-flags | B5: 1 | C5: WR00L2L2 | D5: 36000 | E5: 160 | F5: 2 | G5: 8 | H5: 778.07 | I5: 39.978 | J5: 45481 | K5: 0.74596065 | L5: 0 | M5: 0 | N5: 0 | O5: 0 | P5: 0 | Q5: 0 | R5: 0 | S5: 0 | T5: 0 | U5: 0 | V5: 0 | W5: 0 | Y5: =Y4 -> 39.445
A6: cpu-tune-overr-flags | B6: 2 | C6: WR00L2L2 | D6: 36000 | E6: 160 | F6: 2 | G6: 8 | H6: 775.32 | I6: 40.12 | J6: 45481 | K6: 0.75519676 | L6: 0 | M6: 0 | N6: 0 | O6: 0 | P6: 0 | Q6: 0 | R6: 0 | S6: 0 | T6: 0 | U6: 0 | V6: 0 | W6: 0 | Y6: =Y5 -> 39.445
A7: cpu-tune-overr-flags | B7: 3 | C7: WR00L2L2 | D7: 36000 | E7: 160 | F7: 2 | G7: 8 | H7: 803.21 | I7: 38.727 | J7: 45481 | K7: 0.76476852 | L7: 0 | M7: 0 | N7: 0 | O7: 0 | P7: 0 | Q7: 0 | R7: 0 | S7: 0 | T7: 0 | U7: 0 | V7: 0 | W7: 0 | Y7: =Y6 -> 39.445
A8: cpu-tune-overr-flags | B8: 4 | C8: WR00L2L2 | D8: 36000 | E8: 160 | F8: 2 | G8: 8 | H8: 796.02 | I8: 39.077 | J8: 45481 | K8: 0.77424769 | L8: 0 | M8: 0 | N8: 0 | O8: 0 | P8: 0 | Q8: 0 | R8: 0 | S8: 0 | T8: 0 | U8: 0 | V8: 0 | W8: 0 | Y8: =Y7 -> 39.445
A9: generic-flags | B9: 0 | C9: WR00L2L2 | D9: 36000 | E9: 160 | F9: 2 | G9: 8 | H9: 802.43 | I9: 38.765 | J9: 45481 | K9: 0.87944444 | L9: 0 | M9: 0 | N9: 0 | O9: 0 | P9: 0 | Q9: 0 | R9: 0 | S9: 0 | T9: 0 | U9: 0 | V9: 0 | W9: 0 | Y9: =AVERAGE(I9:I13) -> 39.423
A10: generic-flags | B10: 1 | C10: WR00L2L2 | D10: 36000 | E10: 160 | F10: 2 | G10: 8 | H10: 782.38 | I10: 39.758 | J10: 45481 | K10: 0.88878472 | L10: 0 | M10: 0 | N10: 0 | O10: 0 | P10: 0 | Q10: 0 | R10: 0 | S10: 0 | T10: 0 | U10: 0 | V10: 0 | W10: 0 | Y10: =Y9 -> 39.423
A11: generic-flags | B11: 2 | C11: WR00L2L2 | D11: 36000 | E11: 160 | F11: 2 | G11: 8 | H11: 796.9 | I11: 39.033 | J11: 45481 | K11: 0.89829861 | L11: 0 | M11: 0 | N11: 0 | O11: 0 | P11: 0 | Q11: 0 | R11: 0 | S11: 0 | T11: 0 | U11: 0 | V11: 0 | W11: 0 | Y11: =Y10 -> 39.423
A12: generic-flags | B12: 3 | C12: WR00L2L2 | D12: 36000 | E12: 160 | F12: 2 | G12: 8 | H12: 787.21 | I12: 39.514 | J12: 45481 | K12: 0.90769676 | L12: 0 | M12: 0 | N12: 0 | O12: 0 | P12: 0 | Q12: 0 | R12: 0 | S12: 0 | T12: 0 | U12: 0 | V12: 0 | W12: 0 | Y12: =Y11 -> 39.423
A13: generic-flags | B13: 4 | C13: WR00L2L2 | D13: 36000 | E13: 160 | F13: 2 | G13: 8 | H13: 776.78 | I13: 40.045 | J13: 45481 | K13: 0.91697917 | L13: 0 | M13: 0 | N13: 0 | O13: 0 | P13: 0 | Q13: 0 | R13: 0 | S13: 0 | T13: 0 | U13: 0 | V13: 0 | W13: 0 | Y13: =Y12 -> 39.423
A14: atlarch-tune-spec-overr-flags | B14: 0 | C14: WR00L2L2 | D14: 36000 | E14: 160 | F14: 2 | G14: 8 | H14: 784.44 | I14: 39.654 | J14: 45481 | K14: 0.64101852 | L14: 0 | M14: 0 | N14: 0 | O14: 0 | P14: 0 | Q14: 0 | R14: 0 | S14: 0 | T14: 0 | U14: 0 | V14: 0 | W14: 0 | Y14: =AVERAGE(I14:I18) -> 39.3184
A15: atlarch-tune-spec-overr-flags | B15: 1 | C15: WR00L2L2 | D15: 36000 | E15: 160 | F15: 2 | G15: 8 | H15: 799.19 | I15: 38.922 | J15: 45481 | K15: 0.65060185 | L15: 0 | M15: 0 | N15: 0 | O15: 0 | P15: 0 | Q15: 0 | R15: 0 | S15: 0 | T15: 0 | U15: 0 | V15: 0 | W15: 0 | Y15: =Y14 -> 39.3184
A16: atlarch-tune-spec-overr-flags | B16: 2 | C16: WR00L2L2 | D16: 36000 | E16: 160 | F16: 2 | G16: 8 | H16: 790.66 | I16: 39.342 | J16: 45481 | K16: 0.66008102 | L16: 0 | M16: 0 | N16: 0 | O16: 0 | P16: 0 | Q16: 0 | R16: 0 | S16: 0 | T16: 0 | U16: 0 | V16: 0 | W16: 0 | Y16: =Y15 -> 39.3184
A17: atlarch-tune-spec-overr-flags | B17: 3 | C17: WR00L2L2 | D17: 36000 | E17: 160 | F17: 2 | G17: 8 | H17: 784.6 | I17: 39.646 | J17: 45481 | K17: 0.66947917 | L17: 0 | M17: 0 | N17: 0 | O17: 0 | P17: 0 | Q17: 0 | R17: 0 | S17: 0 | T17: 0 | U17: 0 | V17: 0 | W17: 0 | Y17: =Y16 -> 39.3184
A18: atlarch-tune-spec-overr-flags | B18: 4 | C18: WR00L2L2 | D18: 36000 | E18: 160 | F18: 2 | G18: 8 | H18: 797.02 | I18: 39.028 | J18: 45481 | K18: 0.67903935 | L18: 0 | M18: 0 | N18: 0 | O18: 0 | P18: 0 | Q18: 0 | R18: 0 | S18: 0 | T18: 0 | U18: 0 | V18: 0 | W18: 0 | Y18: =Y17 -> 39.3184
A19: atlarch-tune-spec-crc-flags | B19: 0 | C19: WR00L2L2 | D19: 36000 | E19: 160 | F19: 2 | G19: 8 | H19: 787.29 | I19: 39.51 | J19: 45481 | K19: 0.20553241 | L19: 0 | M19: 0 | N19: 0 | O19: 0 | P19: 0 | Q19: 0 | R19: 0 | S19: 0 | T19: 0 | U19: 0 | V19: 0 | W19: 0 | Y19: =AVERAGE(I19:I23) -> 39.1944
A20: atlarch-tune-spec-crc-flags | B20: 1 | C20: WR00L2L2 | D20: 36000 | E20: 160 | F20: 2 | G20: 8 | H20: 794.48 | I20: 39.153 | J20: 45481 | K20: 0.21501157 | L20: 0 | M20: 0 | N20: 0 | O20: 0 | P20: 0 | Q20: 0 | R20: 0 | S20: 0 | T20: 0 | U20: 0 | V20: 0 | W20: 0 | Y20: =Y19 -> 39.1944
A21: atlarch-tune-spec-crc-flags | B21: 2 | C21: WR00L2L2 | D21: 36000 | E21: 160 | F21: 2 | G21: 8 | H21: 805.93 | I21: 38.596 | J21: 45481 | K21: 0.22462963 | L21: 0 | M21: 0 | N21: 0 | O21: 0 | P21: 0 | Q21: 0 | R21: 0 | S21: 0 | T21: 0 | U21: 0 | V21: 0 | W21: 0 | Y21: =Y20 -> 39.1944
A22: atlarch-tune-spec-crc-flags | B22: 3 | C22: WR00L2L2 | D22: 36000 | E22: 160 | F22: 2 | G22: 8 | H22: 798.87 | I22: 38.937 | J22: 45481 | K22: 0.23416667 | L22: 0 | M22: 0 | N22: 0 | O22: 0 | P22: 0 | Q22: 0 | R22: 0 | S22: 0 | T22: 0 | U22: 0 | V22: 0 | W22: 0 | Y22: =Y21 -> 39.1944
A23: atlarch-tune-spec-crc-flags | B23: 4 | C23: WR00L2L2 | D23: 36000 | E23: 160 | F23: 2 | G23: 8 | H23: 782.03 | I23: 39.776 | J23: 45481 | K23: 0.24350694 | L23: 0 | M23: 0 | N23: 0 | O23: 0 | P23: 0 | Q23: 0 | R23: 0 | S23: 0 | T23: 0 | U23: 0 | V23: 0 | W23: 0 | Y23: =Y22 -> 39.1944
A24: cpu-flags | B24: 0 | C24: WR00L2L2 | D24: 36000 | E24: 160 | F24: 2 | G24: 8 | H24: 789.32 | I24: 39.409 | J24: 45481 | K24: 0.30270833 | L24: 0 | M24: 0 | N24: 0 | O24: 0 | P24: 0 | Q24: 0 | R24: 0 | S24: 0 | T24: 0 | U24: 0 | V24: 0 | W24: 0 | Y24: =AVERAGE(I24:I28) -> 39.1934
A25: cpu-flags | B25: 1 | C25: WR00L2L2 | D25: 36000 | E25: 160 | F25: 2 | G25: 8 | H25: 797.6 | I25: 39 | J25: 45481 | K25: 0.31221065 | L25: 0 | M25: 0 | N25: 0 | O25: 0 | P25: 0 | Q25: 0 | R25: 0 | S25: 0 | T25: 0 | U25: 0 | V25: 0 | W25: 0 | Y25: =Y24 -> 39.1934
A26: cpu-flags | B26: 2 | C26: WR00L2L2 | D26: 36000 | E26: 160 | F26: 2 | G26: 8 | H26: 794.68 | I26: 39.143 | J26: 45481 | K26: 0.32168981 | L26: 0 | M26: 0 | N26: 0 | O26: 0 | P26: 0 | Q26: 0 | R26: 0 | S26: 0 | T26: 0 | U26: 0 | V26: 0 | W26: 0 | Y26: =Y25 -> 39.1934
A27: cpu-flags | B27: 3 | C27: WR00L2L2 | D27: 36000 | E27: 160 | F27: 2 | G27: 8 | H27: 791.7 | I27: 39.29 | J27: 45481 | K27: 0.33113426 | L27: 0 | M27: 0 | N27: 0 | O27: 0 | P27: 0 | Q27: 0 | R27: 0 | S27: 0 | T27: 0 | U27: 0 | V27: 0 | W27: 0 | Y27: =Y26 -> 39.1934
A28: cpu-flags | B28: 4 | C28: WR00L2L2 | D28: 36000 | E28: 160 | F28: 2 | G28: 8 | H28: 795.03 | I28: 39.125 | J28: 45481 | K28: 0.340625 | L28: 0 | M28: 0 | N28: 0 | O28: 0 | P28: 0 | Q28: 0 | R28: 0 | S28: 0 | T28: 0 | U28: 0 | V28: 0 | W28: 0 | Y28: =Y27 -> 39.1934
A29: arch-tune-overr-flags | B29: 0 | C29: WR00L2L2 | D29: 36000 | E29: 160 | F29: 2 | G29: 8 | H29: 804.65 | I29: 38.658 | J29: 45481 | K29: 0.54454861 | L29: 0 | M29: 0 | N29: 0 | O29: 0 | P29: 0 | Q29: 0 | R29: 0 | S29: 0 | T29: 0 | U29: 0 | V29: 0 | W29: 0 | Y29: =AVERAGE(I29:I33) -> 39.0966
A30: arch-tune-overr-flags | B30: 1 | C30: WR00L2L2 | D30: 36000 | E30: 160 | F30: 2 | G30: 8 | H30: 794.97 | I30: 39.129 | J30: 45481 | K30: 0.5540162 | L30: 0 | M30: 0 | N30: 0 | O30: 0 | P30: 0 | Q30: 0 | R30: 0 | S30: 0 | T30: 0 | U30: 0 | V30: 0 | W30: 0 | Y30: =Y29 -> 39.0966
A31: arch-tune-overr-flags | B31: 2 | C31: WR00L2L2 | D31: 36000 | E31: 160 | F31: 2 | G31: 8 | H31: 792.38 | I31: 39.257 | J31: 45481 | K31: 0.56344907 | L31: 0 | M31: 0 | N31: 0 | O31: 0 | P31: 0 | Q31: 0 | R31: 0 | S31: 0 | T31: 0 | U31: 0 | V31: 0 | W31: 0 | Y31: =Y30 -> 39.0966
A32: arch-tune-overr-flags | B32: 3 | C32: WR00L2L2 | D32: 36000 | E32: 160 | F32: 2 | G32: 8 | H32: 789.36 | I32: 39.406 | J32: 45481 | K32: 0.5728588 | L32: 0 | M32: 0 | N32: 0 | O32: 0 | P32: 0 | Q32: 0 | R32: 0 | S32: 0 | T32: 0 | U32: 0 | V32: 0 | W32: 0 | Y32: =Y31 -> 39.0966
A33: arch-tune-overr-flags | B33: 4 | C33: WR00L2L2 | D33: 36000 | E33: 160 | F33: 2 | G33: 8 | H33: 796.92 | I33: 39.033 | J33: 45481 | K33: 0.58234954 | L33: 0 | M33: 0 | N33: 0 | O33: 0 | P33: 0 | Q33: 0 | R33: 0 | S33: 0 | T33: 0 | U33: 0 | V33: 0 | W33: 0 | Y33: =Y32 -> 39.0966
A34: atlarch-cpu-tune-overr-flags | B34: 0 | C34: WR00L2L2 | D34: 36000 | E34: 160 | F34: 2 | G34: 8 | H34: 804.88 | I34: 38.647 | J34: 45481 | K34: 0.83175926 | L34: 0 | M34: 0 | N34: 0 | O34: 0 | P34: 0 | Q34: 0 | R34: 0 | S34: 0 | T34: 0 | U34: 0 | V34: 0 | W34: 0 | Y34: =AVERAGE(I34:I38) -> 39.0376
A35: atlarch-cpu-tune-overr-flags | B35: 1 | C35: WR00L2L2 | D35: 36000 | E35: 160 | F35: 2 | G35: 8 | H35: 798.67 | I35: 38.947 | J35: 45481 | K35: 0.84133102 | L35: 0 | M35: 0 | N35: 0 | O35: 0 | P35: 0 | Q35: 0 | R35: 0 | S35: 0 | T35: 0 | U35: 0 | V35: 0 | W35: 0 | Y35: =Y34 -> 39.0376
A36: atlarch-cpu-tune-overr-flags | B36: 2 | C36: WR00L2L2 | D36: 36000 | E36: 160 | F36: 2 | G36: 8 | H36: 803.29 | I36: 38.723 | J36: 45481 | K36: 0.85094907 | L36: 0 | M36: 0 | N36: 0 | O36: 0 | P36: 0 | Q36: 0 | R36: 0 | S36: 0 | T36: 0 | U36: 0 | V36: 0 | W36: 0 | Y36: =Y35 -> 39.0376
A37: atlarch-cpu-tune-overr-flags | B37: 3 | C37: WR00L2L2 | D37: 36000 | E37: 160 | F37: 2 | G37: 8 | H37: 798.62 | I37: 38.95 | J37: 45481 | K37: 0.86052083 | L37: 0 | M37: 0 | N37: 0 | O37: 0 | P37: 0 | Q37: 0 | R37: 0 | S37: 0 | T37: 0 | U37: 0 | V37: 0 | W37: 0 | Y37: =Y36 -> 39.0376
A38: atlarch-cpu-tune-overr-flags | B38: 4 | C38: WR00L2L2 | D38: 36000 | E38: 160 | F38: 2 | G38: 8 | H38: 779.19 | I38: 39.921 | J38: 45481 | K38: 0.86986111 | L38: 0 | M38: 0 | N38: 0 | O38: 0 | P38: 0 | Q38: 0 | R38: 0 | S38: 0 | T38: 0 | U38: 0 | V38: 0 | W38: 0 | Y38: =Y37 -> 39.0376
A39: atlarch-cpu-overr-flags | B39: 0 | C39: WR00L2L2 | D39: 36000 | E39: 160 | F39: 2 | G39: 8 | H39: 802.1 | I39: 38.781 | J39: 45481 | K39: 0.78385417 | L39: 0 | M39: 0 | N39: 0 | O39: 0 | P39: 0 | Q39: 0 | R39: 0 | S39: 0 | T39: 0 | U39: 0 | V39: 0 | W39: 0 | Y39: =AVERAGE(I39:I43) -> 38.9472
A40: atlarch-cpu-overr-flags | B40: 1 | C40: WR00L2L2 | D40: 36000 | E40: 160 | F40: 2 | G40: 8 | H40: 800.8 | I40: 38.844 | J40: 45481 | K40: 0.79344907 | L40: 0 | M40: 0 | N40: 0 | O40: 0 | P40: 0 | Q40: 0 | R40: 0 | S40: 0 | T40: 0 | U40: 0 | V40: 0 | W40: 0 | Y40: =Y39 -> 38.9472
...

Sheet 1 node, params, RAW
A1: Max avg. GFLOPS (and params): | E1: =MAX(N:N) -> 11.673 | F1: =INDEX(C:C,MATCH(MAX($N:$N),$N:$N,0)) -> 19040 | G1: =INDEX(D:D,MATCH(MAX($N:$N),$N:$N,0)) -> 160 | H1: =INDEX(E:E,MATCH(MAX($N:$N),$N:$N,0)) -> 1 | I1: =INDEX(F:F,MATCH(MAX($N:$N),$N:$N,0)) -> 4 | K1: ATLAS ("--bind to" ne utječe na rez) | N1: Average GFLOP/s | Q1: Max avg. GFLOPS (and params): | U1: =MAX(AD:AD) -> 12.9226 | V1: =INDEX(S:S,MATCH(MAX($AD:$AD),$AD:$AD,0)) -> 20096 | W1: =INDEX(T:T,MATCH(MAX($AD:$AD),$AD:$AD,0)) -> 128 | X1: =INDEX(U:U,MATCH(MAX($AD:$AD),$AD:$AD,0)) -> 1 | Y1: =INDEX(V:V,MATCH(MAX($AD:$AD),$AD:$AD,0)) -> 4 | AA1: OpenBLAS | AD1: Average GFLOP/s | AF1: Max avg. GFLOPS (and params): | AJ1: =MAX(AS:AS) -> 13.0066 | AK1: =INDEX(AH:AH,MATCH(MAX($AS:$AS),$AS:$AS,0)) -> 20096 | AL1: =INDEX(AI:AI,MATCH(MAX($AS:$AS),$AS:$AS,0)) -> 128 | AM1: =INDEX(AJ:AJ,MATCH(MAX($AS:$AS),$AS:$AS,0)) -> 1 | AN1: =INDEX(AK:AK,MATCH(MAX($AS:$AS),$AS:$AS,0)) -> 4 | AP1: OpenBLAS (--bind-to core za mpiexec) | AS1: Average GFLOP/s | AV1: Max avg. GFLOPS (and params): | AZ1: =MAX(BI:BI) -> 12.889333 | BA1: =INDEX(AX:AX,MATCH(MAX($BI:$BI),$BI:$BI,0)) -> 20096 | BB1: =INDEX(AY:AY,MATCH(MAX($BI:$BI),$BI:$BI,0)) -> 128 | BC1: =INDEX(AZ:AZ,MATCH(MAX($BI:$BI),$BI:$BI,0)) -> 1 | BD1: =INDEX(BA:BA,MATCH(MAX($BI:$BI),$BI:$BI,0)) -> 4 | BF1: OpenBLAS - old, by Luke Vassallo | BI1: Average GFLOP/s
A2: MAX GFLOPS: | C2: =MAX(H4:H835) -> 11.748 | K2: raspi21 throttling time [1/100s] | Q2: MAX GFLOPS: | S2: =MAX(X4:X835) -> 13.224 | AA2: raspi21 throttling time [1/100s] | AF2: MAX GFLOPS: | AH2: =MAX(AM4:AM835) -> 13.113 | AP2: raspi21 throttling time [1/100s] | AV2: MAX GFLOPS: | AX2: =MAX(BC4:BC835) -> 13.034 | BF2: raspi21 throttling time [1/100s]
A3: RUN | C3: N | D3: NB | E3: P | F3: Q | G3: Time | H3: GFLOPS | I3: Date | J3: Time | K3: 1200MHz | L3: 1300MHz | M3: 1400MHz | Q3: RUN | S3: N | T3: NB | U3: P | V3: Q | W3: Time | X3: GFLOPS | Y3: Date | Z3: Time | AA3: 1200MHz | AB3: 1300MHz | AC3: 1400MHz | AF3: RUN | AH3: N | AI3: NB | AJ3: P | AK3: Q | AL3: Time | AM3: GFLOPS | AN3: Date | AO3: Time | AP3: 1200MHz | AQ3: 1300MHz | AR3: 1400MHz | AV3: RUN | AX3: N | AY3: NB | AZ3: P | BA3: Q | BB3: Time | BC3: GFLOPS | BD3: Date | BE3: Time | BF3: 1200MHz | BG3: 1300MHz | BH3: 1400MHz
A4: 0 | B4: WR00L2L2 | C4: 17984 | D4: 32 | E4: 1 | F4: 4 | G4: 566.48 | H4: 6.846 | I4: 45508 | J4: 0.84255787 | K4: 0 | L4: 0 | M4: 0 | N4: =AVERAGE(H4:H8) -> 6.87264 | Q4: 0 | R4: WR00L2L2 | S4: 17984 | T4: 32 | U4: 1 | V4: 4 | W4: 518.2 | X4: 7.4838 | Y4: 45505 | Z4: 0.72141204 | AA4: 0 | AB4: 0 | AC4: 0 | AD4: =AVERAGE(X4:X8) -> 7.46272 | AF4: 0 | AG4: WR00L2L2 | AH4: 20096 | AI4: 128 | AJ4: 1 | AK4: 4 | AL4: 412.64 | AM4: 13.113 | AN4: 45509 | AO4: 0.026041667 | AP4: 0 | AQ4: 0 | AR4: 0 | AS4: =AVERAGE(AM4:AM8) -> 13.0066 | AT4: =AS4 -> 13.0066 | AV4: id | AW4: experiment_name | AX4: HPL_N | AY4: HPL_NB | AZ4: HPL_P | BA4: HPL_Q | BB4: HPL_TIME | BC4: HPL_FLOPS
A5: 1 | B5: WR00L2L2 | C5: 17984 | D5: 32 | E5: 1 | F5: 4 | G5: 563.96 | H5: 6.8766 | I5: 45509 | J5: 0.11178241 | K5: 0 | L5: 0 | M5: 0 | N5: =N4 -> 6.87264 | Q5: 1 | R5: WR00L2L2 | S5: 17984 | T5: 32 | U5: 1 | V5: 4 | W5: 519.9 | X5: 7.4594 | Y5: 45505 | Z5: 0.96112269 | AA5: 0 | AB5: 0 | AC5: 0 | AD5: =AD4 -> 7.46272 | AF5: 1 | AG5: WR00L2L2 | AH5: 20096 | AI5: 128 | AJ5: 1 | AK5: 4 | AL5: 415.81 | AM5: 13.013 | AN5: 45509 | AO5: 0.26369213 | AP5: 0 | AQ5: 0 | AR5: 0 | AS5: =AS4 -> 13.0066 | AT5: =AT4 -> 13.0066 | AV5: 1 | AW5: test-1node | AX5: 18048 | AY5: 32 | AZ5: 1 | BA5: 4 | BB5: 527.2 | BC5: 7.4349 | BF5: 0 | BG5: 0 | BH5: 0 | BI5: =AVERAGE(BC5:BC10) -> 7.4426333
A6: 2 | B6: WR00L2L2 | C6: 17984 | D6: 32 | E6: 1 | F6: 4 | G6: 563.83 | H6: 6.8782 | I6: 45509 | J6: 0.37996528 | K6: 0 | L6: 0 | M6: 0 | N6: =N5 -> 6.87264 | Q6: 2 | R6: WR00L2L2 | S6: 17984 | T6: 32 | U6: 1 | V6: 4 | W6: 520.34 | X6: 7.4531 | Y6: 45506 | Z6: 0.19832176 | AA6: 0 | AB6: 0 | AC6: 0 | AD6: =AD5 -> 7.46272 | AF6: 2 | AG6: WR00L2L2 | AH6: 20096 | AI6: 128 | AJ6: 1 | AK6: 4 | AL6: 418.29 | AM6: 12.936 | AN6: 45509 | AO6: 0.5019213 | AP6: 0 | AQ6: 0 | AR6: 0 | AS6: =AS5 -> 13.0066 | AT6: =AT5 -> 13.0066 | AV6: 49 | AW6: test-1node | AX6: 18048 | AY6: 32 | AZ6: 1 | BA6: 4 | BB6: 525.69 | BC6: 7.4563 | BF6: 0 | BG6: 0 | BH6: 0 | BI6: =BI5 -> 7.4426333
A7: 3 | B7: WR00L2L2 | C7: 17984 | D7: 32 | E7: 1 | F7: 4 | G7: 563.4 | H7: 6.8835 | I7: 45509 | J7: 0.6478588 | K7: 0 | L7: 0 | M7: 0 | N7: =N6 -> 6.87264 | Q7: 3 | R7: WR00L2L2 | S7: 17984 | T7: 32 | U7: 1 | V7: 4 | W7: 519.86 | X7: 7.46 | Y7: 45506 | Z7: 0.43575231 | AA7: 0 | AB7: 0 | AC7: 0 | AD7: =AD6 -> 7.46272 | AF7: 3 | AG7: WR00L2L2 | AH7: 20096 | AI7: 128 | AJ7: 1 | AK7: 4 | AL7: 415.47 | AM7: 13.024 | AN7: 45509 | AO7: 0.74020833 | AP7: 0 | AQ7: 0 | AR7: 0 | AS7: =AS6 -> 13.0066 | AT7: =AT6 -> 13.0066 | AV7: 97 | AW7: test-1node | AX7: 18048 | AY7: 32 | AZ7: 1 | BA7: 4 | BB7: 526.57 | BC7: 7.4438 | BF7: 0 | BG7: 0 | BH7: 0 | BI7: =BI6 -> 7.4426333
A8: 4 | B8: WR00L2L2 | C8: 17984 | D8: 32 | E8: 1 | F8: 4 | G8: 563.77 | H8: 6.8789 | I8: 45509 | J8: 0.91585648 | K8: 0 | L8: 0 | M8: 0 | N8: =N7 -> 6.87264 | Q8: 4 | R8: WR00L2L2 | S8: 17984 | T8: 32 | U8: 1 | V8: 4 | W8: 520.04 | X8: 7.4573 | Y8: 45506 | Z8: 0.67290509 | AA8: 0 | AB8: 0 | AC8: 0 | AD8: =AD7 -> 7.46272 | AF8: 4 | AG8: WR00L2L2 | AH8: 20096 | AI8: 128 | AJ8: 1 | AK8: 4 | AL8: 417.95 | AM8: 12.947 | AN8: 45509 | AO8: 0.97791667 | AP8: 0 | AQ8: 0 | AR8: 0 | AS8: =AS7 -> 13.0066 | AT8: =AT7 -> 13.0066 | AV8: 145 | AW8: test-1node | AX8: 18048 | AY8: 32 | AZ8: 1 | BA8: 4 | BB8: 526.26 | BC8: 7.4481 | BF8: 0 | BG8: 0 | BH8: 0 | BI8: =BI7 -> 7.4426333
A9: 0 | B9: WR00L2L2 | C9: 19072 | D9: 32 | E9: 1 | F9: 4 | G9: 657.65 | H9: 7.0332 | I9: 45508 | J9: 0.91997685 | K9: 0 | L9: 0 | M9: 0 | N9: =AVERAGE(H9:H13) -> 7.0233 | Q9: 0 | R9: WR00L2L2 | S9: 19072 | T9: 32 | U9: 1 | V9: 4 | W9: 587.42 | X9: 7.8741 | Y9: 45505 | Z9: 0.78939815 | AA9: 0 | AB9: 0 | AC9: 0 | AD9: =AVERAGE(X9:X13) -> 7.84898 | AF9: 0 | AG9: WR00L2L2 | AH9: 19072 | AI9: 128 | AJ9: 1 | AK9: 4 | AL9: 364.37 | AM9: 12.694 | AN9: 45508 | AO9: 0.94113426 | AP9: 0 | AQ9: 0 | AR9: 0 | AS9: =AVERAGE(AM9:AM13) -> 12.9614 | AT9: =AS9 -> 12.9614 | AV9: 193 | AW9: test-1node | AX9: 18048 | AY9: 32 | AZ9: 1 | BA9: 4 | BB9: 527.39 | BC9: 7.4322 | BF9: 0 | BG9: 0 | BH9: 0 | BI9: =BI8 -> 7.4426333
A10: 1 | B10: WR00L2L2 | C10: 19072 | D10: 32 | E10: 1 | F10: 4 | G10: 665.85 | H10: 6.9466 | I10: 45509 | J10: 0.18851852 | K10: 0 | L10: 0 | M10: 0 | N10: =N9 -> 7.0233 | Q10: 1 | R10: WR00L2L2 | S10: 19072 | T10: 32 | U10: 1 | V10: 4 | W10: 587.94 | X10: 7.8671 | Y10: 45506 | Z10: 0.028414352 | AA10: 0 | AB10: 0 | AC10: 0 | AD10: =AD9 -> 7.84898 | AF10: 1 | AG10: WR00L2L2 | AH10: 19072 | AI10: 128 | AJ10: 1 | AK10: 4 | AL10: 357.13 | AM10: 12.952 | AN10: 45509 | AO10: 0.1784375 | AP10: 0 | AQ10: 0 | AR10: 0 | AS10: =AS9 -> 12.9614 | AT10: =AT9 -> 12.9614 | AV10: 241 | AW10: test-1node | AX10: 18048 | AY10: 32 | AZ10: 1 | BA10: 4 | BB10: 526.8 | BC10: 7.4405 | BF10: 0 | BG10: 0 | BH10: 0 | BI10: =BI9 -> 7.4426333
A11: 2 | B11: WR00L2L2 | C11: 19072 | D11: 32 | E11: 1 | F11: 4 | G11: 656.74 | H11: 7.043 | I11: 45509 | J11: 0.45658565 | K11: 0 | L11: 0 | M11: 0 | N11: =N10 -> 7.0233 | Q11: 2 | R11: WR00L2L2 | S11: 19072 | T11: 32 | U11: 1 | V11: 4 | W11: 589.31 | X11: 7.8489 | Y11: 45506 | Z11: 0.26583333 | AA11: 0 | AB11: 0 | AC11: 0 | AD11: =AD10 -> 7.84898 | AF11: 2 | AG11: WR00L2L2 | AH11: 19072 | AI11: 128 | AJ11: 1 | AK11: 4 | AL11: 353.6 | AM11: 13.081 | AN11: 45509 | AO11: 0.41577546 | AP11: 0 | AQ11: 0 | AR11: 0 | AS11: =AS10 -> 12.9614 | AT11: =AT10 -> 12.9614 | AV11: 17 | AW11: test-1node | AX11: 19072 | AY11: 32 | AZ11: 1 | BA11: 4 | BB11: 593.61 | BC11: 7.792 | BF11: 0 | BG11: 0 | BH11: 0 | BI11: =AVERAGE(BC11:BC16) -> 7.7875833
A12: 3 | B12: WR00L2L2 | C12: 19072 | D12: 32 | E12: 1 | F12: 4 | G12: 656.55 | H12: 7.045 | I12: 45509 | J12: 0.72453704 | K12: 0 | L12: 0 | M12: 0 | N12: =N11 -> 7.0233 | Q12: 3 | R12: WR00L2L2 | S12: 19072 | T12: 32 | U12: 1 | V12: 4 | W12: 591.47 | X12: 7.8202 | Y12: 45506 | Z12: 0.50315972 | AA12: 0 | AB12: 0 | AC12: 0 | AD12: =AD11 -> 7.84898 | AF12: 3 | AG12: WR00L2L2 | AH12: 19072 | AI12: 128 | AJ12: 1 | AK12: 4 | AL12: 352.89 | AM12: 13.107 | AN12: 45509 | AO12: 0.65447917 | AP12: 0 | AQ12: 0 | AR12: 0 | AS12: =AS11 -> 12.9614 | AT12: =AT11 -> 12.9614 | AV12: 65 | AW12: test-1node | AX12: 19072 | AY12: 32 | AZ12: 1 | BA12: 4 | BB12: 592.51 | BC12: 7.8064 | BF12: 0 | BG12: 0 | BH12: 0 | BI12: =BI11 -> 7.7875833
A13: 4 | B13: WR00L2L2 | C13: 19072 | D13: 32 | E13: 1 | F13: 4 | G13: 656.21 | H13: 7.0487 | I13: 45509 | J13: 0.9924537 | K13: 0 | L13: 0 | M13: 0 | N13: =N12 -> 7.0233 | Q13: 4 | R13: WR00L2L2 | S13: 19072 | T13: 32 | U13: 1 | V13: 4 | W13: 590.38 | X13: 7.8346 | Y13: 45506 | Z13: 0.74033565 | AA13: 0 | AB13: 0 | AC13: 0 | AD13: =AD12 -> 7.84898 | AF13: 4 | AG13: WR00L2L2 | AH13: 19072 | AI13: 128 | AJ13: 1 | AK13: 4 | AL13: 356.53 | AM13: 12.973 | AN13: 45509 | AO13: 0.89252315 | AP13: 0 | AQ13: 0 | AR13: 0 | AS13: =AS12 -> 12.9614 | AT13: =AT12 -> 12.9614 | AV13: 113 | AW13: test-1node | AX13: 19072 | AY13: 32 | AZ13: 1 | BA13: 4 | BB13: 593.35 | BC13: 7.7954 | BF13: 0 | BG13: 0 | BH13: 0 | BI13: =BI12 -> 7.7875833
A14: 0 | B14: WR00L2L2 | C14: 20160 | D14: 32 | E14: 1 | F14: 4 | G14: 787.67 | H14: 6.9356 | I14: 45509 | J14: 0.010115741 | K14: 0 | L14: 0 | M14: 0 | N14: =AVERAGE(H14:H18) -> 6.92302 | Q14: 0 | R14: WR00L2L2 | S14: 20160 | T14: 32 | U14: 1 | V14: 4 | W14: 711.94 | X14: 7.6734 | Y14: 45505 | Z14: 0.87028935 | AA14: 0 | AB14: 0 | AC14: 0 | AD14: =AVERAGE(X14:X18) -> 7.6702 | AF14: 0 | AG14: WR00L2L2 | AH14: 19008 | AI14: 192 | AJ14: 1 | AK14: 4 | AL14: 356.68 | AM14: 12.838 | AN14: 45508 | AO14: 0.95920139 | AP14: 0 | AQ14: 0 | AR14: 0 | AS14: =AVERAGE(AM14:AM18) -> 12.8602 | AT14: =AS14 -> 12.8602 | AV14: 161 | AW14: test-1node | AX14: 19072 | AY14: 32 | AZ14: 1 | BA14: 4 | BB14: 597.05 | BC14: 7.747 | BF14: 0 | BG14: 0 | BH14: 0 | BI14: =BI13 -> 7.7875833
A15: 1 | B15: WR00L2L2 | C15: 20160 | D15: 32 | E15: 1 | F15: 4 | G15: 787.9 | H15: 6.9336 | I15: 45509 | J15: 0.27825231 | K15: 0 | L15: 0 | M15: 0 | N15: =N14 -> 6.92302 | Q15: 1 | R15: WR00L2L2 | S15: 20160 | T15: 32 | U15: 1 | V15: 4 | W15: 710.23 | X15: 7.6918 | Y15: 45506 | Z15: 0.10800926 | AA15: 0 | AB15: 0 | AC15: 0 | AD15: =AD14 -> 7.6702 | AF15: 1 | AG15: WR00L2L2 | AH15: 19008 | AI15: 192 | AJ15: 1 | AK15: 4 | AL15: 354.92 | AM15: 12.902 | AN15: 45509 | AO15: 0.19662037 | AP15: 0 | AQ15: 0 | AR15: 0 | AS15: =AS14 -> 12.8602 | AT15: =AT14 -> 12.8602 | AV15: 209 | AW15: test-1node | AX15: 19072 | AY15: 32 | AZ15: 1 | BA15: 4 | BB15: 594.62 | BC15: 7.7788 | BF15: 0 | BG15: 0 | BH15: 0 | BI15: =BI14 -> 7.7875833
A16: 2 | B16: WR00L2L2 | C16: 20160 | D16: 32 | E16: 1 | F16: 4 | G16: 790.24 | H16: 6.913 | I16: 45509 | J16: 0.54626157 | K16: 0 | L16: 0 | M16: 0 | N16: =N15 -> 6.92302 | Q16: 2 | R16: WR00L2L2 | S16: 20160 | T16: 32 | U16: 1 | V16: 4 | W16: 712.64 | X16: 7.6659 | Y16: 45506 | Z16: 0.34525463 | AA16: 0 | AB16: 0 | AC16: 0 | AD16: =AD15 -> 7.6702 | AF16: 2 | AG16: WR00L2L2 | AH16: 19008 | AI16: 192 | AJ16: 1 | AK16: 4 | AL16: 354.32 | AM16: 12.923 | AN16: 45509 | AO16: 0.43391204 | AP16: 0 | AQ16: 0 | AR16: 0 | AS16: =AS15 -> 12.8602 | AT16: =AT15 -> 12.8602 | AV16: 257 | AW16: test-1node | AX16: 19072 | AY16: 32 | AZ16: 1 | BA16: 4 | BB16: 592.55 | BC16: 7.8059 | BF16: 0 | BG16: 0 | BH16: 0 | BI16: =BI15 -> 7.7875833
A17: 3 | B17: WR00L2L2 | C17: 20160 | D17: 32 | E17: 1 | F17: 4 | G17: 790.81 | H17: 6.9081 | I17: 45509 | J17: 0.81415509 | K17: 0 | L17: 0 | M17: 0 | N17: =N16 -> 6.92302 | Q17: 3 | R17: WR00L2L2 | S17: 20160 | T17: 32 | U17: 1 | V17: 4 | W17: 712.52 | X17: 7.6671 | Y17: 45506 | Z17: 0.58262731 | AA17: 0 | AB17: 0 | AC17: 0 | AD17: =AD16 -> 7.6702 | AF17: 3 | AG17: WR00L2L2 | AH17: 19008 | AI17: 192 | AJ17: 1 | AK17: 4 | AL17: 358.9 | AM17: 12.758 | AN17: 45509 | AO17: 0.67280093 | AP17: 0 | AQ17: 0 | AR17: 0 | AS17: =AS16 -> 12.8602 | AT17: =AT16 -> 12.8602 | AV17: 33 | AW17: test-1node | AX17: 20096 | AY17: 32 | AZ17: 1 | BA17: 4 | BB17: 700.72 | BC17: 7.7222 | BF17: 0 | BG17: 0 | BH17: 0 | BI17: =AVERAGE(BC17:BC22) -> 7.68585
A18: 4 | B18: WR00L2L2 | C18: 20160 | D18: 32 | E18: 1 | F18: 4 | G18: 788.9 | H18: 6.9248 | I18: 45510 | J18: 0.082141204 | K18: 0 | L18: 0 | M18: 0 | N18: =N17 -> 6.92302 | Q18: 4 | R18: WR00L2L2 | S18: 20160 | T18: 32 | U18: 1 | V18: 4 | W18: 713.86 | X18: 7.6528 | Y18: 45506 | Z18: 0.82027778 | AA18: 0 | AB18: 0 | AC18: 0 | AD18: =AD17 -> 7.6702 | AF18: 4 | AG18: WR00L2L2 | AH18: 19008 | AI18: 192 | AJ18: 1 | AK18: 4 | AL18: 355.52 | AM18: 12.88 | AN18: 45509 | AO18: 0.91061343 | AP18: 0 | AQ18: 0 | AR18: 0 | AS18: =AS17 -> 12.8602 | AT18: =AT17 -> 12.8602 | AV18: 81 | AW18: test-1node | AX18: 20096 | AY18: 32 | AZ18: 1 | BA18: 4 | BB18: 702.1 | BC18: 7.7071 | BF18: 0 | BG18: 0 | BH18: 0 | BI18: =BI17 -> 7.68585
A19: 0 | B19: WR00L2L2 | C19: 17984 | D19: 32 | E19: 2 | F19: 2 | G19: 563.08 | H19: 6.8873 | I19: 45508 | J19: 0.84931713 | K19: 0 | L19: 0 | M19: 0 | N19: =AVERAGE(H19:H23) -> 6.8488 | Q19: 0 | R19: WR00L2L2 | S19: 17984 | T19: 32 | U19: 2 | V19: 2 | W19: 506.12 | X19: 7.6625 | Y19: 45505 | Z19: 0.72751157 | AA19: 0 | AB19: 0 | AC19: 0 | AD19: =AVERAGE(X19:X23) -> 7.65188 | AF19: 0 | AG19: WR00L2L2 | AH19: 20160 | AI19: 192 | AJ19: 1 | AK19: 4 | AL19: 426.13 | AM19: 12.82 | AN19: 45509 | AO19: 0.047592593 | AP19: 0 | AQ19: 0 | AR19: 0 | AS19: =AVERAGE(AM19:AM23) -> 12.7894 | AT19: =AS19 -> 12.7894 | AV19: 129 | AW19: test-1node | AX19: 20096 | AY19: 32 | AZ19: 1 | BA19: 4 | BB19: 700.34 | BC19: 7.7264 | BF19: 0 | BG19: 0 | BH19: 0 | BI19: =BI18 -> 7.68585
A20: 1 | B20: WR00L2L2 | C20: 17984 | D20: 32 | E20: 2 | F20: 2 | G20: 566.81 | H20: 6.842 | I20: 45509 | J20: 0.11857639 | K20: 0 | L20: 0 | M20: 0 | N20: =N19 -> 6.8488 | Q20: 1 | R20: WR00L2L2 | S20: 17984 | T20: 32 | U20: 2 | V20: 2 | W20: 507.46 | X20: 7.6423 | Y20: 45505 | Z20: 0.96724537 | AA20: 0 | AB20: 0 | AC20: 0 | AD20: =AD19 -> 7.65188 | AF20: 1 | AG20: WR00L2L2 | AH20: 20160 | AI20: 192 | AJ20: 1 | AK20: 4 | AL20: 425.08 | AM20: 12.852 | AN20: 45509 | AO20: 0.28524306 | AP20: 0 | AQ20: 0 | AR20: 0 | AS20: =AS19 -> 12.7894 | AT20: =AT19 -> 12.7894 | AV20: 177 | AW20: test-1node | AX20: 20096 | AY20: 32 | AZ20: 1 | BA20: 4 | BB20: 702.13 | BC20: 7.7067 | BF20: 0 | BG20: 0 | BH20: 0 | BI20: =BI19 -> 7.68585
A21: 2 | B21: WR00L2L2 | C21: 17984 | D21: 32 | E21: 2 | F21: 2 | G21: 566.09 | H21: 6.8507 | I21: 45509 | J21: 0.38675926 | K21: 0 | L21: 0 | M21: 0 | N21: =N20 -> 6.8488 | Q21: 2 | R21: WR00L2L2 | S21: 17984 | T21: 32 | U21: 2 | V21: 2 | W21: 506.44 | X21: 7.6576 | Y21: 45506 | Z21: 0.20443287 | AA21: 0 | AB21: 0 | AC21: 0 | AD21: =AD20 -> 7.65188 | AF21: 2 | AG21: WR00L2L2 | AH21: 20160 | AI21: 192 | AJ21: 1 | AK21: 4 | AL21: 429 | AM21: 12.734 | AN21: 45509 | AO21: 0.52356481 | AP21: 0 | AQ21: 0 | AR21: 0 | AS21: =AS20 -> 12.7894 | AT21: =AT20 -> 12.7894 | AV21: 225 | AW21: test-1node | AX21: 20096 | AY21: 32 | AZ21: 1 | BA21: 4 | BB21: 703.8 | BC21: 7.6884 | BF21: 0 | BG21: 0 | BH21: 0 | BI21: =BI20 -> 7.68585
A22: 3 | B22: WR00L2L2 | C22: 17984 | D22: 32 | E22: 2 | F22: 2 | G22: 566.65 | H22: 6.844 | I22: 45509 | J22: 0.65465278 | K22: 0 | L22: 0 | M22: 0 | N22: =N21 -> 6.8488 | Q22: 3 | R22: WR00L2L2 | S22: 17984 | T22: 32 | U22: 2 | V22: 2 | W22: 506.87 | X22: 7.6512 | Y22: 45506 | Z22: 0.44186343 | AA22: 0 | AB22: 0 | AC22: 0 | AD22: =AD21 -> 7.65188 | AF22: 3 | AG22: WR00L2L2 | AH22: 20160 | AI22: 192 | AJ22: 1 | AK22: 4 | AL22: 426.39 | AM22: 12.812 | AN22: 45509 | AO22: 0.76178241 | AP22: 0 | AQ22: 0 | AR22: 0 | AS22: =AS21 -> 12.7894 | AT22: =AT21 -> 12.7894 | AV22: 273 | AW22: test-1node | AX22: 20096 | AY22: 32 | AZ22: 1 | BA22: 4 | BB22: 715.34 | BC22: 7.5643 | BF22: 0 | BG22: 0 | BH22: 0 | BI22: =BI21 -> 7.68585
A23: 4 | B23: WR00L2L2 | C23: 17984 | D23: 32 | E23: 2 | F23: 2 | G23: 568.64 | H23: 6.82 | I23: 45509 | J23: 0.92267361 | K23: 0 | L23: 0 | M23: 0 | N23: =N22 -> 6.8488 | Q23: 4 | R23: WR00L2L2 | S23: 17984 | T23: 32 | U23: 2 | V23: 2 | W23: 507.23 | X23: 7.6458 | Y23: 45506 | Z23: 0.6790162 | AA23: 0 | AB23: 0 | AC23: 0 | AD23: =AD22 -> 7.65188 | AF23: 4 | AG23: WR00L2L2 | AH23: 20160 | AI23: 192 | AJ23: 1 | AK23: 4 | AL23: 429.18 | AM23: 12.729 | AN23: 45509 | AO23: 0.99950231 | AP23: 0 | AQ23: 0 | AR23: 0 | AS23: =AS22 -> 12.7894 | AT23: =AT22 -> 12.7894 | AV23: 2 | AW23: test-1node | AX23: 18048 | AY23: 32 | AZ23: 2 | BA23: 2 | BB23: 509.84 | BC23: 7.688 | BF23: 0 | BG23: 0 | BH23: 0 | BI23: =AVERAGE(BC23:BC28) -> 7.68225
A24: 0 | B24: WR00L2L2 | C24: 19072 | D24: 32 | E24: 2 | F24: 2 | G24: 666.08 | H24: 6.9442 | I24: 45508 | J24: 0.92795139 | K24: 0 | L24: 0 | M24: 0 | N24: =AVERAGE(H24:H28) -> 6.94606 | Q24: 0 | R24: WR00L2L2 | S24: 19072 | T24: 32 | U24: 2 | V24: 2 | W24: 597.47 | X24: 7.7416 | Y24: 45505 | Z24: 0.79658565 | AA24: 0 | AB24: 0 | AC24: 0 | AD24: =AVERAGE(X24:X28) -> 7.74676 | AF24: 0 | AG24: WR00L2L2 | AH24: 19008 | AI24: 96 | AJ24: 1 | AK24: 4 | AL24: 356.45 | AM24: 12.846 | AN24: 45508 | AO24: 0.93208333 | AP24: 0 | AQ24: 0 | AR24: 0 | AS24: =AVERAGE(AM24:AM28) -> 12.779 | AT24: =AS24 -> 12.779 | AV24: 50 | AW24: test-1node | AX24: 18048 | AY24: 32 | AZ24: 2 | BA24: 2 | BB24: 511.07 | BC24: 7.6696 | BF24: 0 | BG24: 0 | BH24: 0 | BI24: =BI23 -> 7.68225
A25: 1 | B25: WR00L2L2 | C25: 19072 | D25: 32 | E25: 2 | F25: 2 | G25: 665.89 | H25: 6.9462 | I25: 45509 | J25: 0.19650463 | K25: 0 | L25: 0 | M25: 0 | N25: =N24 -> 6.94606 | Q25: 1 | R25: WR00L2L2 | S25: 19072 | T25: 32 | U25: 2 | V25: 2 | W25: 595.9 | X25: 7.762 | Y25: 45506 | Z25: 0.035578704 | AA25: 0 | AB25: 0 | AC25: 0 | AD25: =AD24 -> 7.74676 | AF25: 1 | AG25: WR00L2L2 | AH25: 19008 | AI25: 96 | AJ25: 1 | AK25: 4 | AL25: 359.75 | AM25: 12.728 | AN25: 45509 | AO25: 0.16943287 | AP25: 0 | AQ25: 0 | AR25: 0 | AS25: =AS24 -> 12.779 | AT25: =AT24 -> 12.779 | AV25: 98 | AW25: test-1node | AX25: 18048 | AY25: 32 | AZ25: 2 | BA25: 2 | BB25: 510.21 | BC25: 7.6824 | BF25: 0 | BG25: 0 | BH25: 0 | BI25: =BI24 -> 7.68225
A26: 2 | B26: WR00L2L2 | C26: 19072 | D26: 32 | E26: 2 | F26: 2 | G26: 666.12 | H26: 6.9437 | I26: 45509 | J26: 0.46456019 | K26: 0 | L26: 0 | M26: 0 | N26: =N25 -> 6.94606 | Q26: 2 | R26: WR00L2L2 | S26: 19072 | T26: 32 | U26: 2 | V26: 2 | W26: 595.89 | X26: 7.7622 | Y26: 45506 | Z26: 0.27299769 | AA26: 0 | AB26: 0 | AC26: 0 | AD26: =AD25 -> 7.74676 | AF26: 2 | AG26: WR00L2L2 | AH26: 19008 | AI26: 96 | AJ26: 1 | AK26: 4 | AL26: 358.14 | AM26: 12.786 | AN26: 45509 | AO26: 0.40685185 | AP26: 0 | AQ26: 0 | AR26: 0 | AS26: =AS25 -> 12.779 | AT26: =AT25 -> 12.779 | AV26: 146 | AW26: test-1node | AX26: 18048 | AY26: 32 | AZ26: 2 | BA26: 2 | BB26: 511.16 | BC26: 7.6683 | BF26: 0 | BG26: 0 | BH26: 0 | BI26: =BI25 -> 7.68225
A27: 3 | B27: WR00L2L2 | C27: 19072 | D27: 32 | E27: 2 | F27: 2 | G27: 665.51 | H27: 6.9502 | I27: 45509 | J27: 0.73251157 | K27: 0 | L27: 0 | M27: 0 | N27: =N26 -> 6.94606 | Q27: 3 | R27: WR00L2L2 | S27: 19072 | T27: 32 | U27: 2 | V27: 2 | W27: 596.23 | X27: 7.7578 | Y27: 45506 | Z27: 0.51033565 | AA27: 0 | AB27: 0 | AC27: 0 | AD27: =AD26 -> 7.74676 | AF27: 3 | AG27: WR00L2L2 | AH27: 19008 | AI27: 96 | AJ27: 1 | AK27: 4 | AL27: 356.73 | AM27: 12.836 | AN27: 45509 | AO27: 0.64530093 | AP27: 0 | AQ27: 0 | AR27: 0 | AS27: =AS26 -> 12.779 | AT27: =AT26 -> 12.779 | AV27: 194 | AW27: test-1node | AX27: 18048 | AY27: 32 | AZ27: 2 | BA27: 2 | BB27: 509.74 | BC27: 7.6896 | BF27: 0 | BG27: 0 | BH27: 0 | BI27: =BI26 -> 7.68225
A28: 4 | B28: WR00L2L2 | C28: 19072 | D28: 32 | E28: 2 | F28: 2 | G28: 665.91 | H28: 6.946 | I28: 45510 | J28: 0.00043981481 | K28: 0 | L28: 0 | M28: 0 | N28: =N27 -> 6.94606 | Q28: 4 | R28: WR00L2L2 | S28: 19072 | T28: 32 | U28: 2 | V28: 2 | W28: 599.91 | X28: 7.7102 | Y28: 45506 | Z28: 0.74755787 | AA28: 0 | AB28: 0 | AC28: 0 | AD28: =AD27 -> 7.74676 | AF28: 4 | AG28: WR00L2L2 | AH28: 19008 | AI28: 96 | AJ28: 1 | AK28: 4 | AL28: 360.57 | AM28: 12.699 | AN28: 45509 | AO28: 0.88355324 | AP28: 0 | AQ28: 0 | AR28: 0 | AS28: =AS27 -> 12.779 | AT28: =AT27 -> 12.779 | AV28: 242 | AW28: test-1node | AX28: 18048 | AY28: 32 | AZ28: 2 | BA28: 2 | BB28: 509.34 | BC28: 7.6956 | BF28: 0 | BG28: 0 | BH28: 0 | BI28: =BI27 -> 7.68225
A29: 0 | B29: WR00L2L2 | C29: 20160 | D29: 32 | E29: 2 | F29: 2 | G29: 801.97 | H29: 6.8119 | I29: 45509 | J29: 0.019699074 | K29: 0 | L29: 0 | M29: 0 | N29: =AVERAGE(H29:H33) -> 6.79426 | Q29: 0 | R29: WR00L2L2 | S29: 20160 | T29: 32 | U29: 2 | V29: 2 | W29: 725.8 | X29: 7.5268 | Y29: 45505 | Z29: 0.87899306 | AA29: 0 | AB29: 0 | AC29: 0 | AD29: =AVERAGE(X29:X33) -> 7.51472 | AF29: 0 | AG29: WR00L2L2 | AH29: 17920 | AI29: 128 | AJ29: 1 | AK29: 4 | AL29: 299.13 | AM29: 12.827 | AN29: 45508 | AO29: 0.86915509 | AP29: 0 | AQ29: 0 | AR29: 0 | AS29: =AVERAGE(AM29:AM33) -> 12.766 | AT29: =AS29 -> 12.766 | AV29: 18 | AW29: test-1node | AX29: 19072 | AY29: 32 | AZ29: 2 | BA29: 2 | BB29: 600.66 | BC29: 7.7005 | BF29: 0 | BG29: 0 | BH29: 0 | BI29: =AVERAGE(BC29:BC34) -> 7.7301667
A30: 1 | B30: WR00L2L2 | C30: 20160 | D30: 32 | E30: 2 | F30: 2 | G30: 803.65 | H30: 6.7977 | I30: 45509 | J30: 0.2878588 | K30: 0 | L30: 0 | M30: 0 | N30: =N29 -> 6.79426 | Q30: 1 | R30: WR00L2L2 | S30: 20160 | T30: 32 | U30: 2 | V30: 2 | W30: 729.64 | X30: 7.4872 | Y30: 45506 | Z30: 0.11675926 | AA30: 0 | AB30: 0 | AC30: 0 | AD30: =AD29 -> 7.51472 | AF30: 1 | AG30: WR00L2L2 | AH30: 17920 | AI30: 128 | AJ30: 1 | AK30: 4 | AL30: 298.08 | AM30: 12.872 | AN30: 45509 | AO30: 0.10643519 | AP30: 0 | AQ30: 0 | AR30: 0 | AS30: =AS29 -> 12.766 | AT30: =AT29 -> 12.766 | AV30: 66 | AW30: test-1node | AX30: 19072 | AY30: 32 | AZ30: 2 | BA30: 2 | BB30: 597.38 | BC30: 7.7428 | BF30: 0 | BG30: 0 | BH30: 0 | BI30: =BI29 -> 7.7301667
A31: 2 | B31: WR00L2L2 | C31: 20160 | D31: 32 | E31: 2 | F31: 2 | G31: 803.9 | H31: 6.7956 | I31: 45509 | J31: 0.55585648 | K31: 0 | L31: 0 | M31: 0 | N31: =N30 -> 6.79426 | Q31: 2 | R31: WR00L2L2 | S31: 20160 | T31: 32 | U31: 2 | V31: 2 | W31: 725.27 | X31: 7.5323 | Y31: 45506 | Z31: 0.35394676 | AA31: 0 | AB31: 0 | AC31: 0 | AD31: =AD30 -> 7.51472 | AF31: 2 | AG31: WR00L2L2 | AH31: 17920 | AI31: 128 | AJ31: 1 | AK31: 4 | AL31: 300.29 | AM31: 12.777 | AN31: 45509 | AO31: 0.34398148 | AP31: 0 | AQ31: 0 | AR31: 0 | AS31: =AS30 -> 12.766 | AT31: =AT30 -> 12.766 | AV31: 114 | AW31: test-1node | AX31: 19072 | AY31: 32 | AZ31: 2 | BA31: 2 | BB31: 598.5 | BC31: 7.7284 | BF31: 0 | BG31: 0 | BH31: 0 | BI31: =BI30 -> 7.7301667
A32: 3 | B32: WR00L2L2 | C32: 20160 | D32: 32 | E32: 2 | F32: 2 | G32: 804.54 | H32: 6.7902 | I32: 45509 | J32: 0.82377315 | K32: 0 | L32: 0 | M32: 0 | N32: =N31 -> 6.79426 | Q32: 3 | R32: WR00L2L2 | S32: 20160 | T32: 32 | U32: 2 | V32: 2 | W32: 728.84 | X32: 7.4954 | Y32: 45506 | Z32: 0.59136574 | AA32: 0 | AB32: 0 | AC32: 0 | AD32: =AD31 -> 7.51472 | AF32: 3 | AG32: WR00L2L2 | AH32: 17920 | AI32: 128 | AJ32: 1 | AK32: 4 | AL32: 301.17 | AM32: 12.74 | AN32: 45509 | AO32: 0.58243056 | AP32: 0 | AQ32: 0 | AR32: 0 | AS32: =AS31 -> 12.766 | AT32: =AT31 -> 12.766 | AV32: 162 | AW32: test-1node | AX32: 19072 | AY32: 32 | AZ32: 2 | BA32: 2 | BB32: 598.46 | BC32: 7.7288 | BF32: 0 | BG32: 0 | BH32: 0 | BI32: =BI31 -> 7.7301667
A33: 4 | B33: WR00L2L2 | C33: 20160 | D33: 32 | E33: 2 | F33: 2 | G33: 806.24 | H33: 6.7759 | I33: 45510 | J33: 0.091782407 | K33: 0 | L33: 0 | M33: 0 | N33: =N32 -> 6.79426 | Q33: 4 | R33: WR00L2L2 | S33: 20160 | T33: 32 | U33: 2 | V33: 2 | W33: 725.31 | X33: 7.5319 | Y33: 45506 | Z33: 0.82896991 | AA33: 0 | AB33: 0 | AC33: 0 | AD33: =AD32 -> 7.51472 | AF33: 4 | AG33: WR00L2L2 | AH33: 17920 | AI33: 128 | AJ33: 1 | AK33: 4 | AL33: 304.17 | AM33: 12.614 | AN33: 45509 | AO33: 0.820625 | AP33: 0 | AQ33: 0 | AR33: 0 | AS33: =AS32 -> 12.766 | AT33: =AT32 -> 12.766 | AV33: 210 | AW33: test-1node | AX33: 19072 | AY33: 32 | AZ33: 2 | BA33: 2 | BB33: 597.68 | BC33: 7.7389 | BF33: 0 | BG33: 0 | BH33: 0 | BI33: =BI32 -> 7.7301667
A34: 0 | B34: WR00L2L2 | C34: 17984 | D34: 64 | E34: 1 | F34: 4 | G34: 386.12 | H34: 10.044 | I34: 45508 | J34: 0.85403935 | K34: 0 | L34: 0 | M34: 0 | N34: =AVERAGE(H34:H38) -> 10.1258 | Q34: 0 | R34: WR00L2L2 | S34: 17984 | T34: 64 | U34: 1 | V34: 4 | W34: 332.25 | X34: 11.672 | Y34: 45505 | Z34: 0.73162037 | AA34: 0 | AB34: 0 | AC34: 0 | AD34: =AVERAGE(X34:X38) -> 11.69 | AF34: 0 | AG34: WR00L2L2 | AH34: 19040 | AI34: 224 | AJ34: 1 | AK34: 4 | AL34: 360.5 | AM34: 12.766 | AN34: 45508 | AO34: 0.96825231 | AP34: 0 | AQ34: 0 | AR34: 0 | AS34: =AVERAGE(AM34:AM38) -> 12.7298 | AT34: =AS34 -> 12.7298 | AV34: 258 | AW34: test-1node | AX34: 19072 | AY34: 32 | AZ34: 2 | BA34: 2 | BB34: 597.48 | BC34: 7.7416 | BF34: 0 | BG34: 0 | BH34: 0 | BI34: =BI33 -> 7.7301667
A35: 1 | B35: WR00L2L2 | C35: 17984 | D35: 64 | E35: 1 | F35: 4 | G35: 382.45 | H35: 10.14 | I35: 45509 | J35: 0.12325231 | K35: 0 | L35: 0 | M35: 0 | N35: =N34 -> 10.1258 | Q35: 1 | R35: WR00L2L2 | S35: 17984 | T35: 64 | U35: 1 | V35: 4 | W35: 331.61 | X35: 11.695 | Y35: 45505 | Z35: 0.97134259 | AA35: 0 | AB35: 0 | AC35: 0 | AD35: =AD34 -> 11.69 | AF35: 1 | AG35: WR00L2L2 | AH35: 19040 | AI35: 224 | AJ35: 1 | AK35: 4 | AL35: 361.12 | AM35: 12.744 | AN35: 45509 | AO35: 0.20565972 | AP35: 0 | AQ35: 0 | AR35: 0 | AS35: =AS34 -> 12.7298 | AT35: =AT34 -> 12.7298 | AV35: 34 | AW35: test-1node | AX35: 20096 | AY35: 32 | AZ35: 2 | BA35: 2 | BB35: 715.82 | BC35: 7.5593 | BF35: 0 | BG35: 0 | BH35: 0 | BI35: =AVERAGE(BC35:BC40) -> 7.5499167
A36: 2 | B36: WR00L2L2 | C36: 17984 | D36: 64 | E36: 1 | F36: 4 | G36: 382.23 | H36: 10.146 | I36: 45509 | J36: 0.39143519 | K36: 0 | L36: 0 | M36: 0 | N36: =N35 -> 10.1258 | Q36: 2 | R36: WR00L2L2 | S36: 17984 | T36: 64 | U36: 1 | V36: 4 | W36: 330.2 | X36: 11.745 | Y36: 45506 | Z36: 0.20851852 | AA36: 0 | AB36: 0 | AC36: 0 | AD36: =AD35 -> 11.69 | AF36: 2 | AG36: WR00L2L2 | AH36: 19040 | AI36: 224 | AJ36: 1 | AK36: 4 | AL36: 361.94 | AM36: 12.715 | AN36: 45509 | AO36: 0.44331019 | AP36: 0 | AQ36: 0 | AR36: 0 | AS36: =AS35 -> 12.7298 | AT36: =AT35 -> 12.7298 | AV36: 82 | AW36: test-1node | AX36: 20096 | AY36: 32 | AZ36: 2 | BA36: 2 | BB36: 717.22 | BC36: 7.5445 | BF36: 0 | BG36: 0 | BH36: 0 | BI36: =BI35 -> 7.5499167
A37: 3 | B37: WR00L2L2 | C37: 17984 | D37: 64 | E37: 1 | F37: 4 | G37: 382.33 | H37: 10.143 | I37: 45509 | J37: 0.6593287 | K37: 0 | L37: 0 | M37: 0 | N37: =N36 -> 10.1258 | Q37: 3 | R37: WR00L2L2 | S37: 17984 | T37: 64 | U37: 1 | V37: 4 | W37: 331 | X37: 11.716 | Y37: 45506 | Z37: 0.44596065 | AA37: 0 | AB37: 0 | AC37: 0 | AD37: =AD36 -> 11.69 | AF37: 3 | AG37: WR00L2L2 | AH37: 19040 | AI37: 224 | AJ37: 1 | AK37: 4 | AL37: 361.94 | AM37: 12.715 | AN37: 45509 | AO37: 0.68185185 | AP37: 0 | AQ37: 0 | AR37: 0 | AS37: =AS36 -> 12.7298 | AT37: =AT36 -> 12.7298 | AV37: 130 | AW37: test-1node | AX37: 20096 | AY37: 32 | AZ37: 2 | BA37: 2 | BB37: 716.97 | BC37: 7.5471 | BF37: 0 | BG37: 0 | BH37: 0 | BI37: =BI36 -> 7.5499167
A38: 4 | B38: WR00L2L2 | C38: 17984 | D38: 64 | E38: 1 | F38: 4 | G38: 381.85 | H38: 10.156 | I38: 45509 | J38: 0.92736111 | K38: 0 | L38: 0 | M38: 0 | N38: =N37 -> 10.1258 | Q38: 4 | R38: WR00L2L2 | S38: 17984 | T38: 64 | U38: 1 | V38: 4 | W38: 333.69 | X38: 11.622 | Y38: 45506 | Z38: 0.68313657 | AA38: 0 | AB38: 0 | AC38: 0 | AD38: =AD37 -> 11.69 | AF38: 4 | AG38: WR00L2L2 | AH38: 19040 | AI38: 224 | AJ38: 1 | AK38: 4 | AL38: 362.11 | AM38: 12.709 | AN38: 45509 | AO38: 0.91965278 | AP38: 0 | AQ38: 0 | AR38: 0 | AS38: =AS37 -> 12.7298 | AT38: =AT37 -> 12.7298 | AV38: 178 | AW38: test-1node | AX38: 20096 | AY38: 32 | AZ38: 2 | BA38: 2 | BB38: 716.99 | BC38: 7.5469 | BF38: 0 | BG38: 0 | BH38: 0 | BI38: =BI37 -> 7.5499167
A39: 0 | B39: WR00L2L2 | C39: 19072 | D39: 64 | E39: 1 | F39: 4 | G39: 453.41 | H39: 10.201 | I39: 45508 | J39: 0.9334838 | K39: 0 | L39: 0 | M39: 0 | N39: =AVERAGE(H39:H43) -> 10.278 | Q39: 0 | R39: WR00L2L2 | S39: 19072 | T39: 64 | U39: 1 | V39: 4 | W39: 385.11 | X39: 12.011 | Y39: 45505 | Z39: 0.80134259 | AA39: 0 | AB39: 0 | AC39: 0 | AD39: =AVERAGE(X39:X43) -> 11.9558 | AF39: 0 | AG39: WR00L2L2 | AH39: 18944 | AI39: 256 | AJ39: 1 | AK39: 4 | AL39: 348.56 | AM39: 13.004 | AN39: 45508 | AO39: 0.97709491 | AP39: 0 | AQ39: 0 | AR39: 0 | AS39: =AVERAGE(AM39:AM43) -> 12.7104 | AT39: =AS39 -> 12.7104 | AV39: 226 | AW39: test-1node | AX39: 20096 | AY39: 32 | AZ39: 2 | BA39: 2 | BB39: 716.85 | BC39: 7.5484 | BF39: 0 | BG39: 0 | BH39: 0 | BI39: =BI38 -> 7.5499167
A40: 1 | B40: WR00L2L2 | C40: 19072 | D40: 64 | E40: 1 | F40: 4 | G40: 448.92 | H40: 10.303 | I40: 45509 | J40: 0.20197917 | K40: 0 | L40: 0 | M40: 0 | N40: =N39 -> 10.278 | Q40: 1 | R40: WR00L2L2 | S40: 19072 | T40: 64 | U40: 1 | V40: 4 | W40: 388.34 | X40: 11.911 | Y40: 45506 | Z40: 0.04037037 | AA40: 0 | AB40: 0 | AC40: 0 | AD40: =AD39 -> 11.9558 | AF40: 1 | AG40: WR00L2L2 | AH40: 18944 | AI40: 256 | AJ40: 1 | AK40: 4 | AL40: 355.91 | AM40: 12.736 | AN40: 45509 | AO40: 0.21469907 | AP40: 0 | AQ40: 0 | AR40: 0 | AS40: =AS39 -> 12.7104 | AT40: =AT39 -> 12.7104 | AV40: 274 | AW40: test-1node | AX40: 20096 | AY40: 32 | AZ40: 2 | BA40: 2 | BB40: 716.39 | BC40: 7.5533 | BF40: 0 | BG40: 0 | BH40: 0 | BI40: =BI39 -> 7.5499167
...

Sheet 4 node, params, RAW
A1: Max avg. GFLOPS (and params): | E1: =MAX(W:W) -> 41.3902 | F1: =INDEX(C:C,MATCH(MAX($W:$W),$W:$W,0)) -> 40160 | G1: =INDEX(D:D,MATCH(MAX($W:$W),$W:$W,0)) -> 160 | H1: =INDEX(E:E,MATCH(MAX($W:$W),$W:$W,0)) -> 4 | I1: =INDEX(F:F,MATCH(MAX($W:$W),$W:$W,0)) -> 4 | K1: ATLAS | W1: Average GFLOP/s | Y1: Max avg. GFLOPS (and params): | AC1: =MAX(AU:AU) -> 45.2184 | AD1: =INDEX(AA:AA,MATCH(MAX($AU:$AU),$AU:$AU,0)) -> 40064 | AE1: =INDEX(AB:AB,MATCH(MAX($AU:$AU),$AU:$AU,0)) -> 128 | AF1: =INDEX(AC:AC,MATCH(MAX($AU:$AU),$AU:$AU,0)) -> 2 | AG1: =INDEX(AD:AD,MATCH(MAX($AU:$AU),$AU:$AU,0)) -> 8 | AI1: OpenBLAS | AU1: Average GFLOP/s | AW1: Max avg. GFLOPS (and params): | BA1: =MAX(BS:BS) -> 35.224 | BB1: =INDEX(AY:AY,MATCH(MAX($AU:$AU),$AU:$AU,0)) -> 40064 | BC1: =INDEX(AZ:AZ,MATCH(MAX($AU:$AU),$AU:$AU,0)) -> 128 | BD1: =INDEX(BA:BA,MATCH(MAX($AU:$AU),$AU:$AU,0)) -> 2 | BE1: =INDEX(BB:BB,MATCH(MAX($AU:$AU),$AU:$AU,0)) -> 8 | BG1: OpenBLAS - old measurements | BS1: Average GFLOP/s | BU1: Max avg. GFLOPS (and params): | BY1: =MAX(BS:BS) -> 35.224 | BZ1: =INDEX(AY:AY,MATCH(MAX($BS:$BS),$BS:$BS,0)) -> 40064 | CA1: =INDEX(AZ:AZ,MATCH(MAX($BS:$BS),$BS:$BS,0)) -> 128 | CB1: =INDEX(BA:BA,MATCH(MAX($BS:$BS),$BS:$BS,0)) -> 1 | CC1: =INDEX(BB:BB,MATCH(MAX($BS:$BS),$BS:$BS,0)) -> 16 | CE1: OpenBLAS | CQ1: Average GFLOP/s
A2: MAX GFLOPS: | C2: =MAX(H4:H835) -> 42.049 | K2: raspi21 throttling time [1/100s] | N2: raspi22 throttling time [1/100s] | Q2: raspi23 throttling time [1/100s] | T2: raspi24 throttling time [1/100s] | Y2: MAX GFLOPS: | AA2: =MAX(AF4:AF835) -> 46.051 | AI2: raspi21 throttling time [1/100s] | AL2: raspi22 throttling time [1/100s] | AO2: raspi23 throttling time [1/100s] | AR2: raspi24 throttling time [1/100s] | AW2: MAX GFLOPS: | AY2: =MAX(BD4:BD830) -> 35.413 | BG2: raspi21 throttling time [1/100s] | BJ2: raspi22 throttling time [1/100s] | BM2: raspi23 throttling time [1/100s] | BP2: raspi24 throttling time [1/100s] | BU2: MAX GFLOPS: | BW2: =MAX(BD4:BD822) -> 35.413 | CE2: raspi21 throttling time [1/100s] | CH2: raspi22 throttling time [1/100s] | CK2: raspi23 throttling time [1/100s] | CN2: raspi24 throttling time [1/100s]
A3: RUN | C3: N | D3: NB | E3: P | F3: Q | G3: Time | H3: GFLOPS | I3: Date | J3: Time | K3: 1200MHz | L3: 1300MHz | M3: 1400MHz | N3: 1200MHz | O3: 1300MHz | P3: 1400MHz | Q3: 1200MHz | R3: 1300MHz | S3: 1400MHz | T3: 1200MHz | U3: 1300MHz | V3: 1400MHz | Y3: RUN | AA3: N | AB3: NB | AC3: P | AD3: Q | AE3: Time | AF3: GFLOPS | AG3: Date | AH3: Time | AI3: 1200MHz | AJ3: 1300MHz | AK3: 1400MHz | AL3: 1200MHz | AM3: 1300MHz | AN3: 1400MHz | AO3: 1200MHz | AP3: 1300MHz | AQ3: 1400MHz | AR3: 1200MHz | AS3: 1300MHz | AT3: 1400MHz | AW3: RUN | AY3: N | AZ3: NB | BA3: P | BB3: Q | BC3: Time | BD3: GFLOPS | BE3: Date | BF3: Time | BG3: 1200MHz | BH3: 1300MHz | BI3: 1400MHz | BJ3: 1200MHz | BK3: 1300MHz | BL3: 1400MHz | BM3: 1200MHz | BN3: 1300MHz | BO3: 1400MHz | BP3: 1200MHz | BQ3: 1300MHz | BR3: 1400MHz | BU3: RUN | BW3: N | BX3: NB | BY3: P | BZ3: Q | CA3: Time | CB3: GFLOPS | CC3: Date | CD3: Time | CE3: 1200MHz | CF3: 1300MHz | CG3: 1400MHz | CH3: 1200MHz | CI3: 1300MHz | CJ3: 1400MHz | CK3: 1200MHz | CL3: 1300MHz | CM3: 1400MHz | CN3: 1200MHz | CO3: 1300MHz | CP3: 1400MHz
A4: 0 | B4: WR00L2L2 | C4: 36000 | D4: 32 | E4: 1 | F4: 16 | G4: 1200.83 | H4: 25.904 | I4: 45482 | J4: 0.36896991 | K4: 0 | L4: 0 | M4: 0 | N4: 0 | O4: 0 | P4: 0 | Q4: 0 | R4: 0 | S4: 0 | T4: 0 | U4: 0 | V4: 0 | W4: =AVERAGE(H4:H8) -> 25.8832 | Y4: 0 | Z4: WR00L2L2 | AA4: 36000 | AB4: 32 | AC4: 1 | AD4: 16 | AE4: 1111.2 | AF4: 27.993 | AG4: 45499 | AH4: 0.51796296 | AI4: 0 | AJ4: 0 | AK4: 0 | AL4: 0 | AM4: 0 | AN4: 0 | AO4: 0 | AP4: 0 | AQ4: 0 | AR4: 0 | AS4: 0 | AT4: 0 | AU4: =AVERAGE(AF4:AF8) -> 28.092 | AW4: 0 | AX4: WR00L2L2 | AY4: 36000 | AZ4: 32 | BA4: 1 | BB4: 16 | BC4: 1311.97 | BD4: 23.709 | BE4: 45488 | BF4: 0.53715278 | BG4: 0 | BH4: 0 | BI4: 0 | BJ4: 0 | BK4: 0 | BL4: 0 | BM4: 0 | BN4: 0 | BO4: 0 | BP4: 0 | BQ4: 0 | BR4: 0 | BS4: =AVERAGE(BD4:BD8) -> 23.7526 | BU4: id | BV4: experiment_name | BW4: HPL_N | BX4: HPL_NB | BY4: HPL_P | BZ4: HPL_Q | CA4: HPL_TIME | CB4: HPL_FLOPS
