Workbook

Sheet ATLAS make time results
C1: Single precision | S1: Double precision
C2: Real | K2: Complex | S2: Real | AA2: Complex
A3: Raspberry Pi 1B | C3: kSelMM | D3: kGenMM | E3: kMM_NT | F3: kMM_TN | G3: BIG_MM | H3: kMV_N | I3: kMV_T | J3: kGER | K3: kSelMM | L3: kGenMM | M3: kMM_NT | N3: kMM_TN | O3: BIG_MM | P3: kMV_N | Q3: kMV_T | R3: kGER | S3: kSelMM | T3: kGenMM | U3: kMM_NT | V3: kMM_TN | W3: BIG_MM | X3: kMV_N | Y3: kMV_T | Z3: kGER | AA3: kSelMM | AB3: kGenMM | AC3: kMM_NT | AD3: kMM_TN | AE3: BIG_MM | AF3: kMV_N | AG3: kMV_T | AH3: kGER
A4: 1 | B4: arch | C4: {=TRANSPOSE((OFFSET($D$18,(ROW(D1)-1)*8,0)):(OFFSET($D$25,(ROW(D1)-1)*8,0)))} -> 67.9 | D4: 28.9 | E4: 23 | F4: 27.7 | G4: 67.1 | H4: 5.5 | I4: 6.4 | J4: 5.1 | K4: {=TRANSPOSE((OFFSET($E$18,(ROW(E1)-1)*8,0)):(OFFSET($E$25,(ROW(E1)-1)*8,0)))} -> 64.4 | L4: 27.3 | M4: 22.6 | N4: 26.4 | O4: 68.2 | P4: 9.8 | Q4: 9.7 | R4: 8.9 | S4: {=TRANSPOSE((OFFSET($F$18,(ROW(F1)-1)*8,0)):(OFFSET($F$25,(ROW(F1)-1)*8,0)))} -> 18.3 | T4: 18.3 | U4: 13 | V4: 18.1 | W4: 18.5 | X4: 2.9 | Y4: 4.3 | Z4: 3 | AA4: {=TRANSPOSE((OFFSET($G$18,(ROW(G1)-1)*8,0)):(OFFSET($G$25,(ROW(G1)-1)*8,0)))} -> 17.7 | AB4: 17.7 | AC4: 12.2 | AD4: 15.6 | AE4: 18.6 | AF4: 6.7 | AG4: 8 | AH4: 5.4
A5: 2 | B5: arch-zk | C5: {=TRANSPOSE((OFFSET($D$18,(ROW(D2)-1)*8,0)):(OFFSET($D$25,(ROW(D2)-1)*8,0)))} -> 69.4 | D5: 29.8 | E5: 23.5 | F5: 28.3 | G5: 66.3 | H5: 5.4 | I5: 6.5 | J5: 5 | K5: {=TRANSPOSE((OFFSET($E$18,(ROW(E2)-1)*8,0)):(OFFSET($E$25,(ROW(E2)-1)*8,0)))} -> 66.1 | L5: 28.4 | M5: 23.2 | N5: 27.2 | O5: 68.9 | P5: 9.9 | Q5: 9.8 | R5: 9 | S5: {=TRANSPOSE((OFFSET($F$18,(ROW(F2)-1)*8,0)):(OFFSET($F$25,(ROW(F2)-1)*8,0)))} -> 18.7 | T5: 18.7 | U5: 13.2 | V5: 18.3 | W5: 18.3 | X5: 2.9 | Y5: 4.4 | Z5: 3 | AA5: {=TRANSPOSE((OFFSET($G$18,(ROW(G2)-1)*8,0)):(OFFSET($G$25,(ROW(G2)-1)*8,0)))} -> 18.1 | AB5: 18.1 | AC5: 12.4 | AD5: 16 | AE5: 18.7 | AF5: 6.8 | AG5: 8.2 | AH5: 5.5
A6: 3 | B6: arch-tune | C6: {=TRANSPOSE((OFFSET($D$18,(ROW(D3)-1)*8,0)):(OFFSET($D$25,(ROW(D3)-1)*8,0)))} -> 69 | D6: 29.9 | E6: 23.5 | F6: 28.2 | G6: 67.6 | H6: 5.4 | I6: 6.5 | J6: 5 | K6: {=TRANSPOSE((OFFSET($E$18,(ROW(E3)-1)*8,0)):(OFFSET($E$25,(ROW(E3)-1)*8,0)))} -> 66.2 | L6: 28.8 | M6: 23.2 | N6: 27.2 | O6: 69 | P6: 10 | Q6: 9.8 | R6: 9 | S6: {=TRANSPOSE((OFFSET($F$18,(ROW(F3)-1)*8,0)):(OFFSET($F$25,(ROW(F3)-1)*8,0)))} -> 18.7 | T6: 18.7 | U6: 13.4 | V6: 18.5 | W6: 18.7 | X6: 2.9 | Y6: 4.4 | Z6: 3.1 | AA6: {=TRANSPOSE((OFFSET($G$18,(ROW(G3)-1)*8,0)):(OFFSET($G$25,(ROW(G3)-1)*8,0)))} -> 18.1 | AB6: 18.1 | AC6: 12.3 | AD6: 15.8 | AE6: 18.9 | AF6: 6.8 | AG6: 8.2 | AH6: 5.5
A7: 4 | B7: arch-zk-tune | C7: {=TRANSPOSE((OFFSET($D$18,(ROW(D4)-1)*8,0)):(OFFSET($D$25,(ROW(D4)-1)*8,0)))} -> 69.1 | D7: 29.8 | E7: 23.5 | F7: 28.2 | G7: 65.7 | H7: 5.4 | I7: 6.5 | J7: 5 | K7: {=TRANSPOSE((OFFSET($E$18,(ROW(E4)-1)*8,0)):(OFFSET($E$25,(ROW(E4)-1)*8,0)))} -> 65.4 | L7: 28.9 | M7: 23.2 | N7: 27.2 | O7: 68.5 | P7: 9.9 | Q7: 9.8 | R7: 9 | S7: {=TRANSPOSE((OFFSET($F$18,(ROW(F4)-1)*8,0)):(OFFSET($F$25,(ROW(F4)-1)*8,0)))} -> 18.6 | T7: 18.6 | U7: 13.2 | V7: 18.3 | W7: 18.4 | X7: 2.9 | Y7: 4.4 | Z7: 3.1 | AA7: {=TRANSPOSE((OFFSET($G$18,(ROW(G4)-1)*8,0)):(OFFSET($G$25,(ROW(G4)-1)*8,0)))} -> 18 | AB7: 18 | AC7: 12.3 | AD7: 15.8 | AE7: 18.6 | AF7: 6.8 | AG7: 8.1 | AH7: 5.5
A8: 5 | B8: arch-flags | C8: {=TRANSPOSE((OFFSET($D$18,(ROW(D5)-1)*8,0)):(OFFSET($D$25,(ROW(D5)-1)*8,0)))} -> 69.7 | D8: 69.7 | E8: 58.9 | F8: 68.3 | G8: 66.7 | H8: 9.6 | I8: 8.6 | J8: 7.2 | K8: {=TRANSPOSE((OFFSET($E$18,(ROW(E5)-1)*8,0)):(OFFSET($E$25,(ROW(E5)-1)*8,0)))} -> 68 | L8: 68 | M8: 59.2 | N8: 65.4 | O8: 70.1 | P8: 23.9 | Q8: 19.7 | R8: 21.5 | S8: {=TRANSPOSE((OFFSET($F$18,(ROW(F5)-1)*8,0)):(OFFSET($F$25,(ROW(F5)-1)*8,0)))} -> 44.2 | T8: 44.2 | U8: 32.4 | V8: 37.8 | W8: 36.1 | X8: 5.3 | Y8: 5.5 | Z8: 3.6 | AA8: {=TRANSPOSE((OFFSET($G$18,(ROW(G5)-1)*8,0)):(OFFSET($G$25,(ROW(G5)-1)*8,0)))} -> 45.3 | AB8: 45.3 | AC8: 33.1 | AD8: 35.3 | AE8: 41.6 | AF8: 10 | AG8: 14 | AH8: 7.8
A9: 6 | B9: arch-zk-flags | C9: {=TRANSPOSE((OFFSET($D$18,(ROW(D6)-1)*8,0)):(OFFSET($D$25,(ROW(D6)-1)*8,0)))} -> 73 | D9: 72.4 | E9: 54.7 | F9: 63.7 | G9: 69.9 | H9: 9.6 | I9: 8.6 | J9: 7.3 | K9: {=TRANSPOSE((OFFSET($E$18,(ROW(E6)-1)*8,0)):(OFFSET($E$25,(ROW(E6)-1)*8,0)))} -> 68 | L9: 68 | M9: 59.2 | N9: 65.5 | O9: 70.1 | P9: 21.2 | Q9: 20.3 | R9: 19 | S9: {=TRANSPOSE((OFFSET($F$18,(ROW(F6)-1)*8,0)):(OFFSET($F$25,(ROW(F6)-1)*8,0)))} -> 44.2 | T9: 44.2 | U9: 34.6 | V9: 43.4 | W9: 41.5 | X9: 5.3 | Y9: 5.9 | Z9: 3.9 | AA9: {=TRANSPOSE((OFFSET($G$18,(ROW(G6)-1)*8,0)):(OFFSET($G$25,(ROW(G6)-1)*8,0)))} -> 45.3 | AB9: 45.3 | AC9: 33 | AD9: 30.8 | AE9: 45.3 | AF9: 10.7 | AG9: 13.9 | AH9: 7.8
A10: 7 | B10: arch-tune-flags | C10: {=TRANSPOSE((OFFSET($D$18,(ROW(D7)-1)*8,0)):(OFFSET($D$25,(ROW(D7)-1)*8,0)))} -> 72.9 | D10: 72.3 | E10: 58.5 | F10: 67.9 | G10: 69.8 | H10: 9.4 | I10: 8.6 | J10: 7.3 | K10: {=TRANSPOSE((OFFSET($E$18,(ROW(E7)-1)*8,0)):(OFFSET($E$25,(ROW(E7)-1)*8,0)))} -> 67.7 | L10: 67.7 | M10: 59 | N10: 65.3 | O10: 70.1 | P10: 21.1 | Q10: 19.8 | R10: 19 | S10: {=TRANSPOSE((OFFSET($F$18,(ROW(F7)-1)*8,0)):(OFFSET($F$25,(ROW(F7)-1)*8,0)))} -> 44.1 | T10: 44.1 | U10: 34.8 | V10: 43.9 | W10: 41.9 | X10: 5.2 | Y10: 5.8 | Z10: 3.9 | AA10: {=TRANSPOSE((OFFSET($G$18,(ROW(G7)-1)*8,0)):(OFFSET($G$25,(ROW(G7)-1)*8,0)))} -> 45.1 | AB10: 45.1 | AC10: 32.8 | AD10: 30.6 | AE10: 45.6 | AF10: 10.6 | AG10: 13.8 | AH10: 7.7
A11: 8 | B11: arch-zk-tune-flags | C11: {=TRANSPOSE((OFFSET($D$18,(ROW(D8)-1)*8,0)):(OFFSET($D$25,(ROW(D8)-1)*8,0)))} -> 72.8 | D11: 72.3 | E11: 54.9 | F11: 63.6 | G11: 69.9 | H11: 9.4 | I11: 8.6 | J11: 7.3 | K11: {=TRANSPOSE((OFFSET($E$18,(ROW(E8)-1)*8,0)):(OFFSET($E$25,(ROW(E8)-1)*8,0)))} -> 67.6 | L11: 67.6 | M11: 58.9 | N11: 65.2 | O11: 70 | P11: 21 | Q11: 19.5 | R11: 19 | S11: {=TRANSPOSE((OFFSET($F$18,(ROW(F8)-1)*8,0)):(OFFSET($F$25,(ROW(F8)-1)*8,0)))} -> 44.1 | T11: 44.1 | U11: 34.4 | V11: 43 | W11: 41.1 | X11: 5.2 | Y11: 5.4 | Z11: 3.9 | AA11: {=TRANSPOSE((OFFSET($G$18,(ROW(G8)-1)*8,0)):(OFFSET($G$25,(ROW(G8)-1)*8,0)))} -> 45.1 | AB11: 45.1 | AC11: 32.6 | AD11: 29.8 | AE11: 45.3 | AF11: 10.6 | AG11: 13.8 | AH11: 7.7
C17: Raspi1B
B18: 1 | C18: kSelMM | D18: 67.9 | E18: 64.4 | F18: 18.3 | G18: 17.7
C19: kGenMM | D19: 28.9 | E19: 27.3 | F19: 18.3 | G19: 17.7
C20: kMM_NT | D20: 23 | E20: 22.6 | F20: 13 | G20: 12.2
C21: kMM_TN | D21: 27.7 | E21: 26.4 | F21: 18.1 | G21: 15.6
C22: BIG_MM | D22: 67.1 | E22: 68.2 | F22: 18.5 | G22: 18.6
C23: kMV_N | D23: 5.5 | E23: 9.8 | F23: 2.9 | G23: 6.7
C24: kMV_T | D24: 6.4 | E24: 9.7 | F24: 4.3 | G24: 8
C25: kGER | D25: 5.1 | E25: 8.9 | F25: 3 | G25: 5.4
B26: 2 | C26: kSelMM | D26: 69.4 | E26: 66.1 | F26: 18.7 | G26: 18.1
C27: kGenMM | D27: 29.8 | E27: 28.4 | F27: 18.7 | G27: 18.1
C28: kMM_NT | D28: 23.5 | E28: 23.2 | F28: 13.2 | G28: 12.4
C29: kMM_TN | D29: 28.3 | E29: 27.2 | F29: 18.3 | G29: 16
C30: BIG_MM | D30: 66.3 | E30: 68.9 | F30: 18.3 | G30: 18.7
C31: kMV_N | D31: 5.4 | E31: 9.9 | F31: 2.9 | G31: 6.8
C32: kMV_T | D32: 6.5 | E32: 9.8 | F32: 4.4 | G32: 8.2
C33: kGER | D33: 5 | E33: 9 | F33: 3 | G33: 5.5
B34: 3 | C34: kSelMM | D34: 69 | E34: 66.2 | F34: 18.7 | G34: 18.1
C35: kGenMM | D35: 29.9 | E35: 28.8 | F35: 18.7 | G35: 18.1
C36: kMM_NT | D36: 23.5 | E36: 23.2 | F36: 13.4 | G36: 12.3
C37: kMM_TN | D37: 28.2 | E37: 27.2 | F37: 18.5 | G37: 15.8
C38: BIG_MM | D38: 67.6 | E38: 69 | F38: 18.7 | G38: 18.9
C39: kMV_N | D39: 5.4 | E39: 10 | F39: 2.9 | G39: 6.8
C40: kMV_T | D40: 6.5 | E40: 9.8 | F40: 4.4 | G40: 8.2
C41: kGER | D41: 5 | E41: 9 | F41: 3.1 | G41: 5.5
B42: 4 | C42: kSelMM | D42: 69.1 | E42: 65.4 | F42: 18.6 | G42: 18
C43: kGenMM | D43: 29.8 | E43: 28.9 | F43: 18.6 | G43: 18
C44: kMM_NT | D44: 23.5 | E44: 23.2 | F44: 13.2 | G44: 12.3
C45: kMM_TN | D45: 28.2 | E45: 27.2 | F45: 18.3 | G45: 15.8
...

Sheet Arch details
A1: SBC | B1: Cores | C1: march | D1: mcpu | E1: mtune | F1: fpu | G1: mfloat-abi | J1: ostalo | K1: ostalo (Thumb)
A2: Rpi 1B | C2: armv6 | D2: arm1176jzf-s | E2: arm1176jzf-s | F2: vfpv2 (alias is vfp) | G2: hard | K2: Thumb | L2: 16KB L1 and no L2
A3: Cubieboard2 | C3: armv7-a | D3: cortex-a7 | E3: cortex-a7 | F3: neon-vfpv4 | G3: hard | J3: -funsafe-math-optimizations | K3: Thumb-2
A4: OdroidU3 | C4: armv7-a | D4: cortex-a9 | E4: cortex-a9 | F4: neon-vfpv3 (alias is neon) | G4: hard | J4: -funsafe-math-optimizations | K4: Thumb or Thumb-2 | L4: 1MB L2 cache total? From paper…
A5: OdroidMC1 | B5: LITTLE | C5: armv7-a | D5: cortex-a7 | E5: cortex-a7 | F5: neon-vfpv4 | G5: hard | J5: -funsafe-math-optimizations | K5: Thumb-2 | L5: 2 sockets, 2,5MB L2 cache per socket
B6: Big | C6: armv7-a | D6: cortex-a15 | E6: cortex-a15 | F6: neon-vfpv4 | G6: hard | J6: -funsafe-math-optimizations | K6: Thumb-2
A12: HPL Runs (fixed parameters) | C12: Number of nodes | D12: Node | E12: Total memory of a node (kB) | F12: N, alpha | G12: N, alpha (NB round) | H12: N, beta | I12: N, beta (NB round) | J12: NB | K12: P | L12: Q | M12: Ns difference | N12: Half of the Ns difference | O12: N1 | P12: N2 | Q12: N3
A13: Number of nodes | B13: 4 | C13: 1 | D13: RPi | E13: 489064 | F13: =$B$14*SQRT(($C13*$E13*1024)/8) -> 6329.6226 | G13: =_xlfn.CEILING.MATH(F13/J13)*J13 -> 6336 | H13: =SQRT($B$14*($C13*$E13*1024)/8) -> 7076.7333 | I13: =_xlfn.CEILING.MATH(H13/J13)*J13 -> 7104 | J13: 64 | K13: 1 | L13: 1 | M13: =I13-G13 -> 768 | N13: =M13/2 -> 384 | O13: =G13 -> 6336 | P13: =_xlfn.CEILING.MATH((O13+N13)/J13)*J13 -> 6720 | Q13: =_xlfn.CEILING.MATH((P13+N13)/J13)*J13 -> 7104
A14: Percentage of mem | B14: 0.8 | C14: 4 | D14: RPi | E14: 489064 | F14: =$B$14*SQRT(($B$13*$E14*1024)/8) -> 12659.245 | G14: =_xlfn.CEILING.MATH(F14/J14)*J14 -> 12672 | H14: =SQRT($B$14*($B$13*$E14*1024)/8) -> 14153.467 | I14: =_xlfn.CEILING.MATH(H14/J14)*J14 -> 14208 | J14: 64 | K14: 1 | L14: 4 | M14: =I14-G14 -> 1536 | N14: =M14/2 -> 768 | O14: =G14 -> 12672 | P14: =_xlfn.CEILING.MATH((O14+N14)/J14)*J14 -> 13440 | Q14: =_xlfn.CEILING.MATH((P14+N14)/J14)*J14 -> 14208

Sheet HPL_Builds
A1: Raspberry Pi 1B | C1: Flags used for building ATLAS | D1: Flags used for flagsearching - mandatory | E1: Flags used for building HPL | F1: Machine setup for building HPL | G1: Ran? | H1: NOTE
A2: 1 | B2: arch | C2: -D c -DWALL -b 32 -F al "-march=armv6" | D2: -march=armv6 | E2: -march=armv6 | F2: raspi01
A3: 2 | B3: arch-zk | C3: -D c -DWALL -b 32 -F al "-march=armv6zk" | D3: -march=armv6zk | E3: -march=armv6zk | F3: raspi03
A4: 3 | B4: arch-tune | C4: -D c -DWALL -b 32 -F al "-march=armv6 -mtune=arm1176jzf-s -mfpu=vfp -mfloat-abi=hard" | D4: -march=armv6 -mtune=arm1176jzf-s -mfpu=vfp -mfloat-abi=hard | E4: -march=armv6 -mtune=arm1176jzf-s -mfpu=vfp -mfloat-abi=hard | F4: raspi02
A5: 4 | B5: arch-zk-tune | C5: -D c -DWALL -b 32 -V 1 -F al "-march=armv6zk -mtune=arm1176jzf-s -mfpu=vfp -mfloat-abi=hard" | D5: -march=armv6zk -mtune=arm1176jzf-s -mfpu=vfp -mfloat-abi=hard | E5: -march=armv6zk -mtune=arm1176jzf-s -mfpu=vfp -mfloat-abi=hard | F5: raspi03
A6: 5 | B6: arch-flags | C6: -D c -DWALL -b 32 -V 1 -F al "-O1 -march=armv6 -fschedule-insns2 -mtune=arm1176jzf-s" | D6: -w | E6: -O1 -march=armv6 -fschedule-insns2 -mtune=arm1176jzf-s | F6: raspi01
A7: 6 | B7: arch-zk-flags | C7: -D c -DWALL -b 32 -V 1 -F al "-Os -march=armv6zk" | D7: -w | E7: -Os -march=armv6zk | F7: raspi02
A8: 7 | B8: arch-tune-flags | C8: -D c -DWALL -b 32 -V 1 -F al "-Os -march=armv6 -mtune=arm1176jzf-s -mfpu=vfp -mfloat-abi=hard" | D8: -w | E8: -Os -march=armv6 -mtune=arm1176jzf-s -mfpu=vfp -mfloat-abi=hard | F8: raspi02
A9: 8 | B9: arch-zk-tune-flags | C9: -D c -DWALL -b 32 -V 1 -F al "-Os -march=armv6zk -mtune=arm1176jzf-s -mfpu=vfp -mfloat-abi=hard" | D9: -w | E9: -Os -march=armv6zk -mtune=arm1176jzf-s -mfpu=vfp -mfloat-abi=hard | F9: raspi04
A10: 9 | B10: x-none | C10: -D c -DWALL -b 32 -V 1 | D10: -w | F10: raspi01
A11: 10 | B11: x-no-arch | C11: -D c -DWALL -b 32 -V 1 -Si archdef 0 | D11: -w | F11: raspi02
A12: 11 | B12: x-cpu | C12: -D c -DWALL -b 32 -V 1 -F al "-mcpu=arm1176jzf-s" | D12: -mcpu=arm1176jzf-s | E12: -mcpu=arm1176jzf-s | F12: raspi03
A13: 12 | B13: x-arch-native | C13: -D c -DWALL -b 32 -V 1 -F al "-march=native" | D13: -march=native | F13: raspi04
A14: 13 | B14: x-cpu-append | C14: -D c -DWALL -b 32 -V 1 -Fa al "-mcpu=arm1176jzf-s" | D14: -mcpu=arm1176jzf-s | E14: -mcpu=arm1176jzf-s
A15: 14 | B15: x-cpu-native | C15: -D c -DWALL -b 32 -V 1 -F al "-mcpu=native" | D15: -mcpu=native | E15: -mcpu=native
A16: 15 | B16: x-none-flags | C16: -D c -DWALL -b 32 -V 1 -F al "-O1 -march=armv6zk -fschedule-insns -fselective-scheduling" | D16: -O1 -march=armv6zk -fschedule-insns -fselective-scheduling | E16: -O1 -march=armv6zk -fschedule-insns -fselective-scheduling
A17: 16 | B17: x-no-arch-flags | C17: -D c -DWALL -b 32 -V 1 -Si archdef 0 -F al "-O1 -march=armv6zk -fschedule-insns2 -frename-registers" | H17: Not built
A18: 17 | B18: x-cpu-flags | C18: -D c -DWALL -b 32 -V 1 -F al "-Os -mcpu=arm1176jzf-s -mfpu=vfp -mfloat-abi=hard" | E18: -Os -mcpu=arm1176jzf-s -mfpu=vfp -mfloat-abi=hard
A19: 18 | B19: x-arch-native-flags | C19: -D c -DWALL -b 32 -V 1 -F al "-O1 -march=native -fschedule-insns2" | E19: -O1 -march=native -fschedule-insns2
A20: 19 | B20: arch-tune-flags-nof77 | C20: -D c -DWALL -b 32 --nof77 -V 1 -F al "-Os -march=armv6 -mtune=arm1176jzf-s -mfpu=vfp -mfloat-abi=hard" | F20: raspi02 | H20: Not built?
A21: 20 | B21: arch-tune-flags-wfort | C21: The same ATLAS build as build 7 | E21: -Os -march=armv6 -mtune=arm1176jzf-s -mfpu=vfp -mfloat-abi=hard | F21: raspi01 | H21: Using the same ATLAS build as build 7, only HPL is different
A22: 21 | B22: arch-tune-flags-nohplopt | C22: The same ATLAS build as build 7 | E22: - | F22: raspi01 | H22: Without arch flags in HPL build, same ATLAS build as build 7

Sheet ATLAS builds
A1: Raspberry Pi 1B | C1: Flags used for building | D1: Flags used for flagsearching - mandatory | E1: Flags used for flagsearching - optional | F1: Machine originally built on | G1: Needs flagsearching | H1: Flagsearched (d) | I1: Flagsearched (s) No need! HPL uses only double precision! See ATLAS install manual | J1: Flagsearched (Td) | K1: Kernel | M1: NOTE | O1: TODO
A2: 1 | B2: arch | C2: -D c -DWALL -b 32 -F al "-march=armv6" | D2: -march=armv6 | E2: -mtune=arm1176jzf-s -mcpu=arm1176jzf-s -mfpu=vfp -mfloat-abi=hard | F2: raspi01 | O2: In progress
A3: 2 | B3: arch-zk | C3: -D c -DWALL -b 32 -F al "-march=armv6zk" | D3: -march=armv6zk | E3: -mtune=arm1176jzf-s -mcpu=arm1176jzf-s -mfpu=vfp -mfloat-abi=hard | F3: raspi03 | O3: Freshly finished
A4: 3 | B4: arch-tune | C4: -D c -DWALL -b 32 -F al "-march=armv6 -mtune=arm1176jzf-s -mfpu=vfp -mfloat-abi=hard" | D4: -march=armv6 -mtune=arm1176jzf-s -mfpu=vfp -mfloat-abi=hard | E4: -mcpu=arm1176jzf-s | F4: raspi02 | O4: Done
A5: 4 | B5: arch-zk-tune | C5: -D c -DWALL -b 32 -V 1 -F al "-march=armv6zk -mtune=arm1176jzf-s -mfpu=vfp -mfloat-abi=hard" | D5: -march=armv6zk -mtune=arm1176jzf-s -mfpu=vfp -mfloat-abi=hard | E5: -mcpu=arm1176jzf-s | F5: raspi03 | O5: TODO with the same settings!
A6: 5 | B6: arch-flags | C6: -D c -DWALL -b 32 -V 1 -F al "-O1 -march=armv6 -fschedule-insns2 -mtune=arm1176jzf-s" | D6: -w | E6: -march=armv6zk -march=armv6 -mtune=arm1176jzf-s -mcpu=arm1176jzf-s -mfpu=vfp -mfloat-abi=hard | F6: raspi01
A7: 6 | B7: arch-zk-flags | C7: -D c -DWALL -b 32 -V 1 -F al "-Os -march=armv6zk" | D7: -w | E7: -march=armv6zk -march=armv6 -mtune=arm1176jzf-s -mcpu=arm1176jzf-s -mfpu=vfp -mfloat-abi=hard | F7: raspi02
A8: 7 | B8: arch-tune-flags | C8: -D c -DWALL -b 32 -V 1 -F al "-Os -march=armv6 -mtune=arm1176jzf-s -mfpu=vfp -mfloat-abi=hard" | D8: -Os -march=armv6 -mtune=arm1176jzf-s -mfpu=vfp -mfloat-abi=hard | F8: raspi03
A9: 8 | B9: arch-zk-tune-flags | C9: -D c -DWALL -b 32 -V 1 -F al "-Os -march=armv6zk -mtune=arm1176jzf-s -mfpu=vfp -mfloat-abi=hard" | D9: -w | E9: -march=armv6zk -march=armv6 -mtune=arm1176jzf-s -mcpu=arm1176jzf-s -mfpu=vfp -mfloat-abi=hard | F9: raspi04
A10: 9 | B10: x-none | C10: -D c -DWALL -b 32 -V 1 | D10: -w | E10: -march=armv6zk -march=armv6 -mtune=arm1176jzf-s -mcpu=arm1176jzf-s -mfpu=vfp -mfloat-abi=hard | F10: raspi01
A11: 10 | B11: x-no-arch | C11: -D c -DWALL -b 32 -V 1 -Si archdef 0 | D11: -w | E11: -march=armv6zk -march=armv6 -mtune=arm1176jzf-s -mcpu=arm1176jzf-s -mfpu=vfp -mfloat-abi=hard | F11: raspi02
A12: 11 | B12: x-cpu | C12: -D c -DWALL -b 32 -V 1 -F al "-mcpu=arm1176jzf-s" | D12: -mcpu=arm1176jzf-s | E12: -mfpu=vfp -mfloat-abi=hard | F12: raspi03
A13: 12 | B13: x-arch-native | C13: -D c -DWALL -b 32 -V 1 -F al "-march=native" | D13: -march=native | E13: -mtune=arm1176jzf-s -mfpu=vfp -mfloat-abi=hard | F13: raspi04
A14: 13 | B14: x-cpu-append | C14: -D c -DWALL -b 32 -V 1 -Fa al "-mcpu=arm1176jzf-s" | D14: -mcpu=arm1176jzf-s | E14: -mfpu=vfp -mfloat-abi=hard | F14: raspi02
A15: 14 | B15: x-cpu-native | C15: -D c -DWALL -b 32 -V 1 -F al "-mcpu=native" | D15: -mcpu=native | E15: -mfpu=vfp -mfloat-abi=hard | F15: raspi04
A16: 15 | B16: x-none-flags | C16: -D c -DWALL -b 32 -V 1 -F al "-O1 -march=armv6zk -fschedule-insns -fselective-scheduling" | D16: -O1 -march=armv6zk -fschedule-insns -fselective-scheduling | E16: -march=armv6 -mtune=arm1176jzf-s -mfpu=vfp -mfloat-abi=hard | F16: raspi01
A17: 16 | B17: x-no-arch-flags | C17: -D c -DWALL -b 32 -V 1 -Si archdef 0 -F al "-O1 -march=armv6zk -fschedule-insns2 -frename-registers" | F17: raspi02 | M17: Pokrenuo build atlasa na raspi03, error bacio negdje na sred buildanja, sada sam probao na raspi02 jer je tamo i originalni build napravljen. Bacio error i na raspi02, vjerojatno kombinacije flagova nisu dobre
A18: 17 | B18: x-cpu-flags | C18: -D c -DWALL -b 32 -V 1 -F al "-Os -mcpu=arm1176jzf-s -mfpu=vfp -mfloat-abi=hard" | F18: raspi01
A19: 18 | B19: x-arch-native-flags | C19: -D c -DWALL -b 32 -V 1 -F al "-O1 -march=native -fschedule-insns2" | F19: raspi03
A20: 19 | B20: arch-tune-flags-nof77 | C20: -D c -DWALL -b 32 --nof77 -V 1 -F al "-Os -march=armv6 -mtune=arm1176jzf-s -mfpu=vfp -mfloat-abi=hard" | F20: raspi02 | M20: Did not create HPL for this one

Sheet HPL 4 nodes, builds
A1: Max avg. GFLOPS (and params): | B1: =INDEX(A:A,MATCH(MAX($K:$K),$K:$K,0)) -> arch-tune-flags | F1: =MAX(K4:K500) -> 0.9984125 | G1: =INDEX(D:D,MATCH(MAX($K:$K),$K:$K,0)) -> 12672 | H1: =INDEX(E:E,MATCH(MAX($K:$K),$K:$K,0)) -> 64 | I1: =INDEX(F:F,MATCH(MAX($K:$K),$K:$K,0)) -> 1 | J1: =INDEX(G:G,MATCH(MAX($K:$K),$K:$K,0)) -> 4 | K1: Average GFLOP/s
A2: MAX GFLOPS: | D2: =MAX(I4:I841) -> 0.99882
A3: Build | B3: RUN | D3: N | E3: NB | F3: P | G3: Q | H3: Time | I3: GFLOPS | O3: RANK | P3: GFLOPS
A4: arch-tune-flags | B4: 1 | C4: WR00L2L2 | D4: 12672 | E4: 64 | F4: 1 | G4: 4 | H4: 1359.34 | I4: 0.99815 | K4: =AVERAGE(I4:I7) -> 0.9984125 | M4: arch-tune-flags | N4: -D c -DWALL -b 32 -V 1 -F al "-Os -march=armv6 -mtune=arm1176jzf-s -mfpu=vfp -mfloat-abi=hard" | O4: 1 | P4: 0.998
A5: arch-tune-flags | B5: 2 | C5: WR00L2L2 | D5: 12672 | E5: 64 | F5: 1 | G5: 4 | H5: 1359.72 | I5: 0.99787 | K5: =K4 -> 0.9984125 | M5: arch-zk-tune-flags | N5: -D c -DWALL -b 32 -V 1 -F al "-Os -march=armv6zk -mtune=arm1176jzf-s -mfpu=vfp -mfloat-abi=hard" | O5: 2 | P5: 0.985
A6: arch-tune-flags | B6: 3 | C6: WR00L2L2 | D6: 12672 | E6: 64 | F6: 1 | G6: 4 | H6: 1358.42 | I6: 0.99882 | K6: =K5 -> 0.9984125 | M6: arch-zk-flags | N6: -D c -DWALL -b 32 -V 1 -F al "-Os -march=armv6zk" | O6: 3 | P6: 0.984
A7: arch-tune-flags | B7: 4 | C7: WR00L2L2 | D7: 12672 | E7: 64 | F7: 1 | G7: 4 | H7: 1358.43 | I7: 0.99881 | K7: =K6 -> 0.9984125 | M7: arch-flags | N7: -D c -DWALL -b 32 -V 1 -F al "-O1 -march=armv6 -fschedule-insns2 -mtune=arm1176jzf-s" | O7: 4 | P7: 0.869
A8: arch-zk-tune-flags | B8: 1 | C8: WR00L2L2 | D8: 12672 | E8: 64 | F8: 1 | G8: 4 | H8: 1384.17 | I8: 0.98024 | K8: =AVERAGE(I8:I11) -> 0.9846525 | M8: arch | N8: -D c -DWALL -b 32 -F al "-march=armv6" | O8: 5 | P8: 0.463
A9: arch-zk-tune-flags | B9: 2 | C9: WR00L2L2 | D9: 12672 | E9: 64 | F9: 1 | G9: 4 | H9: 1376.21 | I9: 0.98591 | K9: =K8 -> 0.9846525 | M9: arch-tune | N9: -D c -DWALL -b 32 -F al "-march=armv6 -mtune=arm1176jzf-s -mfpu=vfp -mfloat-abi=hard" | O9: 6 | P9: 0.462
A10: arch-zk-tune-flags | B10: 3 | C10: WR00L2L2 | D10: 12672 | E10: 64 | F10: 1 | G10: 4 | H10: 1374.81 | I10: 0.98691 | K10: =K9 -> 0.9846525 | M10: arch-zk-tune | N10: -D c -DWALL -b 32 -V 1 -F al "-march=armv6zk -mtune=arm1176jzf-s -mfpu=vfp -mfloat-abi=hard" | O10: 7 | P10: 0.46
A11: arch-zk-tune-flags | B11: 4 | C11: WR00L2L2 | D11: 12672 | E11: 64 | F11: 1 | G11: 4 | H11: 1376.71 | I11: 0.98555 | K11: =K10 -> 0.9846525 | M11: arch-zk | N11: -D c -DWALL -b 32 -F al "-march=armv6zk" | O11: 8 | P11: 0.459
A12: arch-zk-flags | B12: 1 | C12: WR00L2L2 | D12: 12672 | E12: 64 | F12: 1 | G12: 4 | H12: 1375.41 | I12: 0.98648 | K12: =AVERAGE(I12:I15) -> 0.983545 | M12: x-none
A13: arch-zk-flags | B13: 2 | C13: WR00L2L2 | D13: 12672 | E13: 64 | F13: 1 | G13: 4 | H13: 1389.78 | I13: 0.97628 | K13: =K12 -> 0.983545 | M13: x-no-arch
A14: arch-zk-flags | B14: 3 | C14: WR00L2L2 | D14: 12672 | E14: 64 | F14: 1 | G14: 4 | H14: 1376.7 | I14: 0.98556 | K14: =K13 -> 0.983545 | M14: x-cpu
A15: arch-zk-flags | B15: 4 | C15: WR00L2L2 | D15: 12672 | E15: 64 | F15: 1 | G15: 4 | H15: 1376.28 | I15: 0.98586 | K15: =K14 -> 0.983545 | M15: x-arch-native
A16: none-flags | B16: 1 | C16: WR00L2L2 | D16: 12672 | E16: 64 | F16: 1 | G16: 4 | H16: 1511.65 | I16: 0.89758 | K16: =AVERAGE(I16:I19) -> 0.898235
A17: none-flags | B17: 2 | C17: WR00L2L2 | D17: 12672 | E17: 64 | F17: 1 | G17: 4 | H17: 1510.28 | I17: 0.89839 | K17: =K16 -> 0.898235 | M17: {=_xlfn.CHOOSECOLS(_xlfn._xlws.FILTER(A4:K500,B4:B500=1),1,11)} -> arch-tune-flags | N17: 0.9984125 | O17: =VLOOKUP(M17,'ATLAS builds'!B2:C20,2,FALSE) -> -D c -DWALL -b 32 -V 1 -F al "-Os -march=armv6 -mtune=arm1176jzf-s -mfpu=vfp -mfloat-abi=hard"
A18: none-flags | B18: 3 | C18: WR00L2L2 | D18: 12672 | E18: 64 | F18: 1 | G18: 4 | H18: 1510.22 | I18: 0.89842 | K18: =K17 -> 0.898235 | M18: arch-zk-tune-flags | N18: 0.9846525 | O18: =VLOOKUP(M18,'ATLAS builds'!B3:C21,2,FALSE) -> -D c -DWALL -b 32 -V 1 -F al "-Os -march=armv6zk -mtune=arm1176jzf-s -mfpu=vfp -mfloat-abi=hard"
A19: none-flags | B19: 4 | C19: WR00L2L2 | D19: 12672 | E19: 64 | F19: 1 | G19: 4 | H19: 1510 | I19: 0.89855 | K19: =K18 -> 0.898235 | M19: arch-zk-flags | N19: 0.983545 | O19: =VLOOKUP(M19,'ATLAS builds'!B4:C22,2,FALSE) -> -D c -DWALL -b 32 -V 1 -F al "-Os -march=armv6zk"
A20: arch-flags | B20: 1 | C20: WR00L2L2 | D20: 12672 | E20: 64 | F20: 1 | G20: 4 | H20: 1559.65 | I20: 0.86995 | K20: =AVERAGE(I20:I23) -> 0.8687125 | M20: none-flags | N20: 0.898235 | O20: =VLOOKUP(M20,'ATLAS builds'!B5:C23,2,FALSE) -> #N/A
A21: arch-flags | B21: 2 | C21: WR00L2L2 | D21: 12672 | E21: 64 | F21: 1 | G21: 4 | H21: 1560.32 | I21: 0.86958 | K21: =K20 -> 0.8687125 | M21: arch-flags | N21: 0.8687125 | O21: =VLOOKUP(M21,'ATLAS builds'!B6:C24,2,FALSE) -> -D c -DWALL -b 32 -V 1 -F al "-O1 -march=armv6 -fschedule-insns2 -mtune=arm1176jzf-s"
A22: arch-flags | B22: 3 | C22: WR00L2L2 | D22: 12672 | E22: 64 | F22: 1 | G22: 4 | H22: 1567.35 | I22: 0.86567 | K22: =K21 -> 0.8687125 | M22: cpu-flags | N22: 0.8608275 | O22: =VLOOKUP(M22,'ATLAS builds'!B7:C25,2,FALSE) -> #N/A
A23: arch-flags | B23: 4 | C23: WR00L2L2 | D23: 12672 | E23: 64 | F23: 1 | G23: 4 | H23: 1560.19 | I23: 0.86965 | K23: =K22 -> 0.8687125 | M23: cpu-append | N23: 0.8571925 | O23: =VLOOKUP(M23,'ATLAS builds'!B8:C26,2,FALSE) -> #N/A
A24: cpu-flags | B24: 1 | C24: WR00L2L2 | D24: 12672 | E24: 64 | F24: 1 | G24: 4 | H24: 1571.22 | I24: 0.86354 | K24: =AVERAGE(I24:I27) -> 0.8608275 | M24: arch-native-flags | N24: 0.82982 | O24: =VLOOKUP(M24,'ATLAS builds'!B9:C27,2,FALSE) -> #N/A
A25: cpu-flags | B25: 2 | C25: WR00L2L2 | D25: 12672 | E25: 64 | F25: 1 | G25: 4 | H25: 1571.9 | I25: 0.86317 | K25: =K24 -> 0.8608275 | M25: arch-native | N25: 0.8103475 | O25: =VLOOKUP(M25,'ATLAS builds'!B10:C28,2,FALSE) -> #N/A
A26: cpu-flags | B26: 3 | C26: WR00L2L2 | D26: 12672 | E26: 64 | F26: 1 | G26: 4 | H26: 1571.79 | I26: 0.86323 | K26: =K25 -> 0.8608275 | M26: none | N26: 0.6935125 | O26: =VLOOKUP(M26,'ATLAS builds'!B11:C29,2,FALSE) -> #N/A
A27: cpu-flags | B27: 4 | C27: WR00L2L2 | D27: 12672 | E27: 64 | F27: 1 | G27: 4 | H27: 1589.95 | I27: 0.85337 | K27: =K26 -> 0.8608275 | M27: no-arch | N27: 0.6897325 | O27: =VLOOKUP(M27,'ATLAS builds'!B12:C30,2,FALSE) -> #N/A
A28: cpu-append | B28: 1 | C28: WR00L2L2 | D28: 12672 | E28: 64 | F28: 1 | G28: 4 | H28: 1583.81 | I28: 0.85668 | K28: =AVERAGE(I28:I31) -> 0.8571925 | M28: arch | N28: 0.462545 | O28: =VLOOKUP(M28,'ATLAS builds'!B13:C31,2,FALSE) -> #N/A
A29: cpu-append | B29: 2 | C29: WR00L2L2 | D29: 12672 | E29: 64 | F29: 1 | G29: 4 | H29: 1582.34 | I29: 0.85748 | K29: =K28 -> 0.8571925 | M29: cpu | N29: 0.4625 | O29: =VLOOKUP(M29,'ATLAS builds'!B14:C32,2,FALSE) -> #N/A
A30: cpu-append | B30: 3 | C30: WR00L2L2 | D30: 12672 | E30: 64 | F30: 1 | G30: 4 | H30: 1582.1 | I30: 0.8576 | K30: =K29 -> 0.8571925 | M30: arch-tune | N30: 0.462115 | O30: =VLOOKUP(M30,'ATLAS builds'!B15:C33,2,FALSE) -> #N/A
A31: cpu-append | B31: 4 | C31: WR00L2L2 | D31: 12672 | E31: 64 | F31: 1 | G31: 4 | H31: 1583.19 | I31: 0.85701 | K31: =K30 -> 0.8571925 | M31: arch-zk-tune | N31: 0.459525 | O31: =VLOOKUP(M31,'ATLAS builds'!B16:C34,2,FALSE) -> #N/A
A32: arch-native-flags | B32: 1 | C32: WR00L2L2 | D32: 12672 | E32: 64 | F32: 1 | G32: 4 | H32: 1637.7 | I32: 0.82849 | K32: =AVERAGE(I32:I35) -> 0.82982 | M32: arch-zk | N32: 0.45939 | O32: =VLOOKUP(M32,'ATLAS builds'!B17:C35,2,FALSE) -> #N/A
A33: arch-native-flags | B33: 2 | C33: WR00L2L2 | D33: 12672 | E33: 64 | F33: 1 | G33: 4 | H33: 1639.41 | I33: 0.82763 | K33: =K32 -> 0.82982 | M33: cpu-native | N33: 0.459365 | O33: =VLOOKUP(M33,'ATLAS builds'!B18:C36,2,FALSE) -> #N/A
A34: arch-native-flags | B34: 3 | C34: WR00L2L2 | D34: 12672 | E34: 64 | F34: 1 | G34: 4 | H34: 1631.2 | I34: 0.83179 | K34: =K33 -> 0.82982
A35: arch-native-flags | B35: 4 | C35: WR00L2L2 | D35: 12672 | E35: 64 | F35: 1 | G35: 4 | H35: 1632.02 | I35: 0.83137 | K35: =K34 -> 0.82982
A36: arch-native | B36: 1 | C36: WR00L2L2 | D36: 12672 | E36: 64 | F36: 1 | G36: 4 | H36: 1674.58 | I36: 0.81024 | K36: =AVERAGE(I36:I39) -> 0.8103475 | M36: arch | N36: -D c -DWALL -b 32 -F al "-march=armv6" | O36: =VLOOKUP(M36,$M$17:$N$33,2,FALSE) -> 0.462545
A37: arch-native | B37: 2 | C37: WR00L2L2 | D37: 12672 | E37: 64 | F37: 1 | G37: 4 | H37: 1673.79 | I37: 0.81063 | K37: =K36 -> 0.8103475 | M37: arch-zk | N37: -D c -DWALL -b 32 -F al "-march=armv6zk" | O37: =VLOOKUP(M37,$M$17:$N$33,2,FALSE) -> 0.45939
A38: arch-native | B38: 3 | C38: WR00L2L2 | D38: 12672 | E38: 64 | F38: 1 | G38: 4 | H38: 1675.33 | I38: 0.80988 | K38: =K37 -> 0.8103475 | M38: arch-tune | N38: -D c -DWALL -b 32 -F al "-march=armv6 -mtune=arm1176jzf-s -mfpu=vfp -mfloat-abi=hard" | O38: =VLOOKUP(M38,$M$17:$N$33,2,FALSE) -> 0.462115
A39: arch-native | B39: 4 | C39: WR00L2L2 | D39: 12672 | E39: 64 | F39: 1 | G39: 4 | H39: 1673.75 | I39: 0.81064 | K39: =K38 -> 0.8103475 | M39: arch-zk-tune | N39: -D c -DWALL -b 32 -V 1 -F al "-march=armv6zk -mtune=arm1176jzf-s -mfpu=vfp -mfloat-abi=hard" | O39: =VLOOKUP(M39,$M$17:$N$33,2,FALSE) -> 0.459525
A40: none | B40: 1 | C40: WR00L2L2 | D40: 12672 | E40: 64 | F40: 1 | G40: 4 | H40: 1951.01 | I40: 0.69544 | K40: =AVERAGE(I40:I43) -> 0.6935125 | M40: arch-flags | N40: -D c -DWALL -b 32 -V 1 -F al "-O1 -march=armv6 -fschedule-insns2 -mtune=arm1176jzf-s" | O40: =VLOOKUP(M40,$M$17:$N$33,2,FALSE) -> 0.8687125
...

Sheet 1 node, params, RAW
A1: Max avg. GFLOPS (and params): | E1: =MAX(N:N) -> 0.286854 | F1: =INDEX(C:C,MATCH(MAX($N:$N),$N:$N,0)) -> 6720 | G1: =INDEX(D:D,MATCH(MAX($N:$N),$N:$N,0)) -> 64 | H1: =INDEX(E:E,MATCH(MAX($N:$N),$N:$N,0)) -> 1 | I1: =INDEX(F:F,MATCH(MAX($N:$N),$N:$N,0)) -> 1 | K1: ATLAS (arch-tune-flags) | N1: Average GFLOP/s | P1: Max avg. GFLOPS (and params): | T1: =MAX(AC:AC) -> 0.229676 | U1: =INDEX(R:R,MATCH(MAX($AC:$AC),$AC:$AC,0)) -> 6720 | V1: =INDEX(S:S,MATCH(MAX($AC:$AC),$AC:$AC,0)) -> 64 | W1: =INDEX(T:T,MATCH(MAX($AC:$AC),$AC:$AC,0)) -> 1 | X1: =INDEX(U:U,MATCH(MAX($AC:$AC),$AC:$AC,0)) -> 1 | Z1: OpenBLAS | AC1: Average GFLOP/s
A2: MAX GFLOPS: | C2: =MAX(H4:H500) -> 0.28746 | K2: raspi01 throttling time [1/100s] | P2: MAX GFLOPS: | R2: =MAX(W4:W500) -> 0.22999 | Z2: raspi02 throttling time [1/100s]
A3: RUN | C3: N | D3: NB | E3: P | F3: Q | G3: Time | H3: GFLOPS | I3: Date | J3: Time | K3: - | L3: - | M3: 700MHz | P3: RUN | R3: N | S3: NB | T3: P | U3: Q | V3: Time | W3: GFLOPS | X3: Date | Y3: Time | Z3: - | AA3: - | AB3: 700MHz
A4: 0 | B4: WR00L2L2 | C4: 6336 | D4: 32 | E4: 1 | F4: 1 | G4: 627.47 | H4: 0.27034 | I4: 45472 | J4: 0.73945602 | K4: 69128 | L4: 69129 | M4: 69129 | N4: =AVERAGE(H4:H8) -> 0.27028 | P4: 0 | Q4: WR00L2L2 | R4: 6336 | S4: 32 | T4: 1 | U4: 1 | V4: 752.28 | W4: 0.22549 | X4: 45472 | Y4: 0.74340278 | Z4: 102299 | AA4: 102298 | AB4: 102299 | AC4: =AVERAGE(W4:W8) -> 0.22606
A5: 1 | B5: WR00L2L2 | C5: 6336 | D5: 32 | E5: 1 | F5: 1 | G5: 628.54 | H5: 0.26988 | I5: 45472 | J5: 0.9593287 | K5: 69152 | L5: 69152 | M5: 69151 | N5: =N4 -> 0.27028 | P5: 1 | Q5: WR00L2L2 | R5: 6336 | S5: 32 | T5: 1 | U5: 1 | V5: 751.95 | W5: 0.22559 | X5: 45473 | Y5: 0.082025463 | Z5: 102271 | AA5: 102270 | AB5: 102271 | AC5: =AC4 -> 0.22606
A6: 2 | B6: WR00L2L2 | C6: 6336 | D6: 32 | E6: 1 | F6: 1 | G6: 626.8 | H6: 0.27063 | I6: 45473 | J6: 0.17895833 | K6: 69114 | L6: 69114 | M6: 69114 | N6: =N5 -> 0.27028 | P6: 2 | Q6: WR00L2L2 | R6: 6336 | S6: 32 | T6: 1 | U6: 1 | V6: 749.17 | W6: 0.22643 | X6: 45473 | Y6: 0.42322917 | Z6: 101946 | AA6: 101945 | AB6: 101946 | AC6: =AC5 -> 0.22606
A7: 3 | B7: WR00L2L2 | C7: 6336 | D7: 32 | E7: 1 | F7: 1 | G7: 628.84 | H7: 0.26975 | I7: 45473 | J7: 0.39846065 | K7: 69127 | L7: 69127 | M7: 69127 | N7: =N6 -> 0.27028 | P7: 3 | Q7: WR00L2L2 | R7: 6336 | S7: 32 | T7: 1 | U7: 1 | V7: 748.81 | W7: 0.22654 | X7: 45473 | Y7: 0.76248843 | Z7: 102076 | AA7: 102083 | AB7: 102083 | AC7: =AC6 -> 0.22606
A8: 4 | B8: WR00L2L2 | C8: 6336 | D8: 32 | E8: 1 | F8: 1 | G8: 626.41 | H8: 0.2708 | I8: 45473 | J8: 0.61780093 | K8: 68879 | L8: 68879 | M8: 68880 | N8: =N7 -> 0.27028 | P8: 4 | Q8: WR00L2L2 | R8: 6336 | S8: 32 | T8: 1 | U8: 1 | V8: 749.77 | W8: 0.22625 | X8: 45474 | Y8: 0.10471065 | Z8: 101926 | AA8: 101927 | AB8: 101927 | AC8: =AC7 -> 0.22606
A9: 0 | B9: WR00L2L2 | C9: 6720 | D9: 32 | E9: 1 | F9: 1 | G9: 744.97 | H9: 0.27166 | I9: 45472 | J9: 0.80201389 | K9: 81591 | L9: 81591 | M9: 81590 | N9: =AVERAGE(H9:H13) -> 0.27124 | P9: 0 | Q9: WR00L2L2 | R9: 6720 | S9: 32 | T9: 1 | U9: 1 | V9: 893.72 | W9: 0.22644 | X9: 45472 | Y9: 0.84071759 | Z9: 119833 | AA9: 119833 | AB9: 119834 | AC9: =AVERAGE(W9:W13) -> 0.22624
A10: 1 | B10: WR00L2L2 | C10: 6720 | D10: 32 | E10: 1 | F10: 1 | G10: 746.07 | H10: 0.27126 | I10: 45473 | J10: 0.021967593 | K10: 81849 | L10: 81848 | M10: 81848 | N10: =N9 -> 0.27124 | P10: 1 | Q10: WR00L2L2 | R10: 6720 | S10: 32 | T10: 1 | U10: 1 | V10: 893.95 | W10: 0.22639 | X10: 45473 | Y10: 0.17853009 | Z10: 119802 | AA10: 119801 | AB10: 119801 | AC10: =AC9 -> 0.22624
A11: 2 | B11: WR00L2L2 | C11: 6720 | D11: 32 | E11: 1 | F11: 1 | G11: 746.91 | H11: 0.27095 | I11: 45473 | J11: 0.24148148 | K11: 81709 | L11: 81709 | M11: 81709 | N11: =N10 -> 0.27124 | P11: 2 | Q11: WR00L2L2 | R11: 6720 | S11: 32 | T11: 1 | U11: 1 | V11: 893.86 | W11: 0.22641 | X11: 45473 | Y11: 0.51998843 | Z11: 119818 | AA11: 119817 | AB11: 119817 | AC11: =AC10 -> 0.22624
A12: 3 | B12: WR00L2L2 | C12: 6720 | D12: 32 | E12: 1 | F12: 1 | G12: 748.44 | H12: 0.2704 | I12: 45473 | J12: 0.46103009 | K12: 81874 | L12: 81875 | M12: 81874 | N12: =N11 -> 0.27124 | P12: 3 | Q12: WR00L2L2 | R12: 6720 | S12: 32 | T12: 1 | U12: 1 | V12: 897.26 | W12: 0.22555 | X12: 45473 | Y12: 0.8583912 | Z12: 120056 | AA12: 120057 | AB12: 120057 | AC12: =AC11 -> 0.22624
A13: 4 | B13: WR00L2L2 | C13: 6720 | D13: 32 | E13: 1 | F13: 1 | G13: 744.23 | H13: 0.27193 | I13: 45473 | J13: 0.68034722 | K13: 81511 | L13: 81511 | M13: 81510 | N13: =N12 -> 0.27124 | P13: 4 | Q13: WR00L2L2 | R13: 6720 | S13: 32 | T13: 1 | U13: 1 | V13: 893.87 | W13: 0.22641 | X13: 45474 | Y13: 0.20196759 | Z13: 119683 | AA13: 119684 | AB13: 119684 | AC13: =AC12 -> 0.22624
A14: 0 | B14: WR00L2L2 | C14: 7104 | D14: 32 | E14: 1 | F14: 1 | G14: 884.12 | H14: 0.27042 | I14: 45472 | J14: 0.87760417 | K14: 96362 | L14: 96362 | M14: 96361 | N14: =AVERAGE(H14:H18) -> 0.270842 | P14: 0 | Q14: WR00L2L2 | R14: 7104 | S14: 32 | T14: 1 | U14: 1 | V14: 1058.95 | W14: 0.22578 | X14: 45472 | Y14: 0.95622685 | Z14: 140043 | AA14: 140043 | AB14: 140044 | AC14: =AVERAGE(W14:W18) -> 0.223478
A15: 1 | B15: WR00L2L2 | C15: 7104 | D15: 32 | E15: 1 | F15: 1 | G15: 881.56 | H15: 0.27121 | I15: 45473 | J15: 0.097650463 | K15: 97399 | L15: 97399 | M15: 97399 | N15: =N14 -> 0.270842 | P15: 1 | Q15: WR00L2L2 | R15: 7104 | S15: 32 | T15: 1 | U15: 1 | V15: 1067.45 | W15: 0.22398 | X15: 45473 | Y15: 0.29482639 | Z15: 141490 | AA15: 141489 | AB15: 141490 | AC15: =AC14 -> 0.223478
A16: 2 | B16: WR00L2L2 | C16: 7104 | D16: 32 | E16: 1 | F16: 1 | G16: 882.98 | H16: 0.27077 | I16: 45473 | J16: 0.31712963 | K16: 96270 | L16: 96270 | M16: 96270 | N16: =N15 -> 0.270842 | P16: 2 | Q16: WR00L2L2 | R16: 7104 | S16: 32 | T16: 1 | U16: 1 | V16: 1077.69 | W16: 0.22185 | X16: 45473 | Y16: 0.63574074 | Z16: 141792 | AA16: 141791 | AB16: 141791 | AC16: =AC15 -> 0.223478
A17: 3 | B17: WR00L2L2 | C17: 7104 | D17: 32 | E17: 1 | F17: 1 | G17: 881.27 | H17: 0.2713 | I17: 45473 | J17: 0.5365625 | K17: 96063 | L17: 96063 | M17: 96062 | N17: =N16 -> 0.270842 | P17: 3 | Q17: WR00L2L2 | R17: 7104 | S17: 32 | T17: 1 | U17: 1 | V17: 1089.12 | W17: 0.21952 | X17: 45473 | Y17: 0.97415509 | Z17: 142924 | AA17: 142925 | AB17: 142925 | AC17: =AC16 -> 0.223478
A18: 4 | B18: WR00L2L2 | C18: 7104 | D18: 32 | E18: 1 | F18: 1 | G18: 883.84 | H18: 0.27051 | I18: 45473 | J18: 0.75618056 | K18: 96364 | L18: 96365 | M18: 96364 | N18: =N17 -> 0.270842 | P18: 4 | Q18: WR00L2L2 | R18: 7104 | S18: 32 | T18: 1 | U18: 1 | V18: 1056.71 | W18: 0.22626 | X18: 45474 | Y18: 0.3165625 | Z18: 139704 | AA18: 139705 | AB18: 139705 | AC18: =AC17 -> 0.223478
A19: 0 | B19: WR00L2L2 | C19: 6336 | D19: 64 | E19: 1 | F19: 1 | G19: 594.57 | H19: 0.2853 | I19: 45472 | J19: 0.74708333 | K19: 65632 | L19: 65632 | M19: 65632 | N19: =AVERAGE(H19:H23) -> 0.28599 | P19: 0 | Q19: WR00L2L2 | R19: 6336 | S19: 64 | T19: 1 | U19: 1 | V19: 766.01 | W19: 0.22145 | X19: 45472 | Y19: 0.75539352 | Z19: 103301 | AA19: 103302 | AB19: 103302 | AC19: =AVERAGE(W19:W23) -> 0.225464
A20: 1 | B20: WR00L2L2 | C20: 6336 | D20: 64 | E20: 1 | F20: 1 | G20: 592.03 | H20: 0.28653 | I20: 45472 | J20: 0.9669213 | K20: 65413 | L20: 65413 | M20: 65413 | N20: =N19 -> 0.28599 | P20: 1 | Q20: WR00L2L2 | R20: 6336 | S20: 64 | T20: 1 | U20: 1 | V20: 753.32 | W20: 0.22518 | X20: 45473 | Y20: 0.093877315 | Z20: 102078 | AA20: 102078 | AB20: 102079 | AC20: =AC19 -> 0.225464
A21: 2 | B21: WR00L2L2 | C21: 6336 | D21: 64 | E21: 1 | F21: 1 | G21: 592.11 | H21: 0.28649 | I21: 45473 | J21: 0.18653935 | K21: 65406 | L21: 65407 | M21: 65406 | N21: =N20 -> 0.28599 | P21: 2 | Q21: WR00L2L2 | R21: 6336 | S21: 64 | T21: 1 | U21: 1 | V21: 737.55 | W21: 0.22999 | X21: 45473 | Y21: 0.43488426 | Z21: 100524 | AA21: 100523 | AB21: 100524 | AC21: =AC20 -> 0.225464
A22: 3 | B22: WR00L2L2 | C22: 6336 | D22: 64 | E22: 1 | F22: 1 | G22: 592.45 | H22: 0.28632 | I22: 45473 | J22: 0.40605324 | K22: 65420 | L22: 65421 | M22: 65420 | N22: =N21 -> 0.28599 | P22: 3 | Q22: WR00L2L2 | R22: 6336 | S22: 64 | T22: 1 | U22: 1 | V22: 767.12 | W22: 0.22113 | X22: 45473 | Y22: 0.77451389 | Z22: 103570 | AA22: 103575 | AB22: 103578 | AC22: =AC21 -> 0.225464
A23: 4 | B23: WR00L2L2 | C23: 6336 | D23: 64 | E23: 1 | F23: 1 | G23: 594.56 | H23: 0.28531 | I23: 45473 | J23: 0.62541667 | K23: 65644 | L23: 65643 | M23: 65643 | N23: =N22 -> 0.28599 | P23: 4 | Q23: WR00L2L2 | R23: 6336 | S23: 64 | T23: 1 | U23: 1 | V23: 738.9 | W23: 0.22957 | X23: 45474 | Y23: 0.11636574 | Z23: 100546 | AA23: 100547 | AB23: 100546 | AC23: =AC22 -> 0.225464
A24: 0 | B24: WR00L2L2 | C24: 6720 | D24: 64 | E24: 1 | F24: 1 | G24: 705.68 | H24: 0.28678 | I24: 45472 | J24: 0.81104167 | K24: 77741 | L24: 77742 | M24: 77742 | N24: =AVERAGE(H24:H28) -> 0.286854 | P24: 0 | Q24: WR00L2L2 | R24: 6720 | S24: 64 | T24: 1 | U24: 1 | V24: 883.63 | W24: 0.22903 | X24: 45472 | Y24: 0.85445602 | Z24: 118378 | AA24: 118378 | AB24: 118378 | AC24: =AVERAGE(W24:W28) -> 0.229676
A25: 1 | B25: WR00L2L2 | C25: 6720 | D25: 64 | E25: 1 | F25: 1 | G25: 704.01 | H25: 0.28746 | I25: 45473 | J25: 0.030949074 | K25: 77339 | L25: 77339 | M25: 77339 | N25: =N24 -> 0.286854 | P25: 1 | Q25: WR00L2L2 | R25: 6720 | S25: 64 | T25: 1 | U25: 1 | V25: 880.33 | W25: 0.22989 | X25: 45473 | Y25: 0.19222222 | Z25: 118061 | AA25: 118062 | AB25: 118060 | AC25: =AC24 -> 0.229676
A26: 2 | B26: WR00L2L2 | C26: 6720 | D26: 64 | E26: 1 | F26: 1 | G26: 706.49 | H26: 0.28645 | I26: 45473 | J26: 0.25048611 | K26: 77578 | L26: 77579 | M26: 77578 | N26: =N25 -> 0.286854 | P26: 2 | Q26: WR00L2L2 | R26: 6720 | S26: 64 | T26: 1 | U26: 1 | V26: 881.34 | W26: 0.22962 | X26: 45473 | Y26: 0.5337037 | Z26: 118258 | AA26: 118257 | AB26: 118256 | AC26: =AC25 -> 0.229676
A27: 3 | B27: WR00L2L2 | C27: 6720 | D27: 64 | E27: 1 | F27: 1 | G27: 704.3 | H27: 0.28734 | I27: 45473 | J27: 0.47003472 | K27: 77621 | L27: 77621 | M27: 77622 | N27: =N26 -> 0.286854 | P27: 3 | Q27: WR00L2L2 | R27: 6720 | S27: 64 | T27: 1 | U27: 1 | V27: 879.98 | W27: 0.22998 | X27: 45473 | Y27: 0.87207176 | Z27: 117962 | AA27: 117961 | AB27: 117962 | AC27: =AC26 -> 0.229676
A28: 4 | B28: WR00L2L2 | C28: 6720 | D28: 64 | E28: 1 | F28: 1 | G28: 707.03 | H28: 0.28624 | I28: 45473 | J28: 0.68935185 | K28: 77632 | L28: 77631 | M28: 77631 | N28: =N27 -> 0.286854 | P28: 4 | Q28: WR00L2L2 | R28: 6720 | S28: 64 | T28: 1 | U28: 1 | V28: 880.42 | W28: 0.22986 | X28: 45474 | Y28: 0.21564815 | Z28: 117976 | AA28: 117977 | AB28: 117976 | AC28: =AC27 -> 0.229676
A29: 0 | B29: WR00L2L2 | C29: 7104 | D29: 64 | E29: 1 | F29: 1 | G29: 836.93 | H29: 0.28567 | I29: 45472 | J29: 0.88822917 | K29: 91573 | L29: 91574 | M29: 91573 | N29: =AVERAGE(H29:H33) -> 0.286156 | P29: 0 | Q29: WR00L2L2 | R29: 7104 | S29: 64 | T29: 1 | U29: 1 | V29: 1056.17 | W29: 0.22637 | X29: 45472 | Y29: 0.97237269 | Z29: 139203 | AA29: 139202 | AB29: 139204 | AC29: =AVERAGE(W29:W33) -> 0.2218
A30: 1 | B30: WR00L2L2 | C30: 7104 | D30: 64 | E30: 1 | F30: 1 | G30: 837.41 | H30: 0.28551 | I30: 45473 | J30: 0.10827546 | K30: 91593 | L30: 91593 | M30: 91593 | N30: =N29 -> 0.286156 | P30: 1 | Q30: WR00L2L2 | R30: 7104 | S30: 64 | T30: 1 | U30: 1 | V30: 1041.22 | W30: 0.22962 | X30: 45473 | Y30: 0.31084491 | Z30: 138081 | AA30: 138081 | AB30: 138081 | AC30: =AC29 -> 0.2218
A31: 2 | B31: WR00L2L2 | C31: 7104 | D31: 64 | E31: 1 | F31: 1 | G31: 833.16 | H31: 0.28696 | I31: 45473 | J31: 0.32771991 | K31: 91231 | L31: 91230 | M31: 91230 | N31: =N30 -> 0.286156 | P31: 2 | Q31: WR00L2L2 | R31: 7104 | S31: 64 | T31: 1 | U31: 1 | V31: 1080.5 | W31: 0.22127 | X31: 45473 | Y31: 0.6521875 | Z31: 141792 | AA31: 141792 | AB31: 141791 | AC31: =AC30 -> 0.2218
A32: 3 | B32: WR00L2L2 | C32: 7104 | D32: 64 | E32: 1 | F32: 1 | G32: 833.5 | H32: 0.28685 | I32: 45473 | J32: 0.54715278 | K32: 91270 | L32: 91270 | M32: 91269 | N32: =N31 -> 0.286156 | P32: 3 | Q32: WR00L2L2 | R32: 7104 | S32: 64 | T32: 1 | U32: 1 | V32: 1181.94 | W32: 0.20228 | X32: 45473 | Y32: 0.99173611 | Z32: 151745 | AA32: 151746 | AB32: 151746 | AC32: =AC31 -> 0.2218
A33: 4 | B33: WR00L2L2 | C33: 7104 | D33: 64 | E33: 1 | F33: 1 | G33: 836.57 | H33: 0.28579 | I33: 45473 | J33: 0.76684028 | K33: 91807 | L33: 91807 | M33: 91807 | N33: =N32 -> 0.286156 | P33: 4 | Q33: WR00L2L2 | R33: 7104 | S33: 64 | T33: 1 | U33: 1 | V33: 1041.95 | W33: 0.22946 | X33: 45474 | Y33: 0.33253472 | Z33: 137805 | AA33: 137805 | AB33: 137805 | AC33: =AC32 -> 0.2218
A34: 0 | B34: WR00L2L2 | C34: 6336 | D34: 96 | E34: 1 | F34: 1 | G34: 601.55 | H34: 0.28199 | I34: 45472 | J34: 0.75478009 | K34: 66332 | L34: 66332 | M34: 66332 | N34: =AVERAGE(H34:H38) -> 0.281654 | P34: 0 | Q34: WR00L2L2 | R34: 6336 | S34: 96 | T34: 1 | U34: 1 | V34: 769.27 | W34: 0.22051 | X34: 45472 | Y34: 0.76739583 | Z34: 103471 | AA34: 103471 | AB34: 103473 | AC34: =AVERAGE(W34:W38) -> 0.221694
A35: 1 | B35: WR00L2L2 | C35: 6336 | D35: 96 | E35: 1 | F35: 1 | G35: 602.95 | H35: 0.28134 | I35: 45472 | J35: 0.97462963 | K35: 66463 | L35: 66464 | M35: 66463 | N35: =N34 -> 0.281654 | P35: 1 | Q35: WR00L2L2 | R35: 6336 | S35: 96 | T35: 1 | U35: 1 | V35: 760.86 | W35: 0.22295 | X35: 45473 | Y35: 0.10579861 | Z35: 102822 | AA35: 102823 | AB35: 102831 | AC35: =AC34 -> 0.221694
A36: 2 | B36: WR00L2L2 | C36: 6336 | D36: 96 | E36: 1 | F36: 1 | G36: 602.8 | H36: 0.28141 | I36: 45473 | J36: 0.19425926 | K36: 66438 | L36: 66439 | M36: 66438 | N36: =N35 -> 0.281654 | P36: 2 | Q36: WR00L2L2 | R36: 6336 | S36: 96 | T36: 1 | U36: 1 | V36: 765.79 | W36: 0.22151 | X36: 45473 | Y36: 0.44685185 | Z36: 103166 | AA36: 103167 | AB36: 103166 | AC36: =AC35 -> 0.221694
A37: 3 | B37: WR00L2L2 | C37: 6336 | D37: 96 | E37: 1 | F37: 1 | G37: 602.99 | H37: 0.28132 | I37: 45473 | J37: 0.41377315 | K37: 66464 | L37: 66464 | M37: 66464 | N37: =N36 -> 0.281654 | P37: 3 | Q37: WR00L2L2 | R37: 6336 | S37: 96 | T37: 1 | U37: 1 | V37: 762.17 | W37: 0.22257 | X37: 45473 | Y37: 0.78655093 | Z37: 102915 | AA37: 102913 | AB37: 102915 | AC37: =AC36 -> 0.221694
A38: 4 | B38: WR00L2L2 | C38: 6336 | D38: 96 | E38: 1 | F38: 1 | G38: 601.08 | H38: 0.28221 | I38: 45473 | J38: 0.63311343 | K38: 66272 | L38: 66273 | M38: 66273 | N38: =N37 -> 0.281654 | P38: 4 | Q38: WR00L2L2 | R38: 6336 | S38: 96 | T38: 1 | U38: 1 | V38: 767.82 | W38: 0.22093 | X38: 45474 | Y38: 0.12833333 | Z38: 103239 | AA38: 103240 | AB38: 103239 | AC38: =AC37 -> 0.221694
A39: 0 | B39: WR00L2L2 | C39: 6720 | D39: 96 | E39: 1 | F39: 1 | G39: 716.74 | H39: 0.28236 | I39: 45472 | J39: 0.82016204 | K39: 78607 | L39: 78608 | M39: 78608 | N39: =AVERAGE(H39:H43) -> 0.28115 | P39: 0 | Q39: WR00L2L2 | R39: 6720 | S39: 96 | T39: 1 | U39: 1 | V39: 907.76 | W39: 0.22294 | X39: 45472 | Y39: 0.86847222 | Z39: 120827 | AA39: 120826 | AB39: 120828 | AC39: =AVERAGE(W39:W43) -> 0.222258
A40: 1 | B40: WR00L2L2 | C40: 6720 | D40: 96 | E40: 1 | F40: 1 | G40: 717.4 | H40: 0.2821 | I40: 45473 | J40: 0.040069444 | K40: 78679 | L40: 78679 | M40: 78678 | N40: =N39 -> 0.28115 | P40: 1 | Q40: WR00L2L2 | R40: 6720 | S40: 96 | T40: 1 | U40: 1 | V40: 913.01 | W40: 0.22166 | X40: 45473 | Y40: 0.20627315 | Z40: 121195 | AA40: 121195 | AB40: 121195 | AC40: =AC39 -> 0.222258
...

Sheet 4 node, params, RAW
A1: Max avg. GFLOPS (and params): | E1: =MAX(W:W) -> 1.03676 | F1: =INDEX(C:C,MATCH(MAX($W:$W),$W:$W,0)) -> 13440 | G1: =INDEX(D:D,MATCH(MAX($W:$W),$W:$W,0)) -> 64 | H1: =INDEX(E:E,MATCH(MAX($W:$W),$W:$W,0)) -> 2 | I1: =INDEX(F:F,MATCH(MAX($W:$W),$W:$W,0)) -> 2 | K1: ATLAS | W1: Average GFLOP/s | Y1: Max avg. GFLOPS (and params): | AC1: =MAX(AU:AU) -> 0.839766 | AD1: =INDEX(AA:AA,MATCH(MAX($AU:$AU),$AU:$AU,0)) -> 13440 | AE1: =INDEX(AB:AB,MATCH(MAX($AU:$AU),$AU:$AU,0)) -> 64 | AF1: =INDEX(AC:AC,MATCH(MAX($AU:$AU),$AU:$AU,0)) -> 2 | AG1: =INDEX(AD:AD,MATCH(MAX($AU:$AU),$AU:$AU,0)) -> 2 | AI1: OpenBLAS | AU1: Average GFLOP/s | AW1: Max avg. GFLOPS (and params): | BA1: =MAX(BS:BS) -> 1.0354 | BB1: =INDEX(AY:AY,MATCH(MAX($BS:$BS),$BS:$BS,0)) -> 14208 | BC1: =INDEX(AZ:AZ,MATCH(MAX($BS:$BS),$BS:$BS,0)) -> 64 | BD1: =INDEX(BA:BA,MATCH(MAX($BS:$BS),$BS:$BS,0)) -> 2 | BE1: =INDEX(BB:BB,MATCH(MAX($BS:$BS),$BS:$BS,0)) -> 2 | BG1: ATLAS (arch-tune-flags) - OLD | BS1: Average GFLOP/s
A2: MAX GFLOPS: | C2: =MAX(H4:H500) -> 1.0437 | K2: raspi01 throttling time [1/100s] | N2: raspi02 throttling time [1/100s] | Q2: raspi03 throttling time [1/100s] | T2: raspi04 throttling time [1/100s] | Y2: MAX GFLOPS: | AA2: =MAX(AF4:AF500) -> 0.84299 | AI2: raspi01 throttling time [1/100s] | AL2: raspi02 throttling time [1/100s] | AO2: raspi03 throttling time [1/100s] | AR2: raspi04 throttling time [1/100s] | AW2: MAX GFLOPS: | AY2: =MAX(H4:H335) -> 1.0437 | BG2: raspi01 throttling time [1/100s] | BJ2: raspi02 throttling time [1/100s] | BM2: raspi03 throttling time [1/100s] | BP2: raspi04 throttling time [1/100s]
A3: RUN | C3: N | D3: NB | E3: P | F3: Q | G3: Time | H3: GFLOPS | I3: Date | J3: Time | K3: - | L3: - | M3: 700MHz | N3: - | O3: - | P3: 700MHz | Q3: - | R3: - | S3: 700MHz | T3: - | U3: - | V3: 700MHz | Y3: RUN | AA3: N | AB3: NB | AC3: P | AD3: Q | AE3: Time | AF3: GFLOPS | AG3: Date | AH3: Time | AI3: - | AJ3: - | AK3: 700MHz | AL3: - | AM3: - | AN3: 700MHz | AO3: - | AP3: - | AQ3: 700MHz | AR3: - | AS3: - | AT3: 700MHz | AW3: RUN | AY3: N | AZ3: NB | BA3: P | BB3: Q | BC3: Time | BD3: GFLOPS | BE3: Date | BF3: Time | BG3: - | BH3: - | BI3: 700MHz | BJ3: - | BK3: - | BL3: 700MHz | BM3: - | BN3: - | BO3: 700MHz | BP3: - | BQ3: - | BR3: 700MHz
A4: 0 | B4: WR00L2L2 | C4: 12672 | D4: 32 | E4: 1 | F4: 4 | G4: 1427.74 | H4: 0.95032 | I4: 45474 | J4: 0.5450463 | K4: 150325 | L4: 150325 | M4: 150326 | N4: 150168 | O4: 150167 | P4: 150168 | Q4: 150015 | R4: 150016 | S4: 150016 | T4: 149862 | U4: 149861 | V4: 149862 | W4: =AVERAGE(H4:H8) -> 0.947932 | Y4: 0 | Z4: WR00L2L2 | AA4: 12672 | AB4: 32 | AC4: 1 | AD4: 4 | AE4: 1690.41 | AF4: 0.80265 | AG4: 45465 | AH4: 0.73690972 | AI4: 197125 | AJ4: 197124 | AK4: 197124 | AL4: 197115 | AM4: 197115 | AN4: 197114 | AO4: 196967 | AP4: 196967 | AQ4: 196966 | AR4: 196822 | AS4: 196822 | AT4: 196821 | AU4: =AVERAGE(AF4:AF8) -> 0.801688 | AW4: 0 | AX4: WR00L2L2 | AY4: 12672 | AZ4: 32 | BA4: 1 | BB4: 4 | BC4: 1427.54 | BD4: 0.95046 | BS4: =AVERAGE(BD4:BD8) -> 0.951422
A5: 1 | B5: WR00L2L2 | C5: 12672 | D5: 32 | E5: 1 | F5: 4 | G5: 1428.87 | H5: 0.94958 | I5: 45475 | J5: 0.53986111 | K5: 149886 | L5: 149885 | M5: 149886 | N5: 149886 | O5: 149886 | P5: 149886 | Q5: 149886 | R5: 149886 | S5: 149886 | T5: 149886 | U5: 149886 | V5: 149887 | W5: =W4 -> 0.947932 | Y5: 1 | Z5: WR00L2L2 | AA5: 12672 | AB5: 32 | AC5: 1 | AD5: 4 | AE5: 1697.25 | AF5: 0.79942 | AG5: 45467 | AH5: 0.12511574 | AI5: 197456 | AJ5: 197457 | AK5: 197456 | AL5: 197457 | AM5: 197456 | AN5: 197456 | AO5: 197459 | AP5: 197460 | AQ5: 197460 | AR5: 197465 | AS5: 197465 | AT5: 197465 | AU5: =AU4 -> 0.801688 | AW5: 1 | AX5: WR00L2L2 | AY5: 12672 | AZ5: 32 | BA5: 1 | BB5: 4 | BC5: 1426.32 | BD5: 0.95127 | BS5: =BS4 -> 0.951422
A6: 2 | B6: WR00L2L2 | C6: 12672 | D6: 32 | E6: 1 | F6: 4 | G6: 1434.2 | H6: 0.94604 | I6: 45476 | J6: 0.53189815 | K6: 150425 | L6: 150425 | M6: 150425 | N6: 150427 | O6: 150428 | P6: 150427 | Q6: 150429 | R6: 150430 | S6: 150429 | T6: 150430 | U6: 150430 | V6: 150430 | W6: =W5 -> 0.947932 | Y6: 2 | Z6: WR00L2L2 | AA6: 12672 | AB6: 32 | AC6: 1 | AD6: 4 | AE6: 1690.13 | AF6: 0.80279 | AG6: 45468 | AH6: 0.50327546 | AI6: 196781 | AJ6: 196782 | AK6: 196781 | AL6: 196783 | AM6: 196782 | AN6: 196783 | AO6: 196784 | AP6: 196784 | AQ6: 196784 | AR6: 196785 | AS6: 196786 | AT6: 196785 | AU6: =AU5 -> 0.801688 | AW6: 2 | AX6: WR00L2L2 | AY6: 12672 | AZ6: 32 | BA6: 1 | BB6: 4 | BC6: 1426.7 | BD6: 0.95102 | BS6: =BS5 -> 0.951422
A7: 3 | B7: WR00L2L2 | C7: 12672 | D7: 32 | E7: 1 | F7: 4 | G7: 1437.83 | H7: 0.94366 | I7: 45477 | J7: 0.51997685 | K7: 150803 | L7: 150804 | M7: 150803 | N7: 150804 | O7: 150804 | P7: 150804 | Q7: 150805 | R7: 150805 | S7: 150805 | T7: 150806 | U7: 150806 | V7: 150807 | W7: =W6 -> 0.947932 | Y7: 3 | Z7: WR00L2L2 | AA7: 12672 | AB7: 32 | AC7: 1 | AD7: 4 | AE7: 1691.35 | AF7: 0.80221 | AG7: 45469 | AH7: 0.87047454 | AI7: 196853 | AJ7: 196854 | AK7: 196854 | AL7: 196854 | AM7: 196854 | AN7: 196854 | AO7: 196851 | AP7: 196851 | AQ7: 196852 | AR7: 196851 | AS7: 196852 | AT7: 196852 | AU7: =AU6 -> 0.801688 | AW7: 3 | AX7: WR00L2L2 | AY7: 12672 | AZ7: 32 | BA7: 1 | BB7: 4 | BC7: 1425.37 | BD7: 0.9519 | BS7: =BS6 -> 0.951422
A8: 4 | B8: WR00L2L2 | C8: 12672 | D8: 32 | E8: 1 | F8: 4 | G8: 1428.14 | H8: 0.95006 | I8: 45478 | J8: 0.50115741 | K8: 149799 | L8: 149799 | M8: 149798 | N8: 149799 | O8: 149799 | P8: 149800 | Q8: 149799 | R8: 149799 | S8: 149799 | T8: 149801 | U8: 149800 | V8: 149800 | W8: =W7 -> 0.947932 | Y8: 4 | Z8: WR00L2L2 | AA8: 12672 | AB8: 32 | AC8: 1 | AD8: 4 | AE8: 1693.12 | AF8: 0.80137 | AG8: 45471 | AH8: 0.22175926 | AI8: 197040 | AJ8: 197041 | AK8: 197040 | AL8: 197043 | AM8: 197042 | AN8: 197042 | AO8: 197044 | AP8: 197045 | AQ8: 197045 | AR8: 197046 | AS8: 197046 | AT8: 197046 | AU8: =AU7 -> 0.801688 | AW8: 4 | AX8: WR00L2L2 | AY8: 12672 | AZ8: 32 | BA8: 1 | BB8: 4 | BC8: 1424.54 | BD8: 0.95246 | BS8: =BS7 -> 0.951422
A9: 0 | B9: WR00L2L2 | C9: 13440 | D9: 32 | E9: 1 | F9: 4 | G9: 1680.54 | H9: 0.96323 | I9: 45474 | J9: 0.81885417 | K9: 175768 | L9: 175768 | M9: 175767 | N9: 175769 | O9: 175770 | P9: 175769 | Q9: 175773 | R9: 175773 | S9: 175773 | T9: 175775 | U9: 175776 | V9: 175776 | W9: =AVERAGE(H9:H13) -> 0.962258 | Y9: 0 | Z9: WR00L2L2 | AA9: 13440 | AB9: 32 | AC9: 1 | AD9: 4 | AE9: 1996.82 | AF9: 0.81066 | AG9: 45466 | AH9: 0.11435185 | AI9: 230750 | AJ9: 230750 | AK9: 230749 | AL9: 230751 | AM9: 230751 | AN9: 230752 | AO9: 230763 | AP9: 230763 | AQ9: 230763 | AR9: 230763 | AS9: 230764 | AT9: 230764 | AU9: =AVERAGE(AF9:AF13) -> 0.80911 | AW9: 0 | AX9: WR00L2L2 | AY9: 13440 | AZ9: 32 | BA9: 1 | BB9: 4 | BC9: 1681.29 | BD9: 0.9628 | BS9: =AVERAGE(BD9:BD13) -> 0.963142
A10: 1 | B10: WR00L2L2 | C10: 13440 | D10: 32 | E10: 1 | F10: 4 | G10: 1681.07 | H10: 0.96292 | I10: 45475 | J10: 0.81364583 | K10: 175835 | L10: 175836 | M10: 175836 | N10: 175837 | O10: 175838 | P10: 175838 | Q10: 175840 | R10: 175840 | S10: 175840 | T10: 175840 | U10: 175841 | V10: 175841 | W10: =W9 -> 0.962258 | Y10: 1 | Z10: WR00L2L2 | AA10: 13440 | AB10: 32 | AC10: 1 | AD10: 4 | AE10: 1996.26 | AF10: 0.81089 | AG10: 45467 | AH10: 0.50332176 | AI10: 230691 | AJ10: 230690 | AK10: 230691 | AL10: 230700 | AM10: 230700 | AN10: 230699 | AO10: 230723 | AP10: 230723 | AQ10: 230723 | AR10: 230729 | AS10: 230729 | AT10: 230729 | AU10: =AU9 -> 0.80911 | AW10: 1 | AX10: WR00L2L2 | AY10: 13440 | AZ10: 32 | BA10: 1 | BB10: 4 | BC10: 1688.26 | BD10: 0.95883 | BS10: =BS9 -> 0.963142
A11: 2 | B11: WR00L2L2 | C11: 13440 | D11: 32 | E11: 1 | F11: 4 | G11: 1680.76 | H11: 0.96311 | I11: 45476 | J11: 0.80574074 | K11: 175786 | L11: 175786 | M11: 175786 | N11: 175789 | O11: 175789 | P11: 175788 | Q11: 175792 | R11: 175791 | S11: 175792 | T11: 175810 | U11: 175810 | V11: 175810 | W11: =W10 -> 0.962258 | Y11: 2 | Z11: WR00L2L2 | AA11: 13440 | AB11: 32 | AC11: 1 | AD11: 4 | AE11: 2013.1 | AF11: 0.80411 | AG11: 45468 | AH11: 0.8809838 | AI11: 232517 | AJ11: 232517 | AK11: 232517 | AL11: 232525 | AM11: 232525 | AN11: 232525 | AO11: 232562 | AP11: 232563 | AQ11: 232563 | AR11: 232563 | AS11: 232564 | AT11: 232564 | AU11: =AU10 -> 0.80911 | AW11: 2 | AX11: WR00L2L2 | AY11: 13440 | AZ11: 32 | BA11: 1 | BB11: 4 | BC11: 1677.8 | BD11: 0.9648 | BS11: =BS10 -> 0.963142
A12: 3 | B12: WR00L2L2 | C12: 13440 | D12: 32 | E12: 1 | F12: 4 | G12: 1681.26 | H12: 0.96282 | I12: 45477 | J12: 0.79391204 | K12: 175866 | L12: 175866 | M12: 175865 | N12: 175889 | O12: 175889 | P12: 175888 | Q12: 175921 | R12: 175920 | S12: 175920 | T12: 175943 | U12: 175943 | V12: 175943 | W12: =W11 -> 0.962258 | Y12: 3 | Z12: WR00L2L2 | AA12: 13440 | AB12: 32 | AC12: 1 | AD12: 4 | AE12: 2003.41 | AF12: 0.808 | AG12: 45470 | AH12: 0.24449074 | AI12: 231416 | AJ12: 231417 | AK12: 231416 | AL12: 231426 | AM12: 231427 | AN12: 231427 | AO12: 231455 | AP12: 231455 | AQ12: 231456 | AR12: 231453 | AS12: 231453 | AT12: 231453 | AU12: =AU11 -> 0.80911 | AW12: 3 | AX12: WR00L2L2 | AY12: 13440 | AZ12: 32 | BA12: 1 | BB12: 4 | BC12: 1677.73 | BD12: 0.96484 | BS12: =BS11 -> 0.963142
A13: 4 | B13: WR00L2L2 | C13: 13440 | D13: 32 | E13: 1 | F13: 4 | G13: 1687.59 | H13: 0.95921 | I13: 45478 | J13: 0.775 | K13: 176648 | L13: 176647 | M13: 176648 | N13: 176650 | O13: 176651 | P13: 176650 | Q13: 176653 | R13: 176653 | S13: 176652 | T13: 176670 | U13: 176670 | V13: 176670 | W13: =W12 -> 0.962258 | Y13: 4 | Z13: WR00L2L2 | AA13: 13440 | AB13: 32 | AC13: 1 | AD13: 4 | AE13: 1993.81 | AF13: 0.81189 | AG13: 45471 | AH13: 0.60130787 | AI13: 230504 | AJ13: 230504 | AK13: 230503 | AL13: 230506 | AM13: 230505 | AN13: 230506 | AO13: 230507 | AP13: 230508 | AQ13: 230507 | AR13: 230538 | AS13: 230538 | AT13: 230538 | AU13: =AU12 -> 0.80911 | AW13: 4 | AX13: WR00L2L2 | AY13: 13440 | AZ13: 32 | BA13: 1 | BB13: 4 | BC13: 1678.43 | BD13: 0.96444 | BS13: =BS12 -> 0.963142
A14: 0 | B14: WR00L2L2 | C14: 14208 | D14: 32 | E14: 1 | F14: 4 | G14: 1981.93 | H14: 0.96492 | I14: 45475 | J14: 0.14480324 | K14: 206953 | L14: 206952 | M14: 206953 | N14: 206988 | O14: 206988 | P14: 206988 | Q14: 206992 | R14: 206991 | S14: 206992 | T14: 207040 | U14: 207040 | V14: 207040 | W14: =AVERAGE(H14:H18) -> 0.962742 | Y14: 0 | Z14: WR00L2L2 | AA14: 14208 | AB14: 32 | AC14: 1 | AD14: 4 | AE14: 2357.54 | AF14: 0.81118 | AG14: 45466 | AH14: 0.56349537 | AI14: 270546 | AJ14: 270545 | AK14: 270545 | AL14: 270593 | AM14: 270592 | AN14: 270593 | AO14: 270638 | AP14: 270638 | AQ14: 270638 | AR14: 270690 | AS14: 270690 | AT14: 270691 | AU14: =AVERAGE(AF14:AF18) -> 0.813152 | AW14: 0 | AX14: WR00L2L2 | AY14: 14208 | AZ14: 32 | BA14: 1 | BB14: 4 | BC14: 1978.01 | BD14: 0.96683 | BS14: =AVERAGE(BD14:BD18) -> 0.959308
A15: 1 | B15: WR00L2L2 | C15: 14208 | D15: 32 | E15: 1 | F15: 4 | G15: 1986.07 | H15: 0.9629 | I15: 45476 | J15: 0.13957176 | K15: 207311 | L15: 207312 | M15: 207311 | N15: 207341 | O15: 207341 | P15: 207342 | Q15: 207389 | R15: 207388 | S15: 207388 | T15: 207434 | U15: 207434 | V15: 207435 | W15: =W14 -> 0.962742 | Y15: 1 | Z15: WR00L2L2 | AA15: 14208 | AB15: 32 | AC15: 1 | AD15: 4 | AE15: 2346.94 | AF15: 0.81484 | AG15: 45467 | AH15: 0.9524537 | AI15: 269386 | AJ15: 269386 | AK15: 269385 | AL15: 269426 | AM15: 269425 | AN15: 269425 | AO15: 269436 | AP15: 269436 | AQ15: 269437 | AR15: 269478 | AS15: 269478 | AT15: 269479 | AU15: =AU14 -> 0.813152 | AW15: 1 | AX15: WR00L2L2 | AY15: 14208 | AZ15: 32 | BA15: 1 | BB15: 4 | BC15: 1983.77 | BD15: 0.96402 | BS15: =BS14 -> 0.959308
A16: 2 | B16: WR00L2L2 | C16: 14208 | D16: 32 | E16: 1 | F16: 4 | G16: 1990.58 | H16: 0.96072 | I16: 45477 | J16: 0.13203704 | K16: 207821 | L16: 207821 | M16: 207821 | N16: 207873 | O16: 207873 | P16: 207873 | Q16: 207935 | R16: 207935 | S16: 207936 | T16: 207976 | U16: 207976 | V16: 207976 | W16: =W15 -> 0.962742 | Y16: 2 | Z16: WR00L2L2 | AA16: 14208 | AB16: 32 | AC16: 1 | AD16: 4 | AE16: 2360.8 | AF16: 0.81006 | AG16: 45469 | AH16: 0.32747685 | AI16: 271118 | AJ16: 271119 | AK16: 271118 | AL16: 271173 | AM16: 271173 | AN16: 271173 | AO16: 271223 | AP16: 271223 | AQ16: 271222 | AR16: 271273 | AS16: 271273 | AT16: 271274 | AU16: =AU15 -> 0.813152 | AW16: 2 | AX16: WR00L2L2 | AY16: 14208 | AZ16: 32 | BA16: 1 | BB16: 4 | BC16: 2010.94 | BD16: 0.95099 | BS16: =BS15 -> 0.959308
A17: 3 | B17: WR00L2L2 | C17: 14208 | D17: 32 | E17: 1 | F17: 4 | G17: 1991.46 | H17: 0.9603 | I17: 45478 | J17: 0.12 | K17: 207751 | L17: 207751 | M17: 207751 | N17: 207778 | O17: 207778 | P17: 207778 | Q17: 207820 | R17: 207820 | S17: 207820 | T17: 207879 | U17: 207879 | V17: 207879 | W17: =W16 -> 0.962742 | Y17: 3 | Z17: WR00L2L2 | AA17: 14208 | AB17: 32 | AC17: 1 | AD17: 4 | AE17: 2352.29 | AF17: 0.81299 | AG17: 45470 | AH17: 0.69 | AI17: 270079 | AJ17: 270079 | AK17: 270079 | AL17: 270126 | AM17: 270126 | AN17: 270127 | AO17: 270132 | AP17: 270132 | AQ17: 270133 | AR17: 270197 | AS17: 270197 | AT17: 270197 | AU17: =AU16 -> 0.813152 | AW17: 3 | AX17: WR00L2L2 | AY17: 14208 | AZ17: 32 | BA17: 1 | BB17: 4 | BC17: 2014.83 | BD17: 0.94915 | BS17: =BS16 -> 0.959308
A18: 4 | B18: WR00L2L2 | C18: 14208 | D18: 32 | E18: 1 | F18: 4 | G18: 1982.02 | H18: 0.96487 | I18: 45479 | J18: 0.10065972 | K18: 206873 | L18: 206873 | M18: 206872 | N18: 206918 | O18: 206918 | P18: 206917 | Q18: 206960 | R18: 206960 | S18: 206960 | T18: 206998 | U18: 206997 | V18: 206997 | W18: =W17 -> 0.962742 | Y18: 4 | Z18: WR00L2L2 | AA18: 14208 | AB18: 32 | AC18: 1 | AD18: 4 | AE18: 2341.65 | AF18: 0.81669 | AG18: 45472 | AH18: 0.053148148 | AI18: 268910 | AJ18: 268909 | AK18: 268910 | AL18: 268921 | AM18: 268921 | AN18: 268921 | AO18: 268966 | AP18: 268966 | AQ18: 268965 | AR18: 268995 | AS18: 268995 | AT18: 268994 | AU18: =AU17 -> 0.813152 | AW18: 4 | AX18: WR00L2L2 | AY18: 14208 | AZ18: 32 | BA18: 1 | BB18: 4 | BC18: 1980.63 | BD18: 0.96555 | BS18: =BS17 -> 0.959308
A19: 0 | B19: WR00L2L2 | C19: 12672 | D19: 32 | E19: 2 | F19: 2 | G19: 1382.59 | H19: 0.98136 | I19: 45474 | J19: 0.56190972 | K19: 145152 | L19: 145152 | M19: 145153 | N19: 145155 | O19: 145154 | P19: 145155 | Q19: 145155 | R19: 145155 | S19: 145155 | T19: 145157 | U19: 145157 | V19: 145157 | W19: =AVERAGE(H19:H23) -> 0.97878 | Y19: 0 | Z19: WR00L2L2 | AA19: 12672 | AB19: 32 | AC19: 2 | AD19: 2 | AE19: 1645.75 | AF19: 0.82444 | AG19: 45465 | AH19: 0.75922454 | AI19: 192200 | AJ19: 192200 | AK19: 192200 | AL19: 192201 | AM19: 192202 | AN19: 192202 | AO19: 192212 | AP19: 192212 | AQ19: 192212 | AR19: 192225 | AS19: 192225 | AT19: 192225 | AU19: =AVERAGE(AF19:AF23) -> 0.826772 | AW19: 0 | AX19: WR00L2L2 | AY19: 12672 | AZ19: 32 | BA19: 2 | BB19: 2 | BC19: 1383.15 | BD19: 0.98096 | BS19: =AVERAGE(BD19:BD23) -> 0.980068
A20: 1 | B20: WR00L2L2 | C20: 12672 | D20: 32 | E20: 2 | F20: 2 | G20: 1382.86 | H20: 0.98117 | I20: 45475 | J20: 0.55672454 | K20: 145154 | L20: 145154 | M20: 145154 | N20: 145160 | O20: 145161 | P20: 145160 | Q20: 145162 | R20: 145162 | S20: 145162 | T20: 145167 | U20: 145168 | V20: 145168 | W20: =W19 -> 0.97878 | Y20: 1 | Z20: WR00L2L2 | AA20: 12672 | AB20: 32 | AC20: 2 | AD20: 2 | AE20: 1635.36 | AF20: 0.82967 | AG20: 45467 | AH20: 0.14730324 | AI20: 191140 | AJ20: 191139 | AK20: 191140 | AL20: 191141 | AM20: 191141 | AN20: 191140 | AO20: 191142 | AP20: 191143 | AQ20: 191143 | AR20: 191148 | AS20: 191149 | AT20: 191148 | AU20: =AU19 -> 0.826772 | AW20: 1 | AX20: WR00L2L2 | AY20: 12672 | AZ20: 32 | BA20: 2 | BB20: 2 | BC20: 1381.02 | BD20: 0.98247 | BS20: =BS19 -> 0.980068
A21: 2 | B21: WR00L2L2 | C21: 12672 | D21: 32 | E21: 2 | F21: 2 | G21: 1391.33 | H21: 0.97519 | I21: 45476 | J21: 0.54886574 | K21: 145963 | L21: 145964 | M21: 145963 | N21: 145965 | O21: 145966 | P21: 145966 | Q21: 145963 | R21: 145963 | S21: 145963 | T21: 145965 | U21: 145965 | V21: 145965 | W21: =W20 -> 0.97878 | Y21: 2 | Z21: WR00L2L2 | AA21: 12672 | AB21: 32 | AC21: 2 | AD21: 2 | AE21: 1638.73 | AF21: 0.82797 | AG21: 45468 | AH21: 0.52559028 | AI21: 192253 | AJ21: 192254 | AK21: 192253 | AL21: 192257 | AM21: 192256 | AN21: 192256 | AO21: 192257 | AP21: 192258 | AQ21: 192258 | AR21: 192259 | AS21: 192260 | AT21: 192259 | AU21: =AU20 -> 0.826772 | AW21: 2 | AX21: WR00L2L2 | AY21: 12672 | AZ21: 32 | BA21: 2 | BB21: 2 | BC21: 1382.24 | BD21: 0.98161 | BS21: =BS20 -> 0.980068
A22: 3 | B22: WR00L2L2 | C22: 12672 | D22: 32 | E22: 2 | F22: 2 | G22: 1391.77 | H22: 0.97489 | I22: 45477 | J22: 0.53694444 | K22: 146019 | L22: 146020 | M22: 146019 | N22: 146021 | O22: 146021 | P22: 146021 | Q22: 146023 | R22: 146023 | S22: 146023 | T22: 146026 | U22: 146026 | V22: 146025 | W22: =W21 -> 0.97878 | Y22: 3 | Z22: WR00L2L2 | AA22: 12672 | AB22: 32 | AC22: 2 | AD22: 2 | AE22: 1643 | AF22: 0.82582 | AG22: 45469 | AH22: 0.89275463 | AI22: 191934 | AJ22: 191935 | AK22: 191934 | AL22: 191937 | AM22: 191937 | AN22: 191936 | AO22: 191935 | AP22: 191936 | AQ22: 191935 | AR22: 191936 | AS22: 191937 | AT22: 191937 | AU22: =AU21 -> 0.826772 | AW22: 3 | AX22: WR00L2L2 | AY22: 12672 | AZ22: 32 | BA22: 2 | BB22: 2 | BC22: 1380.6 | BD22: 0.98278 | BS22: =BS21 -> 0.980068
