Workbook

Sheet Arch details
A1: SBC | B1: Cores | C1: march | D1: mcpu | E1: mtune | F1: fpu | G1: mfloat-abi | H1: mabi | J1: ostalo | K1: ostalo (Thumb)
A2: Rpi 1B | C2: armv6 | D2: arm1176jzf-s | E2: arm1176jzf-s | F2: vfpv2 (alias is vfp) | G2: hard | K2: Thumb | L2: 16KB L1 and no L2
A3: Cubieboard2 | C3: armv7-a | D3: cortex-a7 | E3: cortex-a7 | F3: neon-vfpv4 | G3: hard | J3: -funsafe-math-optimizations | K3: Thumb-2
A4: OdroidU3 | C4: armv7-a | D4: cortex-a9 | E4: cortex-a9 | F4: neon-vfpv3 (alias is neon) | G4: hard | J4: -funsafe-math-optimizations | K4: Thumb or Thumb-2 | L4: 1MB L2 cache total? From paper…
A5: OdroidMC1 | B5: LITTLE | C5: armv7-a | D5: cortex-a7 | E5: cortex-a7 | F5: neon-vfpv4 | G5: hard | J5: -funsafe-math-optimizations | K5: Thumb-2 | L5: 2 sockets, 2,5MB L2 cache per socket
B6: Big | C6: armv7-a | D6: cortex-a15 | E6: cortex-a15 | F6: neon-vfpv4 | G6: hard | J6: -funsafe-math-optimizations | K6: Thumb-2
A7: Rpi 5B | C7: armv8.2-a+crypto+fp16+rcpc+dotprod | D7: cortex-a76+crypto | E7: cortex-a76 | G7: hard | H7: lp64
A12: HPL Runs (fixed parameters) | C12: Number of nodes | D12: Node | E12: Total memory of a node (kB) | F12: N, alpha | G12: N, alpha (NB round) | H12: N, beta | I12: N, beta (NB round) | J12: NB | K12: P | L12: Q | M12: Ns difference | N12: Half of the Ns difference | O12: N1 | P12: N2 | Q12: N3
A13: Number of nodes | B13: 4 | C13: 1 | D13: Raspberry Pi 5 | E13: 8245648 | F13: =$B$14*SQRT(($C13*$E13*1024)/8) -> 25990.065 | G13: =_xlfn.CEILING.MATH(F13/J13)*J13 -> 26048 | H13: =SQRT($B$14*($C13*$E13*1024)/8) -> 29057.776 | I13: =_xlfn.CEILING.MATH(H13/J13)*J13 -> 29120 | J13: 64 | K13: 2 | L13: 2 | M13: =I13-G13 -> 3072 | N13: =M13/2 -> 1536 | O13: =G13 -> 26048 | P13: =_xlfn.CEILING.MATH((O13+N13)/J13)*J13 -> 27584 | Q13: =_xlfn.CEILING.MATH((P13+N13)/J13)*J13 -> 29120
A14: Percentage of mem | B14: 0.8 | C14: 4 | D14: Raspberry Pi 5 | E14: 8245648 | F14: =$B$14*SQRT(($B$13*$E14*1024)/8) -> 51980.13 | G14: =_xlfn.CEILING.MATH(F14/J14)*J14 -> 52000 | H14: =SQRT($B$14*($B$13*$E14*1024)/8) -> 58115.552 | I14: =_xlfn.CEILING.MATH(H14/J14)*J14 -> 58240 | J14: 160 | K14: 2 | L14: 8 | M14: =I14-G14 -> 6240 | N14: =M14/2 -> 3120 | O14: =G14 -> 52000 | P14: =_xlfn.CEILING.MATH((O14+N14)/J14)*J14 -> 55200 | Q14: =_xlfn.CEILING.MATH((P14+N14)/J14)*J14 -> 58400

Sheet ATLAS builds
A1: Raspberry Pi 4B | C1: Repetitive flags | D1: 32/64 build (or none) | E1: Other ATLAS config flags | F1: Compiler append flag | G1: Compiler flags used for building | H1: Main ATLAS flags | I1: Main ATLAS flags after flagsearch | J1: Performance of the build before flagsearch [GFLOP/s] | K1: Performance of the build after flagsearch [GFLOP/s] | L1: Flags used for flagsearching - mandatory | M1: Flags used for flagsearching - optional | N1: Machine originally built on | O1: Flagsearch benchmark results | P1: NOTE | R1: TODO
A2: 1 | B2: atlarch | C2: -D c -DWALL | D2: -b 64 | E2: -A ARM64xgene1 | H2: =D2&E2&F2&G2 -> -b 64-A ARM64xgene1 | I2: -b 64-Fa alg -O2 | J2: =VLOOKUP(B2,'4 nodes, builds, RAW'!$Z$4:$AB$31,3,FALSE) -> 127.786 | K2: 129.378 | L2: -pipe | M2: -march=native -mtune=native -mcpu=native -march=armv8.2-a+crypto+fp16+rcpc+dotprod -mtune=cortex-a76 -mcpu=cortex-a76+crypto -mcpu=cortex-a76+crc+crypto -mabi=lp64 -march=-march=armv8.2-a -mlittle-endian | N2: raspi31 | P2: https://gist.github.com/fm4dd/c663217935dc17f0fc73c9c81b0aa845 | R2: In progress
A3: 2 | B3: atlarch-native | C3: -D c -DWALL | D3: -b 64 | E3: -A ARM64xgene1 | F3: -Fa alg | G3: -march=native -mtune=native -mcpu=native | H3: =D3&E3&F3&G3 -> -b 64-A ARM64xgene1-Fa alg-march=native -mtune=native -mcpu=native | I3: -b 64-Fa alg -O2 -march=native -mtune=native -mcpu=native | J3: =VLOOKUP(B3,'4 nodes, builds, RAW'!$Z$4:$AB$31,3,FALSE) -> 130.522 | K3: 129.854 | L3: -march=native -mtune=native -mcpu=native | N3: raspi32 | R3: Freshly finished
A4: 3 | B4: arch-native | C4: -D c -DWALL | D4: -b 64 | F4: -Fa alg | G4: -march=native -mtune=native -mcpu=native | H4: =D4&E4&F4&G4 -> -b 64-Fa alg-march=native -mtune=native -mcpu=native | I4: -b 64-Fa alg -O2 -march=native -mtune=native -mcpu=native | J4: =VLOOKUP(B4,'4 nodes, builds, RAW'!$Z$4:$AB$31,3,FALSE) -> 129.18 | K4: 127.784 | L4: -march=native -mtune=native -mcpu=native | N4: raspi33 | R4: Done
A5: 4 | B5: all-spec | C5: -D c -DWALL | D5: -b 64 | F5: -Fa alg | G5: -march=armv8.2-a+crypto+fp16+rcpc+dotprod -mtune=cortex-a76 -mcpu=cortex-a76+crypto | H5: =D5&E5&F5&G5 -> -b 64-Fa alg-march=armv8.2-a+crypto+fp16+rcpc+dotprod -mtune=cortex-a76 -mcpu=cortex-a76+crypto | I5: -b 64-Fa alg -O2 -march=armv8.2-a+crypto+fp16+rcpc+dotprod -mtune=cortex-a76 -mcpu=cortex-a76+crypto | J5: =VLOOKUP(B5,'4 nodes, builds, RAW'!$Z$4:$AB$31,3,FALSE) -> 102.922 | K5: 129.732 | L5: -march=armv8.2-a+crypto+fp16+rcpc+dotprod -mtune=cortex-a76 -mcpu=cortex-a76+crypto | N5: raspi34 | R5: TODO with the same settings!
A6: 5 | B6: atlarch-all-spec | C6: -D c -DWALL | D6: -b 64 | E6: -A ARM64xgene1 | F6: -Fa alg | G6: -march=armv8.2-a+crypto+fp16+rcpc+dotprod -mtune=cortex-a76 -mcpu=cortex-a76+crypto | H6: =D6&E6&F6&G6 -> -b 64-A ARM64xgene1-Fa alg-march=armv8.2-a+crypto+fp16+rcpc+dotprod -mtune=cortex-a76 -mcpu=cortex-a76+crypto | I6: -b 64-Fa alg -O2 -march=armv8.2-a+crypto+fp16+rcpc+dotprod -mtune=cortex-a76 -mcpu=cortex-a76+crypto | J6: =VLOOKUP(B6,'4 nodes, builds, RAW'!$Z$4:$AB$31,3,FALSE) -> 130.668 | K6: 129.832 | L6: -march=armv8.2-a+crypto+fp16+rcpc+dotprod -mtune=cortex-a76 -mcpu=cortex-a76+crypto | N6: raspi31 | P6: Čudno da je ovaj najbolji, a uopće nema -O definiran. Jedino ako po defaultu koristi ono što je predefinirano za sve ATLAS kompajlere.
A7: 6 | B7: cpu | C7: -D c -DWALL | D7: -b 64 | F7: -Fa alg | G7: -mcpu=cortex-a76+crypto | H7: =D7&E7&F7&G7 -> -b 64-Fa alg-mcpu=cortex-a76+crypto | I7: -b 64-Fa alg -O2 -mcpu=cortex-a76+crypto | J7: =VLOOKUP(B7,'4 nodes, builds, RAW'!$Z$4:$AB$31,3,FALSE) -> 129.464 | K7: 129.91 | L7: -mcpu=cortex-a76+crypto | N7: raspi32 | P7: According to some reddit posts: https://www.reddit.com/r/Gentoo/comments/1c5y19x/getting_a_pi_5_have_questions/
A8: 7 | B8: cpu-crc | C8: -D c -DWALL | D8: -b 64 | F8: -Fa alg | G8: -mcpu=cortex-a76+crc+crypto | H8: =D8&E8&F8&G8 -> -b 64-Fa alg-mcpu=cortex-a76+crc+crypto | I8: -b 64-Fa alg -O2 -mcpu=cortex-a76+crc+crypto | J8: =VLOOKUP(B8,'4 nodes, builds, RAW'!$Z$4:$AB$31,3,FALSE) -> 129.13 | K8: 129.822 | L8: -mcpu=cortex-a76+crc+crypto | N8: raspi33
A9: 8 | B9: cpu-tune | C9: -D c -DWALL | D9: -b 64 | F9: -Fa alg | G9: -mcpu=cortex-a76+crypto -mtune=cortex-a76 | H9: =D9&E9&F9&G9 -> -b 64-Fa alg-mcpu=cortex-a76+crypto -mtune=cortex-a76 | I9: -b 64-Fa alg -O2 -mcpu=cortex-a76+crypto -mtune=cortex-a76 | J9: =VLOOKUP(B9,'4 nodes, builds, RAW'!$Z$4:$AB$31,3,FALSE) -> 129.36 | K9: 103.114 | L9: -mcpu=cortex-a76+crypto -mtune=cortex-a76 | N9: raspi34 | P9: Malo bolji od cpu-tune-abi, no s flagsima malo veća razlika (cpu-tune-flags vs- cpu-tune-abi-flags)
A10: 9 | B10: cpu-tune-abi | C10: -D c -DWALL | D10: -b 64 | F10: -Fa alg | G10: -mcpu=cortex-a76+crypto -mtune=cortex-a76 -mabi=lp64 | H10: =D10&E10&F10&G10 -> -b 64-Fa alg-mcpu=cortex-a76+crypto -mtune=cortex-a76 -mabi=lp64 | I10: -b 64-Fa alg -O2 -mcpu=cortex-a76+crypto -mtune=cortex-a76 -mabi=lp64 | J10: =VLOOKUP(B10,'4 nodes, builds, RAW'!$Z$4:$AB$31,3,FALSE) -> 129.062 | K10: 129.756 | L10: -mcpu=cortex-a76+crypto -mtune=cortex-a76 -mabi=lp64 | N10: raspi31
A11: 10 | B11: atlarch-cpu | C11: -D c -DWALL | D11: -b 64 | E11: -A ARM64xgene1 | F11: -Fa alg | G11: -mcpu=cortex-a76+crypto | H11: =D11&E11&F11&G11 -> -b 64-A ARM64xgene1-Fa alg-mcpu=cortex-a76+crypto | I11: -b 64-Fa alg -O2 -mcpu=cortex-a76+crypto | J11: =VLOOKUP(B11,'4 nodes, builds, RAW'!$Z$4:$AB$31,3,FALSE) -> 104.594 | K11: 129.698 | L11: -mcpu=cortex-a76+crypto | N11: raspi32
A12: 11 | B12: atlarch-cpu-tune | C12: -D c -DWALL | D12: -b 64 | E12: -A ARM64xgene1 | F12: -Fa alg | G12: -mcpu=cortex-a76+crypto -mtune=cortex-a76 | H12: =D12&E12&F12&G12 -> -b 64-A ARM64xgene1-Fa alg-mcpu=cortex-a76+crypto -mtune=cortex-a76 | I12: -b 64-Fa alg -O2 -mcpu=cortex-a76+crypto -mtune=cortex-a76 | J12: =VLOOKUP(B12,'4 nodes, builds, RAW'!$Z$4:$AB$31,3,FALSE) -> 130.228 | K12: 130.084 | L12: -mcpu=cortex-a76+crypto -mtune=cortex-a76 | N12: raspi33
A13: 12 | B13: cpu-tune-clean-flagsearch | C13: -D c -DWALL | D13: -b 64 | F13: -Fa alg | G13: -mcpu=cortex-a76+crypto -mtune=cortex-a76 | H13: =D13&E13&F13&G13 -> -b 64-Fa alg-mcpu=cortex-a76+crypto -mtune=cortex-a76 | I13: -b 64-Fa alg -O2 -mtune=native | J13: =VLOOKUP(B13,'4 nodes, builds, RAW'!$Z$4:$AB$31,3,FALSE) -> 103.448 | K13: 129.626 | L13: -pipe | N13: raspi34
A14: 13 | B14: generic | C14: -D c -DWALL | E14: -Si archdef 1 | H14: =D14&E14&F14&G14 -> -Si archdef 1 | I14: -b 64-Fa alg -O2 -mtune=native | J14: =VLOOKUP(B14,'4 nodes, builds, RAW'!$Z$4:$AB$31,3,FALSE) -> 103.388 | K14: 129.856 | L14: -pipe | N14: raspi31
A15: 14 | B15: noarch | C15: -D c -DWALL | E15: -Si archdef 0 | H15: =D15&E15&F15&G15 -> -Si archdef 0 | I15: -b 64-Fa alg -O2 -mtune=native | J15: =VLOOKUP(B15,'4 nodes, builds, RAW'!$Z$4:$AB$31,3,FALSE) -> 128.522 | K15: 129.748 | L15: -pipe | N15: raspi32
A16: 15 | B16: atlarch-flags | C16: -D c -DWALL | D16: -b 64 | F16: -Fa alg | G16: -O2 | H16: =D16&E16&F16&G16 -> -b 64-Fa alg -O2 | O16: 877991
A17: 16 | B17: atlarch-native-flags | C17: -D c -DWALL | D17: -b 64 | F17: -Fa alg | G17: -O2 -march=native -mtune=native -mcpu=native | H17: =D17&E17&F17&G17 -> -b 64-Fa alg -O2 -march=native -mtune=native -mcpu=native | O17: 872141
A18: 17 | B18: arch-native-flags | C18: -D c -DWALL | D18: -b 64 | F18: -Fa alg | G18: -O2 -march=native -mtune=native -mcpu=native | H18: =D18&E18&F18&G18 -> -b 64-Fa alg -O2 -march=native -mtune=native -mcpu=native | O18: 880685
A19: 18 | B19: all-spec-flags | C19: -D c -DWALL | D19: -b 64 | F19: -Fa alg | G19: -O2 -march=armv8.2-a+crypto+fp16+rcpc+dotprod -mtune=cortex-a76 -mcpu=cortex-a76+crypto | H19: =D19&E19&F19&G19 -> -b 64-Fa alg -O2 -march=armv8.2-a+crypto+fp16+rcpc+dotprod -mtune=cortex-a76 -mcpu=cortex-a76+crypto | O19: 878809
A20: 19 | B20: atlarch-all-spec-flags | C20: -D c -DWALL | D20: -b 64 | F20: -Fa alg | G20: -O2 -march=armv8.2-a+crypto+fp16+rcpc+dotprod -mtune=cortex-a76 -mcpu=cortex-a76+crypto | H20: =D20&E20&F20&G20 -> -b 64-Fa alg -O2 -march=armv8.2-a+crypto+fp16+rcpc+dotprod -mtune=cortex-a76 -mcpu=cortex-a76+crypto | O20: 873161
A21: 20 | B21: cpu-flags | C21: -D c -DWALL | D21: -b 64 | F21: -Fa alg | G21: -O2 -mcpu=cortex-a76+crypto | H21: =D21&E21&F21&G21 -> -b 64-Fa alg -O2 -mcpu=cortex-a76+crypto | O21: 880663
A22: 21 | B22: cpu-crc-flags | C22: -D c -DWALL | D22: -b 64 | F22: -Fa alg | G22: -O2 -mcpu=cortex-a76+crc+crypto | H22: =D22&E22&F22&G22 -> -b 64-Fa alg -O2 -mcpu=cortex-a76+crc+crypto | O22: 877576
A23: 22 | B23: cpu-tune-flags | C23: -D c -DWALL | D23: -b 64 | F23: -Fa alg | G23: -O2 -mcpu=cortex-a76+crypto -mtune=cortex-a76 | H23: =D23&E23&F23&G23 -> -b 64-Fa alg -O2 -mcpu=cortex-a76+crypto -mtune=cortex-a76 | O23: 877442
A24: 23 | B24: cpu-tune-abi-flags | C24: -D c -DWALL | D24: -b 64 | F24: -Fa alg | G24: -O2 -mcpu=cortex-a76+crypto -mtune=cortex-a76 -mabi=lp64 | H24: =D24&E24&F24&G24 -> -b 64-Fa alg -O2 -mcpu=cortex-a76+crypto -mtune=cortex-a76 -mabi=lp64 | O24: 877622
A25: 24 | B25: atlarch-cpu-flags | C25: -D c -DWALL | D25: -b 64 | F25: -Fa alg | G25: -O2 -mcpu=cortex-a76+crypto | H25: =D25&E25&F25&G25 -> -b 64-Fa alg -O2 -mcpu=cortex-a76+crypto | O25: 879875
A26: 25 | B26: atlarch-cpu-tune-flags | C26: -D c -DWALL | D26: -b 64 | F26: -Fa alg | G26: -O2 -mcpu=cortex-a76+crypto -mtune=cortex-a76 | H26: =D26&E26&F26&G26 -> -b 64-Fa alg -O2 -mcpu=cortex-a76+crypto -mtune=cortex-a76 | O26: 872986
A27: 26 | B27: cpu-tune-clean-flagsearch-flags | C27: -D c -DWALL | D27: -b 64 | F27: -Fa alg | G27: -O2 -mtune=native | H27: =D27&E27&F27&G27 -> -b 64-Fa alg -O2 -mtune=native | O27: 877668
... A29: 28 | B29: noarch-flags | C29: -D c -DWALL | D29: -b 64 | F29: -Fa alg | G29: -O2 -mtune=native | H29: =D29&E29&F29&G29 -> -b 64-Fa alg -O2 -mtune=native | O29: 877641
A35: Build no. | B35: Build name | C35: Main ATLAS flags | D35: ATLAS flags | E35: GCC flags | F35: Performance of the build [GFLOP/s]
A36: 1 | B36: atlarch | C36: -b 64-A ARM64xgene1 | D36: -A ARM64xgene1 | E36: N/A | F36: 127.786
A37: 2 | B37: atlarch-native | C37: -b 64-A ARM64xgene1-Fa alg-march=native -mtune=native -mcpu=native | D37: -A ARM64xgene1 | E37: -march=native -mtune=native -mcpu=native | F37: 130.522
A38: 3 | B38: arch-native | C38: -b 64-Fa alg-march=native -mtune=native -mcpu=native | D38: N/A | E38: -march=native -mtune=native -mcpu=native | F38: 129.18
A39: 4 | B39: all-spec | C39: -b 64-Fa alg-march=armv8.2-a+crypto+fp16+rcpc+dotprod -mtune=cortex-a76 -mcpu=cortex-a76+crypto | D39: N/A | E39: -march=armv8.2-a+crypto+fp16+rcpc+dotprod -mtune=cortex-a76 -mcpu=cortex-a76+crypto | F39: 102.922
A40: 5 | B40: atlarch-all-spec | C40: -b 64-A ARM64xgene1-Fa alg-march=armv8.2-a+crypto+fp16+rcpc+dotprod -mtune=cortex-a76 -mcpu=cortex-a76+crypto | D40: -A ARM64xgene1 | E40: -march=armv8.2-a+crypto+fp16+rcpc+dotprod -mtune=cortex-a76 -mcpu=cortex-a76+crypto | F40: 130.668
A41: 6 | B41: cpu | C41: -b 64-Fa alg-mcpu=cortex-a76+crypto | D41: N/A | E41: -mcpu=cortex-a76+crypto | F41: 129.464
A42: 7 | B42: cpu-crc | C42: -b 64-Fa alg-mcpu=cortex-a76+crc+crypto | D42: N/A | E42: -mcpu=cortex-a76+crc+crypto | F42: 129.13
A43: 8 | B43: cpu-tune | C43: -b 64-Fa alg-mcpu=cortex-a76+crypto -mtune=cortex-a76 | D43: N/A | E43: -mcpu=cortex-a76+crypto -mtune=cortex-a76 | F43: 129.36
A44: 9 | B44: cpu-tune-abi | C44: -b 64-Fa alg-mcpu=cortex-a76+crypto -mtune=cortex-a76 -mabi=lp64 | D44: N/A | E44: -mcpu=cortex-a76+crypto -mtune=cortex-a76 -mabi=lp64 | F44: 129.062
A45: 10 | B45: atlarch-cpu | C45: -b 64-A ARM64xgene1-Fa alg-mcpu=cortex-a76+crypto | D45: -A ARM64xgene1 | E45: -mcpu=cortex-a76+crypto | F45: 104.594
A46: 11 | B46: atlarch-cpu-tune | C46: -b 64-A ARM64xgene1-Fa alg-mcpu=cortex-a76+crypto -mtune=cortex-a76 | D46: -A ARM64xgene1 | E46: -mcpu=cortex-a76+crypto -mtune=cortex-a76 | F46: 130.228
...

Sheet Arch flags GFLOPs
C1: ATLAS build | D1: ATLAS config flags | E1: gcc flags
A2: 1 | B2: atlarch | C2: -D c -DWALL -b 64 -A ARM64xgene1 | D2: -A ARM64xgene1 | E2: -O2
A3: 2 | B3: atlarch-native | C3: -D c -DWALL -b 64 -A ARM64xgene1 -Fa alg "-march=native -mtune=native -mcpu=native" | D3: -Si archdef 1 | E3: -march=native
A4: 3 | B4: arch-native | C4: -D c -DWALL -b 64 -Fa alg "-march=native -mtune=native -mcpu=native" | D4: -Si archdef 0 | E4: -mtune=native
A5: 4 | B5: all-spec | C5: -D c -DWALL -b 64 -Fa alg "-march=armv8.2-a+crypto+fp16+rcpc+dotprod -mtune=cortex-a76 -mcpu=cortex-a76+crypto" | E5: -mcpu=native
A6: 5 | B6: atlarch-all-spec | C6: -D c -DWALL -b 64 -A ARM64xgene1 -Fa alg "-march=armv8.2-a+crypto+fp16+rcpc+dotprod -mtune=cortex-a76 -mcpu=cortex-a76+crypto" | E6: -march=armv8.2-a+crypto+fp16+rcpc+dotprod
A7: 6 | B7: cpu | C7: -D c -DWALL -b 64 -Fa alg "-mcpu=cortex-a76+crypto" | E7: -mtune=cortex-a76
A8: 7 | B8: cpu-crc | C8: -D c -DWALL -b 64 -Fa alg "-mcpu=cortex-a76+crc+crypto" | E8: -mcpu=cortex-A76+crypto
A9: 8 | B9: cpu-tune | C9: -D c -DWALL -b 64 -Fa alg "-mcpu=cortex-a76+crypto -mtune=cortex-a76" | E9: -mabi=LP64
A10: 9 | B10: cpu-tune-abi | C10: -D c -DWALL -b 64 -Fa alg "-mcpu=cortex-a76+crypto -mtune=cortex-a76 -mabi=lp64" | E10: -mcpu=cortex-a76+crc+crypto
A11: 10 | B11: atlarch-cpu | C11: -D c -DWALL -b 64 -A ARM64xgene1 -Fa alg "-mcpu=cortex-a76+crypto"
A12: 11 | B12: atlarch-cpu-tune | C12: -D c -DWALL -b 64 -A ARM64xgene1 -Fa alg "-mcpu=cortex-a76+crypto -mtune=cortex-a76"
A13: 12 | B13: cpu-tune-clean-flagsearch | C13: -D c -DWALL -b 64 -Fa alg "-mcpu=cortex-a76+crypto -mtune=cortex-a76"
A14: 13 | B14: generic | C14: -D c -DWALL -Si archdef 1
A15: 14 | B15: noarch | C15: -D c -DWALL -Si archdef 0
A16: 15 | B16: atlarch-flags | C16: -D c -DWALL -b 64 -Fa alg "-O2 -pipe"
A17: 16 | B17: atlarch-native-flags | C17: -D c -DWALL -b 64 -Fa alg "-O2 -march=native -mtune=native -mcpu=native"
A18: 17 | B18: arch-native-flags | C18: -D c -DWALL -b 64 -Fa alg "-O2 -march=native -mtune=native -mcpu=native"
A19: 18 | B19: all-spec-flags | C19: -D c -DWALL -b 64 -Fa alg "-O2 -march=armv8.2-a+crypto+fp16+rcpc+dotprod -mtune=cortex-a76 -mcpu=cortex-a76+crypto"
A20: 19 | B20: atlarch-all-spec-flags | C20: -D c -DWALL -b 64 -Fa alg "-O2 -march=armv8.2-a+crypto+fp16+rcpc+dotprod -mtune=cortex-a76 -mcpu=cortex-a76+crypto"
A21: 20 | B21: cpu-flags | C21: -D c -DWALL -b 64 -Fa alg "-O2 -mcpu=cortex-a76+crypto"
A22: 21 | B22: cpu-crc-flags | C22: -D c -DWALL -b 64 -Fa alg "-O2 -mcpu=cortex-a76+crc+crypto"
... A29: 28 | B29: noarch-flags | C29: -D c -DWALL -b 64 -Fa alg "-O2 -pipe -mtune=native"

Sheet 4 nodes, builds, RAW
A1: Max avg. GFLOPS (and params): | B1: =INDEX(A:A,MATCH(MAX($BE:$BE),$BE:$BE,0)) -> atlarch-all-spec | F1: =MAX(X:X) -> 130.668 | G1: =INDEX(D:D,MATCH(MAX($BE:$BE),$BE:$BE,0)) -> 52000 | H1: =INDEX(E:E,MATCH(MAX($BE:$BE),$BE:$BE,0)) -> 160 | I1: =INDEX(F:F,MATCH(MAX($BE:$BE),$BE:$BE,0)) -> 2 | J1: =INDEX(G:G,MATCH(MAX($BE:$BE),$BE:$BE,0)) -> 8 | L1: ATLAS | X1: Average GFLOPs | AH1: Max avg. GFLOPS (and params): | AI1: =INDEX(AH:AH,MATCH(MAX($BE:$BE),$BE:$BE,0)) -> cpu-crc-flags | AM1: =MAX(BE:BE) -> 100.762 | AN1: =INDEX(AK:AK,MATCH(MAX($BE:$BE),$BE:$BE,0)) -> 26080 | AO1: =INDEX(AL:AL,MATCH(MAX($BE:$BE),$BE:$BE,0)) -> 160 | AP1: =INDEX(AM:AM,MATCH(MAX($BE:$BE),$BE:$BE,0)) -> 2 | AQ1: =INDEX(AN:AN,MATCH(MAX($BE:$BE),$BE:$BE,0)) -> 8 | AS1: ATLAS (small problem size - by mistake) | BE1: Average GFLOPs
A2: MAX GFLOPS: | D2: =MAX(I4:I686) -> 130.85 | L2: raspi31 throttling time [1/100s] | O2: raspi32 throttling time [1/100s] | R2: raspi33 throttling time [1/100s] | U2: raspi34 throttling time [1/100s] | AH2: MAX GFLOPS: | AK2: =MAX(AP4:AP686) -> 100.91 | AS2: raspi31 throttling time [1/100s] | AV2: raspi32 throttling time [1/100s] | AY2: raspi33 throttling time [1/100s] | BB2: raspi34 throttling time [1/100s]
A3: Build | B3: RUN | D3: N | E3: NB | F3: P | G3: Q | H3: Time | I3: GFLOPS | J3: Date | K3: Time | L3: 2100MHz | M3: 2200MHz | N3: 2300MHz | O3: 2100MHz | P3: 2200MHz | Q3: 2300MHz | R3: 2100MHz | S3: 2200MHz | T3: 2300MHz | U3: 2100MHz | V3: 2200MHz | W3: 2300MHz | AH3: Build | AI3: RUN | AK3: N | AL3: NB | AM3: P | AN3: Q | AO3: Time | AP3: GFLOPS | AQ3: Date | AR3: Time | AS3: 2100MHz | AT3: 2200MHz | AU3: 2300MHz | AV3: 2100MHz | AW3: 2200MHz | AX3: 2300MHz | AY3: 2100MHz | AZ3: 2200MHz | BA3: 2300MHz | BB3: 2100MHz | BC3: 2200MHz | BD3: 2300MHz
A4: atlarch-all-spec | B4: 0 | C4: WR00L2L2 | D4: 52000 | E4: 160 | F4: 2 | G4: 8 | H4: 716.86 | I4: 130.77 | J4: 45545 | K4: 0.068726852 | L4: 0 | M4: 0 | N4: 0 | O4: 0 | P4: 0 | Q4: 0 | R4: 0 | S4: 0 | T4: 0 | U4: 0 | V4: 0 | W4: 0 | X4: =AVERAGE(I4:I8) -> 130.668 | Z4: {=_xlfn.CHOOSECOLS(_xlfn._xlws.FILTER(A4:X500,B4:B500=0),1,8,24)} -> atlarch-all-spec | AA4: 716.86 | AB4: 130.668 | AC4: =IF(VLOOKUP($Z4,'ATLAS builds'!$B$2:$G$50,4,FALSE)=0,"",IFERROR(VLOOKUP($Z4,'ATLAS builds'!$B$2:$G$50,4,FALSE),"")) -> -A ARM64xgene1 | AD4: =IF(VLOOKUP($Z4,'ATLAS builds'!$B$2:$G$50,6,FALSE)=0,"",IFERROR(VLOOKUP($Z4,'ATLAS builds'!$B$2:$G$50,6,FALSE),"")) -> -march=armv8.2-a+crypto+fp16+rcpc+dotprod -mtune=cortex-a76 -mcpu=cortex-a76+crypto | AH4: cpu-crc-flags | AI4: 0 | AJ4: WR00L2L2 | AK4: 26080 | AL4: 160 | AM4: 2 | AN4: 8 | AO4: 117.2 | AP4: 100.91 | AQ4: 45544 | AR4: 0.64509259 | AS4: 0 | AT4: 0 | AU4: 0 | AV4: 0 | AW4: 0 | AX4: 0 | AY4: 0 | AZ4: 0 | BA4: 0 | BB4: 0 | BC4: 0 | BD4: 0 | BE4: =AVERAGE(AP4:AP8) -> 100.762 | BF4: =BE4 -> 100.762
A5: atlarch-all-spec | B5: 1 | C5: WR00L2L2 | D5: 52000 | E5: 160 | F5: 2 | G5: 8 | H5: 719.98 | I5: 130.2 | J5: 45545 | K5: 0.077731481 | L5: 0 | M5: 0 | N5: 0 | O5: 0 | P5: 0 | Q5: 0 | R5: 0 | S5: 0 | T5: 0 | U5: 0 | V5: 0 | W5: 0 | X5: =X4 -> 130.668 | Z5: atlarch-native | AA5: 718.56 | AB5: 130.522 | AC5: =IF(VLOOKUP(Z5,'ATLAS builds'!$B$2:$G$50,4,FALSE)=0,"",IFERROR(VLOOKUP(Z5,'ATLAS builds'!$B$2:$G$50,4,FALSE),"")) -> -A ARM64xgene1 | AD5: =IF(VLOOKUP($Z5,'ATLAS builds'!$B$2:$G$50,6,FALSE)=0,"",IFERROR(VLOOKUP($Z5,'ATLAS builds'!$B$2:$G$50,6,FALSE),"")) -> -march=native -mtune=native -mcpu=native | AH5: cpu-crc-flags | AI5: 1 | AJ5: WR00L2L2 | AK5: 26080 | AL5: 160 | AM5: 2 | AN5: 8 | AO5: 117.52 | AP5: 100.63 | AQ5: 45544 | AR5: 0.64652778 | AS5: 0 | AT5: 0 | AU5: 0 | AV5: 0 | AW5: 0 | AX5: 0 | AY5: 0 | AZ5: 0 | BA5: 0 | BB5: 0 | BC5: 0 | BD5: 0 | BF5: =BE4 -> 100.762
A6: atlarch-all-spec | B6: 2 | C6: WR00L2L2 | D6: 52000 | E6: 160 | F6: 2 | G6: 8 | H6: 717.22 | I6: 130.7 | J6: 45545 | K6: 0.086712963 | L6: 0 | M6: 0 | N6: 0 | O6: 0 | P6: 0 | Q6: 0 | R6: 0 | S6: 0 | T6: 0 | U6: 0 | V6: 0 | W6: 0 | X6: =X5 -> 130.668 | Z6: atlarch-cpu-tune | AA6: 720.87 | AB6: 130.228 | AC6: =IF(VLOOKUP(Z6,'ATLAS builds'!$B$2:$G$50,4,FALSE)=0,"",IFERROR(VLOOKUP(Z6,'ATLAS builds'!$B$2:$G$50,4,FALSE),"")) -> -A ARM64xgene1 | AD6: =IF(VLOOKUP($Z6,'ATLAS builds'!$B$2:$G$50,6,FALSE)=0,"",IFERROR(VLOOKUP($Z6,'ATLAS builds'!$B$2:$G$50,6,FALSE),"")) -> -mcpu=cortex-a76+crypto -mtune=cortex-a76 | AH6: cpu-crc-flags | AI6: 2 | AJ6: WR00L2L2 | AK6: 26080 | AL6: 160 | AM6: 2 | AN6: 8 | AO6: 117.22 | AP6: 100.9 | AQ6: 45544 | AR6: 0.64796296 | AS6: 0 | AT6: 0 | AU6: 0 | AV6: 0 | AW6: 0 | AX6: 0 | AY6: 0 | AZ6: 0 | BA6: 0 | BB6: 0 | BC6: 0 | BD6: 0 | BF6: =BE4 -> 100.762
A7: atlarch-all-spec | B7: 3 | C7: WR00L2L2 | D7: 52000 | E7: 160 | F7: 2 | G7: 8 | H7: 716.43 | I7: 130.85 | J7: 45545 | K7: 0.095671296 | L7: 0 | M7: 0 | N7: 0 | O7: 0 | P7: 0 | Q7: 0 | R7: 0 | S7: 0 | T7: 0 | U7: 0 | V7: 0 | W7: 0 | X7: =X6 -> 130.668 | Z7: atlarch-cpu-tune-flags | AA7: 718.53 | AB7: 130.084 | AC7: =IF(VLOOKUP(Z7,'ATLAS builds'!$B$2:$G$50,4,FALSE)=0,"",IFERROR(VLOOKUP(Z7,'ATLAS builds'!$B$2:$G$50,4,FALSE),"")) | AD7: =IF(VLOOKUP($Z7,'ATLAS builds'!$B$2:$G$50,6,FALSE)=0,"",IFERROR(VLOOKUP($Z7,'ATLAS builds'!$B$2:$G$50,6,FALSE),"")) -> -O2 -mcpu=cortex-a76+crypto -mtune=cortex-a76 | AH7: cpu-crc-flags | AI7: 3 | AJ7: WR00L2L2 | AK7: 26080 | AL7: 160 | AM7: 2 | AN7: 8 | AO7: 117.47 | AP7: 100.68 | AQ7: 45544 | AR7: 0.64939815 | AS7: 0 | AT7: 0 | AU7: 0 | AV7: 0 | AW7: 0 | AX7: 0 | AY7: 0 | AZ7: 0 | BA7: 0 | BB7: 0 | BC7: 0 | BD7: 0 | BF7: =BE4 -> 100.762
A8: atlarch-all-spec | B8: 4 | C8: WR00L2L2 | D8: 52000 | E8: 160 | F8: 2 | G8: 8 | H8: 716.57 | I8: 130.82 | J8: 45545 | K8: 0.1046412 | L8: 0 | M8: 0 | N8: 0 | O8: 0 | P8: 0 | Q8: 0 | R8: 0 | S8: 0 | T8: 0 | U8: 0 | V8: 0 | W8: 0 | X8: =X7 -> 130.668 | Z8: cpu-flags | AA8: 722.32 | AB8: 129.91 | AC8: =IF(VLOOKUP(Z8,'ATLAS builds'!$B$2:$G$50,4,FALSE)=0,"",IFERROR(VLOOKUP(Z8,'ATLAS builds'!$B$2:$G$50,4,FALSE),"")) | AD8: =IF(VLOOKUP($Z8,'ATLAS builds'!$B$2:$G$50,6,FALSE)=0,"",IFERROR(VLOOKUP($Z8,'ATLAS builds'!$B$2:$G$50,6,FALSE),"")) -> -O2 -mcpu=cortex-a76+crypto | AH8: cpu-crc-flags | AI8: 4 | AJ8: WR00L2L2 | AK8: 26080 | AL8: 160 | AM8: 2 | AN8: 8 | AO8: 117.46 | AP8: 100.69 | AQ8: 45544 | AR8: 0.65083333 | AS8: 0 | AT8: 0 | AU8: 0 | AV8: 0 | AW8: 0 | AX8: 0 | AY8: 0 | AZ8: 0 | BA8: 0 | BB8: 0 | BC8: 0 | BD8: 0 | BF8: =BE4 -> 100.762
A9: atlarch-native | B9: 0 | C9: WR00L2L2 | D9: 52000 | E9: 160 | F9: 2 | G9: 8 | H9: 718.56 | I9: 130.46 | J9: 45544 | K9: 0.92234954 | L9: 0 | M9: 0 | N9: 0 | O9: 0 | P9: 0 | Q9: 0 | R9: 0 | S9: 0 | T9: 0 | U9: 0 | V9: 0 | W9: 0 | X9: =AVERAGE(I9:I13) -> 130.522 | Z9: generic-flags | AA9: 720.67 | AB9: 129.856 | AC9: =IF(VLOOKUP(Z9,'ATLAS builds'!$B$2:$G$50,4,FALSE)=0,"",IFERROR(VLOOKUP(Z9,'ATLAS builds'!$B$2:$G$50,4,FALSE),"")) | AD9: =IF(VLOOKUP($Z9,'ATLAS builds'!$B$2:$G$50,6,FALSE)=0,"",IFERROR(VLOOKUP($Z9,'ATLAS builds'!$B$2:$G$50,6,FALSE),"")) -> -O2 -mtune=native | AH9: atlarch-native-flags | AI9: 0 | AJ9: WR00L2L2 | AK9: 26080 | AL9: 160 | AM9: 2 | AN9: 8 | AO9: 117.27 | AP9: 100.85 | AQ9: 45544 | AR9: 0.60892361 | AS9: 0 | AT9: 0 | AU9: 0 | AV9: 0 | AW9: 0 | AX9: 0 | AY9: 0 | AZ9: 0 | BA9: 0 | BB9: 0 | BC9: 0 | BD9: 0 | BE9: =AVERAGE(AP9:AP13) -> 100.712 | BF9: =BE9 -> 100.712
A10: atlarch-native | B10: 1 | C10: WR00L2L2 | D10: 52000 | E10: 160 | F10: 2 | G10: 8 | H10: 719.18 | I10: 130.35 | J10: 45544 | K10: 0.93134259 | L10: 0 | M10: 0 | N10: 0 | O10: 0 | P10: 0 | Q10: 0 | R10: 0 | S10: 0 | T10: 0 | U10: 0 | V10: 0 | W10: 0 | X10: =X9 -> 130.522 | Z10: atlarch-native-flags | AA10: 723.13 | AB10: 129.854 | AC10: =IF(VLOOKUP(Z10,'ATLAS builds'!$B$2:$G$50,4,FALSE)=0,"",IFERROR(VLOOKUP(Z10,'ATLAS builds'!$B$2:$G$50,4,FALSE),"")) | AD10: =IF(VLOOKUP($Z10,'ATLAS builds'!$B$2:$G$50,6,FALSE)=0,"",IFERROR(VLOOKUP($Z10,'ATLAS builds'!$B$2:$G$50,6,FALSE),"")) -> -O2 -march=native -mtune=native -mcpu=native | AH10: atlarch-native-flags | AI10: 1 | AJ10: WR00L2L2 | AK10: 26080 | AL10: 160 | AM10: 2 | AN10: 8 | AO10: 117.53 | AP10: 100.63 | AQ10: 45544 | AR10: 0.6103588 | AS10: 0 | AT10: 0 | AU10: 0 | AV10: 0 | AW10: 0 | AX10: 0 | AY10: 0 | AZ10: 0 | BA10: 0 | BB10: 0 | BC10: 0 | BD10: 0 | BF10: =BE9 -> 100.712
A11: atlarch-native | B11: 2 | C11: WR00L2L2 | D11: 52000 | E11: 160 | F11: 2 | G11: 8 | H11: 718.21 | I11: 130.52 | J11: 45544 | K11: 0.94033565 | L11: 0 | M11: 0 | N11: 0 | O11: 0 | P11: 0 | Q11: 0 | R11: 0 | S11: 0 | T11: 0 | U11: 0 | V11: 0 | W11: 0 | X11: =X10 -> 130.522 | Z11: atlarch-all-spec-flags | AA11: 721.23 | AB11: 129.832 | AC11: =IF(VLOOKUP(Z11,'ATLAS builds'!$B$2:$G$50,4,FALSE)=0,"",IFERROR(VLOOKUP(Z11,'ATLAS builds'!$B$2:$G$50,4,FALSE),"")) | AD11: =IF(VLOOKUP($Z11,'ATLAS builds'!$B$2:$G$50,6,FALSE)=0,"",IFERROR(VLOOKUP($Z11,'ATLAS builds'!$B$2:$G$50,6,FALSE),"")) -> -O2 -march=armv8.2-a+crypto+fp16+rcpc+dotprod -mtune=cortex-a76 -mcpu=cortex-a76+crypto | AH11: atlarch-native-flags | AI11: 2 | AJ11: WR00L2L2 | AK11: 26080 | AL11: 160 | AM11: 2 | AN11: 8 | AO11: 117.23 | AP11: 100.89 | AQ11: 45544 | AR11: 0.61179398 | AS11: 0 | AT11: 0 | AU11: 0 | AV11: 0 | AW11: 0 | AX11: 0 | AY11: 0 | AZ11: 0 | BA11: 0 | BB11: 0 | BC11: 0 | BD11: 0 | BF11: =BE9 -> 100.712
A12: atlarch-native | B12: 3 | C12: WR00L2L2 | D12: 52000 | E12: 160 | F12: 2 | G12: 8 | H12: 718.03 | I12: 130.56 | J12: 45544 | K12: 0.94931713 | L12: 0 | M12: 0 | N12: 0 | O12: 0 | P12: 0 | Q12: 0 | R12: 0 | S12: 0 | T12: 0 | U12: 0 | V12: 0 | W12: 0 | X12: =X11 -> 130.522 | Z12: cpu-crc-flags | AA12: 722.52 | AB12: 129.822 | AC12: =IF(VLOOKUP(Z12,'ATLAS builds'!$B$2:$G$50,4,FALSE)=0,"",IFERROR(VLOOKUP(Z12,'ATLAS builds'!$B$2:$G$50,4,FALSE),"")) | AD12: =IF(VLOOKUP($Z12,'ATLAS builds'!$B$2:$G$50,6,FALSE)=0,"",IFERROR(VLOOKUP($Z12,'ATLAS builds'!$B$2:$G$50,6,FALSE),"")) -> -O2 -mcpu=cortex-a76+crc+crypto | AH12: atlarch-native-flags | AI12: 3 | AJ12: WR00L2L2 | AK12: 26080 | AL12: 160 | AM12: 2 | AN12: 8 | AO12: 117.69 | AP12: 100.5 | AQ12: 45544 | AR12: 0.61324074 | AS12: 0 | AT12: 0 | AU12: 0 | AV12: 0 | AW12: 0 | AX12: 0 | AY12: 0 | AZ12: 0 | BA12: 0 | BB12: 0 | BC12: 0 | BD12: 0 | BF12: =BE9 -> 100.712
A13: atlarch-native | B13: 4 | C13: WR00L2L2 | D13: 52000 | E13: 160 | F13: 2 | G13: 8 | H13: 717.12 | I13: 130.72 | J13: 45544 | K13: 0.95828704 | L13: 0 | M13: 0 | N13: 0 | O13: 0 | P13: 0 | Q13: 0 | R13: 0 | S13: 0 | T13: 0 | U13: 0 | V13: 0 | W13: 0 | X13: =X12 -> 130.522 | Z13: cpu-tune-abi-flags | AA13: 723.28 | AB13: 129.756 | AC13: =IF(VLOOKUP(Z13,'ATLAS builds'!$B$2:$G$50,4,FALSE)=0,"",IFERROR(VLOOKUP(Z13,'ATLAS builds'!$B$2:$G$50,4,FALSE),"")) | AD13: =IF(VLOOKUP($Z13,'ATLAS builds'!$B$2:$G$50,6,FALSE)=0,"",IFERROR(VLOOKUP($Z13,'ATLAS builds'!$B$2:$G$50,6,FALSE),"")) -> -O2 -mcpu=cortex-a76+crypto -mtune=cortex-a76 -mabi=lp64 | AH13: atlarch-native-flags | AI13: 4 | AJ13: WR00L2L2 | AK13: 26080 | AL13: 160 | AM13: 2 | AN13: 8 | AO13: 117.45 | AP13: 100.69 | AQ13: 45544 | AR13: 0.61467593 | AS13: 0 | AT13: 0 | AU13: 0 | AV13: 0 | AW13: 0 | AX13: 0 | AY13: 0 | AZ13: 0 | BA13: 0 | BB13: 0 | BC13: 0 | BD13: 0 | BF13: =BE9 -> 100.712
A14: atlarch-cpu-tune | B14: 0 | C14: WR00L2L2 | D14: 52000 | E14: 160 | F14: 2 | G14: 8 | H14: 720.87 | I14: 130.04 | J14: 45545 | K14: 0.35030093 | L14: 0 | M14: 0 | N14: 0 | O14: 0 | P14: 0 | Q14: 0 | R14: 0 | S14: 0 | T14: 0 | U14: 0 | V14: 0 | W14: 0 | X14: =AVERAGE(I14:I18) -> 130.228 | Z14: noarch-flags | AA14: 721.94 | AB14: 129.748 | AC14: =IF(VLOOKUP(Z14,'ATLAS builds'!$B$2:$G$50,4,FALSE)=0,"",IFERROR(VLOOKUP(Z14,'ATLAS builds'!$B$2:$G$50,4,FALSE),"")) | AD14: =IF(VLOOKUP($Z14,'ATLAS builds'!$B$2:$G$50,6,FALSE)=0,"",IFERROR(VLOOKUP($Z14,'ATLAS builds'!$B$2:$G$50,6,FALSE),"")) -> -O2 -mtune=native | AH14: cpu-flags | AI14: 0 | AJ14: WR00L2L2 | AK14: 26080 | AL14: 160 | AM14: 2 | AN14: 8 | AO14: 117.91 | AP14: 100.3 | AQ14: 45544 | AR14: 0.63790509 | AS14: 0 | AT14: 0 | AU14: 0 | AV14: 0 | AW14: 0 | AX14: 0 | AY14: 0 | AZ14: 0 | BA14: 0 | BB14: 0 | BC14: 0 | BD14: 0 | BE14: =AVERAGE(AP14:AP18) -> 100.538 | BF14: =BE14 -> 100.538
A15: atlarch-cpu-tune | B15: 1 | C15: WR00L2L2 | D15: 52000 | E15: 160 | F15: 2 | G15: 8 | H15: 717.68 | I15: 130.62 | J15: 45545 | K15: 0.35928241 | L15: 0 | M15: 0 | N15: 0 | O15: 0 | P15: 0 | Q15: 0 | R15: 0 | S15: 0 | T15: 0 | U15: 0 | V15: 0 | W15: 0 | X15: =X14 -> 130.228 | Z15: all-spec-flags | AA15: 720.69 | AB15: 129.732 | AC15: =IF(VLOOKUP(Z15,'ATLAS builds'!$B$2:$G$50,4,FALSE)=0,"",IFERROR(VLOOKUP(Z15,'ATLAS builds'!$B$2:$G$50,4,FALSE),"")) | AD15: =IF(VLOOKUP($Z15,'ATLAS builds'!$B$2:$G$50,6,FALSE)=0,"",IFERROR(VLOOKUP($Z15,'ATLAS builds'!$B$2:$G$50,6,FALSE),"")) -> -O2 -march=armv8.2-a+crypto+fp16+rcpc+dotprod -mtune=cortex-a76 -mcpu=cortex-a76+crypto | AH15: cpu-flags | AI15: 1 | AJ15: WR00L2L2 | AK15: 26080 | AL15: 160 | AM15: 2 | AN15: 8 | AO15: 117.35 | AP15: 100.79 | AQ15: 45544 | AR15: 0.63934028 | AS15: 0 | AT15: 0 | AU15: 0 | AV15: 0 | AW15: 0 | AX15: 0 | AY15: 0 | AZ15: 0 | BA15: 0 | BB15: 0 | BC15: 0 | BD15: 0 | BF15: =BE14 -> 100.538
A16: atlarch-cpu-tune | B16: 2 | C16: WR00L2L2 | D16: 52000 | E16: 160 | F16: 2 | G16: 8 | H16: 720.04 | I16: 130.19 | J16: 45545 | K16: 0.36828704 | L16: 0 | M16: 0 | N16: 0 | O16: 0 | P16: 0 | Q16: 0 | R16: 0 | S16: 0 | T16: 0 | U16: 0 | V16: 0 | W16: 0 | X16: =X15 -> 130.228 | Z16: atlarch-cpu-flags | AA16: 721.99 | AB16: 129.698 | AC16: =IF(VLOOKUP(Z16,'ATLAS builds'!$B$2:$G$50,4,FALSE)=0,"",IFERROR(VLOOKUP(Z16,'ATLAS builds'!$B$2:$G$50,4,FALSE),"")) | AD16: =IF(VLOOKUP($Z16,'ATLAS builds'!$B$2:$G$50,6,FALSE)=0,"",IFERROR(VLOOKUP($Z16,'ATLAS builds'!$B$2:$G$50,6,FALSE),"")) -> -O2 -mcpu=cortex-a76+crypto | AH16: cpu-flags | AI16: 2 | AJ16: WR00L2L2 | AK16: 26080 | AL16: 160 | AM16: 2 | AN16: 8 | AO16: 117.37 | AP16: 100.77 | AQ16: 45544 | AR16: 0.64077546 | AS16: 0 | AT16: 0 | AU16: 0 | AV16: 0 | AW16: 0 | AX16: 0 | AY16: 0 | AZ16: 0 | BA16: 0 | BB16: 0 | BC16: 0 | BD16: 0 | BF16: =BE14 -> 100.538
A17: atlarch-cpu-tune | B17: 3 | C17: WR00L2L2 | D17: 52000 | E17: 160 | F17: 2 | G17: 8 | H17: 720.27 | I17: 130.15 | J17: 45545 | K17: 0.37730324 | L17: 0 | M17: 0 | N17: 0 | O17: 0 | P17: 0 | Q17: 0 | R17: 0 | S17: 0 | T17: 0 | U17: 0 | V17: 0 | W17: 0 | X17: =X16 -> 130.228 | Z17: cpu-tune-clean-flagsearch-flags | AA17: 722.15 | AB17: 129.626 | AC17: =IF(VLOOKUP(Z17,'ATLAS builds'!$B$2:$G$50,4,FALSE)=0,"",IFERROR(VLOOKUP(Z17,'ATLAS builds'!$B$2:$G$50,4,FALSE),"")) | AD17: =IF(VLOOKUP($Z17,'ATLAS builds'!$B$2:$G$50,6,FALSE)=0,"",IFERROR(VLOOKUP($Z17,'ATLAS builds'!$B$2:$G$50,6,FALSE),"")) -> -O2 -mtune=native | AH17: cpu-flags | AI17: 3 | AJ17: WR00L2L2 | AK17: 26080 | AL17: 160 | AM17: 2 | AN17: 8 | AO17: 118.01 | AP17: 100.22 | AQ17: 45544 | AR17: 0.64222222 | AS17: 0 | AT17: 0 | AU17: 0 | AV17: 0 | AW17: 0 | AX17: 0 | AY17: 0 | AZ17: 0 | BA17: 0 | BB17: 0 | BC17: 0 | BD17: 0 | BF17: =BE14 -> 100.538
A18: atlarch-cpu-tune | B18: 4 | C18: WR00L2L2 | D18: 52000 | E18: 160 | F18: 2 | G18: 8 | H18: 720.3 | I18: 130.14 | J18: 45545 | K18: 0.38630787 | L18: 0 | M18: 0 | N18: 0 | O18: 0 | P18: 0 | Q18: 0 | R18: 0 | S18: 0 | T18: 0 | U18: 0 | V18: 0 | W18: 0 | X18: =X17 -> 130.228 | Z18: cpu | AA18: 724.23 | AB18: 129.464 | AC18: =IF(VLOOKUP(Z18,'ATLAS builds'!$B$2:$G$50,4,FALSE)=0,"",IFERROR(VLOOKUP(Z18,'ATLAS builds'!$B$2:$G$50,4,FALSE),"")) | AD18: =IF(VLOOKUP($Z18,'ATLAS builds'!$B$2:$G$50,6,FALSE)=0,"",IFERROR(VLOOKUP($Z18,'ATLAS builds'!$B$2:$G$50,6,FALSE),"")) -> -mcpu=cortex-a76+crypto | AH18: cpu-flags | AI18: 4 | AJ18: WR00L2L2 | AK18: 26080 | AL18: 160 | AM18: 2 | AN18: 8 | AO18: 117.55 | AP18: 100.61 | AQ18: 45544 | AR18: 0.64365741 | AS18: 0 | AT18: 0 | AU18: 0 | AV18: 0 | AW18: 0 | AX18: 0 | AY18: 0 | AZ18: 0 | BA18: 0 | BB18: 0 | BC18: 0 | BD18: 0 | BF18: =BE14 -> 100.538
A19: atlarch-cpu-tune-flags | B19: 0 | C19: WR00L2L2 | D19: 52000 | E19: 160 | F19: 2 | G19: 8 | H19: 718.53 | I19: 130.47 | J19: 45545 | K19: 0.99353009 | L19: 0 | M19: 0 | N19: 0 | O19: 0 | P19: 0 | Q19: 0 | R19: 0 | S19: 0 | T19: 0 | U19: 0 | V19: 0 | W19: 0 | X19: =AVERAGE(I19:I23) -> 130.084 | Z19: atlarch-flags | AA19: 724.79 | AB19: 129.378 | AC19: =IF(VLOOKUP(Z19,'ATLAS builds'!$B$2:$G$50,4,FALSE)=0,"",IFERROR(VLOOKUP(Z19,'ATLAS builds'!$B$2:$G$50,4,FALSE),"")) | AD19: =IF(VLOOKUP($Z19,'ATLAS builds'!$B$2:$G$50,6,FALSE)=0,"",IFERROR(VLOOKUP($Z19,'ATLAS builds'!$B$2:$G$50,6,FALSE),"")) -> -O2 | AH19: atlarch-cpu-tune-flags | AI19: 0 | AJ19: WR00L2L2 | AK19: 26080 | AL19: 160 | AM19: 2 | AN19: 8 | AO19: 117.83 | AP19: 100.38 | AQ19: 45544 | AR19: 0.67605324 | AS19: 0 | AT19: 0 | AU19: 0 | AV19: 0 | AW19: 0 | AX19: 0 | AY19: 0 | AZ19: 0 | BA19: 0 | BB19: 0 | BC19: 0 | BD19: 0 | BE19: =AVERAGE(AP19:AP23) -> 100.466 | BF19: =BE19 -> 100.466
A20: atlarch-cpu-tune-flags | B20: 1 | C20: WR00L2L2 | D20: 52000 | E20: 160 | F20: 2 | G20: 8 | H20: 720.9 | I20: 130.04 | J20: 45546 | K20: 0.0020949074 | L20: 0 | M20: 0 | N20: 0 | O20: 0 | P20: 0 | Q20: 0 | R20: 0 | S20: 0 | T20: 0 | U20: 0 | V20: 0 | W20: 0 | X20: =X19 -> 130.084 | Z20: cpu-tune | AA20: 724.37 | AB20: 129.36 | AC20: =IF(VLOOKUP(Z20,'ATLAS builds'!$B$2:$G$50,4,FALSE)=0,"",IFERROR(VLOOKUP(Z20,'ATLAS builds'!$B$2:$G$50,4,FALSE),"")) | AD20: =IF(VLOOKUP($Z20,'ATLAS builds'!$B$2:$G$50,6,FALSE)=0,"",IFERROR(VLOOKUP($Z20,'ATLAS builds'!$B$2:$G$50,6,FALSE),"")) -> -mcpu=cortex-a76+crypto -mtune=cortex-a76 | AH20: atlarch-cpu-tune-flags | AI20: 1 | AJ20: WR00L2L2 | AK20: 26080 | AL20: 160 | AM20: 2 | AN20: 8 | AO20: 117.65 | AP20: 100.53 | AQ20: 45544 | AR20: 0.67748843 | AS20: 0 | AT20: 0 | AU20: 0 | AV20: 0 | AW20: 0 | AX20: 0 | AY20: 0 | AZ20: 0 | BA20: 0 | BB20: 0 | BC20: 0 | BD20: 0 | BF20: =BE19 -> 100.466
A21: atlarch-cpu-tune-flags | B21: 2 | C21: WR00L2L2 | D21: 52000 | E21: 160 | F21: 2 | G21: 8 | H21: 719.86 | I21: 130.22 | J21: 45546 | K21: 0.010648148 | L21: 0 | M21: 0 | N21: 0 | O21: 0 | P21: 0 | Q21: 0 | R21: 0 | S21: 0 | T21: 0 | U21: 0 | V21: 0 | W21: 0 | X21: =X20 -> 130.084 | Z21: arch-native | AA21: 725.29 | AB21: 129.18 | AC21: =IF(VLOOKUP(Z21,'ATLAS builds'!$B$2:$G$50,4,FALSE)=0,"",IFERROR(VLOOKUP(Z21,'ATLAS builds'!$B$2:$G$50,4,FALSE),"")) | AD21: =IF(VLOOKUP($Z21,'ATLAS builds'!$B$2:$G$50,6,FALSE)=0,"",IFERROR(VLOOKUP($Z21,'ATLAS builds'!$B$2:$G$50,6,FALSE),"")) -> -march=native -mtune=native -mcpu=native | AH21: atlarch-cpu-tune-flags | AI21: 2 | AJ21: WR00L2L2 | AK21: 26080 | AL21: 160 | AM21: 2 | AN21: 8 | AO21: 118.01 | AP21: 100.22 | AQ21: 45544 | AR21: 0.67893519 | AS21: 0 | AT21: 0 | AU21: 0 | AV21: 0 | AW21: 0 | AX21: 0 | AY21: 0 | AZ21: 0 | BA21: 0 | BB21: 0 | BC21: 0 | BD21: 0 | BF21: =BE19 -> 100.466
A22: atlarch-cpu-tune-flags | B22: 3 | C22: WR00L2L2 | D22: 52000 | E22: 160 | F22: 2 | G22: 8 | H22: 721.98 | I22: 129.84 | J22: 45546 | K22: 0.019224537 | L22: 0 | M22: 0 | N22: 0 | O22: 0 | P22: 0 | Q22: 0 | R22: 0 | S22: 0 | T22: 0 | U22: 0 | V22: 0 | W22: 0 | X22: =X21 -> 130.084 | Z22: cpu-crc | AA22: 726.07 | AB22: 129.13 | AC22: =IF(VLOOKUP(Z22,'ATLAS builds'!$B$2:$G$50,4,FALSE)=0,"",IFERROR(VLOOKUP(Z22,'ATLAS builds'!$B$2:$G$50,4,FALSE),"")) | AD22: =IF(VLOOKUP($Z22,'ATLAS builds'!$B$2:$G$50,6,FALSE)=0,"",IFERROR(VLOOKUP($Z22,'ATLAS builds'!$B$2:$G$50,6,FALSE),"")) -> -mcpu=cortex-a76+crc+crypto | AH22: atlarch-cpu-tune-flags | AI22: 3 | AJ22: WR00L2L2 | AK22: 26080 | AL22: 160 | AM22: 2 | AN22: 8 | AO22: 117.24 | AP22: 100.88 | AQ22: 45544 | AR22: 0.68037037 | AS22: 0 | AT22: 0 | AU22: 0 | AV22: 0 | AW22: 0 | AX22: 0 | AY22: 0 | AZ22: 0 | BA22: 0 | BB22: 0 | BC22: 0 | BD22: 0 | BF22: =BE19 -> 100.466
A23: atlarch-cpu-tune-flags | B23: 4 | C23: WR00L2L2 | D23: 52000 | E23: 160 | F23: 2 | G23: 8 | H23: 721.93 | I23: 129.85 | J23: 45546 | K23: 0.027800926 | L23: 0 | M23: 0 | N23: 0 | O23: 0 | P23: 0 | Q23: 0 | R23: 0 | S23: 0 | T23: 0 | U23: 0 | V23: 0 | W23: 0 | X23: =X22 -> 130.084 | Z23: cpu-tune-abi | AA23: 726.53 | AB23: 129.062 | AC23: =IF(VLOOKUP(Z23,'ATLAS builds'!$B$2:$G$50,4,FALSE)=0,"",IFERROR(VLOOKUP(Z23,'ATLAS builds'!$B$2:$G$50,4,FALSE),"")) | AD23: =IF(VLOOKUP($Z23,'ATLAS builds'!$B$2:$G$50,6,FALSE)=0,"",IFERROR(VLOOKUP($Z23,'ATLAS builds'!$B$2:$G$50,6,FALSE),"")) -> -mcpu=cortex-a76+crypto -mtune=cortex-a76 -mabi=lp64 | AH23: atlarch-cpu-tune-flags | AI23: 4 | AJ23: WR00L2L2 | AK23: 26080 | AL23: 160 | AM23: 2 | AN23: 8 | AO23: 117.89 | AP23: 100.32 | AQ23: 45544 | AR23: 0.68181713 | AS23: 0 | AT23: 0 | AU23: 0 | AV23: 0 | AW23: 0 | AX23: 0 | AY23: 0 | AZ23: 0 | BA23: 0 | BB23: 0 | BC23: 0 | BD23: 0 | BF23: =BE19 -> 100.466
A24: cpu-flags | B24: 0 | C24: WR00L2L2 | D24: 52000 | E24: 160 | F24: 2 | G24: 8 | H24: 722.32 | I24: 129.78 | J24: 45545 | K24: 0.76826389 | L24: 0 | M24: 0 | N24: 0 | O24: 0 | P24: 0 | Q24: 0 | R24: 0 | S24: 0 | T24: 0 | U24: 0 | V24: 0 | W24: 0 | X24: =AVERAGE(I24:I28) -> 129.91 | Z24: noarch | AA24: 730.11 | AB24: 128.522 | AC24: =IF(VLOOKUP(Z24,'ATLAS builds'!$B$2:$G$50,4,FALSE)=0,"",IFERROR(VLOOKUP(Z24,'ATLAS builds'!$B$2:$G$50,4,FALSE),"")) -> -Si archdef 0 | AD24: =IF(VLOOKUP($Z24,'ATLAS builds'!$B$2:$G$50,6,FALSE)=0,"",IFERROR(VLOOKUP($Z24,'ATLAS builds'!$B$2:$G$50,6,FALSE),"")) | AH24: cpu-tune-abi-flags | AI24: 0 | AJ24: WR00L2L2 | AK24: 26080 | AL24: 160 | AM24: 2 | AN24: 8 | AO24: 117.88 | AP24: 100.33 | AQ24: 45544 | AR24: 0.6616088 | AS24: 0 | AT24: 0 | AU24: 0 | AV24: 0 | AW24: 0 | AX24: 0 | AY24: 0 | AZ24: 0 | BA24: 0 | BB24: 0 | BC24: 0 | BD24: 0 | BE24: =AVERAGE(AP24:AP28) -> 100.3492 | BF24: =BE24 -> 100.3492
A25: cpu-flags | B25: 1 | C25: WR00L2L2 | D25: 52000 | E25: 160 | F25: 2 | G25: 8 | H25: 721.58 | I25: 129.91 | J25: 45545 | K25: 0.7768287 | L25: 0 | M25: 0 | N25: 0 | O25: 0 | P25: 0 | Q25: 0 | R25: 0 | S25: 0 | T25: 0 | U25: 0 | V25: 0 | W25: 0 | X25: =X24 -> 129.91 | Z25: atlarch | AA25: 731.89 | AB25: 127.786 | AC25: =IF(VLOOKUP(Z25,'ATLAS builds'!$B$2:$G$50,4,FALSE)=0,"",IFERROR(VLOOKUP(Z25,'ATLAS builds'!$B$2:$G$50,4,FALSE),"")) -> -A ARM64xgene1 | AD25: =IF(VLOOKUP($Z25,'ATLAS builds'!$B$2:$G$50,6,FALSE)=0,"",IFERROR(VLOOKUP($Z25,'ATLAS builds'!$B$2:$G$50,6,FALSE),"")) | AH25: cpu-tune-abi-flags | AI25: 1 | AJ25: WR00L2L2 | AK25: 26080 | AL25: 160 | AM25: 2 | AN25: 8 | AO25: 118.32 | AP25: 99.956 | AQ25: 45544 | AR25: 0.66305556 | AS25: 0 | AT25: 0 | AU25: 0 | AV25: 0 | AW25: 0 | AX25: 0 | AY25: 0 | AZ25: 0 | BA25: 0 | BB25: 0 | BC25: 0 | BD25: 0 | BF25: =BE24 -> 100.3492
A26: cpu-flags | B26: 2 | C26: WR00L2L2 | D26: 52000 | E26: 160 | F26: 2 | G26: 8 | H26: 721.61 | I26: 129.91 | J26: 45545 | K26: 0.78540509 | L26: 0 | M26: 0 | N26: 0 | O26: 0 | P26: 0 | Q26: 0 | R26: 0 | S26: 0 | T26: 0 | U26: 0 | V26: 0 | W26: 0 | X26: =X25 -> 129.91 | Z26: arch-native-flags | AA26: 734.4 | AB26: 127.784 | AC26: =IF(VLOOKUP(Z26,'ATLAS builds'!$B$2:$G$50,4,FALSE)=0,"",IFERROR(VLOOKUP(Z26,'ATLAS builds'!$B$2:$G$50,4,FALSE),"")) | AD26: =IF(VLOOKUP($Z26,'ATLAS builds'!$B$2:$G$50,6,FALSE)=0,"",IFERROR(VLOOKUP($Z26,'ATLAS builds'!$B$2:$G$50,6,FALSE),"")) -> -O2 -march=native -mtune=native -mcpu=native | AH26: cpu-tune-abi-flags | AI26: 2 | AJ26: WR00L2L2 | AK26: 26080 | AL26: 160 | AM26: 2 | AN26: 8 | AO26: 117.93 | AP26: 100.29 | AQ26: 45544 | AR26: 0.66450231 | AS26: 0 | AT26: 0 | AU26: 0 | AV26: 0 | AW26: 0 | AX26: 0 | AY26: 0 | AZ26: 0 | BA26: 0 | BB26: 0 | BC26: 0 | BD26: 0 | BF26: =BE24 -> 100.3492
A27: cpu-flags | B27: 3 | C27: WR00L2L2 | D27: 52000 | E27: 160 | F27: 2 | G27: 8 | H27: 721.11 | I27: 130 | J27: 45545 | K27: 0.79396991 | L27: 0 | M27: 0 | N27: 0 | O27: 0 | P27: 0 | Q27: 0 | R27: 0 | S27: 0 | T27: 0 | U27: 0 | V27: 0 | W27: 0 | X27: =X26 -> 129.91 | Z27: atlarch-cpu | AA27: 897.67 | AB27: 104.594 | AC27: =IF(VLOOKUP(Z27,'ATLAS builds'!$B$2:$G$50,4,FALSE)=0,"",IFERROR(VLOOKUP(Z27,'ATLAS builds'!$B$2:$G$50,4,FALSE),"")) -> -A ARM64xgene1 | AD27: =IF(VLOOKUP($Z27,'ATLAS builds'!$B$2:$G$50,6,FALSE)=0,"",IFERROR(VLOOKUP($Z27,'ATLAS builds'!$B$2:$G$50,6,FALSE),"")) -> -mcpu=cortex-a76+crypto | AH27: cpu-tune-abi-flags | AI27: 3 | AJ27: WR00L2L2 | AK27: 26080 | AL27: 160 | AM27: 2 | AN27: 8 | AO27: 117.79 | AP27: 100.41 | AQ27: 45544 | AR27: 0.6659375 | AS27: 0 | AT27: 0 | AU27: 0 | AV27: 0 | AW27: 0 | AX27: 0 | AY27: 0 | AZ27: 0 | BA27: 0 | BB27: 0 | BC27: 0 | BD27: 0 | BF27: =BE24 -> 100.3492
A28: cpu-flags | B28: 4 | C28: WR00L2L2 | D28: 52000 | E28: 160 | F28: 2 | G28: 8 | H28: 721.36 | I28: 129.95 | J28: 45545 | K28: 0.80253472 | L28: 0 | M28: 0 | N28: 0 | O28: 0 | P28: 0 | Q28: 0 | R28: 0 | S28: 0 | T28: 0 | U28: 0 | V28: 0 | W28: 0 | X28: =X27 -> 129.91 | Z28: cpu-tune-clean-flagsearch | AA28: 904.45 | AB28: 103.448 | AC28: =IF(VLOOKUP(Z28,'ATLAS builds'!$B$2:$G$50,4,FALSE)=0,"",IFERROR(VLOOKUP(Z28,'ATLAS builds'!$B$2:$G$50,4,FALSE),"")) | AD28: =IF(VLOOKUP($Z28,'ATLAS builds'!$B$2:$G$50,6,FALSE)=0,"",IFERROR(VLOOKUP($Z28,'ATLAS builds'!$B$2:$G$50,6,FALSE),"")) -> -mcpu=cortex-a76+crypto -mtune=cortex-a76 | AH28: cpu-tune-abi-flags | AI28: 4 | AJ28: WR00L2L2 | AK28: 26080 | AL28: 160 | AM28: 2 | AN28: 8 | AO28: 117.37 | AP28: 100.76 | AQ28: 45544 | AR28: 0.66737269 | AS28: 0 | AT28: 0 | AU28: 0 | AV28: 0 | AW28: 0 | AX28: 0 | AY28: 0 | AZ28: 0 | BA28: 0 | BB28: 0 | BC28: 0 | BD28: 0 | BF28: =BE24 -> 100.3492
A29: generic-flags | B29: 0 | C29: WR00L2L2 | D29: 52000 | E29: 160 | F29: 2 | G29: 8 | H29: 720.67 | I29: 130.08 | J29: 45546 | K29: 0.079340278 | L29: 0 | M29: 0 | N29: 0 | O29: 0 | P29: 0 | Q29: 0 | R29: 0 | S29: 0 | T29: 0 | U29: 0 | V29: 0 | W29: 0 | X29: =AVERAGE(I29:I33) -> 129.856 | Z29: generic | AA29: 902.33 | AB29: 103.388 | AC29: =IF(VLOOKUP(Z29,'ATLAS builds'!$B$2:$G$50,4,FALSE)=0,"",IFERROR(VLOOKUP(Z29,'ATLAS builds'!$B$2:$G$50,4,FALSE),"")) -> -Si archdef 1 | AD29: =IF(VLOOKUP($Z29,'ATLAS builds'!$B$2:$G$50,6,FALSE)=0,"",IFERROR(VLOOKUP($Z29,'ATLAS builds'!$B$2:$G$50,6,FALSE),"")) | AH29: generic-flags | AI29: 0 | AJ29: WR00L2L2 | AK29: 26080 | AL29: 160 | AM29: 2 | AN29: 8 | AO29: 117.76 | AP29: 100.43 | AQ29: 45544 | AR29: 0.69050926 | AS29: 0 | AT29: 0 | AU29: 0 | AV29: 0 | AW29: 0 | AX29: 0 | AY29: 0 | AZ29: 0 | BA29: 0 | BB29: 0 | BC29: 0 | BD29: 0 | BE29: =AVERAGE(AP29:AP33) -> 100.2888 | BF29: =BE29 -> 100.2888
A30: generic-flags | B30: 1 | C30: WR00L2L2 | D30: 52000 | E30: 160 | F30: 2 | G30: 8 | H30: 721.75 | I30: 129.88 | J30: 45546 | K30: 0.087916667 | L30: 0 | M30: 0 | N30: 0 | O30: 0 | P30: 0 | Q30: 0 | R30: 0 | S30: 0 | T30: 0 | U30: 0 | V30: 0 | W30: 0 | X30: =X29 -> 129.856 | Z30: cpu-tune-flags | AA30: 911.46 | AB30: 103.114 | AC30: =IF(VLOOKUP(Z30,'ATLAS builds'!$B$2:$G$50,4,FALSE)=0,"",IFERROR(VLOOKUP(Z30,'ATLAS builds'!$B$2:$G$50,4,FALSE),"")) | AD30: =IF(VLOOKUP($Z30,'ATLAS builds'!$B$2:$G$50,6,FALSE)=0,"",IFERROR(VLOOKUP($Z30,'ATLAS builds'!$B$2:$G$50,6,FALSE),"")) -> -O2 -mcpu=cortex-a76+crypto -mtune=cortex-a76 | AH30: generic-flags | AI30: 1 | AJ30: WR00L2L2 | AK30: 26080 | AL30: 160 | AM30: 2 | AN30: 8 | AO30: 117.5 | AP30: 100.65 | AQ30: 45544 | AR30: 0.69195602 | AS30: 0 | AT30: 0 | AU30: 0 | AV30: 0 | AW30: 0 | AX30: 0 | AY30: 0 | AZ30: 0 | BA30: 0 | BB30: 0 | BC30: 0 | BD30: 0 | BF30: =BE29 -> 100.2888
A31: generic-flags | B31: 2 | C31: WR00L2L2 | D31: 52000 | E31: 160 | F31: 2 | G31: 8 | H31: 721.31 | I31: 129.96 | J31: 45546 | K31: 0.096493056 | L31: 0 | M31: 0 | N31: 0 | O31: 0 | P31: 0 | Q31: 0 | R31: 0 | S31: 0 | T31: 0 | U31: 0 | V31: 0 | W31: 0 | X31: =X30 -> 129.856 | Z31: all-spec | AA31: 912.39 | AB31: 102.922 | AC31: =IF(VLOOKUP(Z31,'ATLAS builds'!$B$2:$G$50,4,FALSE)=0,"",IFERROR(VLOOKUP(Z31,'ATLAS builds'!$B$2:$G$50,4,FALSE),"")) | AD31: =IF(VLOOKUP($Z31,'ATLAS builds'!$B$2:$G$50,6,FALSE)=0,"",IFERROR(VLOOKUP($Z31,'ATLAS builds'!$B$2:$G$50,6,FALSE),"")) -> -march=armv8.2-a+crypto+fp16+rcpc+dotprod -mtune=cortex-a76 -mcpu=cortex-a76+crypto | AH31: generic-flags | AI31: 2 | AJ31: WR00L2L2 | AK31: 26080 | AL31: 160 | AM31: 2 | AN31: 8 | AO31: 117.87 | AP31: 100.34 | AQ31: 45544 | AR31: 0.6933912 | AS31: 0 | AT31: 0 | AU31: 0 | AV31: 0 | AW31: 0 | AX31: 0 | AY31: 0 | AZ31: 0 | BA31: 0 | BB31: 0 | BC31: 0 | BD31: 0 | BF31: =BE29 -> 100.2888
A32: generic-flags | B32: 3 | C32: WR00L2L2 | D32: 52000 | E32: 160 | F32: 2 | G32: 8 | H32: 724.32 | I32: 129.42 | J32: 45546 | K32: 0.10510417 | L32: 0 | M32: 0 | N32: 0 | O32: 0 | P32: 0 | Q32: 0 | R32: 0 | S32: 0 | T32: 0 | U32: 0 | V32: 0 | W32: 0 | X32: =X31 -> 129.856 | Z32: 0 | AA32: 0 | AB32: 0 | AH32: generic-flags | AI32: 3 | AJ32: WR00L2L2 | AK32: 26080 | AL32: 160 | AM32: 2 | AN32: 8 | AO32: 118.19 | AP32: 100.07 | AQ32: 45544 | AR32: 0.69483796 | AS32: 0 | AT32: 0 | AU32: 0 | AV32: 0 | AW32: 0 | AX32: 0 | AY32: 0 | AZ32: 0 | BA32: 0 | BB32: 0 | BC32: 0 | BD32: 0 | BF32: =BE29 -> 100.2888
A33: generic-flags | B33: 4 | C33: WR00L2L2 | D33: 52000 | E33: 160 | F33: 2 | G33: 8 | H33: 721.42 | I33: 129.94 | J33: 45546 | K33: 0.11368056 | L33: 0 | M33: 0 | N33: 0 | O33: 0 | P33: 0 | Q33: 0 | R33: 0 | S33: 0 | T33: 0 | U33: 0 | V33: 0 | W33: 0 | X33: =X32 -> 129.856 | Z33: 0 | AA33: 0 | AB33: 0 | AH33: generic-flags | AI33: 4 | AJ33: WR00L2L2 | AK33: 26080 | AL33: 160 | AM33: 2 | AN33: 8 | AO33: 118.32 | AP33: 99.954 | AQ33: 45544 | AR33: 0.69628472 | AS33: 0 | AT33: 0 | AU33: 0 | AV33: 0 | AW33: 0 | AX33: 0 | AY33: 0 | AZ33: 0 | BA33: 0 | BB33: 0 | BC33: 0 | BD33: 0 | BF33: =BE29 -> 100.2888
A34: atlarch-native-flags | B34: 0 | C34: WR00L2L2 | D34: 52000 | E34: 160 | F34: 2 | G34: 8 | H34: 723.13 | I34: 129.63 | J34: 45545 | K34: 0.59597222 | L34: 0 | M34: 0 | N34: 0 | O34: 0 | P34: 0 | Q34: 0 | R34: 0 | S34: 0 | T34: 0 | U34: 0 | V34: 0 | W34: 0 | X34: =AVERAGE(I34:I38) -> 129.854 | Z34: 0 | AA34: 0 | AB34: 0 | AH34: atlarch-all-spec-flags | AI34: 0 | AJ34: WR00L2L2 | AK34: 26080 | AL34: 160 | AM34: 2 | AN34: 8 | AO34: 118.16 | AP34: 100.09 | AQ34: 45544 | AR34: 0.6306713 | AS34: 0 | AT34: 0 | AU34: 0 | AV34: 0 | AW34: 0 | AX34: 0 | AY34: 0 | AZ34: 0 | BA34: 0 | BB34: 0 | BC34: 0 | BD34: 0 | BE34: =AVERAGE(AP34:AP38) -> 100.0586 | BF34: =BE34 -> 100.0586
A35: atlarch-native-flags | B35: 1 | C35: WR00L2L2 | D35: 52000 | E35: 160 | F35: 2 | G35: 8 | H35: 722.34 | I35: 129.78 | J35: 45545 | K35: 0.60454861 | L35: 0 | M35: 0 | N35: 0 | O35: 0 | P35: 0 | Q35: 0 | R35: 0 | S35: 0 | T35: 0 | U35: 0 | V35: 0 | W35: 0 | X35: =X34 -> 129.854 | Z35: 0 | AA35: 0 | AB35: 0 | AH35: atlarch-all-spec-flags | AI35: 1 | AJ35: WR00L2L2 | AK35: 26080 | AL35: 160 | AM35: 2 | AN35: 8 | AO35: 118.12 | AP35: 100.12 | AQ35: 45544 | AR35: 0.63211806 | AS35: 0 | AT35: 0 | AU35: 0 | AV35: 0 | AW35: 0 | AX35: 0 | AY35: 0 | AZ35: 0 | BA35: 0 | BB35: 0 | BC35: 0 | BD35: 0 | BF35: =BE34 -> 100.0586
A36: atlarch-native-flags | B36: 2 | C36: WR00L2L2 | D36: 52000 | E36: 160 | F36: 2 | G36: 8 | H36: 721.93 | I36: 129.85 | J36: 45545 | K36: 0.613125 | L36: 0 | M36: 0 | N36: 0 | O36: 0 | P36: 0 | Q36: 0 | R36: 0 | S36: 0 | T36: 0 | U36: 0 | V36: 0 | W36: 0 | X36: =X35 -> 129.854 | Z36: 0 | AA36: 0 | AB36: 0 | AH36: atlarch-all-spec-flags | AI36: 2 | AJ36: WR00L2L2 | AK36: 26080 | AL36: 160 | AM36: 2 | AN36: 8 | AO36: 118.14 | AP36: 100.1 | AQ36: 45544 | AR36: 0.63356481 | AS36: 0 | AT36: 0 | AU36: 0 | AV36: 0 | AW36: 0 | AX36: 0 | AY36: 0 | AZ36: 0 | BA36: 0 | BB36: 0 | BC36: 0 | BD36: 0 | BF36: =BE34 -> 100.0586
A37: atlarch-native-flags | B37: 3 | C37: WR00L2L2 | D37: 52000 | E37: 160 | F37: 2 | G37: 8 | H37: 720.91 | I37: 130.03 | J37: 45545 | K37: 0.62168981 | L37: 0 | M37: 0 | N37: 0 | O37: 0 | P37: 0 | Q37: 0 | R37: 0 | S37: 0 | T37: 0 | U37: 0 | V37: 0 | W37: 0 | X37: =X36 -> 129.854 | Z37: 0 | AA37: 0 | AB37: 0 | AH37: atlarch-all-spec-flags | AI37: 3 | AJ37: WR00L2L2 | AK37: 26080 | AL37: 160 | AM37: 2 | AN37: 8 | AO37: 118.31 | AP37: 99.963 | AQ37: 45544 | AR37: 0.63501157 | AS37: 0 | AT37: 0 | AU37: 0 | AV37: 0 | AW37: 0 | AX37: 0 | AY37: 0 | AZ37: 0 | BA37: 0 | BB37: 0 | BC37: 0 | BD37: 0 | BF37: =BE34 -> 100.0586
A38: atlarch-native-flags | B38: 4 | C38: WR00L2L2 | D38: 52000 | E38: 160 | F38: 2 | G38: 8 | H38: 721.23 | I38: 129.98 | J38: 45545 | K38: 0.6302662 | L38: 0 | M38: 0 | N38: 0 | O38: 0 | P38: 0 | Q38: 0 | R38: 0 | S38: 0 | T38: 0 | U38: 0 | V38: 0 | W38: 0 | X38: =X37 -> 129.854 | Z38: 0 | AA38: 0 | AB38: 0 | AH38: atlarch-all-spec-flags | AI38: 4 | AJ38: WR00L2L2 | AK38: 26080 | AL38: 160 | AM38: 2 | AN38: 8 | AO38: 118.24 | AP38: 100.02 | AQ38: 45544 | AR38: 0.63645833 | AS38: 0 | AT38: 0 | AU38: 0 | AV38: 0 | AW38: 0 | AX38: 0 | AY38: 0 | AZ38: 0 | BA38: 0 | BB38: 0 | BC38: 0 | BD38: 0 | BF38: =BE34 -> 100.0586
A39: atlarch-all-spec-flags | B39: 0 | C39: WR00L2L2 | D39: 52000 | E39: 160 | F39: 2 | G39: 8 | H39: 721.23 | I39: 129.98 | J39: 45545 | K39: 0.7253588 | L39: 0 | M39: 0 | N39: 0 | O39: 0 | P39: 0 | Q39: 0 | R39: 0 | S39: 0 | T39: 0 | U39: 0 | V39: 0 | W39: 0 | X39: =AVERAGE(I39:I43) -> 129.832 | Z39: 0 | AA39: 0 | AB39: 0 | AH39: atlarch-cpu-flags | AI39: 0 | AJ39: WR00L2L2 | AK39: 26080 | AL39: 160 | AM39: 2 | AN39: 8 | AO39: 118.55 | AP39: 99.764 | AQ39: 45544 | AR39: 0.66883102 | AS39: 0 | AT39: 0 | AU39: 0 | AV39: 0 | AW39: 0 | AX39: 0 | AY39: 0 | AZ39: 0 | BA39: 0 | BB39: 0 | BC39: 0 | BD39: 0 | BE39: =AVERAGE(AP39:AP43) -> 100.0542 | BF39: =BE39 -> 100.0542
A40: atlarch-all-spec-flags | B40: 1 | C40: WR00L2L2 | D40: 52000 | E40: 160 | F40: 2 | G40: 8 | H40: 721.39 | I40: 129.95 | J40: 45545 | K40: 0.73393519 | L40: 0 | M40: 0 | N40: 0 | O40: 0 | P40: 0 | Q40: 0 | R40: 0 | S40: 0 | T40: 0 | U40: 0 | V40: 0 | W40: 0 | X40: =X39 -> 129.832 | Z40: 0 | AA40: 0 | AB40: 0 | AH40: atlarch-cpu-flags | AI40: 1 | AJ40: WR00L2L2 | AK40: 26080 | AL40: 160 | AM40: 2 | AN40: 8 | AO40: 117.85 | AP40: 100.36 | AQ40: 45544 | AR40: 0.6702662 | AS40: 0 | AT40: 0 | AU40: 0 | AV40: 0 | AW40: 0 | AX40: 0 | AY40: 0 | AZ40: 0 | BA40: 0 | BB40: 0 | BC40: 0 | BD40: 0 | BF40: =BE39 -> 100.0542
...

Sheet 1 node, params, RAW
A1: Max avg. GFLOPS (and params): | F1: =MAX(O:O) -> 36.4022 | G1: =INDEX(D:D,MATCH(MAX($O:$O),$O:$O,0)) -> 26080 | H1: =INDEX(E:E,MATCH(MAX($O:$O),$O:$O,0)) -> 160 | I1: =INDEX(F:F,MATCH(MAX($O:$O),$O:$O,0)) -> 1 | J1: =INDEX(G:G,MATCH(MAX($O:$O),$O:$O,0)) -> 4 | K1: ATLAS - no OMP modifications | O1: Average GFLOP/s | R1: Max avg. GFLOPS (and params): | W1: =MAX(AF:AF) -> 35.9878 | X1: =INDEX(U:U,MATCH(MAX($AF:$AF),$AF:$AF,0)) -> 26080 | Y1: =INDEX(V:V,MATCH(MAX($AF:$AF),$AF:$AF,0)) -> 160 | Z1: =INDEX(W:W,MATCH(MAX($AF:$AF),$AF:$AF,0)) -> 1 | AA1: =INDEX(X:X,MATCH(MAX($AF:$AF),$AF:$AF,0)) -> 4 | AB1: ATLAS, OMP flags | AF1: Average GFLOP/s | AI1: Max avg. GFLOPS (and params): | AN1: =MAX(AW:AW) -> 42.326 | AO1: =INDEX(AL:AL,MATCH(MAX($AW:$AW),$AW:$AW,0)) -> 29120 | AP1: =INDEX(AM:AM,MATCH(MAX($AW:$AW),$AW:$AW,0)) -> 224 | AQ1: =INDEX(AN:AN,MATCH(MAX($AW:$AW),$AW:$AW,0)) -> 1 | AR1: =INDEX(AO:AO,MATCH(MAX($AW:$AW),$AW:$AW,0)) -> 4 | AS1: OpenBLAS, OMP flags | AW1: Average GFLOP/s | AZ1: Max avg. GFLOPS (and params): | BE1: =MAX(BN:BN) -> 39.2054 | BF1: =INDEX(BC:BC,MATCH(MAX($BN:$BN),$BN:$BN,0)) -> 29120 | BG1: =INDEX(BD:BD,MATCH(MAX($BN:$BN),$BN:$BN,0)) -> 224 | BH1: =INDEX(BE:BE,MATCH(MAX($BN:$BN),$BN:$BN,0)) -> 1 | BI1: =INDEX(BF:BF,MATCH(MAX($BN:$BN),$BN:$BN,0)) -> 4 | BJ1: OpenBLAS | BN1: Average GFLOP/s
A2: MAX GFLOPS: | D2: =MAX(I4:I856) -> 36.47 | L2: raspi11 throttling time [1/100s] | R2: MAX GFLOPS: | U2: =MAX(Z4:Z856) -> 36.117 | AC2: raspi11 throttling time [1/100s] | AI2: MAX GFLOPS: | AL2: =MAX(AQ4:AQ856) -> 42.69 | AT2: raspi11 throttling time [1/100s] | AZ2: MAX GFLOPS: | BC2: =MAX(BH4:BH856) -> 39.362 | BK2: raspi11 throttling time [1/100s]
A3: Build | B3: RUN | D3: N | E3: NB | F3: P | G3: Q | H3: Time | I3: GFLOPS | J3: Date | K3: Time | L3: 900MHz | M3: 1000MHz | N3: 1100MHz | R3: Build | S3: RUN | U3: N | V3: NB | W3: P | X3: Q | Y3: Time | Z3: GFLOPS | AA3: Date | AB3: Time | AC3: 900MHz | AD3: 1000MHz | AE3: 1100MHz | AI3: Build | AJ3: RUN | AL3: N | AM3: NB | AN3: P | AO3: Q | AP3: Time | AQ3: GFLOPS | AR3: Date | AS3: Time | AT3: 900MHz | AU3: 1000MHz | AV3: 1100MHz | AZ3: Build | BA3: RUN | BC3: N | BD3: NB | BE3: P | BF3: Q | BG3: Time | BH3: GFLOPS | BI3: Date | BJ3: Time | BK3: 900MHz | BL3: 1000MHz | BM3: 1100MHz
A4: atlarch-all-spec | B4: 0 | C4: WR00L2L2 | D4: 26048 | E4: 32 | F4: 1 | G4: 4 | H4: 940.5 | I4: 12.529 | J4: 45558 | K4: 0.28829861 | L4: 0 | M4: 0 | N4: 0 | O4: =AVERAGE(I4:I8) -> 12.5252 | R4: atlarch-all-spec | S4: 0 | T4: WR00L2L2 | U4: 26048 | V4: 32 | W4: 1 | X4: 4 | Y4: 935.38 | Z4: 12.597 | AA4: 45558 | AB4: 0.28655093 | AC4: 0 | AD4: 0 | AE4: 0 | AF4: =AVERAGE(Z4:Z8) -> 12.5358 | AI4: linux_OpenBLAS | AJ4: 0 | AK4: WR00L2L2 | AL4: 26048 | AM4: 32 | AN4: 1 | AO4: 4 | AP4: 934.1 | AQ4: 12.615 | AR4: 45558 | AS4: 0.28670139 | AT4: 0 | AU4: 0 | AV4: 0 | AW4: =AVERAGE(AQ4:AQ8) -> 12.6218 | AZ4: linux_OpenBLAS | BA4: 0 | BB4: WR00L2L2 | BC4: 26048 | BD4: 32 | BE4: 1 | BF4: 4 | BG4: 956.18 | BH4: 12.323 | BI4: 45558 | BJ4: 0.28813657 | BK4: 0 | BL4: 0 | BM4: 0 | BN4: =AVERAGE(BH4:BH8) -> 12.3224
A5: atlarch-all-spec | B5: 1 | C5: WR00L2L2 | D5: 26048 | E5: 32 | F5: 1 | G5: 4 | H5: 941.08 | I5: 12.521 | J5: 45558 | K5: 0.63039352 | L5: 0 | M5: 0 | N5: 0 | O5: =O4 -> 12.5252 | R5: atlarch-all-spec | S5: 1 | T5: WR00L2L2 | U5: 26048 | V5: 32 | W5: 1 | X5: 4 | Y5: 942.37 | Z5: 12.504 | AA5: 45558 | AB5: 0.62961806 | AC5: 0 | AD5: 0 | AE5: 0 | AF5: =AF4 -> 12.5358 | AI5: linux_OpenBLAS | AJ5: 1 | AK5: WR00L2L2 | AL5: 26048 | AM5: 32 | AN5: 1 | AO5: 4 | AP5: 933.46 | AQ5: 12.623 | AR5: 45558 | AS5: 0.46234954 | AT5: 0 | AU5: 0 | AV5: 0 | AW5: =AW4 -> 12.6218 | AZ5: linux_OpenBLAS | BA5: 1 | BB5: WR00L2L2 | BC5: 26048 | BD5: 32 | BE5: 1 | BF5: 4 | BG5: 957.85 | BH5: 12.302 | BI5: 45558 | BJ5: 0.60902778 | BK5: 0 | BL5: 0 | BM5: 0 | BN5: =BN4 -> 12.3224
A6: atlarch-all-spec | B6: 2 | C6: WR00L2L2 | D6: 26048 | E6: 32 | F6: 1 | G6: 4 | H6: 939.72 | I6: 12.539 | J6: 45558 | K6: 0.97256944 | L6: 0 | M6: 0 | N6: 0 | O6: =O5 -> 12.5252 | R6: atlarch-all-spec | S6: 2 | T6: WR00L2L2 | U6: 26048 | V6: 32 | W6: 1 | X6: 4 | Y6: 940.92 | Z6: 12.523 | AA6: 45558 | AB6: 0.97268519 | AC6: 0 | AD6: 0 | AE6: 0 | AF6: =AF5 -> 12.5358 | AI6: linux_OpenBLAS | AJ6: 2 | AK6: WR00L2L2 | AL6: 26048 | AM6: 32 | AN6: 1 | AO6: 4 | AP6: 935.99 | AQ6: 12.589 | AR6: 45558 | AS6: 0.86827546 | AT6: 0 | AU6: 0 | AV6: 0 | AW6: =AW5 -> 12.6218 | AZ6: linux_OpenBLAS | BA6: 2 | BB6: WR00L2L2 | BC6: 26048 | BD6: 32 | BE6: 1 | BF6: 4 | BG6: 955.99 | BH6: 12.326 | BI6: 45558 | BJ6: 0.91773148 | BK6: 0 | BL6: 0 | BM6: 0 | BN6: =BN5 -> 12.3224
A7: atlarch-all-spec | B7: 3 | C7: WR00L2L2 | D7: 26048 | E7: 32 | F7: 1 | G7: 4 | H7: 940.66 | I7: 12.527 | J7: 45559 | K7: 0.31483796 | L7: 0 | M7: 0 | N7: 0 | O7: =O6 -> 12.5252 | R7: atlarch-all-spec | S7: 3 | T7: WR00L2L2 | U7: 26048 | V7: 32 | W7: 1 | X7: 4 | Y7: 940.39 | Z7: 12.53 | AA7: 45559 | AB7: 0.31576389 | AC7: 0 | AD7: 0 | AE7: 0 | AF7: =AF6 -> 12.5358 | AI7: linux_OpenBLAS | AJ7: 3 | AK7: WR00L2L2 | AL7: 26048 | AM7: 32 | AN7: 1 | AO7: 4 | AP7: 933.49 | AQ7: 12.623 | AR7: 45559 | AS7: 0.15710648 | AT7: 0 | AU7: 0 | AV7: 0 | AW7: =AW6 -> 12.6218 | AZ7: linux_OpenBLAS | BA7: 3 | BB7: WR00L2L2 | BC7: 26048 | BD7: 32 | BE7: 1 | BF7: 4 | BG7: 954.49 | BH7: 12.345 | BI7: 45559 | BJ7: 0.22628472 | BK7: 0 | BL7: 0 | BM7: 0 | BN7: =BN6 -> 12.3224
A8: atlarch-all-spec | B8: 4 | C8: WR00L2L2 | D8: 26048 | E8: 32 | F8: 1 | G8: 4 | H8: 941.94 | I8: 12.51 | J8: 45559 | K8: 0.65717593 | L8: 0 | M8: 0 | N8: 0 | O8: =O7 -> 12.5252 | R8: atlarch-all-spec | S8: 4 | T8: WR00L2L2 | U8: 26048 | V8: 32 | W8: 1 | X8: 4 | Y8: 940.75 | Z8: 12.525 | AA8: 45559 | AB8: 0.65900463 | AC8: 0 | AD8: 0 | AE8: 0 | AF8: =AF7 -> 12.5358 | AI8: linux_OpenBLAS | AJ8: 4 | AK8: WR00L2L2 | AL8: 26048 | AM8: 32 | AN8: 1 | AO8: 4 | AP8: 930.85 | AQ8: 12.659 | AR8: 45559 | AS8: 0.44637731 | AT8: 0 | AU8: 0 | AV8: 0 | AW8: =AW7 -> 12.6218 | AZ8: linux_OpenBLAS | BA8: 4 | BB8: WR00L2L2 | BC8: 26048 | BD8: 32 | BE8: 1 | BF8: 4 | BG8: 956.76 | BH8: 12.316 | BI8: 45559 | BJ8: 0.53479167 | BK8: 0 | BL8: 0 | BM8: 0 | BN8: =BN7 -> 12.3224
A9: atlarch-all-spec | B9: 0 | C9: WR00L2L2 | D9: 27584 | E9: 32 | F9: 1 | G9: 4 | H9: 1142.62 | I9: 12.247 | J9: 45558 | K9: 0.38539352 | L9: 0 | M9: 0 | N9: 0 | O9: =AVERAGE(I9:I13) -> 12.228 | R9: atlarch-all-spec | S9: 0 | T9: WR00L2L2 | U9: 27584 | V9: 32 | W9: 1 | X9: 4 | Y9: 1140.03 | Z9: 12.274 | AA9: 45558 | AB9: 0.38394676 | AC9: 0 | AD9: 0 | AE9: 0 | AF9: =AVERAGE(Z9:Z13) -> 12.2678 | AI9: linux_OpenBLAS | AJ9: 0 | AK9: WR00L2L2 | AL9: 27584 | AM9: 32 | AN9: 1 | AO9: 4 | AP9: 1130.23 | AQ9: 12.381 | AR9: 45558 | AS9: 0.36899306 | AT9: 0 | AU9: 0 | AV9: 0 | AW9: =AVERAGE(AQ9:AQ13) -> 12.3568 | AZ9: linux_OpenBLAS | BA9: 0 | BB9: WR00L2L2 | BC9: 27584 | BD9: 32 | BE9: 1 | BF9: 4 | BG9: 1144.72 | BH9: 12.224 | BI9: 45558 | BJ9: 0.37717593 | BK9: 0 | BL9: 0 | BM9: 0 | BN9: =AVERAGE(BH9:BH13) -> 12.2214
A10: atlarch-all-spec | B10: 1 | C10: WR00L2L2 | D10: 27584 | E10: 32 | F10: 1 | G10: 4 | H10: 1146.43 | I10: 12.206 | J10: 45558 | K10: 0.72755787 | L10: 0 | M10: 0 | N10: 0 | O10: =O9 -> 12.228 | R10: atlarch-all-spec | S10: 1 | T10: WR00L2L2 | U10: 27584 | V10: 32 | W10: 1 | X10: 4 | Y10: 1145.18 | Z10: 12.219 | AA10: 45558 | AB10: 0.72711806 | AC10: 0 | AD10: 0 | AE10: 0 | AF10: =AF9 -> 12.2678 | AI10: linux_OpenBLAS | AJ10: 1 | AK10: WR00L2L2 | AL10: 27584 | AM10: 32 | AN10: 1 | AO10: 4 | AP10: 1130.91 | AQ10: 12.373 | AR10: 45558 | AS10: 0.66153935 | AT10: 0 | AU10: 0 | AV10: 0 | AW10: =AW9 -> 12.3568 | AZ10: linux_OpenBLAS | BA10: 1 | BB10: WR00L2L2 | BC10: 27584 | BD10: 32 | BE10: 1 | BF10: 4 | BG10: 1144.61 | BH10: 12.225 | BI10: 45558 | BJ10: 0.69796296 | BK10: 0 | BL10: 0 | BM10: 0 | BN10: =BN9 -> 12.2214
A11: atlarch-all-spec | B11: 2 | C11: WR00L2L2 | D11: 27584 | E11: 32 | F11: 1 | G11: 4 | H11: 1146.82 | I11: 12.202 | J11: 45559 | K11: 0.069733796 | L11: 0 | M11: 0 | N11: 0 | O11: =O10 -> 12.228 | R11: atlarch-all-spec | S11: 2 | T11: WR00L2L2 | U11: 27584 | V11: 32 | W11: 1 | X11: 4 | Y11: 1138.9 | Z11: 12.287 | AA11: 45559 | AB11: 0.070138889 | AC11: 0 | AD11: 0 | AE11: 0 | AF11: =AF10 -> 12.2678 | AI11: linux_OpenBLAS | AJ11: 2 | AK11: WR00L2L2 | AL11: 27584 | AM11: 32 | AN11: 1 | AO11: 4 | AP11: 1135.68 | AQ11: 12.321 | AR11: 45558 | AS11: 0.95070602 | AT11: 0 | AU11: 0 | AV11: 0 | AW11: =AW10 -> 12.3568 | AZ11: linux_OpenBLAS | BA11: 2 | BB11: WR00L2L2 | BC11: 27584 | BD11: 32 | BE11: 1 | BF11: 4 | BG11: 1146.83 | BH11: 12.202 | BI11: 45559 | BJ11: 0.0066319444 | BK11: 0 | BL11: 0 | BM11: 0 | BN11: =BN10 -> 12.2214
A12: atlarch-all-spec | B12: 3 | C12: WR00L2L2 | D12: 27584 | E12: 32 | F12: 1 | G12: 4 | H12: 1142.67 | I12: 12.246 | J12: 45559 | K12: 0.41209491 | L12: 0 | M12: 0 | N12: 0 | O12: =O11 -> 12.228 | R12: atlarch-all-spec | S12: 3 | T12: WR00L2L2 | U12: 27584 | V12: 32 | W12: 1 | X12: 4 | Y12: 1137.32 | Z12: 12.304 | AA12: 45559 | AB12: 0.41325231 | AC12: 0 | AD12: 0 | AE12: 0 | AF12: =AF11 -> 12.2678 | AI12: linux_OpenBLAS | AJ12: 3 | AK12: WR00L2L2 | AL12: 27584 | AM12: 32 | AN12: 1 | AO12: 4 | AP12: 1130.25 | AQ12: 12.381 | AR12: 45559 | AS12: 0.23966435 | AT12: 0 | AU12: 0 | AV12: 0 | AW12: =AW11 -> 12.3568 | AZ12: linux_OpenBLAS | BA12: 3 | BB12: WR00L2L2 | BC12: 27584 | BD12: 32 | BE12: 1 | BF12: 4 | BG12: 1144.83 | BH12: 12.223 | BI12: 45559 | BJ12: 0.31515046 | BK12: 0 | BL12: 0 | BM12: 0 | BN12: =BN11 -> 12.2214
