Workbook

Sheet Arch details
A1: SBC | B1: Cores | C1: march | D1: mcpu | E1: mtune | F1: fpu | G1: mfloat-abi | J1: ostalo | K1: ostalo (Thumb)
A2: Rpi 1B | C2: armv6 | D2: arm1176jzf-s | E2: arm1176jzf-s | F2: vfpv2 (alias is vfp) | G2: hard | K2: Thumb | L2: 16KB L1 and no L2
A3: Cubieboard2 | C3: armv7-a | D3: cortex-a7 | E3: cortex-a7 | F3: neon-vfpv4 | G3: hard | J3: -funsafe-math-optimizations | K3: Thumb-2
A4: OdroidU3 | C4: armv7-a | D4: cortex-a9 | E4: cortex-a9 | F4: neon-vfpv3 (alias is neon) | G4: hard | J4: -funsafe-math-optimizations | K4: Thumb or Thumb-2 | L4: 1MB L2 cache total? From paper…
A5: OdroidMC1 | B5: LITTLE | C5: armv7-a | D5: cortex-a7 | E5: cortex-a7 | F5: neon-vfpv4 | G5: hard | J5: -funsafe-math-optimizations | K5: Thumb-2 | L5: 2 sockets, 2,5MB L2 cache per socket
B6: Big | C6: armv7-a | D6: cortex-a15 | E6: cortex-a15 | F6: neon-vfpv4 | G6: hard | J6: -funsafe-math-optimizations | K6: Thumb-2
A7: Rpi 3B | C7: armv8.1-a | D7: cortex-a53 | E7: cortex-a53 | F7: neon-fp-armv8 | G7: hard | J7: -mneon-for-64bits
A12: HPL Runs (fixed parameters) | C12: Number of nodes | D12: Node | E12: Total memory of a node (kB) | F12: N, alpha | G12: N, alpha (NB round) | H12: N, beta | I12: N, beta (NB round) | J12: NB | K12: P | L12: Q | M12: Ns difference | N12: Half of the Ns difference | O12: N1 | P12: N2 | Q12: N3
A13: Number of nodes | B13: 4 | C13: 1 | D13: Raspberry Pi 3 B | E13: 931432 | F13: =$B$14*SQRT(($C13*$E13*1024)/8) -> 8735.1537 | G13: =_xlfn.CEILING.MATH(F13/J13)*J13 -> 8768 | H13: =SQRT($B$14*($C13*$E13*1024)/8) -> 9766.1987 | I13: =_xlfn.CEILING.MATH(H13/J13)*J13 -> 9792 | J13: 64 | K13: 2 | L13: 2 | M13: =I13-G13 -> 1024 | N13: =M13/2 -> 512 | O13: =G13 -> 8768 | P13: =_xlfn.CEILING.MATH((O13+N13)/J13)*J13 -> 9280 | Q13: =_xlfn.CEILING.MATH((P13+N13)/J13)*J13 -> 9792
A14: Percentage of mem | B14: 0.8 | C14: 4 | D14: Raspberry Pi 3 B | E14: 931432 | F14: =$B$14*SQRT(($B$13*$E14*1024)/8) -> 17470.307 | G14: =_xlfn.CEILING.MATH(F14/J14)*J14 -> 17536 | H14: =SQRT($B$14*($B$13*$E14*1024)/8) -> 19532.397 | I14: =_xlfn.CEILING.MATH(H14/J14)*J14 -> 19584 | J14: 128 | K14: 2 | L14: 8 | M14: =I14-G14 -> 2048 | N14: =M14/2 -> 1024 | O14: =G14 -> 17536 | P14: =_xlfn.CEILING.MATH((O14+N14)/J14)*J14 -> 18560 | Q14: =_xlfn.CEILING.MATH((P14+N14)/J14)*J14 -> 19584
A19: # ARM64 cortex-a53 defaults (untested)
A20: #
A21: MACH=ARM64a53 OS=ALL LVL=1000 COMPS=f77
A22: 'gfortran' '-march=native -O2'
A23: MACH=ARM64a53 OS=ALL LVL=1000 COMPS=xcc
A24: 'gcc' '-march=native -O2'
A25: MACH=ARM64a53 OS=ALL LVL=1000 COMPS=icc
A26: 'gcc' '-mcpu=cortex-a53 -mtune=cortex-a53 -O2'
A27: MACH=ARM64a53 OS=ALL LVL=1000 COMPS=skc,gcc,dkc
A28: 'gcc' ' -mcpu=cortex-a53 -mtune=cortex-a53 -O3 -ftree-vect-loop-version -ftree-vectorize'
A29: MACH=ARM64a53 OS=ALL LVL=1000 COMPS=smc
A30: 'gcc' '-O2 -mcpu=cortex-a53 -mtune=cortex-a53'
... A34: 'gfortran' '-O2 -mcpu=cortex-a53'

Sheet ATLAS builds
A1: Raspberry Pi 3B | C1: Initial ATLAS config flags | D1: 32/64 build (or none) | E1: Other ATLAS config flags | F1: Compiler flag addendum type | G1: Compiler flags used for building | H1: All flags | I1: Flags used for flagsearching - mandatory | J1: Flags used for flagsearching - optional | K1: Machine originally built on | L1: HPL | M1: Flagsearched (d) | N1: Flagsearched (s) No need! HPL uses only double precision! See ATLAS install manual | O1: Flagsearched (Td) | P1: Kernel | R1: NOTE
A2: 1 | B2: archdef | C2: -D c -DWALL | E2: -Si archdef 1 | H2: =_xlfn.TEXTJOIN(" ",TRUE,C2:G2) -> -D c -DWALL -Si archdef 1 | I2: -mcpu=cortex-a53 -mtune=cortex-a53 -march=armv8-a+crc -march=armv8-a -march=armv8.1-a -mfpu=crypto-neon-fp-armv8 -mfpu=neon-fp-armv8 -mneon-for-64bits -mfloat-abi=hard | K2: raspi11 | L2: =VLOOKUP(B2,'HPL 4 nodes, builds'!$A$4:$X$165,24,FALSE) -> 10.20822 | R2: Running
A3: 2 | B3: atlarch | C3: -D c -DWALL | D3: -b 64 | E3: ARM64a53 | H3: =_xlfn.TEXTJOIN(" ",TRUE,C3:G3) -> -D c -DWALL -b 64 ARM64a53 | K3: raspi11 | L3: =VLOOKUP(B3,'HPL 4 nodes, builds'!$A$4:$X$165,24,FALSE) -> 8.16402 | R3: Done
A4: 3 | B4: atlarch-gene | C4: -D c -DWALL | D4: -b 64 | E4: ARM64xgene1 | H4: =_xlfn.TEXTJOIN(" ",TRUE,C4:G4) -> -D c -DWALL -b 64 ARM64xgene1 | K4: raspi13 | L4: =VLOOKUP(B4,'HPL 4 nodes, builds'!$A$4:$X$165,24,FALSE) -> 9.50028 | R4: Failed
A5: 4 | B5: atlarch-gene-cpu-crypto | C5: -D c -DWALL | D5: -b 64 | E5: ARM64xgene1 | F5: -Fa alg | G5: -mcpu=cortex-a53 -mtune=cortex-a53 -mfpu=crypto-neon-fp-armv8 -mneon-for-64bits -mfloat-abi=hard | H5: =_xlfn.TEXTJOIN(" ",TRUE,C5:G5) -> -D c -DWALL -b 64 ARM64xgene1 -Fa alg -mcpu=cortex-a53 -mtune=cortex-a53 -mfpu=crypto-neon-fp-armv8 -mneon-for-64bits -mfloat-abi=hard | K5: raspi13 | L5: =VLOOKUP(B5,'HPL 4 nodes, builds'!$A$4:$X$165,24,FALSE) -> 10.031
A6: 5 | B6: atlarch-gene-cpu | C6: -D c -DWALL | D6: -b 64 | E6: ARM64xgene1 | F6: -Fa alg | G6: -mcpu=cortex-a53 -mtune=cortex-a53 -mfpu=neon-fp-armv8 -mneon-for-64bits -mfloat-abi=hard | H6: =_xlfn.TEXTJOIN(" ",TRUE,C6:G6) -> -D c -DWALL -b 64 ARM64xgene1 -Fa alg -mcpu=cortex-a53 -mtune=cortex-a53 -mfpu=neon-fp-armv8 -mneon-for-64bits -mfloat-abi=hard | K6: raspi14 | L6: =VLOOKUP(B6,'HPL 4 nodes, builds'!$A$4:$X$165,24,FALSE) -> 9.14146 | Q6: Config ne prolazi zbog -mabi=lp64 | R6: TODO
A7: 6 | B7: atlarch-cpu | C7: -D c -DWALL | D7: -b 64 | E7: ARM64a53 | F7: -Fa alg | G7: -mcpu=cortex-a53 -mtune=cortex-a53 -mfpu=neon-fp-armv8 -mneon-for-64bits -mfloat-abi=hard | H7: =_xlfn.TEXTJOIN(" ",TRUE,C7:G7) -> -D c -DWALL -b 64 ARM64a53 -Fa alg -mcpu=cortex-a53 -mtune=cortex-a53 -mfpu=neon-fp-armv8 -mneon-for-64bits -mfloat-abi=hard | K7: raspi13 | L7: =VLOOKUP(B7,'HPL 4 nodes, builds'!$A$4:$X$165,24,FALSE) -> 8.18052
A8: 7 | B8: atlarch-cpu-crypto | C8: -D c -DWALL | D8: -b 64 | E8: ARM64a53 | F8: -Fa alg | G8: -mcpu=cortex-a53 -mtune=cortex-a53 -mfpu=crypto-neon-fp-armv8 -mneon-for-64bits -mfloat-abi=hard | H8: =_xlfn.TEXTJOIN(" ",TRUE,C8:G8) -> -D c -DWALL -b 64 ARM64a53 -Fa alg -mcpu=cortex-a53 -mtune=cortex-a53 -mfpu=crypto-neon-fp-armv8 -mneon-for-64bits -mfloat-abi=hard | K8: raspi14 | L8: =VLOOKUP(B8,'HPL 4 nodes, builds'!$A$4:$X$165,24,FALSE) -> 10.29376
A9: 8 | B9: archdef-flags | C9: -D c -DWALL | D9: -b 64 | F9: -Fa alg | G9: -O1 -fno-schedule-insns -mcpu=cortex-A53 -mfpu=crypto-neon-fp-armv8 -fschedule-insns -frename-registers | H9: =_xlfn.TEXTJOIN(" ",TRUE,C9:G9) -> -D c -DWALL -b 64 -Fa alg -O1 -fno-schedule-insns -mcpu=cortex-A53 -mfpu=crypto-neon-fp-armv8 -fschedule-insns -frename-registers | K9: raspi11 | L9: =VLOOKUP(B9,'HPL 4 nodes, builds'!$A$4:$X$165,24,FALSE) -> 10.69 | Q9: Starting point the same as generic-flags, newer and prefered
A10: 9 | B10: atlarch-flags | C10: -D c -DWALL | D10: -b 64 | F10: -Fa alg | G10: -O2 -fno-schedule-insns -mcpu=cortex-A53 -mfpu=crypto-neon-fp-armv8 -fselective-scheduling2 -frename-registers | H10: =_xlfn.TEXTJOIN(" ",TRUE,C10:G10) -> -D c -DWALL -b 64 -Fa alg -O2 -fno-schedule-insns -mcpu=cortex-A53 -mfpu=crypto-neon-fp-armv8 -fselective-scheduling2 -frename-registers | K10: raspi12 | L10: =VLOOKUP(B10,'HPL 4 nodes, builds'!$A$4:$X$165,24,FALSE) -> 10.7002
A11: 10 | B11: atlarch-gene-flags | C11: -D c -DWALL | D11: -b 64 | F11: -Fa alg | G11: -O1 -fno-schedule-insns -mcpu=cortex-A53 -mfpu=crypto-neon-fp-armv8 -fschedule-insns2 | H11: =_xlfn.TEXTJOIN(" ",TRUE,C11:G11) -> -D c -DWALL -b 64 -Fa alg -O1 -fno-schedule-insns -mcpu=cortex-A53 -mfpu=crypto-neon-fp-armv8 -fschedule-insns2 | K11: raspi14 | L11: =VLOOKUP(B11,'HPL 4 nodes, builds'!$A$4:$X$165,24,FALSE) -> 10.616 | Q11: Failed build
A12: 11 | B12: atlarch-gene-cpu-crypto-flags | C12: -D c -DWALL | D12: -b 64 | F12: -Fa alg | G12: -O2 -mcpu=cortex-a53 -mtune=cortex-a53 -mfpu=crypto-neon-fp-armv8 -mneon-for-64bits -mfloat-abi=hard -fno-expensive-optimizations | H12: =_xlfn.TEXTJOIN(" ",TRUE,C12:G12) -> -D c -DWALL -b 64 -Fa alg -O2 -mcpu=cortex-a53 -mtune=cortex-a53 -mfpu=crypto-neon-fp-armv8 -mneon-for-64bits -mfloat-abi=hard -fno-expensive-optimizations | K12: raspi14 | L12: =VLOOKUP(B12,'HPL 4 nodes, builds'!$A$4:$X$165,24,FALSE) -> 10.6896
A13: 12 | B13: atlarch-gene-cpu-flags | C13: -D c -DWALL | D13: -b 64 | F13: -Fa alg | G13: -O2 -mcpu=cortex-a53 -mtune=cortex-a53 -mfpu=neon-fp-armv8 -mneon-for-64bits -mfloat-abi=hard -fno-schedule-insns -fno-expensive-optimizations | H13: =_xlfn.TEXTJOIN(" ",TRUE,C13:G13) -> -D c -DWALL -b 64 -Fa alg -O2 -mcpu=cortex-a53 -mtune=cortex-a53 -mfpu=neon-fp-armv8 -mneon-for-64bits -mfloat-abi=hard -fno-schedule-insns -fno-expensive-optimizations | K13: raspi11 | L13: =VLOOKUP(B13,'HPL 4 nodes, builds'!$A$4:$X$165,24,FALSE) -> 10.7128
A14: 13 | B14: atlarch-cpu-flags | C14: -D c -DWALL | D14: -b 64 | F14: -Fa alg | G14: -Os -mcpu=cortex-a53 -mtune=cortex-a53 -mfpu=neon-fp-armv8 -mneon-for-64bits -mfloat-abi=hard -fno-tree-ter | H14: =_xlfn.TEXTJOIN(" ",TRUE,C14:G14) -> -D c -DWALL -b 64 -Fa alg -Os -mcpu=cortex-a53 -mtune=cortex-a53 -mfpu=neon-fp-armv8 -mneon-for-64bits -mfloat-abi=hard -fno-tree-ter | K14: raspi12 | L14: =VLOOKUP(B14,'HPL 4 nodes, builds'!$A$4:$X$165,24,FALSE) -> 10.7068
A15: 14 | B15: atlarch-cpu-crypto-flags | C15: -D c -DWALL | D15: -b 64 | F15: -Fa alg | G15: -O1 -mcpu=cortex-a53 -mtune=cortex-a53 -mfpu=crypto-neon-fp-armv8 -mneon-for-64bits -mfloat-abi=hard -fschedule-insns -frename-registers | H15: =_xlfn.TEXTJOIN(" ",TRUE,C15:G15) -> -D c -DWALL -b 64 -Fa alg -O1 -mcpu=cortex-a53 -mtune=cortex-a53 -mfpu=crypto-neon-fp-armv8 -mneon-for-64bits -mfloat-abi=hard -fschedule-insns -frename-registers | K15: raspi13 | L15: =VLOOKUP(B15,'HPL 4 nodes, builds'!$A$4:$X$165,24,FALSE) -> 10.733
A16: 15 | B16: noarch-flags | C16: -D c -DWALL | D16: -b 64 | F16: -Fa alg | G16: -O1 -fschedule-insns2 -fexpensive-optimizations -mcpu=cortex-A53 | H16: =_xlfn.TEXTJOIN(" ",TRUE,C16:G16) -> -D c -DWALL -b 64 -Fa alg -O1 -fschedule-insns2 -fexpensive-optimizations -mcpu=cortex-A53 | K16: raspi11 | L16: =VLOOKUP(B16,'HPL 4 nodes, builds'!$A$4:$X$165,24,FALSE) -> 10.7302 | Q16: OLD
A17: 16 | B17: generic-flags | C17: -D c -DWALL | D17: -b 64 | F17: -Fa alg | G17: -O1 -fno-schedule-insns -fschedule-insns2 -fexpensive-optimizations -fselective-scheduling2 | H17: =_xlfn.TEXTJOIN(" ",TRUE,C17:G17) -> -D c -DWALL -b 64 -Fa alg -O1 -fno-schedule-insns -fschedule-insns2 -fexpensive-optimizations -fselective-scheduling2 | K17: raspi14 | L17: =VLOOKUP(B17,'HPL 4 nodes, builds'!$A$4:$X$165,24,FALSE) -> 10.714 | Q17: OLD, this is actually archdef flags (but the name generic caused issues)
A18: ? | B18: noarch | C18: -D c -DWALL | E18: -Si archdef 0 | H18: =_xlfn.TEXTJOIN(" ",TRUE,C18:G18) -> -D c -DWALL -Si archdef 0 | K18: raspi12 | L18: =VLOOKUP(B18,'HPL 4 nodes, builds'!$A$4:$X$165,24,FALSE) -> 8.47564 | Q18: Failed build, repeated, failed again
A19: ? | B19: recommended | C19: -D c -DWALL | D19: -b 64 | F19: -Fa alg | G19: -mcpu=cortex-a53 -mfloat-abi=hard -mfpu=neon-fp-armv8 -mneon-for-64bits | H19: =_xlfn.TEXTJOIN(" ",TRUE,C19:G19) -> -D c -DWALL -b 64 -Fa alg -mcpu=cortex-a53 -mfloat-abi=hard -mfpu=neon-fp-armv8 -mneon-for-64bits | I19: -mtune=cortex-a53 -march=armv8-a+crc -march=armv8-a -march=armv8.1-a -mfpu=crypto-neon-fp-armv8 | K19: raspi12 | L19: =VLOOKUP(B19,'HPL 4 nodes, builds'!$A$4:$X$165,24,FALSE) -> #N/A | Q19: https://gist.github.com/fm4dd/c663217935dc17f0fc73c9c81b0aa845 | R19: Preporučeni flagovi nisu radili: -mcpu=cortex-a53 -mfloat-abi=hard -mfpu=neon-fp-armv8 -mneon-for-64bits Zapravo nisu radila posljednja 3 iz nekog razloga (kao da ih arhitektura ne prepoznaje) Zato što koristimo 64-bitni OS, koji te opcije podrazumijeva Ni s novim flagovima nije radio build ATLASa
H20: =_xlfn.TEXTJOIN(" ",TRUE,C20:G20) | L20: =VLOOKUP(B20,'HPL 4 nodes, builds'!$A$4:$X$165,24,FALSE) -> #N/A
B21: Bez inicijalnih flagova u flagsearch | H21: =_xlfn.TEXTJOIN(" ",TRUE,C21:G21) | L21: =VLOOKUP(B21,'HPL 4 nodes, builds'!$A$4:$X$165,24,FALSE) -> #N/A
A22: 17 | B22: atlarch-gene-cpu-crypto-flags-2 | C22: -D c -DWALL | D22: -b 64 | F22: -Fa alg | G22: -O1 -fno-schedule-insns -mcpu=cortex-A53 -mfpu=crypto-neon-fp-armv8 -fschedule-insns2 -fmodulo-sched -fmodulo-sched-allow-regmoves -funroll-all-loops | H22: =_xlfn.TEXTJOIN(" ",TRUE,C22:G22) -> -D c -DWALL -b 64 -Fa alg -O1 -fno-schedule-insns -mcpu=cortex-A53 -mfpu=crypto-neon-fp-armv8 -fschedule-insns2 -fmodulo-sched -fmodulo-sched-allow-regmoves -funroll-all-loops | I22: second flagsearch from the originals, without initial flags, only with -pipe | K22: raspi11 | L22: =VLOOKUP(B22,'HPL 4 nodes, builds'!$A$4:$X$165,24,FALSE) -> 10.8972
A23: 18 | B23: atlarch-gene-cpu-flags-2 | C23: -D c -DWALL | D23: -b 64 | F23: -Fa alg | G23: -O1 -fno-schedule-insns -mcpu=cortex-A53 -mfpu=crypto-neon-fp-armv8 -fschedule-insns2 | H23: =_xlfn.TEXTJOIN(" ",TRUE,C23:G23) -> -D c -DWALL -b 64 -Fa alg -O1 -fno-schedule-insns -mcpu=cortex-A53 -mfpu=crypto-neon-fp-armv8 -fschedule-insns2 | K23: raspi12 | L23: =VLOOKUP(B23,'HPL 4 nodes, builds'!$A$4:$X$165,24,FALSE) -> 10.9478
A24: 19 | B24: atlarch-cpu-flags-2 | C24: -D c -DWALL | D24: -b 64 | F24: -Fa alg | G24: -Os -fno-schedule-insns -mcpu=cortex-A53 -mfpu=crypto-neon-fp-armv8 -fschedule-insns -fno-schedule-insns -fno-tree-ter | H24: =_xlfn.TEXTJOIN(" ",TRUE,C24:G24) -> -D c -DWALL -b 64 -Fa alg -Os -fno-schedule-insns -mcpu=cortex-A53 -mfpu=crypto-neon-fp-armv8 -fschedule-insns -fno-schedule-insns -fno-tree-ter | K24: raspi13 | L24: =VLOOKUP(B24,'HPL 4 nodes, builds'!$A$4:$X$165,24,FALSE) -> 11.0582
A25: 20 | B25: atlarch-cpu-crypto-flags-2 | C25: -D c -DWALL | D25: -b 64 | F25: -Fa alg | G25: -O1 -fno-schedule-insns -mcpu=cortex-A53 -mfpu=crypto-neon-fp-armv8 -fschedule-insns -frename-registers | H25: =_xlfn.TEXTJOIN(" ",TRUE,C25:G25) -> -D c -DWALL -b 64 -Fa alg -O1 -fno-schedule-insns -mcpu=cortex-A53 -mfpu=crypto-neon-fp-armv8 -fschedule-insns -frename-registers | K25: raspi14 | L25: =VLOOKUP(B25,'HPL 4 nodes, builds'!$A$4:$X$165,24,FALSE) -> 10.5788

Sheet HPL 4 nodes, builds
A1: Max avg. GFLOPS (and params): | B1: =INDEX(A:A,MATCH(MAX($X:$X),$X:$X,0)) -> noarch-flags | F1: =MAX(X:X) -> 11.9056 | G1: =INDEX(D:D,MATCH(MAX($X:$X),$X:$X,0)) -> 19520 | H1: =INDEX(E:E,MATCH(MAX($X:$X),$X:$X,0)) -> 160 | I1: =INDEX(F:F,MATCH(MAX($X:$X),$X:$X,0)) -> 2 | J1: =INDEX(G:G,MATCH(MAX($X:$X),$X:$X,0)) -> 8 | L1: ATLAS | X1: Average GFLOPs
A2: MAX GFLOPS: | D2: =MAX(I4:I841) -> 12.12 | L2: raspi11 throttling time [1/100s] | O2: raspi12 throttling time [1/100s] | R2: raspi13 throttling time [1/100s] | U2: raspi14 throttling time [1/100s]
A3: Build | B3: RUN | D3: N | E3: NB | F3: P | G3: Q | H3: Time | I3: GFLOPS | J3: Date | K3: Time | L3: 900MHz | M3: 1000MHz | N3: 1100MHz | O3: 900MHz | P3: 1000MHz | Q3: 1100MHz | R3: 900MHz | S3: 1000MHz | T3: 1100MHz | U3: 900MHz | V3: 1000MHz | W3: 1100MHz
A4: noarch-flags | B4: 0 | C4: WR00L2L2 | D4: 17536 | E4: 128 | F4: 2 | G4: 8 | H4: 334.9 | I4: 10.736 | J4: 45472 | K4: 0.18898148 | L4: 0 | M4: 0 | N4: 0 | O4: 0 | P4: 0 | Q4: 0 | R4: 0 | S4: 0 | T4: 0 | U4: 0 | V4: 0 | W4: 0 | X4: =AVERAGE(I4:I8) -> 10.7302
A5: noarch-flags | B5: 1 | C5: WR00L2L2 | D5: 17536 | E5: 128 | F5: 2 | G5: 8 | H5: 334.4 | I5: 10.752 | J5: 45472 | K5: 0.19315972 | L5: 0 | M5: 0 | N5: 0 | O5: 0 | P5: 0 | Q5: 0 | R5: 0 | S5: 0 | T5: 0 | U5: 0 | V5: 0 | W5: 0 | X5: =X4 -> 10.7302
A6: noarch-flags | B6: 2 | C6: WR00L2L2 | D6: 17536 | E6: 128 | F6: 2 | G6: 8 | H6: 336.49 | I6: 10.685 | J6: 45472 | K6: 0.19734954 | L6: 0 | M6: 0 | N6: 0 | O6: 0 | P6: 0 | Q6: 0 | R6: 0 | S6: 0 | T6: 0 | U6: 0 | V6: 0 | W6: 0 | X6: =X5 -> 10.7302
A7: noarch-flags | B7: 3 | C7: WR00L2L2 | D7: 17536 | E7: 128 | F7: 2 | G7: 8 | H7: 333.89 | I7: 10.768 | J7: 45472 | K7: 0.20150463 | L7: 0 | M7: 0 | N7: 0 | O7: 0 | P7: 0 | Q7: 0 | R7: 0 | S7: 0 | T7: 0 | U7: 0 | V7: 0 | W7: 0 | X7: =X6 -> 10.7302
A8: noarch-flags | B8: 4 | C8: WR00L2L2 | D8: 17536 | E8: 128 | F8: 2 | G8: 8 | H8: 335.7 | I8: 10.71 | J8: 45472 | K8: 0.20569444 | L8: 0 | M8: 0 | N8: 0 | O8: 0 | P8: 0 | Q8: 0 | R8: 0 | S8: 0 | T8: 0 | U8: 0 | V8: 0 | W8: 0 | X8: =X7 -> 10.7302
A9: generic-flags | B9: 0 | C9: WR00L2L2 | D9: 17536 | E9: 128 | F9: 2 | G9: 8 | H9: 336.07 | I9: 10.699 | J9: 45472 | K9: 0.084097222 | L9: 0 | M9: 0 | N9: 0 | O9: 0 | P9: 0 | Q9: 0 | R9: 0 | S9: 0 | T9: 0 | U9: 0 | V9: 0 | W9: 0 | X9: =AVERAGE(I9:I13) -> 10.714
A10: generic-flags | B10: 1 | C10: WR00L2L2 | D10: 17536 | E10: 128 | F10: 2 | G10: 8 | H10: 334.7 | I10: 10.742 | J10: 45472 | K10: 0.088275463 | L10: 0 | M10: 0 | N10: 0 | O10: 0 | P10: 0 | Q10: 0 | R10: 0 | S10: 0 | T10: 0 | U10: 0 | V10: 0 | W10: 0 | X10: =X9 -> 10.714
A11: generic-flags | B11: 2 | C11: WR00L2L2 | D11: 17536 | E11: 128 | F11: 2 | G11: 8 | H11: 336.68 | I11: 10.679 | J11: 45472 | K11: 0.092476852 | L11: 0 | M11: 0 | N11: 0 | O11: 0 | P11: 0 | Q11: 0 | R11: 0 | S11: 0 | T11: 0 | U11: 0 | V11: 0 | W11: 0 | X11: =X10 -> 10.714
A12: generic-flags | B12: 3 | C12: WR00L2L2 | D12: 17536 | E12: 128 | F12: 2 | G12: 8 | H12: 335.76 | I12: 10.708 | J12: 45472 | K12: 0.096666667 | L12: 0 | M12: 0 | N12: 0 | O12: 0 | P12: 0 | Q12: 0 | R12: 0 | S12: 0 | T12: 0 | U12: 0 | V12: 0 | W12: 0 | X12: =X11 -> 10.714
A13: generic-flags | B13: 4 | C13: WR00L2L2 | D13: 17536 | E13: 128 | F13: 2 | G13: 8 | H13: 334.71 | I13: 10.742 | J13: 45472 | K13: 0.10084491 | L13: 0 | M13: 0 | N13: 0 | O13: 0 | P13: 0 | Q13: 0 | R13: 0 | S13: 0 | T13: 0 | U13: 0 | V13: 0 | W13: 0 | X13: =X12 -> 10.714
A14: atlarch-gene-cpu-flags | B14: 0 | C14: WR00L2L2 | D14: 17536 | E14: 128 | F14: 2 | G14: 8 | H14: 333.55 | I14: 10.78 | J14: 45472 | K14: 0.14725694 | L14: 0 | M14: 0 | N14: 0 | O14: 0 | P14: 0 | Q14: 0 | R14: 0 | S14: 0 | T14: 0 | U14: 0 | V14: 0 | W14: 0 | X14: =AVERAGE(I14:I18) -> 10.7128
A15: atlarch-gene-cpu-flags | B15: 1 | C15: WR00L2L2 | D15: 17536 | E15: 128 | F15: 2 | G15: 8 | H15: 335.17 | I15: 10.727 | J15: 45472 | K15: 0.15140046 | L15: 0 | M15: 0 | N15: 0 | O15: 0 | P15: 0 | Q15: 0 | R15: 0 | S15: 0 | T15: 0 | U15: 0 | V15: 0 | W15: 0 | X15: =X14 -> 10.7128
A16: atlarch-gene-cpu-flags | B16: 2 | C16: WR00L2L2 | D16: 17536 | E16: 128 | F16: 2 | G16: 8 | H16: 336.64 | I16: 10.68 | J16: 45472 | K16: 0.15556713 | L16: 0 | M16: 0 | N16: 0 | O16: 0 | P16: 0 | Q16: 0 | R16: 0 | S16: 0 | T16: 0 | U16: 0 | V16: 0 | W16: 0 | X16: =X15 -> 10.7128
A17: atlarch-gene-cpu-flags | B17: 3 | C17: WR00L2L2 | D17: 17536 | E17: 128 | F17: 2 | G17: 8 | H17: 336.58 | I17: 10.682 | J17: 45472 | K17: 0.15972222 | L17: 0 | M17: 0 | N17: 0 | O17: 0 | P17: 0 | Q17: 0 | R17: 0 | S17: 0 | T17: 0 | U17: 0 | V17: 0 | W17: 0 | X17: =X16 -> 10.7128
A18: atlarch-gene-cpu-flags | B18: 4 | C18: WR00L2L2 | D18: 17536 | E18: 128 | F18: 2 | G18: 8 | H18: 336.19 | I18: 10.695 | J18: 45472 | K18: 0.16387731 | L18: 0 | M18: 0 | N18: 0 | O18: 0 | P18: 0 | Q18: 0 | R18: 0 | S18: 0 | T18: 0 | U18: 0 | V18: 0 | W18: 0 | X18: =X17 -> 10.7128
A19: atlarch-cpu-flags | B19: 0 | C19: WR00L2L2 | D19: 17536 | E19: 128 | F19: 2 | G19: 8 | H19: 335.03 | I19: 10.732 | J19: 45472 | K19: 0.16805556 | L19: 0 | M19: 0 | N19: 0 | O19: 0 | P19: 0 | Q19: 0 | R19: 0 | S19: 0 | T19: 0 | U19: 0 | V19: 0 | W19: 0 | X19: =AVERAGE(I19:I23) -> 10.7068
A20: atlarch-cpu-flags | B20: 1 | C20: WR00L2L2 | D20: 17536 | E20: 128 | F20: 2 | G20: 8 | H20: 334.99 | I20: 10.733 | J20: 45472 | K20: 0.1722338 | L20: 0 | M20: 0 | N20: 0 | O20: 0 | P20: 0 | Q20: 0 | R20: 0 | S20: 0 | T20: 0 | U20: 0 | V20: 0 | W20: 0 | X20: =X19 -> 10.7068
A21: atlarch-cpu-flags | B21: 2 | C21: WR00L2L2 | D21: 17536 | E21: 128 | F21: 2 | G21: 8 | H21: 336.22 | I21: 10.694 | J21: 45472 | K21: 0.17642361 | L21: 0 | M21: 0 | N21: 0 | O21: 0 | P21: 0 | Q21: 0 | R21: 0 | S21: 0 | T21: 0 | U21: 0 | V21: 0 | W21: 0 | X21: =X20 -> 10.7068
A22: atlarch-cpu-flags | B22: 3 | C22: WR00L2L2 | D22: 17536 | E22: 128 | F22: 2 | G22: 8 | H22: 336.09 | I22: 10.698 | J22: 45472 | K22: 0.18061343 | L22: 0 | M22: 0 | N22: 0 | O22: 0 | P22: 0 | Q22: 0 | R22: 0 | S22: 0 | T22: 0 | U22: 0 | V22: 0 | W22: 0 | X22: =X21 -> 10.7068
A23: atlarch-cpu-flags | B23: 4 | C23: WR00L2L2 | D23: 17536 | E23: 128 | F23: 2 | G23: 8 | H23: 336.75 | I23: 10.677 | J23: 45472 | K23: 0.18480324 | L23: 0 | M23: 0 | N23: 0 | O23: 0 | P23: 0 | Q23: 0 | R23: 0 | S23: 0 | T23: 0 | U23: 0 | V23: 0 | W23: 0 | X23: =X22 -> 10.7068
A24: atlarch-flags | B24: 0 | C24: WR00L2L2 | D24: 17536 | E24: 128 | F24: 2 | G24: 8 | H24: 335.25 | I24: 10.725 | J24: 45472 | K24: 0.10503472 | L24: 0 | M24: 0 | N24: 0 | O24: 0 | P24: 0 | Q24: 0 | R24: 0 | S24: 0 | T24: 0 | U24: 0 | V24: 0 | W24: 0 | X24: =AVERAGE(I24:I28) -> 10.7002
A25: atlarch-flags | B25: 1 | C25: WR00L2L2 | D25: 17536 | E25: 128 | F25: 2 | G25: 8 | H25: 335.64 | I25: 10.712 | J25: 45472 | K25: 0.10922454 | L25: 0 | M25: 0 | N25: 0 | O25: 0 | P25: 0 | Q25: 0 | R25: 0 | S25: 0 | T25: 0 | U25: 0 | V25: 0 | W25: 0 | X25: =X24 -> 10.7002
A26: atlarch-flags | B26: 2 | C26: WR00L2L2 | D26: 17536 | E26: 128 | F26: 2 | G26: 8 | H26: 335.92 | I26: 10.703 | J26: 45472 | K26: 0.11342593 | L26: 0 | M26: 0 | N26: 0 | O26: 0 | P26: 0 | Q26: 0 | R26: 0 | S26: 0 | T26: 0 | U26: 0 | V26: 0 | W26: 0 | X26: =X25 -> 10.7002
A27: atlarch-flags | B27: 3 | C27: WR00L2L2 | D27: 17536 | E27: 128 | F27: 2 | G27: 8 | H27: 337.38 | I27: 10.657 | J27: 45472 | K27: 0.11762731 | L27: 0 | M27: 0 | N27: 0 | O27: 0 | P27: 0 | Q27: 0 | R27: 0 | S27: 0 | T27: 0 | U27: 0 | V27: 0 | W27: 0 | X27: =X26 -> 10.7002
A28: atlarch-flags | B28: 4 | C28: WR00L2L2 | D28: 17536 | E28: 128 | F28: 2 | G28: 8 | H28: 335.89 | I28: 10.704 | J28: 45472 | K28: 0.1218287 | L28: 0 | M28: 0 | N28: 0 | O28: 0 | P28: 0 | Q28: 0 | R28: 0 | S28: 0 | T28: 0 | U28: 0 | V28: 0 | W28: 0 | X28: =X27 -> 10.7002
A29: atlarch-gene-flags | B29: 0 | C29: WR00L2L2 | D29: 17536 | E29: 128 | F29: 2 | G29: 8 | H29: 337.68 | I29: 10.648 | J29: 45472 | K29: 0.12607639 | L29: 0 | M29: 0 | N29: 0 | O29: 0 | P29: 0 | Q29: 0 | R29: 0 | S29: 0 | T29: 0 | U29: 0 | V29: 0 | W29: 0 | X29: =AVERAGE(I29:I33) -> 10.616
A30: atlarch-gene-flags | B30: 1 | C30: WR00L2L2 | D30: 17536 | E30: 128 | F30: 2 | G30: 8 | H30: 339.68 | I30: 10.585 | J30: 45472 | K30: 0.13034722 | L30: 0 | M30: 0 | N30: 0 | O30: 0 | P30: 0 | Q30: 0 | R30: 0 | S30: 0 | T30: 0 | U30: 0 | V30: 0 | W30: 0 | X30: =X29 -> 10.616
A31: atlarch-gene-flags | B31: 2 | C31: WR00L2L2 | D31: 17536 | E31: 128 | F31: 2 | G31: 8 | H31: 337.85 | I31: 10.642 | J31: 45472 | K31: 0.13460648 | L31: 0 | M31: 0 | N31: 0 | O31: 0 | P31: 0 | Q31: 0 | R31: 0 | S31: 0 | T31: 0 | U31: 0 | V31: 0 | W31: 0 | X31: =X30 -> 10.616
A32: atlarch-gene-flags | B32: 3 | C32: WR00L2L2 | D32: 17536 | E32: 128 | F32: 2 | G32: 8 | H32: 339.33 | I32: 10.596 | J32: 45472 | K32: 0.13886574 | L32: 0 | M32: 0 | N32: 0 | O32: 0 | P32: 0 | Q32: 0 | R32: 0 | S32: 0 | T32: 0 | U32: 0 | V32: 0 | W32: 0 | X32: =X31 -> 10.616
A33: atlarch-gene-flags | B33: 4 | C33: WR00L2L2 | D33: 17536 | E33: 128 | F33: 2 | G33: 8 | H33: 338.92 | I33: 10.609 | J33: 45472 | K33: 0.143125 | L33: 0 | M33: 0 | N33: 0 | O33: 0 | P33: 0 | Q33: 0 | R33: 0 | S33: 0 | T33: 0 | U33: 0 | V33: 0 | W33: 0 | X33: =X32 -> 10.616
A34: atlarch-gene | B34: 0 | C34: WR00L2L2 | D34: 17536 | E34: 128 | F34: 2 | G34: 8 | H34: 380.01 | I34: 9.4616 | J34: 45471 | K34: 0.9646412 | L34: 0 | M34: 0 | N34: 0 | O34: 0 | P34: 0 | Q34: 0 | R34: 0 | S34: 0 | T34: 0 | U34: 0 | V34: 0 | W34: 0 | X34: =AVERAGE(I34:I38) -> 9.50028
A35: atlarch-gene | B35: 1 | C35: WR00L2L2 | D35: 17536 | E35: 128 | F35: 2 | G35: 8 | H35: 377.97 | I35: 9.5126 | J35: 45471 | K35: 0.97033565 | L35: 0 | M35: 0 | N35: 0 | O35: 0 | P35: 0 | Q35: 0 | R35: 0 | S35: 0 | T35: 0 | U35: 0 | V35: 0 | W35: 0 | X35: =X34 -> 9.50028
A36: atlarch-gene | B36: 2 | C36: WR00L2L2 | D36: 17536 | E36: 128 | F36: 2 | G36: 8 | H36: 377.58 | I36: 9.5224 | J36: 45471 | K36: 0.97601852 | L36: 0 | M36: 0 | N36: 0 | O36: 0 | P36: 0 | Q36: 0 | R36: 0 | S36: 0 | T36: 0 | U36: 0 | V36: 0 | W36: 0 | X36: =X35 -> 9.50028
A37: atlarch-gene | B37: 3 | C37: WR00L2L2 | D37: 17536 | E37: 128 | F37: 2 | G37: 8 | H37: 377.7 | I37: 9.5193 | J37: 45471 | K37: 0.98170139 | L37: 0 | M37: 0 | N37: 0 | O37: 0 | P37: 0 | Q37: 0 | R37: 0 | S37: 0 | T37: 0 | U37: 0 | V37: 0 | W37: 0 | X37: =X36 -> 9.50028
A38: atlarch-gene | B38: 4 | C38: WR00L2L2 | D38: 17536 | E38: 128 | F38: 2 | G38: 8 | H38: 379.05 | I38: 9.4855 | J38: 45471 | K38: 0.98740741 | L38: 0 | M38: 0 | N38: 0 | O38: 0 | P38: 0 | Q38: 0 | R38: 0 | S38: 0 | T38: 0 | U38: 0 | V38: 0 | W38: 0 | X38: =X37 -> 9.50028
A39: atlarch-gene-cpu | B39: 0 | C39: WR00L2L2 | D39: 17536 | E39: 128 | F39: 2 | G39: 8 | H39: 391.55 | I39: 9.1826 | J39: 45471 | K39: 0.99324074 | L39: 0 | M39: 0 | N39: 0 | O39: 0 | P39: 0 | Q39: 0 | R39: 0 | S39: 0 | T39: 0 | U39: 0 | V39: 0 | W39: 0 | X39: =AVERAGE(I39:I43) -> 9.14146
A40: atlarch-gene-cpu | B40: 1 | C40: WR00L2L2 | D40: 17536 | E40: 128 | F40: 2 | G40: 8 | H40: 394.34 | I40: 9.1176 | J40: 45471 | K40: 0.9991088 | L40: 0 | M40: 0 | N40: 0 | O40: 0 | P40: 0 | Q40: 0 | R40: 0 | S40: 0 | T40: 0 | U40: 0 | V40: 0 | W40: 0 | X40: =X39 -> 9.14146
...

Sheet 1 node, params, RAW
A1: Max avg. GFLOPS (and params): | F1: =MAX(O:O) -> 4.97406 | G1: =INDEX(D:D,MATCH(MAX($O:$O),$O:$O,0)) -> 9760 | H1: =INDEX(E:E,MATCH(MAX($O:$O),$O:$O,0)) -> 160 | I1: =INDEX(F:F,MATCH(MAX($O:$O),$O:$O,0)) -> 1 | J1: =INDEX(G:G,MATCH(MAX($O:$O),$O:$O,0)) -> 4 | K1: ATLAS - no OMP modifications | O1: Average GFLOP/s | R1: Max avg. GFLOPS (and params): | W1: =MAX(AF:AF) -> 4.98056 | X1: =INDEX(U:U,MATCH(MAX($AF:$AF),$AF:$AF,0)) -> 9760 | Y1: =INDEX(V:V,MATCH(MAX($AF:$AF),$AF:$AF,0)) -> 160 | Z1: =INDEX(W:W,MATCH(MAX($AF:$AF),$AF:$AF,0)) -> 1 | AA1: =INDEX(X:X,MATCH(MAX($AF:$AF),$AF:$AF,0)) -> 4 | AB1: ATLAS, OMP flags, over_voltage=2 | AF1: Average GFLOP/s | AI1: Max avg. GFLOPS (and params): | AN1: =MAX(AW:AW) -> 6.7698 | AO1: =INDEX(AL:AL,MATCH(MAX($AW:$AW),$AW:$AW,0)) -> 9792 | AP1: =INDEX(AM:AM,MATCH(MAX($AW:$AW),$AW:$AW,0)) -> 96 | AQ1: =INDEX(AN:AN,MATCH(MAX($AW:$AW),$AW:$AW,0)) -> 1 | AR1: =INDEX(AO:AO,MATCH(MAX($AW:$AW),$AW:$AW,0)) -> 4 | AS1: OpenBLAS, OMP flags, over_voltage=2 | AW1: Average GFLOP/s | AZ1: Max avg. GFLOPS (and params): | BE1: =MAX(BN:BN) -> 4.09934 | BF1: =INDEX(BC:BC,MATCH(MAX($BN:$BN),$BN:$BN,0)) -> 9792 | BG1: =INDEX(BD:BD,MATCH(MAX($BN:$BN),$BN:$BN,0)) -> 96 | BH1: =INDEX(BE:BE,MATCH(MAX($BN:$BN),$BN:$BN,0)) -> 1 | BI1: =INDEX(BF:BF,MATCH(MAX($BN:$BN),$BN:$BN,0)) -> 4 | BJ1: OpenBLAS, over_voltage=2 | BN1: Average GFLOP/s
A2: MAX GFLOPS: | D2: =MAX(I4:I856) -> 4.9768 | L2: raspi11 throttling time [1/100s] | R2: MAX GFLOPS: | U2: =MAX(Z4:Z856) -> 4.9825 | AC2: raspi11 throttling time [1/100s] | AI2: MAX GFLOPS: | AL2: =MAX(AQ4:AQ856) -> 6.8108 | AT2: raspi11 throttling time [1/100s] | AZ2: MAX GFLOPS: | BC2: =MAX(BH4:BH856) -> 4.2804 | BK2: raspi11 throttling time [1/100s]
A3: Build | B3: RUN | D3: N | E3: NB | F3: P | G3: Q | H3: Time | I3: GFLOPS | J3: Date | K3: Time | L3: 900MHz | M3: 1000MHz | N3: 1100MHz | R3: Build | S3: RUN | U3: N | V3: NB | W3: P | X3: Q | Y3: Time | Z3: GFLOPS | AA3: Date | AB3: Time | AC3: 900MHz | AD3: 1000MHz | AE3: 1100MHz | AI3: Build | AJ3: RUN | AL3: N | AM3: NB | AN3: P | AO3: Q | AP3: Time | AQ3: GFLOPS | AR3: Date | AS3: Time | AT3: 900MHz | AU3: 1000MHz | AV3: 1100MHz | AZ3: Build | BA3: RUN | BC3: N | BD3: NB | BE3: P | BF3: Q | BG3: Time | BH3: GFLOPS | BI3: Date | BJ3: Time | BK3: 900MHz | BL3: 1000MHz | BM3: 1100MHz
A4: noarch-flags | B4: 0 | C4: WR00L2L2 | D4: 8768 | E4: 32 | F4: 1 | G4: 4 | H4: 117.77 | I4: 3.8165 | J4: 45549 | K4: 0.90096065 | L4: 0 | M4: 0 | N4: 0 | O4: =AVERAGE(I4:I8) -> 3.81576 | R4: noarch-flags | S4: 0 | T4: WR00L2L2 | U4: 8768 | V4: 32 | W4: 1 | X4: 4 | Y4: 117.55 | Z4: 3.8238 | AA4: 45559 | AB4: 0.54505787 | AC4: 0 | AD4: 0 | AE4: 0 | AF4: =AVERAGE(Z4:Z8) -> 3.82342 | AI4: linux_OpenBLAS | AJ4: 0 | AK4: WR00L2L2 | AL4: 8768 | AM4: 32 | AN4: 1 | AO4: 4 | AP4: 86.48 | AQ4: 5.1975 | AR4: 45559 | AS4: 0.52902778 | AT4: 0 | AU4: 0 | AV4: 0 | AW4: =AVERAGE(AQ4:AQ8) -> 5.1889 | AZ4: linux_OpenBLAS | BA4: 0 | BB4: WR00L2L2 | BC4: 8768 | BD4: 32 | BE4: 1 | BF4: 4 | BG4: 169.23 | BH4: 2.6561 | BI4: 45559 | BJ4: 0.61780093 | BK4: 0 | BL4: 0 | BM4: 0 | BN4: =AVERAGE(BH4:BH8) -> 2.66604
A5: noarch-flags | B5: 1 | C5: WR00L2L2 | D5: 8768 | E5: 32 | F5: 1 | G5: 4 | H5: 117.91 | I5: 3.8123 | J5: 45549 | K5: 0.9722338 | L5: 0 | M5: 0 | N5: 0 | O5: =O4 -> 3.81576 | R5: noarch-flags | S5: 1 | T5: WR00L2L2 | U5: 8768 | V5: 32 | W5: 1 | X5: 4 | Y5: 117.84 | Z5: 3.8143 | AA5: 45559 | AB5: 0.61630787 | AC5: 0 | AD5: 0 | AE5: 0 | AF5: =AF4 -> 3.82342 | AI5: linux_OpenBLAS | AJ5: 1 | AK5: WR00L2L2 | AL5: 8768 | AM5: 32 | AN5: 1 | AO5: 4 | AP5: 86.4 | AQ5: 5.2027 | AR5: 45559 | AS5: 0.58315972 | AT5: 0 | AU5: 0 | AV5: 0 | AW5: =AW4 -> 5.1889 | AZ5: linux_OpenBLAS | BA5: 1 | BB5: WR00L2L2 | BC5: 8768 | BD5: 32 | BE5: 1 | BF5: 4 | BG5: 168.14 | BH5: 2.6732 | BI5: 45559 | BJ5: 0.71336806 | BK5: 0 | BL5: 0 | BM5: 0 | BN5: =BN4 -> 2.66604
A6: noarch-flags | B6: 2 | C6: WR00L2L2 | D6: 8768 | E6: 32 | F6: 1 | G6: 4 | H6: 117.74 | I6: 3.8176 | J6: 45550 | K6: 0.04337963 | L6: 0 | M6: 0 | N6: 0 | O6: =O5 -> 3.81576 | R6: noarch-flags | S6: 2 | T6: WR00L2L2 | U6: 8768 | V6: 32 | W6: 1 | X6: 4 | Y6: 117.46 | Z6: 3.8269 | AA6: 45559 | AB6: 0.6875463 | AC6: 0 | AD6: 0 | AE6: 0 | AF6: =AF5 -> 3.82342 | AI6: linux_OpenBLAS | AJ6: 2 | AK6: WR00L2L2 | AL6: 8768 | AM6: 32 | AN6: 1 | AO6: 4 | AP6: 87.04 | AQ6: 5.1641 | AR6: 45559 | AS6: 0.63737269 | AT6: 0 | AU6: 0 | AV6: 0 | AW6: =AW5 -> 5.1889 | AZ6: linux_OpenBLAS | BA6: 2 | BB6: WR00L2L2 | BC6: 8768 | BD6: 32 | BE6: 1 | BF6: 4 | BG6: 169.85 | BH6: 2.6463 | BI6: 45559 | BJ6: 0.80858796 | BK6: 0 | BL6: 0 | BM6: 0 | BN6: =BN5 -> 2.66604
A7: noarch-flags | B7: 3 | C7: WR00L2L2 | D7: 8768 | E7: 32 | F7: 1 | G7: 4 | H7: 117.71 | I7: 3.8188 | J7: 45550 | K7: 0.11453704 | L7: 0 | M7: 0 | N7: 0 | O7: =O6 -> 3.81576 | R7: noarch-flags | S7: 3 | T7: WR00L2L2 | U7: 8768 | V7: 32 | W7: 1 | X7: 4 | Y7: 117.47 | Z7: 3.8266 | AA7: 45559 | AB7: 0.75880787 | AC7: 0 | AD7: 0 | AE7: 0 | AF7: =AF6 -> 3.82342 | AI7: linux_OpenBLAS | AJ7: 3 | AK7: WR00L2L2 | AL7: 8768 | AM7: 32 | AN7: 1 | AO7: 4 | AP7: 86.72 | AQ7: 5.1833 | AR7: 45559 | AS7: 0.6915162 | AT7: 0 | AU7: 0 | AV7: 0 | AW7: =AW6 -> 5.1889 | AZ7: linux_OpenBLAS | BA7: 3 | BB7: WR00L2L2 | BC7: 8768 | BD7: 32 | BE7: 1 | BF7: 4 | BG7: 167.98 | BH7: 2.6758 | BI7: 45559 | BJ7: 0.90438657 | BK7: 0 | BL7: 0 | BM7: 0 | BN7: =BN6 -> 2.66604
A8: noarch-flags | B8: 4 | C8: WR00L2L2 | D8: 8768 | E8: 32 | F8: 1 | G8: 4 | H8: 117.87 | I8: 3.8136 | J8: 45550 | K8: 0.18574074 | L8: 0 | M8: 0 | N8: 0 | O8: =O7 -> 3.81576 | R8: noarch-flags | S8: 4 | T8: WR00L2L2 | U8: 8768 | V8: 32 | W8: 1 | X8: 4 | Y8: 117.5 | Z8: 3.8255 | AA8: 45559 | AB8: 0.83010417 | AC8: 0 | AD8: 0 | AE8: 0 | AF8: =AF7 -> 3.82342 | AI8: linux_OpenBLAS | AJ8: 4 | AK8: WR00L2L2 | AL8: 8768 | AM8: 32 | AN8: 1 | AO8: 4 | AP8: 86.49 | AQ8: 5.1969 | AR8: 45559 | AS8: 0.74582176 | AT8: 0 | AU8: 0 | AV8: 0 | AW8: =AW7 -> 5.1889 | AZ8: linux_OpenBLAS | BA8: 4 | BB8: WR00L2L2 | BC8: 8768 | BD8: 32 | BE8: 1 | BF8: 4 | BG8: 167.79 | BH8: 2.6788 | BI8: 45559 | BJ8: 0.99966435 | BK8: 0 | BL8: 0 | BM8: 0 | BN8: =BN7 -> 2.66604
A9: noarch-flags | B9: 0 | C9: WR00L2L2 | D9: 9280 | E9: 32 | F9: 1 | G9: 4 | H9: 138.27 | I9: 3.854 | J9: 45549 | K9: 0.9212037 | L9: 0 | M9: 0 | N9: 0 | O9: =AVERAGE(I9:I13) -> 3.85244 | R9: noarch-flags | S9: 0 | T9: WR00L2L2 | U9: 9280 | V9: 32 | W9: 1 | X9: 4 | Y9: 138.01 | Z9: 3.8613 | AA9: 45559 | AB9: 0.56537037 | AC9: 0 | AD9: 0 | AE9: 0 | AF9: =AF8 -> 3.82342 | AI9: linux_OpenBLAS | AJ9: 0 | AK9: WR00L2L2 | AL9: 9280 | AM9: 32 | AN9: 1 | AO9: 4 | AP9: 99.78 | AQ9: 5.341 | AR9: 45559 | AS9: 0.54453704 | AT9: 0 | AU9: 0 | AV9: 0 | AW9: =AVERAGE(AQ9:AQ13) -> 5.33072 | AZ9: linux_OpenBLAS | BA9: 0 | BB9: WR00L2L2 | BC9: 9280 | BD9: 32 | BE9: 1 | BF9: 4 | BG9: 188.84 | BH9: 2.8221 | BI9: 45559 | BJ9: 0.64615741 | BK9: 0 | BL9: 0 | BM9: 0 | BN9: =AVERAGE(BH9:BH13) -> 2.82636
A10: noarch-flags | B10: 1 | C10: WR00L2L2 | D10: 9280 | E10: 32 | F10: 1 | G10: 4 | H10: 138.41 | I10: 3.8504 | J10: 45549 | K10: 0.99247685 | L10: 0 | M10: 0 | N10: 0 | O10: =O9 -> 3.85244 | R10: noarch-flags | S10: 1 | T10: WR00L2L2 | U10: 9280 | V10: 32 | W10: 1 | X10: 4 | Y10: 137.95 | Z10: 3.8632 | AA10: 45559 | AB10: 0.6366088 | AC10: 0 | AD10: 0 | AE10: 0 | AF10: =AF9 -> 3.82342 | AI10: linux_OpenBLAS | AJ10: 1 | AK10: WR00L2L2 | AL10: 9280 | AM10: 32 | AN10: 1 | AO10: 4 | AP10: 99.92 | AQ10: 5.3333 | AR10: 45559 | AS10: 0.59869213 | AT10: 0 | AU10: 0 | AV10: 0 | AW10: =AW9 -> 5.33072 | AZ10: linux_OpenBLAS | BA10: 1 | BB10: WR00L2L2 | BC10: 9280 | BD10: 32 | BE10: 1 | BF10: 4 | BG10: 190.17 | BH10: 2.8023 | BI10: 45559 | BJ10: 0.74171296 | BK10: 0 | BL10: 0 | BM10: 0 | BN10: =BN9 -> 2.82636
A11: noarch-flags | B11: 2 | C11: WR00L2L2 | D11: 9280 | E11: 32 | F11: 1 | G11: 4 | H11: 138.41 | I11: 3.8503 | J11: 45550 | K11: 0.063622685 | L11: 0 | M11: 0 | N11: 0 | O11: =O10 -> 3.85244 | R11: noarch-flags | S11: 2 | T11: WR00L2L2 | U11: 9280 | V11: 32 | W11: 1 | X11: 4 | Y11: 137.95 | Z11: 3.8632 | AA11: 45559 | AB11: 0.70784722 | AC11: 0 | AD11: 0 | AE11: 0 | AF11: =AF10 -> 3.82342 | AI11: linux_OpenBLAS | AJ11: 2 | AK11: WR00L2L2 | AL11: 9280 | AM11: 32 | AN11: 1 | AO11: 4 | AP11: 99.92 | AQ11: 5.3334 | AR11: 45559 | AS11: 0.65292824 | AT11: 0 | AU11: 0 | AV11: 0 | AW11: =AW10 -> 5.33072 | AZ11: linux_OpenBLAS | BA11: 2 | BB11: WR00L2L2 | BC11: 9280 | BD11: 32 | BE11: 1 | BF11: 4 | BG11: 188.3 | BH11: 2.8302 | BI11: 45559 | BJ11: 0.83704861 | BK11: 0 | BL11: 0 | BM11: 0 | BN11: =BN10 -> 2.82636
A12: noarch-flags | B12: 3 | C12: WR00L2L2 | D12: 9280 | E12: 32 | F12: 1 | G12: 4 | H12: 138.3 | I12: 3.8532 | J12: 45550 | K12: 0.13478009 | L12: 0 | M12: 0 | N12: 0 | O12: =O11 -> 3.85244 | R12: noarch-flags | S12: 3 | T12: WR00L2L2 | U12: 9280 | V12: 32 | W12: 1 | X12: 4 | Y12: 137.91 | Z12: 3.8642 | AA12: 45559 | AB12: 0.77913194 | AC12: 0 | AD12: 0 | AE12: 0 | AF12: =AVERAGE(Z12:Z16) -> 3.86364 | AI12: linux_OpenBLAS | AJ12: 3 | AK12: WR00L2L2 | AL12: 9280 | AM12: 32 | AN12: 1 | AO12: 4 | AP12: 100.12 | AQ12: 5.3228 | AR12: 45559 | AS12: 0.70707176 | AT12: 0 | AU12: 0 | AV12: 0 | AW12: =AW11 -> 5.33072 | AZ12: linux_OpenBLAS | BA12: 3 | BB12: WR00L2L2 | BC12: 9280 | BD12: 32 | BE12: 1 | BF12: 4 | BG12: 187.42 | BH12: 2.8435 | BI12: 45559 | BJ12: 0.9325463 | BK12: 0 | BL12: 0 | BM12: 0 | BN12: =BN11 -> 2.82636
A13: noarch-flags | B13: 4 | C13: WR00L2L2 | D13: 9280 | E13: 32 | F13: 1 | G13: 4 | H13: 138.27 | I13: 3.8543 | J13: 45550 | K13: 0.20597222 | L13: 0 | M13: 0 | N13: 0 | O13: =O12 -> 3.85244 | R13: noarch-flags | S13: 4 | T13: WR00L2L2 | U13: 9280 | V13: 32 | W13: 1 | X13: 4 | Y13: 137.99 | Z13: 3.862 | AA13: 45559 | AB13: 0.85028935 | AC13: 0 | AD13: 0 | AE13: 0 | AF13: =AF12 -> 3.86364 | AI13: linux_OpenBLAS | AJ13: 4 | AK13: WR00L2L2 | AL13: 9280 | AM13: 32 | AN13: 1 | AO13: 4 | AP13: 100.11 | AQ13: 5.3231 | AR13: 45559 | AS13: 0.76137731 | AT13: 0 | AU13: 0 | AV13: 0 | AW13: =AW12 -> 5.33072 | AZ13: linux_OpenBLAS | BA13: 4 | BB13: WR00L2L2 | BC13: 9280 | BD13: 32 | BE13: 1 | BF13: 4 | BG13: 188.06 | BH13: 2.8337 | BI13: 45560 | BJ13: 0.028402778 | BK13: 0 | BL13: 0 | BM13: 0 | BN13: =BN12 -> 2.82636
A14: noarch-flags | B14: 0 | C14: WR00L2L2 | D14: 9792 | E14: 32 | F14: 1 | G14: 4 | H14: 164.07 | I14: 3.8159 | J14: 45549 | K14: 0.94532407 | L14: 0 | M14: 0 | N14: 0 | O14: =AVERAGE(I14:I18) -> 3.83928 | R14: noarch-flags | S14: 0 | T14: WR00L2L2 | U14: 9792 | V14: 32 | W14: 1 | X14: 4 | Y14: 161.98 | Z14: 3.8652 | AA14: 45559 | AB14: 0.58952546 | AC14: 0 | AD14: 0 | AE14: 0 | AF14: =AF13 -> 3.86364 | AI14: linux_OpenBLAS | AJ14: 0 | AK14: WR00L2L2 | AL14: 9792 | AM14: 32 | AN14: 1 | AO14: 4 | AP14: 117.79 | AQ14: 5.3152 | AR14: 45559 | AS14: 0.56269676 | AT14: 0 | AU14: 0 | AV14: 0 | AW14: =AVERAGE(AQ14:AQ18) -> 5.30858 | AZ14: linux_OpenBLAS | BA14: 0 | BB14: WR00L2L2 | BC14: 9792 | BD14: 32 | BE14: 1 | BF14: 4 | BG14: 211.32 | BH14: 2.9626 | BI14: 45559 | BJ14: 0.67806713 | BK14: 0 | BL14: 0 | BM14: 0 | BN14: =AVERAGE(BH14:BH18) -> 2.94702
A15: noarch-flags | B15: 1 | C15: WR00L2L2 | D15: 9792 | E15: 32 | F15: 1 | G15: 4 | H15: 162.91 | I15: 3.843 | J15: 45550 | K15: 0.016597222 | L15: 0 | M15: 0 | N15: 0 | O15: =O14 -> 3.83928 | R15: noarch-flags | S15: 1 | T15: WR00L2L2 | U15: 9792 | V15: 32 | W15: 1 | X15: 4 | Y15: 162.03 | Z15: 3.864 | AA15: 45559 | AB15: 0.66076389 | AC15: 0 | AD15: 0 | AE15: 0 | AF15: =AVERAGE(Z15:Z19) -> 3.85346 | AI15: linux_OpenBLAS | AJ15: 1 | AK15: WR00L2L2 | AL15: 9792 | AM15: 32 | AN15: 1 | AO15: 4 | AP15: 118.15 | AQ15: 5.2988 | AR15: 45559 | AS15: 0.61685185 | AT15: 0 | AU15: 0 | AV15: 0 | AW15: =AW14 -> 5.30858 | AZ15: linux_OpenBLAS | BA15: 1 | BB15: WR00L2L2 | BC15: 9792 | BD15: 32 | BE15: 1 | BF15: 4 | BG15: 212.79 | BH15: 2.9421 | BI15: 45559 | BJ15: 0.7737037 | BK15: 0 | BL15: 0 | BM15: 0 | BN15: =BN14 -> 2.94702
A16: noarch-flags | B16: 2 | C16: WR00L2L2 | D16: 9792 | E16: 32 | F16: 1 | G16: 4 | H16: 162.67 | I16: 3.8487 | J16: 45550 | K16: 0.087719907 | L16: 0 | M16: 0 | N16: 0 | O16: =O15 -> 3.83928 | R16: noarch-flags | S16: 2 | T16: WR00L2L2 | U16: 9792 | V16: 32 | W16: 1 | X16: 4 | Y16: 162.08 | Z16: 3.8628 | AA16: 45559 | AB16: 0.73201389 | AC16: 0 | AD16: 0 | AE16: 0 | AF16: =AF15 -> 3.85346 | AI16: linux_OpenBLAS | AJ16: 2 | AK16: WR00L2L2 | AL16: 9792 | AM16: 32 | AN16: 1 | AO16: 4 | AP16: 117.92 | AQ16: 5.3092 | AR16: 45559 | AS16: 0.67108796 | AT16: 0 | AU16: 0 | AV16: 0 | AW16: =AW15 -> 5.30858 | AZ16: linux_OpenBLAS | BA16: 2 | BB16: WR00L2L2 | BC16: 9792 | BD16: 32 | BE16: 1 | BF16: 4 | BG16: 213.39 | BH16: 2.9339 | BI16: 45559 | BJ16: 0.8690162 | BK16: 0 | BL16: 0 | BM16: 0 | BN16: =BN15 -> 2.94702
A17: noarch-flags | B17: 3 | C17: WR00L2L2 | D17: 9792 | E17: 32 | F17: 1 | G17: 4 | H17: 162.81 | I17: 3.8454 | J17: 45550 | K17: 0.15888889 | L17: 0 | M17: 0 | N17: 0 | O17: =O16 -> 3.83928 | R17: noarch-flags | S17: 3 | T17: WR00L2L2 | U17: 9792 | V17: 32 | W17: 1 | X17: 4 | Y17: 161.93 | Z17: 3.8662 | AA17: 45559 | AB17: 0.8033912 | AC17: 0 | AD17: 0 | AE17: 0 | AF17: =AF16 -> 3.85346 | AI17: linux_OpenBLAS | AJ17: 3 | AK17: WR00L2L2 | AL17: 9792 | AM17: 32 | AN17: 1 | AO17: 4 | AP17: 117.76 | AQ17: 5.3165 | AR17: 45559 | AS17: 0.72524306 | AT17: 0 | AU17: 0 | AV17: 0 | AW17: =AW16 -> 5.30858 | AZ17: linux_OpenBLAS | BA17: 3 | BB17: WR00L2L2 | BC17: 9792 | BD17: 32 | BE17: 1 | BF17: 4 | BG17: 214.17 | BH17: 2.9232 | BI17: 45559 | BJ17: 0.96434028 | BK17: 0 | BL17: 0 | BM17: 0 | BN17: =BN16 -> 2.94702
A18: noarch-flags | B18: 4 | C18: WR00L2L2 | D18: 9792 | E18: 32 | F18: 1 | G18: 4 | H18: 162.9 | I18: 3.8434 | J18: 45550 | K18: 0.23008102 | L18: 0 | M18: 0 | N18: 0 | O18: =O17 -> 3.83928 | R18: noarch-flags | S18: 4 | T18: WR00L2L2 | U18: 9792 | V18: 32 | W18: 1 | X18: 4 | Y18: 162.06 | Z18: 3.8631 | AA18: 45559 | AB18: 0.8743287 | AC18: 0 | AD18: 0 | AE18: 0 | AF18: =AF17 -> 3.85346 | AI18: linux_OpenBLAS | AJ18: 4 | AK18: WR00L2L2 | AL18: 9792 | AM18: 32 | AN18: 1 | AO18: 4 | AP18: 118.06 | AQ18: 5.3032 | AR18: 45559 | AS18: 0.77956019 | AT18: 0 | AU18: 0 | AV18: 0 | AW18: =AW17 -> 5.30858 | AZ18: linux_OpenBLAS | BA18: 4 | BB18: WR00L2L2 | BC18: 9792 | BD18: 32 | BE18: 1 | BF18: 4 | BG18: 210.56 | BH18: 2.9733 | BI18: 45560 | BJ18: 0.060277778 | BK18: 0 | BL18: 0 | BM18: 0 | BN18: =BN17 -> 2.94702
A19: noarch-flags | B19: 0 | C19: WR00L2L2 | D19: 8768 | E19: 32 | F19: 2 | G19: 2 | H19: 118.42 | I19: 3.7957 | J19: 45549 | K19: 0.9024537 | L19: 0 | M19: 0 | N19: 0 | O19: =AVERAGE(I19:I23) -> 3.80106 | R19: noarch-flags | S19: 0 | T19: WR00L2L2 | U19: 8768 | V19: 32 | W19: 2 | X19: 2 | Y19: 117.94 | Z19: 3.8112 | AA19: 45559 | AB19: 0.5465625 | AC19: 0 | AD19: 0 | AE19: 0 | AF19: =AF18 -> 3.85346 | AI19: linux_OpenBLAS | AJ19: 0 | AK19: WR00L2L2 | AL19: 8768 | AM19: 32 | AN19: 2 | AO19: 2 | AP19: 84.52 | AQ19: 5.3183 | AR19: 45559 | AS19: 0.53013889 | AT19: 0 | AU19: 0 | AV19: 0 | AW19: =AVERAGE(AQ19:AQ23) -> 5.30362 | AZ19: linux_OpenBLAS | BA19: 0 | BB19: WR00L2L2 | BC19: 8768 | BD19: 32 | BE19: 2 | BF19: 2 | BG19: 179.54 | BH19: 2.5035 | BI19: 45559 | BJ19: 0.62002315 | BK19: 0 | BL19: 0 | BM19: 0 | BN19: =AVERAGE(BH19:BH23) -> 2.47556
A20: noarch-flags | B20: 1 | C20: WR00L2L2 | D20: 8768 | E20: 32 | F20: 2 | G20: 2 | H20: 118.29 | I20: 3.8 | J20: 45549 | K20: 0.97372685 | L20: 0 | M20: 0 | N20: 0 | O20: =O19 -> 3.80106 | R20: noarch-flags | S20: 1 | T20: WR00L2L2 | U20: 8768 | V20: 32 | W20: 2 | X20: 2 | Y20: 117.81 | Z20: 3.8154 | AA20: 45559 | AB20: 0.61780093 | AC20: 0 | AD20: 0 | AE20: 0 | AF20: =AF19 -> 3.85346 | AI20: linux_OpenBLAS | AJ20: 1 | AK20: WR00L2L2 | AL20: 8768 | AM20: 32 | AN20: 2 | AO20: 2 | AP20: 84.47 | AQ20: 5.3213 | AR20: 45559 | AS20: 0.58425926 | AT20: 0 | AU20: 0 | AV20: 0 | AW20: =AW19 -> 5.30362 | AZ20: linux_OpenBLAS | BA20: 1 | BB20: WR00L2L2 | BC20: 8768 | BD20: 32 | BE20: 2 | BF20: 2 | BG20: 182.61 | BH20: 2.4615 | BI20: 45559 | BJ20: 0.715625 | BK20: 0 | BL20: 0 | BM20: 0 | BN20: =BN19 -> 2.47556
A21: noarch-flags | B21: 2 | C21: WR00L2L2 | D21: 8768 | E21: 32 | F21: 2 | G21: 2 | H21: 118.34 | I21: 3.7982 | J21: 45550 | K21: 0.044872685 | L21: 0 | M21: 0 | N21: 0 | O21: =O20 -> 3.80106 | R21: noarch-flags | S21: 2 | T21: WR00L2L2 | U21: 8768 | V21: 32 | W21: 2 | X21: 2 | Y21: 117.72 | Z21: 3.8184 | AA21: 45559 | AB21: 0.68903935 | AC21: 0 | AD21: 0 | AE21: 0 | AF21: =AF20 -> 3.85346 | AI21: linux_OpenBLAS | AJ21: 2 | AK21: WR00L2L2 | AL21: 8768 | AM21: 32 | AN21: 2 | AO21: 2 | AP21: 85.08 | AQ21: 5.2832 | AR21: 45559 | AS21: 0.6384838 | AT21: 0 | AU21: 0 | AV21: 0 | AW21: =AW20 -> 5.30362 | AZ21: linux_OpenBLAS | BA21: 2 | BB21: WR00L2L2 | BC21: 8768 | BD21: 32 | BE21: 2 | BF21: 2 | BG21: 182.11 | BH21: 2.4683 | BI21: 45559 | BJ21: 0.81082176 | BK21: 0 | BL21: 0 | BM21: 0 | BN21: =BN20 -> 2.47556
A22: noarch-flags | B22: 3 | C22: WR00L2L2 | D22: 8768 | E22: 32 | F22: 2 | G22: 2 | H22: 118.33 | I22: 3.7987 | J22: 45550 | K22: 0.11603009 | L22: 0 | M22: 0 | N22: 0 | O22: =O21 -> 3.80106 | R22: noarch-flags | S22: 3 | T22: WR00L2L2 | U22: 8768 | V22: 32 | W22: 2 | X22: 2 | Y22: 117.99 | Z22: 3.8095 | AA22: 45559 | AB22: 0.7603125 | AC22: 0 | AD22: 0 | AE22: 0 | AF22: =AVERAGE(Z22:Z26) -> 3.82622 | AI22: linux_OpenBLAS | AJ22: 3 | AK22: WR00L2L2 | AL22: 8768 | AM22: 32 | AN22: 2 | AO22: 2 | AP22: 84.87 | AQ22: 5.2964 | AR22: 45559 | AS22: 0.69262731 | AT22: 0 | AU22: 0 | AV22: 0 | AW22: =AW21 -> 5.30362 | AZ22: linux_OpenBLAS | BA22: 3 | BB22: WR00L2L2 | BC22: 8768 | BD22: 32 | BE22: 2 | BF22: 2 | BG22: 180.37 | BH22: 2.4921 | BI22: 45559 | BJ22: 0.9066088 | BK22: 0 | BL22: 0 | BM22: 0 | BN22: =BN21 -> 2.47556
A23: noarch-flags | B23: 4 | C23: WR00L2L2 | D23: 8768 | E23: 32 | F23: 2 | G23: 2 | H23: 117.89 | I23: 3.8127 | J23: 45550 | K23: 0.1872338 | L23: 0 | M23: 0 | N23: 0 | O23: =O22 -> 3.80106 | R23: noarch-flags | S23: 4 | T23: WR00L2L2 | U23: 8768 | V23: 32 | W23: 2 | X23: 2 | Y23: 117.93 | Z23: 3.8116 | AA23: 45559 | AB23: 0.83159722 | AC23: 0 | AD23: 0 | AE23: 0 | AF23: =AF22 -> 3.82622 | AI23: linux_OpenBLAS | AJ23: 4 | AK23: WR00L2L2 | AL23: 8768 | AM23: 32 | AN23: 2 | AO23: 2 | AP23: 84.83 | AQ23: 5.2989 | AR23: 45559 | AS23: 0.74693287 | AT23: 0 | AU23: 0 | AV23: 0 | AW23: =AW22 -> 5.30362 | AZ23: linux_OpenBLAS | BA23: 4 | BB23: WR00L2L2 | BC23: 8768 | BD23: 32 | BE23: 2 | BF23: 2 | BG23: 183.29 | BH23: 2.4524 | BI23: 45560 | BJ23: 0.0019212963 | BK23: 0 | BL23: 0 | BM23: 0 | BN23: =BN22 -> 2.47556
A24: noarch-flags | B24: 0 | C24: WR00L2L2 | D24: 9280 | E24: 32 | F24: 2 | G24: 2 | H24: 139.52 | I24: 3.8197 | J24: 45549 | K24: 0.92296296 | L24: 0 | M24: 0 | N24: 0 | O24: =AVERAGE(I24:I28) -> 3.82424 | R24: noarch-flags | S24: 0 | T24: WR00L2L2 | U24: 9280 | V24: 32 | W24: 2 | X24: 2 | Y24: 138.95 | Z24: 3.8352 | AA24: 45559 | AB24: 0.56711806 | AC24: 0 | AD24: 0 | AE24: 0 | AF24: =AF23 -> 3.82622 | AI24: linux_OpenBLAS | AJ24: 0 | AK24: WR00L2L2 | AL24: 9280 | AM24: 32 | AN24: 2 | AO24: 2 | AP24: 98.97 | AQ24: 5.3845 | AR24: 45559 | AS24: 0.54582176 | AT24: 0 | AU24: 0 | AV24: 0 | AW24: =AVERAGE(AQ24:AQ28) -> 5.38784 | AZ24: linux_OpenBLAS | BA24: 0 | BB24: WR00L2L2 | BC24: 9280 | BD24: 32 | BE24: 2 | BF24: 2 | BG24: 201.65 | BH24: 2.6428 | BI24: 45559 | BJ24: 0.64864583 | BK24: 0 | BL24: 0 | BM24: 0 | BN24: =AVERAGE(BH24:BH28) -> 2.60962
A25: noarch-flags | B25: 1 | C25: WR00L2L2 | D25: 9280 | E25: 32 | F25: 2 | G25: 2 | H25: 139.47 | I25: 3.8211 | J25: 45549 | K25: 0.99422454 | L25: 0 | M25: 0 | N25: 0 | O25: =O24 -> 3.82424 | R25: noarch-flags | S25: 1 | T25: WR00L2L2 | U25: 9280 | V25: 32 | W25: 2 | X25: 2 | Y25: 138.84 | Z25: 3.8384 | AA25: 45559 | AB25: 0.63836806 | AC25: 0 | AD25: 0 | AE25: 0 | AF25: =AVERAGE(Z25:Z29) -> 3.83788 | AI25: linux_OpenBLAS | AJ25: 1 | AK25: WR00L2L2 | AL25: 9280 | AM25: 32 | AN25: 2 | AO25: 2 | AP25: 98.72 | AQ25: 5.3982 | AR25: 45559 | AS25: 0.59997685 | AT25: 0 | AU25: 0 | AV25: 0 | AW25: =AW24 -> 5.38784 | AZ25: linux_OpenBLAS | BA25: 1 | BB25: WR00L2L2 | BC25: 9280 | BD25: 32 | BE25: 2 | BF25: 2 | BG25: 207.75 | BH25: 2.5652 | BI25: 45559 | BJ25: 0.74427083 | BK25: 0 | BL25: 0 | BM25: 0 | BN25: =BN24 -> 2.60962
A26: noarch-flags | B26: 2 | C26: WR00L2L2 | D26: 9280 | E26: 32 | F26: 2 | G26: 2 | H26: 139.24 | I26: 3.8272 | J26: 45550 | K26: 0.06537037 | L26: 0 | M26: 0 | N26: 0 | O26: =O25 -> 3.82424 | R26: noarch-flags | S26: 2 | T26: WR00L2L2 | U26: 9280 | V26: 32 | W26: 2 | X26: 2 | Y26: 138.91 | Z26: 3.8364 | AA26: 45559 | AB26: 0.70960648 | AC26: 0 | AD26: 0 | AE26: 0 | AF26: =AF25 -> 3.83788 | AI26: linux_OpenBLAS | AJ26: 2 | AK26: WR00L2L2 | AL26: 9280 | AM26: 32 | AN26: 2 | AO26: 2 | AP26: 98.96 | AQ26: 5.3851 | AR26: 45559 | AS26: 0.65421296 | AT26: 0 | AU26: 0 | AV26: 0 | AW26: =AW25 -> 5.38784 | AZ26: linux_OpenBLAS | BA26: 2 | BB26: WR00L2L2 | BC26: 9280 | BD26: 32 | BE26: 2 | BF26: 2 | BG26: 207.38 | BH26: 2.5698 | BI26: 45559 | BJ26: 0.83959491 | BK26: 0 | BL26: 0 | BM26: 0 | BN26: =BN25 -> 2.60962
A27: noarch-flags | B27: 3 | C27: WR00L2L2 | D27: 9280 | E27: 32 | F27: 2 | G27: 2 | H27: 139.31 | I27: 3.8255 | J27: 45550 | K27: 0.13653935 | L27: 0 | M27: 0 | N27: 0 | O27: =O26 -> 3.82424 | R27: noarch-flags | S27: 3 | T27: WR00L2L2 | U27: 9280 | V27: 32 | W27: 2 | X27: 2 | Y27: 138.81 | Z27: 3.8392 | AA27: 45559 | AB27: 0.7808912 | AC27: 0 | AD27: 0 | AE27: 0 | AF27: =AF26 -> 3.83788 | AI27: linux_OpenBLAS | AJ27: 3 | AK27: WR00L2L2 | AL27: 9280 | AM27: 32 | AN27: 2 | AO27: 2 | AP27: 98.97 | AQ27: 5.3848 | AR27: 45559 | AS27: 0.70835648 | AT27: 0 | AU27: 0 | AV27: 0 | AW27: =AW26 -> 5.38784 | AZ27: linux_OpenBLAS | BA27: 3 | BB27: WR00L2L2 | BC27: 9280 | BD27: 32 | BE27: 2 | BF27: 2 | BG27: 205.56 | BH27: 2.5925 | BI27: 45559 | BJ27: 0.93508102 | BK27: 0 | BL27: 0 | BM27: 0 | BN27: =BN26 -> 2.60962
A28: noarch-flags | B28: 4 | C28: WR00L2L2 | D28: 9280 | E28: 32 | F28: 2 | G28: 2 | H28: 139.23 | I28: 3.8277 | J28: 45550 | K28: 0.20773148 | L28: 0 | M28: 0 | N28: 0 | O28: =O27 -> 3.82424 | R28: noarch-flags | S28: 4 | T28: WR00L2L2 | U28: 9280 | V28: 32 | W28: 2 | X28: 2 | Y28: 138.65 | Z28: 3.8436 | AA28: 45559 | AB28: 0.85203704 | AC28: 0 | AD28: 0 | AE28: 0 | AF28: =AF27 -> 3.83788 | AI28: linux_OpenBLAS | AJ28: 4 | AK28: WR00L2L2 | AL28: 9280 | AM28: 32 | AN28: 2 | AO28: 2 | AP28: 98.93 | AQ28: 5.3866 | AR28: 45559 | AS28: 0.76267361 | AT28: 0 | AU28: 0 | AV28: 0 | AW28: =AW27 -> 5.38784 | AZ28: linux_OpenBLAS | BA28: 4 | BB28: WR00L2L2 | BC28: 9280 | BD28: 32 | BE28: 2 | BF28: 2 | BG28: 199.01 | BH28: 2.6778 | BI28: 45560 | BJ28: 0.030844907 | BK28: 0 | BL28: 0 | BM28: 0 | BN28: =BN27 -> 2.60962
A29: noarch-flags | B29: 0 | C29: WR00L2L2 | D29: 9792 | E29: 32 | F29: 2 | G29: 2 | H29: 165.25 | I29: 3.7885 | J29: 45549 | K29: 0.94739583 | L29: 0 | M29: 0 | N29: 0 | O29: =AVERAGE(I29:I33) -> 3.8126 | R29: noarch-flags | S29: 0 | T29: WR00L2L2 | U29: 9792 | V29: 32 | W29: 2 | X29: 2 | Y29: 163.39 | Z29: 3.8318 | AA29: 45559 | AB29: 0.59158565 | AC29: 0 | AD29: 0 | AE29: 0 | AF29: =AF28 -> 3.83788 | AI29: linux_OpenBLAS | AJ29: 0 | AK29: WR00L2L2 | AL29: 9792 | AM29: 32 | AN29: 2 | AO29: 2 | AP29: 117.21 | AQ29: 5.3413 | AR29: 45559 | AS29: 0.56421296 | AT29: 0 | AU29: 0 | AV29: 0 | AW29: =AVERAGE(AQ29:AQ33) -> 5.33366 | AZ29: linux_OpenBLAS | BA29: 0 | BB29: WR00L2L2 | BC29: 9792 | BD29: 32 | BE29: 2 | BF29: 2 | BG29: 224.45 | BH29: 2.7893 | BI29: 45559 | BJ29: 0.68083333 | BK29: 0 | BL29: 0 | BM29: 0 | BN29: =AVERAGE(BH29:BH33) -> 2.73132
A30: noarch-flags | B30: 1 | C30: WR00L2L2 | D30: 9792 | E30: 32 | F30: 2 | G30: 2 | H30: 163.73 | I30: 3.8237 | J30: 45550 | K30: 0.018645833 | L30: 0 | M30: 0 | N30: 0 | O30: =O29 -> 3.8126 | R30: noarch-flags | S30: 1 | T30: WR00L2L2 | U30: 9792 | V30: 32 | W30: 2 | X30: 2 | Y30: 163.38 | Z30: 3.832 | AA30: 45559 | AB30: 0.6628125 | AC30: 0 | AD30: 0 | AE30: 0 | AF30: =AF29 -> 3.83788 | AI30: linux_OpenBLAS | AJ30: 1 | AK30: WR00L2L2 | AL30: 9792 | AM30: 32 | AN30: 2 | AO30: 2 | AP30: 117.43 | AQ30: 5.3316 | AR30: 45559 | AS30: 0.61836806 | AT30: 0 | AU30: 0 | AV30: 0 | AW30: =AW29 -> 5.33366 | AZ30: linux_OpenBLAS | BA30: 1 | BB30: WR00L2L2 | BC30: 9792 | BD30: 32 | BE30: 2 | BF30: 2 | BG30: 229.31 | BH30: 2.7302 | BI30: 45559 | BJ30: 0.7765162 | BK30: 0 | BL30: 0 | BM30: 0 | BN30: =BN29 -> 2.73132
A31: noarch-flags | B31: 2 | C31: WR00L2L2 | D31: 9792 | E31: 32 | F31: 2 | G31: 2 | H31: 164.18 | I31: 3.8133 | J31: 45550 | K31: 0.089780093 | L31: 0 | M31: 0 | N31: 0 | O31: =O30 -> 3.8126 | R31: noarch-flags | S31: 2 | T31: WR00L2L2 | U31: 9792 | V31: 32 | W31: 2 | X31: 2 | Y31: 163.47 | Z31: 3.8298 | AA31: 45559 | AB31: 0.7340625 | AC31: 0 | AD31: 0 | AE31: 0 | AF31: =AF30 -> 3.83788 | AI31: linux_OpenBLAS | AJ31: 2 | AK31: WR00L2L2 | AL31: 9792 | AM31: 32 | AN31: 2 | AO31: 2 | AP31: 117.44 | AQ31: 5.3309 | AR31: 45559 | AS31: 0.67261574 | AT31: 0 | AU31: 0 | AV31: 0 | AW31: =AW30 -> 5.33366 | AZ31: linux_OpenBLAS | BA31: 2 | BB31: WR00L2L2 | BC31: 9792 | BD31: 32 | BE31: 2 | BF31: 2 | BG31: 232.23 | BH31: 2.6959 | BI31: 45559 | BJ31: 0.87186343 | BK31: 0 | BL31: 0 | BM31: 0 | BN31: =BN30 -> 2.73132
A32: noarch-flags | B32: 3 | C32: WR00L2L2 | D32: 9792 | E32: 32 | F32: 2 | G32: 2 | H32: 163.95 | I32: 3.8186 | J32: 45550 | K32: 0.1609375 | L32: 0 | M32: 0 | N32: 0 | O32: =O31 -> 3.8126 | R32: noarch-flags | S32: 3 | T32: WR00L2L2 | U32: 9792 | V32: 32 | W32: 2 | X32: 2 | Y32: 163.49 | Z32: 3.8293 | AA32: 45559 | AB32: 0.80543981 | AC32: 0 | AD32: 0 | AE32: 0 | AF32: =AF31 -> 3.83788 | AI32: linux_OpenBLAS | AJ32: 3 | AK32: WR00L2L2 | AL32: 9792 | AM32: 32 | AN32: 2 | AO32: 2 | AP32: 117.42 | AQ32: 5.3319 | AR32: 45559 | AS32: 0.72677083 | AT32: 0 | AU32: 0 | AV32: 0 | AW32: =AW31 -> 5.33366 | AZ32: linux_OpenBLAS | BA32: 3 | BB32: WR00L2L2 | BC32: 9792 | BD32: 32 | BE32: 2 | BF32: 2 | BG32: 232.47 | BH32: 2.6932 | BI32: 45559 | BJ32: 0.96719907 | BK32: 0 | BL32: 0 | BM32: 0 | BN32: =BN31 -> 2.73132
A33: noarch-flags | B33: 4 | C33: WR00L2L2 | D33: 9792 | E33: 32 | F33: 2 | G33: 2 | H33: 163.94 | I33: 3.8189 | J33: 45550 | K33: 0.23212963 | L33: 0 | M33: 0 | N33: 0 | O33: =O32 -> 3.8126 | R33: noarch-flags | S33: 4 | T33: WR00L2L2 | U33: 9792 | V33: 32 | W33: 2 | X33: 2 | Y33: 163.58 | Z33: 3.8274 | AA33: 45559 | AB33: 0.87638889 | AC33: 0 | AD33: 0 | AE33: 0 | AF33: =AVERAGE(Z33:Z37) -> 4.41406 | AI33: linux_OpenBLAS | AJ33: 4 | AK33: WR00L2L2 | AL33: 9792 | AM33: 32 | AN33: 2 | AO33: 2 | AP33: 117.4 | AQ33: 5.3326 | AR33: 45559 | AS33: 0.78107639 | AT33: 0 | AU33: 0 | AV33: 0 | AW33: =AW32 -> 5.33366 | AZ33: linux_OpenBLAS | BA33: 4 | BB33: WR00L2L2 | BC33: 9792 | BD33: 32 | BE33: 2 | BF33: 2 | BG33: 227.83 | BH33: 2.748 | BI33: 45560 | BJ33: 0.063078704 | BK33: 0 | BL33: 0 | BM33: 0 | BN33: =BN32 -> 2.73132
A34: noarch-flags | B34: 0 | C34: WR00L2L2 | D34: 8768 | E34: 64 | F34: 1 | G34: 4 | H34: 98.84 | I34: 4.5476 | J34: 45549 | K34: 0.90372685 | L34: 0 | M34: 0 | N34: 0 | O34: =AVERAGE(I34:I38) -> 4.54692 | R34: noarch-flags | S34: 0 | T34: WR00L2L2 | U34: 8768 | V34: 64 | W34: 1 | X34: 4 | Y34: 98.6 | Z34: 4.5589 | AA34: 45559 | AB34: 0.54783565 | AC34: 0 | AD34: 0 | AE34: 0 | AF34: =AF33 -> 4.41406 | AI34: linux_OpenBLAS | AJ34: 0 | AK34: WR00L2L2 | AL34: 8768 | AM34: 64 | AN34: 1 | AO34: 4 | AP34: 69.45 | AQ34: 6.4718 | AR34: 45559 | AS34: 0.53107639 | AT34: 0 | AU34: 0 | AV34: 0 | AW34: =AVERAGE(AQ34:AQ38) -> 6.4612 | AZ34: linux_OpenBLAS | BA34: 0 | BB34: WR00L2L2 | BC34: 8768 | BD34: 64 | BE34: 1 | BF34: 4 | BG34: 121.92 | BH34: 3.6869 | BI34: 45559 | BJ34: 0.62157407 | BK34: 0 | BL34: 0 | BM34: 0 | BN34: =AVERAGE(BH34:BH38) -> 3.68536
A35: noarch-flags | B35: 1 | C35: WR00L2L2 | D35: 8768 | E35: 64 | F35: 1 | G35: 4 | H35: 98.9 | I35: 4.5451 | J35: 45549 | K35: 0.975 | L35: 0 | M35: 0 | N35: 0 | O35: =O34 -> 4.54692 | R35: noarch-flags | S35: 1 | T35: WR00L2L2 | U35: 8768 | V35: 64 | W35: 1 | X35: 4 | Y35: 98.53 | Z35: 4.5622 | AA35: 45559 | AB35: 0.61907407 | AC35: 0 | AD35: 0 | AE35: 0 | AF35: =AVERAGE(Z35:Z39) -> 4.56708 | AI35: linux_OpenBLAS | AJ35: 1 | AK35: WR00L2L2 | AL35: 8768 | AM35: 64 | AN35: 1 | AO35: 4 | AP35: 69.59 | AQ35: 6.4593 | AR35: 45559 | AS35: 0.58519676 | AT35: 0 | AU35: 0 | AV35: 0 | AW35: =AW34 -> 6.4612 | AZ35: linux_OpenBLAS | BA35: 1 | BB35: WR00L2L2 | BC35: 8768 | BD35: 64 | BE35: 1 | BF35: 4 | BG35: 122.53 | BH35: 3.6683 | BI35: 45559 | BJ35: 0.7171875 | BK35: 0 | BL35: 0 | BM35: 0 | BN35: =BN34 -> 3.68536
A36: noarch-flags | B36: 2 | C36: WR00L2L2 | D36: 8768 | E36: 64 | F36: 1 | G36: 4 | H36: 98.92 | I36: 4.5442 | J36: 45550 | K36: 0.046145833 | L36: 0 | M36: 0 | N36: 0 | O36: =O35 -> 4.54692 | R36: noarch-flags | S36: 2 | T36: WR00L2L2 | U36: 8768 | V36: 64 | W36: 1 | X36: 4 | Y36: 98.53 | Z36: 4.5619 | AA36: 45559 | AB36: 0.6903125 | AC36: 0 | AD36: 0 | AE36: 0 | AF36: =AF35 -> 4.56708 | AI36: linux_OpenBLAS | AJ36: 2 | AK36: WR00L2L2 | AL36: 8768 | AM36: 64 | AN36: 1 | AO36: 4 | AP36: 69.47 | AQ36: 6.4703 | AR36: 45559 | AS36: 0.6394213 | AT36: 0 | AU36: 0 | AV36: 0 | AW36: =AW35 -> 6.4612 | AZ36: linux_OpenBLAS | BA36: 2 | BB36: WR00L2L2 | BC36: 8768 | BD36: 64 | BE36: 1 | BF36: 4 | BG36: 121.13 | BH36: 3.7108 | BI36: 45559 | BJ36: 0.81236111 | BK36: 0 | BL36: 0 | BM36: 0 | BN36: =BN35 -> 3.68536
A37: noarch-flags | B37: 3 | C37: WR00L2L2 | D37: 8768 | E37: 64 | F37: 1 | G37: 4 | H37: 98.82 | I37: 4.5486 | J37: 45550 | K37: 0.11730324 | L37: 0 | M37: 0 | N37: 0 | O37: =O36 -> 4.54692 | R37: noarch-flags | S37: 3 | T37: WR00L2L2 | U37: 8768 | V37: 64 | W37: 1 | X37: 4 | Y37: 98.57 | Z37: 4.5599 | AA37: 45559 | AB37: 0.76158565 | AC37: 0 | AD37: 0 | AE37: 0 | AF37: =AF36 -> 4.56708 | AI37: linux_OpenBLAS | AJ37: 3 | AK37: WR00L2L2 | AL37: 8768 | AM37: 64 | AN37: 1 | AO37: 4 | AP37: 69.68 | AQ37: 6.4512 | AR37: 45559 | AS37: 0.69356481 | AT37: 0 | AU37: 0 | AV37: 0 | AW37: =AW36 -> 6.4612 | AZ37: linux_OpenBLAS | BA37: 3 | BB37: WR00L2L2 | BC37: 8768 | BD37: 64 | BE37: 1 | BF37: 4 | BG37: 121.99 | BH37: 3.6847 | BI37: 45559 | BJ37: 0.90814815 | BK37: 0 | BL37: 0 | BM37: 0 | BN37: =BN36 -> 3.68536
A38: noarch-flags | B38: 4 | C38: WR00L2L2 | D38: 8768 | E38: 64 | F38: 1 | G38: 4 | H38: 98.81 | I38: 4.5491 | J38: 45550 | K38: 0.18850694 | L38: 0 | M38: 0 | N38: 0 | O38: =O37 -> 4.54692 | R38: noarch-flags | S38: 4 | T38: WR00L2L2 | U38: 8768 | V38: 64 | W38: 1 | X38: 4 | Y38: 98.65 | Z38: 4.5564 | AA38: 45559 | AB38: 0.8328588 | AC38: 0 | AD38: 0 | AE38: 0 | AF38: =AF37 -> 4.56708 | AI38: linux_OpenBLAS | AJ38: 4 | AK38: WR00L2L2 | AL38: 8768 | AM38: 64 | AN38: 1 | AO38: 4 | AP38: 69.65 | AQ38: 6.4534 | AR38: 45559 | AS38: 0.74787037 | AT38: 0 | AU38: 0 | AV38: 0 | AW38: =AW37 -> 6.4612 | AZ38: linux_OpenBLAS | BA38: 4 | BB38: WR00L2L2 | BC38: 8768 | BD38: 64 | BE38: 1 | BF38: 4 | BG38: 122.27 | BH38: 3.6761 | BI38: 45560 | BJ38: 0.0034722222 | BK38: 0 | BL38: 0 | BM38: 0 | BN38: =BN37 -> 3.68536
A39: noarch-flags | B39: 0 | C39: WR00L2L2 | D39: 9280 | E39: 64 | F39: 1 | G39: 4 | H39: 116.39 | I39: 4.5787 | J39: 45549 | K39: 0.92444444 | L39: 0 | M39: 0 | N39: 0 | O39: =AVERAGE(I39:I43) -> 4.58052 | R39: noarch-flags | S39: 0 | T39: WR00L2L2 | U39: 9280 | V39: 64 | W39: 1 | X39: 4 | Y39: 115.98 | Z39: 4.595 | AA39: 45559 | AB39: 0.56861111 | AC39: 0 | AD39: 0 | AE39: 0 | AF39: =AF38 -> 4.56708 | AI39: linux_OpenBLAS | AJ39: 0 | AK39: WR00L2L2 | AL39: 9280 | AM39: 64 | AN39: 1 | AO39: 4 | AP39: 81.48 | AQ39: 6.5402 | AR39: 45559 | AS39: 0.54690972 | AT39: 0 | AU39: 0 | AV39: 0 | AW39: =AVERAGE(AQ39:AQ43) -> 6.53672 | AZ39: linux_OpenBLAS | BA39: 0 | BB39: WR00L2L2 | BC39: 9280 | BD39: 64 | BE39: 1 | BF39: 4 | BG39: 140.85 | BH39: 3.7836 | BI39: 45559 | BJ39: 0.65042824 | BK39: 0 | BL39: 0 | BM39: 0 | BN39: =AVERAGE(BH39:BH43) -> 3.80606
A40: noarch-flags | B40: 1 | C40: WR00L2L2 | D40: 9280 | E40: 64 | F40: 1 | G40: 4 | H40: 116.38 | I40: 4.5791 | J40: 45549 | K40: 0.99571759 | L40: 0 | M40: 0 | N40: 0 | O40: =O39 -> 4.58052 | R40: noarch-flags | S40: 1 | T40: WR00L2L2 | U40: 9280 | V40: 64 | W40: 1 | X40: 4 | Y40: 116.03 | Z40: 4.593 | AA40: 45559 | AB40: 0.63986111 | AC40: 0 | AD40: 0 | AE40: 0 | AF40: =AF39 -> 4.56708 | AI40: linux_OpenBLAS | AJ40: 1 | AK40: WR00L2L2 | AL40: 9280 | AM40: 64 | AN40: 1 | AO40: 4 | AP40: 81.53 | AQ40: 6.5366 | AR40: 45559 | AS40: 0.60106481 | AT40: 0 | AU40: 0 | AV40: 0 | AW40: =AW39 -> 6.53672 | AZ40: linux_OpenBLAS | BA40: 1 | BB40: WR00L2L2 | BC40: 9280 | BD40: 64 | BE40: 1 | BF40: 4 | BG40: 140.7 | BH40: 3.7875 | BI40: 45559 | BJ40: 0.74606481 | BK40: 0 | BL40: 0 | BM40: 0 | BN40: =BN39 -> 3.80606
...

Sheet 4 nodes, params, RAW
A1: Max avg. GFLOPS (and params): | F1: =MAX(X:X) -> 12.012 | G1: =INDEX(D:D,MATCH(MAX($X:$X),$X:$X,0)) -> 19520 | H1: =INDEX(E:E,MATCH(MAX($X:$X),$X:$X,0)) -> 160 | I1: =INDEX(F:F,MATCH(MAX($X:$X),$X:$X,0)) -> 2 | J1: =INDEX(G:G,MATCH(MAX($X:$X),$X:$X,0)) -> 8 | L1: ATLAS (noarch-flags) | X1: Average GFLOP/s | Z1: Max avg. GFLOPS (and params): | AE1: =MAX(AW:AW) -> 13.911 | AF1: =INDEX(AC:AC,MATCH(MAX($AW:$AW),$AW:$AW,0)) -> 19584 | AG1: =INDEX(AD:AD,MATCH(MAX($AW:$AW),$AW:$AW,0)) -> 96 | AH1: =INDEX(AE:AE,MATCH(MAX($AW:$AW),$AW:$AW,0)) -> 2 | AI1: =INDEX(AF:AF,MATCH(MAX($AW:$AW),$AW:$AW,0)) -> 8 | AK1: OpenBLAS | AW1: Average GFLOP/s | AY1: Max avg. GFLOPS (and params): | BD1: =MAX(BU:BU) -> 0 | BE1: =INDEX(BA:BA,MATCH(MAX($BU:$BU),$BU:$BU,0)) -> WR00L2L2 | BF1: =INDEX(BB:BB,MATCH(MAX($BU:$BU),$BU:$BU,0)) -> 17536 | BG1: =INDEX(BC:BC,MATCH(MAX($BU:$BU),$BU:$BU,0)) -> 32 | BH1: =INDEX(BD:BD,MATCH(MAX($BU:$BU),$BU:$BU,0)) -> 1 | BJ1: ATLAS (noarch-flags/atlarch-gene-cpu-flags) - stara mjerenja | BV1: Average GFLOP/s
A2: MAX GFLOPS: | D2: =MAX(I4:I856) -> 12.246 | L2: raspi11 throttling time [1/100s] | O2: raspi12 throttling time [1/100s] | R2: raspi13 throttling time [1/100s] | U2: raspi14 throttling time [1/100s] | Z2: MAX GFLOPS: | AC2: =MAX(AH4:AH855) -> 13.926 | AK2: raspi11 throttling time [1/100s] | AN2: raspi12 throttling time [1/100s] | AQ2: raspi13 throttling time [1/100s] | AT2: raspi14 throttling time [1/100s] | AY2: MAX GFLOPS: | BB2: =MAX(BF4:BF856) -> 7559.93 | BJ2: raspi11 throttling time [1/100s] | BM2: raspi12 throttling time [1/100s] | BP2: raspi13 throttling time [1/100s] | BS2: raspi14 throttling time [1/100s]
