Workbook

Sheet Arch details
A1: SBC | B1: Cores | C1: march | D1: mcpu | E1: mtune | F1: fpu | G1: mfloat-abi | J1: ostalo | K1: ostalo (Thumb)
A2: Rpi 1B | C2: armv6 | D2: arm1176jzf-s | E2: arm1176jzf-s | F2: vfpv2 (alias is vfp) | G2: hard | K2: Thumb | L2: 16KB L1 and no L2
A3: Cubieboard2 | C3: armv7-a | D3: cortex-a7 | E3: cortex-a7 | F3: neon-vfpv4 | G3: hard | J3: -funsafe-math-optimizations | K3: Thumb-2
A4: OdroidU3 | C4: armv7-a | D4: cortex-a9 | E4: cortex-a9 | F4: neon-vfpv3 (alias is neon) | G4: hard | J4: -funsafe-math-optimizations | K4: Thumb or Thumb-2 | L4: 1MB L2 cache total? From paper…
A5: OdroidMC1 | B5: LITTLE | C5: armv7-a | D5: cortex-a7 | E5: cortex-a7 | F5: neon-vfpv4 | G5: hard | J5: -funsafe-math-optimizations | K5: Thumb-2 | L5: 2 sockets, 2,5MB L2 cache per socket
B6: Big | C6: armv7-a | D6: cortex-a15 | E6: cortex-a15 | F6: neon-vfpv4 | G6: hard | J6: -funsafe-math-optimizations | K6: Thumb-2
A12: HPL Runs (fixed parameters) | C12: Number of nodes | D12: Node | E12: Total memory of a node (kB) | F12: N, alpha | G12: N, alpha (NB round) | H12: N, beta | I12: N, beta (NB round) | J12: NB | K12: P | L12: Q | M12: Ns difference | N12: Half of the Ns difference | O12: N1 | P12: N2 | Q12: N3
A13: Number of nodes | B13: 4 | C13: 1 | D13: OdroidU3 | E13: 2019172 | F13: =$B$14*SQRT(($C13*$E13*1024)/8) -> 12861.204 | G13: =_xlfn.CEILING.MATH(F13/J13)*J13 -> 12864 | H13: =SQRT($B$14*($C13*$E13*1024)/8) -> 14379.263 | I13: =_xlfn.CEILING.MATH(H13/J13)*J13 -> 14400 | J13: 64 | K13: 2 | L13: 2 | M13: =I13-G13 -> 1536 | N13: =M13/2 -> 768 | O13: =G13 -> 12864 | P13: =_xlfn.CEILING.MATH((O13+N13)/J13)*J13 -> 13632 | Q13: =_xlfn.CEILING.MATH((P13+N13)/J13)*J13 -> 14400
A14: Percentage of mem | B14: 0.8 | C14: 4 | D14: OdroidU3 | E14: 2019173 | F14: =$B$14*SQRT(($B$13*$E14*1024)/8) -> 25722.415 | G14: =_xlfn.CEILING.MATH(F14/J14)*J14 -> 25728 | H14: =SQRT($B$14*($B$13*$E14*1024)/8) -> 28758.534 | I14: =_xlfn.CEILING.MATH(H14/J14)*J14 -> 28800 | J14: 128 | K14: 2 | L14: 8 | M14: =I14-G14 -> 3072 | N14: =M14/2 -> 1536 | O14: =G14 -> 25728 | P14: =_xlfn.CEILING.MATH((O14+N14)/J14)*J14 -> 27264 | Q14: =_xlfn.CEILING.MATH((P14+N14)/J14)*J14 -> 28800

Sheet HPL_Builds
A1: Raspberry Pi 1B | C1: Flags used for building ATLAS | D1: Flags used for flagsearching - mandatory | E1: Flags used for building HPL | F1: Machine setup for building HPL | G1: Ran? | H1: NOTE

Sheet ATLAS builds
A1: OdroidU3 | C1: Flags used for building | D1: Flags used for flagsearching - mandatory | E1: Flags used for flagsearching - optional | F1: Machine originally built on | G1: Needs flagsearching | H1: Flagsearched (d) | I1: Flagsearched (s) No need! HPL uses only double precision! See ATLAS install manual | J1: Flagsearched (Td) | K1: Kernel | L1: Gflops | M1: NOTE | O1: TODO
A2: 1 | B2: atlarch | C2: -D c -DWALL -b 32 -A ARMa9 | D2: -mcpu=cortex-a9 -fno-schedule-insns -fno-schedule-insns2 | E2: -mcpu=native -mcpu=cortex-a9 -march=native -mtune=cortex-a9 -mfloat-abi=hard -mfpu=neon-vfpv3 | L2: =VLOOKUP(B2,'HPL 4 nodes, builds'!$A$4:$X$43,24,FALSE) -> 12.425
A3: 2 | B3: cpu-tune | C3: -D c -DWALL -b 32 -Fa al "-mcpu=native -mfloat-abi=hard -mfpu=neon-vfpv3" | D3: -mcpu=native -mfloat-abi=hard -mfpu=neon-vfpv3 | L3: =VLOOKUP(B3,'HPL 4 nodes, builds'!$A$4:$X$43,24,FALSE) -> 12.4086
A4: 3 | B4: arch-native-tune | C4: -D c -DWALL -b 32 -Fa al "-march=native -mtune=cortex-a9 -mfloat-abi=hard -mfpu=neon-vfpv3" | D4: -march=native -mtune=cortex-a9 -mfloat-abi=hard -mfpu=neon-vfpv3 | L4: =VLOOKUP(B4,'HPL 4 nodes, builds'!$A$4:$X$43,24,FALSE) -> 12.392
A5: 4 | B5: cpu-tune-overr | C5: -D c -DWALL -b 32 -F al "-mcpu=native -mfloat-abi=hard -mfpu=neon-vfpv3" | D5: -mcpu=native -mfloat-abi=hard -mfpu=neon-vfpv3 | L5: =VLOOKUP(B5,'HPL 4 nodes, builds'!$A$4:$X$43,24,FALSE) -> 11.98
A6: 5 | B6: atlarch-flags | C6: -D c -DWALL -b 32 -Fa alg "-O3 -mcpu=cortex-a9 -fno-schedule-insns -fno-schedule-insns2 -fschedule-insns2 -mfpu=neon-vfpv3 -frename-registers -fno-tree-fre -fno-ivopts" | L6: =VLOOKUP(B6,'HPL 4 nodes, builds'!$A$4:$X$43,24,FALSE) -> 12.435
A7: 6 | B7: cpu-tune-flags | C7: -D c -DWALL -b 32 -Fa alg "-O3 -mcpu=native -mfloat-abi=hard -mfpu=neon-vfpv3 -fno-schedule-insns -frename-registers -fno-tree-fre -fno-ivopts" | L7: =VLOOKUP(B7,'HPL 4 nodes, builds'!$A$4:$X$43,24,FALSE) -> 12.3924
A8: 7 | B8: arch-native-tune-flags | C8: -D c -DWALL -b 32 -Fa alg "-O3 -march=native -mtune=cortex-a9 -mfloat-abi=hard -mfpu=neon-vfpv3 -fno-schedule-insns -frename-registers -fno-tree-fre -fno-ivopts" | L8: =VLOOKUP(B8,'HPL 4 nodes, builds'!$A$4:$X$43,24,FALSE) -> 12.4106
A9: 8 | B9: cpu-tune-overr-flags | C9: -D c -DWALL -b 32 -F alg "-O3 -mcpu=native -mfloat-abi=hard -mfpu=neon-vfpv3 -fno-schedule-insns -frename-registers -fno-tree-fre" | F9: Should not work since we have overriden the VFP with the more advanced one | L9: =VLOOKUP(B9,'HPL 4 nodes, builds'!$A$4:$X$43,24,FALSE) -> 12.441

Sheet HPL 4 nodes, builds
A1: Max avg. GFLOPS (and params): | B1: =INDEX(A:A,MATCH(MAX($X:$X),$X:$X,0)) -> cpu-tune-overr-flags | F1: =MAX(X:X) -> 12.441 | G1: =INDEX(D:D,MATCH(MAX($X:$X),$X:$X,0)) -> 25728 | H1: =INDEX(E:E,MATCH(MAX($X:$X),$X:$X,0)) -> 128 | I1: =INDEX(F:F,MATCH(MAX($X:$X),$X:$X,0)) -> 2 | J1: =INDEX(G:G,MATCH(MAX($X:$X),$X:$X,0)) -> 8 | L1: ATLAS | X1: Average GFLOP/s
A2: MAX GFLOPS: | D2: =MAX(I4:I841) -> 12.491 | L2: Odroid01 throttling time [1/100s] | O2: Odroid02 throttling time [1/100s] | R2: Odroid03 throttling time [1/100s] | U2: Odroid04 throttling time [1/100s]
A3: Build | B3: RUN | D3: N | E3: NB | F3: P | G3: Q | H3: Time | I3: GFLOPS | J3: Date | K3: Time | L3: 1400MHz | M3: 1500MHz | N3: 1600MHz | O3: 1400MHz | P3: 1500MHz | Q3: 1600MHz | R3: 1400MHz | S3: 1500MHz | T3: 1600MHz | U3: 1400MHz | V3: 1500MHz | W3: 1600MHz
A4: cpu-tune-overr-flags | B4: 0 | C4: WR00L2L2 | D4: 25728 | E4: 128 | F4: 2 | G4: 8 | H4: 913.66 | I4: 12.427 | J4: 45458 | K4: 0.0076851852 | L4: 0 | M4: 0 | N4: 0 | O4: 0 | P4: 0 | Q4: 0 | R4: 0 | S4: 0 | T4: 0 | U4: 0 | V4: 0 | W4: 0 | X4: =AVERAGE(I4:I8) -> 12.441
A5: cpu-tune-overr-flags | B5: 1 | C5: WR00L2L2 | D5: 25728 | E5: 128 | F5: 2 | G5: 8 | H5: 915.07 | I5: 12.408 | J5: 45458 | K5: 0.018553241 | L5: 0 | M5: 0 | N5: 0 | O5: 0 | P5: 0 | Q5: 0 | R5: 0 | S5: 0 | T5: 0 | U5: 0 | V5: 0 | W5: 0 | X5: =X4 -> 12.441
A6: cpu-tune-overr-flags | B6: 2 | C6: WR00L2L2 | D6: 25728 | E6: 128 | F6: 2 | G6: 8 | H6: 911.59 | I6: 12.456 | J6: 45458 | K6: 0.029398148 | L6: 0 | M6: 0 | N6: 0 | O6: 0 | P6: 0 | Q6: 0 | R6: 0 | S6: 0 | T6: 0 | U6: 0 | V6: 0 | W6: 0 | X6: =X5 -> 12.441
A7: cpu-tune-overr-flags | B7: 3 | C7: WR00L2L2 | D7: 25728 | E7: 128 | F7: 2 | G7: 8 | H7: 912.19 | I7: 12.447 | J7: 45458 | K7: 0.040231481 | L7: 0 | M7: 0 | N7: 0 | O7: 0 | P7: 0 | Q7: 0 | R7: 0 | S7: 0 | T7: 0 | U7: 0 | V7: 0 | W7: 0 | X7: =X6 -> 12.441
A8: cpu-tune-overr-flags | B8: 4 | C8: WR00L2L2 | D8: 25728 | E8: 128 | F8: 2 | G8: 8 | H8: 910.77 | I8: 12.467 | J8: 45458 | K8: 0.051053241 | L8: 0 | M8: 0 | N8: 0 | O8: 0 | P8: 0 | Q8: 0 | R8: 0 | S8: 0 | T8: 0 | U8: 0 | V8: 0 | W8: 0 | X8: =X7 -> 12.441
A9: atlarch-flags | B9: 0 | C9: WR00L2L2 | D9: 25728 | E9: 128 | F9: 2 | G9: 8 | H9: 913.34 | I9: 12.432 | J9: 45457 | K9: 0.84462963 | L9: 0 | M9: 0 | N9: 0 | O9: 0 | P9: 0 | Q9: 0 | R9: 0 | S9: 0 | T9: 0 | U9: 0 | V9: 0 | W9: 0 | X9: =AVERAGE(I9:I13) -> 12.435
A10: atlarch-flags | B10: 1 | C10: WR00L2L2 | D10: 25728 | E10: 128 | F10: 2 | G10: 8 | H10: 912.83 | I10: 12.439 | J10: 45457 | K10: 0.85548611 | L10: 0 | M10: 0 | N10: 0 | O10: 0 | P10: 0 | Q10: 0 | R10: 0 | S10: 0 | T10: 0 | U10: 0 | V10: 0 | W10: 0 | X10: =X9 -> 12.435
A11: atlarch-flags | B11: 2 | C11: WR00L2L2 | D11: 25728 | E11: 128 | F11: 2 | G11: 8 | H11: 912.23 | I11: 12.447 | J11: 45457 | K11: 0.86631944 | L11: 0 | M11: 0 | N11: 0 | O11: 0 | P11: 0 | Q11: 0 | R11: 0 | S11: 0 | T11: 0 | U11: 0 | V11: 0 | W11: 0 | X11: =X10 -> 12.435
A12: atlarch-flags | B12: 3 | C12: WR00L2L2 | D12: 25728 | E12: 128 | F12: 2 | G12: 8 | H12: 914.19 | I12: 12.42 | J12: 45457 | K12: 0.8771875 | L12: 0 | M12: 0 | N12: 0 | O12: 0 | P12: 0 | Q12: 0 | R12: 0 | S12: 0 | T12: 0 | U12: 0 | V12: 0 | W12: 0 | X12: =X11 -> 12.435
A13: atlarch-flags | B13: 4 | C13: WR00L2L2 | D13: 25728 | E13: 128 | F13: 2 | G13: 8 | H13: 912.93 | I13: 12.437 | J13: 45457 | K13: 0.88803241 | L13: 0 | M13: 0 | N13: 0 | O13: 0 | P13: 0 | Q13: 0 | R13: 0 | S13: 0 | T13: 0 | U13: 0 | V13: 0 | W13: 0 | X13: =X12 -> 12.435
A14: atlarch | B14: 0 | C14: WR00L2L2 | D14: 25728 | E14: 128 | F14: 2 | G14: 8 | H14: 911.8 | I14: 12.453 | J14: 45457 | K14: 0.61020833 | L14: 0 | M14: 0 | N14: 0 | O14: 0 | P14: 0 | Q14: 0 | R14: 0 | S14: 0 | T14: 0 | U14: 0 | V14: 0 | W14: 0 | X14: =AVERAGE(I14:I18) -> 12.425
A15: atlarch | B15: 1 | C15: WR00L2L2 | D15: 25728 | E15: 128 | F15: 2 | G15: 8 | H15: 920.05 | I15: 12.341 | J15: 45457 | K15: 0.62193287 | L15: 0 | M15: 0 | N15: 0 | O15: 0 | P15: 0 | Q15: 0 | R15: 0 | S15: 0 | T15: 0 | U15: 0 | V15: 0 | W15: 0 | X15: =X14 -> 12.425
A16: atlarch | B16: 2 | C16: WR00L2L2 | D16: 25728 | E16: 128 | F16: 2 | G16: 8 | H16: 911.38 | I16: 12.458 | J16: 45457 | K16: 0.63357639 | L16: 0 | M16: 0 | N16: 0 | O16: 0 | P16: 0 | Q16: 0 | R16: 0 | S16: 0 | T16: 0 | U16: 0 | V16: 0 | W16: 0 | X16: =X15 -> 12.425
A17: atlarch | B17: 3 | C17: WR00L2L2 | D17: 25728 | E17: 128 | F17: 2 | G17: 8 | H17: 912.66 | I17: 12.441 | J17: 45457 | K17: 0.64520833 | L17: 0 | M17: 0 | N17: 0 | O17: 0 | P17: 0 | Q17: 0 | R17: 0 | S17: 0 | T17: 0 | U17: 0 | V17: 0 | W17: 0 | X17: =X16 -> 12.425
A18: atlarch | B18: 4 | C18: WR00L2L2 | D18: 25728 | E18: 128 | F18: 2 | G18: 8 | H18: 913.29 | I18: 12.432 | J18: 45457 | K18: 0.65685185 | L18: 0 | M18: 0 | N18: 0 | O18: 0 | P18: 0 | Q18: 0 | R18: 0 | S18: 0 | T18: 0 | U18: 0 | V18: 0 | W18: 0 | X18: =X17 -> 12.425
A19: arch-native-tune-flags | B19: 0 | C19: WR00L2L2 | D19: 25728 | E19: 128 | F19: 2 | G19: 8 | H19: 917.22 | I19: 12.379 | J19: 45457 | K19: 0.95336806 | L19: 0 | M19: 0 | N19: 0 | O19: 0 | P19: 0 | Q19: 0 | R19: 0 | S19: 0 | T19: 0 | U19: 0 | V19: 0 | W19: 0 | X19: =AVERAGE(I19:I23) -> 12.4106
A20: arch-native-tune-flags | B20: 1 | C20: WR00L2L2 | D20: 25728 | E20: 128 | F20: 2 | G20: 8 | H20: 917.91 | I20: 12.37 | J20: 45457 | K20: 0.96427083 | L20: 0 | M20: 0 | N20: 0 | O20: 0 | P20: 0 | Q20: 0 | R20: 0 | S20: 0 | T20: 0 | U20: 0 | V20: 0 | W20: 0 | X20: =X19 -> 12.4106
A21: arch-native-tune-flags | B21: 2 | C21: WR00L2L2 | D21: 25728 | E21: 128 | F21: 2 | G21: 8 | H21: 910.21 | I21: 12.474 | J21: 45457 | K21: 0.97509259 | L21: 0 | M21: 0 | N21: 0 | O21: 0 | P21: 0 | Q21: 0 | R21: 0 | S21: 0 | T21: 0 | U21: 0 | V21: 0 | W21: 0 | X21: =X20 -> 12.4106
A22: arch-native-tune-flags | B22: 3 | C22: WR00L2L2 | D22: 25728 | E22: 128 | F22: 2 | G22: 8 | H22: 913.38 | I22: 12.431 | J22: 45457 | K22: 0.98594907 | L22: 0 | M22: 0 | N22: 0 | O22: 0 | P22: 0 | Q22: 0 | R22: 0 | S22: 0 | T22: 0 | U22: 0 | V22: 0 | W22: 0 | X22: =X21 -> 12.4106
A23: arch-native-tune-flags | B23: 4 | C23: WR00L2L2 | D23: 25728 | E23: 128 | F23: 2 | G23: 8 | H23: 915.73 | I23: 12.399 | J23: 45457 | K23: 0.9968287 | L23: 0 | M23: 0 | N23: 0 | O23: 0 | P23: 0 | Q23: 0 | R23: 0 | S23: 0 | T23: 0 | U23: 0 | V23: 0 | W23: 0 | X23: =X22 -> 12.4106
A24: cpu-tune | B24: 0 | C24: WR00L2L2 | D24: 25728 | E24: 128 | F24: 2 | G24: 8 | H24: 911.9 | I24: 12.451 | J24: 45457 | K24: 0.6684838 | L24: 0 | M24: 0 | N24: 0 | O24: 0 | P24: 0 | Q24: 0 | R24: 0 | S24: 0 | T24: 0 | U24: 0 | V24: 0 | W24: 0 | X24: =AVERAGE(I24:I28) -> 12.4086
A25: cpu-tune | B25: 1 | C25: WR00L2L2 | D25: 25728 | E25: 128 | F25: 2 | G25: 8 | H25: 918.61 | I25: 12.36 | J25: 45457 | K25: 0.68019676 | L25: 0 | M25: 0 | N25: 0 | O25: 0 | P25: 0 | Q25: 0 | R25: 0 | S25: 0 | T25: 0 | U25: 0 | V25: 0 | W25: 0 | X25: =X24 -> 12.4086
A26: cpu-tune | B26: 2 | C26: WR00L2L2 | D26: 25728 | E26: 128 | F26: 2 | G26: 8 | H26: 917.22 | I26: 12.379 | J26: 45457 | K26: 0.69188657 | L26: 0 | M26: 0 | N26: 0 | O26: 0 | P26: 0 | Q26: 0 | R26: 0 | S26: 0 | T26: 0 | U26: 0 | V26: 0 | W26: 0 | X26: =X25 -> 12.4086
A27: cpu-tune | B27: 3 | C27: WR00L2L2 | D27: 25728 | E27: 128 | F27: 2 | G27: 8 | H27: 918.49 | I27: 12.362 | J27: 45457 | K27: 0.70358796 | L27: 0 | M27: 0 | N27: 0 | O27: 0 | P27: 0 | Q27: 0 | R27: 0 | S27: 0 | T27: 0 | U27: 0 | V27: 0 | W27: 0 | X27: =X26 -> 12.4086
A28: cpu-tune | B28: 4 | C28: WR00L2L2 | D28: 25728 | E28: 128 | F28: 2 | G28: 8 | H28: 909.01 | I28: 12.491 | J28: 45457 | K28: 0.71517361 | L28: 0 | M28: 0 | N28: 0 | O28: 0 | P28: 0 | Q28: 0 | R28: 0 | S28: 0 | T28: 0 | U28: 0 | V28: 0 | W28: 0 | X28: =X27 -> 12.4086
A29: cpu-tune-flags | B29: 0 | C29: WR00L2L2 | D29: 25728 | E29: 128 | F29: 2 | G29: 8 | H29: 920.73 | I29: 12.332 | J29: 45457 | K29: 0.89896991 | L29: 0 | M29: 0 | N29: 0 | O29: 0 | P29: 0 | Q29: 0 | R29: 0 | S29: 0 | T29: 0 | U29: 0 | V29: 0 | W29: 0 | X29: =AVERAGE(I29:I33) -> 12.3924
A30: cpu-tune-flags | B30: 1 | C30: WR00L2L2 | D30: 25728 | E30: 128 | F30: 2 | G30: 8 | H30: 911.54 | I30: 12.456 | J30: 45457 | K30: 0.90980324 | L30: 0 | M30: 0 | N30: 0 | O30: 0 | P30: 0 | Q30: 0 | R30: 0 | S30: 0 | T30: 0 | U30: 0 | V30: 0 | W30: 0 | X30: =X29 -> 12.3924
A31: cpu-tune-flags | B31: 2 | C31: WR00L2L2 | D31: 25728 | E31: 128 | F31: 2 | G31: 8 | H31: 919.82 | I31: 12.344 | J31: 45457 | K31: 0.92072917 | L31: 0 | M31: 0 | N31: 0 | O31: 0 | P31: 0 | Q31: 0 | R31: 0 | S31: 0 | T31: 0 | U31: 0 | V31: 0 | W31: 0 | X31: =X30 -> 12.3924
A32: cpu-tune-flags | B32: 3 | C32: WR00L2L2 | D32: 25728 | E32: 128 | F32: 2 | G32: 8 | H32: 915.53 | I32: 12.402 | J32: 45457 | K32: 0.9316088 | L32: 0 | M32: 0 | N32: 0 | O32: 0 | P32: 0 | Q32: 0 | R32: 0 | S32: 0 | T32: 0 | U32: 0 | V32: 0 | W32: 0 | X32: =X31 -> 12.3924
A33: cpu-tune-flags | B33: 4 | C33: WR00L2L2 | D33: 25728 | E33: 128 | F33: 2 | G33: 8 | H33: 913.62 | I33: 12.428 | J33: 45457 | K33: 0.94246528 | L33: 0 | M33: 0 | N33: 0 | O33: 0 | P33: 0 | Q33: 0 | R33: 0 | S33: 0 | T33: 0 | U33: 0 | V33: 0 | W33: 0 | X33: =X32 -> 12.3924
A34: arch-native-tune | B34: 0 | C34: WR00L2L2 | D34: 25728 | E34: 128 | F34: 2 | G34: 8 | H34: 917.17 | I34: 12.38 | J34: 45457 | K34: 0.726875 | L34: 0 | M34: 0 | N34: 0 | O34: 0 | P34: 0 | Q34: 0 | R34: 0 | S34: 0 | T34: 0 | U34: 0 | V34: 0 | W34: 0 | X34: =AVERAGE(I34:I38) -> 12.392
A35: arch-native-tune | B35: 1 | C35: WR00L2L2 | D35: 25728 | E35: 128 | F35: 2 | G35: 8 | H35: 913.98 | I35: 12.423 | J35: 45457 | K35: 0.73851852 | L35: 0 | M35: 0 | N35: 0 | O35: 0 | P35: 0 | Q35: 0 | R35: 0 | S35: 0 | T35: 0 | U35: 0 | V35: 0 | W35: 0 | X35: =X34 -> 12.392
A36: arch-native-tune | B36: 2 | C36: WR00L2L2 | D36: 25728 | E36: 128 | F36: 2 | G36: 8 | H36: 918.22 | I36: 12.366 | J36: 45457 | K36: 0.75021991 | L36: 0 | M36: 0 | N36: 0 | O36: 0 | P36: 0 | Q36: 0 | R36: 0 | S36: 0 | T36: 0 | U36: 0 | V36: 0 | W36: 0 | X36: =X35 -> 12.392
A37: arch-native-tune | B37: 3 | C37: WR00L2L2 | D37: 25728 | E37: 128 | F37: 2 | G37: 8 | H37: 919.18 | I37: 12.353 | J37: 45457 | K37: 0.76193287 | L37: 0 | M37: 0 | N37: 0 | O37: 0 | P37: 0 | Q37: 0 | R37: 0 | S37: 0 | T37: 0 | U37: 0 | V37: 0 | W37: 0 | X37: =X36 -> 12.392
A38: arch-native-tune | B38: 4 | C38: WR00L2L2 | D38: 25728 | E38: 128 | F38: 2 | G38: 8 | H38: 912.87 | I38: 12.438 | J38: 45457 | K38: 0.77356481 | L38: 0 | M38: 0 | N38: 0 | O38: 0 | P38: 0 | Q38: 0 | R38: 0 | S38: 0 | T38: 0 | U38: 0 | V38: 0 | W38: 0 | X38: =X37 -> 12.392
A39: cpu-tune-overr | B39: 0 | C39: WR00L2L2 | D39: 25728 | E39: 128 | F39: 2 | G39: 8 | H39: 953.67 | I39: 11.906 | J39: 45457 | K39: 0.78568287 | L39: 0 | M39: 0 | N39: 0 | O39: 0 | P39: 0 | Q39: 0 | R39: 0 | S39: 0 | T39: 0 | U39: 0 | V39: 0 | W39: 0 | X39: =AVERAGE(I39:I43) -> 11.98
A40: cpu-tune-overr | B40: 1 | C40: WR00L2L2 | D40: 25728 | E40: 128 | F40: 2 | G40: 8 | H40: 945.1 | I40: 12.014 | J40: 45457 | K40: 0.79768519 | L40: 0 | M40: 0 | N40: 0 | O40: 0 | P40: 0 | Q40: 0 | R40: 0 | S40: 0 | T40: 0 | U40: 0 | V40: 0 | W40: 0 | X40: =X39 -> 11.98
...

Sheet 1 node, params, RAW
A1: Max avg. GFLOPS (and params): | E1: =MAX(N:N) -> 4.4801 | F1: =INDEX(C:C,MATCH(MAX($N:$N),$N:$N,0)) -> 14400 | G1: =INDEX(D:D,MATCH(MAX($N:$N),$N:$N,0)) -> 96 | H1: =INDEX(E:E,MATCH(MAX($N:$N),$N:$N,0)) -> 2 | I1: =INDEX(F:F,MATCH(MAX($N:$N),$N:$N,0)) -> 2 | K1: ATLAS (cpu-tune-overr-flags) | N1: Average GFLOP/s | P1: Max avg. GFLOPS (and params): | T1: =MAX(AC:AC) -> 4.4017 | U1: =INDEX(R:R,MATCH(MAX($AC:$AC),$AC:$AC,0)) -> 14400 | V1: =INDEX(S:S,MATCH(MAX($AC:$AC),$AC:$AC,0)) -> 192 | W1: =INDEX(T:T,MATCH(MAX($AC:$AC),$AC:$AC,0)) -> 1 | X1: =INDEX(U:U,MATCH(MAX($AC:$AC),$AC:$AC,0)) -> 4 | Z1: OpenBLAS | AC1: Average GFLOP/s
A2: MAX GFLOPS: | C2: =MAX(H4:H840) -> 4.4859 | K2: Odroid01 throttling time [1/100s] | P2: MAX GFLOPS: | R2: =MAX(W4:W841) -> 4.4464 | Z2: Odroid02 throttling time [1/100s]
A3: RUN | C3: N | D3: NB | E3: P | F3: Q | G3: Time | H3: GFLOPS | I3: Date | J3: Time | K3: 1400MHz | L3: 1500MHz | M3: 1600MHz | P3: RUN | R3: N | S3: NB | T3: P | U3: Q | V3: Time | W3: GFLOPS | X3: Date | Y3: Time | Z3: 1400MHz | AA3: 1500MHz | AB3: 1600MHz
A4: 0 | B4: WR00L2L2 | C4: 12864 | D4: 32 | E4: 1 | F4: 4 | G4: 364.79 | H4: 3.8911 | I4: 45474 | J4: 0.50143519 | K4: 0 | L4: 0 | M4: 0 | N4: =AVERAGE(H4:H8) -> 3.93302 | P4: 0 | Q4: WR00L2L2 | R4: 12864 | S4: 32 | T4: 1 | U4: 4 | V4: 403.34 | W4: 3.5192 | X4: 45474 | Y4: 0.50275463 | Z4: 0 | AA4: 0 | AB4: 0 | AC4: =AVERAGE(W4:W8) -> 3.5624
A5: 1 | B5: WR00L2L2 | C5: 12864 | D5: 32 | E5: 1 | F5: 4 | G5: 362.54 | H5: 3.9153 | I5: 45474 | J5: 0.7353588 | K5: 0 | L5: 0 | M5: 0 | P5: 1 | Q5: WR00L2L2 | R5: 12864 | S5: 32 | T5: 1 | U5: 4 | V5: 397.66 | W5: 3.5695 | X5: 45474 | Y5: 0.78759259 | Z5: 0 | AA5: 0 | AB5: 0
A6: 2 | B6: WR00L2L2 | C6: 12864 | D6: 32 | E6: 1 | F6: 4 | G6: 359.95 | H6: 3.9434 | I6: 45474 | J6: 0.96913194 | K6: 0 | L6: 0 | M6: 0 | P6: 2 | Q6: WR00L2L2 | R6: 12864 | S6: 32 | T6: 1 | U6: 4 | V6: 397.75 | W6: 3.5686 | X6: 45475 | Y6: 0.07162037 | Z6: 0 | AA6: 0 | AB6: 0
A7: 3 | B7: WR00L2L2 | C7: 12864 | D7: 32 | E7: 1 | F7: 4 | G7: 359.17 | H7: 3.952 | I7: 45475 | J7: 0.20274306 | K7: 0 | L7: 0 | M7: 0 | P7: 3 | Q7: WR00L2L2 | R7: 12864 | S7: 32 | T7: 1 | U7: 4 | V7: 395.76 | W7: 3.5866 | X7: 45475 | Y7: 0.3553125 | Z7: 0 | AA7: 0 | AB7: 0
A8: 4 | B8: WR00L2L2 | C8: 12864 | D8: 32 | E8: 1 | F8: 4 | G8: 358.15 | H8: 3.9633 | I8: 45475 | J8: 0.43623843 | K8: 0 | L8: 0 | M8: 0 | P8: 4 | Q8: WR00L2L2 | R8: 12864 | S8: 32 | T8: 1 | U8: 4 | V8: 397.81 | W8: 3.5681 | X8: 45475 | Y8: 0.63900463 | Z8: 0 | AA8: 0 | AB8: 0
A9: 0 | B9: WR00L2L2 | C9: 13632 | D9: 32 | E9: 1 | F9: 4 | G9: 442.37 | H9: 3.8184 | I9: 45474 | J9: 0.56765046 | K9: 0 | L9: 0 | M9: 0 | N9: =AVERAGE(H9:H13) -> 3.8564 | P9: 0 | Q9: WR00L2L2 | R9: 13632 | S9: 32 | T9: 1 | U9: 4 | V9: 465.9 | W9: 3.6255 | X9: 45474 | Y9: 0.58527778 | Z9: 0 | AA9: 0 | AB9: 0 | AC9: =AVERAGE(W9:W13) -> 3.62406
A10: 1 | B10: WR00L2L2 | C10: 13632 | D10: 32 | E10: 1 | F10: 4 | G10: 439.55 | H10: 3.8429 | I10: 45474 | J10: 0.80146991 | K10: 0 | L10: 0 | M10: 0 | P10: 1 | Q10: WR00L2L2 | R10: 13632 | S10: 32 | T10: 1 | U10: 4 | V10: 465.74 | W10: 3.6268 | X10: 45474 | Y10: 0.87 | Z10: 0 | AA10: 0 | AB10: 0
A11: 2 | B11: WR00L2L2 | C11: 13632 | D11: 32 | E11: 1 | F11: 4 | G11: 438.1 | H11: 3.8555 | I11: 45475 | J11: 0.035196759 | K11: 0 | L11: 0 | M11: 0 | P11: 2 | Q11: WR00L2L2 | R11: 13632 | S11: 32 | T11: 1 | U11: 4 | V11: 467.73 | W11: 3.6113 | X11: 45475 | Y11: 0.15378472 | Z11: 0 | AA11: 0 | AB11: 0
A12: 3 | B12: WR00L2L2 | C12: 13632 | D12: 32 | E12: 1 | F12: 4 | G12: 434.6 | H12: 3.8866 | I12: 45475 | J12: 0.2687037 | K12: 0 | L12: 0 | M12: 0 | P12: 3 | Q12: WR00L2L2 | R12: 13632 | S12: 32 | T12: 1 | U12: 4 | V12: 465.5 | W12: 3.6286 | X12: 45475 | Y12: 0.43761574 | Z12: 0 | AA12: 0 | AB12: 0
A13: 4 | B13: WR00L2L2 | C13: 13632 | D13: 32 | E13: 1 | F13: 4 | G13: 435.5 | H13: 3.8786 | I13: 45475 | J13: 0.50222222 | K13: 0 | L13: 0 | M13: 0 | P13: 4 | Q13: WR00L2L2 | R13: 13632 | S13: 32 | T13: 1 | U13: 4 | V13: 465.57 | W13: 3.6281 | X13: 45475 | Y13: 0.72135417 | Z13: 0 | AA13: 0 | AB13: 0
A14: 0 | B14: WR00L2L2 | C14: 14400 | D14: 32 | E14: 1 | F14: 4 | G14: 497.96 | H14: 3.9982 | I14: 45474 | J14: 0.64619213 | K14: 0 | L14: 0 | M14: 0 | N14: =AVERAGE(H14:H18) -> 3.95198 | P14: 0 | Q14: WR00L2L2 | R14: 14400 | S14: 32 | T14: 1 | U14: 4 | V14: 530.91 | W14: 3.7501 | X14: 45474 | Y14: 0.68056713 | Z14: 0 | AA14: 0 | AB14: 0 | AC14: =AVERAGE(W14:W18) -> 3.72338
A15: 1 | B15: WR00L2L2 | C15: 14400 | D15: 32 | E15: 1 | F15: 4 | G15: 506.11 | H15: 3.9339 | I15: 45474 | J15: 0.87993056 | K15: 0 | L15: 0 | M15: 0 | P15: 1 | Q15: WR00L2L2 | R15: 14400 | S15: 32 | T15: 1 | U15: 4 | V15: 535.69 | W15: 3.7166 | X15: 45474 | Y15: 0.96503472 | Z15: 0 | AA15: 0 | AB15: 0
A16: 2 | B16: WR00L2L2 | C16: 14400 | D16: 32 | E16: 1 | F16: 4 | G16: 506.08 | H16: 3.9341 | I16: 45475 | J16: 0.11358796 | K16: 0 | L16: 0 | M16: 0 | P16: 2 | Q16: WR00L2L2 | R16: 14400 | S16: 32 | T16: 1 | U16: 4 | V16: 535.07 | W16: 3.721 | X16: 45475 | Y16: 0.24886574 | Z16: 0 | AA16: 0 | AB16: 0
A17: 3 | B17: WR00L2L2 | C17: 14400 | D17: 32 | E17: 1 | F17: 4 | G17: 504.58 | H17: 3.9458 | I17: 45475 | J17: 0.34710648 | K17: 0 | L17: 0 | M17: 0 | P17: 3 | Q17: WR00L2L2 | R17: 14400 | S17: 32 | T17: 1 | U17: 4 | V17: 535.15 | W17: 3.7204 | X17: 45475 | Y17: 0.53247685 | Z17: 0 | AA17: 0 | AB17: 0
A18: 4 | B18: WR00L2L2 | C18: 14400 | D18: 32 | E18: 1 | F18: 4 | G18: 504.31 | H18: 3.9479 | I18: 45475 | J18: 0.58054398 | K18: 0 | L18: 0 | M18: 0 | P18: 4 | Q18: WR00L2L2 | R18: 14400 | S18: 32 | T18: 1 | U18: 4 | V18: 536.82 | W18: 3.7088 | X18: 45475 | Y18: 0.81579861 | Z18: 0 | AA18: 0 | AB18: 0
A19: 0 | B19: WR00L2L2 | C19: 12864 | D19: 32 | E19: 2 | F19: 2 | G19: 362.61 | H19: 3.9144 | I19: 45474 | J19: 0.50581019 | K19: 0 | L19: 0 | M19: 0 | N19: =AVERAGE(H19:H23) -> 3.9397 | P19: 0 | Q19: WR00L2L2 | R19: 12864 | S19: 32 | T19: 2 | U19: 2 | V19: 401.01 | W19: 3.5396 | X19: 45474 | Y19: 0.50840278 | Z19: 0 | AA19: 0 | AB19: 0 | AC19: =AVERAGE(W19:W23) -> 3.56798
A20: 1 | B20: WR00L2L2 | C20: 12864 | D20: 32 | E20: 2 | F20: 2 | G20: 360.47 | H20: 3.9377 | I20: 45474 | J20: 0.73972222 | K20: 0 | L20: 0 | M20: 0 | P20: 1 | Q20: WR00L2L2 | R20: 12864 | S20: 32 | T20: 2 | U20: 2 | V20: 397.56 | W20: 3.5703 | X20: 45474 | Y20: 0.79320602 | Z20: 0 | AA20: 0 | AB20: 0
A21: 2 | B21: WR00L2L2 | C21: 12864 | D21: 32 | E21: 2 | F21: 2 | G21: 360.09 | H21: 3.9419 | I21: 45474 | J21: 0.9734838 | K21: 0 | L21: 0 | M21: 0 | P21: 2 | Q21: WR00L2L2 | R21: 12864 | S21: 32 | T21: 2 | U21: 2 | V21: 396.29 | W21: 3.5818 | X21: 45475 | Y21: 0.077222222 | Z21: 0 | AA21: 0 | AB21: 0
A22: 3 | B22: WR00L2L2 | C22: 12864 | D22: 32 | E22: 2 | F22: 2 | G22: 359.69 | H22: 3.9462 | I22: 45475 | J22: 0.20708333 | K22: 0 | L22: 0 | M22: 0 | P22: 3 | Q22: WR00L2L2 | R22: 12864 | S22: 32 | T22: 2 | U22: 2 | V22: 397.1 | W22: 3.5745 | X22: 45475 | Y22: 0.36092593 | Z22: 0 | AA22: 0 | AB22: 0
A23: 4 | B23: WR00L2L2 | C23: 12864 | D23: 32 | E23: 2 | F23: 2 | G23: 358.59 | H23: 3.9583 | I23: 45475 | J23: 0.44056713 | K23: 0 | L23: 0 | M23: 0 | P23: 4 | Q23: WR00L2L2 | R23: 12864 | S23: 32 | T23: 2 | U23: 2 | V23: 397.18 | W23: 3.5737 | X23: 45475 | Y23: 0.64460648 | Z23: 0 | AA23: 0 | AB23: 0
A24: 0 | B24: WR00L2L2 | C24: 13632 | D24: 32 | E24: 2 | F24: 2 | G24: 435.7 | H24: 3.8768 | I24: 45474 | J24: 0.57290509 | K24: 0 | L24: 0 | M24: 0 | N24: =AVERAGE(H24:H28) -> 3.89724 | P24: 0 | Q24: WR00L2L2 | R24: 13632 | S24: 32 | T24: 2 | U24: 2 | V24: 465.56 | W24: 3.6281 | X24: 45474 | Y24: 0.59179398 | Z24: 0 | AA24: 0 | AB24: 0 | AC24: =AVERAGE(W24:W28) -> 3.6387
A25: 1 | B25: WR00L2L2 | C25: 13632 | D25: 32 | E25: 2 | F25: 2 | G25: 433.24 | H25: 3.8988 | I25: 45474 | J25: 0.80668981 | K25: 0 | L25: 0 | M25: 0 | P25: 1 | Q25: WR00L2L2 | R25: 13632 | S25: 32 | T25: 2 | U25: 2 | V25: 462.2 | W25: 3.6545 | X25: 45474 | Y25: 0.87648148 | Z25: 0 | AA25: 0 | AB25: 0
A26: 2 | B26: WR00L2L2 | C26: 13632 | D26: 32 | E26: 2 | F26: 2 | G26: 433.46 | H26: 3.8969 | I26: 45475 | J26: 0.040416667 | K26: 0 | L26: 0 | M26: 0 | P26: 2 | Q26: WR00L2L2 | R26: 13632 | S26: 32 | T26: 2 | U26: 2 | V26: 464.24 | W26: 3.6384 | X26: 45475 | Y26: 0.16028935 | Z26: 0 | AA26: 0 | AB26: 0
A27: 3 | B27: WR00L2L2 | C27: 13632 | D27: 32 | E27: 2 | F27: 2 | G27: 432.75 | H27: 3.9032 | I27: 45475 | J27: 0.27392361 | K27: 0 | L27: 0 | M27: 0 | P27: 3 | Q27: WR00L2L2 | R27: 13632 | S27: 32 | T27: 2 | U27: 2 | V27: 464.65 | W27: 3.6352 | X27: 45475 | Y27: 0.4441088 | Z27: 0 | AA27: 0 | AB27: 0
A28: 4 | B28: WR00L2L2 | C28: 13632 | D28: 32 | E28: 2 | F28: 2 | G28: 431.94 | H28: 3.9105 | I28: 45475 | J28: 0.50743056 | K28: 0 | L28: 0 | M28: 0 | P28: 4 | Q28: WR00L2L2 | R28: 13632 | S28: 32 | T28: 2 | U28: 2 | V28: 464.38 | W28: 3.6373 | X28: 45475 | Y28: 0.72782407 | Z28: 0 | AA28: 0 | AB28: 0
A29: 0 | B29: WR00L2L2 | C29: 14400 | D29: 32 | E29: 2 | F29: 2 | G29: 508.24 | H29: 3.9174 | I29: 45474 | J29: 0.65230324 | K29: 0 | L29: 0 | M29: 0 | N29: =AVERAGE(H29:H33) -> 3.926 | P29: 0 | Q29: WR00L2L2 | R29: 14400 | S29: 32 | T29: 2 | U29: 2 | V29: 535.74 | W29: 3.7163 | X29: 45474 | Y29: 0.68802083 | Z29: 0 | AA29: 0 | AB29: 0 | AC29: =AVERAGE(W29:W33) -> 3.71718
A30: 1 | B30: WR00L2L2 | C30: 14400 | D30: 32 | E30: 2 | F30: 2 | G30: 507.26 | H30: 3.9249 | I30: 45474 | J30: 0.88601852 | K30: 0 | L30: 0 | M30: 0 | P30: 1 | Q30: WR00L2L2 | R30: 14400 | S30: 32 | T30: 2 | U30: 2 | V30: 535.14 | W30: 3.7204 | X30: 45474 | Y30: 0.97247685 | Z30: 0 | AA30: 0 | AB30: 0
A31: 2 | B31: WR00L2L2 | C31: 14400 | D31: 32 | E31: 2 | F31: 2 | G31: 506.91 | H31: 3.9276 | I31: 45475 | J31: 0.11967593 | K31: 0 | L31: 0 | M31: 0 | P31: 2 | Q31: WR00L2L2 | R31: 14400 | S31: 32 | T31: 2 | U31: 2 | V31: 536.6 | W31: 3.7103 | X31: 45475 | Y31: 0.25633102 | Z31: 0 | AA31: 0 | AB31: 0
A32: 3 | B32: WR00L2L2 | C32: 14400 | D32: 32 | E32: 2 | F32: 2 | G32: 507.17 | H32: 3.9257 | I32: 45475 | J32: 0.35320602 | K32: 0 | L32: 0 | M32: 0 | P32: 3 | Q32: WR00L2L2 | R32: 14400 | S32: 32 | T32: 2 | U32: 2 | V32: 534.45 | W32: 3.7252 | X32: 45475 | Y32: 0.53990741 | Z32: 0 | AA32: 0 | AB32: 0
A33: 4 | B33: WR00L2L2 | C33: 14400 | D33: 32 | E33: 2 | F33: 2 | G33: 506.05 | H33: 3.9344 | I33: 45475 | J33: 0.58663194 | K33: 0 | L33: 0 | M33: 0 | P33: 4 | Q33: WR00L2L2 | R33: 14400 | S33: 32 | T33: 2 | U33: 2 | V33: 536.11 | W33: 3.7137 | X33: 45475 | Y33: 0.82322917 | Z33: 0 | AA33: 0 | AB33: 0
A34: 0 | B34: WR00L2L2 | C34: 12864 | D34: 64 | E34: 1 | F34: 4 | G34: 330.64 | H34: 4.2929 | I34: 45474 | J34: 0.50983796 | K34: 0 | L34: 0 | M34: 0 | N34: =AVERAGE(H34:H38) -> 4.31218 | P34: 0 | Q34: WR00L2L2 | R34: 12864 | S34: 64 | T34: 1 | U34: 4 | V34: 357.3 | W34: 3.9726 | X34: 45474 | Y34: 0.51355324 | Z34: 0 | AA34: 0 | AB34: 0 | AC34: =AVERAGE(W34:W38) -> 3.9991
A35: 1 | B35: WR00L2L2 | C35: 12864 | D35: 64 | E35: 1 | F35: 4 | G35: 330.44 | H35: 4.2955 | I35: 45474 | J35: 0.74373843 | K35: 0 | L35: 0 | M35: 0 | P35: 1 | Q35: WR00L2L2 | R35: 12864 | S35: 64 | T35: 1 | U35: 4 | V35: 355.83 | W35: 3.9891 | X35: 45474 | Y35: 0.79833333 | Z35: 0 | AA35: 0 | AB35: 0
A36: 2 | B36: WR00L2L2 | C36: 12864 | D36: 64 | E36: 1 | F36: 4 | G36: 328.25 | H36: 4.3242 | I36: 45474 | J36: 0.97747685 | K36: 0 | L36: 0 | M36: 0 | P36: 2 | Q36: WR00L2L2 | R36: 12864 | S36: 64 | T36: 1 | U36: 4 | V36: 353.61 | W36: 4.0141 | X36: 45475 | Y36: 0.082314815 | Z36: 0 | AA36: 0 | AB36: 0
A37: 3 | B37: WR00L2L2 | C37: 12864 | D37: 64 | E37: 1 | F37: 4 | G37: 327.76 | H37: 4.3307 | I37: 45475 | J37: 0.21106481 | K37: 0 | L37: 0 | M37: 0 | P37: 3 | Q37: WR00L2L2 | R37: 12864 | S37: 64 | T37: 1 | U37: 4 | V37: 353.8 | W37: 4.012 | X37: 45475 | Y37: 0.36603009 | Z37: 0 | AA37: 0 | AB37: 0
A38: 4 | B38: WR00L2L2 | C38: 12864 | D38: 64 | E38: 1 | F38: 4 | G38: 328.76 | H38: 4.3176 | I38: 45475 | J38: 0.44456019 | K38: 0 | L38: 0 | M38: 0 | P38: 4 | Q38: WR00L2L2 | R38: 12864 | S38: 64 | T38: 1 | U38: 4 | V38: 354.17 | W38: 4.0077 | X38: 45475 | Y38: 0.64972222 | Z38: 0 | AA38: 0 | AB38: 0
A39: 0 | B39: WR00L2L2 | C39: 13632 | D39: 64 | E39: 1 | F39: 4 | G39: 402.16 | H39: 4.2001 | I39: 45474 | J39: 0.5777662 | K39: 0 | L39: 0 | M39: 0 | N39: =AVERAGE(H39:H43) -> 4.23126 | P39: 0 | Q39: WR00L2L2 | R39: 13632 | S39: 64 | T39: 1 | U39: 4 | V39: 416.04 | W39: 4.06 | X39: 45474 | Y39: 0.59773148 | Z39: 0 | AA39: 0 | AB39: 0 | AC39: =AVERAGE(W39:W43) -> 4.06798
A40: 1 | B40: WR00L2L2 | C40: 13632 | D40: 64 | E40: 1 | F40: 4 | G40: 399.81 | H40: 4.2248 | I40: 45474 | J40: 0.81152778 | K40: 0 | L40: 0 | M40: 0 | P40: 1 | Q40: WR00L2L2 | R40: 13632 | S40: 64 | T40: 1 | U40: 4 | V40: 414.04 | W40: 4.0796 | X40: 45474 | Y40: 0.88240741 | Z40: 0 | AA40: 0 | AB40: 0
...

Sheet 4 node, params, RAW
A1: Max avg. GFLOPS (and params): | E1: =MAX(W:W) -> 13.4608 | F1: =INDEX(C:C,MATCH(MAX($W:$W),$W:$W,0)) -> 28800 | G1: =INDEX(D:D,MATCH(MAX($W:$W),$W:$W,0)) -> 96 | H1: =INDEX(E:E,MATCH(MAX($W:$W),$W:$W,0)) -> 2 | I1: =INDEX(F:F,MATCH(MAX($W:$W),$W:$W,0)) -> 8 | K1: ATLAS (cpu-tune-overr-flags) | W1: Average GFLOP/s | Y1: Max avg. GFLOPS (and params): | AC1: =MAX(AU:AU) -> 13.102 | AD1: =INDEX(AA:AA,MATCH(MAX($AU:$AU),$AU:$AU,0)) -> 28800 | AE1: =INDEX(AB:AB,MATCH(MAX($AU:$AU),$AU:$AU,0)) -> 160 | AF1: =INDEX(AC:AC,MATCH(MAX($AU:$AU),$AU:$AU,0)) -> 2 | AG1: =INDEX(AD:AD,MATCH(MAX($AU:$AU),$AU:$AU,0)) -> 8 | AI1: OpenBLAS | AU1: Average GFLOP/s
A2: MAX GFLOPS: | C2: =MAX(H4:H840) -> 13.509 | K2: Odroid01 throttling time [1/100s] | N2: Odroid02 throttling time [1/100s] | Q2: Odroid03 throttling time [1/100s] | T2: Odroid04 throttling time [1/100s] | Y2: MAX GFLOPS: | AA2: =MAX(AF4:AF841) -> 13.2 | AI2: Odroid01 throttling time [1/100s] | AL2: Odroid02 throttling time [1/100s] | AO2: Odroid03 throttling time [1/100s] | AR2: Odroid04 throttling time [1/100s]
A3: RUN | C3: N | D3: NB | E3: P | F3: Q | G3: Time | H3: GFLOPS | I3: Date | J3: Time | K3: 1400MHz | L3: 1500MHz | M3: 1600MHz | N3: 1400MHz | O3: 1500MHz | P3: 1600MHz | Q3: 1400MHz | R3: 1500MHz | S3: 1600MHz | T3: 1400MHz | U3: 1500MHz | V3: 1600MHz | Y3: RUN | AA3: N | AB3: NB | AC3: P | AD3: Q | AE3: Time | AF3: GFLOPS | AG3: Date | AH3: Time | AI3: 1400MHz | AJ3: 1500MHz | AK3: 1600MHz | AL3: 1400MHz | AM3: 1500MHz | AN3: 1600MHz | AO3: 1400MHz | AP3: 1500MHz | AQ3: 1600MHz | AR3: 1400MHz | AS3: 1500MHz | AT3: 1600MHz
A4: 0 | B4: WR00L2L2 | C4: 25728 | D4: 32 | E4: 1 | F4: 16 | G4: 1094.52 | H4: 10.374 | I4: 45458 | J4: 0.88520833 | K4: 0 | L4: 0 | M4: 0 | N4: 0 | O4: 0 | P4: 0 | Q4: 0 | R4: 0 | S4: 0 | T4: 0 | U4: 0 | V4: 0 | W4: =AVERAGE(H4:H8) -> 10.3756 | Y4: 0 | Z4: WR00L2L2 | AA4: 25728 | AB4: 32 | AC4: 1 | AD4: 16 | AE4: 1096.15 | AF4: 10.358 | AG4: 45468 | AH4: 0.6746875 | AI4: 0 | AJ4: 0 | AK4: 0 | AL4: 0 | AM4: 0 | AN4: 0 | AO4: 0 | AP4: 0 | AQ4: 0 | AR4: 0 | AS4: 0 | AT4: 0 | AU4: =AVERAGE(AF4:AF8) -> 10.3794 | AW4: 25728 | AX4: 32 | AY4: 1 | AZ4: 16 | BA4: 1052.7 | BB4: 10.786
A5: 1 | B5: WR00L2L2 | C5: 25728 | D5: 32 | E5: 1 | F5: 16 | G5: 1093.46 | H5: 10.384 | I5: 45459 | J5: 0.90586806 | K5: 0 | L5: 0 | M5: 0 | N5: 0 | O5: 0 | P5: 0 | Q5: 0 | R5: 0 | S5: 0 | T5: 0 | U5: 0 | V5: 0 | Y5: 1 | Z5: WR00L2L2 | AA5: 25728 | AB5: 32 | AC5: 1 | AD5: 16 | AE5: 1090.98 | AF5: 10.407 | AG5: 45469 | AH5: 0.72635417 | AI5: 0 | AJ5: 0 | AK5: 0 | AL5: 0 | AM5: 0 | AN5: 0 | AO5: 0 | AP5: 0 | AQ5: 0 | AR5: 0 | AS5: 0 | AT5: 0 | AW5: 25728 | AX5: 32 | AY5: 2 | AZ5: 8 | BA5: 922.22 | BB5: 12.312
A6: 2 | B6: WR00L2L2 | C6: 25728 | D6: 32 | E6: 1 | F6: 16 | G6: 1091.4 | H6: 10.403 | I6: 45460 | J6: 0.925625 | K6: 0 | L6: 0 | M6: 0 | N6: 0 | O6: 0 | P6: 0 | Q6: 0 | R6: 0 | S6: 0 | T6: 0 | U6: 0 | V6: 0 | Y6: 2 | Z6: WR00L2L2 | AA6: 25728 | AB6: 32 | AC6: 1 | AD6: 16 | AE6: 1090.68 | AF6: 10.41 | AG6: 45471 | AH6: 0.11702546 | AI6: 0 | AJ6: 0 | AK6: 0 | AL6: 0 | AM6: 0 | AN6: 0 | AO6: 0 | AP6: 0 | AQ6: 0 | AR6: 0 | AS6: 0 | AT6: 0 | AW6: 25728 | AX6: 32 | AY6: 4 | AZ6: 4 | BA6: 1080.93 | BB6: 10.504
A7: 3 | B7: WR00L2L2 | C7: 25728 | D7: 32 | E7: 1 | F7: 16 | G7: 1099.48 | H7: 10.327 | I7: 45462 | J7: 0.25577546 | K7: 0 | L7: 0 | M7: 0 | N7: 0 | O7: 0 | P7: 0 | Q7: 0 | R7: 0 | S7: 0 | T7: 0 | U7: 0 | V7: 0 | Y7: 3 | Z7: WR00L2L2 | AA7: 25728 | AB7: 32 | AC7: 1 | AD7: 16 | AE7: 1095.06 | AF7: 10.369 | AG7: 45472 | AH7: 0.17164352 | AI7: 0 | AJ7: 0 | AK7: 0 | AL7: 0 | AM7: 0 | AN7: 0 | AO7: 0 | AP7: 0 | AQ7: 0 | AR7: 0 | AS7: 0 | AT7: 0 | AW7: 25728 | AX7: 64 | AY7: 1 | AZ7: 16 | BA7: 984.54 | BB7: 11.533
A8: 4 | B8: WR00L2L2 | C8: 25728 | D8: 32 | E8: 1 | F8: 16 | G8: 1092.83 | H8: 10.39 | I8: 45465 | J8: 0.33240741 | K8: 0 | L8: 0 | M8: 0 | N8: 0 | O8: 0 | P8: 0 | Q8: 0 | R8: 0 | S8: 0 | T8: 0 | U8: 0 | V8: 0 | Y8: 4 | Z8: WR00L2L2 | AA8: 25728 | AB8: 32 | AC8: 1 | AD8: 16 | AE8: 1096.68 | AF8: 10.353 | AG8: 45473 | AH8: 0.22655093 | AI8: 0 | AJ8: 0 | AK8: 0 | AL8: 0 | AM8: 0 | AN8: 0 | AO8: 0 | AP8: 0 | AQ8: 0 | AR8: 0 | AS8: 0 | AT8: 0 | AW8: 25728 | AX8: 64 | AY8: 2 | AZ8: 8 | BA8: 864.46 | BB8: 13.135
A9: 0 | B9: WR00L2L2 | C9: 27264 | D9: 32 | E9: 1 | F9: 16 | G9: 1303.1 | H9: 10.369 | I9: 45459 | J9: 0.1778125 | K9: 0 | L9: 0 | M9: 0 | N9: 0 | O9: 0 | P9: 0 | Q9: 0 | R9: 0 | S9: 0 | T9: 0 | U9: 0 | V9: 0 | W9: =AVERAGE(H9:H13) -> 10.3598 | Y9: 0 | Z9: WR00L2L2 | AA9: 27264 | AB9: 32 | AC9: 1 | AD9: 16 | AE9: 1268.7 | AF9: 10.65 | AG9: 45468 | AH9: 0.97918981 | AI9: 0 | AJ9: 0 | AK9: 0 | AL9: 0 | AM9: 0 | AN9: 0 | AO9: 0 | AP9: 0 | AQ9: 0 | AR9: 0 | AS9: 0 | AT9: 0 | AU9: =AVERAGE(AF9:AF13) -> 10.7022 | AW9: 25728 | AX9: 64 | AY9: 4 | AZ9: 4 | BA9: 1029.37 | BB9: 11.03
A10: 1 | B10: WR00L2L2 | C10: 27264 | D10: 32 | E10: 1 | F10: 16 | G10: 1299.01 | H10: 10.402 | I10: 45460 | J10: 0.19724537 | K10: 0 | L10: 0 | M10: 0 | N10: 0 | O10: 0 | P10: 0 | Q10: 0 | R10: 0 | S10: 0 | T10: 0 | U10: 0 | V10: 0 | Y10: 1 | Z10: WR00L2L2 | AA10: 27264 | AB10: 32 | AC10: 1 | AD10: 16 | AE10: 1260.76 | AF10: 10.717 | AG10: 45470 | AH10: 0.030081019 | AI10: 0 | AJ10: 0 | AK10: 0 | AL10: 0 | AM10: 0 | AN10: 0 | AO10: 0 | AP10: 0 | AQ10: 0 | AR10: 0 | AS10: 0 | AT10: 0 | AW10: 25728 | AX10: 96 | AY10: 1 | AZ10: 16 | BA10: 975.67 | BB10: 11.638
A11: 2 | B11: WR00L2L2 | C11: 27264 | D11: 32 | E11: 1 | F11: 16 | G11: 1299.44 | H11: 10.398 | I11: 45461 | J11: 0.21719907 | K11: 0 | L11: 0 | M11: 0 | N11: 0 | O11: 0 | P11: 0 | Q11: 0 | R11: 0 | S11: 0 | T11: 0 | U11: 0 | V11: 0 | Y11: 2 | Z11: WR00L2L2 | AA11: 27264 | AB11: 32 | AC11: 1 | AD11: 16 | AE11: 1264.26 | AF11: 10.688 | AG11: 45471 | AH11: 0.42278935 | AI11: 0 | AJ11: 0 | AK11: 0 | AL11: 0 | AM11: 0 | AN11: 0 | AO11: 0 | AP11: 0 | AQ11: 0 | AR11: 0 | AS11: 0 | AT11: 0 | AW11: 25728 | AX11: 96 | AY11: 2 | AZ11: 8 | BA11: 858.02 | BB11: 13.233
A12: 3 | B12: WR00L2L2 | C12: 27264 | D12: 32 | E12: 1 | F12: 16 | G12: 1307.26 | H12: 10.336 | I12: 45462 | J12: 0.54761574 | K12: 0 | L12: 0 | M12: 0 | N12: 0 | O12: 0 | P12: 0 | Q12: 0 | R12: 0 | S12: 0 | T12: 0 | U12: 0 | V12: 0 | Y12: 3 | Z12: WR00L2L2 | AA12: 27264 | AB12: 32 | AC12: 1 | AD12: 16 | AE12: 1262.26 | AF12: 10.704 | AG12: 45472 | AH12: 0.47671296 | AI12: 0 | AJ12: 0 | AK12: 0 | AL12: 0 | AM12: 0 | AN12: 0 | AO12: 0 | AP12: 0 | AQ12: 0 | AR12: 0 | AS12: 0 | AT12: 0 | AW12: 25728 | AX12: 96 | AY12: 4 | AZ12: 4 | BA12: 1040.56 | BB12: 10.912
A13: 4 | B13: WR00L2L2 | C13: 27264 | D13: 32 | E13: 1 | F13: 16 | G13: 1312.62 | H13: 10.294 | I13: 45465 | J13: 0.62380787 | K13: 0 | L13: 0 | M13: 0 | N13: 0 | O13: 0 | P13: 0 | Q13: 0 | R13: 0 | S13: 0 | T13: 0 | U13: 0 | V13: 0 | Y13: 4 | Z13: WR00L2L2 | AA13: 27264 | AB13: 32 | AC13: 1 | AD13: 16 | AE13: 1256.69 | AF13: 10.752 | AG13: 45473 | AH13: 0.53133102 | AI13: 0 | AJ13: 0 | AK13: 0 | AL13: 0 | AM13: 0 | AN13: 0 | AO13: 0 | AP13: 0 | AQ13: 0 | AR13: 0 | AS13: 0 | AT13: 0 | AW13: 25728 | AX13: 128 | AY13: 1 | AZ13: 16 | BA13: 996.91 | BB13: 11.39
A14: 0 | B14: WR00L2L2 | C14: 28800 | D14: 32 | E14: 1 | F14: 16 | G14: 1472.98 | H14: 10.812 | I14: 45459 | J14: 0.5199537 | K14: 0 | L14: 0 | M14: 0 | N14: 0 | O14: 0 | P14: 0 | Q14: 0 | R14: 0 | S14: 0 | T14: 0 | U14: 0 | V14: 0 | W14: =AVERAGE(H14:H18) -> 10.8156 | Y14: 0 | Z14: WR00L2L2 | AA14: 28800 | AB14: 32 | AC14: 1 | AD14: 16 | AE14: 1442.34 | AF14: 11.042 | AG14: 45469 | AH14: 0.33074074 | AI14: 0 | AJ14: 0 | AK14: 0 | AL14: 0 | AM14: 0 | AN14: 0 | AO14: 0 | AP14: 0 | AQ14: 0 | AR14: 0 | AS14: 0 | AT14: 0 | AU14: =AVERAGE(AF14:AF18) -> 11.0576 | AW14: 25728 | AX14: 128 | AY14: 2 | AZ14: 8 | BA14: 876.25 | BB14: 12.958
A15: 1 | B15: WR00L2L2 | C15: 28800 | D15: 32 | E15: 1 | F15: 16 | G15: 1470.69 | H15: 10.829 | I15: 45460 | J15: 0.53840278 | K15: 0 | L15: 0 | M15: 0 | N15: 0 | O15: 0 | P15: 0 | Q15: 0 | R15: 0 | S15: 0 | T15: 0 | U15: 0 | V15: 0 | Y15: 1 | Z15: WR00L2L2 | AA15: 28800 | AB15: 32 | AC15: 1 | AD15: 16 | AE15: 1428.89 | AF15: 11.146 | AG15: 45470 | AH15: 0.38070602 | AI15: 0 | AJ15: 0 | AK15: 0 | AL15: 0 | AM15: 0 | AN15: 0 | AO15: 0 | AP15: 0 | AQ15: 0 | AR15: 0 | AS15: 0 | AT15: 0 | AW15: 25728 | AX15: 128 | AY15: 4 | AZ15: 4 | BA15: 1055.74 | BB15: 10.755
A16: 2 | B16: WR00L2L2 | C16: 28800 | D16: 32 | E16: 1 | F16: 16 | G16: 1480.51 | H16: 10.757 | I16: 45461 | J16: 0.87101852 | K16: 0 | L16: 0 | M16: 0 | N16: 0 | O16: 0 | P16: 0 | Q16: 0 | R16: 0 | S16: 0 | T16: 0 | U16: 0 | V16: 0 | Y16: 2 | Z16: WR00L2L2 | AA16: 28800 | AB16: 32 | AC16: 1 | AD16: 16 | AE16: 1441.28 | AF16: 11.05 | AG16: 45471 | AH16: 0.77480324 | AI16: 0 | AJ16: 0 | AK16: 0 | AL16: 0 | AM16: 0 | AN16: 0 | AO16: 0 | AP16: 0 | AQ16: 0 | AR16: 0 | AS16: 0 | AT16: 0 | AW16: 25600 | AX16: 160 | AY16: 1 | AZ16: 16 | BA16: 1026.85 | BB16: 10.893
A17: 3 | B17: WR00L2L2 | C17: 28800 | D17: 32 | E17: 1 | F17: 16 | G17: 1467.8 | H17: 10.851 | I17: 45464 | J17: 0.94752315 | K17: 0 | L17: 0 | M17: 0 | N17: 0 | O17: 0 | P17: 0 | Q17: 0 | R17: 0 | S17: 0 | T17: 0 | U17: 0 | V17: 0 | Y17: 3 | Z17: WR00L2L2 | AA17: 28800 | AB17: 32 | AC17: 1 | AD17: 16 | AE17: 1447.9 | AF17: 11 | AG17: 45472 | AH17: 0.82928241 | AI17: 0 | AJ17: 0 | AK17: 0 | AL17: 0 | AM17: 0 | AN17: 0 | AO17: 0 | AP17: 0 | AQ17: 0 | AR17: 0 | AS17: 0 | AT17: 0 | AW17: 25600 | AX17: 160 | AY17: 2 | AZ17: 8 | BA17: 912.12 | BB17: 12.264
A18: 4 | B18: WR00L2L2 | C18: 28800 | D18: 32 | E18: 1 | F18: 16 | G18: 1470.76 | H18: 10.829 | I18: 45465 | J18: 0.96513889 | K18: 0 | L18: 0 | M18: 0 | N18: 0 | O18: 0 | P18: 0 | Q18: 0 | R18: 0 | S18: 0 | T18: 0 | U18: 0 | V18: 0 | Y18: 4 | Z18: WR00L2L2 | AA18: 28800 | AB18: 32 | AC18: 1 | AD18: 16 | AE18: 1441.36 | AF18: 11.05 | AG18: 45473 | AH18: 0.88310185 | AI18: 0 | AJ18: 0 | AK18: 0 | AL18: 0 | AM18: 0 | AN18: 0 | AO18: 0 | AP18: 0 | AQ18: 0 | AR18: 0 | AS18: 0 | AT18: 0 | AW18: 25600 | AX18: 160 | AY18: 4 | AZ18: 4 | BA18: 1098.89 | BB18: 10.179
A19: 0 | B19: WR00L2L2 | C19: 25728 | D19: 32 | E19: 2 | F19: 8 | G19: 969.07 | H19: 11.717 | I19: 45458 | J19: 0.89670139 | K19: 0 | L19: 0 | M19: 0 | N19: 0 | O19: 0 | P19: 0 | Q19: 0 | R19: 0 | S19: 0 | T19: 0 | U19: 0 | V19: 0 | W19: =AVERAGE(H19:H23) -> 11.886 | Y19: 0 | Z19: WR00L2L2 | AA19: 25728 | AB19: 32 | AC19: 2 | AD19: 8 | AE19: 999.05 | AF19: 11.365 | AG19: 45468 | AH19: 0.68733796 | AI19: 0 | AJ19: 0 | AK19: 0 | AL19: 0 | AM19: 0 | AN19: 0 | AO19: 0 | AP19: 0 | AQ19: 0 | AR19: 0 | AS19: 0 | AT19: 0 | AU19: =AVERAGE(AF19:AF23) -> 11.3548 | AW19: 25728 | AX19: 192 | AY19: 1 | AZ19: 16 | BA19: 1043.42 | BB19: 10.882
A20: 1 | B20: WR00L2L2 | C20: 25728 | D20: 32 | E20: 2 | F20: 8 | G20: 953.42 | H20: 11.909 | I20: 45459 | J20: 0.91717593 | K20: 0 | L20: 0 | M20: 0 | N20: 0 | O20: 0 | P20: 0 | Q20: 0 | R20: 0 | S20: 0 | T20: 0 | U20: 0 | V20: 0 | Y20: 1 | Z20: WR00L2L2 | AA20: 25728 | AB20: 32 | AC20: 2 | AD20: 8 | AE20: 997.28 | AF20: 11.385 | AG20: 45469 | AH20: 0.73898148 | AI20: 0 | AJ20: 0 | AK20: 0 | AL20: 0 | AM20: 0 | AN20: 0 | AO20: 0 | AP20: 0 | AQ20: 0 | AR20: 0 | AS20: 0 | AT20: 0 | AW20: 25728 | AX20: 192 | AY20: 2 | AZ20: 8 | BA20: 957.01 | BB20: 11.865
A21: 2 | B21: WR00L2L2 | C21: 25728 | D21: 32 | E21: 2 | F21: 8 | G21: 950.4 | H21: 11.947 | I21: 45460 | J21: 0.93690972 | K21: 0 | L21: 0 | M21: 0 | N21: 0 | O21: 0 | P21: 0 | Q21: 0 | R21: 0 | S21: 0 | T21: 0 | U21: 0 | V21: 0 | Y21: 2 | Z21: WR00L2L2 | AA21: 25728 | AB21: 32 | AC21: 2 | AD21: 8 | AE21: 1001.25 | AF21: 11.34 | AG21: 45471 | AH21: 0.1296875 | AI21: 0 | AJ21: 0 | AK21: 0 | AL21: 0 | AM21: 0 | AN21: 0 | AO21: 0 | AP21: 0 | AQ21: 0 | AR21: 0 | AS21: 0 | AT21: 0 | AW21: 25728 | AX21: 192 | AY21: 4 | AZ21: 4 | BA21: 1121.45 | BB21: 10.125
A22: 3 | B22: WR00L2L2 | C22: 25728 | D22: 32 | E22: 2 | F22: 8 | G22: 953.62 | H22: 11.907 | I22: 45462 | J22: 0.26709491 | K22: 0 | L22: 0 | M22: 0 | N22: 0 | O22: 0 | P22: 0 | Q22: 0 | R22: 0 | S22: 0 | T22: 0 | U22: 0 | V22: 0 | Y22: 3 | Z22: WR00L2L2 | AA22: 25728 | AB22: 32 | AC22: 2 | AD22: 8 | AE22: 1002.87 | AF22: 11.322 | AG22: 45472 | AH22: 0.1843287 | AI22: 0 | AJ22: 0 | AK22: 0 | AL22: 0 | AM22: 0 | AN22: 0 | AO22: 0 | AP22: 0 | AQ22: 0 | AR22: 0 | AS22: 0 | AT22: 0 | AW22: 25536 | AX22: 224 | AY22: 1 | AZ22: 16 | BA22: 1075.2 | BB22: 10.326
A23: 4 | B23: WR00L2L2 | C23: 25728 | D23: 32 | E23: 2 | F23: 8 | G23: 950.15 | H23: 11.95 | I23: 45465 | J23: 0.34369213 | K23: 0 | L23: 0 | M23: 0 | N23: 0 | O23: 0 | P23: 0 | Q23: 0 | R23: 0 | S23: 0 | T23: 0 | U23: 0 | V23: 0 | Y23: 4 | Z23: WR00L2L2 | AA23: 25728 | AB23: 32 | AC23: 2 | AD23: 8 | AE23: 999.32 | AF23: 11.362 | AG23: 45473 | AH23: 0.23920139 | AI23: 0 | AJ23: 0 | AK23: 0 | AL23: 0 | AM23: 0 | AN23: 0 | AO23: 0 | AP23: 0 | AQ23: 0 | AR23: 0 | AS23: 0 | AT23: 0 | AW23: 25536 | AX23: 224 | AY23: 2 | AZ23: 8 | BA23: 947.5 | BB23: 11.717
A24: 0 | B24: WR00L2L2 | C24: 27264 | D24: 32 | E24: 2 | F24: 8 | G24: 1142.18 | H24: 11.83 | I24: 45459 | J24: 0.19133102 | K24: 0 | L24: 0 | M24: 0 | N24: 0 | O24: 0 | P24: 0 | Q24: 0 | R24: 0 | S24: 0 | T24: 0 | U24: 0 | V24: 0 | W24: =AVERAGE(H24:H28) -> 11.8946 | Y24: 0 | Z24: WR00L2L2 | AA24: 27264 | AB24: 32 | AC24: 2 | AD24: 8 | AE24: 1163.56 | AF24: 11.612 | AG24: 45468 | AH24: 0.99385417 | AI24: 0 | AJ24: 0 | AK24: 0 | AL24: 0 | AM24: 0 | AN24: 0 | AO24: 0 | AP24: 0 | AQ24: 0 | AR24: 0 | AS24: 0 | AT24: 0 | AU24: =AVERAGE(AF24:AF28) -> 11.6762 | AW24: 25536 | AX24: 224 | AY24: 4 | AZ24: 4 | BA24: 1115.45 | BB24: 9.9531
A25: 1 | B25: WR00L2L2 | C25: 27264 | D25: 32 | E25: 2 | F25: 8 | G25: 1131.54 | H25: 11.941 | I25: 45460 | J25: 0.21064815 | K25: 0 | L25: 0 | M25: 0 | N25: 0 | O25: 0 | P25: 0 | Q25: 0 | R25: 0 | S25: 0 | T25: 0 | U25: 0 | V25: 0 | Y25: 1 | Z25: WR00L2L2 | AA25: 27264 | AB25: 32 | AC25: 2 | AD25: 8 | AE25: 1148.24 | AF25: 11.767 | AG25: 45470 | AH25: 0.044583333 | AI25: 0 | AJ25: 0 | AK25: 0 | AL25: 0 | AM25: 0 | AN25: 0 | AO25: 0 | AP25: 0 | AQ25: 0 | AR25: 0 | AS25: 0 | AT25: 0 | AW25: 25600 | AX25: 256 | AY25: 1 | AZ25: 16 | BA25: 1074.34 | BB25: 10.412
A26: 2 | B26: WR00L2L2 | C26: 27264 | D26: 32 | E26: 2 | F26: 8 | G26: 1131.76 | H26: 11.939 | I26: 45461 | J26: 0.23060185 | K26: 0 | L26: 0 | M26: 0 | N26: 0 | O26: 0 | P26: 0 | Q26: 0 | R26: 0 | S26: 0 | T26: 0 | U26: 0 | V26: 0 | Y26: 2 | Z26: WR00L2L2 | AA26: 27264 | AB26: 32 | AC26: 2 | AD26: 8 | AE26: 1154.35 | AF26: 11.705 | AG26: 45471 | AH26: 0.43739583 | AI26: 0 | AJ26: 0 | AK26: 0 | AL26: 0 | AM26: 0 | AN26: 0 | AO26: 0 | AP26: 0 | AQ26: 0 | AR26: 0 | AS26: 0 | AT26: 0 | AW26: 25600 | AX26: 256 | AY26: 2 | AZ26: 8 | BA26: 943.48 | BB26: 11.856
A27: 3 | B27: WR00L2L2 | C27: 27264 | D27: 32 | E27: 2 | F27: 8 | G27: 1134.18 | H27: 11.913 | I27: 45462 | J27: 0.56105324 | K27: 0 | L27: 0 | M27: 0 | N27: 0 | O27: 0 | P27: 0 | Q27: 0 | R27: 0 | S27: 0 | T27: 0 | U27: 0 | V27: 0 | Y27: 3 | Z27: WR00L2L2 | AA27: 27264 | AB27: 32 | AC27: 2 | AD27: 8 | AE27: 1161.37 | AF27: 11.634 | AG27: 45472 | AH27: 0.49135417 | AI27: 0 | AJ27: 0 | AK27: 0 | AL27: 0 | AM27: 0 | AN27: 0 | AO27: 0 | AP27: 0 | AQ27: 0 | AR27: 0 | AS27: 0 | AT27: 0 | AW27: 25600 | AX27: 256 | AY27: 4 | AZ27: 4 | BA27: 1166.28 | BB27: 9.591
A28: 4 | B28: WR00L2L2 | C28: 27264 | D28: 32 | E28: 2 | F28: 8 | G28: 1140.27 | H28: 11.85 | I28: 45465 | J28: 0.63730324 | K28: 0 | L28: 0 | M28: 0 | N28: 0 | O28: 0 | P28: 0 | Q28: 0 | R28: 0 | S28: 0 | T28: 0 | U28: 0 | V28: 0 | Y28: 4 | Z28: WR00L2L2 | AA28: 27264 | AB28: 32 | AC28: 2 | AD28: 8 | AE28: 1158.48 | AF28: 11.663 | AG28: 45473 | AH28: 0.54594907 | AI28: 0 | AJ28: 0 | AK28: 0 | AL28: 0 | AM28: 0 | AN28: 0 | AO28: 0 | AP28: 0 | AQ28: 0 | AR28: 0 | AS28: 0 | AT28: 0 | AW28: 27264 | AX28: 32 | AY28: 1 | AZ28: 16 | BA28: 1276.6 | BB28: 10.584
A29: 0 | B29: WR00L2L2 | C29: 28800 | D29: 32 | E29: 2 | F29: 8 | G29: 1303.83 | H29: 12.215 | I29: 45459 | J29: 0.53537037 | K29: 0 | L29: 0 | M29: 0 | N29: 0 | O29: 0 | P29: 0 | Q29: 0 | R29: 0 | S29: 0 | T29: 0 | U29: 0 | V29: 0 | W29: =AVERAGE(H29:H33) -> 12.2092 | Y29: 0 | Z29: WR00L2L2 | AA29: 28800 | AB29: 32 | AC29: 2 | AD29: 8 | AE29: 1321.29 | AF29: 12.054 | AG29: 45469 | AH29: 0.34736111 | AI29: 0 | AJ29: 0 | AK29: 0 | AL29: 0 | AM29: 0 | AN29: 0 | AO29: 0 | AP29: 0 | AQ29: 0 | AR29: 0 | AS29: 0 | AT29: 0 | AU29: =AVERAGE(AF29:AF33) -> 12.0282 | AW29: 27264 | AX29: 32 | AY29: 2 | AZ29: 8 | BA29: 1144.16 | BB29: 11.809
A30: 1 | B30: WR00L2L2 | C30: 28800 | D30: 32 | E30: 2 | F30: 8 | G30: 1299.82 | H30: 12.253 | I30: 45460 | J30: 0.55378472 | K30: 0 | L30: 0 | M30: 0 | N30: 0 | O30: 0 | P30: 0 | Q30: 0 | R30: 0 | S30: 0 | T30: 0 | U30: 0 | V30: 0 | Y30: 1 | Z30: WR00L2L2 | AA30: 28800 | AB30: 32 | AC30: 2 | AD30: 8 | AE30: 1318.88 | AF30: 12.076 | AG30: 45470 | AH30: 0.39730324 | AI30: 0 | AJ30: 0 | AK30: 0 | AL30: 0 | AM30: 0 | AN30: 0 | AO30: 0 | AP30: 0 | AQ30: 0 | AR30: 0 | AS30: 0 | AT30: 0 | AW30: 27264 | AX30: 32 | AY30: 4 | AZ30: 4 | BA30: 1345.29 | BB30: 10.044
A31: 2 | B31: WR00L2L2 | C31: 28800 | D31: 32 | E31: 2 | F31: 8 | G31: 1304.53 | H31: 12.209 | I31: 45461 | J31: 0.88645833 | K31: 0 | L31: 0 | M31: 0 | N31: 0 | O31: 0 | P31: 0 | Q31: 0 | R31: 0 | S31: 0 | T31: 0 | U31: 0 | V31: 0 | Y31: 2 | Z31: WR00L2L2 | AA31: 28800 | AB31: 32 | AC31: 2 | AD31: 8 | AE31: 1326.74 | AF31: 12.004 | AG31: 45471 | AH31: 0.79152778 | AI31: 0 | AJ31: 0 | AK31: 0 | AL31: 0 | AM31: 0 | AN31: 0 | AO31: 0 | AP31: 0 | AQ31: 0 | AR31: 0 | AS31: 0 | AT31: 0 | AW31: 27264 | AX31: 64 | AY31: 1 | AZ31: 16 | BA31: 1195.63 | BB31: 11.301
A32: 3 | B32: WR00L2L2 | C32: 28800 | D32: 32 | E32: 2 | F32: 8 | G32: 1309.08 | H32: 12.166 | I32: 45464 | J32: 0.96302083 | K32: 0 | L32: 0 | M32: 0 | N32: 0 | O32: 0 | P32: 0 | Q32: 0 | R32: 0 | S32: 0 | T32: 0 | U32: 0 | V32: 0 | Y32: 3 | Z32: WR00L2L2 | AA32: 28800 | AB32: 32 | AC32: 2 | AD32: 8 | AE32: 1327.07 | AF32: 12.001 | AG32: 45472 | AH32: 0.84597222 | AI32: 0 | AJ32: 0 | AK32: 0 | AL32: 0 | AM32: 0 | AN32: 0 | AO32: 0 | AP32: 0 | AQ32: 0 | AR32: 0 | AS32: 0 | AT32: 0 | AW32: 27264 | AX32: 64 | AY32: 2 | AZ32: 8 | BA32: 1063.49 | BB32: 12.705
A33: 4 | B33: WR00L2L2 | C33: 28800 | D33: 32 | E33: 2 | F33: 8 | G33: 1305.18 | H33: 12.203 | I33: 45465 | J33: 0.98056713 | K33: 0 | L33: 0 | M33: 0 | N33: 0 | O33: 0 | P33: 0 | Q33: 0 | R33: 0 | S33: 0 | T33: 0 | U33: 0 | V33: 0 | Y33: 4 | Z33: WR00L2L2 | AA33: 28800 | AB33: 32 | AC33: 2 | AD33: 8 | AE33: 1326.59 | AF33: 12.006 | AG33: 45473 | AH33: 0.89979167 | AI33: 0 | AJ33: 0 | AK33: 0 | AL33: 0 | AM33: 0 | AN33: 0 | AO33: 0 | AP33: 0 | AQ33: 0 | AR33: 0 | AS33: 0 | AT33: 0 | AW33: 27264 | AX33: 64 | AY33: 4 | AZ33: 4 | BA33: 1262.34 | BB33: 10.704
A34: 0 | B34: WR00L2L2 | C34: 25728 | D34: 32 | E34: 4 | F34: 4 | G34: 1152.49 | H34: 9.8521 | I34: 45458 | J34: 0.9103125 | K34: 0 | L34: 0 | M34: 0 | N34: 0 | O34: 0 | P34: 0 | Q34: 0 | R34: 0 | S34: 0 | T34: 0 | U34: 0 | V34: 0 | W34: =AVERAGE(H34:H38) -> 9.97542 | Y34: 0 | Z34: WR00L2L2 | AA34: 25728 | AB34: 32 | AC34: 4 | AD34: 4 | AE34: 1163.14 | AF34: 9.7619 | AG34: 45468 | AH34: 0.70186343 | AI34: 0 | AJ34: 0 | AK34: 0 | AL34: 0 | AM34: 0 | AN34: 0 | AO34: 0 | AP34: 0 | AQ34: 0 | AR34: 0 | AS34: 0 | AT34: 0 | AU34: =AVERAGE(AF34:AF38) -> 9.78898 | AW34: 27264 | AX34: 96 | AY34: 1 | AZ34: 16 | BA34: 1212.81 | BB34: 11.141
A35: 1 | B35: WR00L2L2 | C35: 25728 | D35: 32 | E35: 4 | F35: 4 | G35: 1134.48 | H35: 10.009 | I35: 45459 | J35: 0.9305787 | K35: 0 | L35: 0 | M35: 0 | N35: 0 | O35: 0 | P35: 0 | Q35: 0 | R35: 0 | S35: 0 | T35: 0 | U35: 0 | V35: 0 | Y35: 1 | Z35: WR00L2L2 | AA35: 25728 | AB35: 32 | AC35: 4 | AD35: 4 | AE35: 1153.34 | AF35: 9.8448 | AG35: 45469 | AH35: 0.75341435 | AI35: 0 | AJ35: 0 | AK35: 0 | AL35: 0 | AM35: 0 | AN35: 0 | AO35: 0 | AP35: 0 | AQ35: 0 | AR35: 0 | AS35: 0 | AT35: 0 | AW35: 27264 | AX35: 96 | AY35: 2 | AZ35: 8 | BA35: 1071.94 | BB35: 12.605
A36: 2 | B36: WR00L2L2 | C36: 25728 | D36: 32 | E36: 4 | F36: 4 | G36: 1133.98 | H36: 10.013 | I36: 45460 | J36: 0.95030093 | K36: 0 | L36: 0 | M36: 0 | N36: 0 | O36: 0 | P36: 0 | Q36: 0 | R36: 0 | S36: 0 | T36: 0 | U36: 0 | V36: 0 | Y36: 2 | Z36: WR00L2L2 | AA36: 25728 | AB36: 32 | AC36: 4 | AD36: 4 | AE36: 1158.93 | AF36: 9.7973 | AG36: 45471 | AH36: 0.14417824 | AI36: 0 | AJ36: 0 | AK36: 0 | AL36: 0 | AM36: 0 | AN36: 0 | AO36: 0 | AP36: 0 | AQ36: 0 | AR36: 0 | AS36: 0 | AT36: 0 | AW36: 27264 | AX36: 96 | AY36: 4 | AZ36: 4 | BA36: 1281.96 | BB36: 10.54
A37: 3 | B37: WR00L2L2 | C37: 25728 | D37: 32 | E37: 4 | F37: 4 | G37: 1137.72 | H37: 9.98 | I37: 45462 | J37: 0.28054398 | K37: 0 | L37: 0 | M37: 0 | N37: 0 | O37: 0 | P37: 0 | Q37: 0 | R37: 0 | S37: 0 | T37: 0 | U37: 0 | V37: 0 | Y37: 3 | Z37: WR00L2L2 | AA37: 25728 | AB37: 32 | AC37: 4 | AD37: 4 | AE37: 1165.58 | AF37: 9.7414 | AG37: 45472 | AH37: 0.19888889 | AI37: 0 | AJ37: 0 | AK37: 0 | AL37: 0 | AM37: 0 | AN37: 0 | AO37: 0 | AP37: 0 | AQ37: 0 | AR37: 0 | AS37: 0 | AT37: 0 | AW37: 27264 | AX37: 128 | AY37: 1 | AZ37: 16 | BA37: 1208.27 | BB37: 11.183
A38: 4 | B38: WR00L2L2 | C38: 25728 | D38: 32 | E38: 4 | F38: 4 | G38: 1132.79 | H38: 10.023 | I38: 45465 | J38: 0.35707176 | K38: 0 | L38: 0 | M38: 0 | N38: 0 | O38: 0 | P38: 0 | Q38: 0 | R38: 0 | S38: 0 | T38: 0 | U38: 0 | V38: 0 | Y38: 4 | Z38: WR00L2L2 | AA38: 25728 | AB38: 32 | AC38: 4 | AD38: 4 | AE38: 1158.67 | AF38: 9.7995 | AG38: 45473 | AH38: 0.2537037 | AI38: 0 | AJ38: 0 | AK38: 0 | AL38: 0 | AM38: 0 | AN38: 0 | AO38: 0 | AP38: 0 | AQ38: 0 | AR38: 0 | AS38: 0 | AT38: 0 | AW38: 27264 | AX38: 128 | AY38: 2 | AZ38: 8 | BA38: 1079.67 | BB38: 12.515
A39: 0 | B39: WR00L2L2 | C39: 27264 | D39: 32 | E39: 4 | F39: 4 | G39: 1339.66 | H39: 10.086 | I39: 45459 | J39: 0.20712963 | K39: 0 | L39: 0 | M39: 0 | N39: 0 | O39: 0 | P39: 0 | Q39: 0 | R39: 0 | S39: 0 | T39: 0 | U39: 0 | V39: 0 | W39: =AVERAGE(H39:H43) -> 10.1324 | Y39: 0 | Z39: WR00L2L2 | AA39: 27264 | AB39: 32 | AC39: 4 | AD39: 4 | AE39: 1339.05 | AF39: 10.091 | AG39: 45469 | AH39: 0.010543981 | AI39: 0 | AJ39: 0 | AK39: 0 | AL39: 0 | AM39: 0 | AN39: 0 | AO39: 0 | AP39: 0 | AQ39: 0 | AR39: 0 | AS39: 0 | AT39: 0 | AU39: =AVERAGE(AF39:AF43) -> 10.092 | AW39: 27264 | AX39: 128 | AY39: 4 | AZ39: 4 | BA39: 1277.02 | BB39: 10.581
A40: 1 | B40: WR00L2L2 | C40: 27264 | D40: 32 | E40: 4 | F40: 4 | G40: 1331.47 | H40: 10.148 | I40: 45460 | J40: 0.22634259 | K40: 0 | L40: 0 | M40: 0 | N40: 0 | O40: 0 | P40: 0 | Q40: 0 | R40: 0 | S40: 0 | T40: 0 | U40: 0 | V40: 0 | Y40: 1 | Z40: WR00L2L2 | AA40: 27264 | AB40: 32 | AC40: 4 | AD40: 4 | AE40: 1331.73 | AF40: 10.146 | AG40: 45470 | AH40: 0.06119213 | AI40: 0 | AJ40: 0 | AK40: 0 | AL40: 0 | AM40: 0 | AN40: 0 | AO40: 0 | AP40: 0 | AQ40: 0 | AR40: 0 | AS40: 0 | AT40: 0 | AW40: 27200 | AX40: 160 | AY40: 1 | AZ40: 16 | BA40: 1184.73 | BB40: 11.325
...

Sheet 1 node, params
A1: ATLAS (cpu-tune-overr-flags) | G1: OpenBLAS
A2: =INDEX(A4:A500,MATCH(MAX(E4:E500),E4:E500,0)) -> 14400 | B2: =INDEX(B4:B500,MATCH(MAX(E4:E500),E4:E500,0)) -> 96 | C2: =INDEX(C4:C500,MATCH(MAX(E4:E500),E4:E500,0)) -> 2 | D2: =INDEX(D4:D500,MATCH(MAX(E4:E500),E4:E500,0)) -> 2 | E2: =MAX(E4:E500) -> 4.4801 | G2: =INDEX(G4:G500,MATCH(MAX(K4:K500),K4:K500,0)) -> 14400 | H2: =INDEX(H4:H500,MATCH(MAX(K4:K500),K4:K500,0)) -> 192 | I2: =INDEX(I4:I500,MATCH(MAX(K4:K500),K4:K500,0)) -> 1 | J2: =INDEX(J4:J500,MATCH(MAX(K4:K500),K4:K500,0)) -> 4 | K2: =MAX(K4:K500) -> 4.4017
A3: N | B3: NB | C3: P | D3: Q | E3: Average GFLOP/s | G3: N | H3: NB | I3: P | J3: Q | K3: Average GFLOP/s | M3: N | O3: NB | P3: P | Q3: Q | R3: Average GFLOP/s | T3: N | V3: NB | W3: P | X3: Q | Y3: Average GFLOP/s
A4: {=_xlfn.CHOOSECOLS(_xlfn._xlws.FILTER('1 node, params, RAW'!A4:N500,'1 node, params, RAW'!A4:A500=0),3,4,5,6,14)} -> 12864 | B4: 32 | C4: 1 | D4: 4 | E4: 3.93302 | G4: {=_xlfn.CHOOSECOLS(_xlfn._xlws.FILTER('1 node, params, RAW'!P4:AC500,'1 node, params, RAW'!P4:P500=0),3,4,5,6,14)} -> 12864 | H4: 32 | I4: 1 | J4: 4 | K4: 3.5624 | M4: 12864 | N4: =CHOOSE(IF(ABS(M4-12864) <= ABS(M4-13632),IF(ABS(M4-12864) <= ABS(M4-14400),1,3),IF(ABS(M4-13632) <= ABS(M4-14400),2,3)),12864,13632,14400) -> 12864 | O4: 32 | P4: 1 | Q4: 4 | R4: 3.93302 | T4: 12864 | U4: =CHOOSE(IF(ABS(T4-12864) <= ABS(T4-13632),IF(ABS(T4-12864) <= ABS(T4-14400),1,3),IF(ABS(T4-13632) <= ABS(T4-14400),2,3)),12864,13632,14400) -> 12864 | V4: 32 | W4: 1 | X4: 4 | Y4: 3.5624
A5: 13632 | B5: 32 | C5: 1 | D5: 4 | E5: 3.8564 | G5: 13632 | H5: 32 | I5: 1 | J5: 4 | K5: 3.62406 | M5: 13632 | N5: =CHOOSE(IF(ABS(M5-12864) <= ABS(M5-13632),IF(ABS(M5-12864) <= ABS(M5-14400),1,3),IF(ABS(M5-13632) <= ABS(M5-14400),2,3)),12864,13632,14400) -> 13632 | O5: 32 | P5: 1 | Q5: 4 | R5: 3.8564 | T5: 13632 | U5: =CHOOSE(IF(ABS(T5-12864) <= ABS(T5-13632),IF(ABS(T5-12864) <= ABS(T5-14400),1,3),IF(ABS(T5-13632) <= ABS(T5-14400),2,3)),12864,13632,14400) -> 13632 | V5: 32 | W5: 1 | X5: 4 | Y5: 3.62406
A6: 14400 | B6: 32 | C6: 1 | D6: 4 | E6: 3.95198 | G6: 14400 | H6: 32 | I6: 1 | J6: 4 | K6: 3.72338 | M6: 14400 | N6: =CHOOSE(IF(ABS(M6-12864) <= ABS(M6-13632),IF(ABS(M6-12864) <= ABS(M6-14400),1,3),IF(ABS(M6-13632) <= ABS(M6-14400),2,3)),12864,13632,14400) -> 14400 | O6: 32 | P6: 1 | Q6: 4 | R6: 3.95198 | T6: 14400 | U6: =CHOOSE(IF(ABS(T6-12864) <= ABS(T6-13632),IF(ABS(T6-12864) <= ABS(T6-14400),1,3),IF(ABS(T6-13632) <= ABS(T6-14400),2,3)),12864,13632,14400) -> 14400 | V6: 32 | W6: 1 | X6: 4 | Y6: 3.72338
A7: 12864 | B7: 32 | C7: 2 | D7: 2 | E7: 3.9397 | G7: 12864 | H7: 32 | I7: 2 | J7: 2 | K7: 3.56798 | M7: 12864 | N7: =CHOOSE(IF(ABS(M7-12864) <= ABS(M7-13632),IF(ABS(M7-12864) <= ABS(M7-14400),1,3),IF(ABS(M7-13632) <= ABS(M7-14400),2,3)),12864,13632,14400) -> 12864 | O7: 32 | P7: 2 | Q7: 2 | R7: 3.9397 | T7: 12864 | U7: =CHOOSE(IF(ABS(T7-12864) <= ABS(T7-13632),IF(ABS(T7-12864) <= ABS(T7-14400),1,3),IF(ABS(T7-13632) <= ABS(T7-14400),2,3)),12864,13632,14400) -> 12864 | V7: 32 | W7: 2 | X7: 2 | Y7: 3.56798
A8: 13632 | B8: 32 | C8: 2 | D8: 2 | E8: 3.89724 | G8: 13632 | H8: 32 | I8: 2 | J8: 2 | K8: 3.6387 | M8: 13632 | N8: =CHOOSE(IF(ABS(M8-12864) <= ABS(M8-13632),IF(ABS(M8-12864) <= ABS(M8-14400),1,3),IF(ABS(M8-13632) <= ABS(M8-14400),2,3)),12864,13632,14400) -> 13632 | O8: 32 | P8: 2 | Q8: 2 | R8: 3.89724 | T8: 13632 | U8: =CHOOSE(IF(ABS(T8-12864) <= ABS(T8-13632),IF(ABS(T8-12864) <= ABS(T8-14400),1,3),IF(ABS(T8-13632) <= ABS(T8-14400),2,3)),12864,13632,14400) -> 13632 | V8: 32 | W8: 2 | X8: 2 | Y8: 3.6387
A9: 14400 | B9: 32 | C9: 2 | D9: 2 | E9: 3.926 | G9: 14400 | H9: 32 | I9: 2 | J9: 2 | K9: 3.71718 | M9: 14400 | N9: =CHOOSE(IF(ABS(M9-12864) <= ABS(M9-13632),IF(ABS(M9-12864) <= ABS(M9-14400),1,3),IF(ABS(M9-13632) <= ABS(M9-14400),2,3)),12864,13632,14400) -> 14400 | O9: 32 | P9: 2 | Q9: 2 | R9: 3.926 | T9: 14400 | U9: =CHOOSE(IF(ABS(T9-12864) <= ABS(T9-13632),IF(ABS(T9-12864) <= ABS(T9-14400),1,3),IF(ABS(T9-13632) <= ABS(T9-14400),2,3)),12864,13632,14400) -> 14400 | V9: 32 | W9: 2 | X9: 2 | Y9: 3.71718
A10: 12864 | B10: 64 | C10: 1 | D10: 4 | E10: 4.31218 | G10: 12864 | H10: 64 | I10: 1 | J10: 4 | K10: 3.9991 | M10: 12864 | N10: =CHOOSE(IF(ABS(M10-12864) <= ABS(M10-13632),IF(ABS(M10-12864) <= ABS(M10-14400),1,3),IF(ABS(M10-13632) <= ABS(M10-14400),2,3)),12864,13632,14400) -> 12864 | O10: 64 | P10: 1 | Q10: 4 | R10: 4.31218 | T10: 12864 | U10: =CHOOSE(IF(ABS(T10-12864) <= ABS(T10-13632),IF(ABS(T10-12864) <= ABS(T10-14400),1,3),IF(ABS(T10-13632) <= ABS(T10-14400),2,3)),12864,13632,14400) -> 12864 | V10: 64 | W10: 1 | X10: 4 | Y10: 3.9991
A11: 13632 | B11: 64 | C11: 1 | D11: 4 | E11: 4.23126 | G11: 13632 | H11: 64 | I11: 1 | J11: 4 | K11: 4.06798 | M11: 13632 | N11: =CHOOSE(IF(ABS(M11-12864) <= ABS(M11-13632),IF(ABS(M11-12864) <= ABS(M11-14400),1,3),IF(ABS(M11-13632) <= ABS(M11-14400),2,3)),12864,13632,14400) -> 13632 | O11: 64 | P11: 1 | Q11: 4 | R11: 4.23126 | T11: 13632 | U11: =CHOOSE(IF(ABS(T11-12864) <= ABS(T11-13632),IF(ABS(T11-12864) <= ABS(T11-14400),1,3),IF(ABS(T11-13632) <= ABS(T11-14400),2,3)),12864,13632,14400) -> 13632 | V11: 64 | W11: 1 | X11: 4 | Y11: 4.06798
A12: 14400 | B12: 64 | C12: 1 | D12: 4 | E12: 4.33982 | G12: 14400 | H12: 64 | I12: 1 | J12: 4 | K12: 4.1592 | M12: 14400 | N12: =CHOOSE(IF(ABS(M12-12864) <= ABS(M12-13632),IF(ABS(M12-12864) <= ABS(M12-14400),1,3),IF(ABS(M12-13632) <= ABS(M12-14400),2,3)),12864,13632,14400) -> 14400 | O12: 64 | P12: 1 | Q12: 4 | R12: 4.33982 | T12: 14400 | U12: =CHOOSE(IF(ABS(T12-12864) <= ABS(T12-13632),IF(ABS(T12-12864) <= ABS(T12-14400),1,3),IF(ABS(T12-13632) <= ABS(T12-14400),2,3)),12864,13632,14400) -> 14400 | V12: 64 | W12: 1 | X12: 4 | Y12: 4.1592
A13: 12864 | B13: 64 | C13: 2 | D13: 2 | E13: 4.31608 | G13: 12864 | H13: 64 | I13: 2 | J13: 2 | K13: 3.90262 | M13: 12864 | N13: =CHOOSE(IF(ABS(M13-12864) <= ABS(M13-13632),IF(ABS(M13-12864) <= ABS(M13-14400),1,3),IF(ABS(M13-13632) <= ABS(M13-14400),2,3)),12864,13632,14400) -> 12864 | O13: 64 | P13: 2 | Q13: 2 | R13: 4.31608 | T13: 12864 | U13: =CHOOSE(IF(ABS(T13-12864) <= ABS(T13-13632),IF(ABS(T13-12864) <= ABS(T13-14400),1,3),IF(ABS(T13-13632) <= ABS(T13-14400),2,3)),12864,13632,14400) -> 12864 | V13: 64 | W13: 2 | X13: 2 | Y13: 3.90262
A14: 13632 | B14: 64 | C14: 2 | D14: 2 | E14: 4.29148 | G14: 13632 | H14: 64 | I14: 2 | J14: 2 | K14: 3.99624 | M14: 13632 | N14: =CHOOSE(IF(ABS(M14-12864) <= ABS(M14-13632),IF(ABS(M14-12864) <= ABS(M14-14400),1,3),IF(ABS(M14-13632) <= ABS(M14-14400),2,3)),12864,13632,14400) -> 13632 | O14: 64 | P14: 2 | Q14: 2 | R14: 4.29148 | T14: 13632 | U14: =CHOOSE(IF(ABS(T14-12864) <= ABS(T14-13632),IF(ABS(T14-12864) <= ABS(T14-14400),1,3),IF(ABS(T14-13632) <= ABS(T14-14400),2,3)),12864,13632,14400) -> 13632 | V14: 64 | W14: 2 | X14: 2 | Y14: 3.99624
A15: 14400 | B15: 64 | C15: 2 | D15: 2 | E15: 4.30104 | G15: 14400 | H15: 64 | I15: 2 | J15: 2 | K15: 4.0763 | M15: 14400 | N15: =CHOOSE(IF(ABS(M15-12864) <= ABS(M15-13632),IF(ABS(M15-12864) <= ABS(M15-14400),1,3),IF(ABS(M15-13632) <= ABS(M15-14400),2,3)),12864,13632,14400) -> 14400 | O15: 64 | P15: 2 | Q15: 2 | R15: 4.30104 | T15: 14400 | U15: =CHOOSE(IF(ABS(T15-12864) <= ABS(T15-13632),IF(ABS(T15-12864) <= ABS(T15-14400),1,3),IF(ABS(T15-13632) <= ABS(T15-14400),2,3)),12864,13632,14400) -> 14400 | V15: 64 | W15: 2 | X15: 2 | Y15: 4.0763
A16: 12864 | B16: 96 | C16: 1 | D16: 4 | E16: 4.42858 | G16: 12864 | H16: 96 | I16: 1 | J16: 4 | K16: 4.14868 | M16: 12864 | N16: =CHOOSE(IF(ABS(M16-12864) <= ABS(M16-13632),IF(ABS(M16-12864) <= ABS(M16-14400),1,3),IF(ABS(M16-13632) <= ABS(M16-14400),2,3)),12864,13632,14400) -> 12864 | O16: 96 | P16: 1 | Q16: 4 | R16: 4.42858 | T16: 12864 | U16: =CHOOSE(IF(ABS(T16-12864) <= ABS(T16-13632),IF(ABS(T16-12864) <= ABS(T16-14400),1,3),IF(ABS(T16-13632) <= ABS(T16-14400),2,3)),12864,13632,14400) -> 12864 | V16: 96 | W16: 1 | X16: 4 | Y16: 4.14868
... A51: 14336 | B51: 256 | C51: 2 | D51: 2 | E51: 4.22562 | G51: 14336 | H51: 256 | I51: 2 | J51: 2 | K51: 4.05244 | M51: 14336 | N51: =CHOOSE(IF(ABS(M51-12864) <= ABS(M51-13632),IF(ABS(M51-12864) <= ABS(M51-14400),1,3),IF(ABS(M51-13632) <= ABS(M51-14400),2,3)),12864,13632,14400) -> 14400 | O51: 256 | P51: 2 | Q51: 2 | R51: 4.22562 | T51: 14336 | U51: =CHOOSE(IF(ABS(T51-12864) <= ABS(T51-13632),IF(ABS(T51-12864) <= ABS(T51-14400),1,3),IF(ABS(T51-13632) <= ABS(T51-14400),2,3)),12864,13632,14400) -> 14400 | V51: 256 | W51: 2 | X51: 2 | Y51: 4.05244
