Workbook

Sheet 4 - node
A1: Cubieboard2s
B2: T/V | C2: N | D2: NB | E2: P | F2: Q | G2: Time | H2: MFLOPS(?)
B3: WR00L2L2 | C3: 18432 | D3: 256 | E3: 1 | F3: 8 | G3: 2073.56 | H3: 20136
B4: WR00L2L2 | C4: 18432 | D4: 128 | E4: 1 | F4: 8 | G4: 2132.14 | H4: 19582
B5: WR00L2L2 | C5: 18432 | D5: 64 | E5: 1 | F5: 8 | G5: 2123.14 | H5: 19665
B6: WR00L2L2 | C6: 18432 | D6: 32 | E6: 1 | F6: 8 | G6: 2158.32 | H6: 19345
B7: WR00L2L2 | C7: 19456 | D7: 256 | E7: 1 | F7: 8 | G7: 2421.78 | H7: 20276
B8: WR00L2L2 | C8: 19456 | D8: 128 | E8: 1 | F8: 8 | G8: 2346.65 | H8: 20925
B9: WR00L2L2 | C9: 19456 | D9: 64 | E9: 1 | F9: 8 | G9: 2343.72 | H9: 20951
B10: WR00L2L2 | C10: 19456 | D10: 32 | E10: 1 | F10: 8 | G10: 2445.65 | H10: 20078
B11: WR00L2L2 | C11: 18432 | D11: 256 | E11: 8 | F11: 1 | G11: 2465.10 | H11: 16937
B12: WR00L2L2 | C12: 18432 | D12: 128 | E12: 8 | F12: 1 | G12: 2407.33 | H12: 17344
B13: WR00L2L2 | C13: 18432 | D13: 64 | E13: 8 | F13: 1 | G13: 2463.01 | H13: 16952
B14: WR00L2L2 | C14: 18432 | D14: 32 | E14: 8 | F14: 1 | G14: 2495.48 | H14: 16731
... B67: WR00L2L2 | C67: 18960 | D67: 40 | E67: 8 | F67: 1 | G67: 2693.92 | H67: 16869
H121: =#REF!/#REF! -> #REF!

Sheet Arch details
A1: SBC | B1: Cores | C1: march | D1: mcpu | E1: mtune | F1: fpu | G1: mfloat-abi | J1: ostalo | K1: ostalo (Thumb)
A2: Rpi 1B | C2: armv6 | D2: arm1176jzf-s | E2: arm1176jzf-s | F2: vfpv2 (alias is vfp) | G2: hard | K2: Thumb | L2: 16KB L1 and no L2
A3: Cubieboard2 | C3: armv7-a | D3: cortex-a7 | E3: cortex-a7 | F3: neon-vfpv4 | G3: hard | J3: -funsafe-math-optimizations | K3: Thumb-2
A4: OdroidU3 | C4: armv7-a | D4: cortex-a9 | E4: cortex-a9 | F4: neon-vfpv3 (alias is neon) | G4: hard | J4: -funsafe-math-optimizations | K4: Thumb or Thumb-2 | L4: 1MB L2 cache total? From paper…
A5: OdroidMC1 | B5: LITTLE | C5: armv7-a | D5: cortex-a7 | E5: cortex-a7 | F5: neon-vfpv4 | G5: hard | J5: -funsafe-math-optimizations | K5: Thumb-2 | L5: 2 sockets, 2,5MB L2 cache per socket
B6: Big | C6: armv7-a | D6: cortex-a15 | E6: cortex-a15 | F6: neon-vfpv4 | G6: hard | J6: -funsafe-math-optimizations | K6: Thumb-2
A12: HPL Runs (fixed parameters) | C12: Number of nodes | D12: Node | E12: Total memory of a node (kB) | F12: N, alpha | G12: N, alpha (NB round) | H12: N, beta | I12: N, beta (NB round) | J12: NB | K12: P | L12: Q | M12: Ns difference | N12: Half of the Ns difference | O12: N1 | P12: N2 | Q12: N3
A13: Number of nodes | B13: 4 | C13: 1 | D13: Cubieboard2 | E13: 1022960 | F13: =$B$14*SQRT(($C13*$E13*1024)/8) -> 9154.2822 | G13: =_xlfn.CEILING.MATH(F13/J13)*J13 -> 9216 | H13: =SQRT($B$14*($C13*$E13*1024)/8) -> 10234.799 | I13: =_xlfn.CEILING.MATH(H13/J13)*J13 -> 10240 | J13: 64 | K13: 1 | L13: 2 | M13: =I13-G13 -> 1024 | N13: =M13/2 -> 512 | O13: =G13 -> 9216 | P13: =_xlfn.CEILING.MATH((O13+N13)/J13)*J13 -> 9728 | Q13: =_xlfn.CEILING.MATH((P13+N13)/J13)*J13 -> 10240
A14: Percentage of mem | B14: 0.8 | C14: 4 | D14: Cubieboard2 | E14: 1022961 | F14: =$B$14*SQRT(($B$13*$E14*1024)/8) -> 18308.573 | G14: =_xlfn.CEILING.MATH(F14/J14)*J14 -> 18368 | H14: =SQRT($B$14*($B$13*$E14*1024)/8) -> 20469.607 | I14: =_xlfn.CEILING.MATH(H14/J14)*J14 -> 20480 | J14: 64 | K14: 2 | L14: 4 | M14: =I14-G14 -> 2112 | N14: =M14/2 -> 1056 | O14: =G14 -> 18368 | P14: =_xlfn.CEILING.MATH((O14+N14)/J14)*J14 -> 19456 | Q14: =_xlfn.CEILING.MATH((P14+N14)/J14)*J14 -> 20544

Sheet HPL_Builds
A1: Cubieboard2 | C1: Flags used for building ATLAS | D1: Flags used for flagsearching - mandatory | E1: Flags used for building HPL | F1: Machine setup for building HPL | G1: Ran? | H1: NOTE
A2: 1 | B2: atlarch | C2: -D c -DWALL -b 32 -A ARMa7 | D2: -O2 -mcpu=cortex-a7 -fno-schedule-insns -fselective-scheduling2 | E2: -O2 -mcpu=cortex-a7 -fno-schedule-insns -fselective-scheduling2
A3: 2 | B3: cpu-tune | C3: -D c -DWALL -b 32 -Fa al "-mcpu=native -mfloat-abi=hard -mfpu=neon-vfpv4" | D3: -mcpu=native -mfloat-abi=hard -mfpu=neon-vfpv4 | E3: -mcpu=native -mfloat-abi=hard -mfpu=neon-vfpv4
A4: 3 | B4: arch-native-tune | C4: -D c -DWALL -b 32 -Fa al "-march=native -mtune=cortex-a7 -mfloat-abi=hard -mfpu=neon-vfpv4" | D4: -march=native -mtune=cortex-a7 -mfloat-abi=hard -mfpu=neon-vfpv4 | E4: -march=native -mtune=cortex-a7 -mfloat-abi=hard -mfpu=neon-vfpv4
A5: 4 | B5: cpu-tune-overr | C5: -D c -DWALL -b 32 -F al "-mcpu=native -mfloat-abi=hard -mfpu=neon-vfpv4" | D5: -mcpu=native -mfloat-abi=hard -mfpu=neon-vfpv4 | E5: -mcpu=native -mfloat-abi=hard -mfpu=neon-vfpv4
A6: 5 | B6: atlarch-flags | C6: -D c -DWALL -b 32 -A ARMa7 -Fa al "-O2 -mcpu=cortex-a7 -fno-schedule-insns -fselective-scheduling2 -fschedule-insns -fno-schedule-insns -frename-registers -fno-tree-pre" | E6: -O2 -mcpu=cortex-a7 -fno-schedule-insns -fselective-scheduling2 -fschedule-insns -fno-schedule-insns -frename-registers -fno-tree-pre
A7: 6 | B7: cpu-tune-flags | C7: -D c -DWALL -b 32 -Fa al "-O1 -mcpu=native -mfloat-abi=hard -mfpu=neon-vfpv4 -fno-expensive-optimizations -fschedule-insns -fschedule-insns2 -fselective-scheduling -fselective-scheduling2 -fno-tree-ter" | E7: -O1 -mcpu=native -mfloat-abi=hard -mfpu=neon-vfpv4 -fno-expensive-optimizations -fschedule-insns -fschedule-insns2 -fselective-scheduling -fselective-scheduling2 -fno-tree-ter
A8: 7 | B8: arch-native-tune-flags | C8: -D c -DWALL -b 32 -Fa al "-Os -march=native -mtune=cortex-a7 -mfloat-abi=hard -mfpu=neon-vfpv4 -fno-expensive-optimizations -fschedule-insns2 -fschedule-insns -fselective-scheduling -fselective-scheduling2 -fno-tree-ter" | E8: -Os -march=native -mtune=cortex-a7 -mfloat-abi=hard -mfpu=neon-vfpv4 -fno-expensive-optimizations -fschedule-insns2 -fschedule-insns -fselective-scheduling -fselective-scheduling2 -fno-tree-ter
A9: 8 | B9: cpu-tune-overr-flags | C9: -D c -DWALL -b 32 -F al "-O1 -mcpu=native -mfloat-abi=hard -mfpu=neon-vfpv4 -fno-expensive-optimizations -fschedule-insns -fschedule-insns2 -fselective-scheduling -fselective-scheduling2 -fno-tree-ter" | E9: -O1 -mcpu=native -mfloat-abi=hard -mfpu=neon-vfpv4 -fno-expensive-optimizations -fschedule-insns -fschedule-insns2 -fselective-scheduling -fselective-scheduling2 -fno-tree-ter

Sheet ATLAS builds
A1: Raspberry Pi 1B | C1: Flags used for building | D1: Flags used for flagsearching - mandatory | E1: Flags used for flagsearching - optional | F1: Machine originally built on | G1: Needs flagsearching | H1: Flagsearched (d) | I1: Flagsearched (s) No need! HPL uses only double precision! See ATLAS install manual | J1: Flagsearched (Td) | K1: Kernel | L1: GFLOPS | M1: NOTE | O1: TODO
A2: Cubieboard 2 | O2: In progress
A3: 1 | B3: atlarch | C3: -D c -DWALL -b 32 -A ARMa7 | D3: -O2 -mcpu=cortex-a7 -fno-schedule-insns -fselective-scheduling2 | E3: - | F3: cubie01 | L3: =VLOOKUP(B3,'HPL 4 nodes, builds'!$Z$4:$AW$43,24,FALSE) -> 1.91522 | O3: Freshly finished
A4: 2 | B4: cpu-tune | C4: -D c -DWALL -b 32 -Fa al "-mcpu=native -mfloat-abi=hard -mfpu=neon-vfpv4" | D4: -mcpu=native -mfloat-abi=hard -mfpu=neon-vfpv4 | E4: -mcpu=cortex-a7 | F4: cubie02 | L4: =VLOOKUP(B4,'HPL 4 nodes, builds'!$Z$4:$AW$43,24,FALSE) -> 1.67164 | O4: Done
A5: 3 | B5: arch-native-tune | C5: -D c -DWALL -b 32 -Fa al "-march=native -mtune=cortex-a7 -mfloat-abi=hard -mfpu=neon-vfpv4" | D5: -march=native -mtune=cortex-a7 -mfloat-abi=hard -mfpu=neon-vfpv4 | E5: -march=armv7-a | F5: cubie03 | L5: =VLOOKUP(B5,'HPL 4 nodes, builds'!$Z$4:$AW$43,24,FALSE) -> 1.68718 | O5: TODO with the same settings!
A6: 4 | B6: cpu-tune-overr | C6: -D c -DWALL -b 32 -F al "-mcpu=native -mfloat-abi=hard -mfpu=neon-vfpv4" | D6: -mcpu=native -mfloat-abi=hard -mfpu=neon-vfpv4 | E6: -mcpu=cortex-a7 | F6: cubie04 | L6: =VLOOKUP(B6,'HPL 4 nodes, builds'!$Z$4:$AW$43,24,FALSE) -> 1.28458
A7: 5 | B7: atlarch-flags | C7: -D c -DWALL -b 32 -A ARMa7 -Fa al "-O2 -mcpu=cortex-a7 -fno-schedule-insns -fselective-scheduling2 -fschedule-insns -fno-schedule-insns -frename-registers -fno-tree-pre" | F7: cubie01 | L7: =VLOOKUP(B7,'HPL 4 nodes, builds'!$Z$4:$AW$43,24,FALSE) -> 1.9635
A8: 6 | B8: cpu-tune-flags | C8: -D c -DWALL -b 32 -Fa al "-O1 -mcpu=native -mfloat-abi=hard -mfpu=neon-vfpv4 -fno-expensive-optimizations -fschedule-insns -fschedule-insns2 -fselective-scheduling -fselective-scheduling2 -fno-tree-ter" | F8: cubie02 | L8: =VLOOKUP(B8,'HPL 4 nodes, builds'!$Z$4:$AW$43,24,FALSE) -> 1.81704
A9: 7 | B9: arch-native-tune-flags | C9: -D c -DWALL -b 32 -Fa al "-Os -march=native -mtune=cortex-a7 -mfloat-abi=hard -mfpu=neon-vfpv4 -fno-expensive-optimizations -fschedule-insns2 -fschedule-insns -fselective-scheduling -fselective-scheduling2 -fno-tree-ter" | F9: cubie03 | L9: =VLOOKUP(B9,'HPL 4 nodes, builds'!$Z$4:$AW$43,24,FALSE) -> 1.87352 | M9: Originalno je bilo "-O1 -march=native -mtune=cortex-a7 -mfloat-abi=hard -mfpu=neon-vfpv4 -fno-expensive-optimizations -fschedule-insns -fschedule-insns2 -fselective-scheduling -fsel-sched-pipelining -fselective-scheduling2 -fsel-sched-pipelining -fno-tree-ter" no TO NIJE RADILO, make je bacao error. Stavio sam samo ovo što sada piše.
A10: 8 | B10: cpu-tune-overr-flags | C10: -D c -DWALL -b 32 -F al "-O1 -mcpu=native -mfloat-abi=hard -mfpu=neon-vfpv4 -fno-expensive-optimizations -fschedule-insns -fschedule-insns2 -fselective-scheduling -fselective-scheduling2 -fno-tree-ter" | F10: cubie04 | L10: =VLOOKUP(B10,'HPL 4 nodes, builds'!$Z$4:$AW$43,24,FALSE) -> 1.8137

Sheet HPL 4 nodes, builds
A1: Max avg. GFLOPS (and params): | B1: =INDEX(A:A,MATCH(MAX($X:$X),$X:$X,0)) -> atlarch-flags | F1: =MAX(X:X) -> 1.95548 | G1: =INDEX(D:D,MATCH(MAX($W:$W),$W:$W,0)) -> 18368 | H1: =INDEX(E:E,MATCH(MAX($W:$W),$W:$W,0)) -> 64 | I1: =INDEX(F:F,MATCH(MAX($W:$W),$W:$W,0)) -> 2 | J1: =INDEX(G:G,MATCH(MAX($W:$W),$W:$W,0)) -> 4 | L1: ATLAS (with "-al") | X1: Average GFLOP/s | Z1: Max avg. GFLOPS (and params): | AA1: =INDEX(Z:Z,MATCH(MAX($AW:$AW),$AW:$AW,0)) -> atlarch-flags | AE1: =MAX(AW:AW) -> 1.9635 | AF1: =INDEX(AC:AC,MATCH(MAX($AW:$AW),$AW:$AW,0)) -> 18368 | AG1: =INDEX(AD:AD,MATCH(MAX($AW:$AW),$AW:$AW,0)) -> 64 | AH1: =INDEX(AE:AE,MATCH(MAX($AW:$AW),$AW:$AW,0)) -> 2 | AI1: =INDEX(AF:AF,MATCH(MAX($AW:$AW),$AW:$AW,0)) -> 4 | AK1: ATLAS (with "-alg") | AW1: Average GFLOP/s
A2: MAX GFLOPS: | D2: =MAX(I4:I841) -> 2.0587 | L2: cubie01 throttling time [1/100s] | O2: cubie02 throttling time [1/100s] | R2: cubie03 throttling time [1/100s] | U2: cubie04 throttling time [1/100s] | Z2: MAX GFLOPS: | AC2: =MAX(AH4:AH841) -> 2.0079 | AK2: cubie01 throttling time [1/100s] | AN2: cubie02 throttling time [1/100s] | AQ2: cubie03 throttling time [1/100s] | AT2: cubie04 throttling time [1/100s]
A3: Build | B3: RUN | D3: N | E3: NB | F3: P | G3: Q | H3: Time | I3: GFLOPS | J3: Date | K3: Time | L3: 720MHz | M3: 864MHz | N3: 912MHz | O3: 720MHz | P3: 864MHz | Q3: 912MHz | R3: 720MHz | S3: 864MHz | T3: 912MHz | U3: 720MHz | V3: 864MHz | W3: 912MHz | Z3: Build | AA3: RUN | AC3: N | AD3: NB | AE3: P | AF3: Q | AG3: Time | AH3: GFLOPS | AI3: Date | AJ3: Time | AK3: 720MHz | AL3: 864MHz | AM3: 912MHz | AN3: 720MHz | AO3: 864MHz | AP3: 912MHz | AQ3: 720MHz | AR3: 864MHz | AS3: 912MHz | AT3: 720MHz | AU3: 864MHz | AV3: 912MHz
A4: atlarch-flags | B4: 0 | C4: WR00L2L2 | D4: 18368 | E4: 64 | F4: 2 | G4: 4 | H4: 2205.23 | I4: 1.8737 | J4: 45457 | K4: 0.55703704 | L4: 0 | M4: 0 | N4: 0 | O4: 0 | P4: 0 | Q4: 0 | R4: 0 | S4: 0 | T4: 0 | U4: 0 | V4: 0 | W4: 0 | X4: =AVERAGE(I4:I8) -> 1.91936 | Z4: atlarch-flags | AA4: 0 | AB4: WR00L2L2 | AC4: 18368 | AD4: 64 | AE4: 2 | AF4: 4 | AG4: 2160.37 | AH4: 1.9126 | AI4: 45484 | AJ4: 0.39947917 | AK4: 0 | AL4: 0 | AM4: 0 | AN4: 0 | AO4: 0 | AP4: 0 | AQ4: 0 | AR4: 0 | AS4: 0 | AT4: 0 | AU4: 0 | AV4: 0 | AW4: =AVERAGE(AH4:AH8) -> 1.9635
A5: atlarch-flags | B5: 1 | C5: WR00L2L2 | D5: 18368 | E5: 64 | F5: 2 | G5: 4 | H5: 2116.61 | I5: 1.9521 | J5: 45457 | K5: 0.58211806 | L5: 0 | M5: 0 | N5: 0 | O5: 0 | P5: 0 | Q5: 0 | R5: 0 | S5: 0 | T5: 0 | U5: 0 | V5: 0 | W5: 0 | X5: =X4 -> 1.91936 | Z5: atlarch-flags | AA5: 1 | AB5: WR00L2L2 | AC5: 18368 | AD5: 64 | AE5: 2 | AF5: 4 | AG5: 2107 | AH5: 1.961 | AI5: 45484 | AJ5: 0.42444444 | AK5: 0 | AL5: 0 | AM5: 0 | AN5: 0 | AO5: 0 | AP5: 0 | AQ5: 0 | AR5: 0 | AS5: 0 | AT5: 0 | AU5: 0 | AV5: 0 | AW5: =AW4 -> 1.9635
A6: atlarch-flags | B6: 2 | C6: WR00L2L2 | D6: 18368 | E6: 64 | F6: 2 | G6: 4 | H6: 2167 | I6: 1.9067 | J6: 45457 | K6: 0.60790509 | L6: 0 | M6: 0 | N6: 0 | O6: 0 | P6: 0 | Q6: 0 | R6: 0 | S6: 0 | T6: 0 | U6: 0 | V6: 0 | W6: 0 | X6: =X5 -> 1.91936 | Z6: atlarch-flags | AA6: 2 | AB6: WR00L2L2 | AC6: 18368 | AD6: 64 | AE6: 2 | AF6: 4 | AG6: 2057.83 | AH6: 2.0079 | AI6: 45484 | AJ6: 0.44895833 | AK6: 0 | AL6: 0 | AM6: 0 | AN6: 0 | AO6: 0 | AP6: 0 | AQ6: 0 | AR6: 0 | AS6: 0 | AT6: 0 | AU6: 0 | AV6: 0 | AW6: =AW5 -> 1.9635
A7: atlarch-flags | B7: 3 | C7: WR00L2L2 | D7: 18368 | E7: 64 | F7: 2 | G7: 4 | H7: 2131.4 | I7: 1.9386 | J7: 45457 | K7: 0.63314815 | L7: 0 | M7: 0 | N7: 0 | O7: 0 | P7: 0 | Q7: 0 | R7: 0 | S7: 0 | T7: 0 | U7: 0 | V7: 0 | W7: 0 | X7: =X6 -> 1.91936 | Z7: atlarch-flags | AA7: 3 | AB7: WR00L2L2 | AC7: 18368 | AD7: 64 | AE7: 2 | AF7: 4 | AG7: 2087.44 | AH7: 1.9794 | AI7: 45484 | AJ7: 0.47373843 | AK7: 0 | AL7: 0 | AM7: 0 | AN7: 0 | AO7: 0 | AP7: 0 | AQ7: 0 | AR7: 0 | AS7: 0 | AT7: 0 | AU7: 0 | AV7: 0 | AW7: =AW6 -> 1.9635
A8: atlarch-flags | B8: 4 | C8: WR00L2L2 | D8: 18368 | E8: 64 | F8: 2 | G8: 4 | H8: 2145.6 | I8: 1.9257 | J8: 45457 | K8: 0.65855324 | L8: 0 | M8: 0 | N8: 0 | O8: 0 | P8: 0 | Q8: 0 | R8: 0 | S8: 0 | T8: 0 | U8: 0 | V8: 0 | W8: 0 | X8: =X7 -> 1.91936 | Z8: atlarch-flags | AA8: 4 | AB8: WR00L2L2 | AC8: 18368 | AD8: 64 | AE8: 2 | AF8: 4 | AG8: 2111.73 | AH8: 1.9566 | AI8: 45484 | AJ8: 0.49894676 | AK8: 0 | AL8: 0 | AM8: 0 | AN8: 0 | AO8: 0 | AP8: 0 | AQ8: 0 | AR8: 0 | AS8: 0 | AT8: 0 | AU8: 0 | AV8: 0 | AW8: =AW7 -> 1.9635
A9: atlarch | B9: 0 | C9: WR00L2L2 | D9: 18368 | E9: 64 | F9: 2 | G9: 4 | H9: 2188.97 | I9: 1.8876 | J9: 45456 | K9: 0.92225694 | L9: 0 | M9: 0 | N9: 0 | O9: 0 | P9: 0 | Q9: 0 | R9: 0 | S9: 0 | T9: 0 | U9: 0 | V9: 0 | W9: 0 | X9: =AVERAGE(I9:I13) -> 1.90934 | Z9: atlarch | AA9: 0 | AB9: WR00L2L2 | AC9: 18368 | AD9: 64 | AE9: 2 | AF9: 4 | AG9: 2090.85 | AH9: 1.9762 | AI9: 45483 | AJ9: 0.75483796 | AK9: 0 | AL9: 0 | AM9: 0 | AN9: 0 | AO9: 0 | AP9: 0 | AQ9: 0 | AR9: 0 | AS9: 0 | AT9: 0 | AU9: 0 | AV9: 0 | AW9: =AVERAGE(AH9:AH13) -> 1.91522
A10: atlarch | B10: 1 | C10: WR00L2L2 | D10: 18368 | E10: 64 | F10: 2 | G10: 4 | H10: 2162.75 | I10: 1.9105 | J10: 45456 | K10: 0.94797454 | L10: 0 | M10: 0 | N10: 0 | O10: 0 | P10: 0 | Q10: 0 | R10: 0 | S10: 0 | T10: 0 | U10: 0 | V10: 0 | W10: 0 | X10: =X9 -> 1.90934 | Z10: atlarch | AA10: 1 | AB10: WR00L2L2 | AC10: 18368 | AD10: 64 | AE10: 2 | AF10: 4 | AG10: 2198.31 | AH10: 1.8796 | AI10: 45483 | AJ10: 0.78275463 | AK10: 0 | AL10: 0 | AM10: 0 | AN10: 0 | AO10: 0 | AP10: 0 | AQ10: 0 | AR10: 0 | AS10: 0 | AT10: 0 | AU10: 0 | AV10: 0 | AW10: =AW9 -> 1.91522
A11: atlarch | B11: 2 | C11: WR00L2L2 | D11: 18368 | E11: 64 | F11: 2 | G11: 4 | H11: 2124.49 | I11: 1.9449 | J11: 45456 | K11: 0.97324074 | L11: 0 | M11: 0 | N11: 0 | O11: 0 | P11: 0 | Q11: 0 | R11: 0 | S11: 0 | T11: 0 | U11: 0 | V11: 0 | W11: 0 | X11: =X10 -> 1.90934 | Z11: atlarch | AA11: 2 | AB11: WR00L2L2 | AC11: 18368 | AD11: 64 | AE11: 2 | AF11: 4 | AG11: 2191.25 | AH11: 1.8856 | AI11: 45483 | AJ11: 0.81053241 | AK11: 0 | AL11: 0 | AM11: 0 | AN11: 0 | AO11: 0 | AP11: 0 | AQ11: 0 | AR11: 0 | AS11: 0 | AT11: 0 | AU11: 0 | AV11: 0 | AW11: =AW10 -> 1.91522
A12: atlarch | B12: 3 | C12: WR00L2L2 | D12: 18368 | E12: 64 | F12: 2 | G12: 4 | H12: 2143.94 | I12: 1.9272 | J12: 45456 | K12: 0.99876157 | L12: 0 | M12: 0 | N12: 0 | O12: 0 | P12: 0 | Q12: 0 | R12: 0 | S12: 0 | T12: 0 | U12: 0 | V12: 0 | W12: 0 | X12: =X11 -> 1.90934 | Z12: atlarch | AA12: 3 | AB12: WR00L2L2 | AC12: 18368 | AD12: 64 | AE12: 2 | AF12: 4 | AG12: 2132.47 | AH12: 1.9376 | AI12: 45483 | AJ12: 0.83788194 | AK12: 0 | AL12: 0 | AM12: 0 | AN12: 0 | AO12: 0 | AP12: 0 | AQ12: 0 | AR12: 0 | AS12: 0 | AT12: 0 | AU12: 0 | AV12: 0 | AW12: =AW11 -> 1.91522
A13: atlarch | B13: 4 | C13: WR00L2L2 | D13: 18368 | E13: 64 | F13: 2 | G13: 4 | H13: 2201.94 | I13: 1.8765 | J13: 45457 | K13: 0.024826389 | L13: 0 | M13: 0 | N13: 0 | O13: 0 | P13: 0 | Q13: 0 | R13: 0 | S13: 0 | T13: 0 | U13: 0 | V13: 0 | W13: 0 | X13: =X12 -> 1.90934 | Z13: atlarch | AA13: 4 | AB13: WR00L2L2 | AC13: 18368 | AD13: 64 | AE13: 2 | AF13: 4 | AG13: 2177.99 | AH13: 1.8971 | AI13: 45483 | AJ13: 0.86559028 | AK13: 0 | AL13: 0 | AM13: 0 | AN13: 0 | AO13: 0 | AP13: 0 | AQ13: 0 | AR13: 0 | AS13: 0 | AT13: 0 | AU13: 0 | AV13: 0 | AW13: =AW12 -> 1.91522
A14: arch-native-tune-flags | B14: 0 | C14: WR00L2L2 | D14: 18368 | E14: 64 | F14: 2 | G14: 4 | H14: 2277.34 | I14: 1.8143 | J14: 45457 | K14: 0.82138889 | L14: 0 | M14: 0 | N14: 0 | O14: 0 | P14: 0 | Q14: 0 | R14: 0 | S14: 0 | T14: 0 | U14: 0 | V14: 0 | W14: 0 | X14: =AVERAGE(I14:I18) -> 1.84274 | Z14: arch-native-tune-flags | AA14: 0 | AB14: WR00L2L2 | AC14: 18368 | AD14: 64 | AE14: 2 | AF14: 4 | AG14: 2236.66 | AH14: 1.8473 | AI14: 45484 | AJ14: 0.66046296 | AK14: 0 | AL14: 0 | AM14: 0 | AN14: 0 | AO14: 0 | AP14: 0 | AQ14: 0 | AR14: 0 | AS14: 0 | AT14: 0 | AU14: 0 | AV14: 0 | AW14: =AVERAGE(AH14:AH18) -> 1.87352
A15: arch-native-tune-flags | B15: 1 | C15: WR00L2L2 | D15: 18368 | E15: 64 | F15: 2 | G15: 4 | H15: 2291.43 | I15: 1.8032 | J15: 45457 | K15: 0.84855324 | L15: 0 | M15: 0 | N15: 0 | O15: 0 | P15: 0 | Q15: 0 | R15: 0 | S15: 0 | T15: 0 | U15: 0 | V15: 0 | W15: 0 | X15: =X14 -> 1.84274 | Z15: arch-native-tune-flags | AA15: 1 | AB15: WR00L2L2 | AC15: 18368 | AD15: 64 | AE15: 2 | AF15: 4 | AG15: 2100.84 | AH15: 1.9668 | AI15: 45484 | AJ15: 0.68550926 | AK15: 0 | AL15: 0 | AM15: 0 | AN15: 0 | AO15: 0 | AP15: 0 | AQ15: 0 | AR15: 0 | AS15: 0 | AT15: 0 | AU15: 0 | AV15: 0 | AW15: =AW14 -> 1.87352
A16: arch-native-tune-flags | B16: 2 | C16: WR00L2L2 | D16: 18368 | E16: 64 | F16: 2 | G16: 4 | H16: 2220.41 | I16: 1.8609 | J16: 45457 | K16: 0.87494213 | L16: 0 | M16: 0 | N16: 0 | O16: 0 | P16: 0 | Q16: 0 | R16: 0 | S16: 0 | T16: 0 | U16: 0 | V16: 0 | W16: 0 | X16: =X15 -> 1.84274 | Z16: arch-native-tune-flags | AA16: 2 | AB16: WR00L2L2 | AC16: 18368 | AD16: 64 | AE16: 2 | AF16: 4 | AG16: 2156.79 | AH16: 1.9158 | AI16: 45484 | AJ16: 0.71121528 | AK16: 0 | AL16: 0 | AM16: 0 | AN16: 0 | AO16: 0 | AP16: 0 | AQ16: 0 | AR16: 0 | AS16: 0 | AT16: 0 | AU16: 0 | AV16: 0 | AW16: =AW15 -> 1.87352
A17: arch-native-tune-flags | B17: 3 | C17: WR00L2L2 | D17: 18368 | E17: 64 | F17: 2 | G17: 4 | H17: 2212.66 | I17: 1.8674 | J17: 45457 | K17: 0.90118056 | L17: 0 | M17: 0 | N17: 0 | O17: 0 | P17: 0 | Q17: 0 | R17: 0 | S17: 0 | T17: 0 | U17: 0 | V17: 0 | W17: 0 | X17: =X16 -> 1.84274 | Z17: arch-native-tune-flags | AA17: 3 | AB17: WR00L2L2 | AC17: 18368 | AD17: 64 | AE17: 2 | AF17: 4 | AG17: 2287.45 | AH17: 1.8063 | AI17: 45484 | AJ17: 0.73829861 | AK17: 0 | AL17: 0 | AM17: 0 | AN17: 0 | AO17: 0 | AP17: 0 | AQ17: 0 | AR17: 0 | AS17: 0 | AT17: 0 | AU17: 0 | AV17: 0 | AW17: =AW16 -> 1.87352
A18: arch-native-tune-flags | B18: 4 | C18: WR00L2L2 | D18: 18368 | E18: 64 | F18: 2 | G18: 4 | H18: 2212.09 | I18: 1.8679 | J18: 45457 | K18: 0.92768519 | L18: 0 | M18: 0 | N18: 0 | O18: 0 | P18: 0 | Q18: 0 | R18: 0 | S18: 0 | T18: 0 | U18: 0 | V18: 0 | W18: 0 | X18: =X17 -> 1.84274 | Z18: arch-native-tune-flags | AA18: 4 | AB18: WR00L2L2 | AC18: 18368 | AD18: 64 | AE18: 2 | AF18: 4 | AG18: 2256.13 | AH18: 1.8314 | AI18: 45484 | AJ18: 0.76506944 | AK18: 0 | AL18: 0 | AM18: 0 | AN18: 0 | AO18: 0 | AP18: 0 | AQ18: 0 | AR18: 0 | AS18: 0 | AT18: 0 | AU18: 0 | AV18: 0 | AW18: =AW17 -> 1.87352
A19: cpu-tune-overr-flags | B19: 0 | C19: WR00L2L2 | D19: 18368 | E19: 64 | F19: 2 | G19: 4 | H19: 2254.38 | I19: 1.8328 | J19: 45457 | K19: 0.95446759 | L19: 0 | M19: 0 | N19: 0 | O19: 0 | P19: 0 | Q19: 0 | R19: 0 | S19: 0 | T19: 0 | U19: 0 | V19: 0 | W19: 0 | X19: =AVERAGE(I19:I23) -> 1.82554 | Z19: cpu-tune-flags | AA19: 0 | AB19: WR00L2L2 | AC19: 18368 | AD19: 64 | AE19: 2 | AF19: 4 | AG19: 2343.28 | AH19: 1.7633 | AI19: 45484 | AJ19: 0.52680556 | AK19: 0 | AL19: 0 | AM19: 0 | AN19: 0 | AO19: 0 | AP19: 0 | AQ19: 0 | AR19: 0 | AS19: 0 | AT19: 0 | AU19: 0 | AV19: 0 | AW19: =AVERAGE(AH19:AH23) -> 1.81704
A20: cpu-tune-overr-flags | B20: 1 | C20: WR00L2L2 | D20: 18368 | E20: 64 | F20: 2 | G20: 4 | H20: 2302.59 | I20: 1.7944 | J20: 45457 | K20: 0.98180556 | L20: 0 | M20: 0 | N20: 0 | O20: 0 | P20: 0 | Q20: 0 | R20: 0 | S20: 0 | T20: 0 | U20: 0 | V20: 0 | W20: 0 | X20: =X19 -> 1.82554 | Z20: cpu-tune-flags | AA20: 1 | AB20: WR00L2L2 | AC20: 18368 | AD20: 64 | AE20: 2 | AF20: 4 | AG20: 2264.46 | AH20: 1.8247 | AI20: 45484 | AJ20: 0.55365741 | AK20: 0 | AL20: 0 | AM20: 0 | AN20: 0 | AO20: 0 | AP20: 0 | AQ20: 0 | AR20: 0 | AS20: 0 | AT20: 0 | AU20: 0 | AV20: 0 | AW20: =AW19 -> 1.81704
A21: cpu-tune-overr-flags | B21: 2 | C21: WR00L2L2 | D21: 18368 | E21: 64 | F21: 2 | G21: 4 | H21: 2229.77 | I21: 1.8531 | J21: 45458 | K21: 0.0084953704 | L21: 0 | M21: 0 | N21: 0 | O21: 0 | P21: 0 | Q21: 0 | R21: 0 | S21: 0 | T21: 0 | U21: 0 | V21: 0 | W21: 0 | X21: =X20 -> 1.82554 | Z21: cpu-tune-flags | AA21: 2 | AB21: WR00L2L2 | AC21: 18368 | AD21: 64 | AE21: 2 | AF21: 4 | AG21: 2218.28 | AH21: 1.8627 | AI21: 45484 | AJ21: 0.57997685 | AK21: 0 | AL21: 0 | AM21: 0 | AN21: 0 | AO21: 0 | AP21: 0 | AQ21: 0 | AR21: 0 | AS21: 0 | AT21: 0 | AU21: 0 | AV21: 0 | AW21: =AW20 -> 1.81704
A22: cpu-tune-overr-flags | B22: 3 | C22: WR00L2L2 | D22: 18368 | E22: 64 | F22: 2 | G22: 4 | H22: 2259.78 | I22: 1.8284 | J22: 45458 | K22: 0.035358796 | L22: 0 | M22: 0 | N22: 0 | O22: 0 | P22: 0 | Q22: 0 | R22: 0 | S22: 0 | T22: 0 | U22: 0 | V22: 0 | W22: 0 | X22: =X21 -> 1.82554 | Z22: cpu-tune-flags | AA22: 3 | AB22: WR00L2L2 | AC22: 18368 | AD22: 64 | AE22: 2 | AF22: 4 | AG22: 2266.28 | AH22: 1.8232 | AI22: 45484 | AJ22: 0.6068287 | AK22: 0 | AL22: 0 | AM22: 0 | AN22: 0 | AO22: 0 | AP22: 0 | AQ22: 0 | AR22: 0 | AS22: 0 | AT22: 0 | AU22: 0 | AV22: 0 | AW22: =AW21 -> 1.81704
A23: cpu-tune-overr-flags | B23: 4 | C23: WR00L2L2 | D23: 18368 | E23: 64 | F23: 2 | G23: 4 | H23: 2271.55 | I23: 1.819 | J23: 45458 | K23: 0.062395833 | L23: 0 | M23: 0 | N23: 0 | O23: 0 | P23: 0 | Q23: 0 | R23: 0 | S23: 0 | T23: 0 | U23: 0 | V23: 0 | W23: 0 | X23: =X22 -> 1.82554 | Z23: cpu-tune-flags | AA23: 4 | AB23: WR00L2L2 | AC23: 18368 | AD23: 64 | AE23: 2 | AF23: 4 | AG23: 2281.12 | AH23: 1.8113 | AI23: 45484 | AJ23: 0.63395833 | AK23: 0 | AL23: 0 | AM23: 0 | AN23: 0 | AO23: 0 | AP23: 0 | AQ23: 0 | AR23: 0 | AS23: 0 | AT23: 0 | AU23: 0 | AV23: 0 | AW23: =AW22 -> 1.81704
A24: cpu-tune-flags | B24: 0 | C24: WR00L2L2 | D24: 18368 | E24: 64 | F24: 2 | G24: 4 | H24: 2273.99 | I24: 1.817 | J24: 45457 | K24: 0.68550926 | L24: 0 | M24: 0 | N24: 0 | O24: 0 | P24: 0 | Q24: 0 | R24: 0 | S24: 0 | T24: 0 | U24: 0 | V24: 0 | W24: 0 | X24: =AVERAGE(I24:I28) -> 1.80912 | Z24: cpu-tune-overr-flags | AA24: 0 | AB24: WR00L2L2 | AC24: 18368 | AD24: 64 | AE24: 2 | AF24: 4 | AG24: 2274.61 | AH24: 1.8165 | AI24: 45484 | AJ24: 0.79208333 | AK24: 0 | AL24: 0 | AM24: 0 | AN24: 0 | AO24: 0 | AP24: 0 | AQ24: 0 | AR24: 0 | AS24: 0 | AT24: 0 | AU24: 0 | AV24: 0 | AW24: =AVERAGE(AH24:AH28) -> 1.8137
A25: cpu-tune-flags | B25: 1 | C25: WR00L2L2 | D25: 18368 | E25: 64 | F25: 2 | G25: 4 | H25: 2331.69 | I25: 1.7721 | J25: 45457 | K25: 0.71324074 | L25: 0 | M25: 0 | N25: 0 | O25: 0 | P25: 0 | Q25: 0 | R25: 0 | S25: 0 | T25: 0 | U25: 0 | V25: 0 | W25: 0 | X25: =X24 -> 1.80912 | Z25: cpu-tune-overr-flags | AA25: 1 | AB25: WR00L2L2 | AC25: 18368 | AD25: 64 | AE25: 2 | AF25: 4 | AG25: 2232.54 | AH25: 1.8507 | AI25: 45484 | AJ25: 0.8187037 | AK25: 0 | AL25: 0 | AM25: 0 | AN25: 0 | AO25: 0 | AP25: 0 | AQ25: 0 | AR25: 0 | AS25: 0 | AT25: 0 | AU25: 0 | AV25: 0 | AW25: =AW24 -> 1.8137
A26: cpu-tune-flags | B26: 2 | C26: WR00L2L2 | D26: 18368 | E26: 64 | F26: 2 | G26: 4 | H26: 2216.08 | I26: 1.8645 | J26: 45457 | K26: 0.7396875 | L26: 0 | M26: 0 | N26: 0 | O26: 0 | P26: 0 | Q26: 0 | R26: 0 | S26: 0 | T26: 0 | U26: 0 | V26: 0 | W26: 0 | X26: =X25 -> 1.80912 | Z26: cpu-tune-overr-flags | AA26: 2 | AB26: WR00L2L2 | AC26: 18368 | AD26: 64 | AE26: 2 | AF26: 4 | AG26: 2302.16 | AH26: 1.7948 | AI26: 45484 | AJ26: 0.84613426 | AK26: 0 | AL26: 0 | AM26: 0 | AN26: 0 | AO26: 0 | AP26: 0 | AQ26: 0 | AR26: 0 | AS26: 0 | AT26: 0 | AU26: 0 | AV26: 0 | AW26: =AW25 -> 1.8137
A27: cpu-tune-flags | B27: 3 | C27: WR00L2L2 | D27: 18368 | E27: 64 | F27: 2 | G27: 4 | H27: 2330.84 | I27: 1.7727 | J27: 45457 | K27: 0.76741898 | L27: 0 | M27: 0 | N27: 0 | O27: 0 | P27: 0 | Q27: 0 | R27: 0 | S27: 0 | T27: 0 | U27: 0 | V27: 0 | W27: 0 | X27: =X26 -> 1.80912 | Z27: cpu-tune-overr-flags | AA27: 3 | AB27: WR00L2L2 | AC27: 18368 | AD27: 64 | AE27: 2 | AF27: 4 | AG27: 2307.63 | AH27: 1.7905 | AI27: 45484 | AJ27: 0.87358796 | AK27: 0 | AL27: 0 | AM27: 0 | AN27: 0 | AO27: 0 | AP27: 0 | AQ27: 0 | AR27: 0 | AS27: 0 | AT27: 0 | AU27: 0 | AV27: 0 | AW27: =AW26 -> 1.8137
A28: cpu-tune-flags | B28: 4 | C28: WR00L2L2 | D28: 18368 | E28: 64 | F28: 2 | G28: 4 | H28: 2271.15 | I28: 1.8193 | J28: 45457 | K28: 0.79440972 | L28: 0 | M28: 0 | N28: 0 | O28: 0 | P28: 0 | Q28: 0 | R28: 0 | S28: 0 | T28: 0 | U28: 0 | V28: 0 | W28: 0 | X28: =X27 -> 1.80912 | Z28: cpu-tune-overr-flags | AA28: 4 | AB28: WR00L2L2 | AC28: 18368 | AD28: 64 | AE28: 2 | AF28: 4 | AG28: 2275.27 | AH28: 1.816 | AI28: 45484 | AJ28: 0.90056713 | AK28: 0 | AL28: 0 | AM28: 0 | AN28: 0 | AO28: 0 | AP28: 0 | AQ28: 0 | AR28: 0 | AS28: 0 | AT28: 0 | AU28: 0 | AV28: 0 | AW28: =AW27 -> 1.8137
A29: arch-native-tune | B29: 0 | C29: WR00L2L2 | D29: 18368 | E29: 64 | F29: 2 | G29: 4 | H29: 2394.29 | I29: 1.7257 | J29: 45457 | K29: 0.21112269 | L29: 0 | M29: 0 | N29: 0 | O29: 0 | P29: 0 | Q29: 0 | R29: 0 | S29: 0 | T29: 0 | U29: 0 | V29: 0 | W29: 0 | X29: =AVERAGE(I29:I33) -> 1.68406 | Z29: arch-native-tune | AA29: 0 | AB29: WR00L2L2 | AC29: 18368 | AD29: 64 | AE29: 2 | AF29: 4 | AG29: 2514.06 | AH29: 1.6435 | AI29: 45484 | AJ29: 0.05275463 | AK29: 0 | AL29: 0 | AM29: 0 | AN29: 0 | AO29: 0 | AP29: 0 | AQ29: 0 | AR29: 0 | AS29: 0 | AT29: 0 | AU29: 0 | AV29: 0 | AW29: =AVERAGE(AH29:AH33) -> 1.68718
A30: arch-native-tune | B30: 1 | C30: WR00L2L2 | D30: 18368 | E30: 64 | F30: 2 | G30: 4 | H30: 2494.18 | I30: 1.6566 | J30: 45457 | K30: 0.24241898 | L30: 0 | M30: 0 | N30: 0 | O30: 0 | P30: 0 | Q30: 0 | R30: 0 | S30: 0 | T30: 0 | U30: 0 | V30: 0 | W30: 0 | X30: =X29 -> 1.68406 | Z30: arch-native-tune | AA30: 1 | AB30: WR00L2L2 | AC30: 18368 | AD30: 64 | AE30: 2 | AF30: 4 | AG30: 2473.41 | AH30: 1.6705 | AI30: 45484 | AJ30: 0.083842593 | AK30: 0 | AL30: 0 | AM30: 0 | AN30: 0 | AO30: 0 | AP30: 0 | AQ30: 0 | AR30: 0 | AS30: 0 | AT30: 0 | AU30: 0 | AV30: 0 | AW30: =AW29 -> 1.68718
A31: arch-native-tune | B31: 2 | C31: WR00L2L2 | D31: 18368 | E31: 64 | F31: 2 | G31: 4 | H31: 2405.44 | I31: 1.7177 | J31: 45457 | K31: 0.27284722 | L31: 0 | M31: 0 | N31: 0 | O31: 0 | P31: 0 | Q31: 0 | R31: 0 | S31: 0 | T31: 0 | U31: 0 | V31: 0 | W31: 0 | X31: =X30 -> 1.68406 | Z31: arch-native-tune | AA31: 2 | AB31: WR00L2L2 | AC31: 18368 | AD31: 64 | AE31: 2 | AF31: 4 | AG31: 2416.55 | AH31: 1.7098 | AI31: 45484 | AJ31: 0.11425926 | AK31: 0 | AL31: 0 | AM31: 0 | AN31: 0 | AO31: 0 | AP31: 0 | AQ31: 0 | AR31: 0 | AS31: 0 | AT31: 0 | AU31: 0 | AV31: 0 | AW31: =AW30 -> 1.68718
A32: arch-native-tune | B32: 3 | C32: WR00L2L2 | D32: 18368 | E32: 64 | F32: 2 | G32: 4 | H32: 2504.82 | I32: 1.6496 | J32: 45457 | K32: 0.30438657 | L32: 0 | M32: 0 | N32: 0 | O32: 0 | P32: 0 | Q32: 0 | R32: 0 | S32: 0 | T32: 0 | U32: 0 | V32: 0 | W32: 0 | X32: =X31 -> 1.68406 | Z32: arch-native-tune | AA32: 3 | AB32: WR00L2L2 | AC32: 18368 | AD32: 64 | AE32: 2 | AF32: 4 | AG32: 2448.33 | AH32: 1.6876 | AI32: 45484 | AJ32: 0.1450463 | AK32: 0 | AL32: 0 | AM32: 0 | AN32: 0 | AO32: 0 | AP32: 0 | AQ32: 0 | AR32: 0 | AS32: 0 | AT32: 0 | AU32: 0 | AV32: 0 | AW32: =AW31 -> 1.68718
A33: arch-native-tune | B33: 4 | C33: WR00L2L2 | D33: 18368 | E33: 64 | F33: 2 | G33: 4 | H33: 2473.2 | I33: 1.6707 | J33: 45457 | K33: 0.33559028 | L33: 0 | M33: 0 | N33: 0 | O33: 0 | P33: 0 | Q33: 0 | R33: 0 | S33: 0 | T33: 0 | U33: 0 | V33: 0 | W33: 0 | X33: =X32 -> 1.68406 | Z33: arch-native-tune | AA33: 4 | AB33: WR00L2L2 | AC33: 18368 | AD33: 64 | AE33: 2 | AF33: 4 | AG33: 2395.92 | AH33: 1.7245 | AI33: 45484 | AJ33: 0.17515046 | AK33: 0 | AL33: 0 | AM33: 0 | AN33: 0 | AO33: 0 | AP33: 0 | AQ33: 0 | AR33: 0 | AS33: 0 | AT33: 0 | AU33: 0 | AV33: 0 | AW33: =AW32 -> 1.68718
A34: cpu-tune | B34: 0 | C34: WR00L2L2 | D34: 18368 | E34: 64 | F34: 2 | G34: 4 | H34: 2439.06 | I34: 1.694 | J34: 45457 | K34: 0.055474537 | L34: 0 | M34: 0 | N34: 0 | O34: 0 | P34: 0 | Q34: 0 | R34: 0 | S34: 0 | T34: 0 | U34: 0 | V34: 0 | W34: 0 | X34: =AVERAGE(I34:I38) -> 1.66248 | Z34: cpu-tune | AA34: 0 | AB34: WR00L2L2 | AC34: 18368 | AD34: 64 | AE34: 2 | AF34: 4 | AG34: 2427.01 | AH34: 1.7025 | AI34: 45483 | AJ34: 0.89611111 | AK34: 0 | AL34: 0 | AM34: 0 | AN34: 0 | AO34: 0 | AP34: 0 | AQ34: 0 | AR34: 0 | AS34: 0 | AT34: 0 | AU34: 0 | AV34: 0 | AW34: =AVERAGE(AH34:AH38) -> 1.67164
A35: cpu-tune | B35: 1 | C35: WR00L2L2 | D35: 18368 | E35: 64 | F35: 2 | G35: 4 | H35: 2470.92 | I35: 1.6722 | J35: 45457 | K35: 0.086493056 | L35: 0 | M35: 0 | N35: 0 | O35: 0 | P35: 0 | Q35: 0 | R35: 0 | S35: 0 | T35: 0 | U35: 0 | V35: 0 | W35: 0 | X35: =X34 -> 1.66248 | Z35: cpu-tune | AA35: 1 | AB35: WR00L2L2 | AC35: 18368 | AD35: 64 | AE35: 2 | AF35: 4 | AG35: 2461.33 | AH35: 1.6787 | AI35: 45483 | AJ35: 0.92719907 | AK35: 0 | AL35: 0 | AM35: 0 | AN35: 0 | AO35: 0 | AP35: 0 | AQ35: 0 | AR35: 0 | AS35: 0 | AT35: 0 | AU35: 0 | AV35: 0 | AW35: =AW34 -> 1.67164
A36: cpu-tune | B36: 2 | C36: WR00L2L2 | D36: 18368 | E36: 64 | F36: 2 | G36: 4 | H36: 2521.36 | I36: 1.6387 | J36: 45457 | K36: 0.11828704 | L36: 0 | M36: 0 | N36: 0 | O36: 0 | P36: 0 | Q36: 0 | R36: 0 | S36: 0 | T36: 0 | U36: 0 | V36: 0 | W36: 0 | X36: =X35 -> 1.66248 | Z36: cpu-tune | AA36: 2 | AB36: WR00L2L2 | AC36: 18368 | AD36: 64 | AE36: 2 | AF36: 4 | AG36: 2460.79 | AH36: 1.6791 | AI36: 45483 | AJ36: 0.95799769 | AK36: 0 | AL36: 0 | AM36: 0 | AN36: 0 | AO36: 0 | AP36: 0 | AQ36: 0 | AR36: 0 | AS36: 0 | AT36: 0 | AU36: 0 | AV36: 0 | AW36: =AW35 -> 1.67164
A37: cpu-tune | B37: 3 | C37: WR00L2L2 | D37: 18368 | E37: 64 | F37: 2 | G37: 4 | H37: 2475.94 | I37: 1.6688 | J37: 45457 | K37: 0.14923611 | L37: 0 | M37: 0 | N37: 0 | O37: 0 | P37: 0 | Q37: 0 | R37: 0 | S37: 0 | T37: 0 | U37: 0 | V37: 0 | W37: 0 | X37: =X36 -> 1.66248 | Z37: cpu-tune | AA37: 3 | AB37: WR00L2L2 | AC37: 18368 | AD37: 64 | AE37: 2 | AF37: 4 | AG37: 2490 | AH37: 1.6594 | AI37: 45483 | AJ37: 0.98940972 | AK37: 0 | AL37: 0 | AM37: 0 | AN37: 0 | AO37: 0 | AP37: 0 | AQ37: 0 | AR37: 0 | AS37: 0 | AT37: 0 | AU37: 0 | AV37: 0 | AW37: =AW36 -> 1.67164
A38: cpu-tune | B38: 4 | C38: WR00L2L2 | D38: 18368 | E38: 64 | F38: 2 | G38: 4 | H38: 2521.36 | I38: 1.6387 | J38: 45457 | K38: 0.18086806 | L38: 0 | M38: 0 | N38: 0 | O38: 0 | P38: 0 | Q38: 0 | R38: 0 | S38: 0 | T38: 0 | U38: 0 | V38: 0 | W38: 0 | X38: =X37 -> 1.66248 | Z38: cpu-tune | AA38: 4 | AB38: WR00L2L2 | AC38: 18368 | AD38: 64 | AE38: 2 | AF38: 4 | AG38: 2521.71 | AH38: 1.6385 | AI38: 45484 | AJ38: 0.02119213 | AK38: 0 | AL38: 0 | AM38: 0 | AN38: 0 | AO38: 0 | AP38: 0 | AQ38: 0 | AR38: 0 | AS38: 0 | AT38: 0 | AU38: 0 | AV38: 0 | AW38: =AW37 -> 1.67164
A39: cpu-tune-overr | B39: 0 | C39: WR00L2L2 | D39: 18368 | E39: 64 | F39: 2 | G39: 4 | H39: 3243.27 | I39: 1.274 | J39: 45457 | K39: 0.37559028 | L39: 0 | M39: 0 | N39: 0 | O39: 0 | P39: 0 | Q39: 0 | R39: 0 | S39: 0 | T39: 0 | U39: 0 | V39: 0 | W39: 0 | X39: =AVERAGE(I39:I43) -> 1.3088 | Z39: cpu-tune-overr | AA39: 0 | AB39: WR00L2L2 | AC39: 18368 | AD39: 64 | AE39: 2 | AF39: 4 | AG39: 3141.6 | AH39: 1.3152 | AI39: 45484 | AJ39: 0.21409722 | AK39: 0 | AL39: 0 | AM39: 0 | AN39: 0 | AO39: 0 | AP39: 0 | AQ39: 0 | AR39: 0 | AS39: 0 | AT39: 0 | AU39: 0 | AV39: 0 | AW39: =AVERAGE(AH39:AH43) -> 1.28458
A40: cpu-tune-overr | B40: 1 | C40: WR00L2L2 | D40: 18368 | E40: 64 | F40: 2 | G40: 4 | H40: 3015.37 | I40: 1.3703 | J40: 45457 | K40: 0.41295139 | L40: 0 | M40: 0 | N40: 0 | O40: 0 | P40: 0 | Q40: 0 | R40: 0 | S40: 0 | T40: 0 | U40: 0 | V40: 0 | W40: 0 | X40: =X39 -> 1.3088 | Z40: cpu-tune-overr | AA40: 1 | AB40: WR00L2L2 | AC40: 18368 | AD40: 64 | AE40: 2 | AF40: 4 | AG40: 3225.71 | AH40: 1.2809 | AI40: 45484 | AJ40: 0.25408565 | AK40: 0 | AL40: 0 | AM40: 0 | AN40: 0 | AO40: 0 | AP40: 0 | AQ40: 0 | AR40: 0 | AS40: 0 | AT40: 0 | AU40: 0 | AV40: 0 | AW40: =AW39 -> 1.28458
...

Sheet 1 node, params, RAW
A1: Max avg. GFLOPS (and params): | E1: =MAX(N:N) -> 0.66076 | F1: =INDEX(C:C,MATCH(MAX($N:$N),$N:$N,0)) -> 9696 | G1: =INDEX(D:D,MATCH(MAX($N:$N),$N:$N,0)) -> 96 | H1: =INDEX(E:E,MATCH(MAX($N:$N),$N:$N,0)) -> 1 | I1: =INDEX(F:F,MATCH(MAX($N:$N),$N:$N,0)) -> 2 | K1: ATLAS (atlarch-flags) | N1: Average GFLOP/s | P1: Max avg. GFLOPS (and params): | T1: =MAX(AC:AC) -> 0.722498 | U1: =INDEX(R:R,MATCH(MAX($AC:$AC),$AC:$AC,0)) -> 10080 | V1: =INDEX(S:S,MATCH(MAX($AC:$AC),$AC:$AC,0)) -> 224 | W1: =INDEX(T:T,MATCH(MAX($AC:$AC),$AC:$AC,0)) -> 1 | X1: =INDEX(U:U,MATCH(MAX($AC:$AC),$AC:$AC,0)) -> 2 | Z1: OpenBLAS | AC1: Average GFLOP/s
A2: MAX GFLOPS: | C2: =MAX(H4:H841) -> 0.66798 | K2: cubie01 throttling time [1/100s] | P2: MAX GFLOPS: | R2: =MAX(W4:W841) -> 0.73424 | Z2: cubie02 throttling time [1/100s]
A3: RUN | C3: N | D3: NB | E3: P | F3: Q | G3: Time | H3: GFLOPS | I3: Date | J3: Time | K3: 720MHz | L3: 864MHz | M3: 912MHz | P3: RUN | R3: N | S3: NB | T3: P | U3: Q | V3: Time | W3: GFLOPS | X3: Date | Y3: Time | Z3: 720MHz | AA3: 864MHz | AB3: 912MHz
A4: 0 | B4: WR00L2L2 | C4: 9216 | D4: 32 | E4: 1 | F4: 2 | G4: 850.46 | H4: 0.61374 | I4: 45473 | J4: 0.84427083 | K4: 0 | L4: 0 | M4: 0 | N4: =AVERAGE(H4:H8) -> 0.616352 | P4: 0 | Q4: WR00L2L2 | R4: 9216 | S4: 32 | T4: 1 | U4: 2 | V4: 783.63 | W4: 0.66608 | X4: 45473 | Y4: 0.84574074 | Z4: 0 | AA4: 0 | AB4: 0 | AC4: =AVERAGE(W4:W8) -> 0.665978
A5: 1 | B5: WR00L2L2 | C5: 9216 | D5: 32 | E5: 1 | F5: 2 | G5: 840.96 | H5: 0.62068 | I5: 45474 | J5: 0.12278935 | K5: 0 | L5: 0 | M5: 0 | P5: 1 | Q5: WR00L2L2 | R5: 9216 | S5: 32 | T5: 1 | U5: 2 | V5: 781.1 | W5: 0.66825 | X5: 45474 | Y5: 0.14606481 | Z5: 0 | AA5: 0 | AB5: 0
A6: 2 | B6: WR00L2L2 | C6: 9216 | D6: 32 | E6: 1 | F6: 2 | G6: 843.14 | H6: 0.61908 | I6: 45474 | J6: 0.40077546 | K6: 0 | L6: 0 | M6: 0 | P6: 2 | Q6: WR00L2L2 | R6: 9216 | S6: 32 | T6: 1 | U6: 2 | V6: 790.89 | W6: 0.65998 | X6: 45474 | Y6: 0.44636574 | Z6: 0 | AA6: 0 | AB6: 0
A7: 3 | B7: WR00L2L2 | C7: 9216 | D7: 32 | E7: 1 | F7: 2 | G7: 857.83 | H7: 0.60847 | I7: 45474 | J7: 0.67914352 | K7: 0 | L7: 0 | M7: 0 | P7: 3 | Q7: WR00L2L2 | R7: 9216 | S7: 32 | T7: 1 | U7: 2 | V7: 781.3 | W7: 0.66807 | X7: 45474 | Y7: 0.74613426 | Z7: 0 | AA7: 0 | AB7: 0
A8: 4 | B8: WR00L2L2 | C8: 9216 | D8: 32 | E8: 1 | F8: 2 | G8: 842.16 | H8: 0.61979 | I8: 45474 | J8: 0.95700231 | K8: 0 | L8: 0 | M8: 0 | P8: 4 | Q8: WR00L2L2 | R8: 9216 | S8: 32 | T8: 1 | U8: 2 | V8: 781.95 | W8: 0.66751 | X8: 45475 | Y8: 0.046875 | Z8: 0 | AA8: 0 | AB8: 0
A9: 0 | B9: WR00L2L2 | C9: 9728 | D9: 32 | E9: 1 | F9: 2 | G9: 1002.9 | H9: 0.6121 | I9: 45473 | J9: 0.92534722 | K9: 0 | L9: 0 | M9: 0 | N9: =AVERAGE(H9:H13) -> 0.616688 | P9: 0 | Q9: WR00L2L2 | R9: 9728 | S9: 32 | T9: 1 | U9: 2 | V9: 924.5 | W9: 0.66401 | X9: 45473 | Y9: 0.93405093 | Z9: 0 | AA9: 0 | AB9: 0 | AC9: =AVERAGE(W9:W13) -> 0.671752
A10: 1 | B10: WR00L2L2 | C10: 9728 | D10: 32 | E10: 1 | F10: 2 | G10: 999.26 | H10: 0.61433 | I10: 45474 | J10: 0.20395833 | K10: 0 | L10: 0 | M10: 0 | P10: 1 | Q10: WR00L2L2 | R10: 9728 | S10: 32 | T10: 1 | U10: 2 | V10: 924.1 | W10: 0.66429 | X10: 45474 | Y10: 0.23387731 | Z10: 0 | AA10: 0 | AB10: 0
A11: 2 | B11: WR00L2L2 | C11: 9728 | D11: 32 | E11: 1 | F11: 2 | G11: 980.72 | H11: 0.62594 | I11: 45474 | J11: 0.48185185 | K11: 0 | L11: 0 | M11: 0 | P11: 2 | Q11: WR00L2L2 | R11: 9728 | S11: 32 | T11: 1 | U11: 2 | V11: 904.82 | W11: 0.67845 | X11: 45474 | Y11: 0.53435185 | Z11: 0 | AA11: 0 | AB11: 0
A12: 3 | B12: WR00L2L2 | C12: 9728 | D12: 32 | E12: 1 | F12: 2 | G12: 992.32 | H12: 0.61863 | I12: 45474 | J12: 0.76027778 | K12: 0 | L12: 0 | M12: 0 | P12: 3 | Q12: WR00L2L2 | R12: 9728 | S12: 32 | T12: 1 | U12: 2 | V12: 904.35 | W12: 0.6788 | X12: 45474 | Y12: 0.83449074 | Z12: 0 | AA12: 0 | AB12: 0
A13: 4 | B13: WR00L2L2 | C13: 9728 | D13: 32 | E13: 1 | F13: 2 | G13: 1002.34 | H13: 0.61244 | I13: 45475 | J13: 0.038414352 | K13: 0 | L13: 0 | M13: 0 | P13: 4 | Q13: WR00L2L2 | R13: 9728 | S13: 32 | T13: 1 | U13: 2 | V13: 911.86 | W13: 0.67321 | X13: 45475 | Y13: 0.13518519 | Z13: 0 | AA13: 0 | AB13: 0
A14: 0 | B14: WR00L2L2 | C14: 10240 | D14: 32 | E14: 1 | F14: 2 | G14: 1165.65 | H14: 0.61424 | I14: 45474 | J14: 0.019201389 | K14: 0 | L14: 0 | M14: 0 | N14: =AVERAGE(H14:H18) -> 0.61733 | P14: 0 | Q14: WR00L2L2 | R14: 10240 | S14: 32 | T14: 1 | U14: 2 | V14: 1050.16 | W14: 0.68179 | X14: 45474 | Y14: 0.0353125 | Z14: 0 | AA14: 0 | AB14: 0 | AC14: =AVERAGE(W14:W18) -> 0.678436
A15: 1 | B15: WR00L2L2 | C15: 10240 | D15: 32 | E15: 1 | F15: 2 | G15: 1152.09 | H15: 0.62147 | I15: 45474 | J15: 0.29756944 | K15: 0 | L15: 0 | M15: 0 | P15: 1 | Q15: WR00L2L2 | R15: 10240 | S15: 32 | T15: 1 | U15: 2 | V15: 1063.51 | W15: 0.67323 | X15: 45474 | Y15: 0.33534722 | Z15: 0 | AA15: 0 | AB15: 0
A16: 2 | B16: WR00L2L2 | C16: 10240 | D16: 32 | E16: 1 | F16: 2 | G16: 1168.13 | H16: 0.61293 | I16: 45474 | J16: 0.57547454 | K16: 0 | L16: 0 | M16: 0 | P16: 2 | Q16: WR00L2L2 | R16: 10240 | S16: 32 | T16: 1 | U16: 2 | V16: 1047.74 | W16: 0.68336 | X16: 45474 | Y16: 0.63537037 | Z16: 0 | AA16: 0 | AB16: 0
A17: 3 | B17: WR00L2L2 | C17: 10240 | D17: 32 | E17: 1 | F17: 2 | G17: 1156.02 | H17: 0.61935 | I17: 45474 | J17: 0.85364583 | K17: 0 | L17: 0 | M17: 0 | P17: 3 | Q17: WR00L2L2 | R17: 10240 | S17: 32 | T17: 1 | U17: 2 | V17: 1062.82 | W17: 0.67367 | X17: 45474 | Y17: 0.93585648 | Z17: 0 | AA17: 0 | AB17: 0
A18: 4 | B18: WR00L2L2 | C18: 10240 | D18: 32 | E18: 1 | F18: 2 | G18: 1157.32 | H18: 0.61866 | I18: 45475 | J18: 0.13216435 | K18: 0 | L18: 0 | M18: 0 | P18: 4 | Q18: WR00L2L2 | R18: 10240 | S18: 32 | T18: 1 | U18: 2 | V18: 1052.72 | W18: 0.68013 | X18: 45475 | Y18: 0.23612269 | Z18: 0 | AA18: 0 | AB18: 0
A19: 0 | B19: WR00L2L2 | C19: 9216 | D19: 64 | E19: 1 | F19: 2 | G19: 840.69 | H19: 0.62088 | I19: 45473 | J19: 0.85447917 | K19: 0 | L19: 0 | M19: 0 | N19: =AVERAGE(H19:H23) -> 0.621298 | P19: 0 | Q19: WR00L2L2 | R19: 9216 | S19: 64 | T19: 1 | U19: 2 | V19: 740.71 | W19: 0.70468 | X19: 45473 | Y19: 0.85666667 | Z19: 0 | AA19: 0 | AB19: 0 | AC19: =AVERAGE(W19:W23) -> 0.707938
A20: 1 | B20: WR00L2L2 | C20: 9216 | D20: 64 | E20: 1 | F20: 2 | G20: 854.12 | H20: 0.61111 | I20: 45474 | J20: 0.13311343 | K20: 0 | L20: 0 | M20: 0 | P20: 1 | Q20: WR00L2L2 | R20: 9216 | S20: 64 | T20: 1 | U20: 2 | V20: 741.5 | W20: 0.70393 | X20: 45474 | Y20: 0.15679398 | Z20: 0 | AA20: 0 | AB20: 0
A21: 2 | B21: WR00L2L2 | C21: 9216 | D21: 64 | E21: 1 | F21: 2 | G21: 835.61 | H21: 0.62465 | I21: 45474 | J21: 0.4108912 | K21: 0 | L21: 0 | M21: 0 | P21: 2 | Q21: WR00L2L2 | R21: 9216 | S21: 64 | T21: 1 | U21: 2 | V21: 738.96 | W21: 0.70635 | X21: 45474 | Y21: 0.45706019 | Z21: 0 | AA21: 0 | AB21: 0
A22: 3 | B22: WR00L2L2 | C22: 9216 | D22: 64 | E22: 1 | F22: 2 | G22: 833.96 | H22: 0.62589 | I22: 45474 | J22: 0.68923611 | K22: 0 | L22: 0 | M22: 0 | P22: 3 | Q22: WR00L2L2 | R22: 9216 | S22: 64 | T22: 1 | U22: 2 | V22: 742.58 | W22: 0.70291 | X22: 45474 | Y22: 0.75695602 | Z22: 0 | AA22: 0 | AB22: 0
A23: 4 | B23: WR00L2L2 | C23: 9216 | D23: 64 | E23: 1 | F23: 2 | G23: 836.54 | H23: 0.62396 | I23: 45474 | J23: 0.96711806 | K23: 0 | L23: 0 | M23: 0 | P23: 4 | Q23: WR00L2L2 | R23: 9216 | S23: 64 | T23: 1 | U23: 2 | V23: 723.12 | W23: 0.72182 | X23: 45475 | Y23: 0.057800926 | Z23: 0 | AA23: 0 | AB23: 0
A24: 0 | B24: WR00L2L2 | C24: 9728 | D24: 64 | E24: 1 | F24: 2 | G24: 990.62 | H24: 0.61969 | I24: 45473 | J24: 0.93729167 | K24: 0 | L24: 0 | M24: 0 | N24: =AVERAGE(H24:H28) -> 0.624304 | P24: 0 | Q24: WR00L2L2 | R24: 9728 | S24: 64 | T24: 1 | U24: 2 | V24: 857.94 | W24: 0.71552 | X24: 45473 | Y24: 0.94672454 | Z24: 0 | AA24: 0 | AB24: 0 | AC24: =AVERAGE(W24:W28) -> 0.715902
A25: 1 | B25: WR00L2L2 | C25: 9728 | D25: 64 | E25: 1 | F25: 2 | G25: 988.54 | H25: 0.62099 | I25: 45474 | J25: 0.2158912 | K25: 0 | L25: 0 | M25: 0 | P25: 1 | Q25: WR00L2L2 | R25: 9728 | S25: 64 | T25: 1 | U25: 2 | V25: 857.41 | W25: 0.71597 | X25: 45474 | Y25: 0.24657407 | Z25: 0 | AA25: 0 | AB25: 0
A26: 2 | B26: WR00L2L2 | C26: 9728 | D26: 64 | E26: 1 | F26: 2 | G26: 972.73 | H26: 0.63108 | I26: 45474 | J26: 0.49361111 | K26: 0 | L26: 0 | M26: 0 | P26: 2 | Q26: WR00L2L2 | R26: 9728 | S26: 64 | T26: 1 | U26: 2 | V26: 856.97 | W26: 0.71633 | X26: 45474 | Y26: 0.54703704 | Z26: 0 | AA26: 0 | AB26: 0
A27: 3 | B27: WR00L2L2 | C27: 9728 | D27: 64 | E27: 1 | F27: 2 | G27: 972.4 | H27: 0.6313 | I27: 45474 | J27: 0.77201389 | K27: 0 | L27: 0 | M27: 0 | P27: 3 | Q27: WR00L2L2 | R27: 9728 | S27: 64 | T27: 1 | U27: 2 | V27: 857.95 | W27: 0.71551 | X27: 45474 | Y27: 0.84700231 | Z27: 0 | AA27: 0 | AB27: 0
A28: 4 | B28: WR00L2L2 | C28: 9728 | D28: 64 | E28: 1 | F28: 2 | G28: 992.58 | H28: 0.61846 | I28: 45475 | J28: 0.050381944 | K28: 0 | L28: 0 | M28: 0 | P28: 4 | Q28: WR00L2L2 | R28: 9728 | S28: 64 | T28: 1 | U28: 2 | V28: 857.15 | W28: 0.71618 | X28: 45475 | Y28: 0.14765046 | Z28: 0 | AA28: 0 | AB28: 0
A29: 0 | B29: WR00L2L2 | C29: 10240 | D29: 64 | E29: 1 | F29: 2 | G29: 1145.03 | H29: 0.6253 | I29: 45474 | J29: 0.033148148 | K29: 0 | L29: 0 | M29: 0 | N29: =AVERAGE(H29:H33) -> 0.62391 | P29: 0 | Q29: WR00L2L2 | R29: 10240 | S29: 64 | T29: 1 | U29: 2 | V29: 1009.13 | W29: 0.70951 | X29: 45474 | Y29: 0.049641204 | Z29: 0 | AA29: 0 | AB29: 0 | AC29: =AVERAGE(W29:W33) -> 0.708562
A30: 1 | B30: WR00L2L2 | C30: 10240 | D30: 64 | E30: 1 | F30: 2 | G30: 1145.93 | H30: 0.62481 | I30: 45474 | J30: 0.31152778 | K30: 0 | L30: 0 | M30: 0 | P30: 1 | Q30: WR00L2L2 | R30: 10240 | S30: 64 | T30: 1 | U30: 2 | V30: 1023.2 | W30: 0.69975 | X30: 45474 | Y30: 0.34990741 | Z30: 0 | AA30: 0 | AB30: 0
A31: 2 | B31: WR00L2L2 | C31: 10240 | D31: 64 | E31: 1 | F31: 2 | G31: 1143.39 | H31: 0.62619 | I31: 45474 | J31: 0.58923611 | K31: 0 | L31: 0 | M31: 0 | P31: 2 | Q31: WR00L2L2 | R31: 10240 | S31: 64 | T31: 1 | U31: 2 | V31: 1006.87 | W31: 0.7111 | X31: 45474 | Y31: 0.64986111 | Z31: 0 | AA31: 0 | AB31: 0
A32: 3 | B32: WR00L2L2 | C32: 10240 | D32: 64 | E32: 1 | F32: 2 | G32: 1161 | H32: 0.6167 | I32: 45474 | J32: 0.86761574 | K32: 0 | L32: 0 | M32: 0 | P32: 3 | Q32: WR00L2L2 | R32: 10240 | S32: 64 | T32: 1 | U32: 2 | V32: 1008.08 | W32: 0.71024 | X32: 45474 | Y32: 0.95034722 | Z32: 0 | AA32: 0 | AB32: 0
A33: 4 | B33: WR00L2L2 | C33: 10240 | D33: 64 | E33: 1 | F33: 2 | G33: 1142.74 | H33: 0.62655 | I33: 45475 | J33: 0.14592593 | K33: 0 | L33: 0 | M33: 0 | P33: 4 | Q33: WR00L2L2 | R33: 10240 | S33: 64 | T33: 1 | U33: 2 | V33: 1005.31 | W33: 0.71221 | X33: 45475 | Y33: 0.2505787 | Z33: 0 | AA33: 0 | AB33: 0
A34: 0 | B34: WR00L2L2 | C34: 9216 | D34: 96 | E34: 1 | F34: 2 | G34: 810.13 | H34: 0.6443 | I34: 45473 | J34: 0.86429398 | K34: 0 | L34: 0 | M34: 0 | N34: =AVERAGE(H34:H38) -> 0.643476 | P34: 0 | Q34: WR00L2L2 | R34: 9216 | S34: 96 | T34: 1 | U34: 2 | V34: 730.77 | W34: 0.71427 | X34: 45473 | Y34: 0.8674537 | Z34: 0 | AA34: 0 | AB34: 0 | AC34: =AVERAGE(W34:W38) -> 0.71399
A35: 1 | B35: WR00L2L2 | C35: 9216 | D35: 96 | E35: 1 | F35: 2 | G35: 800.92 | H35: 0.65171 | I35: 45474 | J35: 0.14292824 | K35: 0 | L35: 0 | M35: 0 | P35: 1 | Q35: WR00L2L2 | R35: 9216 | S35: 96 | T35: 1 | U35: 2 | V35: 733 | W35: 0.71209 | X35: 45474 | Y35: 0.16753472 | Z35: 0 | AA35: 0 | AB35: 0
A36: 2 | B36: WR00L2L2 | C36: 9216 | D36: 96 | E36: 1 | F36: 2 | G36: 810.6 | H36: 0.64393 | I36: 45474 | J36: 0.42086806 | K36: 0 | L36: 0 | M36: 0 | P36: 2 | Q36: WR00L2L2 | R36: 9216 | S36: 96 | T36: 1 | U36: 2 | V36: 729.05 | W36: 0.71596 | X36: 45474 | Y36: 0.4678588 | Z36: 0 | AA36: 0 | AB36: 0
A37: 3 | B37: WR00L2L2 | C37: 9216 | D37: 96 | E37: 1 | F37: 2 | G37: 808.48 | H37: 0.64562 | I37: 45474 | J37: 0.69902778 | K37: 0 | L37: 0 | M37: 0 | P37: 3 | Q37: WR00L2L2 | R37: 9216 | S37: 96 | T37: 1 | U37: 2 | V37: 728.9 | W37: 0.7161 | X37: 45474 | Y37: 0.76777778 | Z37: 0 | AA37: 0 | AB37: 0
A38: 4 | B38: WR00L2L2 | C38: 9216 | D38: 96 | E38: 1 | F38: 2 | G38: 826.13 | H38: 0.63182 | I38: 45474 | J38: 0.97711806 | K38: 0 | L38: 0 | M38: 0 | P38: 4 | Q38: WR00L2L2 | R38: 9216 | S38: 96 | T38: 1 | U38: 2 | V38: 733.58 | W38: 0.71153 | X38: 45475 | Y38: 0.068622685 | Z38: 0 | AA38: 0 | AB38: 0
A39: 0 | B39: WR00L2L2 | C39: 9696 | D39: 96 | E39: 1 | F39: 2 | G39: 917.37 | H39: 0.66258 | I39: 45473 | J39: 0.94850694 | K39: 0 | L39: 0 | M39: 0 | N39: =AVERAGE(H39:H43) -> 0.66076 | P39: 0 | Q39: WR00L2L2 | R39: 9696 | S39: 96 | T39: 1 | U39: 2 | V39: 837.85 | W39: 0.72547 | X39: 45473 | Y39: 0.95898148 | Z39: 0 | AA39: 0 | AB39: 0 | AC39: =AVERAGE(W39:W43) -> 0.722168
A40: 1 | B40: WR00L2L2 | C40: 9696 | D40: 96 | E40: 1 | F40: 2 | G40: 929.15 | H40: 0.65418 | I40: 45474 | J40: 0.22712963 | K40: 0 | L40: 0 | M40: 0 | P40: 1 | Q40: WR00L2L2 | R40: 9696 | S40: 96 | T40: 1 | U40: 2 | V40: 836.88 | W40: 0.72631 | X40: 45474 | Y40: 0.25883102 | Z40: 0 | AA40: 0 | AB40: 0
...

Sheet 4 node, params, RAW
A1: Max avg. GFLOPS (and params): | E1: =MAX(W:W) -> 2.1007 | F1: =INDEX(C:C,MATCH(MAX($W:$W),$W:$W,0)) -> 19392 | G1: =INDEX(D:D,MATCH(MAX($W:$W),$W:$W,0)) -> 192 | H1: =INDEX(E:E,MATCH(MAX($W:$W),$W:$W,0)) -> 2 | I1: =INDEX(F:F,MATCH(MAX($W:$W),$W:$W,0)) -> 4 | K1: ATLAS (atlarch-flags) | W1: Average GFLOP/s | Y1: Max avg. GFLOPS (and params): | AC1: =MAX(AU:AU) -> 2.3454 | AD1: =INDEX(AA:AA,MATCH(MAX($AU:$AU),$AU:$AU,0)) -> 19264 | AE1: =INDEX(AB:AB,MATCH(MAX($AU:$AU),$AU:$AU,0)) -> 224 | AF1: =INDEX(AC:AC,MATCH(MAX($AU:$AU),$AU:$AU,0)) -> 1 | AG1: =INDEX(AD:AD,MATCH(MAX($AU:$AU),$AU:$AU,0)) -> 8 | AI1: OpenBLAS | AU1: Average GFLOP/s
A2: MAX GFLOPS: | C2: =MAX(H4:H841) -> 2.209 | K2: cubie01 throttling time [1/100s] | N2: cubie02 throttling time [1/100s] | Q2: cubie03 throttling time [1/100s] | T2: cubie04 throttling time [1/100s] | Y2: MAX GFLOPS: | AA2: =MAX(AF4:AF841) -> 2.3921 | AI2: cubie01 throttling time [1/100s] | AL2: cubie02 throttling time [1/100s] | AO2: cubie03 throttling time [1/100s] | AR2: cubie04 throttling time [1/100s]
A3: RUN | C3: N | D3: NB | E3: P | F3: Q | G3: Time | H3: GFLOPS | I3: Date | J3: Time | K3: 720MHz | L3: 864MHz | M3: 912MHz | N3: 720MHz | O3: 864MHz | P3: 912MHz | Q3: 720MHz | R3: 864MHz | S3: 912MHz | T3: 720MHz | U3: 864MHz | V3: 912MHz | Y3: RUN | AA3: N | AB3: NB | AC3: P | AD3: Q | AE3: Time | AF3: GFLOPS | AG3: Date | AH3: Time | AI3: 720MHz | AJ3: 864MHz | AK3: 912MHz | AL3: 720MHz | AM3: 864MHz | AN3: 912MHz | AO3: 720MHz | AP3: 864MHz | AQ3: 912MHz | AR3: 720MHz | AS3: 864MHz | AT3: 912MHz
A4: 0 | B4: WR00L2L2 | C4: 18368 | D4: 32 | E4: 1 | F4: 8 | G4: 2173.15 | H4: 1.9013 | I4: 45458 | J4: 0.84365741 | K4: 0 | L4: 0 | M4: 0 | N4: 0 | O4: 0 | P4: 0 | Q4: 0 | R4: 0 | S4: 0 | T4: 0 | U4: 0 | V4: 0 | W4: =AVERAGE(H4:H8) -> 1.92026 | Y4: 0 | Z4: WR00L2L2 | AA4: 18368 | AB4: 32 | AC4: 1 | AD4: 8 | AE4: 2052.06 | AF4: 2.0135 | AG4: 45465 | AH4: 0.87331019 | AI4: 0 | AJ4: 0 | AK4: 0 | AL4: 0 | AM4: 0 | AN4: 0 | AO4: 0 | AP4: 0 | AQ4: 0 | AR4: 0 | AS4: 0 | AT4: 0 | AU4: =AVERAGE(AF4:AF8) -> 2.069
A5: 1 | B5: WR00L2L2 | C5: 18368 | D5: 32 | E5: 1 | F5: 8 | G5: 2209.33 | H5: 1.8702 | I5: 45460 | J5: 0.13945602 | K5: 0 | L5: 0 | M5: 0 | N5: 0 | O5: 0 | P5: 0 | Q5: 0 | R5: 0 | S5: 0 | T5: 0 | U5: 0 | V5: 0 | Y5: 1 | Z5: WR00L2L2 | AA5: 18368 | AB5: 32 | AC5: 1 | AD5: 8 | AE5: 2033.12 | AF5: 2.0323 | AG5: 45468 | AH5: 0.73483796 | AI5: 0 | AJ5: 0 | AK5: 0 | AL5: 0 | AM5: 0 | AN5: 0 | AO5: 0 | AP5: 0 | AQ5: 0 | AR5: 0 | AS5: 0 | AT5: 0
A6: 2 | B6: WR00L2L2 | C6: 18368 | D6: 32 | E6: 1 | F6: 8 | G6: 2230.14 | H6: 1.8527 | I6: 45461 | J6: 0.74884259 | K6: 0 | L6: 0 | M6: 0 | N6: 0 | O6: 0 | P6: 0 | Q6: 0 | R6: 0 | S6: 0 | T6: 0 | U6: 0 | V6: 0 | Y6: 2 | Z6: WR00L2L2 | AA6: 18368 | AB6: 32 | AC6: 1 | AD6: 8 | AE6: 1875.5 | AF6: 2.2031 | AG6: 45469 | AH6: 0.99608796 | AI6: 0 | AJ6: 0 | AK6: 0 | AL6: 0 | AM6: 0 | AN6: 0 | AO6: 0 | AP6: 0 | AQ6: 0 | AR6: 0 | AS6: 0 | AT6: 0
A7: 3 | B7: WR00L2L2 | C7: 18368 | D7: 32 | E7: 1 | F7: 8 | G7: 2088.59 | H7: 1.9783 | I7: 45463 | J7: 0.048402778 | K7: 0 | L7: 0 | M7: 0 | N7: 0 | O7: 0 | P7: 0 | Q7: 0 | R7: 0 | S7: 0 | T7: 0 | U7: 0 | V7: 0 | Y7: 3 | Z7: WR00L2L2 | AA7: 18368 | AB7: 32 | AC7: 1 | AD7: 8 | AE7: 2114.33 | AF7: 1.9542 | AG7: 45471 | AH7: 0.26579861 | AI7: 0 | AJ7: 0 | AK7: 0 | AL7: 0 | AM7: 0 | AN7: 0 | AO7: 0 | AP7: 0 | AQ7: 0 | AR7: 0 | AS7: 0 | AT7: 0
A8: 4 | B8: WR00L2L2 | C8: 18368 | D8: 32 | E8: 1 | F8: 8 | G8: 2067.22 | H8: 1.9988 | I8: 45464 | J8: 0.32649306 | K8: 0 | L8: 0 | M8: 0 | N8: 0 | O8: 0 | P8: 0 | Q8: 0 | R8: 0 | S8: 0 | T8: 0 | U8: 0 | V8: 0 | Y8: 4 | Z8: WR00L2L2 | AA8: 18368 | AB8: 32 | AC8: 1 | AD8: 8 | AE8: 1929.08 | AF8: 2.1419 | AG8: 45472 | AH8: 0.53038194 | AI8: 0 | AJ8: 0 | AK8: 0 | AL8: 0 | AM8: 0 | AN8: 0 | AO8: 0 | AP8: 0 | AQ8: 0 | AR8: 0 | AS8: 0 | AT8: 0
A9: 0 | B9: WR00L2L2 | C9: 19456 | D9: 32 | E9: 1 | F9: 8 | G9: 2633.52 | H9: 1.8646 | I9: 45459 | J9: 0.2371875 | K9: 0 | L9: 0 | M9: 0 | N9: 0 | O9: 0 | P9: 0 | Q9: 0 | R9: 0 | S9: 0 | T9: 0 | U9: 0 | V9: 0 | W9: =AVERAGE(H9:H13) -> 1.87564 | Y9: 0 | Z9: WR00L2L2 | AA9: 19456 | AB9: 32 | AC9: 1 | AD9: 8 | AE9: 2220.95 | AF9: 2.211 | AG9: 45466 | AH9: 0.26012731 | AI9: 0 | AJ9: 0 | AK9: 0 | AL9: 0 | AM9: 0 | AN9: 0 | AO9: 0 | AP9: 0 | AQ9: 0 | AR9: 0 | AS9: 0 | AT9: 0 | AU9: =AVERAGE(AF9:AF13) -> 2.0891
A10: 1 | B10: WR00L2L2 | C10: 19456 | D10: 32 | E10: 1 | F10: 8 | G10: 2649.02 | H10: 1.8537 | I10: 45460 | J10: 0.53678241 | K10: 0 | L10: 0 | M10: 0 | N10: 0 | O10: 0 | P10: 0 | Q10: 0 | R10: 0 | S10: 0 | T10: 0 | U10: 0 | V10: 0 | Y10: 1 | Z10: WR00L2L2 | AA10: 19456 | AB10: 32 | AC10: 1 | AD10: 8 | AE10: 2397.63 | AF10: 2.048 | AG10: 45469 | AH10: 0.11774306 | AI10: 0 | AJ10: 0 | AK10: 0 | AL10: 0 | AM10: 0 | AN10: 0 | AO10: 0 | AP10: 0 | AQ10: 0 | AR10: 0 | AS10: 0 | AT10: 0
A11: 2 | B11: WR00L2L2 | C11: 19456 | D11: 32 | E11: 1 | F11: 8 | G11: 2643.58 | H11: 1.8575 | I11: 45462 | J11: 0.14311343 | K11: 0 | L11: 0 | M11: 0 | N11: 0 | O11: 0 | P11: 0 | Q11: 0 | R11: 0 | S11: 0 | T11: 0 | U11: 0 | V11: 0 | Y11: 2 | Z11: WR00L2L2 | AA11: 19456 | AB11: 32 | AC11: 1 | AD11: 8 | AE11: 2340.06 | AF11: 2.0984 | AG11: 45470 | AH11: 0.38740741 | AI11: 0 | AJ11: 0 | AK11: 0 | AL11: 0 | AM11: 0 | AN11: 0 | AO11: 0 | AP11: 0 | AQ11: 0 | AR11: 0 | AS11: 0 | AT11: 0
A12: 3 | B12: WR00L2L2 | C12: 19456 | D12: 32 | E12: 1 | F12: 8 | G12: 2573.3 | H12: 1.9082 | I12: 45463 | J12: 0.43929398 | K12: 0 | L12: 0 | M12: 0 | N12: 0 | O12: 0 | P12: 0 | Q12: 0 | R12: 0 | S12: 0 | T12: 0 | U12: 0 | V12: 0 | Y12: 3 | Z12: WR00L2L2 | AA12: 19456 | AB12: 32 | AC12: 1 | AD12: 8 | AE12: 2424.03 | AF12: 2.0257 | AG12: 45471 | AH12: 0.65341435 | AI12: 0 | AJ12: 0 | AK12: 0 | AL12: 0 | AM12: 0 | AN12: 0 | AO12: 0 | AP12: 0 | AQ12: 0 | AR12: 0 | AS12: 0 | AT12: 0
A13: 4 | B13: WR00L2L2 | C13: 19456 | D13: 32 | E13: 1 | F13: 8 | G13: 2592.3 | H13: 1.8942 | I13: 45464 | J13: 0.719375 | K13: 0 | L13: 0 | M13: 0 | N13: 0 | O13: 0 | P13: 0 | Q13: 0 | R13: 0 | S13: 0 | T13: 0 | U13: 0 | V13: 0 | Y13: 4 | Z13: WR00L2L2 | AA13: 19456 | AB13: 32 | AC13: 1 | AD13: 8 | AE13: 2380.9 | AF13: 2.0624 | AG13: 45472 | AH13: 0.9155787 | AI13: 0 | AJ13: 0 | AK13: 0 | AL13: 0 | AM13: 0 | AN13: 0 | AO13: 0 | AP13: 0 | AQ13: 0 | AR13: 0 | AS13: 0 | AT13: 0
A14: 0 | B14: WR00L2L2 | C14: 20544 | D14: 32 | E14: 1 | F14: 8 | G14: 2930.42 | H14: 1.9728 | I14: 45459 | J14: 0.69859954 | K14: 0 | L14: 0 | M14: 0 | N14: 0 | O14: 0 | P14: 0 | Q14: 0 | R14: 0 | S14: 0 | T14: 0 | U14: 0 | V14: 0 | W14: =AVERAGE(H14:H18) -> 1.96902 | Y14: 0 | Z14: WR00L2L2 | AA14: 20544 | AB14: 32 | AC14: 1 | AD14: 8 | AE14: 2777.38 | AF14: 2.0815 | AG14: 45466 | AH14: 0.71125 | AI14: 0 | AJ14: 0 | AK14: 0 | AL14: 0 | AM14: 0 | AN14: 0 | AO14: 0 | AP14: 0 | AQ14: 0 | AR14: 0 | AS14: 0 | AT14: 0 | AU14: =AVERAGE(AF14:AF18) -> 2.12486
A15: 1 | B15: WR00L2L2 | C15: 20544 | D15: 32 | E15: 1 | F15: 8 | G15: 3069.11 | H15: 1.8836 | I15: 45461 | J15: 0.0017013889 | K15: 0 | L15: 0 | M15: 0 | N15: 0 | O15: 0 | P15: 0 | Q15: 0 | R15: 0 | S15: 0 | T15: 0 | U15: 0 | V15: 0 | Y15: 1 | Z15: WR00L2L2 | AA15: 20544 | AB15: 32 | AC15: 1 | AD15: 8 | AE15: 2751.49 | AF15: 2.1011 | AG15: 45469 | AH15: 0.56872685 | AI15: 0 | AJ15: 0 | AK15: 0 | AL15: 0 | AM15: 0 | AN15: 0 | AO15: 0 | AP15: 0 | AQ15: 0 | AR15: 0 | AS15: 0 | AT15: 0
A16: 2 | B16: WR00L2L2 | C16: 20544 | D16: 32 | E16: 1 | F16: 8 | G16: 2870.37 | H16: 2.0141 | I16: 45462 | J16: 0.60650463 | K16: 0 | L16: 0 | M16: 0 | N16: 0 | O16: 0 | P16: 0 | Q16: 0 | R16: 0 | S16: 0 | T16: 0 | U16: 0 | V16: 0 | Y16: 2 | Z16: WR00L2L2 | AA16: 20544 | AB16: 32 | AC16: 1 | AD16: 8 | AE16: 2610.62 | AF16: 2.2145 | AG16: 45470 | AH16: 0.83747685 | AI16: 0 | AJ16: 0 | AK16: 0 | AL16: 0 | AM16: 0 | AN16: 0 | AO16: 0 | AP16: 0 | AQ16: 0 | AR16: 0 | AS16: 0 | AT16: 0
A17: 3 | B17: WR00L2L2 | C17: 20544 | D17: 32 | E17: 1 | F17: 8 | G17: 2997.22 | H17: 1.9288 | I17: 45463 | J17: 0.90179398 | K17: 0 | L17: 0 | M17: 0 | N17: 0 | O17: 0 | P17: 0 | Q17: 0 | R17: 0 | S17: 0 | T17: 0 | U17: 0 | V17: 0 | Y17: 3 | Z17: WR00L2L2 | AA17: 20544 | AB17: 32 | AC17: 1 | AD17: 8 | AE17: 2695.51 | AF17: 2.1447 | AG17: 45472 | AH17: 0.10237269 | AI17: 0 | AJ17: 0 | AK17: 0 | AL17: 0 | AM17: 0 | AN17: 0 | AO17: 0 | AP17: 0 | AQ17: 0 | AR17: 0 | AS17: 0 | AT17: 0
A18: 4 | B18: WR00L2L2 | C18: 20544 | D18: 32 | E18: 1 | F18: 8 | G18: 2825.81 | H18: 2.0458 | I18: 45465 | J18: 0.17564815 | K18: 0 | L18: 0 | M18: 0 | N18: 0 | O18: 0 | P18: 0 | Q18: 0 | R18: 0 | S18: 0 | T18: 0 | U18: 0 | V18: 0 | Y18: 4 | Z18: WR00L2L2 | AA18: 20544 | AB18: 32 | AC18: 1 | AD18: 8 | AE18: 2776.07 | AF18: 2.0825 | AG18: 45473 | AH18: 0.37005787 | AI18: 0 | AJ18: 0 | AK18: 0 | AL18: 0 | AM18: 0 | AN18: 0 | AO18: 0 | AP18: 0 | AQ18: 0 | AR18: 0 | AS18: 0 | AT18: 0
A19: 0 | B19: WR00L2L2 | C19: 18368 | D19: 32 | E19: 2 | F19: 4 | G19: 2163.45 | H19: 1.9099 | I19: 45458 | J19: 0.86940972 | K19: 0 | L19: 0 | M19: 0 | N19: 0 | O19: 0 | P19: 0 | Q19: 0 | R19: 0 | S19: 0 | T19: 0 | U19: 0 | V19: 0 | W19: =AVERAGE(H19:H23) -> 1.97662 | Y19: 0 | Z19: WR00L2L2 | AA19: 18368 | AB19: 32 | AC19: 2 | AD19: 4 | AE19: 2043.38 | AF19: 2.0221 | AG19: 45465 | AH19: 0.89940972 | AI19: 0 | AJ19: 0 | AK19: 0 | AL19: 0 | AM19: 0 | AN19: 0 | AO19: 0 | AP19: 0 | AQ19: 0 | AR19: 0 | AS19: 0 | AT19: 0 | AU19: =AVERAGE(AF19:AF23) -> 2.04912
A20: 1 | B20: WR00L2L2 | C20: 18368 | D20: 32 | E20: 2 | F20: 4 | G20: 2076.12 | H20: 1.9902 | I20: 45460 | J20: 0.16418981 | K20: 0 | L20: 0 | M20: 0 | N20: 0 | O20: 0 | P20: 0 | Q20: 0 | R20: 0 | S20: 0 | T20: 0 | U20: 0 | V20: 0 | Y20: 1 | Z20: WR00L2L2 | AA20: 18368 | AB20: 32 | AC20: 2 | AD20: 4 | AE20: 2014.83 | AF20: 2.0507 | AG20: 45468 | AH20: 0.76061343 | AI20: 0 | AJ20: 0 | AK20: 0 | AL20: 0 | AM20: 0 | AN20: 0 | AO20: 0 | AP20: 0 | AQ20: 0 | AR20: 0 | AS20: 0 | AT20: 0
A21: 2 | B21: WR00L2L2 | C21: 18368 | D21: 32 | E21: 2 | F21: 4 | G21: 2131.33 | H21: 1.9386 | I21: 45461 | J21: 0.77415509 | K21: 0 | L21: 0 | M21: 0 | N21: 0 | O21: 0 | P21: 0 | Q21: 0 | R21: 0 | S21: 0 | T21: 0 | U21: 0 | V21: 0 | Y21: 2 | Z21: WR00L2L2 | AA21: 18368 | AB21: 32 | AC21: 2 | AD21: 4 | AE21: 1965.66 | AF21: 2.102 | AG21: 45470 | AH21: 0.021458333 | AI21: 0 | AJ21: 0 | AK21: 0 | AL21: 0 | AM21: 0 | AN21: 0 | AO21: 0 | AP21: 0 | AQ21: 0 | AR21: 0 | AS21: 0 | AT21: 0
A22: 3 | B22: WR00L2L2 | C22: 18368 | D22: 32 | E22: 2 | F22: 4 | G22: 2050.77 | H22: 2.0148 | I22: 45463 | J22: 0.072847222 | K22: 0 | L22: 0 | M22: 0 | N22: 0 | O22: 0 | P22: 0 | Q22: 0 | R22: 0 | S22: 0 | T22: 0 | U22: 0 | V22: 0 | Y22: 3 | Z22: WR00L2L2 | AA22: 18368 | AB22: 32 | AC22: 2 | AD22: 4 | AE22: 2038.54 | AF22: 2.0269 | AG22: 45471 | AH22: 0.29185185 | AI22: 0 | AJ22: 0 | AK22: 0 | AL22: 0 | AM22: 0 | AN22: 0 | AO22: 0 | AP22: 0 | AQ22: 0 | AR22: 0 | AS22: 0 | AT22: 0
A23: 4 | B23: WR00L2L2 | C23: 18368 | D23: 32 | E23: 2 | F23: 4 | G23: 2035.84 | H23: 2.0296 | I23: 45464 | J23: 0.35075231 | K23: 0 | L23: 0 | M23: 0 | N23: 0 | O23: 0 | P23: 0 | Q23: 0 | R23: 0 | S23: 0 | T23: 0 | U23: 0 | V23: 0 | Y23: 4 | Z23: WR00L2L2 | AA23: 18368 | AB23: 32 | AC23: 2 | AD23: 4 | AE23: 2021.53 | AF23: 2.0439 | AG23: 45472 | AH23: 0.55616898 | AI23: 0 | AJ23: 0 | AK23: 0 | AL23: 0 | AM23: 0 | AN23: 0 | AO23: 0 | AP23: 0 | AQ23: 0 | AR23: 0 | AS23: 0 | AT23: 0
A24: 0 | B24: WR00L2L2 | C24: 19456 | D24: 32 | E24: 2 | F24: 4 | G24: 2530.92 | H24: 1.9402 | I24: 45459 | J24: 0.26725694 | K24: 0 | L24: 0 | M24: 0 | N24: 0 | O24: 0 | P24: 0 | Q24: 0 | R24: 0 | S24: 0 | T24: 0 | U24: 0 | V24: 0 | W24: =AVERAGE(H24:H28) -> 1.96984 | Y24: 0 | Z24: WR00L2L2 | AA24: 19456 | AB24: 32 | AC24: 2 | AD24: 4 | AE24: 2407.29 | AF24: 2.0398 | AG24: 45466 | AH24: 0.29091435 | AI24: 0 | AJ24: 0 | AK24: 0 | AL24: 0 | AM24: 0 | AN24: 0 | AO24: 0 | AP24: 0 | AQ24: 0 | AR24: 0 | AS24: 0 | AT24: 0 | AU24: =AVERAGE(AF24:AF28) -> 2.07586
A25: 1 | B25: WR00L2L2 | C25: 19456 | D25: 32 | E25: 2 | F25: 4 | G25: 2429.96 | H25: 2.0208 | I25: 45460 | J25: 0.56556713 | K25: 0 | L25: 0 | M25: 0 | N25: 0 | O25: 0 | P25: 0 | Q25: 0 | R25: 0 | S25: 0 | T25: 0 | U25: 0 | V25: 0 | Y25: 1 | Z25: WR00L2L2 | AA25: 19456 | AB25: 32 | AC25: 2 | AD25: 4 | AE25: 2262.64 | AF25: 2.1702 | AG25: 45469 | AH25: 0.1466088 | AI25: 0 | AJ25: 0 | AK25: 0 | AL25: 0 | AM25: 0 | AN25: 0 | AO25: 0 | AP25: 0 | AQ25: 0 | AR25: 0 | AS25: 0 | AT25: 0
A26: 2 | B26: WR00L2L2 | C26: 19456 | D26: 32 | E26: 2 | F26: 4 | G26: 2670.12 | H26: 1.839 | I26: 45462 | J26: 0.1746412 | K26: 0 | L26: 0 | M26: 0 | N26: 0 | O26: 0 | P26: 0 | Q26: 0 | R26: 0 | S26: 0 | T26: 0 | U26: 0 | V26: 0 | Y26: 2 | Z26: WR00L2L2 | AA26: 19456 | AB26: 32 | AC26: 2 | AD26: 4 | AE26: 2456 | AF26: 1.9994 | AG26: 45470 | AH26: 0.41856481 | AI26: 0 | AJ26: 0 | AK26: 0 | AL26: 0 | AM26: 0 | AN26: 0 | AO26: 0 | AP26: 0 | AQ26: 0 | AR26: 0 | AS26: 0 | AT26: 0
A27: 3 | B27: WR00L2L2 | C27: 19456 | D27: 32 | E27: 2 | F27: 4 | G27: 2436.6 | H27: 2.0153 | I27: 45463 | J27: 0.4681713 | K27: 0 | L27: 0 | M27: 0 | N27: 0 | O27: 0 | P27: 0 | Q27: 0 | R27: 0 | S27: 0 | T27: 0 | U27: 0 | V27: 0 | Y27: 3 | Z27: WR00L2L2 | AA27: 19456 | AB27: 32 | AC27: 2 | AD27: 4 | AE27: 2350.77 | AF27: 2.0889 | AG27: 45471 | AH27: 0.68333333 | AI27: 0 | AJ27: 0 | AK27: 0 | AL27: 0 | AM27: 0 | AN27: 0 | AO27: 0 | AP27: 0 | AQ27: 0 | AR27: 0 | AS27: 0 | AT27: 0
A28: 4 | B28: WR00L2L2 | C28: 19456 | D28: 32 | E28: 2 | F28: 4 | G28: 2414.34 | H28: 2.0339 | I28: 45464 | J28: 0.74793981 | K28: 0 | L28: 0 | M28: 0 | N28: 0 | O28: 0 | P28: 0 | Q28: 0 | R28: 0 | S28: 0 | T28: 0 | U28: 0 | V28: 0 | Y28: 4 | Z28: WR00L2L2 | AA28: 19456 | AB28: 32 | AC28: 2 | AD28: 4 | AE28: 2359.63 | AF28: 2.081 | AG28: 45472 | AH28: 0.945625 | AI28: 0 | AJ28: 0 | AK28: 0 | AL28: 0 | AM28: 0 | AN28: 0 | AO28: 0 | AP28: 0 | AQ28: 0 | AR28: 0 | AS28: 0 | AT28: 0
A29: 0 | B29: WR00L2L2 | C29: 20544 | D29: 32 | E29: 2 | F29: 4 | G29: 2863.14 | H29: 2.0192 | I29: 45459 | J29: 0.73243056 | K29: 0 | L29: 0 | M29: 0 | N29: 0 | O29: 0 | P29: 0 | Q29: 0 | R29: 0 | S29: 0 | T29: 0 | U29: 0 | V29: 0 | W29: =AVERAGE(H29:H33) -> 1.97724 | Y29: 0 | Z29: WR00L2L2 | AA29: 20544 | AB29: 32 | AC29: 2 | AD29: 4 | AE29: 2698.39 | AF29: 2.1424 | AG29: 45466 | AH29: 0.74555556 | AI29: 0 | AJ29: 0 | AK29: 0 | AL29: 0 | AM29: 0 | AN29: 0 | AO29: 0 | AP29: 0 | AQ29: 0 | AR29: 0 | AS29: 0 | AT29: 0 | AU29: =AVERAGE(AF29:AF33) -> 2.11032
